File: data/TGA/005d-L_M/ExpDat_2025_02_21_PS-F2-dynamic-1K.csv
#EXPORTTYPE:                 ,DATA ALL
#FILE:                       ,2025_02_21_PS-F2-dynamic-1K.ngb-ss5
#FORMAT:                     ,NETZSCH5
#FTYPE:                      ,ASCII
#IDENTITY:                   ,PS-F2
#DECIMAL:                    ,POINT
#SEPARATOR:                  ,COMMA
#MTYPE:                      ,DSC
#INSTRUMENT:                 ,NETZSCH STA 449F5
#PROJECT:                    ,PS
#DATE/TIME:                  ,2/21/2025 4:40:02 PM (UTC-5)
#CORR. FILE:                 ,
#TEMPCAL:                    ,13-11-2024 10:37
#SENSITIVITY:                ,28-06-2023 13:53
#LABORATORY:                 ,Tran/Aspuru
#OPERATOR:                   ,Stanley
#REMARK:                     ,
#SAMPLE:                     ,PS-F2
#SAMPLE MASS /mg:            ,5.39
#MATERIAL:                   ,
#REFERENCE:                  ,
#REFERENCE MASS /mg:         ,0
#TYPE OF CRUCIBLE:           ,Al2O3 85 ‘l, open
#SAMPLE CRUCIBLE MASS /mg:   ,0
#REFERENCE CRUCIBLE MASS /mg:,0
#DSC RANGE /‘V:              ,5000
#TG RANGE /mg:               ,35000
#TAU-R:                      ,---
#CORR. CODE:                 ,000
#EXO:                        ,-1
#RANGE:                      ,20›C....800›C/0.0....20.0K/min
#SEGMENT:                    ,S1-4/4
#SEG. 1:                     ,20›C/5.0(K/min)/100›C
#SEG. 2:                     ,100›C/00:05/100›C
#SEG. 3:                     ,100›C/1.0(K/min)/400›C
#SEG. 4:                     ,400›C/20.0(K/min)/800›C

##Temp./›C,Time/min,DSC/(mW/mg),Mass/%,Gas Flow(purge2)/(ml/min),Gas Flow(protective)/(ml/min),TIC(scan:1)/A,Sensit./(uV/mW),Segment
 30.22100,  0.00000,      0.59479,100.00000,50.00000,37.00000,            ,0.92359,1
 31.46500,  1.06667,      0.15536, 99.75009,50.00000,36.00000,2.022801e-10,0.92367,1
 32.46600,  2.13333, 7.399134e-02, 93.99685,50.00000,36.00000,2.034645e-10,0.92376,1
 33.46200,  3.20000, 8.163629e-02, 93.50779,50.00000,36.00000,2.024879e-10,0.92384,1
 35.19600,  4.26667,      0.20579, 93.60853,50.00000,36.00000,2.021522e-10,0.92392,1
 38.01600,  5.33333,      0.38539, 93.99054,50.00000,36.00000,2.027054e-10,0.92399,1
 41.92300,  6.40000,      0.56937, 94.42931,50.00000,36.00000,2.033004e-10,0.92404,1
 46.74300,  7.46667,      0.74111, 94.89314,50.00000,36.00000,2.033501e-10,0.92412,1
 52.33800,  8.53333,      0.89248, 95.27106,50.00000,36.00000,2.039394e-10,0.92419,1
 58.50400,  9.60000,      1.01430, 95.57959,50.00000,36.00000,2.033959e-10,0.92431,1
 64.98100, 10.66667,      1.10461, 95.78312,50.00000,36.00000,2.030144e-10,0.92443,1
 71.60000, 11.73333,      1.16900, 95.98460,50.00000,36.00000,2.043896e-10,0.92457,1
 78.19000, 12.80000,      1.21053, 96.08534,50.00000,36.00000,2.040271e-10,0.92474,1
 84.73200, 13.86667,      1.23515, 96.16085,50.00000,36.00000,2.040005e-10,0.92495,1
 91.15400, 14.93333,      1.24895, 96.18609,50.00000,36.00000,2.040425e-10,0.92512,1
 97.32300, 15.98417,      1.26409, 96.21132,50.00000,36.00000,2.044887e-10,0.92530,2
101.40500, 16.78417,      1.11048, 95.87959,50.00000,36.00000,2.042179e-10,0.92544,2
104.04700, 17.58417,      0.74421, 95.27737,50.00000,36.00000,2.051391e-10,0.92558,2
105.79900, 18.38417,      0.48306, 94.83228,50.00000,36.00000,2.045135e-10,0.92572,2
107.02400, 19.18417,      0.31739, 94.54063,50.00000,36.00000,2.052021e-10,0.92584,2
107.70700, 19.98417,      0.15542, 94.09351,50.00000,36.00000,2.047863e-10,0.92595,2
107.88200, 20.78417, 6.161542e-03, 93.70928,50.00000,36.00000,2.047615e-10,0.92604,2
107.67000, 21.80083,     -0.10197, 93.35455,50.00000,36.00000,2.046509e-10,0.92612,3
107.41700, 22.86750,     -0.10812, 93.15306,50.00000,36.00000,2.051754e-10,0.92619,3
107.18700, 23.93417,     -0.10673, 92.98108,50.00000,36.00000,2.054119e-10,0.92620,3
107.03000, 25.00083,-8.623851e-02, 92.82987,50.00000,36.00000,2.050972e-10,0.92617,3
107.04600, 26.06750,-4.404346e-02, 92.73544,50.00000,36.00000,2.043323e-10,0.92611,3
107.26200, 27.13417, 4.620255e-04, 92.67885,50.00000,36.00000,2.049541e-10,0.92599,3
107.65700, 28.20083, 4.358981e-02, 92.66623,50.00000,36.00000,2.055721e-10,0.92584,3
108.23700, 29.26750, 8.241991e-02, 92.62208,50.00000,36.00000,2.048721e-10,0.92562,3
108.97000, 30.33417,      0.11757, 92.56549,50.00000,36.00000,2.054748e-10,0.92540,3
109.82100, 31.40083,      0.14735, 92.58423,50.00000,36.00000,2.054901e-10,0.92508,3
110.77700, 32.46750,      0.16883, 92.55918,50.00000,36.00000,2.054423e-10,0.92478,3
111.79600, 33.53417,      0.18555, 92.51503,50.00000,36.00000,2.054882e-10,0.92438,3
112.85700, 34.60083,      0.19780, 92.48349,50.00000,36.00000,2.060661e-10,0.92400,3
113.95800, 35.66750,      0.20621, 92.45844,50.00000,36.00000,2.053242e-10,0.92351,3
115.06700, 36.73417,      0.21077, 92.44583,50.00000,36.00000,2.053605e-10,0.92307,3
116.20800, 37.80083,      0.21395, 92.42059,50.00000,36.00000,2.058850e-10,0.92251,3
117.32800, 38.86750,      0.21497, 92.38275,50.00000,36.00000,2.057361e-10,0.92200,3
118.45800, 39.93417,      0.21506, 92.33878,50.00000,36.00000,2.058105e-10,0.92147,3
119.57200, 41.00083,      0.21345, 92.32616,50.00000,36.00000,2.065449e-10,0.92108,3
120.67200, 42.06750,      0.21323, 92.29462,50.00000,36.00000,2.060966e-10,0.92068,3
121.78700, 43.13417,      0.21193, 92.28200,50.00000,36.00000,2.059078e-10,0.92038,3
122.87100, 44.20083,      0.21094, 92.26327,50.00000,36.00000,2.062492e-10,0.92009,3
123.96200, 45.26750,      0.20887, 92.26327,50.00000,36.00000,2.063408e-10,0.91988,3
125.03300, 46.33417,      0.20818, 92.26327,50.00000,36.00000,2.067680e-10,0.91966,3
126.11400, 47.40083,      0.20905, 92.25696,50.00000,36.00000,2.067814e-10,0.91948,3
127.19700, 48.46750,      0.20977, 92.28200,50.00000,36.00000,2.064095e-10,0.91933,3
128.25700, 49.53417,      0.20971, 92.25696,50.00000,36.00000,2.070713e-10,0.91921,3
129.33000, 50.60083,      0.20919, 92.23803,50.00000,36.00000,2.066936e-10,0.91909,3
130.39999, 51.66750,      0.20991, 92.25065,50.00000,36.00000,2.073422e-10,0.91901,3
131.46001, 52.73417,      0.20955, 92.26327,50.00000,36.00000,2.069416e-10,0.91895,3
132.52699, 53.80083,      0.20872, 92.26327,50.00000,36.00000,2.074909e-10,0.91892,3
133.59700, 54.86750,      0.20898, 92.26939,50.00000,36.00000,2.077656e-10,0.91891,3
134.65601, 55.93417,      0.21126, 92.30724,50.00000,36.00000,2.081184e-10,0.91892,3
135.73399, 57.00083,      0.20997, 92.29258,50.00000,36.00000,2.078571e-10,0.91895,3
136.80200, 58.06750,      0.21070, 92.31781,50.00000,36.00000,2.074241e-10,0.91898,3
137.86700, 59.13417,      0.21050, 92.34286,50.00000,36.00000,2.071133e-10,0.91901,3
138.93401, 60.20083,      0.21030, 92.34286,50.00000,36.00000,2.074184e-10,0.91904,3
140.00400, 61.26750,      0.20947, 92.36178,50.00000,36.00000,2.077350e-10,0.91907,3
141.07001, 62.33417,      0.20803, 92.39332,50.00000,36.00000,2.084408e-10,0.91909,3
142.12601, 63.40083,      0.20751, 92.39332,50.00000,36.00000,2.077923e-10,0.91912,3
143.20399, 64.46750,      0.20591, 92.42486,50.00000,36.00000,2.071762e-10,0.91914,3
144.29401, 65.53417,      0.20493, 92.44991,50.00000,36.00000,2.078628e-10,0.91916,3
145.32800, 66.60083,      0.20567, 92.47514,50.00000,36.00000,2.070656e-10,0.91916,3
146.39900, 67.66750,      0.20689, 92.48776,50.00000,36.00000,2.072258e-10,0.91915,3
147.49001, 68.73417,      0.20576, 92.53822,50.00000,36.00000,2.081528e-10,0.91914,3
148.54900, 69.80083,      0.20305, 92.54453,50.00000,36.00000,2.080059e-10,0.91912,3
149.61200, 70.86750,      0.20380, 92.56327,50.00000,36.00000,2.082157e-10,0.91909,3
150.68800, 71.93417,      0.20220, 92.58850,50.00000,36.00000,2.074050e-10,0.91905,3
151.75400, 73.00083,      0.19996, 92.58850,50.00000,36.00000,2.075978e-10,0.91900,3
152.81799, 74.06750,      0.19899, 92.63896,50.00000,36.00000,2.083569e-10,0.91895,3
153.89101, 75.13417,      0.19848, 92.66401,50.00000,36.00000,2.079029e-10,0.91887,3
154.94299, 76.20083,      0.19750, 92.70186,50.00000,36.00000,2.083054e-10,0.91879,3
156.02100, 77.26750,      0.19700, 92.72078,50.00000,37.00000,2.078361e-10,0.91871,3
157.09000, 78.33417,      0.19397, 92.74601,50.00000,37.00000,2.079544e-10,0.91862,3
158.15900, 79.40083,      0.19047, 92.78367,50.00000,37.00000,2.084350e-10,0.91853,3
159.21600, 80.46750,      0.18933, 92.78367,50.00000,37.00000,2.082367e-10,0.91843,3
160.28500, 81.53417,      0.18661, 92.83414,50.00000,37.00000,2.085361e-10,0.91832,3
161.35800, 82.60083,      0.18342, 92.82783,50.00000,37.00000,2.087765e-10,0.91821,3
162.42900, 83.66750,      0.18212, 92.85306,50.00000,37.00000,2.082080e-10,0.91808,3
163.49800, 84.73417,      0.17987, 92.89072,50.00000,37.00000,2.091693e-10,0.91795,3
164.55600, 85.80083,      0.17698, 92.92857,50.00000,37.00000,2.081584e-10,0.91783,3
165.63000, 86.86750,      0.17394, 92.92857,50.00000,37.00000,2.088108e-10,0.91769,3
166.70700, 87.93417,      0.17089, 92.98516,50.00000,37.00000,2.086925e-10,0.91757,3
167.76900, 89.00083,      0.16878, 92.98516,50.00000,37.00000,2.085667e-10,0.91742,3
168.83200, 90.06750,      0.16636, 93.04193,50.00000,37.00000,2.096176e-10,0.91728,3
169.89600, 91.13417,      0.16219, 93.04193,50.00000,37.00000,2.086983e-10,0.91713,3
170.97600, 92.20083,      0.16104, 93.06716,50.00000,37.00000,2.088012e-10,0.91699,3
172.04201, 93.26750,      0.15733, 93.11744,50.00000,37.00000,2.092075e-10,0.91684,3
173.10100, 94.33417,      0.15458, 93.14267,50.00000,37.00000,2.093239e-10,0.91670,3
174.18100, 95.40083,      0.15151, 93.16790,50.00000,37.00000,2.086544e-10,0.91653,3
175.23900, 96.46750,      0.14700, 93.19926,50.00000,37.00000,2.083091e-10,0.91639,3
176.29700, 97.53417,      0.14360, 93.23711,50.00000,37.00000,2.088489e-10,0.91623,3
177.34801, 98.60083,      0.14131, 93.26234,50.00000,37.00000,2.089939e-10,0.91608,3
178.42200, 99.66750,      0.14046, 93.29369,50.00000,37.00000,2.087383e-10,0.91592,3
179.49699,100.73417,      0.13577, 93.31892,50.00000,37.00000,2.089767e-10,0.91577,3
180.55800,101.80083,      0.13171, 93.36308,50.00000,37.00000,2.093048e-10,0.91560,3
181.63600,102.86750,      0.12861, 93.38831,50.00000,37.00000,2.088242e-10,0.91545,3
182.69099,103.93417,      0.12550, 93.39443,50.00000,37.00000,2.089844e-10,0.91528,3
183.76401,105.00083,      0.12191, 93.41967,50.00000,37.00000,2.096081e-10,0.91514,3
184.83299,106.06750,      0.11928, 93.46382,50.00000,37.00000,2.091369e-10,0.91496,3
185.90500,107.13417,      0.11632, 93.50779,50.00000,37.00000,2.087593e-10,0.91481,3
186.97301,108.20083,      0.11127, 93.53506,50.00000,37.00000,2.086277e-10,0.91464,3
188.04201,109.26750,      0.10669, 93.56030,50.00000,37.00000,2.086716e-10,0.91449,3
189.10001,110.33417,      0.10388, 93.58553,50.00000,37.00000,2.090931e-10,0.91432,3
190.15100,111.40083,      0.10025, 93.61076,50.00000,37.00000,1.924248e-10,0.91414,3
191.22701,112.46750, 9.565977e-02, 93.62338,50.00000,37.00000,1.911602e-10,0.91399,3
192.29500,113.53417, 9.364020e-02, 93.66735,50.00000,37.00000,1.915512e-10,0.91381,3
193.37500,114.60083, 8.935639e-02, 93.68627,50.00000,37.00000,1.911983e-10,0.91366,3
194.44501,115.66750, 8.377132e-02, 93.71150,50.00000,37.00000,1.911220e-10,0.91348,3
195.50500,116.73417, 7.979517e-02, 93.74286,50.00000,37.00000,1.916199e-10,0.91332,3
196.56700,117.80083, 7.678477e-02, 93.79332,50.00000,37.00000,1.911259e-10,0.91314,3
197.63800,118.86750, 7.231095e-02, 93.81855,50.00000,37.00000,1.918965e-10,0.91299,3
198.70500,119.93417, 6.766728e-02, 93.82486,50.00000,37.00000,1.916236e-10,0.91281,3
199.77100,121.00083, 6.350309e-02, 93.84991,50.00000,37.00000,1.908341e-10,0.91266,3
200.83701,122.06750, 5.949451e-02, 93.88145,50.00000,37.00000,1.915322e-10,0.91247,3
201.89101,123.13417, 5.564134e-02, 93.92560,50.00000,37.00000,1.911316e-10,0.91231,3
202.96600,124.20083, 5.178263e-02, 93.95288,50.00000,37.00000,1.906929e-10,0.91213,3
204.03799,125.26750, 4.824312e-02, 93.97180,50.00000,37.00000,1.914730e-10,0.91197,3
205.09599,126.33417, 4.420759e-02, 93.99685,50.00000,37.00000,1.909255e-10,0.91178,3
206.16000,127.40083, 3.918565e-02, 94.04100,50.00000,37.00000,1.909790e-10,0.91162,3
207.22900,128.46750, 3.562580e-02, 94.05993,50.00000,37.00000,1.911411e-10,0.91143,3
208.28600,129.53417, 3.058722e-02, 94.07885,50.00000,37.00000,1.914768e-10,0.91127,3
209.37399,130.60083, 2.750500e-02, 94.10390,50.00000,37.00000,1.909618e-10,0.91108,3
210.42999,131.66750, 2.031974e-02, 94.13544,50.00000,37.00000,1.913814e-10,0.91091,3
211.49899,132.73417, 1.525389e-02, 94.16067,50.00000,37.00000,1.913776e-10,0.91072,3
212.55200,133.80083, 1.099943e-02, 94.18590,50.00000,37.00000,1.914959e-10,0.91056,3
213.62601,134.86750, 7.394610e-03, 94.21725,50.00000,37.00000,1.912880e-10,0.91036,3
214.68600,135.93417, 1.809255e-03, 94.24249,50.00000,37.00000,1.912746e-10,0.91019,3
215.76500,137.00083,-3.457326e-03, 94.28033,50.00000,37.00000,1.918374e-10,0.91000,3
216.83000,138.06750,-9.557838e-03, 94.28033,50.00000,37.00000,1.912289e-10,0.90983,3
217.88499,139.13417,-1.286575e-02, 94.33061,50.00000,37.00000,1.908989e-10,0.90963,3
218.96800,140.20083,-1.733611e-02, 94.33061,50.00000,37.00000,1.918697e-10,0.90947,3
220.02499,141.26750,-2.379792e-02, 94.35788,50.00000,37.00000,1.914997e-10,0.90926,3
221.09000,142.33417,-2.994154e-02, 94.38942,50.00000,37.00000,1.916084e-10,0.90908,3
222.16800,143.40083,-3.411059e-02, 94.40835,50.00000,37.00000,1.912517e-10,0.90888,3
223.23500,144.46750,-3.961358e-02, 94.44601,50.00000,37.00000,1.914424e-10,0.90870,3
224.30000,145.53417,-4.761606e-02, 94.47124,50.00000,37.00000,1.911202e-10,0.90851,3
225.35400,146.60083,-5.015355e-02, 94.47124,50.00000,37.00000,1.922607e-10,0.90833,3
226.42599,147.66750,-5.585556e-02, 94.52171,50.00000,37.00000,1.911392e-10,0.90812,3
227.48700,148.73417,-6.090294e-02, 94.55306,50.00000,37.00000,1.910153e-10,0.90794,3
228.56100,149.80083,-6.729393e-02, 94.58460,50.00000,37.00000,1.917801e-10,0.90773,3
229.61700,150.86750,-7.419703e-02, 94.58460,50.00000,37.00000,1.918831e-10,0.90755,3
230.69400,151.93417,-8.094891e-02, 94.60983,50.00000,37.00000,1.919861e-10,0.90734,3
231.74800,153.00083,-8.537395e-02, 94.62876,50.00000,37.00000,1.920299e-10,0.90716,3
232.81700,154.06750,-8.897326e-02, 94.65380,50.00000,37.00000,1.918544e-10,0.90694,3
233.89400,155.13417,-9.475739e-02, 94.67904,50.00000,37.00000,1.915588e-10,0.90676,3
234.95900,156.20083,     -0.10307, 94.70427,50.00000,37.00000,1.914253e-10,0.90655,3
236.01100,157.26750,     -0.10871, 94.72319,50.00000,37.00000,1.919460e-10,0.90636,3
237.07600,158.33417,     -0.11218, 94.77347,50.00000,37.00000,1.916886e-10,0.90615,3
238.15100,159.40083,     -0.11986, 94.79239,50.00000,37.00000,1.912938e-10,0.90596,3
239.22701,160.46750,     -0.12504, 94.80501,50.00000,37.00000,1.921139e-10,0.90574,3
240.29100,161.53417,     -0.13174, 94.83024,50.00000,37.00000,1.920834e-10,0.90555,3
241.35201,162.60083,     -0.13997, 94.83024,50.00000,37.00000,1.915912e-10,0.90533,3
242.42799,163.66750,     -0.14569, 94.87421,50.00000,37.00000,1.915302e-10,0.90514,3
243.49699,164.73417,     -0.15244, 94.89314,50.00000,37.00000,1.922855e-10,0.90493,3
244.54800,165.80083,     -0.15987, 94.88275,50.00000,37.00000,1.924000e-10,0.90473,3
245.61600,166.86750,     -0.16496, 94.93302,50.00000,37.00000,1.921291e-10,0.90451,3
246.68100,167.93417,     -0.17107, 94.95826,50.00000,37.00000,1.919594e-10,0.90432,3
247.75200,169.00083,     -0.17736, 94.97087,50.00000,37.00000,1.923713e-10,0.90409,3
248.82500,170.06750,     -0.18520, 94.98349,50.00000,37.00000,1.927604e-10,0.90386,3
249.88600,171.13417,     -0.19272, 95.01484,50.00000,37.00000,1.926574e-10,0.90366,3
250.94299,172.20083,     -0.19872, 95.00223,50.00000,37.00000,1.925545e-10,0.90343,3
252.01100,173.26750,     -0.20644, 95.03377,50.00000,37.00000,1.927052e-10,0.90323,3
253.07800,174.33417,     -0.21144, 95.04638,50.00000,37.00000,1.927738e-10,0.90300,3
254.15601,175.40083,     -0.21971, 95.07161,50.00000,37.00000,1.927395e-10,0.90280,3
255.22099,176.46750,     -0.22508, 95.09685,50.00000,37.00000,1.929455e-10,0.90257,3
256.28201,177.53417,     -0.23235, 95.13451,50.00000,37.00000,1.919804e-10,0.90237,3
257.35999,178.60083,     -0.24033, 95.14082,50.00000,37.00000,1.924038e-10,0.90213,3
258.41299,179.66750,     -0.24695, 95.14082,50.00000,37.00000,1.921234e-10,0.90193,3
259.49301,180.73417,     -0.25307, 95.16809,50.00000,37.00000,1.920624e-10,0.90169,3
260.54901,181.80083,     -0.26041, 95.16809,50.00000,37.00000,1.917534e-10,0.90149,3
261.60300,182.86750,     -0.26827, 95.21855,50.00000,37.00000,1.920891e-10,0.90125,3
262.69400,183.93417,     -0.27565, 95.21855,50.00000,37.00000,1.919422e-10,0.90100,3
263.74701,185.00083,     -0.28201, 95.23748,50.00000,37.00000,1.918316e-10,0.90080,3
264.81201,186.06750,     -0.28993, 95.26252,50.00000,37.00000,1.921711e-10,0.90056,3
265.87900,187.13417,     -0.29840, 95.28145,50.00000,37.00000,1.917229e-10,0.90035,3
266.93701,188.20083,     -0.30653, 95.29406,50.00000,37.00000,1.923961e-10,0.90011,3
268.01199,189.26750,     -0.31226, 95.31929,50.00000,37.00000,1.927547e-10,0.89990,3
269.06601,190.33417,     -0.32338, 95.31299,50.00000,37.00000,1.926403e-10,0.89965,3
270.14401,191.40083,     -0.32828, 95.33822,50.00000,37.00000,1.928119e-10,0.89945,3
271.19601,192.46750,     -0.33597, 95.33822,50.00000,37.00000,1.927719e-10,0.89919,3
272.26300,193.53417,     -0.34507, 95.37588,50.00000,37.00000,1.927357e-10,0.89899,3
273.34100,194.60083,     -0.35054, 95.38219,50.00000,37.00000,1.933689e-10,0.89873,3
274.40100,195.66750,     -0.36038, 95.38219,50.00000,37.00000,1.930637e-10,0.89852,3
275.47699,196.73417,     -0.36938, 95.41373,50.00000,37.00000,1.930370e-10,0.89827,3
276.54599,197.80083,     -0.37752, 95.40742,50.00000,37.00000,1.929664e-10,0.89805,3
277.59799,198.86750,     -0.38480, 95.43265,50.00000,37.00000,1.926232e-10,0.89780,3
278.66400,199.93417,     -0.39368, 95.43265,50.00000,37.00000,1.929531e-10,0.89754,3
279.73801,201.00083,     -0.40065, 95.45788,50.00000,37.00000,1.928711e-10,0.89732,3
280.79999,202.06750,     -0.41028, 95.45788,50.00000,37.00000,1.926499e-10,0.89707,3
281.86801,203.13417,     -0.41729, 95.45788,50.00000,37.00000,1.927833e-10,0.89685,3
282.92899,204.20083,     -0.42572, 95.47032,50.00000,37.00000,1.929492e-10,0.89660,3
283.99399,205.26750,     -0.43383, 95.49555,50.00000,37.00000,1.930160e-10,0.89637,3
285.07999,206.33417,     -0.44144, 95.50186,50.00000,37.00000,1.928807e-10,0.89611,3
286.13501,207.40083,     -0.45223, 95.52709,50.00000,37.00000,1.932163e-10,0.89589,3
287.20300,208.46750,     -0.46005, 95.50186,50.00000,37.00000,1.927872e-10,0.89563,3
288.26300,209.53417,     -0.47090, 95.50186,50.00000,37.00000,1.936112e-10,0.89540,3
289.32199,210.60083,     -0.47698, 95.55863,50.00000,37.00000,1.925506e-10,0.89513,3
290.39499,211.66750,     -0.48735, 95.55863,50.00000,37.00000,1.928462e-10,0.89491,3
291.45999,212.73417,     -0.49596, 95.54601,50.00000,37.00000,1.933956e-10,0.89465,3
292.53500,213.80083,     -0.50371, 95.55863,50.00000,37.00000,1.935767e-10,0.89442,3
293.60101,214.86750,     -0.51469, 95.55863,50.00000,37.00000,1.935806e-10,0.89416,3
294.66501,215.93417,     -0.52265, 95.57106,50.00000,37.00000,1.939373e-10,0.89393,3
295.71600,217.00083,     -0.53099, 95.58367,50.00000,37.00000,1.925373e-10,0.89366,3
296.79099,218.06750,     -0.54079, 95.58998,50.00000,37.00000,1.929608e-10,0.89339,3
297.85999,219.13417,     -0.54883, 95.60891,50.00000,37.00000,1.938400e-10,0.89316,3
298.93100,220.20083,     -0.56030, 95.58367,50.00000,37.00000,1.934242e-10,0.89288,3
300.00699,221.26750,     -0.56910, 95.60260,50.00000,37.00000,1.931038e-10,0.89266,3
301.05899,222.33417,     -0.58151, 95.58998,50.00000,37.00000,1.932106e-10,0.89238,3
302.11899,223.40083,     -0.58964, 95.58998,50.00000,37.00000,1.937122e-10,0.89215,3
303.18600,224.46750,     -0.59797, 95.58367,50.00000,37.00000,1.930389e-10,0.89187,3
304.25500,225.53417,     -0.60885, 95.56475,50.00000,37.00000,1.934929e-10,0.89163,3
305.32700,226.60083,     -0.62013, 95.57106,50.00000,37.00000,1.932412e-10,0.89136,3
306.40100,227.66750,     -0.62818, 95.57106,50.00000,37.00000,1.939887e-10,0.89112,3
307.45801,228.73417,     -0.63805, 95.56475,50.00000,37.00000,1.930943e-10,0.89084,3
308.52200,229.80083,     -0.64777, 95.56475,50.00000,37.00000,1.930370e-10,0.89061,3
309.58499,230.86750,     -0.65769, 95.55863,50.00000,37.00000,1.939315e-10,0.89033,3
310.66000,231.93417,     -0.66929, 95.53340,50.00000,37.00000,1.935729e-10,0.89009,3
311.71600,233.00083,     -0.67635, 95.51447,50.00000,37.00000,1.936016e-10,0.88981,3
312.79099,234.06750,     -0.68819, 95.51447,50.00000,37.00000,1.942043e-10,0.88952,3
313.85101,235.13417,     -0.69694, 95.48924,50.00000,37.00000,1.932030e-10,0.88928,3
314.91699,236.20083,     -0.70719, 95.46401,50.00000,37.00000,1.938877e-10,0.88900,3
315.98599,237.26750,     -0.71544, 95.45788,50.00000,37.00000,1.941242e-10,0.88875,3
317.05600,238.33417,     -0.72758, 95.42004,50.00000,37.00000,1.936322e-10,0.88846,3
318.12799,239.40083,     -0.73717, 95.40742,50.00000,37.00000,1.935920e-10,0.88823,3
319.20099,240.46750,     -0.74827, 95.37588,50.00000,37.00000,1.932449e-10,0.88794,3
320.27200,241.53417,     -0.75866, 95.33191,50.00000,37.00000,1.933479e-10,0.88770,3
321.33401,242.60083,     -0.77275, 95.28145,50.00000,37.00000,1.931286e-10,0.88741,3
322.39401,243.66750,     -0.78097, 95.24991,50.00000,37.00000,1.940308e-10,0.88716,3
323.45901,244.73417,     -0.79181, 95.19332,50.00000,37.00000,1.934395e-10,0.88687,3
324.53400,245.80083,     -0.80120, 95.12412,50.00000,37.00000,1.933574e-10,0.88662,3
325.60199,246.86750,     -0.80969, 95.09258,50.00000,37.00000,1.934948e-10,0.88633,3
326.68399,247.93417,     -0.82471, 95.01707,50.00000,37.00000,1.935138e-10,0.88604,3
327.73199,249.00083,     -0.83174, 94.96660,50.00000,37.00000,1.936893e-10,0.88579,3
328.79300,250.06750,     -0.84365, 94.87217,50.00000,37.00000,1.936645e-10,0.88549,3
329.85300,251.13417,     -0.85186, 94.81558,50.00000,37.00000,1.939583e-10,0.88524,3
330.92401,252.20083,     -0.86552, 94.71484,50.00000,37.00000,1.935234e-10,0.88493,3
331.98999,253.26750,     -0.87659, 94.62022,50.00000,37.00000,1.939945e-10,0.88469,3
333.06201,254.33417,     -0.88264, 94.48813,50.00000,37.00000,1.933536e-10,0.88440,3
334.13501,255.40083,     -0.89640, 94.36215,50.00000,37.00000,1.944866e-10,0.88414,3
335.19400,256.46750,     -0.90285, 94.24879,50.00000,37.00000,1.937313e-10,0.88383,3
336.26401,257.53417,     -0.91385, 94.07254,50.00000,37.00000,1.941490e-10,0.88357,3
337.31500,258.60083,     -0.92072, 93.92134,50.00000,37.00000,1.934204e-10,0.88328,3
338.39401,259.66750,     -0.93160, 93.71781,50.00000,37.00000,1.937351e-10,0.88298,3
339.46701,260.73417,     -0.93910, 93.54137,50.00000,36.00000,1.946697e-10,0.88271,3
340.52701,261.80083,     -0.95152, 93.28961,50.00000,37.00000,1.939525e-10,0.88242,3
341.58801,262.86750,     -0.95962, 93.06289,50.00000,36.00000,1.944962e-10,0.88216,3
342.66400,263.93417,     -0.96795, 92.78794,50.00000,37.00000,1.939258e-10,0.88185,3
343.72000,265.00083,     -0.97685, 92.48571,50.00000,36.00000,1.936397e-10,0.88159,3
344.78799,266.06750,     -0.98389, 92.17495,50.00000,36.00000,1.941356e-10,0.88129,3
345.85300,267.13417,     -0.99056, 91.79295,50.00000,36.00000,1.940536e-10,0.88102,3
346.92099,268.20083,     -0.99936, 91.38590,50.00000,36.00000,1.940365e-10,0.88071,3
347.97299,269.26750,     -1.00567, 90.95139,50.00000,36.00000,1.943588e-10,0.88044,3
349.05301,270.33417,     -1.00994, 90.46438,50.00000,36.00000,1.947555e-10,0.88014,3
350.12100,271.40083,     -1.01898, 89.89759,50.00000,36.00000,1.941338e-10,0.87982,3
351.18799,272.46750,     -1.02556, 89.32245,50.00000,36.00000,1.938514e-10,0.87956,3
352.25500,273.53417,     -1.03158, 88.66141,50.00000,36.00000,1.944332e-10,0.87925,3
353.31699,274.60083,     -1.03569, 87.93098,50.00000,36.00000,1.945133e-10,0.87898,3
354.38300,275.66750,     -1.03963, 87.13748,50.00000,36.00000,1.948300e-10,0.87867,3
355.44800,276.73417,     -1.04569, 86.27477,50.00000,36.00000,1.943798e-10,0.87840,3
356.51599,277.80083,     -1.05119, 85.35547,50.00000,36.00000,1.939468e-10,0.87808,3
357.57001,278.86750,     -1.05534, 84.30186,50.00000,36.00000,1.951198e-10,0.87783,3
358.63599,279.93417,     -1.06009, 83.16846,50.00000,36.00000,1.944352e-10,0.87751,3
359.70001,281.00083,     -1.06350, 81.94267,50.00000,36.00000,1.944179e-10,0.87719,3
360.78299,282.06750,     -1.06675, 80.58460,50.00000,36.00000,1.946335e-10,0.87691,3
361.85101,283.13417,     -1.06747, 79.14675,50.00000,36.00000,1.939659e-10,0.87659,3
362.89301,284.20083,     -1.07145, 77.54731,50.00000,36.00000,1.947498e-10,0.87632,3
363.97501,285.26750,     -1.07278, 75.82412,50.00000,36.00000,1.942824e-10,0.87599,3
365.02499,286.33417,     -1.07250, 73.97699,50.00000,36.00000,1.945343e-10,0.87573,3
366.09900,287.40083,     -1.07362, 71.98516,50.00000,36.00000,1.950091e-10,0.87540,3
367.16901,288.46750,     -1.07591, 69.81688,50.00000,36.00000,1.945801e-10,0.87512,3
368.23300,289.53417,     -1.07800, 67.49332,50.00000,36.00000,1.947269e-10,0.87480,3
369.30801,290.60083,     -1.07600, 65.01243,50.00000,36.00000,1.945820e-10,0.87452,3
370.36600,291.66750,     -1.08437, 62.41596,50.00000,36.00000,1.948204e-10,0.87420,3
371.43701,292.73417,     -1.08787, 59.62022,50.00000,36.00000,1.947727e-10,0.87392,3
372.49799,293.80083,     -1.10161, 56.69833,50.00000,36.00000,1.947975e-10,0.87360,3
373.57101,294.86750,     -1.11107, 53.66549,50.00000,36.00000,1.943932e-10,0.87327,3
374.63599,295.93417,     -1.12429, 50.50019,50.00000,36.00000,1.949272e-10,0.87299,3
375.71799,297.00083,     -1.14232, 47.24471,50.00000,36.00000,1.951943e-10,0.87265,3
376.78000,298.06750,     -1.16295, 43.93673,50.00000,36.00000,1.949425e-10,0.87238,3
377.84500,299.13417,     -1.18602, 40.58887,50.00000,36.00000,1.950435e-10,0.87205,3
378.90500,300.20083,     -1.21571, 37.19703,50.00000,36.00000,1.948528e-10,0.87177,3
379.96600,301.26750,     -1.24926, 33.81763,50.00000,36.00000,1.951351e-10,0.87143,3
381.04501,302.33417,     -1.28513, 30.50334,50.00000,36.00000,1.949635e-10,0.87115,3
382.11099,303.40083,     -1.32906, 27.32968,50.00000,36.00000,1.951542e-10,0.87082,3
383.17300,304.46750,     -1.37270, 24.23599,50.00000,36.00000,1.950989e-10,0.87053,3
384.24399,305.53417,     -1.42829, 21.32041,50.00000,36.00000,1.949024e-10,0.87021,3
385.30301,306.60083,     -1.47079, 18.58980,50.00000,36.00000,1.951751e-10,0.86992,3
386.37601,307.66750,     -1.52086, 16.05213,50.00000,36.00000,1.959592e-10,0.86959,3
387.44601,308.73417,     -1.57267, 13.79777,50.00000,36.00000,1.951599e-10,0.86930,3
388.51300,309.80083,     -1.62502, 11.75343,50.00000,36.00000,1.958447e-10,0.86897,3
389.58200,310.86750,     -1.67652,  9.93785,50.00000,36.00000,1.950322e-10,0.86863,3
390.64401,311.93417,     -1.73077,  8.42022,50.00000,36.00000,1.956825e-10,0.86834,3
391.71500,313.00083,     -1.78499,  7.03915,50.00000,36.00000,1.948128e-10,0.86799,3
392.78699,314.06750,     -1.84139,  5.83006,50.00000,36.00000,1.954098e-10,0.86771,3
393.85699,315.13417,     -1.90281,  4.72820,50.00000,36.00000,1.961555e-10,0.86737,3
394.91800,316.20083,     -1.96378,  3.82356,50.00000,36.00000,1.956558e-10,0.86708,3
395.97400,317.26750,     -2.02063,  3.03432,50.00000,36.00000,1.955529e-10,0.86673,3
397.04800,318.33417,     -2.06873,  2.35640,50.00000,36.00000,1.947575e-10,0.86644,3
398.11200,319.40083,     -2.11082,  1.80649,50.00000,36.00000,1.954441e-10,0.86609,3
399.17599,320.46750,     -2.14853,  1.35102,50.00000,36.00000,1.961155e-10,0.86580,3
399.68900,320.97917,     -2.16574,  1.14731,50.00000,36.00000,1.952705e-10,0.86561,4
399.81900,321.05917,     -2.13506,  1.12226,50.00000,36.00000,1.952705e-10,0.86561,4
400.07901,321.13917,     -1.99906,  1.12226,50.00000,36.00000,1.952705e-10,0.86561,4
400.50000,321.21917,     -1.74188,  1.12226,50.00000,36.00000,1.954651e-10,0.86556,4
401.09900,321.29917,     -1.36912,  1.14731,50.00000,36.00000,1.954651e-10,0.86556,4
401.88199,321.37917,     -0.89397,  1.22301,50.00000,36.00000,1.953811e-10,0.86552,4
402.85101,321.45917,     -0.34221,  1.28794,50.00000,36.00000,1.953811e-10,0.86552,4
403.98499,321.53917,      0.26013,  1.38460,50.00000,36.00000,1.948910e-10,0.86547,4
405.27600,321.61917,      0.87705,  1.44119,50.00000,36.00000,1.948910e-10,0.86547,4
406.67899,321.69917,      1.48520,  1.50000,50.00000,36.00000,1.954727e-10,0.86542,4
408.20099,321.77917,      2.05733,  1.55881,50.00000,36.00000,1.954727e-10,0.86542,4
409.76901,321.85917,      2.57129,  1.64063,50.00000,36.00000,1.954460e-10,0.86537,4
411.39600,321.93917,      3.01232,  1.66586,50.00000,36.00000,1.954460e-10,0.86537,4
413.03299,322.01917,      3.37212,  1.69091,50.00000,36.00000,1.954270e-10,0.86532,4
414.65100,322.09917,      3.64439,  1.71614,50.00000,36.00000,1.954270e-10,0.86532,4
416.26300,322.17917,      3.83361,  1.71614,50.00000,36.00000,1.949216e-10,0.86527,4
417.82300,322.25917,      3.94047,  1.72245,50.00000,36.00000,1.949216e-10,0.86527,4
419.35599,322.33917,      3.98111,  1.70353,50.00000,36.00000,1.951733e-10,0.86522,4
420.83401,322.41917,      3.96423,  1.69091,50.00000,36.00000,1.951733e-10,0.86522,4
422.30600,322.49917,      3.89964,  1.63636,50.00000,36.00000,1.953468e-10,0.86517,4
423.71100,322.57917,      3.80636,  1.61132,50.00000,36.00000,1.953468e-10,0.86517,4
425.07599,322.65917,      3.69287,  1.58609,50.00000,36.00000,1.954556e-10,0.86512,4
426.41299,322.73917,      3.57160,  1.52931,50.00000,36.00000,1.954556e-10,0.86512,4
427.74200,322.81917,      3.45261,  1.48534,50.00000,36.00000,1.962281e-10,0.86508,4
429.05899,322.89917,      3.34886,  1.43915,50.00000,36.00000,1.962281e-10,0.86508,4
430.39099,322.97917,      3.26203,  1.40130,50.00000,36.00000,1.957798e-10,0.86502,4
431.70001,323.05917,      3.19739,  1.37607,50.00000,36.00000,1.957798e-10,0.86502,4
433.04099,323.13917,      3.15936,  1.32375,50.00000,36.00000,1.957245e-10,0.86497,4
434.40701,323.21917,      3.14761,  1.27328,50.00000,36.00000,1.957245e-10,0.86497,4
435.79800,323.29917,      3.15821,  1.24805,50.00000,36.00000,1.960506e-10,0.86491,4
437.21301,323.37917,      3.19622,  1.19777,50.00000,36.00000,1.960506e-10,0.86491,4
438.65701,323.45917,      3.25043,  1.17254,50.00000,36.00000,1.950817e-10,0.86487,4
440.13101,323.53917,      3.32006,  1.15993,50.00000,36.00000,1.950817e-10,0.86487,4
441.63599,323.61917,      3.40306,  1.12226,50.00000,36.00000,1.958408e-10,0.86483,4
443.17801,323.69917,      3.49088,  1.09703,50.00000,36.00000,1.958408e-10,0.86483,4
444.73700,323.77917,      3.58021,  1.07180,50.00000,36.00000,1.957512e-10,0.86477,4
446.32599,323.85917,      3.66591,  1.04657,50.00000,36.00000,1.957512e-10,0.86477,4
447.92401,323.93917,      3.74328,  1.04657,50.00000,36.00000,1.958504e-10,0.86472,4
449.53400,324.01917,      3.81120,  1.04026,50.00000,36.00000,1.958504e-10,0.86472,4
451.17001,324.09917,      3.86988,  1.01929,50.00000,36.00000,1.960830e-10,0.86467,4
452.78500,324.17917,      3.91618,  0.99406,50.00000,36.00000,1.960830e-10,0.86467,4
454.42999,324.25917,      3.95182,  0.96902,50.00000,36.00000,1.961232e-10,0.86463,4
456.07501,324.33917,      3.97592,  0.96902,50.00000,36.00000,1.961232e-10,0.86463,4
457.71301,324.41917,      3.99034,  0.94378,50.00000,36.00000,1.954918e-10,0.86457,4
459.34500,324.49917,      3.99148,  0.94378,50.00000,36.00000,1.954918e-10,0.86457,4
460.98901,324.57917,      3.98624,  0.93748,50.00000,36.00000,1.954498e-10,0.86453,4
462.62900,324.65917,      3.97314,  0.91855,50.00000,36.00000,1.954498e-10,0.86453,4
464.26901,324.73917,      3.95818,  0.91855,50.00000,36.00000,1.957264e-10,0.86447,4
465.89700,324.81917,      3.93881,  0.91855,50.00000,36.00000,1.957264e-10,0.86447,4
467.53699,324.89917,      3.91471,  0.91855,50.00000,36.00000,1.957130e-10,0.86442,4
469.17700,324.97917,      3.88979,  0.94378,50.00000,36.00000,1.957130e-10,0.86442,4
470.81699,325.05917,      3.86182,  0.94378,50.00000,36.00000,1.961002e-10,0.86438,4
472.45801,325.13917,      3.83821,  0.94378,50.00000,36.00000,1.961002e-10,0.86438,4
474.10199,325.21917,      3.81403,  0.94378,50.00000,36.00000,1.958465e-10,0.86433,4
475.74799,325.29917,      3.78724,  0.96902,50.00000,36.00000,1.958465e-10,0.86433,4
477.41299,325.37917,      3.76584,  0.98776,50.00000,36.00000,1.964817e-10,0.86428,4
479.04599,325.45917,      3.74370,  0.99406,50.00000,36.00000,1.964817e-10,0.86428,4
480.69601,325.53917,      3.72084,  1.01929,50.00000,36.00000,1.964817e-10,0.86428,4
482.36301,325.61917,      3.70022,  1.04453,50.00000,36.00000,1.957130e-10,0.86422,4
484.01599,325.69917,      3.68055,  1.06976,50.00000,36.00000,1.957130e-10,0.86422,4
485.67700,325.77917,      3.66287,  1.09481,50.00000,36.00000,1.957225e-10,0.86416,4
487.34601,325.85917,      3.64099,  1.09481,50.00000,36.00000,1.957225e-10,0.86416,4
489.01599,325.93917,      3.61875,  1.12004,50.00000,36.00000,1.962548e-10,0.86413,4
490.69000,326.01917,      3.59526,  1.12004,50.00000,36.00000,1.962548e-10,0.86413,4
492.35599,326.09917,      3.57090,  1.13896,50.00000,36.00000,1.956176e-10,0.86407,4
494.02399,326.17917,      3.54248,  1.17050,50.00000,36.00000,1.956176e-10,0.86407,4
495.69199,326.25917,      3.51298,  1.19555,50.00000,36.00000,1.963691e-10,0.86403,4
497.35400,326.33917,      3.48027,  1.19555,50.00000,36.00000,1.963691e-10,0.86403,4
499.02399,326.41917,      3.44347,  1.22078,50.00000,36.00000,1.960564e-10,0.86398,4
500.69400,326.49917,      3.40531,  1.27124,50.00000,36.00000,1.960564e-10,0.86398,4
502.35699,326.57917,      3.36552,  1.27124,50.00000,36.00000,1.960907e-10,0.86392,4
504.02301,326.65917,      3.32226,  1.29647,50.00000,36.00000,1.960907e-10,0.86392,4
505.68399,326.73917,      3.28488,  1.29647,50.00000,36.00000,1.962852e-10,0.86388,4
507.35101,326.81917,      3.24615,  1.32152,50.00000,36.00000,1.962852e-10,0.86388,4
509.01099,326.89917,      3.21241,  1.34675,50.00000,36.00000,1.955319e-10,0.86383,4
510.67001,326.97917,      3.17659,  1.37199,50.00000,36.00000,1.955319e-10,0.86383,4
512.34003,327.05917,      3.14016,  1.37199,50.00000,36.00000,1.957588e-10,0.86378,4
514.00403,327.13917,      3.10757,  1.39722,50.00000,36.00000,1.957588e-10,0.86378,4
515.65698,327.21917,      3.07239,  1.42226,50.00000,36.00000,1.955147e-10,0.86374,4
517.32501,327.29917,      3.03685,  1.42226,50.00000,36.00000,1.955147e-10,0.86374,4
519.00403,327.37917,      3.00692,  1.46846,50.00000,36.00000,1.956940e-10,0.86368,4
520.67603,327.45917,      2.97010,  1.47477,50.00000,36.00000,1.956940e-10,0.86368,4
522.32898,327.53917,      2.93351,  1.50000,50.00000,36.00000,1.958561e-10,0.86363,4
523.99500,327.61917,      2.89702,  1.50000,50.00000,36.00000,1.958561e-10,0.86363,4
525.66101,327.69917,      2.85723,  1.52523,50.00000,36.00000,1.963329e-10,0.86358,4
527.33002,327.77917,      2.81774,  1.52523,50.00000,36.00000,1.963329e-10,0.86358,4
528.98297,327.85917,      2.77534,  1.55028,50.00000,36.00000,1.959649e-10,0.86353,4
530.64899,327.93917,      2.73448,  1.55028,50.00000,36.00000,1.959649e-10,0.86353,4
532.32001,328.01917,      2.69150,  1.60074,50.00000,36.00000,1.955032e-10,0.86349,4
533.97601,328.09917,      2.64389,  1.60074,50.00000,36.00000,1.955032e-10,0.86349,4
535.63599,328.17917,      2.59899,  1.62597,50.00000,36.00000,1.960163e-10,0.86344,4
537.27899,328.25917,      2.55066,  1.62597,50.00000,36.00000,1.960163e-10,0.86344,4
538.94098,328.33917,      2.50536,  1.65102,50.00000,36.00000,1.958637e-10,0.86339,4
540.59302,328.41917,      2.45589,  1.67625,50.00000,36.00000,1.958637e-10,0.86339,4
542.23102,328.49917,      2.40960,  1.67625,50.00000,36.00000,1.957226e-10,0.86333,4
543.89203,328.57917,      2.36317,  1.70148,50.00000,36.00000,1.957226e-10,0.86333,4
545.53497,328.65917,      2.31698,  1.72672,50.00000,36.00000,1.962204e-10,0.86329,4
547.20898,328.73917,      2.26869,  1.72672,50.00000,36.00000,1.962204e-10,0.86329,4
548.82599,328.81917,      2.22127,  1.75195,50.00000,36.00000,1.958884e-10,0.86324,4
550.47498,328.89917,      2.17546,  1.75195,50.00000,36.00000,1.958884e-10,0.86324,4
552.12097,328.97917,      2.12721,  1.77699,50.00000,36.00000,1.956768e-10,0.86319,4
553.77301,329.05917,      2.07652,  1.77699,50.00000,36.00000,1.956768e-10,0.86319,4
555.40698,329.13917,      2.02356,  1.80223,50.00000,36.00000,1.958484e-10,0.86313,4
557.05701,329.21917,      1.97818,  1.82746,50.00000,36.00000,1.958484e-10,0.86313,4
558.70801,329.29917,      1.93663,  1.85269,50.00000,36.00000,1.958484e-10,0.86313,4
560.34802,329.37917,      1.89411,  1.85269,50.00000,36.00000,1.959152e-10,0.86309,4
561.99597,329.45917,      1.85118,  1.87774,50.00000,36.00000,1.959152e-10,0.86309,4
563.62799,329.53917,      1.80223,  1.87774,50.00000,36.00000,1.964073e-10,0.86304,4
565.28601,329.61917,      1.75945,  1.90297,50.00000,36.00000,1.964073e-10,0.86304,4
566.91199,329.69917,      1.71211,  1.92820,50.00000,36.00000,1.964341e-10,0.86299,4
568.56201,329.77917,      1.66437,  1.95343,50.00000,36.00000,1.964341e-10,0.86299,4
570.19702,329.85917,      1.61590,  1.95343,50.00000,36.00000,1.958904e-10,0.86293,4
571.83600,329.93917,      1.56061,  1.97848,50.00000,36.00000,1.958904e-10,0.86293,4
573.48401,330.01917,      1.51481,  1.97848,50.00000,36.00000,1.961651e-10,0.86289,4
575.11798,330.09917,      1.46445,  2.00371,50.00000,36.00000,1.961651e-10,0.86289,4
576.76001,330.17917,      1.41390,  2.00371,50.00000,36.00000,1.967220e-10,0.86285,4
578.39099,330.25917,      1.36108,  2.02894,50.00000,36.00000,1.967220e-10,0.86285,4
580.03699,330.33917,      1.30859,  2.02894,50.00000,36.00000,1.960373e-10,0.86279,4
581.66699,330.41917,      1.25483,  2.05417,50.00000,36.00000,1.960373e-10,0.86279,4
583.30402,330.49917,      1.20087,  2.07922,50.00000,36.00000,1.956482e-10,0.86274,4
584.94299,330.57917,      1.14800,  2.10445,50.00000,36.00000,1.956482e-10,0.86274,4
586.56500,330.65917,      1.09024,  2.10445,50.00000,36.00000,1.958809e-10,0.86269,4
588.20502,330.73917,      1.03357,  2.12968,50.00000,36.00000,1.958809e-10,0.86269,4
589.84497,330.81917,      0.98241,  2.12968,50.00000,36.00000,1.955910e-10,0.86264,4
591.46802,330.89917,      0.92634,  2.15492,50.00000,36.00000,1.955910e-10,0.86264,4
593.10199,330.97917,      0.86564,  2.15492,50.00000,36.00000,1.956214e-10,0.86259,4
594.72699,331.05917,      0.80444,  2.18219,50.00000,36.00000,1.956214e-10,0.86259,4
596.35699,331.13917,      0.74249,  2.20742,50.00000,36.00000,1.963120e-10,0.86254,4
597.98700,331.21917,      0.67978,  2.23247,50.00000,36.00000,1.963120e-10,0.86254,4
599.62299,331.29917,      0.61422,  2.23247,50.00000,36.00000,1.955719e-10,0.86249,4
601.25702,331.37917,      0.56870,  2.25139,50.00000,36.00000,1.955719e-10,0.86249,4
602.87598,331.45917,      0.50981,  2.25770,50.00000,36.00000,1.961002e-10,0.86244,4
604.50702,331.53917,      0.44648,  2.29555,50.00000,36.00000,1.961002e-10,0.86244,4
606.14203,331.61917,      0.38319,  2.30816,50.00000,36.00000,1.952858e-10,0.86240,4
607.76898,331.69917,      0.31913,  2.33321,50.00000,36.00000,1.952858e-10,0.86240,4
609.39899,331.77917,      0.25778,  2.33321,50.00000,36.00000,1.959553e-10,0.86234,4
611.02600,331.85917,      0.19034,  2.35844,50.00000,36.00000,1.959553e-10,0.86234,4
612.66400,331.93917,      0.12214,  2.35844,50.00000,36.00000,1.952438e-10,0.86229,4
614.28802,332.01917, 4.781900e-02,  2.38367,50.00000,36.00000,1.952438e-10,0.86229,4
615.91400,332.09917,-2.194393e-02,  2.40891,50.00000,36.00000,1.958733e-10,0.86224,4
617.53699,332.17917,-9.489715e-02,  2.40891,50.00000,36.00000,1.958733e-10,0.86224,4
619.16199,332.25917,     -0.16783,  2.41521,50.00000,36.00000,1.957245e-10,0.86220,4
620.78400,332.33917,     -0.24586,  2.43395,50.00000,36.00000,1.957245e-10,0.86220,4
622.40698,332.41917,     -0.31796,  2.43395,50.00000,36.00000,1.956329e-10,0.86215,4
624.03003,332.49917,     -0.39677,  2.45918,50.00000,36.00000,1.956329e-10,0.86215,4
625.65002,332.57917,     -0.47099,  2.48442,50.00000,36.00000,1.960258e-10,0.86210,4
627.27698,332.65917,     -0.54789,  2.48442,50.00000,36.00000,1.960258e-10,0.86210,4
628.89697,332.73917,     -0.62288,  2.50334,50.00000,36.00000,1.960678e-10,0.86205,4
630.52100,332.81917,     -0.69893,  2.50965,50.00000,36.00000,1.960678e-10,0.86205,4
632.13397,332.89917,     -0.77822,  2.53692,50.00000,36.00000,1.968574e-10,0.86200,4
633.76300,332.97917,     -0.85887,  2.56197,50.00000,36.00000,1.968574e-10,0.86200,4
635.37799,333.05917,     -0.93977,  2.56197,50.00000,36.00000,1.951370e-10,0.86195,4
636.99902,333.13917,     -1.01493,  2.58720,50.00000,36.00000,1.951370e-10,0.86195,4
638.63898,333.21917,     -1.09774,  2.61243,50.00000,36.00000,1.959000e-10,0.86189,4
640.24402,333.29917,     -1.18133,  2.61243,50.00000,36.00000,1.959000e-10,0.86189,4
641.85999,333.37917,     -1.26355,  2.61243,50.00000,36.00000,1.963291e-10,0.86185,4
643.48102,333.45917,     -1.34549,  2.61243,50.00000,36.00000,1.963291e-10,0.86185,4
645.09003,333.53917,     -1.43098,  2.63766,50.00000,36.00000,1.957073e-10,0.86180,4
646.70697,333.61917,     -1.51287,  2.66289,50.00000,36.00000,1.957073e-10,0.86180,4
648.33002,333.69917,     -1.59200,  2.66289,50.00000,36.00000,1.962051e-10,0.86174,4
649.94299,333.77917,     -1.67550,  2.68794,50.00000,36.00000,1.962051e-10,0.86174,4
651.56799,333.85917,     -1.76123,  2.68794,50.00000,36.00000,1.959000e-10,0.86169,4
653.18103,333.93917,     -1.84193,  2.70686,50.00000,36.00000,1.959000e-10,0.86169,4
654.79401,334.01917,     -1.92760,  2.73840,50.00000,36.00000,1.959000e-10,0.86169,4
656.41901,334.09917,     -2.01021,  2.73840,50.00000,36.00000,1.956233e-10,0.86164,4
658.03699,334.17917,     -2.09361,  2.73840,50.00000,36.00000,1.956233e-10,0.86164,4
659.64899,334.25917,     -2.18061,  2.76364,50.00000,36.00000,1.965485e-10,0.86159,4
661.25299,334.33917,     -2.25973,  2.78868,50.00000,36.00000,1.965485e-10,0.86159,4
662.87299,334.41917,     -2.34586,  2.78868,50.00000,36.00000,1.957627e-10,0.86154,4
664.48798,334.49917,     -2.42886,  2.81391,50.00000,36.00000,1.957627e-10,0.86154,4
666.10199,334.57917,     -2.51182,  2.81391,50.00000,36.00000,1.961804e-10,0.86149,4
667.71802,334.65917,     -2.59615,  2.83915,50.00000,36.00000,1.961804e-10,0.86149,4
669.33197,334.73917,     -2.67734,  2.84545,50.00000,36.00000,1.962624e-10,0.86143,4
670.95099,334.81917,     -2.75991,  2.88312,50.00000,36.00000,1.962624e-10,0.86143,4
672.55798,334.89917,     -2.83901,  2.88942,50.00000,36.00000,1.954518e-10,0.86139,4
674.17700,334.97917,     -2.92120,  2.88942,50.00000,36.00000,1.954518e-10,0.86139,4
675.79700,335.05917,     -2.99653,  2.91466,50.00000,36.00000,1.958694e-10,0.86133,4
677.40802,335.13917,     -3.08087,  2.91466,50.00000,36.00000,1.958694e-10,0.86133,4
679.02502,335.21917,     -3.16462,  2.93989,50.00000,36.00000,1.964969e-10,0.86128,4
680.64697,335.29917,     -3.24605,  2.93989,50.00000,36.00000,1.964969e-10,0.86128,4
682.25403,335.37917,     -3.32481,  2.93989,50.00000,36.00000,1.961727e-10,0.86124,4
683.85602,335.45917,     -3.40949,  2.96512,50.00000,36.00000,1.961727e-10,0.86124,4
685.47699,335.53917,     -3.48817,  2.99017,50.00000,36.00000,1.960983e-10,0.86118,4
687.09497,335.61917,     -3.57884,  3.00278,50.00000,36.00000,1.960983e-10,0.86118,4
688.70801,335.69917,     -3.66140,  3.00278,50.00000,36.00000,1.963463e-10,0.86113,4
690.32800,335.77917,     -3.73874,  3.01540,50.00000,36.00000,1.963463e-10,0.86113,4
691.94397,335.85917,     -3.82033,  3.04490,50.00000,36.00000,1.962166e-10,0.86109,4
693.55798,335.93917,     -3.90010,  3.04490,50.00000,36.00000,1.962166e-10,0.86109,4
695.17603,336.01917,     -3.97982,  3.04490,50.00000,36.00000,1.963711e-10,0.86104,4
696.79199,336.09917,     -4.05541,  3.06994,50.00000,36.00000,1.963711e-10,0.86104,4
698.39801,336.17917,     -4.13494,  3.09518,50.00000,36.00000,1.951923e-10,0.86098,4
700.01801,336.25917,     -4.21095,  3.09518,50.00000,36.00000,1.951923e-10,0.86098,4
701.63000,336.33917,     -4.28860,  3.12041,50.00000,36.00000,1.963405e-10,0.86093,4
703.25702,336.41917,     -4.36243,  3.12041,50.00000,36.00000,1.963405e-10,0.86093,4
704.86603,336.49917,     -4.44253,  3.14564,50.00000,36.00000,1.964131e-10,0.86088,4
706.48700,336.57917,     -4.51821,  3.15807,50.00000,36.00000,1.964131e-10,0.86088,4
708.09100,336.65917,     -4.59548,  3.15807,50.00000,36.00000,1.961765e-10,0.86083,4
709.71100,336.73917,     -4.66629,  3.17069,50.00000,36.00000,1.961765e-10,0.86083,4
711.32599,336.81917,     -4.74548,  3.19592,50.00000,36.00000,1.963901e-10,0.86077,4
712.93103,336.89917,     -4.82308,  3.19592,50.00000,36.00000,1.963901e-10,0.86077,4
714.55298,336.97917,     -4.89978,  3.21484,50.00000,36.00000,1.955910e-10,0.86073,4
716.15900,337.05917,     -4.97662,  3.24007,50.00000,36.00000,1.955910e-10,0.86073,4
717.77698,337.13917,     -5.04898,  3.24007,50.00000,36.00000,1.963444e-10,0.86067,4
719.39697,337.21917,     -5.12302,  3.24007,50.00000,36.00000,1.963444e-10,0.86067,4
721.00299,337.29917,     -5.19690,  3.25900,50.00000,36.00000,1.961135e-10,0.86063,4
722.61798,337.37917,     -5.27339,  3.29666,50.00000,36.00000,1.961135e-10,0.86063,4
724.22198,337.45917,     -5.34705,  3.29666,50.00000,36.00000,1.962967e-10,0.86059,4
725.84497,337.53917,     -5.41951,  3.29666,50.00000,36.00000,1.962967e-10,0.86059,4
727.45697,337.61917,     -5.49509,  3.32189,50.00000,36.00000,1.961861e-10,0.86053,4
729.07397,337.69917,     -5.56791,  3.34082,50.00000,36.00000,1.961861e-10,0.86053,4
730.67902,337.77917,     -5.63697,  3.34712,50.00000,36.00000,1.954079e-10,0.86048,4
732.29999,337.85917,     -5.71437,  3.34712,50.00000,36.00000,1.954079e-10,0.86048,4
733.90802,337.93917,     -5.78862,  3.34712,50.00000,36.00000,1.961632e-10,0.86043,4
735.51398,338.01917,     -5.86274,  3.37217,50.00000,36.00000,1.961632e-10,0.86043,4
737.13202,338.09917,     -5.94104,  3.39740,50.00000,36.00000,1.964455e-10,0.86038,4
738.75299,338.17917,     -6.02498,  3.42263,50.00000,36.00000,1.964455e-10,0.86038,4
740.35303,338.25917,     -6.09726,  3.42263,50.00000,36.00000,1.959324e-10,0.86033,4
741.96899,338.33917,     -6.16831,  3.44787,50.00000,36.00000,1.959324e-10,0.86033,4
743.58099,338.41917,     -6.25042,  3.44787,50.00000,36.00000,1.959324e-10,0.86033,4
745.17902,338.49917,     -6.32539,  3.47291,50.00000,36.00000,1.955071e-10,0.86028,4
746.79700,338.57917,     -6.39915,  3.47291,50.00000,36.00000,1.955071e-10,0.86028,4
748.40900,338.65917,     -6.46973,  3.47291,50.00000,36.00000,1.964359e-10,0.86023,4
750.02802,338.73917,     -6.54297,  3.49814,50.00000,36.00000,1.964359e-10,0.86023,4
751.62903,338.81917,     -6.61386,  3.52338,50.00000,36.00000,1.969376e-10,0.86017,4
753.25800,338.89917,     -6.68327,  3.54230,50.00000,36.00000,1.969376e-10,0.86017,4
754.85303,338.97917,     -6.75113,  3.57384,50.00000,36.00000,1.959229e-10,0.86012,4
756.46698,339.05917,     -6.82449,  3.57384,50.00000,36.00000,1.959229e-10,0.86012,4
758.08099,339.13917,     -6.89252,  3.58627,50.00000,36.00000,1.954765e-10,0.86007,4
759.69000,339.21917,     -6.96715,  3.59889,50.00000,36.00000,1.954765e-10,0.86007,4
761.30298,339.29917,     -7.04415,  3.59889,50.00000,36.00000,1.961994e-10,0.86002,4
762.91699,339.37917,     -7.11644,  3.61150,50.00000,36.00000,1.961994e-10,0.86002,4
764.53802,339.45917,     -7.19205,  3.62412,50.00000,36.00000,1.961288e-10,0.85998,4
766.14301,339.53917,     -7.25942,  3.64935,50.00000,36.00000,1.961288e-10,0.85998,4
767.75299,339.61917,     -7.33134,  3.64935,50.00000,36.00000,1.960983e-10,0.85992,4
769.37000,339.69917,     -7.40163,  3.67458,50.00000,36.00000,1.960983e-10,0.85992,4
771.00299,339.77917,     -7.47222,  3.69963,50.00000,36.00000,1.964778e-10,0.85987,4
772.60400,339.85917,     -7.54092,  3.69963,50.00000,36.00000,1.964778e-10,0.85987,4
774.19800,339.93917,     -7.61412,  3.69963,50.00000,36.00000,1.959190e-10,0.85982,4
775.81403,340.01917,     -7.68174,  3.75009,50.00000,36.00000,1.959190e-10,0.85982,4
777.41498,340.09917,     -7.75038,  3.75640,50.00000,36.00000,1.960296e-10,0.85977,4
779.03101,340.17917,     -7.82087,  3.77532,50.00000,36.00000,1.960296e-10,0.85977,4
780.63702,340.25917,     -7.88961,  3.77532,50.00000,36.00000,1.965179e-10,0.85972,4
782.25800,340.33917,     -7.95488,  3.79406,50.00000,36.00000,1.965179e-10,0.85972,4
783.85797,340.41917,     -8.02175,  3.80037,50.00000,36.00000,1.963291e-10,0.85966,4
785.46997,340.49917,     -8.09204,  3.82560,50.00000,36.00000,1.963291e-10,0.85966,4
787.07599,340.57917,     -8.15869,  3.82560,50.00000,36.00000,1.960678e-10,0.85962,4
788.69598,340.65917,     -8.22532,  3.85083,50.00000,36.00000,1.960678e-10,0.85962,4
790.30701,340.73917,     -8.29081,  3.85083,50.00000,36.00000,1.964455e-10,0.85956,4
791.90198,340.81917,     -8.35921,  3.87607,50.00000,36.00000,            ,0.44813,4
793.51099,340.89917,     -8.42537,  3.89481,50.00000,36.00000,            ,0.44749,4
794.21997,340.93417,     -8.45542,  3.90111,50.00000,36.00000,            ,0.44720,4