File: data/TGA/005d-L_M/ExpDat_2025_07_15_SL_PS_Tosoh_F2_isothermal.csv
#EXPORTTYPE:                 ,DATA ALL
#FILE:                       ,2025_07_15_SL_PS_Tosoh_F2_isothermal.ngb-ss5
#FORMAT:                     ,NETZSCH5
#FTYPE:                      ,ASCII
#IDENTITY:                   ,PS-Tosoh-F2
#DECIMAL:                    ,POINT
#SEPARATOR:                  ,COMMA
#MTYPE:                      ,DSC
#INSTRUMENT:                 ,NETZSCH STA 449F5
#PROJECT:                    ,
#DATE/TIME:                  ,7/15/2025 9:28:45 AM (UTC-4)
#CORR. FILE:                 ,
#TEMPCAL:                    ,05-05-2025 14:38
#SENSITIVITY:                ,28-06-2023 13:53
#LABORATORY:                 ,Tran/AAG
#OPERATOR:                   ,Stanley
#REMARK:                     ,2025_03_29_SL_005d_M1_isothermal
#SAMPLE:                     ,PS-Tosoh-F2
#SAMPLE MASS /mg:            ,4.75
#MATERIAL:                   ,Polystyrene
#REFERENCE:                  ,
#REFERENCE MASS /mg:         ,0
#TYPE OF CRUCIBLE:           ,Al2O3 85 ‘l, open
#SAMPLE CRUCIBLE MASS /mg:   ,0
#REFERENCE CRUCIBLE MASS /mg:,0
#DSC RANGE /‘V:              ,5000
#TG RANGE /mg:               ,35000
#TAU-R:                      ,---
#CORR. CODE:                 ,000
#EXO:                        ,-1
#RANGE:                      ,30›C....800›C/0.0....20.0K/min
#SEGMENT:                    ,S1-5/5
#SEG. 1:                     ,30›C/10.0(K/min)/100›C
#SEG. 2:                     ,100›C/00:10/100›C
#SEG. 3:                     ,100›C/5.0(K/min)/300›C
#SEG. 4:                     ,300›C/20:00/300›C
#SEG. 5:                     ,300›C/20.0(K/min)/800›C

##Temp./›C,Time/min,DSC/(mW/mg),Mass/%,Gas Flow(purge2)/(ml/min),Gas Flow(protective)/(ml/min),TIC(scan:1)/A,Sensit./(uV/mW),Segment
 33.07300,   0.00000,      0.17659,    100.00000,50.00000,57.00000,            ,0.92409,1
 35.42000,   1.36000,      0.42306,     92.18063,50.00000,57.00000,1.864882e-08,0.92412,1
 41.76100,   2.72000,      1.14447,     93.85495,50.00000,57.00000,1.868561e-08,0.92418,1
 51.29100,   4.08000,      1.84429,     95.19347,50.00000,57.00000,1.870076e-08,0.92427,1
 64.29300,   5.44000,      2.63048,     96.51305,50.00000,57.00000,1.869815e-08,0.92440,1
 79.63600,   6.80000,      3.30284,     97.41579,50.00000,57.00000,1.873028e-08,0.92457,1
 88.74400,   7.58000,      3.44304,     97.49200,50.00000,57.00000,1.873378e-08,0.92468,2
 95.05400,   8.26000,      2.88361,     96.71074,50.00000,57.00000,1.869043e-08,0.92478,2
 99.46800,   8.94000,      2.14348,     95.85811,50.00000,57.00000,1.872720e-08,0.92488,2
102.81100,   9.62000,      1.66830,     95.22442,50.00000,57.00000,1.871715e-08,0.92498,2
105.58300,  10.30000,      1.36102,     94.73389,50.00000,57.00000,1.872555e-08,0.92508,2
107.65600,  10.98000,      1.03732,     94.23137,50.00000,57.00000,1.875246e-08,0.92518,2
109.00300,  11.66000,      0.67809,     93.68589,50.00000,57.00000,1.866543e-08,0.92528,2
109.74700,  12.34000,      0.35259,     93.17389,50.00000,57.00000,1.871556e-08,0.92538,2
110.01200,  13.02000, 9.865122e-02,     92.92842,50.00000,57.00000,1.868796e-08,0.92548,2
109.94500,  13.70000,-9.794941e-02,     92.45684,50.00000,57.00000,1.867205e-08,0.92558,2
109.60400,  14.38000,     -0.25359,     92.03053,50.00000,57.00000,1.870234e-08,0.92567,2
109.05900,  15.06000,     -0.37472,     91.67811,50.00000,57.00000,1.867996e-08,0.92576,2
108.35200,  15.74000,     -0.45908,     91.36126,50.00000,57.00000,1.867864e-08,0.92584,2
107.57800,  16.42000,     -0.51437,     91.10168,50.00000,57.00000,1.863758e-08,0.92592,2
106.64400,  17.20000,     -0.54375,     90.83726,50.00000,57.00000,1.868069e-08,0.92601,3
106.72100,  18.56000,      0.11759,     91.52084,50.00000,57.00000,1.864284e-08,0.92612,3
109.49900,  19.92000,      0.76862,     92.20674,50.00000,57.00000,1.863627e-08,0.92619,3
114.03500,  21.28000,      1.30017,     92.87853,50.00000,58.00000,1.866381e-08,0.92620,3
120.26700,  22.64000,      1.78107,     93.50021,50.00000,58.00000,1.863322e-08,0.92615,3
127.54300,  24.00000,      2.10655,     93.93600,50.00000,58.00000,1.861515e-08,0.92602,3
135.39101,  25.36000,      2.33307,     94.25032,50.00000,58.00000,1.862041e-08,0.92581,3
143.47900,  26.72000,      2.46695,     94.45747,50.00000,58.00000,1.861040e-08,0.92552,3
151.46700,  28.08000,      2.53923,     94.60042,50.00000,58.00000,1.862436e-08,0.92514,3
159.25101,  29.44000,      2.57473,     94.68632,50.00000,58.00000,1.856241e-08,0.92467,3
166.79601,  30.80000,      2.59636,     94.77200,50.00000,58.00000,1.859027e-08,0.92432,3
174.08900,  32.16000,      2.61938,     94.84337,50.00000,58.00000,1.854726e-08,0.92403,3
181.20200,  33.52000,      2.65055,     94.95768,50.00000,58.00000,1.856139e-08,0.92372,3
188.19701,  34.88000,      2.68716,     95.04358,50.00000,58.00000,1.854941e-08,0.92340,3
195.10001,  36.24000,      2.73590,     95.13642,50.00000,58.00000,1.855665e-08,0.92309,3
201.94600,  37.60000,      2.78430,     95.22211,50.00000,58.00000,1.855875e-08,0.92279,3
208.73399,  38.96000,      2.84291,     95.35074,50.00000,58.00000,1.852673e-08,0.92249,3
215.50999,  40.32000,      2.91051,     95.45074,50.00000,58.00000,1.854890e-08,0.92221,3
222.26801,  41.68000,      2.98255,     95.55074,50.00000,58.00000,1.853809e-08,0.92195,3
229.05299,  43.04000,      3.06096,     95.65789,50.00000,58.00000,1.852663e-08,0.92167,3
235.80000,  44.40000,      3.13633,     95.80084,50.00000,58.00000,1.853358e-08,0.92143,3
242.55701,  45.76000,      3.21259,     95.88905,50.00000,58.00000,1.854739e-08,0.92121,3
249.32500,  47.12000,      3.28939,     95.97474,50.00000,58.00000,1.848159e-08,0.92100,3
256.11200,  48.48000,      3.37141,     96.06042,50.00000,58.00000,1.850982e-08,0.92079,3
262.87399,  49.84000,      3.44513,     96.14632,50.00000,58.00000,1.847975e-08,0.92060,3
269.64600,  51.20000,      3.53057,     96.18189,50.00000,58.00000,1.848858e-08,0.92040,3
276.42700,  52.56000,      3.60794,     96.26779,50.00000,58.00000,1.846275e-08,0.92021,3
283.19800,  53.92000,      3.68557,     96.29621,50.00000,58.00000,1.845284e-08,0.92004,3
289.98801,  55.28000,      3.76922,     96.34632,50.00000,58.00000,1.849647e-08,0.91986,3
296.75299,  56.64000,      3.84033,     96.37495,50.00000,58.00000,1.847989e-08,0.91969,3
303.03000,  59.50000,      1.82596,     95.67937,50.00000,58.00000,1.845054e-08,0.91935,4
302.73599,  62.90000,      1.23353,     95.10779,50.00000,58.00000,1.841349e-08,0.91901,4
301.46399,  66.30000,      1.22941,     94.68863,50.00000,58.00000,1.840954e-08,0.91875,4
300.67899,  69.70000,      1.29953,     94.35747,50.00000,58.00000,1.843701e-08,0.91854,4
300.30099,  73.10000,      1.34039,     94.05032,50.00000,58.00000,1.843831e-08,0.91840,4
300.14499,  76.50000,      1.36626,     93.75726,50.00000,58.00000,1.839977e-08,0.91832,4
300.06201,  79.90000,      1.37674,     93.52863,50.00000,58.00000,1.846290e-08,0.91828,4
300.01901,  83.30000,      1.38728,     93.28568,50.00000,58.00000,1.848157e-08,0.91827,4
300.01801,  86.70000,      1.39442,     93.07853,50.00000,58.00000,1.845559e-08,0.91830,4
300.01300,  90.10000,      1.39849,     92.85705,50.00000,58.00000,1.844686e-08,0.91836,4
300.00699,  93.50000,      1.40236,     92.70232,50.00000,58.00000,1.845770e-08,0.91844,4
300.01700,  96.90000,      1.40625,     92.53789,50.00000,58.00000,1.842522e-08,0.91854,4
300.00500, 100.30000,      1.41133,     92.37347,50.00000,58.00000,1.840584e-08,0.91866,4
300.01300, 103.70000,      1.42236,     92.24253,50.00000,58.00000,1.836629e-08,0.91877,4
300.01901, 107.10000,      1.42502,     92.12105,50.00000,58.00000,1.835479e-08,0.91891,4
300.00299, 110.50000,      1.42724,     91.98295,50.00000,58.00000,1.839252e-08,0.91904,4
300.00201, 113.90000,      1.43295,     91.86147,50.00000,58.00000,1.838999e-08,0.91919,4
300.01801, 117.30000,      1.43665,     91.72568,50.00000,58.00000,1.838077e-08,0.91938,4
300.01901, 120.70000,      1.44726,     91.64000,50.00000,58.00000,1.838231e-08,0.91924,4
300.01099, 124.10000,      1.45031,     91.51853,50.00000,58.00000,1.835020e-08,0.91883,4
300.02100, 127.50000,      1.44094,     91.38758,50.00000,58.00000,1.838461e-08,0.91823,4
300.01901, 130.90000,      1.44665,     91.27789,50.00000,58.00000,1.839697e-08,0.91741,4
300.00699, 134.30000,      1.44173,     91.17074,50.00000,58.00000,1.832783e-08,0.91628,4
300.01501, 137.70000,      1.44318,     91.06358,50.00000,59.00000,1.833749e-08,0.91496,4
300.02200, 141.10000,      1.44951,     90.96358,50.00000,59.00000,1.839135e-08,0.91343,4
300.02200, 144.50000,      1.45176,     90.85642,50.00000,59.00000,1.838566e-08,0.91169,4
300.02701, 147.90000,      1.45626,     90.75621,50.00000,59.00000,1.838669e-08,0.90969,4
300.01099, 151.30000,      1.46847,     90.67768,50.00000,59.00000,1.834116e-08,0.90763,4
300.01599, 154.70000,      1.45971,     90.55853,50.00000,59.00000,1.836019e-08,0.90543,4
300.01001, 158.10000,      1.46255,     90.46568,50.00000,59.00000,1.834061e-08,0.90314,4
300.00900, 161.50000,      1.46071,     90.36568,50.00000,59.00000,1.835792e-08,0.90078,4
300.02701, 164.90000,      1.46605,     90.26800,50.00000,59.00000,1.835223e-08,0.89835,4
300.01401, 168.30000,      1.46786,     90.17516,50.00000,59.00000,1.835331e-08,0.89576,4
300.01099, 171.70000,      1.47398,     90.06800,50.00000,59.00000,1.830611e-08,0.89326,4
300.01300, 175.10000,      1.47562,     89.97516,50.00000,59.00000,1.833111e-08,0.89071,4
300.01300, 178.50000,      1.47623,     89.89411,50.00000,59.00000,1.833860e-08,0.88813,4
300.01401, 181.90000,      1.47031,     89.81074,50.00000,59.00000,1.831004e-08,0.88552,4
300.01501, 185.30000,      1.47297,     89.68926,50.00000,59.00000,1.831298e-08,0.88287,4
300.00900, 188.70000,      1.47357,     89.58926,50.00000,59.00000,1.831495e-08,0.88017,4
300.02100, 192.10000,      1.47502,     89.48926,50.00000,59.00000,1.833243e-08,0.87744,4
300.03201, 195.50000,      1.47973,     89.39642,50.00000,59.00000,1.836144e-08,0.87453,4
300.03201, 198.90000,      1.47932,     89.31053,50.00000,59.00000,1.829778e-08,0.87170,4
300.01801, 202.30000,      1.48093,     89.23916,50.00000,59.00000,1.832722e-08,0.86884,4
300.01501, 205.70000,      1.48664,     89.11053,50.00000,59.00000,1.834029e-08,0.86593,4
300.01099, 209.10000,      1.48969,     89.02484,50.00000,59.00000,1.837332e-08,0.86297,4
300.01099, 212.50000,      1.49398,     88.93179,50.00000,59.00000,1.830861e-08,0.85996,4
300.01501, 215.90000,      1.49541,     88.83895,50.00000,59.00000,1.832228e-08,0.85691,4
300.00500, 219.30000,      1.49090,     88.72463,50.00000,59.00000,1.830982e-08,0.85364,4
300.02200, 222.70000,      1.49400,     88.63179,50.00000,59.00000,1.828329e-08,0.85050,4
300.01700, 226.10000,      1.49705,     88.55326,50.00000,59.00000,1.833893e-08,0.84732,4
300.00500, 229.50000,      1.50009,     88.35789,50.00000,59.00000,1.831216e-08,0.84409,4
300.00000, 232.90000,      1.50110,     88.35074,50.00000,59.00000,1.832182e-08,0.84081,4
299.99100, 236.30000,      1.50618,     88.31495,50.00000,58.00000,1.835521e-08,0.83750,4
299.98801, 239.70000,      1.50965,     88.26505,50.00000,58.00000,1.837506e-08,0.83399,4
299.99701, 243.10000,      1.51191,     88.20063,50.00000,58.00000,1.836752e-08,0.83060,4
300.01501, 246.50000,      1.50929,     88.13389,50.00000,58.00000,1.836814e-08,0.82717,4
300.01700, 249.90000,      1.51194,     88.05305,50.00000,58.00000,1.839764e-08,0.82370,4
300.02600, 253.30000,      1.50869,     88.01726,50.00000,58.00000,1.840733e-08,0.82022,4
300.01901, 256.70000,      1.51133,     87.92674,50.00000,58.00000,1.837875e-08,0.81668,4
300.01099, 260.10000,      1.51622,     87.84337,50.00000,58.00000,1.835533e-08,0.81296,4
300.00699, 263.50000,      1.51662,     87.77916,50.00000,57.00000,1.837014e-08,0.80938,4
300.01001, 266.90000,      1.51846,     87.64105,50.00000,57.00000,1.836754e-08,0.80577,4
300.00400, 270.30000,      1.52151,     87.55284,50.00000,57.00000,1.836878e-08,0.80216,4
300.02499, 273.70000,      1.52093,     87.50042,50.00000,57.00000,1.841106e-08,0.79851,4
300.00601, 277.10000,      1.52600,     87.37411,50.00000,57.00000,1.838585e-08,0.79465,4
300.02600, 280.50000,      1.52849,     87.29326,50.00000,57.00000,1.831871e-08,0.79096,4
300.04199, 283.90000,      1.53076,     87.15979,50.00000,58.00000,1.830205e-08,0.78598,4
300.04099, 287.30000,      1.52933,     87.05263,50.00000,58.00000,1.826184e-08,0.78424,4
300.02701, 290.70000,      1.53257,     86.90253,50.00000,58.00000,1.827022e-08,0.78431,4
300.01999, 294.10000,      1.53766,     86.81684,50.00000,58.00000,1.822809e-08,0.78499,4
300.01501, 297.50000,      1.54254,     86.67389,50.00000,58.00000,1.825730e-08,0.78569,4
300.00699, 300.90000,      1.53845,     86.57389,50.00000,58.00000,1.823244e-08,0.78622,4
300.01199, 304.30000,      1.54417,     86.45958,50.00000,58.00000,1.825930e-08,0.78658,4
300.01501, 307.70000,      1.54642,     86.38105,50.00000,59.00000,1.819701e-08,0.78683,4
300.01199, 311.10000,      1.54478,     86.28105,50.00000,59.00000,1.823628e-08,0.78697,4
300.02802, 314.50000,      1.55134,     86.16905,50.00000,59.00000,1.819467e-08,0.78706,4
300.01700, 317.90000,      1.54887,     86.08337,50.00000,59.00000,1.820015e-08,0.78712,4
300.01501, 321.30000,      1.55071,     85.99747,50.00000,59.00000,1.823671e-08,0.78714,4
300.00699, 324.70000,      1.55110,     85.89747,50.00000,59.00000,1.822948e-08,0.78717,4
300.01801, 328.10000,      1.55234,     85.81179,50.00000,59.00000,1.823485e-08,0.78718,4
300.02802, 331.50000,      1.55604,     85.74021,50.00000,59.00000,1.818948e-08,0.78719,4
300.02200, 334.90000,      1.55398,     85.63305,50.00000,59.00000,1.819748e-08,0.78720,4
300.01999, 338.30000,      1.55888,     85.57600,50.00000,59.00000,1.818892e-08,0.78719,4
300.02399, 341.70000,      1.56154,     85.46632,50.00000,59.00000,1.818490e-08,0.78720,4
300.01501, 345.10000,      1.55846,     85.38779,50.00000,59.00000,1.819674e-08,0.78720,4
300.01599, 348.50000,      1.56173,     85.28779,50.00000,59.00000,1.819198e-08,0.78720,4
300.02200, 351.90000,      1.55970,     85.21874,50.00000,59.00000,1.817168e-08,0.78720,4
300.02399, 355.30000,      1.56174,     85.13305,50.00000,59.00000,1.816006e-08,0.78720,4
300.01801, 358.70000,      1.56275,     85.06147,50.00000,59.00000,1.812735e-08,0.78719,4
300.02499, 362.10000,      1.56297,     84.99011,50.00000,59.00000,1.820373e-08,0.78720,4
300.02701, 365.50000,      1.56930,     84.87579,50.00000,59.00000,1.817136e-08,0.78719,4
300.00601, 368.90000,      1.56926,     84.80674,50.00000,59.00000,1.818351e-08,0.78719,4
300.00800, 372.30000,      1.56824,     84.70653,50.00000,59.00000,1.819256e-08,0.78719,4
300.02600, 375.70000,      1.57052,     84.63747,50.00000,59.00000,1.816371e-08,0.78720,4
300.01801, 379.10000,      1.56948,     84.52316,50.00000,60.00000,1.818942e-08,0.78720,4
300.01300, 382.50000,      1.57111,     84.45411,50.00000,60.00000,1.817649e-08,0.78720,4
300.01599, 385.90000,      1.57295,     84.38274,50.00000,60.00000,1.815780e-08,0.78719,4
300.02200, 389.30000,      1.57276,     84.28274,50.00000,60.00000,1.816520e-08,0.78720,4
300.01401, 392.70000,      1.56948,     84.19684,50.00000,60.00000,1.818020e-08,0.78719,4
300.01801, 396.10000,      1.57275,     84.08737,50.00000,60.00000,1.816304e-08,0.78719,4
299.99701, 399.50000,      1.57536,     84.00884,50.00000,60.00000,1.815401e-08,0.78719,4
300.02100, 402.90000,      1.57887,     83.93011,50.00000,60.00000,1.819918e-08,0.78719,4
300.02100, 406.30000,      1.57683,     83.82295,50.00000,60.00000,1.815813e-08,0.78719,4
300.02301, 409.70000,      1.57643,     83.75158,50.00000,60.00000,1.817724e-08,0.78719,4
300.01300, 413.10000,      1.57906,     83.65158,50.00000,60.00000,1.821037e-08,0.78720,4
300.01901, 416.50000,      1.57846,     83.56568,50.00000,60.00000,1.816558e-08,0.78719,4
300.01700, 419.90000,      1.57866,     83.49432,50.00000,60.00000,1.822631e-08,0.78719,4
300.00900, 423.30000,      1.57640,     83.38000,50.00000,60.00000,1.819245e-08,0.78720,4
300.01700, 426.70000,      1.57989,     83.29179,50.00000,60.00000,1.817758e-08,0.78720,4
300.01001, 430.10000,      1.58192,     83.19895,50.00000,60.00000,1.819929e-08,0.78720,4
300.02499, 433.50000,      1.58317,     83.10611,50.00000,60.00000,1.814904e-08,0.78718,4
300.02100, 436.90000,      1.58561,     83.02505,50.00000,60.00000,1.820018e-08,0.78719,4
300.02200, 440.30000,      1.58255,     82.94653,50.00000,60.00000,1.817230e-08,0.78720,4
300.01501, 443.70000,      1.58315,     82.86800,50.00000,60.00000,1.820502e-08,0.78719,4
300.01401, 447.10000,      1.58498,     82.78211,50.00000,60.00000,1.816895e-08,0.78719,4
300.01199, 450.50000,      1.58722,     82.70358,50.00000,60.00000,1.817546e-08,0.78719,4
300.01700, 453.90000,      1.58438,     82.58211,50.00000,60.00000,1.819962e-08,0.78720,4
300.01999, 457.30000,      1.58805,     82.51305,50.00000,60.00000,1.819577e-08,0.78720,4
300.02399, 460.70000,      1.59010,     82.40589,50.00000,60.00000,1.822327e-08,0.78721,4
300.01599, 464.10000,      1.58907,     82.32484,50.00000,60.00000,1.819727e-08,0.78719,4
300.01801, 467.50000,      1.58642,     82.22968,50.00000,60.00000,1.820249e-08,0.78719,4
300.01901, 470.90000,      1.58907,     82.15095,50.00000,60.00000,1.817262e-08,0.78720,4
300.02600, 474.30000,      1.59051,     82.04379,50.00000,60.00000,1.818088e-08,0.78719,4
300.01901, 477.70000,      1.59295,     81.97242,50.00000,60.00000,1.822387e-08,0.78719,4
300.02301, 481.10000,      1.59051,     81.87937,50.00000,60.00000,1.821241e-08,0.78720,4
300.00299, 484.50000,      1.59231,     81.77937,50.00000,60.00000,1.822817e-08,0.78719,4
300.01999, 487.90000,      1.59152,     81.68653,50.00000,60.00000,1.824211e-08,0.78720,4
300.00400, 491.30000,      1.59272,     81.59137,50.00000,60.00000,1.824486e-08,0.78720,4
299.99100, 494.70000,      1.59473,     81.52926,50.00000,59.00000,1.826746e-08,0.78718,4
299.98999, 498.10000,      1.59290,     81.49600,50.00000,59.00000,1.827278e-08,0.78719,4
300.00201, 501.50000,      1.59598,     81.41032,50.00000,59.00000,1.825985e-08,0.78719,4
300.00900, 504.90000,      1.59375,     81.38168,50.00000,59.00000,1.831542e-08,0.78720,4
300.01001, 508.30000,      1.59314,     81.31747,50.00000,59.00000,1.831436e-08,0.78719,4
300.01401, 511.70000,      1.59110,     81.20063,50.00000,59.00000,1.832092e-08,0.78718,4
300.02200, 515.10000,      1.59010,     81.12926,50.00000,59.00000,1.829565e-08,0.78720,4
300.01801, 518.50000,      1.59152,     81.03642,50.00000,59.00000,1.829510e-08,0.78719,4
300.01801, 521.90000,      1.59438,     80.94337,50.00000,58.00000,1.826042e-08,0.78717,4
300.01099, 525.30000,      1.59191,     80.87916,50.00000,58.00000,1.830298e-08,0.78719,4
300.02200, 528.70000,      1.59255,     80.79347,50.00000,58.00000,1.828804e-08,0.78719,4
300.01901, 532.10000,      1.59377,     80.70758,50.00000,58.00000,1.827719e-08,0.78719,4
300.03201, 535.50000,      1.59563,     80.63621,50.00000,58.00000,1.828517e-08,0.78719,4
300.00299, 538.90000,      1.59374,     80.55053,50.00000,58.00000,1.830855e-08,0.78718,4
300.01001, 542.30000,      1.59967,     80.42421,50.00000,58.00000,1.831610e-08,0.78719,4
300.01700, 545.70000,      1.59437,     80.34568,50.00000,58.00000,1.830037e-08,0.78719,4
299.99799, 549.10000,      1.59679,     80.23368,50.00000,58.00000,1.825862e-08,0.78720,4
300.01901, 552.50000,      1.59683,     80.14084,50.00000,58.00000,1.832641e-08,0.78720,4
300.02399, 555.90000,      1.59643,     80.05495,50.00000,58.00000,1.833213e-08,0.78720,4
300.01801, 559.30000,      1.59805,     79.96926,50.00000,58.00000,1.828532e-08,0.78719,4
300.00500, 562.70000,      1.59721,     79.84779,50.00000,58.00000,1.830106e-08,0.78719,4
300.01001, 566.10000,      1.59824,     79.75263,50.00000,58.00000,1.833151e-08,0.78720,4
300.01300, 569.50000,      1.59906,     79.69537,50.00000,58.00000,1.830824e-08,0.78717,4
300.01599, 572.90000,      1.59988,     79.59768,50.00000,58.00000,1.830745e-08,0.78720,4
300.02399, 576.30000,      1.59806,     79.53095,50.00000,58.00000,1.828191e-08,0.78720,4
300.01801, 579.70000,      1.59723,     79.42379,50.00000,58.00000,1.830268e-08,0.78721,4
300.01801, 583.10000,      1.59846,     79.33579,50.00000,58.00000,1.830277e-08,0.78721,4
300.02100, 586.50000,      1.60010,     79.23579,50.00000,58.00000,1.831913e-08,0.78722,4
300.02200, 589.90000,      1.59928,     79.18084,50.00000,58.00000,1.828552e-08,0.78722,4
300.01501, 593.30000,      1.59825,     79.07368,50.00000,58.00000,1.830837e-08,0.78722,4
300.02600, 596.70000,      1.59929,     78.98800,50.00000,58.00000,1.829737e-08,0.78721,4
300.01999, 600.10000,      1.60091,     78.90695,50.00000,58.00000,1.832155e-08,0.78720,4
300.01801, 603.50000,      1.59540,     78.80695,50.00000,58.00000,1.828772e-08,0.78720,4
299.99701, 606.90000,      1.59964,     78.70695,50.00000,58.00000,1.830785e-08,0.78720,4
300.01501, 610.30000,      1.59845,     78.64737,50.00000,58.00000,1.829067e-08,0.78719,4
300.00900, 613.70000,      1.59946,     78.56168,50.00000,58.00000,1.829547e-08,0.78719,4
300.01700, 617.10000,      1.59784,     78.48779,50.00000,58.00000,1.830222e-08,0.78719,4
300.01501, 620.50000,      1.59886,     78.40211,50.00000,59.00000,1.830239e-08,0.78719,4
300.00201, 623.90000,      1.59659,     78.32358,50.00000,59.00000,1.833769e-08,0.78721,4
300.03101, 627.30000,      1.59603,     78.24484,50.00000,59.00000,1.831012e-08,0.78719,4
300.01300, 630.70000,      1.59478,     78.13768,50.00000,59.00000,1.829129e-08,0.78719,4
300.01401, 634.10000,      1.59988,     78.06632,50.00000,59.00000,1.829495e-08,0.78719,4
300.02600, 637.50000,      1.59827,     77.99474,50.00000,59.00000,1.829426e-08,0.78720,4
300.00299, 640.90000,      1.59333,     77.90905,50.00000,59.00000,1.836247e-08,0.78720,4
300.01599, 644.30000,      1.59498,     77.82337,50.00000,59.00000,1.833851e-08,0.78721,4
300.03101, 647.70000,      1.59461,     77.73747,50.00000,59.00000,1.833994e-08,0.78720,4
300.01099, 651.10000,      1.59151,     77.68042,50.00000,59.00000,1.832682e-08,0.78720,4
300.01700, 654.50000,      1.59233,     77.57558,50.00000,59.00000,1.832978e-08,0.78720,4
300.01501, 657.90000,      1.58907,     77.50421,50.00000,59.00000,1.834352e-08,0.78719,4
300.01300, 661.30000,      1.59212,     77.44695,50.00000,59.00000,1.831279e-08,0.78719,4
300.01300, 664.70000,      1.58804,     77.34695,50.00000,59.00000,1.829213e-08,0.78716,4
300.00299, 668.10000,      1.59292,     77.27558,50.00000,59.00000,1.834270e-08,0.78716,4
300.01501, 671.50000,      1.58601,     77.16589,50.00000,59.00000,1.831629e-08,0.78716,4
300.01599, 674.90000,      1.59131,     77.08737,50.00000,59.00000,1.829110e-08,0.78716,4
300.01901, 678.30000,      1.58683,     77.00884,50.00000,59.00000,1.832730e-08,0.78719,4
300.00699, 681.70000,      1.58823,     76.93726,50.00000,59.00000,1.831562e-08,0.78718,4
300.01501, 685.10000,      1.58560,     76.82779,50.00000,59.00000,1.832300e-08,0.78719,4
300.01999, 688.50000,      1.58540,     76.74189,50.00000,59.00000,1.834865e-08,0.78718,4
300.01801, 691.90000,      1.58928,     76.69200,50.00000,59.00000,1.830925e-08,0.78718,4
300.01300, 695.30000,      1.58743,     76.60863,50.00000,59.00000,1.828986e-08,0.78720,4
300.01801, 698.70000,      1.58662,     76.52295,50.00000,59.00000,1.831107e-08,0.78719,4
300.01700, 702.10000,      1.58846,     76.42989,50.00000,59.00000,1.828910e-08,0.78719,4
300.01099, 705.50000,      1.58559,     76.34189,50.00000,59.00000,1.832635e-08,0.78718,4
300.01999, 708.90000,      1.58703,     76.25853,50.00000,59.00000,1.830462e-08,0.78717,4
300.01501, 712.30000,      1.58927,     76.19411,50.00000,59.00000,1.829674e-08,0.78719,4
300.01599, 715.70000,      1.58948,     76.12989,50.00000,59.00000,1.832021e-08,0.78720,4
300.01801, 719.10000,      1.58683,     76.02274,50.00000,59.00000,1.828183e-08,0.78718,4
300.01700, 722.50000,      1.58315,     75.95832,50.00000,59.00000,1.828077e-08,0.78719,4
300.00601, 725.90000,      1.58476,     75.85832,50.00000,59.00000,1.828201e-08,0.78719,4
300.00601, 729.30000,      1.58701,     75.78695,50.00000,59.00000,1.831297e-08,0.78718,4
300.01599, 732.70000,      1.58335,     75.69874,50.00000,59.00000,1.830605e-08,0.78718,4
300.01999, 736.10000,      1.58928,     75.64168,50.00000,59.00000,1.829935e-08,0.78719,4
300.02100, 739.50000,      1.58561,     75.58442,50.00000,59.00000,1.828238e-08,0.78720,4
300.02200, 742.90000,      1.58847,     75.48211,50.00000,59.00000,1.831664e-08,0.78718,4
300.02301, 746.30000,      1.58745,     75.39621,50.00000,59.00000,1.833091e-08,0.78718,4
300.02100, 749.70000,      1.58724,     75.32484,50.00000,59.00000,1.834267e-08,0.78718,4
300.01401, 753.10000,      1.58804,     75.23916,50.00000,59.00000,1.829317e-08,0.78719,4
300.02200, 756.50000,      1.58765,     75.13916,50.00000,59.00000,1.826550e-08,0.78719,4
300.01999, 759.90000,      1.58642,     75.07474,50.00000,59.00000,1.830036e-08,0.78719,4
300.02301, 763.30000,      1.58500,     74.96758,50.00000,59.00000,1.829685e-08,0.78720,4
300.02200, 766.70000,      1.58745,     74.90568,50.00000,59.00000,1.824565e-08,0.78719,4
300.01801, 770.10000,      1.58642,     74.82716,50.00000,59.00000,1.828798e-08,0.78719,4
300.00500, 773.50000,      1.58660,     74.76274,50.00000,59.00000,1.828657e-08,0.78719,4
300.01401, 776.90000,      1.58621,     74.69137,50.00000,59.00000,1.828695e-08,0.78718,4
300.01801, 780.30000,      1.58703,     74.57705,50.00000,59.00000,1.828590e-08,0.78719,4
300.01401, 783.70000,      1.58458,     74.51979,50.00000,59.00000,1.827756e-08,0.78718,4
300.01001, 787.10000,      1.58926,     74.40547,50.00000,59.00000,1.829634e-08,0.78718,4
300.02399, 790.50000,      1.58725,     74.31979,50.00000,59.00000,1.831666e-08,0.78719,4
300.00101, 793.90000,      1.58884,     74.24105,50.00000,59.00000,1.834314e-08,0.78719,4
300.01801, 797.30000,      1.58948,     74.16968,50.00000,59.00000,1.826908e-08,0.78718,4
300.01599, 800.70000,      1.58560,     74.06968,50.00000,59.00000,1.832481e-08,0.78719,4
300.00800, 804.10000,      1.58681,     74.01958,50.00000,59.00000,1.834342e-08,0.78718,4
300.01401, 807.50000,      1.58682,     73.91958,50.00000,59.00000,1.830028e-08,0.78719,4
300.01001, 810.90000,      1.58783,     73.86253,50.00000,59.00000,1.827764e-08,0.78720,4
300.01999, 814.30000,      1.58540,     73.76947,50.00000,59.00000,1.828438e-08,0.78719,4
300.02600, 817.70000,      1.59092,     73.68379,50.00000,59.00000,1.834505e-08,0.78720,4
300.02701, 821.10000,      1.58705,     73.60526,50.00000,59.00000,1.831085e-08,0.78719,4
300.00000, 824.50000,      1.58475,     73.51937,50.00000,59.00000,1.828229e-08,0.78719,4
300.00900, 827.90000,      1.58742,     73.43368,50.00000,59.00000,1.829073e-08,0.78719,4
300.02899, 831.30000,      1.58705,     73.37663,50.00000,59.00000,1.831796e-08,0.78719,4
300.00800, 834.70000,      1.58354,     73.31221,50.00000,59.00000,1.833348e-08,0.78719,4
300.01801, 838.10000,      1.58948,     73.20274,50.00000,59.00000,1.827722e-08,0.78719,4
300.01901, 841.50000,      1.59030,     73.12400,50.00000,59.00000,1.827705e-08,0.78719,4
300.01300, 844.90000,      1.58641,     73.05263,50.00000,59.00000,1.828034e-08,0.78719,4
300.00201, 848.30000,      1.58782,     72.92884,50.00000,59.00000,1.830149e-08,0.78719,4
300.01401, 851.70000,      1.58600,     72.85726,50.00000,59.00000,1.831573e-08,0.78720,4
300.02399, 855.10000,      1.58561,     72.78589,50.00000,59.00000,1.830709e-08,0.78719,4
300.00101, 858.50000,      1.58680,     72.70253,50.00000,59.00000,1.825739e-08,0.78719,4
300.00601, 861.90000,      1.59415,     72.64526,50.00000,59.00000,1.830895e-08,0.78721,4
300.01801, 865.30000,      1.58928,     72.52379,50.00000,59.00000,1.832753e-08,0.78719,4
299.99399, 868.70000,      1.59086,     72.44526,50.00000,59.00000,1.827788e-08,0.78718,4
300.01300, 872.10000,      1.58947,     72.37389,50.00000,59.00000,1.828568e-08,0.78719,4
300.02802, 875.50000,      1.58848,     72.30232,50.00000,59.00000,1.834982e-08,0.78719,4
300.01999, 878.90000,      1.59275,     72.22863,50.00000,59.00000,1.831539e-08,0.78718,4
300.02100, 882.30000,      1.59234,     72.14526,50.00000,59.00000,1.832078e-08,0.78719,4
300.01501, 885.70000,      1.59029,     72.03811,50.00000,59.00000,1.833289e-08,0.78718,4
300.02802, 889.10000,      1.59215,     71.97368,50.00000,59.00000,1.831601e-08,0.78720,4
300.01599, 892.50000,      1.59009,     71.88800,50.00000,59.00000,1.830393e-08,0.78719,4
300.00800, 895.90000,      1.58864,     71.80926,50.00000,59.00000,1.830442e-08,0.78719,4
300.01801, 899.30000,      1.59132,     71.72358,50.00000,59.00000,1.832383e-08,0.78718,4
300.01599, 902.70000,      1.58825,     71.64505,50.00000,59.00000,1.832978e-08,0.78719,4
300.02301, 906.10000,      1.58847,     71.57347,50.00000,59.00000,1.830556e-08,0.78719,4
300.01401, 909.50000,      1.59090,     71.46632,50.00000,59.00000,1.828979e-08,0.78719,4
300.02701, 912.90000,      1.58827,     71.42358,50.00000,59.00000,1.833248e-08,0.78720,4
300.01901, 916.30000,      1.59132,     71.32358,50.00000,59.00000,1.838704e-08,0.78718,4
300.01999, 919.70000,      1.58908,     71.23768,50.00000,59.00000,1.831149e-08,0.78718,4
300.00699, 923.10000,      1.59599,     71.20211,50.00000,59.00000,1.829268e-08,0.78718,4
300.03699, 926.50000,      1.58850,     71.12337,50.00000,59.00000,1.831180e-08,0.78719,4
300.01501, 929.90000,      1.58621,     71.03537,50.00000,59.00000,1.830887e-08,0.78718,4
300.02701, 933.30000,      1.59133,     70.97811,50.00000,59.00000,1.826973e-08,0.78719,4
300.00699, 936.70000,      1.58783,     70.88526,50.00000,59.00000,1.828389e-08,0.78719,4
300.00800, 940.10000,      1.58783,     70.79705,50.00000,59.00000,1.831335e-08,0.78719,4
300.01700, 943.50000,      1.59437,     70.72568,50.00000,59.00000,1.831290e-08,0.78719,4
300.01999, 946.90000,      1.59112,     70.64463,50.00000,59.00000,1.828967e-08,0.78719,4
300.02100, 950.30000,      1.59153,     70.55179,50.00000,59.00000,1.832983e-08,0.78720,4
300.02200, 953.70000,      1.58990,     70.48042,50.00000,59.00000,1.830493e-08,0.78719,4
300.02701, 957.10000,      1.59031,     70.39453,50.00000,59.00000,1.833245e-08,0.78720,4
300.01300, 960.50000,      1.58743,     70.30884,50.00000,59.00000,1.830414e-08,0.78719,4
300.01401, 963.90000,      1.59029,     70.23032,50.00000,59.00000,1.829081e-08,0.78719,4
300.01300, 967.30000,      1.59498,     70.17305,50.00000,59.00000,1.832271e-08,0.78720,4
300.01599, 970.70000,      1.59009,     70.07074,50.00000,59.00000,1.831537e-08,0.78720,4
300.01001, 974.10000,      1.59334,     69.97074,50.00000,59.00000,1.828912e-08,0.78718,4
300.01300, 977.50000,      1.59375,     69.91347,50.00000,59.00000,1.831426e-08,0.78719,4
300.03201, 980.90000,      1.58930,     69.83495,50.00000,59.00000,1.831576e-08,0.78718,4
300.01300, 984.30000,      1.58784,     69.74189,50.00000,59.00000,1.830034e-08,0.78718,4
300.02200, 987.70000,      1.59561,     69.65389,50.00000,59.00000,1.831704e-08,0.78718,4
300.02301, 991.10000,      1.58949,     69.58232,50.00000,59.00000,1.831151e-08,0.78718,4
300.01401, 994.50000,      1.58784,     69.48947,50.00000,59.00000,1.830773e-08,0.78719,4
300.01401, 997.90000,      1.59355,     69.38232,50.00000,59.00000,1.831430e-08,0.78718,4
300.01300,1001.30000,      1.59335,     69.31811,50.00000,59.00000,1.831664e-08,0.78718,4
300.01599,1004.70000,      1.59539,     69.22505,50.00000,59.00000,1.833351e-08,0.78719,4
300.02200,1008.10000,      1.59398,     69.12505,50.00000,59.00000,1.828549e-08,0.78720,4
299.99899,1011.50000,      1.58700,     69.05368,50.00000,59.00000,1.830073e-08,0.78719,4
300.01300,1014.90000,      1.59314,     68.98211,50.00000,59.00000,1.836083e-08,0.78721,4
300.01199,1018.30000,      1.59314,     68.88926,50.00000,59.00000,1.828563e-08,0.78722,4
300.01401,1021.70000,      1.58988,     68.84653,50.00000,59.00000,1.829261e-08,0.78722,4
300.02399,1025.10000,      1.58949,     68.73684,50.00000,59.00000,1.830375e-08,0.78721,4
300.01901,1028.50000,      1.59213,     68.64400,50.00000,59.00000,1.831451e-08,0.78721,4
300.02100,1031.90000,      1.59499,     68.57263,50.00000,59.00000,1.826140e-08,0.78721,4
300.01001,1035.30000,      1.58804,     68.50821,50.00000,59.00000,1.833678e-08,0.78720,4
300.02499,1038.70000,      1.58929,     68.40821,50.00000,59.00000,1.827375e-08,0.78719,4
300.02100,1042.10000,      1.59193,     68.33684,50.00000,59.00000,1.828731e-08,0.78720,4
300.01401,1045.50000,      1.59335,     68.27958,50.00000,60.00000,1.830487e-08,0.78721,4
300.01999,1048.90000,      1.59173,     68.20105,50.00000,60.00000,1.831661e-08,0.78719,4
300.02499,1052.30000,      1.59541,     68.08674,50.00000,60.00000,1.829621e-08,0.78720,4
300.00201,1055.70000,      1.59149,     68.00800,50.00000,59.00000,1.830468e-08,0.78719,4
300.00900,1059.10000,      1.58844,     67.92947,50.00000,60.00000,1.830465e-08,0.78720,4
300.01001,1062.50000,      1.59069,     67.85095,50.00000,60.00000,1.830969e-08,0.78719,4
300.00800,1065.90000,      1.59089,     67.76505,50.00000,60.00000,1.830542e-08,0.78719,4
300.01501,1069.30000,      1.59294,     67.70084,50.00000,60.00000,1.829502e-08,0.78720,4
300.02200,1072.70000,      1.59030,     67.63411,50.00000,60.00000,1.830182e-08,0.78718,4
300.01099,1076.10000,      1.58804,     67.56989,50.00000,60.00000,1.829247e-08,0.78720,4
300.01199,1079.50000,      1.58906,     67.46968,50.00000,60.00000,1.827919e-08,0.78719,4
300.01401,1082.90000,      1.58886,     67.40547,50.00000,60.00000,1.832931e-08,0.78720,4
300.01901,1086.30000,      1.59315,     67.31263,50.00000,59.00000,1.831876e-08,0.78719,4
300.01300,1089.70000,      1.59253,     67.22674,50.00000,60.00000,1.831956e-08,0.78719,4
300.01099,1093.10000,      1.59008,     67.16253,50.00000,60.00000,1.829031e-08,0.78718,4
300.01099,1096.50000,      1.58926,     67.08400,50.00000,60.00000,1.831361e-08,0.78719,4
300.02301,1099.90000,      1.59153,     67.00526,50.00000,60.00000,1.830118e-08,0.78719,4
300.01599,1103.30000,      1.58662,     66.94105,50.00000,60.00000,1.831958e-08,0.78718,4
300.02301,1106.70000,      1.59377,     66.84821,50.00000,59.00000,1.831553e-08,0.78719,4
300.02100,1110.10000,      1.58908,     66.76232,50.00000,60.00000,1.829833e-08,0.78720,4
300.01300,1113.50000,      1.58763,     66.67663,50.00000,60.00000,1.830976e-08,0.78719,4
300.01401,1116.90000,      1.59049,     66.61958,50.00000,59.00000,1.829467e-08,0.78720,4
300.01401,1120.30000,      1.58621,     66.53368,50.00000,59.00000,1.833177e-08,0.78720,4
300.01001,1123.70000,      1.58946,     66.45516,50.00000,59.00000,1.832725e-08,0.78719,4
300.02499,1127.10000,      1.59031,     66.34800,50.00000,59.00000,1.830904e-08,0.78720,4
300.00900,1130.50000,      1.59212,     66.28358,50.00000,59.00000,1.834599e-08,0.78719,4
300.01501,1133.90000,      1.59111,     66.23368,50.00000,59.00000,1.829442e-08,0.78720,4
300.01300,1137.30000,      1.58906,     66.16926,50.00000,59.00000,1.832199e-08,0.78720,4
300.00500,1140.70000,      1.58843,     66.05263,50.00000,59.00000,1.831347e-08,0.78720,4
300.01099,1144.10000,      1.59028,     65.98842,50.00000,59.00000,1.835506e-08,0.78718,4
300.01801,1147.50000,      1.59111,     65.91684,50.00000,59.00000,1.833662e-08,0.78719,4
300.02701,1150.90000,      1.58909,     65.84547,50.00000,59.00000,1.834007e-08,0.78721,4
300.01501,1154.30000,      1.59029,     65.74547,50.00000,59.00000,1.832441e-08,0.78720,4
300.02399,1157.70000,      1.59031,     65.66442,50.00000,59.00000,1.834469e-08,0.78719,4
300.02899,1161.10000,      1.58930,     65.57874,50.00000,59.00000,1.830859e-08,0.78719,4
300.02600,1164.50000,      1.59256,     65.50253,50.00000,59.00000,1.831340e-08,0.78719,4
300.02200,1167.90000,      1.59438,     65.45958,50.00000,59.00000,1.834356e-08,0.78721,4
300.02100,1171.30000,      1.59193,     65.37389,50.00000,59.00000,1.830950e-08,0.78719,4
300.02100,1174.70000,      1.59173,     65.30232,50.00000,59.00000,1.832501e-08,0.78720,4
300.01801,1178.10000,      1.58907,     65.20947,50.00000,59.00000,1.832055e-08,0.78719,4
300.02301,1181.50000,      1.58969,     65.15937,50.00000,59.00000,1.829608e-08,0.78719,4
300.01401,1184.90000,      1.58723,     65.09032,50.00000,59.00000,1.831517e-08,0.78718,4
300.01999,1188.30000,      1.59050,     65.01179,50.00000,59.00000,1.833225e-08,0.78719,4
300.01401,1191.70000,      1.59070,     64.93326,50.00000,59.00000,1.833042e-08,0.78720,4
300.01001,1195.10000,      1.58865,     64.87600,50.00000,59.00000,1.835294e-08,0.78720,4
300.01501,1198.50000,      1.58988,     64.77600,50.00000,59.00000,1.834438e-08,0.78719,4
300.01700,1201.90000,      1.58866,     64.70463,50.00000,59.00000,1.832892e-08,0.78719,4
300.03601,1205.30000,      1.59033,     64.62589,50.00000,59.00000,1.832398e-08,0.78719,4
300.01999,1208.70000,      1.58887,     64.55937,50.00000,59.00000,1.835749e-08,0.78719,4
300.01300,1212.10000,      1.58559,     64.50211,50.00000,59.00000,1.833359e-08,0.78720,4
300.02600,1215.50000,      1.58705,     64.40926,50.00000,59.00000,1.833798e-08,0.78719,4
300.01099,1218.90000,      1.58437,     64.34968,50.00000,59.00000,1.831603e-08,0.78720,4
300.01401,1222.30000,      1.58376,     64.26400,50.00000,59.00000,1.835942e-08,0.78719,4
300.00900,1225.70000,      1.58681,     64.18526,50.00000,59.00000,1.830913e-08,0.78719,4
300.01700,1229.10000,      1.59070,     64.08758,50.00000,59.00000,1.830269e-08,0.78719,4
300.01801,1232.50000,      1.58907,     64.03053,50.00000,59.00000,1.828576e-08,0.78720,4
300.01099,1235.90000,      1.58926,     63.93053,50.00000,59.00000,1.831719e-08,0.78720,4
300.01199,1239.30000,      1.58702,     63.86863,50.00000,59.00000,1.833263e-08,0.78720,4
300.00699,1242.70000,      1.58436,     63.82568,50.00000,59.00000,1.834621e-08,0.78719,4
300.02200,1246.10000,      1.59092,     63.74000,50.00000,59.00000,1.836015e-08,0.78718,4
300.02600,1249.50000,      1.59276,     63.67558,50.00000,59.00000,1.834440e-08,0.78718,4
300.00699,1252.90000,      1.58619,     63.56842,50.00000,59.00000,1.833008e-08,0.78720,4
300.02301,1256.30000,      1.58990,     63.51137,50.00000,59.00000,1.829659e-08,0.78719,4
300.05301,1257.13500,      1.61505,     63.51137,50.00000,59.00000,1.829887e-08,0.78719,5
300.35001,1257.30500,      1.89914,     63.57326,50.00000,59.00000,1.832816e-08,0.78719,5
301.13699,1257.47500,      2.58026,     63.84232,50.00000,59.00000,1.830142e-08,0.78719,5
302.54599,1257.64500,      3.63364,     64.21621,50.00000,59.00000,1.833253e-08,0.78719,5
304.57700,1257.81500,      4.92117,     64.62126,50.00000,59.00000,1.831508e-08,0.78720,5
307.10800,1257.98500,      6.25844,     64.96884,50.00000,59.00000,1.834232e-08,0.78719,5
310.00400,1258.15500,      7.47739,     65.23811,50.00000,59.00000,1.831782e-08,0.78720,5
313.05600,1258.32500,      8.45398,     65.48568,50.00000,59.00000,1.834488e-08,0.78719,5
316.15900,1258.49500,      9.13642,     65.60716,50.00000,59.00000,1.833341e-08,0.78720,5
319.21799,1258.66500,      9.53981,     65.71916,50.00000,59.00000,1.831591e-08,0.78719,5
322.17499,1258.83500,      9.72017,     65.76442,50.00000,59.00000,1.834212e-08,0.78719,5
325.05399,1259.00500,      9.76591,     65.79537,50.00000,59.00000,1.831432e-08,0.78720,5
327.87000,1259.17500,      9.76417,     65.79537,50.00000,59.00000,1.831053e-08,0.78719,5
330.70001,1259.34500,      9.78848,     65.85263,50.00000,59.00000,1.834994e-08,0.78721,5
333.58701,1259.51500,      9.89364,     65.87874,50.00000,59.00000,1.833657e-08,0.78720,5
336.57599,1259.68500,     10.09287,     65.96926,50.00000,59.00000,1.828134e-08,0.78719,5
339.71899,1259.85500,     10.38457,     66.03116,50.00000,59.00000,1.834970e-08,0.78719,5
342.99200,1260.02500,     10.74539,     66.11937,50.00000,59.00000,1.830224e-08,0.78719,5
346.40601,1260.19500,     11.13353,     66.20737,50.00000,59.00000,1.832774e-08,0.78720,5
349.92899,1260.36500,     11.51628,     66.26463,50.00000,59.00000,1.834560e-08,0.78720,5
353.52802,1260.53500,     11.86356,     66.32168,50.00000,59.00000,1.832852e-08,0.78720,5
357.18600,1260.70500,     12.15955,     66.35032,50.00000,59.00000,1.834730e-08,0.78718,5
360.84601,1260.87500,     12.39011,     66.35032,50.00000,59.00000,1.833187e-08,0.78720,5
364.52499,1261.04500,     12.61007,     66.32884,50.00000,59.00000,1.829087e-08,0.78719,5
368.19901,1261.21500,     12.74685,     66.29326,50.00000,59.00000,1.830924e-08,0.78719,5
371.86301,1261.38500,     12.82615,     66.19789,50.00000,59.00000,1.832229e-08,0.78719,5
375.53900,1261.55500,     12.98444,     66.08358,50.00000,59.00000,1.832423e-08,0.78719,5
379.20001,1261.72500,     13.06131,     65.86442,50.00000,59.00000,1.832673e-08,0.78719,5
382.87701,1261.89500,     13.06767,     65.61684,50.00000,59.00000,1.833202e-08,0.78719,5
386.56299,1262.06500,     13.20254,     65.20716,50.00000,59.00000,1.830378e-08,0.78719,5
390.25900,1262.23500,     13.37285,     64.73074,50.00000,59.00000,1.830758e-08,0.78719,5
393.98801,1262.40500,     13.48680,     64.09011,50.00000,59.00000,1.834925e-08,0.78718,5
397.71399,1262.57500,     13.63259,     63.28737,50.00000,59.00000,1.831862e-08,0.78719,5
401.44400,1262.74500,     13.77316,     62.23221,50.00000,59.00000,1.831088e-08,0.78719,5
405.16699,1262.91500,     13.88206,     60.96042,50.00000,59.00000,1.832988e-08,0.78719,5
408.88501,1263.08500,     14.21744,     59.29326,50.00000,59.00000,1.833850e-08,0.78719,5
412.59900,1263.25500,     12.99857,     57.23053,50.00000,59.00000,1.830992e-08,0.78718,5
416.28101,1263.42500,     14.01029,     54.55116,50.00000,59.00000,1.832857e-08,0.78718,5
419.96399,1263.59500,     14.45885,     51.46905,50.00000,59.00000,1.830405e-08,0.78719,5
423.64001,1263.76500,     15.31860,     47.60589,50.00000,59.00000,1.835098e-08,0.78719,5
427.30200,1263.93500,     14.86612,     43.07579,50.00000,59.00000,1.832315e-08,0.78719,5
430.95401,1264.10500,     16.80763,     37.79768,50.00000,59.00000,1.831554e-08,0.78719,5
434.59900,1264.27500,     15.80507,     32.09579,50.00000,59.00000,1.831725e-08,0.78719,5
438.23001,1264.44500,     17.78460,     26.18653,50.00000,59.00000,1.838753e-08,0.78719,5
441.84799,1264.61500,     18.22189,     20.20126,50.00000,59.00000,1.835612e-08,0.78719,5
445.45599,1264.78500,     18.35228,     14.64695,50.00000,59.00000,1.835181e-08,0.78720,5
449.07001,1264.95500,     17.72134,      9.98337,50.00000,59.00000,1.835669e-08,0.78718,5
452.66901,1265.12500,     17.13988,      6.27747,50.00000,59.00000,1.830666e-08,0.78719,5
456.27701,1265.29500,     16.55148,      3.45263,50.00000,59.00000,1.831365e-08,0.78720,5
459.88699,1265.46500,     16.01821,      1.50905,50.00000,59.00000,1.833335e-08,0.78719,5
463.47900,1265.63500,     15.57106,      0.32063,50.00000,59.00000,1.832178e-08,0.78719,5
467.07199,1265.80500,     15.22467,     -0.39389,50.00000,59.00000,1.828309e-08,0.78719,5
470.65100,1265.97500,     14.96085,     -0.78442,50.00000,59.00000,1.834843e-08,0.78719,5
474.22400,1266.14500,     14.76739,     -1.02274,50.00000,59.00000,1.831360e-08,0.78719,5
477.77701,1266.31500,     14.62523,     -1.17979,50.00000,59.00000,1.831888e-08,0.78719,5
481.31900,1266.48500,     14.52005,     -1.27032,50.00000,59.00000,1.826643e-08,0.78720,5
484.84900,1266.65500,     14.43962,     -1.29895,50.00000,59.00000,1.832787e-08,0.78718,5
488.36801,1266.82500,     14.37938,     -1.29895,50.00000,59.00000,1.832530e-08,0.78720,5
491.88199,1266.99500,     14.33396,     -1.28463,50.00000,59.00000,1.831831e-08,0.78718,5
495.39899,1267.16500,     14.30633,     -1.24884,50.00000,59.00000,1.830961e-08,0.78719,5
498.90500,1267.33500,     14.29041,     -1.22042,50.00000,59.00000,1.837320e-08,0.78720,5
502.38800,1267.50500,     14.27684,     -1.19179,50.00000,59.00000,1.828433e-08,0.78719,5
505.87799,1267.67500,     14.26620,     -1.14884,50.00000,59.00000,1.834052e-08,0.78719,5
509.36301,1267.84500,     14.25858,     -1.10611,50.00000,59.00000,1.833249e-08,0.78719,5
512.82898,1268.01500,     14.25162,     -1.07747,50.00000,59.00000,1.829636e-08,0.78719,5
516.31097,1268.18500,     14.24623,     -1.02021,50.00000,59.00000,1.833947e-08,0.78719,5
519.76703,1268.35500,     14.24303,     -0.99179,50.00000,59.00000,1.829611e-08,0.78720,5
523.22900,1268.52500,     14.24154,     -0.97747,50.00000,59.00000,1.828712e-08,0.78719,5
526.68103,1268.69500,     14.24121,     -0.92021,50.00000,59.00000,1.835692e-08,0.78719,5
530.14099,1268.86500,     14.24019,     -0.89158,50.00000,59.00000,1.830852e-08,0.78719,5
533.58197,1269.03500,     14.24240,     -0.81789,50.00000,59.00000,1.831977e-08,0.78719,5
537.02301,1269.20500,     14.24740,     -0.77263,50.00000,59.00000,1.830344e-08,0.78720,5
540.46899,1269.37500,     14.25252,     -0.71537,50.00000,59.00000,1.828367e-08,0.78719,5
543.90802,1269.54500,     14.25812,     -0.65116,50.00000,59.00000,1.830911e-08,0.78720,5
547.35199,1269.71500,     14.26440,     -0.62968,50.00000,59.00000,1.826134e-08,0.78720,5
550.78101,1269.88500,     14.26765,     -0.57242,50.00000,59.00000,1.829981e-08,0.78719,5
554.22198,1270.05500,     14.27340,     -0.60105,50.00000,59.00000,1.826508e-08,0.78719,5
557.65302,1270.22500,     14.28101,     -0.54400,50.00000,59.00000,1.825818e-08,0.78719,5
561.08502,1270.39500,     14.28499,     -0.53684,50.00000,59.00000,1.831901e-08,0.78718,5
564.50897,1270.56500,     14.28973,     -0.47495,50.00000,59.00000,1.828415e-08,0.78720,5
567.95398,1270.73500,     14.29572,     -0.44632,50.00000,59.00000,1.831538e-08,0.78720,5
571.38000,1270.90500,     14.29770,     -0.41768,50.00000,59.00000,1.829039e-08,0.78718,5
574.81500,1271.07500,     14.29957,     -0.38905,50.00000,59.00000,1.833957e-08,0.78719,5
578.23199,1271.24500,     14.30728,     -0.33200,50.00000,59.00000,1.829312e-08,0.78718,5
581.66602,1271.41500,     14.31185,     -0.30337,50.00000,59.00000,1.829107e-08,0.78719,5
585.08398,1271.58500,     14.31445,     -0.27242,50.00000,59.00000,1.834055e-08,0.78718,5
588.51099,1271.75500,     14.31371,     -0.27242,50.00000,59.00000,1.828956e-08,0.78719,5
591.94501,1271.92500,     14.31340,     -0.21516,50.00000,59.00000,1.832364e-08,0.78718,5
595.36700,1272.09500,     14.30937,     -0.18674,50.00000,59.00000,1.828430e-08,0.78719,5
598.78601,1272.26500,     14.30621,     -0.15811,50.00000,59.00000,1.828792e-08,0.78719,5
602.20300,1272.43500,     14.30304,     -0.10084,50.00000,59.00000,1.831668e-08,0.78718,5
605.62097,1272.60500,     14.29481,-7.957895e-02,50.00000,59.00000,1.828764e-08,0.78719,5
609.04401,1272.77500,     14.28787,-7.242105e-02,50.00000,59.00000,1.829298e-08,0.78718,5
612.46198,1272.94500,     14.27815,-1.515789e-02,50.00000,59.00000,1.832558e-08,0.78718,5
615.87500,1273.11500,     14.26623, 1.347368e-02,50.00000,59.00000,1.826892e-08,0.78718,5
619.29199,1273.28500,     14.25041, 4.189474e-02,50.00000,59.00000,1.830829e-08,0.78719,5
622.71301,1273.45500,     14.23554, 7.052632e-02,50.00000,59.00000,1.827082e-08,0.78718,5
626.13702,1273.62500,     14.21611, 9.915789e-02,50.00000,59.00000,1.827606e-08,0.78718,5
629.55798,1273.79500,     14.20061,      0.12779,50.00000,59.00000,1.831635e-08,0.78719,5
632.96899,1273.96500,     14.18064,      0.18484,50.00000,59.00000,1.828503e-08,0.78720,5
636.39001,1274.13500,     14.15739,      0.18484,50.00000,59.00000,1.828908e-08,0.78719,5
639.79498,1274.30500,     14.13606,      0.21347,50.00000,59.00000,1.829584e-08,0.78719,5
643.20300,1274.47500,     14.10603,      0.24211,50.00000,59.00000,1.832163e-08,0.78718,5
646.61200,1274.64500,     14.07659,      0.27053,50.00000,59.00000,1.827967e-08,0.78718,5
650.03400,1274.81500,     14.04384,      0.32779,50.00000,59.00000,1.832638e-08,0.78719,5
653.44501,1274.98500,     14.00773,      0.35642,50.00000,59.00000,1.827287e-08,0.78719,5
656.85699,1275.15500,     13.97095,      0.35642,50.00000,59.00000,1.829213e-08,0.78719,5
660.26801,1275.32500,     13.93251,      0.41600,50.00000,59.00000,1.832175e-08,0.78720,5
663.67902,1275.49500,     13.88860,      0.41600,50.00000,59.00000,1.830009e-08,0.78719,5
667.09998,1275.66500,     13.83868,      0.44442,50.00000,59.00000,1.826714e-08,0.78720,5
670.51202,1275.83500,     13.78052,      0.50168,50.00000,59.00000,1.829096e-08,0.78721,5
673.91302,1276.00500,     13.72593,      0.50168,50.00000,59.00000,1.830054e-08,0.78720,5
677.33398,1276.17500,     13.66634,      0.53032,50.00000,59.00000,1.826802e-08,0.78720,5
680.74200,1276.34500,     13.60516,      0.55874,50.00000,59.00000,1.825394e-08,0.78719,5
684.16998,1276.51500,     13.53925,      0.55874,50.00000,59.00000,1.827256e-08,0.78719,5
687.58801,1276.68500,     13.46785,      0.61600,50.00000,59.00000,1.831810e-08,0.78719,5
690.99500,1276.85500,     13.39256,      0.61600,50.00000,59.00000,1.831123e-08,0.78719,5
694.42603,1277.02500,     13.31150,      0.64463,50.00000,59.00000,1.829345e-08,0.78719,5
697.84003,1277.19500,     13.22872,      0.67305,50.00000,59.00000,1.832218e-08,0.78719,5
701.25598,1277.36500,     13.14381,      0.70168,50.00000,59.00000,1.825192e-08,0.78719,5
704.67401,1277.53500,     13.04747,      0.70884,50.00000,59.00000,1.830040e-08,0.78719,5
708.09900,1277.70500,     12.95197,      0.75895,50.00000,59.00000,1.832058e-08,0.78719,5
711.51398,1277.87500,     12.85148,      0.78737,50.00000,59.00000,1.828542e-08,0.78720,5
714.93701,1278.04500,     12.74047,      0.81600,50.00000,59.00000,1.827819e-08,0.78719,5
718.36401,1278.21500,     12.63191,      0.84463,50.00000,59.00000,1.831706e-08,0.78718,5
721.77399,1278.38500,     12.51449,      0.84463,50.00000,59.00000,1.826474e-08,0.78718,5
725.19397,1278.55500,     12.39521,      0.90189,50.00000,59.00000,1.827931e-08,0.78719,5
728.61700,1278.72500,     12.27534,      0.93032,50.00000,59.00000,1.829136e-08,0.78719,5
732.02600,1278.89500,     12.14791,      0.95895,50.00000,59.00000,1.828041e-08,0.78719,5
735.45599,1279.06500,     12.02040,      1.01853,50.00000,59.00000,1.827902e-08,0.78718,5
738.88702,1279.23500,     11.88372,      1.00421,50.00000,59.00000,1.825071e-08,0.78718,5
742.29401,1279.40500,     11.74611,      1.06147,50.00000,59.00000,1.827397e-08,0.78718,5
745.70599,1279.57500,     11.60446,      1.08989,50.00000,59.00000,1.827410e-08,0.78718,5
749.12402,1279.74500,     11.46667,      1.08989,50.00000,59.00000,1.831008e-08,0.78719,5
752.54999,1279.91500,     11.32936,      1.14716,50.00000,59.00000,1.828782e-08,0.78719,5
755.96802,1280.08500,     11.18996,      1.14716,50.00000,59.00000,1.827079e-08,0.78717,5
759.38300,1280.25500,     11.04711,      1.20421,50.00000,59.00000,1.828750e-08,0.78718,5
762.80298,1280.42500,     10.90682,      1.22568,50.00000,59.00000,1.831550e-08,0.78718,5
766.22498,1280.59500,     10.76279,      1.26147,50.00000,59.00000,1.822197e-08,0.78717,5
769.65002,1280.76500,     10.61887,      1.29011,50.00000,59.00000,1.827197e-08,0.78718,5
773.06500,1280.93500,     10.47917,      1.29011,50.00000,59.00000,1.824714e-08,0.78718,5
776.47998,1281.10500,     10.33961,      1.35200,50.00000,59.00000,1.827006e-08,0.78718,5
779.91101,1281.27500,     10.19928,      1.35200,50.00000,59.00000,1.824008e-08,0.78718,5
783.32202,1281.44500,     10.06211,      1.38295,50.00000,59.00000,1.826417e-08,0.78719,5
786.74103,1281.61500,      9.93127,      1.41621,50.00000,59.00000,1.827104e-08,0.78719,5
790.16400,1281.78500,      9.79926,      1.44484,50.00000,59.00000,            ,0.44883,5
793.58398,1281.95500,      9.66853,      1.44484,50.00000,59.00000,            ,0.44746,5
794.47803,1282.00000,      9.63570,      1.47347,50.00000,59.00000,            ,0.44710,5