File: data/TGA/005d-L_M/ExpDat_2025_03_10_SL_005F_J1_dynamic.csv
#EXPORTTYPE:                 ,DATA ALL
#FILE:                       ,2025_03_10_SL_005F_J1_dynamic.ngb-ss5
#FORMAT:                     ,NETZSCH5
#FTYPE:                      ,ASCII
#IDENTITY:                   ,2025_03_10_SL_005F_J1
#DECIMAL:                    ,POINT
#SEPARATOR:                  ,COMMA
#MTYPE:                      ,DSC
#INSTRUMENT:                 ,NETZSCH STA 449F5
#PROJECT:                    ,PS
#DATE/TIME:                  ,3/10/2025 11:24:03 AM (UTC-4)
#CORR. FILE:                 ,
#TEMPCAL:                    ,13-11-2024 10:37
#SENSITIVITY:                ,28-06-2023 13:53
#LABORATORY:                 ,Tran/Aspuru
#OPERATOR:                   ,Stanley
#REMARK:                     ,
#SAMPLE:                     ,2025_03_10_SL_005F_J1
#SAMPLE MASS /mg:            ,5.05
#MATERIAL:                   ,
#REFERENCE:                  ,
#REFERENCE MASS /mg:         ,0
#TYPE OF CRUCIBLE:           ,Al2O3 85 ‘l, open
#SAMPLE CRUCIBLE MASS /mg:   ,0
#REFERENCE CRUCIBLE MASS /mg:,0
#DSC RANGE /‘V:              ,5000
#TG RANGE /mg:               ,35000
#TAU-R:                      ,---
#CORR. CODE:                 ,000
#EXO:                        ,-1
#RANGE:                      ,20›C....800›C/0.0....20.0K/min
#SEGMENT:                    ,S1-4/4
#SEG. 1:                     ,20›C/5.0(K/min)/100›C
#SEG. 2:                     ,100›C/00:05/100›C
#SEG. 3:                     ,100›C/1.0(K/min)/400›C
#SEG. 4:                     ,400›C/20.0(K/min)/800›C

##Temp./›C,Time/min,DSC/(mW/mg),Mass/%,Gas Flow(purge2)/(ml/min),Gas Flow(protective)/(ml/min),TIC(scan:1)/A,Sensit./(uV/mW),Segment
 31.91300,  0.00000, 3.270435e-02,100.00000,50.00000,48.00000,            ,0.92390,1
 32.52600,  1.06667, 4.954148e-02, 99.84535,50.00000,48.00000,2.037659e-10,0.92393,1
 33.26600,  2.13333, 5.770896e-02, 99.40178,50.00000,48.00000,1.970958e-10,0.92398,1
 34.07900,  3.20000, 8.336372e-02, 99.27861,50.00000,48.00000,1.969680e-10,0.92403,1
 35.62600,  4.26667,      0.21898, 99.59446,50.00000,48.00000,1.971569e-10,0.92408,1
 38.25000,  5.33333,      0.41998,100.09644,50.00000,48.00000,1.975765e-10,0.92413,1
 41.97200,  6.40000,      0.63105,100.71683,50.00000,48.00000,1.967830e-10,0.92417,1
 46.65300,  7.46667,      0.83067,101.30158,50.00000,48.00000,1.966438e-10,0.92423,1
 52.14700,  8.53333,      1.00135,101.84158,50.00000,48.00000,1.979332e-10,0.92430,1
 58.24600,  9.60000,      1.13479,102.20673,50.00000,48.00000,1.973057e-10,0.92438,1
 64.68400, 10.66667,      1.23541,102.53149,50.00000,48.00000,1.973476e-10,0.92451,1
 71.28200, 11.73333,      1.30332,102.74653,50.00000,48.00000,1.977425e-10,0.92466,1
 77.90600, 12.80000,      1.34114,102.88990,50.00000,48.00000,1.964301e-10,0.92481,1
 84.45800, 13.86667,      1.35634,103.02218,50.00000,48.00000,1.973648e-10,0.92499,1
 90.93200, 14.93333,      1.34705,103.09604,50.00000,48.00000,1.970711e-10,0.92516,1
 97.10800, 15.98417,      1.31897,103.14990,50.00000,48.00000,1.970921e-10,0.92533,2
101.27100, 16.78417,      1.13910,102.83624,50.00000,48.00000,1.978549e-10,0.92547,2
103.98400, 17.58417,      0.75621,102.21347,50.00000,48.00000,1.977234e-10,0.92561,2
105.82900, 18.38417,      0.47763,101.75188,50.00000,48.00000,1.976604e-10,0.92574,2
107.08000, 19.18417,      0.29734,101.33960,50.00000,48.00000,1.979637e-10,0.92585,2
107.81500, 19.98417,      0.12643,100.96337,50.00000,48.00000,1.976718e-10,0.92596,2
108.01400, 20.78417,-2.827961e-02,100.60040,50.00000,48.00000,1.974011e-10,0.92605,2
107.81200, 21.80083,     -0.14665,100.18594,50.00000,48.00000,1.973839e-10,0.92613,3
107.56800, 22.86750,     -0.16045, 99.91703,50.00000,48.00000,1.983872e-10,0.92618,3
107.32100, 23.93417,     -0.16191, 99.82970,50.00000,48.00000,1.982422e-10,0.92620,3
107.13400, 25.00083,     -0.14415, 99.67525,50.00000,48.00000,1.979466e-10,0.92617,3
107.13800, 26.06750,     -0.10290, 99.62812,50.00000,48.00000,1.987152e-10,0.92611,3
107.30400, 27.13417,-5.868350e-02, 99.56772,50.00000,48.00000,1.977329e-10,0.92600,3
107.68000, 28.20083,-1.430271e-02, 99.52059,50.00000,48.00000,1.976489e-10,0.92583,3
108.22900, 29.26750, 2.680169e-02, 99.49366,50.00000,48.00000,1.983585e-10,0.92565,3
108.93100, 30.33417, 6.167423e-02, 99.49366,50.00000,48.00000,1.981773e-10,0.92538,3
109.77100, 31.40083, 9.278340e-02, 99.48693,50.00000,48.00000,1.983166e-10,0.92512,3
110.73200, 32.46750,      0.11667, 99.46020,50.00000,48.00000,1.976433e-10,0.92476,3
111.72600, 33.53417,      0.13268, 99.43089,50.00000,48.00000,1.979046e-10,0.92435,3
112.81000, 34.60083,      0.14459, 99.41762,50.00000,48.00000,1.983509e-10,0.92397,3
113.89100, 35.66750,      0.15321, 99.38396,50.00000,48.00000,1.979256e-10,0.92348,3
115.04200, 36.73417,      0.15690, 99.37050,50.00000,48.00000,1.986466e-10,0.92303,3
116.15700, 37.80083,      0.15680, 99.34356,50.00000,48.00000,1.977539e-10,0.92247,3
117.28400, 38.86750,      0.15802, 99.32337,50.00000,48.00000,1.981926e-10,0.92196,3
118.40700, 39.93417,      0.15594, 99.31683,50.00000,48.00000,1.984234e-10,0.92145,3
119.54300, 41.00083,      0.15204, 99.29663,50.00000,48.00000,1.971626e-10,0.92106,3
120.65500, 42.06750,      0.14732, 99.30099,50.00000,48.00000,1.980877e-10,0.92066,3
121.75000, 43.13417,      0.14358, 99.23386,50.00000,48.00000,1.987286e-10,0.92036,3
122.84100, 44.20083,      0.14067, 99.26079,50.00000,48.00000,1.993142e-10,0.92007,3
123.92900, 45.26750,      0.13842, 99.23604,50.00000,48.00000,1.982669e-10,0.91986,3
125.02000, 46.33417,      0.13501, 99.23604,50.00000,48.00000,1.987267e-10,0.91964,3
126.09000, 47.40083,      0.13126, 99.26297,50.00000,48.00000,1.976604e-10,0.91944,3
127.16500, 48.46750,      0.12784, 99.23604,50.00000,48.00000,1.987247e-10,0.91930,3
128.23100, 49.53417,      0.12476, 99.23604,50.00000,49.00000,1.982212e-10,0.91915,3
129.31000, 50.60083,      0.12216, 99.24495,50.00000,49.00000,1.991577e-10,0.91905,3
130.35100, 51.66750,      0.11940, 99.27188,50.00000,49.00000,1.983356e-10,0.91897,3
131.42700, 52.73417,      0.11747, 99.26515,50.00000,49.00000,1.986676e-10,0.91891,3
132.50500, 53.80083,      0.11504, 99.27861,50.00000,49.00000,1.986771e-10,0.91888,3
133.56100, 54.86750,      0.11127, 99.28535,50.00000,49.00000,1.980858e-10,0.91887,3
134.64000, 55.93417,      0.10784, 99.31228,50.00000,49.00000,1.991577e-10,0.91888,3
135.69501, 57.00083,      0.10440, 99.33921,50.00000,49.00000,1.987934e-10,0.91891,3
136.74800, 58.06750,      0.10130, 99.34139,50.00000,49.00000,1.984081e-10,0.91894,3
137.81700, 59.13417,      0.10035, 99.34356,50.00000,49.00000,1.988926e-10,0.91897,3
138.90500, 60.20083, 9.657500e-02, 99.39960,50.00000,49.00000,1.983756e-10,0.91900,3
139.96500, 61.26750, 9.312786e-02, 99.37267,50.00000,49.00000,1.986504e-10,0.91903,3
141.02600, 62.33417, 9.067776e-02, 99.41980,50.00000,49.00000,1.988945e-10,0.91906,3
142.10800, 63.40083, 8.572481e-02, 99.43327,50.00000,49.00000,1.993026e-10,0.91909,3
143.16000, 64.46750, 8.293491e-02, 99.45347,50.00000,49.00000,1.993713e-10,0.91911,3
144.23399, 65.53417, 7.947549e-02, 99.48693,50.00000,49.00000,1.990108e-10,0.91912,3
145.29900, 66.60083, 7.517697e-02, 99.50040,50.00000,49.00000,1.991025e-10,0.91913,3
146.36800, 67.66750, 7.304716e-02, 99.52733,50.00000,49.00000,1.985359e-10,0.91913,3
147.43401, 68.73417, 6.874094e-02, 99.54752,50.00000,49.00000,1.988469e-10,0.91911,3
148.52100, 69.80083, 6.576967e-02, 99.56772,50.00000,49.00000,1.990738e-10,0.91910,3
149.59000, 70.86750, 6.145498e-02, 99.59446,50.00000,49.00000,1.984844e-10,0.91907,3
150.65100, 71.93417, 5.696770e-02, 99.62139,50.00000,49.00000,1.987343e-10,0.91903,3
151.72000, 73.00083, 5.348152e-02, 99.66178,50.00000,49.00000,1.989632e-10,0.91898,3
152.79100, 74.06750, 5.015923e-02, 99.66614,50.00000,49.00000,1.991119e-10,0.91892,3
153.85001, 75.13417, 4.481848e-02, 99.68634,50.00000,49.00000,1.989823e-10,0.91886,3
154.91701, 76.20083, 4.182309e-02, 99.71327,50.00000,49.00000,1.982021e-10,0.91878,3
156.00101, 77.26750, 3.731193e-02, 99.76931,50.00000,49.00000,1.984749e-10,0.91870,3
157.05600, 78.33417, 3.111284e-02, 99.76931,50.00000,49.00000,1.991177e-10,0.91861,3
158.12900, 79.40083, 2.658921e-02, 99.80950,50.00000,49.00000,1.987153e-10,0.91853,3
159.20000, 80.46750, 2.340700e-02, 99.84990,50.00000,49.00000,1.991405e-10,0.91842,3
160.27699, 81.53417, 1.971532e-02, 99.86337,50.00000,49.00000,1.984291e-10,0.91831,3
161.32401, 82.60083, 1.315207e-02, 99.87683,50.00000,49.00000,1.988449e-10,0.91819,3
162.39500, 83.66750, 8.942640e-03, 99.91703,50.00000,49.00000,1.985875e-10,0.91808,3
163.46300, 84.73417, 2.870326e-03, 99.91703,50.00000,49.00000,1.988048e-10,0.91795,3
164.53900, 85.80083,-2.196457e-03, 99.97089,50.00000,49.00000,1.989002e-10,0.91783,3
165.62000, 86.86750,-7.439321e-03, 99.99782,50.00000,49.00000,1.985969e-10,0.91768,3
166.66499, 87.93417,-1.404276e-02,100.02475,50.00000,49.00000,1.991501e-10,0.91756,3
167.74001, 89.00083,-1.896256e-02,100.05149,50.00000,49.00000,1.993103e-10,0.91741,3
168.80200, 90.06750,-2.473634e-02,100.06277,50.00000,49.00000,1.990547e-10,0.91728,3
169.85001, 91.13417,-3.238307e-02,100.08297,50.00000,49.00000,1.982822e-10,0.91713,3
170.93500, 92.20083,-3.563028e-02,100.10970,50.00000,49.00000,1.987171e-10,0.91696,3
172.01100, 93.26750,-3.973116e-02,100.13228,50.00000,49.00000,1.995697e-10,0.91683,3
173.06700, 94.33417,-4.791554e-02,100.15901,50.00000,49.00000,1.994266e-10,0.91667,3
174.12900, 95.40083,-5.305155e-02,100.18812,50.00000,49.00000,1.996670e-10,0.91653,3
175.18600, 96.46750,-6.108790e-02,100.17485,50.00000,49.00000,1.984367e-10,0.91637,3
176.24800, 97.53417,-6.402798e-02,100.25545,50.00000,49.00000,1.991119e-10,0.91622,3
177.32100, 98.60083,-6.714369e-02,100.25762,50.00000,49.00000,1.990185e-10,0.91605,3
178.38300, 99.66750,-7.606239e-02,100.27109,50.00000,49.00000,1.988334e-10,0.91591,3
179.45000,100.73417,-8.260582e-02,100.29129,50.00000,49.00000,1.992702e-10,0.91574,3
180.52200,101.80083,-8.693953e-02,100.31149,50.00000,49.00000,1.995735e-10,0.91559,3
181.59399,102.86750,-9.589569e-02,100.34495,50.00000,49.00000,1.990624e-10,0.91542,3
182.65800,103.93417,     -0.10093,100.35168,50.00000,49.00000,1.989707e-10,0.91527,3
183.72701,105.00083,     -0.10734,100.40099,50.00000,49.00000,1.989059e-10,0.91509,3
184.79100,106.06750,     -0.11514,100.36733,50.00000,49.00000,1.995544e-10,0.91495,3
185.86099,107.13417,     -0.12123,100.41446,50.00000,49.00000,1.993427e-10,0.91478,3
186.92599,108.20083,     -0.12854,100.40990,50.00000,49.00000,1.998005e-10,0.91463,3
187.99200,109.26750,     -0.13637,100.47505,50.00000,49.00000,1.999588e-10,0.91445,3
189.05600,110.33417,     -0.14250,100.43465,50.00000,49.00000,1.996918e-10,0.91430,3
190.13800,111.40083,     -0.15070,100.46158,50.00000,49.00000,1.995353e-10,0.91413,3
191.19701,112.46750,     -0.15702,100.49505,50.00000,49.00000,1.998787e-10,0.91398,3
192.26401,113.53417,     -0.16473,100.50851,50.00000,49.00000,1.998997e-10,0.91380,3
193.32500,114.60083,     -0.17142,100.54891,50.00000,49.00000,2.001019e-10,0.91365,3
194.39200,115.66750,     -0.17847,100.52871,50.00000,49.00000,1.994686e-10,0.91347,3
195.47099,116.73417,     -0.18450,100.57584,50.00000,49.00000,2.001056e-10,0.91331,3
196.53900,117.80083,     -0.19122,100.58693,50.00000,49.00000,2.004947e-10,0.91313,3
197.59900,118.86750,     -0.19883,100.59822,50.00000,49.00000,1.994343e-10,0.91298,3
198.67101,119.93417,     -0.20852,100.59822,50.00000,49.00000,1.991042e-10,0.91280,3
199.73300,121.00083,     -0.21234,100.61168,50.00000,49.00000,2.003956e-10,0.91264,3
200.80000,122.06750,     -0.22086,100.60713,50.00000,50.00000,1.996212e-10,0.91245,3
201.87000,123.13417,     -0.22782,100.69010,50.00000,50.00000,1.993446e-10,0.91230,3
202.93500,124.20083,     -0.23845,100.60931,50.00000,50.00000,2.002601e-10,0.91211,3
203.98500,125.26750,     -0.24614,100.63624,50.00000,49.00000,1.998271e-10,0.91195,3
205.05901,126.33417,     -0.25541,100.66535,50.00000,50.00000,1.993503e-10,0.91177,3
206.12100,127.40083,     -0.26174,100.66535,50.00000,50.00000,1.998271e-10,0.91160,3
207.18300,128.46750,     -0.27122,100.65861,50.00000,50.00000,2.008610e-10,0.91141,3
208.25301,129.53417,     -0.27758,100.68554,50.00000,50.00000,2.002487e-10,0.91125,3
209.31599,130.60083,     -0.28429,100.71465,50.00000,50.00000,1.995430e-10,0.91106,3
210.38800,131.66750,     -0.29312,100.68772,50.00000,50.00000,1.998691e-10,0.91090,3
211.46400,132.73417,     -0.30145,100.68772,50.00000,50.00000,1.992188e-10,0.91071,3
212.51900,133.80083,     -0.31119,100.71465,50.00000,50.00000,1.995811e-10,0.91054,3
213.59200,134.86750,     -0.31744,100.71465,50.00000,50.00000,1.997375e-10,0.91034,3
214.67500,135.93417,     -0.32828,100.71465,50.00000,50.00000,1.995011e-10,0.91015,3
215.72099,137.00083,     -0.33772,100.68772,50.00000,50.00000,2.006073e-10,0.90998,3
216.79401,138.06750,     -0.34490,100.71465,50.00000,50.00000,1.998901e-10,0.90978,3
217.86900,139.13417,     -0.35421,100.72139,50.00000,50.00000,2.002124e-10,0.90961,3
218.93300,140.20083,     -0.36283,100.70574,50.00000,50.00000,1.992969e-10,0.90941,3
219.99800,141.26750,     -0.37376,100.68554,50.00000,50.00000,1.997815e-10,0.90924,3
221.05499,142.33417,     -0.38206,100.71248,50.00000,50.00000,1.997165e-10,0.90904,3
222.12399,143.40083,     -0.39039,100.71248,50.00000,50.00000,2.000408e-10,0.90886,3
223.18900,144.46750,     -0.39855,100.71248,50.00000,50.00000,2.002124e-10,0.90866,3
224.25999,145.53417,     -0.40922,100.71248,50.00000,50.00000,1.997185e-10,0.90849,3
225.32100,146.60083,     -0.41742,100.70574,50.00000,50.00000,2.001724e-10,0.90829,3
226.38699,147.66750,     -0.42581,100.67881,50.00000,50.00000,1.999302e-10,0.90811,3
227.46100,148.73417,     -0.43636,100.67208,50.00000,50.00000,2.001858e-10,0.90790,3
228.52499,149.80083,     -0.44676,100.70574,50.00000,50.00000,2.002258e-10,0.90772,3
229.59200,150.86750,     -0.45539,100.66535,50.00000,50.00000,2.000198e-10,0.90751,3
230.65300,151.93417,     -0.46671,100.72812,50.00000,50.00000,1.999855e-10,0.90732,3
231.70700,153.00083,     -0.47628,100.67426,50.00000,50.00000,1.991291e-10,0.90711,3
232.78500,154.06750,     -0.48551,100.68099,50.00000,50.00000,1.997165e-10,0.90693,3
233.85201,155.13417,     -0.49745,100.66099,50.00000,50.00000,1.999093e-10,0.90672,3
234.90500,156.20083,     -0.50725,100.64752,50.00000,50.00000,2.004299e-10,0.90653,3
235.96700,157.26750,     -0.51547,100.64079,50.00000,50.00000,2.005081e-10,0.90631,3
237.04601,158.33417,     -0.52605,100.64297,50.00000,50.00000,2.002468e-10,0.90613,3
238.10400,159.40083,     -0.53700,100.67208,50.00000,50.00000,2.000141e-10,0.90592,3
239.17900,160.46750,     -0.54691,100.63168,50.00000,50.00000,2.003745e-10,0.90573,3
240.23700,161.53417,     -0.55736,100.63168,50.00000,50.00000,2.002124e-10,0.90552,3
241.30800,162.60083,     -0.56785,100.62515,50.00000,50.00000,2.002716e-10,0.90532,3
242.37199,163.66750,     -0.57891,100.62950,50.00000,50.00000,1.996326e-10,0.90510,3
243.43201,164.73417,     -0.59088,100.60713,50.00000,50.00000,2.007904e-10,0.90491,3
244.50600,165.80083,     -0.60072,100.58257,50.00000,50.00000,2.000542e-10,0.90468,3
245.57300,166.86750,     -0.61041,100.56911,50.00000,50.00000,2.002430e-10,0.90446,3
246.65100,167.93417,     -0.61976,100.57347,50.00000,50.00000,2.002163e-10,0.90427,3
247.73000,169.00083,     -0.63348,100.54000,50.00000,50.00000,2.003021e-10,0.90404,3
248.80099,170.06750,     -0.64596,100.53327,50.00000,50.00000,2.004852e-10,0.90384,3
249.85201,171.13417,     -0.65772,100.53327,50.00000,50.00000,2.001038e-10,0.90361,3
250.92500,172.20083,     -0.66826,100.48396,50.00000,50.00000,2.003002e-10,0.90341,3
251.97900,173.26750,     -0.68081,100.49069,50.00000,50.00000,2.005577e-10,0.90318,3
253.04401,174.33417,     -0.69067,100.45030,50.00000,50.00000,2.004680e-10,0.90299,3
254.10300,175.40083,     -0.70182,100.43010,50.00000,50.00000,2.007008e-10,0.90275,3
255.17200,176.46750,     -0.71429,100.40337,50.00000,50.00000,2.005253e-10,0.90255,3
256.26001,177.53417,     -0.72533,100.38990,50.00000,50.00000,2.004489e-10,0.90232,3
257.31699,178.60083,     -0.73693,100.35624,50.00000,50.00000,2.002220e-10,0.90211,3
258.37500,179.66750,     -0.75204,100.31584,50.00000,50.00000,1.997032e-10,0.90188,3
259.43799,180.73417,     -0.76132,100.30238,50.00000,50.00000,2.002124e-10,0.90167,3
260.51001,181.80083,     -0.77357,100.24871,50.00000,50.00000,2.007046e-10,0.90143,3
261.57001,182.86750,     -0.78785,100.19485,50.00000,50.00000,2.002811e-10,0.90120,3
262.64001,183.93417,     -0.79667,100.16812,50.00000,50.00000,2.006912e-10,0.90099,3
263.70099,185.00083,     -0.81083,100.14119,50.00000,50.00000,2.004395e-10,0.90075,3
264.76199,186.06750,     -0.82301,100.06059,50.00000,50.00000,2.006969e-10,0.90054,3
265.83200,187.13417,     -0.83393,100.01347,50.00000,50.00000,2.007999e-10,0.90029,3
266.89401,188.20083,     -0.84579, 99.93287,50.00000,50.00000,2.001170e-10,0.90009,3
267.96399,189.26750,     -0.85806, 99.85663,50.00000,50.00000,2.010441e-10,0.89985,3
269.03101,190.33417,     -0.87147, 99.82752,50.00000,50.00000,2.008381e-10,0.89963,3
270.10400,191.40083,     -0.88214, 99.76475,50.00000,50.00000,1.998825e-10,0.89937,3
271.17499,192.46750,     -0.89395, 99.68416,50.00000,50.00000,2.006969e-10,0.89917,3
272.23199,193.53417,     -0.90744, 99.61030,50.00000,50.00000,2.007179e-10,0.89892,3
273.30600,194.60083,     -0.91969, 99.48475,50.00000,50.00000,2.003155e-10,0.89870,3
274.36600,195.66750,     -0.93065, 99.40416,50.00000,50.00000,2.004165e-10,0.89846,3
275.44000,196.73417,     -0.94407, 99.30772,50.00000,50.00000,2.012882e-10,0.89825,3
276.50500,197.80083,     -0.95640, 99.20020,50.00000,50.00000,2.000561e-10,0.89799,3
277.57700,198.86750,     -0.96970, 99.10614,50.00000,50.00000,2.012138e-10,0.89777,3
278.64001,199.93417,     -0.98265, 98.96733,50.00000,50.00000,2.010956e-10,0.89752,3
279.70599,201.00083,     -0.99676, 98.83960,50.00000,50.00000,2.008037e-10,0.89731,3
280.76999,202.06750,     -1.01035, 98.69842,50.00000,50.00000,2.006760e-10,0.89705,3
281.81900,203.13417,     -1.02226, 98.55723,50.00000,50.00000,2.004108e-10,0.89683,3
282.89301,204.20083,     -1.03667, 98.41624,50.00000,50.00000,2.003288e-10,0.89656,3
283.96100,205.26750,     -1.04980, 98.28851,50.00000,50.00000,2.007046e-10,0.89635,3
285.03299,206.33417,     -1.06240, 98.12713,50.00000,50.00000,2.010937e-10,0.89609,3
286.08801,207.40083,     -1.07369, 97.95248,50.00000,50.00000,2.014618e-10,0.89587,3
287.16901,208.46750,     -1.08731, 97.80455,50.00000,50.00000,2.001820e-10,0.89561,3
288.22601,209.53417,     -1.10018, 97.64317,50.00000,50.00000,2.006435e-10,0.89538,3
289.29099,210.60083,     -1.11347, 97.45505,50.00000,50.00000,2.003555e-10,0.89512,3
290.35199,211.66750,     -1.13173, 97.28040,50.00000,50.00000,2.016831e-10,0.89489,3
291.42899,212.73417,     -1.14397, 97.07644,50.00000,50.00000,2.008000e-10,0.89463,3
292.48999,213.80083,     -1.15832, 96.86812,50.00000,50.00000,1.998654e-10,0.89440,3
293.56201,214.86750,     -1.17386, 96.68000,50.00000,50.00000,2.008228e-10,0.89414,3
294.61401,215.93417,     -1.18541, 96.51406,50.00000,50.00000,2.006168e-10,0.89390,3
295.67099,217.00083,     -1.20120, 96.29901,50.00000,50.00000,2.008323e-10,0.89363,3
296.73901,218.06750,     -1.21360, 96.06832,50.00000,50.00000,2.005730e-10,0.89341,3
297.80301,219.13417,     -1.23063, 95.85109,50.00000,50.00000,2.004051e-10,0.89314,3
298.87500,220.20083,     -1.24273, 95.63366,50.00000,50.00000,2.006741e-10,0.89287,3
299.94601,221.26750,     -1.25370, 95.43881,50.00000,50.00000,2.011089e-10,0.89263,3
301.01401,222.33417,     -1.27239, 95.16772,50.00000,50.00000,1.998024e-10,0.89236,3
302.08401,223.40083,     -1.28498, 94.92812,50.00000,50.00000,2.016506e-10,0.89213,3
303.15500,224.46750,     -1.30087, 94.69960,50.00000,50.00000,2.014923e-10,0.89186,3
304.22501,225.53417,     -1.31507, 94.48000,50.00000,50.00000,2.008400e-10,0.89162,3
305.28500,226.60083,     -1.33200, 94.19545,50.00000,50.00000,2.007332e-10,0.89134,3
306.35501,227.66750,     -1.34280, 93.95584,50.00000,50.00000,2.007541e-10,0.89111,3
307.40601,228.73417,     -1.35863, 93.64653,50.00000,50.00000,2.013073e-10,0.89084,3
308.49100,229.80083,     -1.37417, 93.39802,50.00000,50.00000,2.004967e-10,0.89059,3
309.54300,230.86750,     -1.39184, 93.16040,50.00000,51.00000,2.010155e-10,0.89032,3
310.60501,231.93417,     -1.40587, 92.82673,50.00000,50.00000,2.015114e-10,0.89007,3
311.68399,233.00083,     -1.41803, 92.51525,50.00000,51.00000,2.012653e-10,0.88978,3
312.74799,234.06750,     -1.43370, 92.19485,50.00000,51.00000,2.007885e-10,0.88955,3
313.83200,235.13417,     -1.45218, 91.88356,50.00000,51.00000,2.005119e-10,0.88927,3
314.90201,236.20083,     -1.46717, 91.56752,50.00000,51.00000,2.015553e-10,0.88902,3
315.96500,237.26750,     -1.48140, 91.18238,50.00000,51.00000,2.015171e-10,0.88874,3
317.03601,238.33417,     -1.49843, 90.85960,50.00000,51.00000,2.007809e-10,0.88850,3
318.09100,239.40083,     -1.51783, 90.46990,50.00000,51.00000,2.011433e-10,0.88821,3
319.15500,240.46750,     -1.53023, 90.09347,50.00000,51.00000,2.011756e-10,0.88797,3
320.22400,241.53417,     -1.54778, 89.73723,50.00000,51.00000,2.001858e-10,0.88768,3
321.27899,242.60083,     -1.56260, 89.32515,50.00000,51.00000,2.008228e-10,0.88744,3
322.36099,243.66750,     -1.57672, 88.91960,50.00000,51.00000,2.017994e-10,0.88715,3
323.43201,244.73417,     -1.59363, 88.46040,50.00000,51.00000,2.016754e-10,0.88690,3
324.47800,245.80083,     -1.60914, 87.99881,50.00000,51.00000,2.012501e-10,0.88661,3
325.56201,246.86750,     -1.62498, 87.56416,50.00000,51.00000,2.015648e-10,0.88636,3
326.61099,247.93417,     -1.64217, 87.07584,50.00000,51.00000,2.020264e-10,0.88606,3
327.68301,249.00083,     -1.65687, 86.55604,50.00000,51.00000,2.015648e-10,0.88581,3
328.75800,250.06750,     -1.67123, 86.06099,50.00000,51.00000,2.015076e-10,0.88552,3
329.83301,251.13417,     -1.68880, 85.49426,50.00000,51.00000,2.013339e-10,0.88527,3
330.88699,252.20083,     -1.70918, 84.95663,50.00000,51.00000,2.011871e-10,0.88497,3
331.94501,253.26750,     -1.72422, 84.39644,50.00000,51.00000,2.017384e-10,0.88467,3
333.01599,254.33417,     -1.73854, 83.78713,50.00000,51.00000,2.014695e-10,0.88441,3
334.08600,255.40083,     -1.75910, 83.17564,50.00000,51.00000,2.009010e-10,0.88412,3
335.14401,256.46750,     -1.77327, 82.51683,50.00000,51.00000,2.016773e-10,0.88385,3
336.21201,257.53417,     -1.78992, 81.87624,50.00000,51.00000,2.006302e-10,0.88356,3
337.28900,258.60083,     -1.80261, 81.17267,50.00000,51.00000,2.013816e-10,0.88331,3
338.36499,259.66750,     -1.82338, 80.44911,50.00000,51.00000,2.009506e-10,0.88300,3
339.41299,260.73417,     -1.84112, 79.71426,50.00000,51.00000,2.014046e-10,0.88274,3
340.48499,261.80083,     -1.85998, 78.96376,50.00000,51.00000,2.020721e-10,0.88244,3
341.56201,262.86750,     -1.87870, 78.18653,50.00000,51.00000,2.012863e-10,0.88218,3
342.62601,263.93417,     -1.89582, 77.36436,50.00000,51.00000,2.018471e-10,0.88188,3
343.68500,265.00083,     -1.91641, 76.53762,50.00000,51.00000,2.019463e-10,0.88162,3
344.75101,266.06750,     -1.93262, 75.67069,50.00000,51.00000,2.014599e-10,0.88130,3
345.82101,267.13417,     -1.95112, 74.78574,50.00000,51.00000,2.020435e-10,0.88104,3
346.90601,268.20083,     -1.97133, 73.89624,50.00000,51.00000,2.015800e-10,0.88074,3
347.96701,269.26750,     -1.99154, 72.92851,50.00000,51.00000,2.020760e-10,0.88047,3
349.03299,270.33417,     -2.01059, 71.98099,50.00000,51.00000,2.019100e-10,0.88016,3
350.07800,271.40083,     -2.02740, 70.97723,50.00000,51.00000,2.021732e-10,0.87991,3
351.15799,272.46750,     -2.04597, 70.00040,50.00000,51.00000,2.016677e-10,0.87959,3
352.22198,273.53417,     -2.06702, 68.98792,50.00000,51.00000,2.018832e-10,0.87932,3
353.29099,274.60083,     -2.08711, 67.91921,50.00000,51.00000,2.016048e-10,0.87900,3
354.34299,275.66750,     -2.10577, 66.86851,50.00000,51.00000,2.020435e-10,0.87874,3
355.41400,276.73417,     -2.12659, 65.77307,50.00000,51.00000,2.020111e-10,0.87843,3
356.47699,277.80083,     -2.14724, 64.71802,50.00000,51.00000,2.018833e-10,0.87811,3
357.55099,278.86750,     -2.16632, 63.56871,50.00000,51.00000,2.023811e-10,0.87784,3
358.60999,279.93417,     -2.19223, 62.41723,50.00000,51.00000,2.018051e-10,0.87752,3
359.66400,281.00083,     -2.21572, 61.29030,50.00000,51.00000,2.017116e-10,0.87725,3
360.72900,282.06750,     -2.23495, 60.15446,50.00000,51.00000,2.014465e-10,0.87694,3
361.80899,283.13417,     -2.25739, 58.98733,50.00000,51.00000,2.018242e-10,0.87667,3
362.87799,284.20083,     -2.27696, 57.84693,50.00000,51.00000,2.019787e-10,0.87635,3
363.92401,285.26750,     -2.30108, 56.61941,50.00000,51.00000,2.023983e-10,0.87608,3
365.01099,286.33417,     -2.32039, 55.38713,50.00000,51.00000,2.018508e-10,0.87576,3
366.07800,287.40083,     -2.34533, 54.16396,50.00000,51.00000,2.021923e-10,0.87543,3
367.14099,288.46750,     -2.36657, 52.95881,50.00000,51.00000,2.019463e-10,0.87516,3
368.19000,289.53417,     -2.39513, 51.69069,50.00000,51.00000,2.020054e-10,0.87483,3
369.26999,290.60083,     -2.41236, 50.44515,50.00000,51.00000,2.010250e-10,0.87455,3
370.32700,291.66750,     -2.43879, 49.17723,50.00000,51.00000,2.018222e-10,0.87422,3
371.40100,292.73417,     -2.45925, 47.93386,50.00000,51.00000,2.019558e-10,0.87395,3
372.47501,293.80083,     -2.48103, 46.60297,50.00000,51.00000,2.022076e-10,0.87363,3
373.53799,294.86750,     -2.50958, 45.27228,50.00000,51.00000,2.017898e-10,0.87335,3
374.59399,295.93417,     -2.53691, 43.95505,50.00000,51.00000,2.025032e-10,0.87302,3
375.67700,297.00083,     -2.55660, 42.62436,50.00000,51.00000,2.023563e-10,0.87273,3
376.74899,298.06750,     -2.58666, 41.28455,50.00000,51.00000,2.029495e-10,0.87241,3
377.79300,299.13417,     -2.61015, 39.92475,50.00000,51.00000,2.031174e-10,0.87213,3
378.87100,300.20083,     -2.63530, 38.57842,50.00000,51.00000,2.028541e-10,0.87180,3
379.93701,301.26750,     -2.66536, 37.22970,50.00000,51.00000,2.022934e-10,0.87152,3
381.01001,302.33417,     -2.69298, 35.87663,50.00000,51.00000,2.026481e-10,0.87118,3
382.06100,303.40083,     -2.72017, 34.59069,50.00000,51.00000,2.023030e-10,0.87090,3
383.14200,304.46750,     -2.74584, 33.22871,50.00000,51.00000,2.021313e-10,0.87056,3
384.20401,305.53417,     -2.77770, 31.95842,50.00000,51.00000,2.025680e-10,0.87027,3
385.26700,306.60083,     -2.80901, 30.64772,50.00000,51.00000,2.021503e-10,0.86994,3
386.32101,307.66750,     -2.83480, 29.36871,50.00000,51.00000,2.026291e-10,0.86965,3
387.39899,308.73417,     -2.86698, 28.07604,50.00000,52.00000,2.025833e-10,0.86932,3
388.47101,309.80083,     -2.89449, 26.81703,50.00000,52.00000,2.028084e-10,0.86904,3
389.54599,310.86750,     -2.92747, 25.61386,50.00000,52.00000,2.022057e-10,0.86870,3
390.60501,311.93417,     -2.95811, 24.41089,50.00000,52.00000,2.026024e-10,0.86841,3
391.66599,313.00083,     -2.98927, 23.21465,50.00000,52.00000,2.025948e-10,0.86807,3
392.73700,314.06750,     -3.02141, 22.12139,50.00000,52.00000,2.030296e-10,0.86779,3
393.80099,315.13417,     -3.05319, 21.01248,50.00000,52.00000,2.028427e-10,0.86744,3
394.87299,316.20083,     -3.08725, 19.90574,50.00000,52.00000,2.024040e-10,0.86715,3
395.94101,317.26750,     -3.11944, 18.91782,50.00000,52.00000,2.028084e-10,0.86681,3
397.00299,318.33417,     -3.15103, 17.86257,50.00000,52.00000,2.022400e-10,0.86653,3
398.05899,319.40083,     -3.18552, 16.89703,50.00000,52.00000,2.034303e-10,0.86618,3
399.13599,320.46750,     -3.21800, 15.94040,50.00000,52.00000,2.025528e-10,0.86588,3
399.64600,320.97917,     -3.23569, 15.50812,50.00000,52.00000,2.029171e-10,0.86569,4
399.76901,321.05917,     -3.23142, 15.42970,50.00000,52.00000,2.029171e-10,0.86569,4
400.00900,321.13917,     -3.13953, 15.40277,50.00000,52.00000,2.030716e-10,0.86564,4
400.38501,321.21917,     -2.94032, 15.37366,50.00000,52.00000,2.030716e-10,0.86564,4
400.91800,321.29917,     -2.62485, 15.37366,50.00000,52.00000,2.026672e-10,0.86560,4
401.63599,321.37917,     -2.20544, 15.38713,50.00000,52.00000,2.026672e-10,0.86560,4
402.52399,321.45917,     -1.69261, 15.42970,50.00000,52.00000,2.028389e-10,0.86555,4
403.58401,321.53917,     -1.12051, 15.45644,50.00000,52.00000,2.028389e-10,0.86555,4
404.78400,321.61917,     -0.50913, 15.51248,50.00000,52.00000,2.029572e-10,0.86550,4
406.13101,321.69917,      0.11129, 15.52594,50.00000,52.00000,2.029572e-10,0.86550,4
407.58499,321.77917,      0.71246, 15.56634,50.00000,52.00000,2.035637e-10,0.86545,4
409.13699,321.85917,      1.27619, 15.59307,50.00000,52.00000,2.035637e-10,0.86545,4
410.68900,321.93917,      1.77831, 15.59307,50.00000,52.00000,2.027092e-10,0.86540,4
412.28101,322.01917,      2.20614, 15.59307,50.00000,52.00000,2.027092e-10,0.86540,4
413.89099,322.09917,      2.55207, 15.56634,50.00000,52.00000,2.027092e-10,0.86540,4
415.49701,322.17917,      2.81729, 15.50574,50.00000,52.00000,2.026730e-10,0.86536,4
417.06100,322.25917,      2.99999, 15.40495,50.00000,52.00000,2.026730e-10,0.86536,4
418.59900,322.33917,      3.10438, 15.34455,50.00000,52.00000,2.032966e-10,0.86530,4
420.09000,322.41917,      3.14558, 15.24139,50.00000,52.00000,2.032966e-10,0.86530,4
421.55200,322.49917,      3.13268, 15.13842,50.00000,52.00000,2.023697e-10,0.86525,4
422.97699,322.57917,      3.07299, 15.00614,50.00000,52.00000,2.023697e-10,0.86525,4
424.35001,322.65917,      2.98513, 14.87624,50.00000,52.00000,2.023507e-10,0.86520,4
425.71799,322.73917,      2.88111, 14.72614,50.00000,52.00000,2.023507e-10,0.86520,4
427.04599,322.81917,      2.77270, 14.57386,50.00000,52.00000,2.021389e-10,0.86515,4
428.36600,322.89917,      2.66658, 14.41030,50.00000,52.00000,2.021389e-10,0.86515,4
429.67999,322.97917,      2.57163, 14.23327,50.00000,52.00000,2.034626e-10,0.86510,4
431.01199,323.05917,      2.49982, 14.09663,50.00000,52.00000,2.034626e-10,0.86510,4
432.34900,323.13917,      2.44736, 13.91960,50.00000,52.00000,2.031479e-10,0.86506,4
433.69699,323.21917,      2.42030, 13.76059,50.00000,52.00000,2.031479e-10,0.86506,4
435.08301,323.29917,      2.41886, 13.59485,50.00000,52.00000,2.034416e-10,0.86501,4
436.47699,323.37917,      2.44194, 13.40000,50.00000,52.00000,2.034416e-10,0.86501,4
437.92300,323.45917,      2.48915, 13.23406,50.00000,52.00000,2.025776e-10,0.86495,4
439.39099,323.53917,      2.55386, 13.08396,50.00000,52.00000,2.025776e-10,0.86495,4
440.88599,323.61917,      2.63249, 12.88475,50.00000,52.00000,2.032508e-10,0.86490,4
442.41000,323.69917,      2.71962, 12.69208,50.00000,52.00000,2.032508e-10,0.86490,4
443.95401,323.77917,      2.81342, 12.49267,50.00000,52.00000,2.033386e-10,0.86485,4
445.53201,323.85917,      2.91328, 12.28436,50.00000,52.00000,2.033386e-10,0.86485,4
447.12299,323.93917,      3.00640, 12.10277,50.00000,52.00000,2.038612e-10,0.86480,4
448.73199,324.01917,      3.09322, 11.90792,50.00000,52.00000,2.038612e-10,0.86480,4
450.35101,324.09917,      3.17227, 11.69743,50.00000,52.00000,2.025318e-10,0.86474,4
451.99100,324.17917,      3.24425, 11.45307,50.00000,52.00000,2.025318e-10,0.86474,4
453.63000,324.25917,      3.30245, 11.25822,50.00000,52.00000,2.031021e-10,0.86471,4
455.27399,324.33917,      3.34822, 10.98713,50.00000,52.00000,2.031021e-10,0.86471,4
456.92401,324.41917,      3.37890, 10.72950,50.00000,52.00000,2.029285e-10,0.86465,4
458.57300,324.49917,      3.40000, 10.52574,50.00000,52.00000,2.029285e-10,0.86465,4
460.25101,324.57917,      3.41043, 10.29485,50.00000,52.00000,2.028580e-10,0.86461,4
461.86301,324.65917,      3.40802, 10.06634,50.00000,52.00000,2.028580e-10,0.86461,4
463.49899,324.73917,      3.39453,  9.84238,50.00000,52.00000,2.037430e-10,0.86456,4
465.14200,324.81917,      3.37431,  9.63624,50.00000,52.00000,2.037430e-10,0.86456,4
466.78500,324.89917,      3.35232,  9.38752,50.00000,52.00000,2.029686e-10,0.86451,4
468.42099,324.97917,      3.32372,  9.17248,50.00000,52.00000,2.029686e-10,0.86451,4
470.06799,325.05917,      3.29334,  8.98891,50.00000,52.00000,2.030106e-10,0.86446,4
471.70599,325.13917,      3.25917,  8.79624,50.00000,52.00000,2.030106e-10,0.86446,4
473.35400,325.21917,      3.22582,  8.64158,50.00000,52.00000,2.032375e-10,0.86441,4
474.99899,325.29917,      3.18893,  8.46455,50.00000,52.00000,2.032375e-10,0.86441,4
476.65302,325.37917,      3.15575,  8.34812,50.00000,52.00000,2.025032e-10,0.86436,4
478.31100,325.45917,      3.12169,  8.17347,50.00000,52.00000,2.025032e-10,0.86436,4
479.95700,325.53917,      3.08377,  8.09723,50.00000,52.00000,2.025032e-10,0.86436,4
481.61700,325.61917,      3.05253,  7.97168,50.00000,52.00000,2.032623e-10,0.86431,4
483.28299,325.69917,      3.01359,  7.92475,50.00000,52.00000,2.032623e-10,0.86431,4
484.95401,325.77917,      2.97864,  7.86871,50.00000,52.00000,2.032490e-10,0.86426,4
486.62399,325.85917,      2.93812,  7.81485,50.00000,52.00000,2.032490e-10,0.86426,4
488.29199,325.93917,      2.90426,  7.78812,50.00000,52.00000,2.023621e-10,0.86421,4
489.96500,326.01917,      2.87024,  7.76792,50.00000,52.00000,2.023621e-10,0.86421,4
491.64301,326.09917,      2.83731,  7.76792,50.00000,52.00000,2.035828e-10,0.86416,4
493.32101,326.17917,      2.80026,  7.76792,50.00000,52.00000,2.035828e-10,0.86416,4
494.99899,326.25917,      2.76797,  7.76792,50.00000,52.00000,2.031955e-10,0.86411,4
496.67801,326.33917,      2.73180,  7.76792,50.00000,52.00000,2.031955e-10,0.86411,4
498.36401,326.41917,      2.69697,  7.79485,50.00000,52.00000,2.028064e-10,0.86406,4
500.04199,326.49917,      2.66143,  7.79485,50.00000,52.00000,2.028064e-10,0.86406,4
501.72299,326.57917,      2.62199,  7.79485,50.00000,52.00000,2.029190e-10,0.86401,4
503.39499,326.65917,      2.58182,  7.79485,50.00000,52.00000,2.029190e-10,0.86401,4
505.07700,326.73917,      2.54475,  7.79485,50.00000,52.00000,2.032852e-10,0.86395,4
506.75000,326.81917,      2.50345,  7.79485,50.00000,52.00000,2.032852e-10,0.86395,4
508.42599,326.89917,      2.45969,  7.82158,50.00000,52.00000,2.033729e-10,0.86391,4
510.10400,326.97917,      2.41043,  7.82158,50.00000,52.00000,2.033729e-10,0.86391,4
511.77301,327.05917,      2.36546,  7.82158,50.00000,52.00000,2.036591e-10,0.86388,4
513.44800,327.13917,      2.32182,  7.82158,50.00000,52.00000,2.036591e-10,0.86388,4
515.11499,327.21917,      2.27643,  7.84851,50.00000,52.00000,2.029457e-10,0.86381,4
516.78900,327.29917,      2.23161,  7.84851,50.00000,52.00000,2.029457e-10,0.86381,4
518.46399,327.37917,      2.18505,  7.84851,50.00000,52.00000,2.031250e-10,0.86377,4
520.13202,327.45917,      2.13571,  7.84851,50.00000,52.00000,2.031250e-10,0.86377,4
521.79901,327.53917,      2.08920,  7.87545,50.00000,52.00000,2.034035e-10,0.86371,4
523.46698,327.61917,      2.04120,  7.87545,50.00000,52.00000,2.034035e-10,0.86371,4
525.12097,327.69917,      1.99270,  7.90238,50.00000,52.00000,2.025108e-10,0.86367,4
526.79797,327.77917,      1.94712,  7.87545,50.00000,52.00000,2.025108e-10,0.86367,4
528.48602,327.85917,      1.89878,  7.90238,50.00000,52.00000,2.031784e-10,0.86362,4
530.12500,327.93917,      1.85062,  7.90238,50.00000,52.00000,2.031784e-10,0.86362,4
531.78699,328.01917,      1.80619,  7.90238,50.00000,52.00000,2.030849e-10,0.86356,4
533.45398,328.09917,      1.75352,  7.92238,50.00000,52.00000,2.030849e-10,0.86356,4
535.11298,328.17917,      1.70711,  7.92238,50.00000,52.00000,2.039433e-10,0.86352,4
536.77002,328.25917,      1.66101,  7.92238,50.00000,52.00000,2.039433e-10,0.86352,4
538.42499,328.33917,      1.61209,  7.92911,50.00000,52.00000,2.026385e-10,0.86346,4
540.09399,328.41917,      1.56220,  7.95604,50.00000,52.00000,2.026385e-10,0.86346,4
541.75201,328.49917,      1.51128,  7.95604,50.00000,52.00000,2.031173e-10,0.86343,4
543.41302,328.57917,      1.46857,  7.98297,50.00000,52.00000,2.031173e-10,0.86343,4
545.07001,328.65917,      1.42118,  7.98297,50.00000,52.00000,2.036228e-10,0.86337,4
546.72803,328.73917,      1.36937,  8.00990,50.00000,52.00000,2.036228e-10,0.86337,4
548.37598,328.81917,      1.31970,  7.98297,50.00000,52.00000,2.036228e-10,0.86337,4
550.04303,328.89917,      1.26959,  8.00990,50.00000,52.00000,2.030811e-10,0.86331,4
551.69702,328.97917,      1.21898,  8.00990,50.00000,52.00000,2.030811e-10,0.86331,4
553.34802,329.05917,      1.17028,  8.05683,50.00000,52.00000,2.031040e-10,0.86326,4
555.00500,329.13917,      1.12032,  8.09050,50.00000,52.00000,2.031040e-10,0.86326,4
556.65997,329.21917,      1.07122,  8.09050,50.00000,52.00000,2.034206e-10,0.86322,4
558.30798,329.29917,      1.01923,  8.09050,50.00000,52.00000,2.034206e-10,0.86322,4
559.94800,329.37917,      0.96729,  8.11743,50.00000,52.00000,2.025662e-10,0.86317,4
561.60199,329.45917,      0.91838,  8.14416,50.00000,52.00000,2.025662e-10,0.86317,4
563.24799,329.53917,      0.86387,  8.14416,50.00000,52.00000,2.028637e-10,0.86312,4
564.90002,329.61917,      0.80943,  8.17347,50.00000,52.00000,2.028637e-10,0.86312,4
566.54498,329.69917,      0.75773,  8.17347,50.00000,52.00000,2.030926e-10,0.86307,4
568.19202,329.77917,      0.70555,  8.20020,50.00000,52.00000,2.030926e-10,0.86307,4
569.83502,329.85917,      0.65561,  8.22713,50.00000,52.00000,2.028617e-10,0.86301,4
571.48499,329.93917,      0.60385,  8.22713,50.00000,52.00000,2.028617e-10,0.86301,4
573.13098,330.01917,      0.56005,  8.22713,50.00000,52.00000,2.031002e-10,0.86297,4
574.77899,330.09917,      0.50489,  8.25406,50.00000,52.00000,2.031002e-10,0.86297,4
576.41803,330.17917,      0.45116,  8.25406,50.00000,52.00000,2.032508e-10,0.86292,4
578.06403,330.25917,      0.40434,  8.28099,50.00000,52.00000,2.032508e-10,0.86292,4
579.71100,330.33917,      0.35158,  8.28099,50.00000,52.00000,2.023677e-10,0.86287,4
581.35901,330.41917,      0.29890,  8.30772,50.00000,52.00000,2.023677e-10,0.86287,4
582.98297,330.49917,      0.24600,  8.33465,50.00000,52.00000,2.034073e-10,0.86282,4
584.62701,330.57917,      0.19347,  8.33465,50.00000,52.00000,2.034073e-10,0.86282,4
586.26599,330.65917,      0.13963,  8.36158,50.00000,52.00000,2.032699e-10,0.86276,4
587.91101,330.73917, 8.476654e-02,  8.36158,50.00000,52.00000,2.032699e-10,0.86276,4
589.54901,330.81917, 3.829825e-02,  8.39287,50.00000,52.00000,2.027417e-10,0.86272,4
591.18103,330.89917,-1.807194e-02,  8.39287,50.00000,52.00000,2.027417e-10,0.86272,4
592.82898,330.97917,-7.102784e-02,  8.39287,50.00000,52.00000,2.023983e-10,0.86267,4
594.46002,331.05917,     -0.12306,  8.41980,50.00000,52.00000,2.023983e-10,0.86267,4
596.09497,331.13917,     -0.17472,  8.44673,50.00000,52.00000,2.030296e-10,0.86262,4
597.73602,331.21917,     -0.23021,  8.47366,50.00000,52.00000,2.030296e-10,0.86262,4
599.36902,331.29917,     -0.28505,  8.47366,50.00000,52.00000,2.029895e-10,0.86257,4
601.01001,331.37917,     -0.33784,  8.47366,50.00000,52.00000,2.029895e-10,0.86257,4
602.64398,331.45917,     -0.39166,  8.47366,50.00000,52.00000,2.035732e-10,0.86252,4
604.27197,331.53917,     -0.44567,  8.50040,50.00000,52.00000,2.035732e-10,0.86252,4
605.90002,331.61917,     -0.50156,  8.52733,50.00000,52.00000,2.032795e-10,0.86247,4
607.53601,331.69917,     -0.55510,  8.55426,50.00000,52.00000,2.032795e-10,0.86247,4
609.17200,331.77917,     -0.61081,  8.55426,50.00000,52.00000,2.034073e-10,0.86242,4
610.80298,331.85917,     -0.66131,  8.58119,50.00000,52.00000,2.034073e-10,0.86242,4
612.42999,331.93917,     -0.70999,  8.58119,50.00000,52.00000,2.032890e-10,0.86237,4
614.06201,332.01917,     -0.76511,  8.60792,50.00000,52.00000,2.032890e-10,0.86237,4
615.68597,332.09917,     -0.81812,  8.62812,50.00000,52.00000,2.025356e-10,0.86233,4
617.33002,332.17917,     -0.87104,  8.62812,50.00000,52.00000,2.025356e-10,0.86233,4
618.96399,332.25917,     -0.92041,  8.62812,50.00000,52.00000,2.023830e-10,0.86226,4
620.58502,332.33917,     -0.97423,  8.63485,50.00000,52.00000,2.023830e-10,0.86226,4
622.22498,332.41917,     -1.02537,  8.66396,50.00000,52.00000,2.030544e-10,0.86222,4
623.83801,332.49917,     -1.07348,  8.69089,50.00000,52.00000,2.030544e-10,0.86222,4
625.47900,332.57917,     -1.12611,  8.69089,50.00000,52.00000,2.039604e-10,0.86217,4
627.10303,332.65917,     -1.18091,  8.71782,50.00000,52.00000,2.039604e-10,0.86217,4
628.73401,332.73917,     -1.23010,  8.74455,50.00000,52.00000,2.041875e-10,0.86212,4
630.35999,332.81917,     -1.28844,  8.74455,50.00000,52.00000,2.041875e-10,0.86212,4
631.99298,332.89917,     -1.34610,  8.76475,50.00000,52.00000,2.029209e-10,0.86207,4
633.60797,332.97917,     -1.40509,  8.77149,50.00000,52.00000,2.029209e-10,0.86207,4
635.23102,333.05917,     -1.45523,  8.79842,50.00000,52.00000,2.033558e-10,0.86203,4
636.85699,333.13917,     -1.50758,  8.79842,50.00000,52.00000,2.033558e-10,0.86203,4
638.48700,333.21917,     -1.56654,  8.82535,50.00000,52.00000,2.031688e-10,0.86197,4
640.10797,333.29917,     -1.61775,  8.82535,50.00000,52.00000,2.031688e-10,0.86197,4
641.72498,333.37917,     -1.67469,  8.82535,50.00000,52.00000,2.032528e-10,0.86192,4
643.35400,333.45917,     -1.72800,  8.85228,50.00000,52.00000,2.032528e-10,0.86192,4
644.97900,333.53917,     -1.79178,  8.87901,50.00000,52.00000,2.036171e-10,0.86187,4
646.60101,333.61917,     -1.84690,  8.90594,50.00000,52.00000,2.036171e-10,0.86187,4
648.21600,333.69917,     -1.89951,  8.90594,50.00000,52.00000,2.036171e-10,0.86187,4
649.84302,333.77917,     -1.95230,  8.90594,50.00000,52.00000,2.031441e-10,0.86182,4
651.46198,333.85917,     -2.00435,  8.90594,50.00000,52.00000,2.031441e-10,0.86182,4
653.08698,333.93917,     -2.05775,  8.93287,50.00000,52.00000,2.032204e-10,0.86177,4
654.71301,334.01917,     -2.11161,  8.95980,50.00000,52.00000,2.032204e-10,0.86177,4
656.33197,334.09917,     -2.17156,  8.95980,50.00000,52.00000,2.031670e-10,0.86172,4
657.94702,334.17917,     -2.22692,  8.98653,50.00000,52.00000,2.031670e-10,0.86172,4
659.57202,334.25917,     -2.27857,  8.99327,50.00000,52.00000,2.033425e-10,0.86166,4
661.18799,334.33917,     -2.33334,  8.99327,50.00000,52.00000,2.033425e-10,0.86166,4
662.80402,334.41917,     -2.39217,  9.01347,50.00000,52.00000,2.034302e-10,0.86161,4
664.41699,334.49917,     -2.45626,  9.04040,50.00000,52.00000,2.034302e-10,0.86161,4
666.04303,334.57917,     -2.50735,  9.04040,50.00000,52.00000,2.032566e-10,0.86156,4
667.65802,334.65917,     -2.57029,  9.06733,50.00000,52.00000,2.032566e-10,0.86156,4
669.27600,334.73917,     -2.62256,  9.06733,50.00000,52.00000,2.030220e-10,0.86152,4
670.89697,334.81917,     -2.68043,  9.08733,50.00000,52.00000,2.030220e-10,0.86152,4
672.52100,334.89917,     -2.74180,  9.09406,50.00000,52.00000,2.034416e-10,0.86146,4
674.13599,334.97917,     -2.79998,  9.09406,50.00000,52.00000,2.034416e-10,0.86146,4
675.75500,335.05917,     -2.85379,  9.12099,50.00000,52.00000,2.031536e-10,0.86141,4
677.39203,335.13917,     -2.90628,  9.14792,50.00000,52.00000,2.031536e-10,0.86141,4
678.97900,335.21917,     -2.97003,  9.14792,50.00000,52.00000,2.040901e-10,0.86136,4
680.60199,335.29917,     -3.02674,  9.16139,50.00000,52.00000,2.040901e-10,0.86136,4
682.21899,335.37917,     -3.08177,  9.20158,50.00000,52.00000,2.030639e-10,0.86131,4
683.84198,335.45917,     -3.16111,  9.20158,50.00000,52.00000,2.030639e-10,0.86131,4
685.46002,335.53917,     -3.21771,  9.18158,50.00000,52.00000,2.031841e-10,0.86125,4
687.07300,335.61917,     -3.27719,  9.20832,50.00000,52.00000,2.031841e-10,0.86125,4
688.69897,335.69917,     -3.33566,  9.22851,50.00000,52.00000,2.033233e-10,0.86121,4
690.31201,335.77917,     -3.39240,  9.25545,50.00000,52.00000,2.033233e-10,0.86121,4
691.94202,335.85917,     -3.44872,  9.26218,50.00000,52.00000,2.036114e-10,0.86116,4
693.55298,335.93917,     -3.51687,  9.26218,50.00000,52.00000,2.036114e-10,0.86116,4
695.17902,336.01917,     -3.58247,  9.28911,50.00000,52.00000,2.031441e-10,0.86111,4
696.79401,336.09917,     -3.64635,  9.28911,50.00000,52.00000,2.031441e-10,0.86111,4
698.41101,336.17917,     -3.70886,  9.28911,50.00000,52.00000,2.029342e-10,0.86105,4
700.03198,336.25917,     -3.77404,  9.31584,50.00000,52.00000,2.029342e-10,0.86105,4
701.64099,336.33917,     -3.84371,  9.33604,50.00000,52.00000,2.031956e-10,0.86101,4
703.26398,336.41917,     -3.91673,  9.33604,50.00000,52.00000,2.031956e-10,0.86101,4
704.87799,336.49917,     -3.97650,  9.33604,50.00000,52.00000,2.028142e-10,0.86096,4
706.49597,336.57917,     -4.03801,  9.34277,50.00000,52.00000,2.028142e-10,0.86096,4
708.10999,336.65917,     -4.09779,  9.36970,50.00000,52.00000,2.026940e-10,0.86090,4
709.73700,336.73917,     -4.16248,  9.36970,50.00000,52.00000,2.026940e-10,0.86090,4
711.35999,336.81917,     -4.22795,  9.40099,50.00000,52.00000,2.030258e-10,0.86086,4
712.97601,336.89917,     -4.28760,  9.42792,50.00000,52.00000,2.030258e-10,0.86086,4
714.59698,336.97917,     -4.34995,  9.42792,50.00000,52.00000,2.032127e-10,0.86081,4
716.21503,337.05917,     -4.40992,  9.45485,50.00000,52.00000,2.032127e-10,0.86081,4
717.83002,337.13917,     -4.47857,  9.45485,50.00000,52.00000,2.024917e-10,0.86074,4
719.45398,337.21917,     -4.54300,  9.48178,50.00000,52.00000,2.024917e-10,0.86074,4
721.05902,337.29917,     -4.61228,  9.48178,50.00000,52.00000,2.028828e-10,0.86070,4
722.67401,337.37917,     -4.67702,  9.50851,50.00000,52.00000,2.028828e-10,0.86070,4
724.28497,337.45917,     -4.73938,  9.50851,50.00000,52.00000,2.029629e-10,0.86066,4
725.91302,337.53917,     -4.80801,  9.51525,50.00000,52.00000,2.029629e-10,0.86066,4
727.51801,337.61917,     -4.87450,  9.53545,50.00000,52.00000,2.026768e-10,0.86059,4
729.12903,337.69917,     -4.95522,  9.53545,50.00000,52.00000,2.026768e-10,0.86059,4
730.74500,337.77917,     -5.01989,  9.56238,50.00000,52.00000,2.029838e-10,0.86056,4
732.36499,337.85917,     -5.08251,  9.63188,50.00000,52.00000,2.029838e-10,0.86056,4
733.96899,337.93917,     -5.14714,  9.63188,50.00000,52.00000,2.031995e-10,0.86051,4
735.59198,338.01917,     -5.20786,  9.63188,50.00000,52.00000,2.031995e-10,0.86051,4
737.21002,338.09917,     -5.27289,  9.63188,50.00000,52.00000,2.032909e-10,0.86045,4
738.82800,338.17917,     -5.33456,  9.65861,50.00000,52.00000,2.032909e-10,0.86045,4
740.45801,338.25917,     -5.40095,  9.65861,50.00000,52.00000,2.032509e-10,0.86041,4
742.07300,338.33917,     -5.46293,  9.65861,50.00000,52.00000,2.032509e-10,0.86041,4
743.68298,338.41917,     -5.52085,  9.65861,50.00000,52.00000,2.032509e-10,0.86041,4
745.29999,338.49917,     -5.58833,  9.67881,50.00000,52.00000,2.033215e-10,0.86035,4
746.92401,338.57917,     -5.65181,  9.68554,50.00000,52.00000,2.033215e-10,0.86035,4
748.53699,338.65917,     -5.71800,  9.68554,50.00000,52.00000,2.038383e-10,0.86030,4
750.15503,338.73917,     -5.79186,  9.71248,50.00000,52.00000,2.038383e-10,0.86030,4
751.76202,338.81917,     -5.85643,  9.73941,50.00000,52.00000,2.037735e-10,0.86025,4
753.39099,338.89917,     -5.92357,  9.76614,50.00000,52.00000,2.037735e-10,0.86025,4
755.00500,338.97917,     -5.98819,  9.76614,50.00000,52.00000,2.030373e-10,0.86020,4
756.62097,339.05917,     -6.05103,  9.76614,50.00000,52.00000,2.030373e-10,0.86020,4
758.23700,339.13917,     -6.11175,  9.79307,50.00000,52.00000,2.028275e-10,0.86014,4
759.85699,339.21917,     -6.17790,  9.79307,50.00000,52.00000,2.028275e-10,0.86014,4
761.47400,339.29917,     -6.23600,  9.82000,50.00000,52.00000,2.027263e-10,0.86010,4
763.09601,339.37917,     -6.30316,  9.84911,50.00000,52.00000,2.027263e-10,0.86010,4
764.71997,339.45917,     -6.36162,  9.87604,50.00000,52.00000,2.036838e-10,0.86005,4
766.33502,339.53917,     -6.42842,  9.87604,50.00000,52.00000,2.036838e-10,0.86005,4
767.94299,339.61917,     -6.50296,  9.89624,50.00000,52.00000,2.030487e-10,0.86000,4
769.57501,339.69917,     -6.56362,  9.92970,50.00000,52.00000,2.030487e-10,0.86000,4
771.17499,339.77917,     -6.63816,  9.92970,50.00000,52.00000,2.034416e-10,0.85995,4
772.78802,339.85917,     -6.71829,  9.94317,50.00000,52.00000,2.034416e-10,0.85995,4
774.40302,339.93917,     -6.78736,  9.95663,50.00000,52.00000,2.031422e-10,0.85990,4
776.01501,340.01917,     -6.85926,  9.95663,50.00000,52.00000,2.031422e-10,0.85990,4
777.62500,340.09917,     -6.91470,  9.99703,50.00000,52.00000,2.035217e-10,0.85985,4
779.23602,340.17917,     -6.97529,  9.98356,50.00000,52.00000,2.035217e-10,0.85985,4
780.84399,340.25917,     -7.04872, 10.01485,50.00000,52.00000,2.041073e-10,0.85980,4
782.45099,340.33917,     -7.10830, 10.02832,50.00000,52.00000,2.041073e-10,0.85980,4
784.06201,340.41917,     -7.17109, 10.03505,50.00000,52.00000,2.033215e-10,0.85975,4
785.67401,340.49917,     -7.23942, 10.06871,50.00000,52.00000,2.033215e-10,0.85975,4
787.28003,340.57917,     -7.30152, 10.06871,50.00000,52.00000,2.029190e-10,0.85969,4
788.88397,340.65917,     -7.36310, 10.09545,50.00000,52.00000,            ,0.44935,4
790.50598,340.73917,     -7.42566, 10.09545,50.00000,52.00000,            ,0.44870,4
792.10999,340.81917,     -7.48624, 10.11564,50.00000,52.00000,            ,0.44805,4
793.72601,340.89917,     -7.55383, 10.15149,50.00000,52.00000,            ,0.44740,4
794.42999,340.93417,     -7.58496, 10.15149,50.00000,52.00000,            ,0.44712,4