File: data/TGA/005d-L_M/ExpDat_2025_07_17_SL_PS_Tosoh_F10_dynamic.csv
#EXPORTTYPE:                 ,DATA ALL
#FILE:                       ,2025_07_17_SL_PS_Tosoh_F10_dynamic.ngb-ss5
#FORMAT:                     ,NETZSCH5
#FTYPE:                      ,ASCII
#IDENTITY:                   ,PS-Tosoh-F10
#DECIMAL:                    ,POINT
#SEPARATOR:                  ,COMMA
#MTYPE:                      ,DSC
#INSTRUMENT:                 ,NETZSCH STA 449F5
#PROJECT:                    ,
#DATE/TIME:                  ,7/17/2025 6:46:12 PM (UTC-4)
#CORR. FILE:                 ,
#TEMPCAL:                    ,05-05-2025 14:38
#SENSITIVITY:                ,28-06-2023 13:53
#LABORATORY:                 ,Tran/AAG
#OPERATOR:                   ,Stan
#REMARK:                     ,2025_03_20_Styrofoam_dynamic
#SAMPLE:                     ,PS-Tosoh-F10
#SAMPLE MASS /mg:            ,4.92
#MATERIAL:                   ,Polystyrene
#REFERENCE:                  ,
#REFERENCE MASS /mg:         ,0
#TYPE OF CRUCIBLE:           ,Al2O3 85 ‘l, open
#SAMPLE CRUCIBLE MASS /mg:   ,0
#REFERENCE CRUCIBLE MASS /mg:,0
#DSC RANGE /‘V:              ,5000
#TG RANGE /mg:               ,35000
#TAU-R:                      ,---
#CORR. CODE:                 ,000
#EXO:                        ,-1
#RANGE:                      ,20›C....800›C/0.0....20.0K/min
#SEGMENT:                    ,S1-4/4
#SEG. 1:                     ,20›C/5.0(K/min)/100›C
#SEG. 2:                     ,100›C/00:05/100›C
#SEG. 3:                     ,100›C/1.0(K/min)/400›C
#SEG. 4:                     ,400›C/20.0(K/min)/800›C

##Temp./›C,Time/min,DSC/(mW/mg),Mass/%,Gas Flow(purge2)/(ml/min),Gas Flow(protective)/(ml/min),TIC(scan:1)/A,Sensit./(uV/mW),Segment
 33.89900,  0.00000,      0.87280,    100.00000,50.00000,33.00000,            ,0.92423,1
 35.02400,  1.06667,      0.21321,     99.57012,50.00000,39.00000,1.793197e-08,0.92430,1
 35.85900,  2.13333, 7.195529e-02,     91.77033,50.00000,38.00000,1.789816e-08,0.92437,1
 36.40300,  3.20000, 1.492651e-02,     92.05305,50.00000,38.00000,1.789634e-08,0.92443,1
 37.29900,  4.26667,      0.10380,     92.12907,50.00000,38.00000,1.787966e-08,0.92448,1
 39.24800,  5.33333,      0.33898,     92.53130,50.00000,38.00000,1.791781e-08,0.92452,1
 42.33500,  6.40000,      0.61016,     93.04878,50.00000,38.00000,1.789321e-08,0.92456,1
 46.49800,  7.46667,      0.86838,     94.19167,50.00000,28.00000,1.791698e-08,0.92459,1
 51.59300,  8.53333,      1.10503,     95.15285,50.00000,28.00000,1.788832e-08,0.92462,1
 57.39800,  9.60000,      1.30726,     95.58049,50.00000,28.00000,1.791537e-08,0.92466,1
 63.70200, 10.66667,      1.46442,     95.93455,50.00000,28.00000,1.790307e-08,0.92472,1
 70.27800, 11.73333,      1.57918,     96.21280,50.00000,28.00000,1.790895e-08,0.92480,1
 76.92200, 12.80000,      1.66118,     96.43354,50.00000,28.00000,1.794606e-08,0.92489,1
 83.57800, 13.86667,      1.70922,     96.57154,50.00000,28.00000,1.787826e-08,0.92503,1
 90.13300, 14.93333,      1.73884,     96.67033,50.00000,28.00000,1.790185e-08,0.92516,1
 96.46200, 15.98417,      1.74958,     96.71402,50.00000,28.00000,1.788857e-08,0.92530,2
100.74500, 16.78417,      1.59322,     96.38760,50.00000,28.00000,1.788473e-08,0.92541,2
103.67400, 17.58417,      1.17269,     95.72541,50.00000,28.00000,1.788149e-08,0.92553,2
105.65500, 18.38417,      0.82379,     95.26077,50.00000,28.00000,1.790095e-08,0.92563,2
107.06200, 19.18417,      0.57480,     94.86768,50.00000,28.00000,1.788481e-08,0.92575,2
107.90900, 19.98417,      0.34004,     94.44451,50.00000,28.00000,1.789266e-08,0.92585,2
108.19100, 20.78417,      0.11915,     94.00528,50.00000,28.00000,1.791870e-08,0.92593,2
108.06200, 21.80083,-6.564890e-02,     93.63516,50.00000,28.00000,1.786614e-08,0.92604,3
107.84400, 22.86750,     -0.10682,     93.44187,50.00000,28.00000,1.787589e-08,0.92613,3
107.58700, 23.93417,     -0.12520,     93.24431,50.00000,28.00000,1.787696e-08,0.92618,3
107.37400, 25.00083,     -0.11018,     93.10630,50.00000,28.00000,1.786670e-08,0.92620,3
107.30200, 26.06750,-6.158382e-02,     93.05102,50.00000,28.00000,1.791189e-08,0.92618,3
107.43100, 27.13417,-4.555700e-03,     93.00976,50.00000,28.00000,1.791404e-08,0.92613,3
107.74000, 28.20083, 5.551745e-02,     93.00976,50.00000,28.00000,1.789271e-08,0.92603,3
108.26600, 29.26750,      0.11409,     93.03720,50.00000,28.00000,1.786876e-08,0.92587,3
108.94700, 30.33417,      0.16729,     93.03720,50.00000,28.00000,1.787653e-08,0.92570,3
109.75400, 31.40083,      0.21090,     93.05102,50.00000,28.00000,1.789547e-08,0.92548,3
110.65100, 32.46750,      0.24778,     93.07866,50.00000,28.00000,1.786647e-08,0.92518,3
111.67400, 33.53417,      0.27592,     93.07866,50.00000,28.00000,1.790562e-08,0.92489,3
112.74200, 34.60083,      0.29732,     93.05102,50.00000,28.00000,1.789719e-08,0.92455,3
113.82000, 35.66750,      0.31129,     93.05102,50.00000,28.00000,1.789962e-08,0.92411,3
114.95600, 36.73417,      0.32377,     93.05793,50.00000,28.00000,1.786997e-08,0.92370,3
116.09700, 37.80083,      0.32982,     93.05102,50.00000,28.00000,1.787090e-08,0.92326,3
117.23300, 38.86750,      0.33267,     93.05102,50.00000,29.00000,1.793126e-08,0.92279,3
118.36900, 39.93417,      0.33468,     93.05346,50.00000,29.00000,1.786455e-08,0.92220,3
119.48800, 41.00083,      0.33465,     93.06707,50.00000,29.00000,1.786231e-08,0.92173,3
120.61100, 42.06750,      0.33429,     93.01199,50.00000,29.00000,1.789297e-08,0.92133,3
121.73400, 43.13417,      0.33359,     93.01890,50.00000,29.00000,1.786334e-08,0.92090,3
122.81200, 44.20083,      0.33289,     93.03272,50.00000,29.00000,1.787731e-08,0.92057,3
123.92200, 45.26750,      0.32998,     93.02581,50.00000,29.00000,1.783877e-08,0.92029,3
124.99800, 46.33417,      0.33047,     93.00508,50.00000,29.00000,1.789559e-08,0.92000,3
126.08200, 47.40083,      0.33147,     93.03963,50.00000,29.00000,1.787378e-08,0.91979,3
127.15500, 48.46750,      0.33315,     93.01890,50.00000,29.00000,1.789258e-08,0.91960,3
128.22800, 49.53417,      0.33382,     93.03963,50.00000,29.00000,1.782870e-08,0.91943,3
129.31300, 50.60083,      0.33381,     93.03963,50.00000,29.00000,1.787042e-08,0.91926,3
130.36600, 51.66750,      0.33601,     93.08089,50.00000,29.00000,1.785786e-08,0.91912,3
131.42999, 52.73417,      0.33821,     93.08780,50.00000,29.00000,1.787515e-08,0.91902,3
132.50101, 53.80083,      0.33991,     93.09472,50.00000,29.00000,1.782793e-08,0.91892,3
133.56100, 54.86750,      0.34145,     93.14309,50.00000,29.00000,1.784171e-08,0.91887,3
134.63000, 55.93417,      0.34537,     93.17073,50.00000,29.00000,1.787217e-08,0.91883,3
135.68401, 57.00083,      0.34759,     93.17744,50.00000,29.00000,1.786844e-08,0.91882,3
136.75900, 58.06750,      0.35102,     93.21890,50.00000,29.00000,1.786075e-08,0.91882,3
137.82700, 59.13417,      0.35240,     93.25346,50.00000,29.00000,1.785678e-08,0.91884,3
138.88800, 60.20083,      0.35429,     93.24654,50.00000,29.00000,1.783470e-08,0.91887,3
139.96201, 61.26750,      0.35602,     93.26037,50.00000,29.00000,1.786440e-08,0.91889,3
141.01900, 62.33417,      0.35861,     93.28780,50.00000,29.00000,1.783887e-08,0.91892,3
142.08000, 63.40083,      0.36257,     93.30407,50.00000,29.00000,1.781850e-08,0.91895,3
143.15601, 64.46750,      0.36517,     93.35467,50.00000,29.00000,1.781351e-08,0.91898,3
144.23000, 65.53417,      0.36555,     93.38211,50.00000,29.00000,1.786008e-08,0.91901,3
145.27699, 66.60083,      0.36764,     93.40976,50.00000,29.00000,1.783800e-08,0.91904,3
146.35400, 67.66750,      0.37128,     93.44431,50.00000,29.00000,1.783954e-08,0.91905,3
147.42999, 68.73417,      0.37201,     93.47886,50.00000,29.00000,1.786277e-08,0.91907,3
148.49500, 69.80083,      0.37567,     93.49939,50.00000,29.00000,1.783521e-08,0.91908,3
149.55600, 70.86750,      0.37967,     93.53394,50.00000,29.00000,1.785629e-08,0.91907,3
150.63200, 71.93417,      0.38110,     93.57541,50.00000,29.00000,1.786006e-08,0.91906,3
151.70200, 73.00083,      0.38443,     93.56850,50.00000,29.00000,1.782574e-08,0.91905,3
152.76700, 74.06750,      0.38639,     93.62358,50.00000,29.00000,1.782260e-08,0.91902,3
153.85100, 75.13417,      0.38852,     93.63740,50.00000,29.00000,1.785351e-08,0.91897,3
154.91701, 76.20083,      0.39135,     93.69024,50.00000,29.00000,1.782356e-08,0.91893,3
155.98599, 77.26750,      0.39350,     93.74553,50.00000,29.00000,1.784525e-08,0.91888,3
157.05200, 78.33417,      0.39703,     93.76626,50.00000,29.00000,1.783447e-08,0.91880,3
158.12801, 79.40083,      0.39867,     93.79370,50.00000,29.00000,1.779885e-08,0.91874,3
159.18401, 80.46750,      0.39944,     93.79370,50.00000,29.00000,1.782018e-08,0.91866,3
160.26199, 81.53417,      0.40351,     93.84898,50.00000,29.00000,1.783301e-08,0.91858,3
161.32001, 82.60083,      0.40377,     93.89736,50.00000,29.00000,1.778578e-08,0.91848,3
162.39101, 83.66750,      0.40474,     93.91789,50.00000,29.00000,1.784010e-08,0.91839,3
163.44299, 84.73417,      0.40917,     93.94553,50.00000,29.00000,1.779283e-08,0.91829,3
164.52200, 85.80083,      0.41187,     93.96626,50.00000,29.00000,1.780635e-08,0.91818,3
165.58501, 86.86750,      0.41354,     94.02134,50.00000,29.00000,1.784147e-08,0.91806,3
166.66200, 87.93417,      0.41539,     94.04898,50.00000,29.00000,1.783861e-08,0.91795,3
167.71700, 89.00083,      0.41481,     94.06972,50.00000,29.00000,1.783982e-08,0.91782,3
168.79401, 90.06750,      0.41806,     94.09736,50.00000,29.00000,1.784610e-08,0.91769,3
169.86900, 91.13417,      0.42010,     94.15244,50.00000,29.00000,1.782316e-08,0.91756,3
170.92599, 92.20083,      0.42057,     94.18008,50.00000,29.00000,1.778911e-08,0.91743,3
171.97400, 93.26750,      0.42087,     94.20081,50.00000,29.00000,1.780463e-08,0.91728,3
173.05099, 94.33417,      0.42502,     94.22154,50.00000,29.00000,1.782590e-08,0.91715,3
174.12100, 95.40083,      0.42725,     94.26972,50.00000,29.00000,1.783061e-08,0.91701,3
175.18201, 96.46750,      0.42966,     94.27663,50.00000,29.00000,1.778077e-08,0.91685,3
176.24899, 97.53417,      0.42963,     94.29045,50.00000,29.00000,1.780230e-08,0.91671,3
177.31900, 98.60083,      0.42960,     94.32033,50.00000,29.00000,1.779358e-08,0.91658,3
178.37700, 99.66750,      0.43045,     94.37561,50.00000,29.00000,1.778284e-08,0.91643,3
179.43600,100.73417,      0.43252,     94.41687,50.00000,29.00000,1.781006e-08,0.91626,3
180.50999,101.80083,      0.43496,     94.43760,50.00000,29.00000,1.779221e-08,0.91612,3
181.57899,102.86750,      0.43740,     94.45833,50.00000,29.00000,1.778923e-08,0.91597,3
182.65199,103.93417,      0.43827,     94.49045,50.00000,29.00000,1.778138e-08,0.91580,3
183.71300,105.00083,      0.43861,     94.54573,50.00000,29.00000,1.777384e-08,0.91566,3
184.80000,106.06750,      0.44002,     94.53191,50.00000,29.00000,1.781041e-08,0.91551,3
185.84900,107.13417,      0.44300,     94.58720,50.00000,29.00000,1.781389e-08,0.91533,3
186.91800,108.20083,      0.44212,     94.64228,50.00000,29.00000,1.779130e-08,0.91519,3
187.98199,109.26750,      0.44407,     94.64919,50.00000,29.00000,1.776617e-08,0.91504,3
189.05901,110.33417,      0.44602,     94.67683,50.00000,29.00000,1.778327e-08,0.91488,3
190.11501,111.40083,      0.44726,     94.71118,50.00000,29.00000,1.779324e-08,0.91471,3
191.19299,112.46750,      0.44887,     94.74126,50.00000,29.00000,1.780657e-08,0.91456,3
192.24400,113.53417,      0.45136,     94.76179,50.00000,29.00000,1.778696e-08,0.91441,3
193.31200,114.60083,      0.45315,     94.80325,50.00000,29.00000,1.775176e-08,0.91426,3
194.38699,115.66750,      0.45282,     94.83089,50.00000,29.00000,1.775731e-08,0.91408,3
195.44600,116.73417,      0.45427,     94.85163,50.00000,29.00000,1.774058e-08,0.91393,3
196.51100,117.80083,      0.45590,     94.87215,50.00000,29.00000,1.777969e-08,0.91378,3
197.58600,118.86750,      0.45771,     94.92744,50.00000,29.00000,1.777922e-08,0.91361,3
198.65500,119.93417,      0.45953,     94.92276,50.00000,29.00000,1.779699e-08,0.91344,3
199.72200,121.00083,      0.46063,     94.95041,50.00000,29.00000,1.777506e-08,0.91329,3
200.78300,122.06750,      0.46317,     95.00569,50.00000,29.00000,1.773888e-08,0.91314,3
201.85699,123.13417,      0.46215,     95.01260,50.00000,29.00000,1.776343e-08,0.91295,3
202.91499,124.20083,      0.46505,     95.06768,50.00000,29.00000,1.775335e-08,0.91280,3
203.99699,125.26750,      0.46636,     95.10915,50.00000,29.00000,1.778570e-08,0.91264,3
205.06100,126.33417,      0.46839,     95.10915,50.00000,29.00000,1.777139e-08,0.91246,3
206.12399,127.40083,      0.46738,     95.14817,50.00000,29.00000,1.777563e-08,0.91230,3
207.18800,128.46750,      0.47030,     95.17581,50.00000,29.00000,1.773331e-08,0.91214,3
208.24100,129.53417,      0.47108,     95.21016,50.00000,29.00000,1.776340e-08,0.91195,3
209.31200,130.60083,      0.47295,     95.22398,50.00000,29.00000,1.777273e-08,0.91180,3
210.37199,131.66750,      0.47571,     95.25163,50.00000,29.00000,1.773374e-08,0.91163,3
211.43500,132.73417,      0.47561,     95.27927,50.00000,29.00000,1.775082e-08,0.91147,3
212.52200,133.80083,      0.47624,     95.31382,50.00000,29.00000,1.775591e-08,0.91128,3
213.56700,134.86750,      0.47667,     95.34817,50.00000,29.00000,1.773578e-08,0.91112,3
214.64301,135.93417,      0.47695,     95.34817,50.00000,29.00000,1.775674e-08,0.91096,3
215.71100,137.00083,      0.47812,     95.38740,50.00000,29.00000,1.773768e-08,0.91076,3
216.78200,138.06750,      0.48038,     95.41484,50.00000,29.00000,1.771932e-08,0.91060,3
217.85001,139.13417,      0.48156,     95.45630,50.00000,29.00000,1.773284e-08,0.91043,3
218.92599,140.20083,      0.48220,     95.46321,50.00000,29.00000,1.775980e-08,0.91023,3
219.98000,141.26750,      0.48284,     95.49776,50.00000,29.00000,1.773026e-08,0.91007,3
221.06400,142.33417,      0.48295,     95.52520,50.00000,29.00000,1.772441e-08,0.90990,3
222.10899,143.40083,      0.48287,     95.55285,50.00000,29.00000,1.774219e-08,0.90970,3
223.17500,144.46750,      0.48734,     95.58049,50.00000,29.00000,1.776192e-08,0.90954,3
224.25500,145.53417,      0.48600,     95.60813,50.00000,29.00000,1.770011e-08,0.90936,3
225.31400,146.60083,      0.48757,     95.63557,50.00000,29.00000,1.772475e-08,0.90919,3
226.39101,147.66750,      0.48824,     95.67012,50.00000,29.00000,1.770679e-08,0.90899,3
227.45700,148.73417,      0.48836,     95.69776,50.00000,30.00000,1.769288e-08,0.90881,3
228.51700,149.80083,      0.48994,     95.70467,50.00000,30.00000,1.769918e-08,0.90864,3
229.58600,150.86750,      0.48806,     95.73232,50.00000,30.00000,1.772283e-08,0.90843,3
230.64900,151.93417,      0.48928,     95.77358,50.00000,30.00000,1.771665e-08,0.90825,3
231.71800,153.00083,      0.48996,     95.78740,50.00000,30.00000,1.769681e-08,0.90808,3
232.78799,154.06750,      0.48827,     95.78740,50.00000,30.00000,1.767300e-08,0.90787,3
233.84000,155.13417,      0.49041,     95.83577,50.00000,30.00000,1.768730e-08,0.90769,3
234.91701,156.20083,      0.49055,     95.87012,50.00000,30.00000,1.766332e-08,0.90751,3
235.97701,157.26750,      0.48995,     95.87703,50.00000,30.00000,1.770425e-08,0.90730,3
237.03999,158.33417,      0.49046,     95.87703,50.00000,29.00000,1.769194e-08,0.90712,3
238.10899,159.40083,      0.48931,     95.92764,50.00000,30.00000,1.769256e-08,0.90694,3
239.18201,160.46750,      0.48799,     95.95528,50.00000,30.00000,1.769233e-08,0.90675,3
240.23500,161.53417,      0.48868,     95.96220,50.00000,30.00000,1.767895e-08,0.90654,3
241.30400,162.60083,      0.48827,     95.99675,50.00000,30.00000,1.769015e-08,0.90636,3
242.36800,163.66750,      0.48879,     96.02419,50.00000,30.00000,1.767943e-08,0.90617,3
243.44701,164.73417,      0.48691,     96.05183,50.00000,30.00000,1.763054e-08,0.90595,3
244.50900,165.80083,      0.48576,     96.07256,50.00000,30.00000,1.770948e-08,0.90576,3
245.57201,166.86750,      0.48813,     96.08638,50.00000,30.00000,1.766241e-08,0.90558,3
246.63901,167.93417,      0.48643,     96.13455,50.00000,30.00000,1.767747e-08,0.90535,3
247.70200,169.00083,      0.48621,     96.13232,50.00000,30.00000,1.767131e-08,0.90517,3
248.77200,170.06750,      0.48674,     96.16687,50.00000,30.00000,1.766374e-08,0.90497,3
249.83701,171.13417,      0.48373,     96.17378,50.00000,30.00000,1.768477e-08,0.90475,3
250.89900,172.20083,      0.48183,     96.20833,50.00000,30.00000,1.766554e-08,0.90455,3
251.97200,173.26750,      0.48329,     96.23130,50.00000,30.00000,1.767368e-08,0.90437,3
253.03400,174.33417,      0.48196,     96.25650,50.00000,30.00000,1.768930e-08,0.90417,3
254.09000,175.40083,      0.48305,     96.28415,50.00000,30.00000,1.769503e-08,0.90394,3
255.16600,176.46750,      0.48396,     96.33923,50.00000,30.00000,1.769830e-08,0.90375,3
256.24399,177.53417,      0.48094,     96.33923,50.00000,30.00000,1.767255e-08,0.90355,3
257.29999,178.60083,      0.47941,     96.36687,50.00000,30.00000,1.765329e-08,0.90332,3
258.35999,179.66750,      0.47844,     96.41748,50.00000,30.00000,1.764785e-08,0.90312,3
259.43600,180.73417,      0.47786,     96.41972,50.00000,30.00000,1.762987e-08,0.90293,3
260.50000,181.80083,      0.47934,     96.42907,50.00000,30.00000,1.767590e-08,0.90273,3
261.57599,182.86750,      0.47800,     96.42907,50.00000,30.00000,1.767329e-08,0.90250,3
262.63400,183.93417,      0.47514,     96.44268,50.00000,30.00000,1.767261e-08,0.90230,3
263.70200,185.00083,      0.47398,     96.49329,50.00000,30.00000,1.765904e-08,0.90209,3
264.76801,186.06750,      0.47339,     96.48638,50.00000,30.00000,1.763686e-08,0.90185,3
265.84399,187.13417,      0.47072,     96.51402,50.00000,30.00000,1.764539e-08,0.90165,3
266.91000,188.20083,      0.47050,     96.51870,50.00000,30.00000,1.764026e-08,0.90144,3
267.97198,189.26750,      0.47276,     96.54634,50.00000,30.00000,1.762229e-08,0.90124,3
269.03601,190.33417,      0.47197,     96.55996,50.00000,30.00000,1.763744e-08,0.90100,3
270.10001,191.40083,      0.47005,     96.59228,50.00000,30.00000,1.766029e-08,0.90079,3
271.17300,192.46750,      0.46965,     96.61301,50.00000,30.00000,1.762299e-08,0.90059,3
272.24701,193.53417,      0.46772,     96.61992,50.00000,30.00000,1.763093e-08,0.90033,3
273.30399,194.60083,      0.46827,     96.63598,50.00000,30.00000,1.765753e-08,0.90013,3
274.37799,195.66750,      0.46462,     96.66362,50.00000,30.00000,1.766709e-08,0.89992,3
275.43201,196.73417,      0.46631,     96.67033,50.00000,30.00000,1.761915e-08,0.89968,3
276.50800,197.80083,      0.46438,     96.67724,50.00000,30.00000,1.764101e-08,0.89946,3
277.55600,198.86750,      0.46204,     96.66362,50.00000,30.00000,1.767259e-08,0.89925,3
278.63000,199.93417,      0.46394,     96.69106,50.00000,30.00000,1.765820e-08,0.89903,3
279.69000,201.00083,      0.46180,     96.73943,50.00000,30.00000,1.766569e-08,0.89879,3
280.77802,202.06750,      0.46256,     96.73943,50.00000,30.00000,1.763908e-08,0.89857,3
281.85001,203.13417,      0.46119,     96.76016,50.00000,30.00000,1.754915e-08,0.89832,3
282.90201,204.20083,      0.45692,     96.77154,50.00000,30.00000,1.759501e-08,0.89810,3
283.97699,205.26750,      0.45825,     96.78537,50.00000,30.00000,1.764846e-08,0.89789,3
285.03500,206.33417,      0.45570,     96.82683,50.00000,30.00000,1.763815e-08,0.89767,3
286.09698,207.40083,      0.45393,     96.79919,50.00000,30.00000,1.763391e-08,0.89742,3
287.16000,208.46750,      0.45177,     96.82439,50.00000,30.00000,1.762704e-08,0.89719,3
288.21799,209.53417,      0.45173,     96.82439,50.00000,30.00000,1.761704e-08,0.89697,3
289.28400,210.60083,      0.45151,     96.84512,50.00000,30.00000,1.760429e-08,0.89672,3
290.35501,211.66750,      0.45110,     96.87276,50.00000,30.00000,1.763676e-08,0.89650,3
291.42599,212.73417,      0.44893,     96.90041,50.00000,30.00000,1.758070e-08,0.89627,3
292.48300,213.80083,      0.44636,     96.87967,50.00000,30.00000,1.756404e-08,0.89602,3
293.56299,214.86750,      0.44633,     96.89350,50.00000,30.00000,1.760788e-08,0.89580,3
294.62000,215.93417,      0.44512,     96.90732,50.00000,30.00000,1.758472e-08,0.89557,3
295.69501,217.00083,      0.44568,     96.89350,50.00000,30.00000,1.759180e-08,0.89535,3
296.76300,218.06750,      0.44369,     96.92114,50.00000,30.00000,1.760735e-08,0.89509,3
297.81900,219.13417,      0.44031,     96.90732,50.00000,30.00000,1.760283e-08,0.89486,3
298.88501,220.20083,      0.44028,     96.92114,50.00000,30.00000,1.761774e-08,0.89463,3
299.96399,221.26750,      0.44005,     96.92805,50.00000,30.00000,1.759488e-08,0.89437,3
301.02100,222.33417,      0.43922,     96.95549,50.00000,30.00000,1.758413e-08,0.89413,3
302.09100,223.40083,      0.43780,     96.98313,50.00000,30.00000,1.761597e-08,0.89391,3
303.16501,224.46750,      0.43263,     96.96240,50.00000,30.00000,1.762174e-08,0.89364,3
304.21799,225.53417,      0.42981,     96.99472,50.00000,30.00000,1.761041e-08,0.89341,3
305.28699,226.60083,      0.42917,     96.98780,50.00000,30.00000,1.759934e-08,0.89318,3
306.35400,227.66750,      0.42714,     96.96707,50.00000,30.00000,1.758363e-08,0.89295,3
307.40900,228.73417,      0.42709,     97.00163,50.00000,30.00000,1.760948e-08,0.89268,3
308.47800,229.80083,      0.42644,     97.00163,50.00000,30.00000,1.762898e-08,0.89246,3
309.55200,230.86750,      0.42480,     97.00163,50.00000,30.00000,1.759826e-08,0.89221,3
310.61899,231.93417,      0.42376,     96.98089,50.00000,30.00000,1.762627e-08,0.89194,3
311.68900,233.00083,      0.42391,     97.01545,50.00000,30.00000,1.756356e-08,0.89170,3
312.76300,234.06750,      0.41946,     97.02215,50.00000,30.00000,1.760900e-08,0.89147,3
313.82901,235.13417,      0.41920,     96.99919,50.00000,30.00000,1.759098e-08,0.89123,3
314.89700,236.20083,      0.41674,     97.00163,50.00000,30.00000,1.765234e-08,0.89095,3
315.97000,237.26750,      0.41327,     97.01992,50.00000,30.00000,1.759816e-08,0.89071,3
317.03699,238.33417,      0.40758,     97.00610,50.00000,30.00000,1.758002e-08,0.89048,3
318.10199,239.40083,      0.40630,     96.98537,50.00000,30.00000,1.759509e-08,0.89021,3
319.16901,240.46750,      0.40482,     96.98537,50.00000,30.00000,1.758769e-08,0.88997,3
320.23999,241.53417,      0.40132,     96.96484,50.00000,30.00000,1.757710e-08,0.88972,3
321.30801,242.60083,      0.39760,     96.94411,50.00000,30.00000,1.758874e-08,0.88944,3
322.37299,243.66750,      0.39610,     96.91646,50.00000,30.00000,1.759937e-08,0.88919,3
323.42599,244.73417,      0.39378,     96.94411,50.00000,30.00000,1.758167e-08,0.88895,3
324.49701,245.80083,      0.39207,     96.90488,50.00000,30.00000,1.760669e-08,0.88867,3
325.56000,246.86750,      0.39280,     96.88435,50.00000,30.00000,1.758740e-08,0.88842,3
326.62201,247.93417,      0.38884,     96.84289,50.00000,30.00000,1.762756e-08,0.88817,3
327.69601,249.00083,      0.39303,     96.81524,50.00000,30.00000,1.760513e-08,0.88789,3
328.75699,250.06750,      0.38682,     96.77398,50.00000,30.00000,1.756382e-08,0.88765,3
329.83401,251.13417,      0.38734,     96.75325,50.00000,30.00000,1.759102e-08,0.88740,3
330.89801,252.20083,      0.38990,     96.69797,50.00000,30.00000,1.755693e-08,0.88715,3
331.95999,253.26750,      0.38448,     96.67033,50.00000,30.00000,1.758002e-08,0.88686,3
333.03400,254.33417,      0.38603,     96.58760,50.00000,30.00000,1.760675e-08,0.88661,3
334.10300,255.40083,      0.38265,     96.47724,50.00000,30.00000,1.760779e-08,0.88632,3
335.15601,256.46750,      0.38439,     96.42215,50.00000,30.00000,1.759498e-08,0.88607,3
336.23499,257.53417,      0.38306,     96.31179,50.00000,30.00000,1.758935e-08,0.88582,3
337.28900,258.60083,      0.38316,     96.19207,50.00000,30.00000,1.760053e-08,0.88557,3
338.36899,259.66750,      0.38658,     96.10935,50.00000,30.00000,1.757532e-08,0.88527,3
339.43701,260.73417,      0.38897,     95.97134,50.00000,30.00000,1.759654e-08,0.88502,3
340.49600,261.80083,      0.38701,     95.80346,50.00000,30.00000,1.759248e-08,0.88476,3
341.55899,262.86750,      0.39085,     95.63801,50.00000,30.00000,1.759479e-08,0.88447,3
342.62399,263.93417,      0.39429,     95.44024,50.00000,30.00000,1.758615e-08,0.88422,3
343.68900,265.00083,      0.39836,     95.24024,50.00000,30.00000,1.759770e-08,0.88395,3
344.75400,266.06750,      0.40473,     94.99187,50.00000,30.00000,1.759408e-08,0.88370,3
345.82300,267.13417,      0.40633,     94.71585,50.00000,30.00000,1.757558e-08,0.88340,3
346.89001,268.20083,      0.41148,     94.40996,50.00000,30.00000,1.755892e-08,0.88314,3
347.96100,269.26750,      0.41309,     94.07439,50.00000,30.00000,1.758589e-08,0.88288,3
349.03799,270.33417,      0.41178,     93.68110,50.00000,30.00000,1.756850e-08,0.88258,3
350.09201,271.40083,      0.40731,     93.24878,50.00000,30.00000,1.758102e-08,0.88232,3
351.16299,272.46750,      0.40851,     92.75894,50.00000,30.00000,1.757763e-08,0.88206,3
352.23001,273.53417,      0.40718,     92.23699,50.00000,30.00000,1.756666e-08,0.88174,3
353.28400,274.60083,      0.40731,     91.66911,50.00000,30.00000,1.756861e-08,0.88149,3
354.35599,275.66750,      0.41863,     90.97012,50.00000,30.00000,1.757932e-08,0.88122,3
355.43500,276.73417,      0.41711,     90.21809,50.00000,30.00000,1.755832e-08,0.88096,3
356.49799,277.80083,      0.41515,     89.40407,50.00000,30.00000,1.758248e-08,0.88066,3
357.57199,278.86750,      0.41763,     88.42907,50.00000,30.00000,1.759031e-08,0.88039,3
358.62100,279.93417,      0.42371,     87.43801,50.00000,30.00000,1.758712e-08,0.88013,3
359.69901,281.00083,      0.42940,     86.34817,50.00000,30.00000,1.755400e-08,0.87981,3
360.75500,282.06750,      0.43127,     85.06504,50.00000,30.00000,1.759444e-08,0.87955,3
361.81799,283.13417,      0.44081,     83.68293,50.00000,30.00000,1.758211e-08,0.87928,3
362.88599,284.20083,      0.44931,     82.12866,50.00000,30.00000,1.755786e-08,0.87897,3
363.95300,285.26750,      0.45677,     80.45915,50.00000,30.00000,1.759116e-08,0.87869,3
365.01001,286.33417,      0.46275,     78.64939,50.00000,30.00000,1.757350e-08,0.87844,3
366.07599,287.40083,      0.47303,     76.59370,50.00000,30.00000,1.756241e-08,0.87816,3
367.14999,288.46750,      0.47884,     74.39776,50.00000,30.00000,1.753259e-08,0.87785,3
368.21301,289.53417,      0.49024,     72.00630,50.00000,30.00000,1.758156e-08,0.87758,3
369.28101,290.60083,      0.49630,     69.37805,50.00000,30.00000,1.755489e-08,0.87731,3
370.34000,291.66750,      0.50001,     66.62561,50.00000,30.00000,1.758391e-08,0.87698,3
371.40500,292.73417,      0.50502,     63.63862,50.00000,30.00000,1.757016e-08,0.87672,3
372.48099,293.80083,      0.50380,     60.39634,50.00000,30.00000,1.758037e-08,0.87645,3
373.54700,294.86750,      0.49759,     57.03679,50.00000,30.00000,1.758385e-08,0.87613,3
374.60199,295.93417,      0.49049,     53.46118,50.00000,30.00000,1.757589e-08,0.87585,3
375.67999,297.00083,      0.48013,     49.77276,50.00000,30.00000,1.756550e-08,0.87558,3
376.74301,298.06750,      0.46410,     45.90264,50.00000,30.00000,1.756947e-08,0.87530,3
377.81299,299.13417,      0.44215,     41.93150,50.00000,30.00000,1.757989e-08,0.87497,3
378.88400,300.20083,      0.41078,     37.86382,50.00000,30.00000,1.757824e-08,0.87470,3
379.95700,301.26750,      0.37081,     33.86037,50.00000,30.00000,1.757224e-08,0.87443,3
381.02200,302.33417,      0.32135,     29.81098,50.00000,30.00000,1.757386e-08,0.87410,3
382.08200,303.40083,      0.26408,     25.92256,50.00000,30.00000,1.759451e-08,0.87382,3
383.14700,304.46750,      0.19922,     22.11463,50.00000,30.00000,1.759244e-08,0.87354,3
384.23199,305.53417,      0.12190,     18.57134,50.00000,30.00000,1.757252e-08,0.87321,3
385.28500,306.60083, 3.929878e-02,     15.24167,50.00000,30.00000,1.757653e-08,0.87294,3
386.36600,307.66750,-4.749030e-02,     12.25915,50.00000,30.00000,1.755897e-08,0.87265,3
387.43301,308.73417,     -0.14311,      9.64939,50.00000,30.00000,1.752205e-08,0.87238,3
388.50201,309.80083,     -0.23548,      7.39126,50.00000,30.00000,1.755012e-08,0.87204,3
389.56000,310.86750,     -0.33054,      5.51707,50.00000,30.00000,1.752909e-08,0.87176,3
390.63199,311.93417,     -0.41946,      3.99268,50.00000,30.00000,1.753844e-08,0.87147,3
391.69800,313.00083,     -0.49446,      2.79919,50.00000,30.00000,1.753748e-08,0.87114,3
392.76700,314.06750,     -0.57233,      1.91850,50.00000,30.00000,1.755603e-08,0.87086,3
393.83099,315.13417,     -0.63022,      1.23557,50.00000,30.00000,1.750425e-08,0.87057,3
394.89700,316.20083,     -0.69005,      0.74573,50.00000,30.00000,1.760467e-08,0.87025,3
395.96301,317.26750,     -0.73824,      0.35264,50.00000,30.00000,1.757601e-08,0.86995,3
397.03000,318.33417,     -0.78390, 4.674797e-02,50.00000,30.00000,1.757049e-08,0.86967,3
398.09900,319.40083,     -0.83059,     -0.15325,50.00000,30.00000,1.753959e-08,0.86938,3
399.16101,320.46750,     -0.86890,     -0.32114,50.00000,30.00000,1.757190e-08,0.86904,3
399.68500,320.97917,     -0.88674,     -0.39715,50.00000,30.00000,1.752993e-08,0.86890,4
399.78000,321.05917,     -0.86111,     -0.41768,50.00000,30.00000,1.752993e-08,0.86890,4
399.95700,321.13917,     -0.74870,     -0.42459,50.00000,30.00000,1.755256e-08,0.86885,4
400.23999,321.21917,     -0.52232,     -0.38333,50.00000,30.00000,1.755256e-08,0.86885,4
400.65701,321.29917,     -0.17368,     -0.33963,50.00000,30.00000,1.752433e-08,0.86880,4
401.22198,321.37917,      0.30053,     -0.22683,50.00000,30.00000,1.752433e-08,0.86880,4
401.94101,321.45917,      0.88965,     -0.12114,50.00000,30.00000,1.754819e-08,0.86875,4
402.83801,321.53917,      1.57376, 1.686992e-02,50.00000,30.00000,1.754819e-08,0.86875,4
403.89301,321.61917,      2.32775,      0.13638,50.00000,30.00000,1.753765e-08,0.86870,4
405.09399,321.69917,      3.12280,      0.25833,50.00000,30.00000,1.753765e-08,0.86870,4
406.42200,321.77917,      3.93011,      0.32947,50.00000,30.00000,1.753765e-08,0.86870,4
407.84799,321.85917,      4.72395,      0.42378,50.00000,30.00000,1.752281e-08,0.86865,4
409.35901,321.93917,      5.47203,      0.52967,50.00000,30.00000,1.752281e-08,0.86865,4
410.93799,322.01917,      6.16234,      0.58943,50.00000,30.00000,1.751772e-08,0.86861,4
412.53900,322.09917,      6.76810,      0.61707,50.00000,30.00000,1.751772e-08,0.86861,4
414.16501,322.17917,      7.28222,      0.67907,50.00000,30.00000,1.753425e-08,0.86856,4
415.79001,322.25917,      7.70021,      0.72053,50.00000,30.00000,1.753425e-08,0.86856,4
417.38901,322.33917,      8.01955,      0.73882,50.00000,30.00000,1.753978e-08,0.86851,4
418.96701,322.41917,      8.24490,      0.73882,50.00000,30.00000,1.753978e-08,0.86851,4
420.49799,322.49917,      8.37927,      0.71118,50.00000,30.00000,1.756674e-08,0.86846,4
421.99899,322.57917,      8.44555,      0.71118,50.00000,30.00000,1.756674e-08,0.86846,4
423.46600,322.65917,      8.45229,      0.71118,50.00000,30.00000,1.755284e-08,0.86841,4
424.89099,322.73917,      8.40992,      0.67907,50.00000,30.00000,1.755284e-08,0.86841,4
426.28201,322.81917,      8.33682,      0.65142,50.00000,30.00000,1.753294e-08,0.86836,4
427.64200,322.89917,      8.24333,      0.64451,50.00000,30.00000,1.753294e-08,0.86836,4
428.98199,322.97917,      8.14691,      0.64451,50.00000,30.00000,1.757277e-08,0.86831,4
430.33099,323.05917,      8.05907,      0.63760,50.00000,30.00000,1.757277e-08,0.86831,4
431.67599,323.13917,      7.98954,      0.62398,50.00000,30.00000,1.757277e-08,0.86831,4
433.00800,323.21917,      7.94299,      0.62398,50.00000,30.00000,1.751055e-08,0.86826,4
434.37399,323.29917,      7.92474,      0.62398,50.00000,30.00000,1.751055e-08,0.86826,4
435.75500,323.37917,      7.93733,      0.62398,50.00000,30.00000,1.751683e-08,0.86822,4
437.16199,323.45917,      7.98599,      0.62398,50.00000,30.00000,1.751683e-08,0.86822,4
438.59900,323.53917,      8.06460,      0.62398,50.00000,30.00000,1.754105e-08,0.86817,4
440.06400,323.61917,      8.16859,      0.65142,50.00000,30.00000,1.754105e-08,0.86817,4
441.57300,323.69917,      8.29806,      0.65142,50.00000,30.00000,1.752097e-08,0.86812,4
443.10199,323.77917,      8.44532,      0.67907,50.00000,30.00000,1.752097e-08,0.86812,4
444.64099,323.85917,      8.60491,      0.67907,50.00000,30.00000,1.754220e-08,0.86807,4
446.25299,323.93917,      8.77073,      0.70671,50.00000,30.00000,1.754220e-08,0.86807,4
447.84698,324.01917,      8.93939,      0.70671,50.00000,30.00000,1.756123e-08,0.86803,4
449.48001,324.09917,      9.10224,      0.73435,50.00000,30.00000,1.756123e-08,0.86803,4
451.13901,324.17917,      9.25673,      0.76179,50.00000,30.00000,1.753723e-08,0.86798,4
452.79501,324.25917,      9.39737,      0.76179,50.00000,30.00000,1.753723e-08,0.86798,4
454.45700,324.33917,      9.52589,      0.76179,50.00000,30.00000,1.751349e-08,0.86793,4
456.13101,324.41917,      9.63503,      0.78943,50.00000,30.00000,1.751349e-08,0.86793,4
457.81500,324.49917,      9.72851,      0.78943,50.00000,30.00000,1.755240e-08,0.86788,4
459.48199,324.57917,      9.80442,      0.78943,50.00000,30.00000,1.755240e-08,0.86788,4
461.15100,324.65917,      9.86604,      0.80325,50.00000,30.00000,1.755240e-08,0.86788,4
462.83899,324.73917,      9.91057,      0.81707,50.00000,30.00000,1.754906e-08,0.86783,4
464.50900,324.81917,      9.94377,      0.84472,50.00000,30.00000,1.754906e-08,0.86783,4
466.17200,324.89917,      9.96422,      0.81707,50.00000,30.00000,1.754515e-08,0.86778,4
467.84201,324.97917,      9.97620,      0.81707,50.00000,30.00000,1.754515e-08,0.86778,4
469.50000,325.05917,      9.98235,      0.84472,50.00000,30.00000,1.752328e-08,0.86773,4
471.16000,325.13917,      9.98405,      0.84472,50.00000,30.00000,1.752328e-08,0.86773,4
472.83200,325.21917,      9.98411,      0.84472,50.00000,30.00000,1.752891e-08,0.86768,4
474.48801,325.29917,      9.98289,      0.84472,50.00000,30.00000,1.752891e-08,0.86768,4
476.14499,325.37917,      9.98161,      0.84472,50.00000,30.00000,1.755322e-08,0.86764,4
477.82001,325.45917,      9.98271,      0.87215,50.00000,30.00000,1.755322e-08,0.86764,4
479.49100,325.53917,      9.98493,      0.89980,50.00000,30.00000,1.755028e-08,0.86759,4
481.15799,325.61917,      9.98928,      0.89980,50.00000,30.00000,1.755028e-08,0.86759,4
482.82300,325.69917,      9.99704,      0.92744,50.00000,30.00000,1.755332e-08,0.86754,4
484.50299,325.77917,     10.00470,      0.92744,50.00000,30.00000,1.755332e-08,0.86754,4
486.17899,325.85917,     10.01452,      0.95508,50.00000,30.00000,1.755060e-08,0.86750,4
487.86801,325.93917,     10.02598,      0.95508,50.00000,30.00000,1.755060e-08,0.86750,4
489.54999,326.01917,     10.03757,      0.98252,50.00000,30.00000,1.755060e-08,0.86750,4
491.23801,326.09917,     10.04567,      1.01016,50.00000,30.00000,1.754442e-08,0.86745,4
492.92999,326.17917,     10.05452,      1.01016,50.00000,30.00000,1.754442e-08,0.86745,4
494.62000,326.25917,     10.06330,      1.02398,50.00000,30.00000,1.756997e-08,0.86740,4
496.31601,326.33917,     10.06626,      1.05163,50.00000,30.00000,1.756997e-08,0.86740,4
498.01300,326.41917,     10.06916,      1.09289,50.00000,30.00000,1.754444e-08,0.86735,4
499.70300,326.49917,     10.06626,      1.09289,50.00000,30.00000,1.754444e-08,0.86735,4
501.40399,326.57917,     10.06085,      1.09289,50.00000,30.00000,1.754452e-08,0.86731,4
503.09399,326.65917,     10.05287,      1.09289,50.00000,30.00000,1.754452e-08,0.86731,4
504.78299,326.73917,     10.04346,      1.14817,50.00000,30.00000,1.750960e-08,0.86726,4
506.47198,326.81917,     10.02800,      1.14817,50.00000,30.00000,1.750960e-08,0.86726,4
508.15201,326.89917,     10.01071,      1.14817,50.00000,30.00000,1.753865e-08,0.86721,4
509.84500,326.97917,      9.99291,      1.20569,50.00000,30.00000,1.753865e-08,0.86721,4
511.54700,327.05917,      9.97116,      1.20569,50.00000,30.00000,1.754048e-08,0.86716,4
513.23102,327.13917,      9.94744,      1.22642,50.00000,30.00000,1.754048e-08,0.86716,4
514.91101,327.21917,      9.92479,      1.23333,50.00000,30.00000,1.753555e-08,0.86711,4
516.59100,327.29917,      9.89750,      1.26077,50.00000,30.00000,1.753555e-08,0.86711,4
518.27600,327.37917,      9.87086,      1.26077,50.00000,30.00000,1.753555e-08,0.86711,4
519.94202,327.45917,      9.84220,      1.28841,50.00000,30.00000,1.751526e-08,0.86706,4
521.63300,327.53917,      9.81286,      1.31606,50.00000,30.00000,1.751526e-08,0.86706,4
523.31299,327.61917,      9.78501,      1.31606,50.00000,30.00000,1.752487e-08,0.86701,4
524.98401,327.69917,      9.75578,      1.31606,50.00000,30.00000,1.752487e-08,0.86701,4
526.65399,327.77917,      9.72739,      1.34370,50.00000,30.00000,1.752039e-08,0.86696,4
528.33002,327.85917,      9.69675,      1.34370,50.00000,30.00000,1.752039e-08,0.86696,4
530.00702,327.93917,      9.66935,      1.34370,50.00000,30.00000,1.754846e-08,0.86691,4
531.67603,328.01917,      9.64006,      1.37114,50.00000,30.00000,1.754846e-08,0.86691,4
533.34601,328.09917,      9.60870,      1.42642,50.00000,30.00000,1.756467e-08,0.86687,4
535.01801,328.17917,      9.58089,      1.42642,50.00000,30.00000,1.756467e-08,0.86687,4
536.68201,328.25917,      9.54984,      1.42642,50.00000,30.00000,1.755019e-08,0.86681,4
538.35498,328.33917,      9.51840,      1.42642,50.00000,30.00000,1.755019e-08,0.86681,4
540.02301,328.41917,      9.48616,      1.45407,50.00000,30.00000,1.755354e-08,0.86677,4
541.69501,328.49917,      9.45536,      1.48150,50.00000,30.00000,1.755354e-08,0.86677,4
543.35999,328.57917,      9.42075,      1.48150,50.00000,30.00000,1.751595e-08,0.86671,4
545.02197,328.65917,      9.38697,      1.48150,50.00000,30.00000,1.751595e-08,0.86671,4
546.69501,328.73917,      9.35362,      1.53679,50.00000,30.00000,1.755254e-08,0.86667,4
548.35699,328.81917,      9.31803,      1.53679,50.00000,30.00000,1.755254e-08,0.86667,4
550.01599,328.89917,      9.28517,      1.56443,50.00000,30.00000,1.752430e-08,0.86663,4
551.67200,328.97917,      9.24825,      1.56443,50.00000,30.00000,1.752430e-08,0.86663,4
553.34302,329.05917,      9.21235,      1.57825,50.00000,30.00000,1.752430e-08,0.86663,4
555.00000,329.13917,      9.17551,      1.61951,50.00000,30.00000,1.754475e-08,0.86658,4
556.65802,329.21917,      9.13928,      1.61951,50.00000,30.00000,1.754475e-08,0.86658,4
558.30701,329.29917,      9.10218,      1.61951,50.00000,30.00000,1.751785e-08,0.86652,4
559.96399,329.37917,      9.06549,      1.61951,50.00000,30.00000,1.751785e-08,0.86652,4
561.61603,329.45917,      9.02879,      1.64715,50.00000,30.00000,1.750769e-08,0.86648,4
563.28198,329.53917,      8.99173,      1.64715,50.00000,30.00000,1.750769e-08,0.86648,4
564.95300,329.61917,      8.95339,      1.67480,50.00000,30.00000,1.755480e-08,0.86643,4
566.59900,329.69917,      8.91317,      1.67480,50.00000,30.00000,1.755480e-08,0.86643,4
568.24298,329.77917,      8.87825,      1.70224,50.00000,30.00000,1.753513e-08,0.86638,4
569.90002,329.85917,      8.83879,      1.70224,50.00000,30.00000,1.753513e-08,0.86638,4
571.55200,329.93917,      8.80100,      1.72988,50.00000,30.00000,1.755279e-08,0.86633,4
573.21198,330.01917,      8.75915,      1.75061,50.00000,30.00000,1.755279e-08,0.86633,4
574.85498,330.09917,      8.72109,      1.75752,50.00000,30.00000,1.753386e-08,0.86629,4
576.50403,330.17917,      8.68175,      1.75752,50.00000,30.00000,1.753386e-08,0.86629,4
578.15302,330.25917,      8.64386,      1.78516,50.00000,30.00000,1.752779e-08,0.86623,4
579.80603,330.33917,      8.59763,      1.81280,50.00000,30.00000,1.752779e-08,0.86623,4
581.45898,330.41917,      8.55508,      1.83333,50.00000,30.00000,1.752779e-08,0.86623,4
583.09497,330.49917,      8.51412,      1.84024,50.00000,30.00000,1.753416e-08,0.86618,4
584.74298,330.57917,      8.46965,      1.84024,50.00000,30.00000,1.753416e-08,0.86618,4
586.39301,330.65917,      8.42438,      1.87480,50.00000,30.00000,1.754334e-08,0.86613,4
588.03302,330.73917,      8.37849,      1.89553,50.00000,30.00000,1.754334e-08,0.86613,4
589.67902,330.81917,      8.33013,      1.86789,50.00000,30.00000,1.755772e-08,0.86609,4
591.30902,330.89917,      8.28423,      1.92317,50.00000,30.00000,1.755772e-08,0.86609,4
592.96301,330.97917,      8.23316,      1.92317,50.00000,30.00000,1.754544e-08,0.86604,4
594.59802,331.05917,      8.18251,      1.95061,50.00000,30.00000,1.754544e-08,0.86604,4
596.24200,331.13917,      8.13398,      1.97825,50.00000,30.00000,1.753591e-08,0.86599,4
597.88000,331.21917,      8.08573,      1.97825,50.00000,30.00000,1.753591e-08,0.86599,4
599.50897,331.29917,      8.03513,      1.95061,50.00000,30.00000,1.753894e-08,0.86594,4
601.15002,331.37917,      7.98324,      2.00813,50.00000,30.00000,1.753894e-08,0.86594,4
602.78302,331.45917,      7.93420,      2.00813,50.00000,30.00000,1.753587e-08,0.86589,4
604.42798,331.53917,      7.88589,      2.00813,50.00000,30.00000,1.753587e-08,0.86589,4
606.05701,331.61917,      7.83749,      2.03577,50.00000,30.00000,1.753157e-08,0.86584,4
607.70099,331.69917,      7.78781,      2.03577,50.00000,30.00000,1.753157e-08,0.86584,4
609.33398,331.77917,      7.73809,      2.06341,50.00000,30.00000,1.752758e-08,0.86579,4
610.96198,331.85917,      7.68955,      2.06341,50.00000,30.00000,1.752758e-08,0.86579,4
612.60699,331.93917,      7.63536,      2.06341,50.00000,30.00000,1.752758e-08,0.86579,4
614.23297,332.01917,      7.58485,      2.11159,50.00000,30.00000,1.752676e-08,0.86575,4
615.87000,332.09917,      7.53214,      2.11850,50.00000,30.00000,1.752676e-08,0.86575,4
617.50201,332.17917,      7.47886,      2.11850,50.00000,30.00000,1.753143e-08,0.86569,4
619.13898,332.25917,      7.42124,      2.14614,50.00000,30.00000,1.753143e-08,0.86569,4
620.77197,332.33917,      7.36805,      2.12541,50.00000,30.00000,1.752934e-08,0.86564,4
622.39899,332.41917,      7.31132,      2.16687,50.00000,30.00000,1.752934e-08,0.86564,4
624.02899,332.49917,      7.25347,      2.17378,50.00000,30.00000,1.756027e-08,0.86560,4
625.65698,332.57917,      7.19505,      2.17378,50.00000,30.00000,1.756027e-08,0.86560,4
627.28601,332.65917,      7.13372,      2.20122,50.00000,30.00000,1.752585e-08,0.86555,4
628.91199,332.73917,      7.07566,      2.22886,50.00000,30.00000,1.752585e-08,0.86555,4
630.53802,332.81917,      7.01318,      2.22886,50.00000,30.00000,1.754242e-08,0.86550,4
632.15399,332.89917,      6.95334,      2.22886,50.00000,30.00000,1.754242e-08,0.86550,4
633.78900,332.97917,      6.89249,      2.22886,50.00000,30.00000,1.752065e-08,0.86545,4
635.40802,333.05917,      6.83276,      2.25650,50.00000,30.00000,1.752065e-08,0.86545,4
637.04303,333.13917,      6.77409,      2.28415,50.00000,30.00000,1.753547e-08,0.86541,4
638.66302,333.21917,      6.71207,      2.28415,50.00000,30.00000,1.753547e-08,0.86541,4
640.28802,333.29917,      6.65373,      2.29797,50.00000,30.00000,1.753547e-08,0.86541,4
641.90503,333.37917,      6.59269,      2.31179,50.00000,30.00000,1.753933e-08,0.86535,4
643.53101,333.45917,      6.53386,      2.31179,50.00000,30.00000,1.753933e-08,0.86535,4
645.16199,333.53917,      6.47120,      2.34167,50.00000,30.00000,1.750308e-08,0.86530,4
646.77802,333.61917,      6.41122,      2.36911,50.00000,30.00000,1.750308e-08,0.86530,4
648.39899,333.69917,      6.35042,      2.36911,50.00000,30.00000,1.753685e-08,0.86525,4
650.02802,333.77917,      6.28487,      2.36911,50.00000,30.00000,1.753685e-08,0.86525,4
651.65198,333.85917,      6.22359,      2.39675,50.00000,30.00000,1.753101e-08,0.86520,4
653.26801,333.93917,      6.16293,      2.39675,50.00000,30.00000,1.753101e-08,0.86520,4
654.89502,334.01917,      6.10058,      2.41748,50.00000,30.00000,1.752120e-08,0.86515,4
656.50800,334.09917,      6.03942,      2.45203,50.00000,30.00000,1.752120e-08,0.86515,4
658.12201,334.17917,      5.97956,      2.45203,50.00000,30.00000,1.749678e-08,0.86510,4
659.73798,334.25917,      5.91703,      2.46585,50.00000,30.00000,1.749678e-08,0.86510,4
661.35498,334.33917,      5.85580,      2.47947,50.00000,30.00000,1.752074e-08,0.86506,4
662.98102,334.41917,      5.79654,      2.50020,50.00000,30.00000,1.752074e-08,0.86506,4
664.60199,334.49917,      5.73364,      2.50711,50.00000,30.00000,1.750214e-08,0.86501,4
666.22803,334.57917,      5.67515,      2.53476,50.00000,30.00000,1.750214e-08,0.86501,4
667.84100,334.65917,      5.61266,      2.50711,50.00000,30.00000,1.750214e-08,0.86501,4
669.46301,334.73917,      5.55339,      2.53699,50.00000,30.00000,1.755905e-08,0.86496,4
671.08197,334.81917,      5.49140,      2.54390,50.00000,30.00000,1.755905e-08,0.86496,4
672.69202,334.89917,      5.42883,      2.56463,50.00000,30.00000,1.754945e-08,0.86491,4
674.32397,334.97917,      5.36676,      2.56463,50.00000,30.00000,1.754945e-08,0.86491,4
675.93799,335.05917,      5.30530,      2.59228,50.00000,30.00000,1.750651e-08,0.86486,4
677.55603,335.13917,      5.24240,      2.59228,50.00000,30.00000,1.750651e-08,0.86486,4
679.17401,335.21917,      5.18051,      2.59228,50.00000,30.00000,1.754522e-08,0.86482,4
680.79102,335.29917,      5.11778,      2.61992,50.00000,30.00000,1.754522e-08,0.86482,4
682.40601,335.37917,      5.05575,      2.61992,50.00000,30.00000,1.758392e-08,0.86476,4
684.01801,335.45917,      4.99442,      2.61992,50.00000,30.00000,1.758392e-08,0.86476,4
685.64697,335.53917,      4.93044,      2.64736,50.00000,30.00000,1.754156e-08,0.86471,4
687.25800,335.61917,      4.86994,      2.65427,50.00000,30.00000,1.754156e-08,0.86471,4
688.87402,335.69917,      4.80766,      2.67500,50.00000,30.00000,1.752985e-08,0.86466,4
690.49200,335.77917,      4.74581,      2.68191,50.00000,30.00000,1.752985e-08,0.86466,4
692.09998,335.85917,      4.68181,      2.70264,50.00000,30.00000,1.752634e-08,0.86461,4
693.71802,335.93917,      4.62459,      2.70264,50.00000,30.00000,1.752634e-08,0.86461,4
695.33600,336.01917,      4.56559,      2.70955,50.00000,30.00000,1.752634e-08,0.86461,4
696.96198,336.09917,      4.50738,      2.73028,50.00000,30.00000,1.748185e-08,0.86456,4
698.58398,336.17917,      4.44958,      2.75772,50.00000,30.00000,1.748185e-08,0.86456,4
700.20502,336.25917,      4.38999,      2.75772,50.00000,30.00000,1.754560e-08,0.86451,4
701.81897,336.33917,      4.33304,      2.78537,50.00000,30.00000,1.754560e-08,0.86451,4
703.42700,336.41917,      4.27524,      2.78537,50.00000,30.00000,1.751891e-08,0.86446,4
705.04901,336.49917,      4.22018,      2.81301,50.00000,30.00000,1.751891e-08,0.86446,4
706.66101,336.57917,      4.16136,      2.80610,50.00000,30.00000,1.752116e-08,0.86441,4
708.28003,336.65917,      4.10559,      2.83374,50.00000,30.00000,1.752116e-08,0.86441,4
709.89697,336.73917,      4.05027,      2.83374,50.00000,30.00000,1.753585e-08,0.86436,4
711.51099,336.81917,      3.99154,      2.83374,50.00000,30.00000,1.753585e-08,0.86436,4
713.12701,336.89917,      3.93359,      2.86118,50.00000,30.00000,1.753450e-08,0.86430,4
714.74500,336.97917,      3.87771,      2.86118,50.00000,30.00000,1.753450e-08,0.86430,4
716.36603,337.05917,      3.82296,      2.86118,50.00000,30.00000,1.751956e-08,0.86427,4
717.97699,337.13917,      3.76864,      2.88882,50.00000,30.00000,1.751956e-08,0.86427,4
719.58698,337.21917,      3.71382,      2.88882,50.00000,30.00000,1.750628e-08,0.86422,4
721.20801,337.29917,      3.66146,      2.90264,50.00000,30.00000,1.750628e-08,0.86422,4
722.82098,337.37917,      3.60857,      2.91646,50.00000,30.00000,1.750628e-08,0.86422,4
724.44202,337.45917,      3.55620,      2.94411,50.00000,30.00000,1.751799e-08,0.86416,4
726.05200,337.53917,      3.50460,      2.94411,50.00000,30.00000,1.751799e-08,0.86416,4
727.65997,337.61917,      3.45185,      2.94411,50.00000,30.00000,1.752357e-08,0.86412,4
729.27600,337.69917,      3.39470,      2.97154,50.00000,30.00000,1.752357e-08,0.86412,4
730.89801,337.77917,      3.34395,      2.97154,50.00000,30.00000,1.755210e-08,0.86407,4
732.50403,337.85917,      3.29496,      2.99919,50.00000,30.00000,1.755210e-08,0.86407,4
734.11401,337.93917,      3.24517,      3.01301,50.00000,30.00000,1.749987e-08,0.86402,4
735.72998,338.01917,      3.19622,      3.01301,50.00000,30.00000,1.749987e-08,0.86402,4
737.34497,338.09917,      3.14548,      3.01301,50.00000,30.00000,1.753100e-08,0.86396,4
738.96198,338.17917,      3.09788,      3.02683,50.00000,30.00000,1.753100e-08,0.86396,4
740.58301,338.25917,      3.04783,      3.05447,50.00000,30.00000,1.752699e-08,0.86391,4
742.18799,338.33917,      2.99924,      3.05447,50.00000,30.00000,1.752699e-08,0.86391,4
743.81299,338.41917,      2.95254,      3.05447,50.00000,30.00000,1.751233e-08,0.86387,4
745.41400,338.49917,      2.90099,      3.05447,50.00000,30.00000,1.751233e-08,0.86387,4
747.03003,338.57917,      2.85264,      3.08211,50.00000,30.00000,1.753093e-08,0.86383,4
748.64899,338.65917,      2.80648,      3.10955,50.00000,30.00000,1.753093e-08,0.86383,4
750.25702,338.73917,      2.75749,      3.10955,50.00000,30.00000,1.753093e-08,0.86383,4
751.87903,338.81917,      2.71139,      3.10955,50.00000,30.00000,1.750023e-08,0.86377,4
753.49200,338.89917,      2.66312,      3.13720,50.00000,30.00000,1.750023e-08,0.86377,4
755.09998,338.97917,      2.61469,      3.13720,50.00000,30.00000,1.754009e-08,0.86372,4
756.70898,339.05917,      2.56612,      3.13720,50.00000,30.00000,1.754009e-08,0.86372,4
758.31201,339.13917,      2.52041,      3.16484,50.00000,30.00000,1.753000e-08,0.86367,4
759.92200,339.21917,      2.47189,      3.19248,50.00000,30.00000,1.753000e-08,0.86367,4
761.53998,339.29917,      2.42662,      3.19248,50.00000,30.00000,1.755044e-08,0.86362,4
763.15503,339.37917,      2.38524,      3.19248,50.00000,30.00000,1.755044e-08,0.86362,4
764.77100,339.45917,      2.33801,      3.19248,50.00000,30.00000,1.753477e-08,0.86357,4
766.38397,339.53917,      2.29536,      3.21992,50.00000,30.00000,1.753477e-08,0.86357,4
767.99298,339.61917,      2.25292,      3.21301,50.00000,30.00000,1.750413e-08,0.86352,4
769.60901,339.69917,      2.20358,      3.21301,50.00000,30.00000,1.750413e-08,0.86352,4
771.21997,339.77917,      2.16121,      3.24065,50.00000,30.00000,1.751702e-08,0.86348,4
772.83398,339.85917,      2.11533,      3.26138,50.00000,30.00000,1.751702e-08,0.86348,4
774.44000,339.93917,      2.06998,      3.26829,50.00000,30.00000,1.751702e-08,0.86348,4
776.04901,340.01917,      2.02586,      3.26829,50.00000,30.00000,1.753558e-08,0.86342,4
777.66199,340.09917,      1.98060,      3.29593,50.00000,30.00000,1.753558e-08,0.86342,4
779.27197,340.17917,      1.93931,      3.30976,50.00000,30.00000,1.752374e-08,0.86338,4
780.88501,340.25917,      1.89138,      3.30976,50.00000,30.00000,1.752374e-08,0.86338,4
782.49103,340.33917,      1.85155,      3.30976,50.00000,30.00000,1.752489e-08,0.86333,4
784.10901,340.41917,      1.80749,      3.32337,50.00000,30.00000,1.752489e-08,0.86333,4
785.72400,340.49917,      1.76330,      3.35102,50.00000,30.00000,1.753176e-08,0.86328,4
787.33502,340.57917,      1.71793,      3.32337,50.00000,30.00000,1.753176e-08,0.86328,4
788.95001,340.65917,      1.66761,      3.35102,50.00000,30.00000,1.750343e-08,0.86323,4
790.56000,340.73917,      1.62267,      3.35102,50.00000,30.00000,            ,0.44867,4
792.15997,340.81917,      1.57897,      3.37866,50.00000,30.00000,            ,0.44803,4
793.77502,340.89917,      1.53585,      3.37866,50.00000,30.00000,            ,0.44738,4
794.48499,340.93417,      1.51255,      3.37866,50.00000,30.00000,            ,0.44710,4