File: data/TGA/005d-L_M/ExpDat_2025_07_19_SL_PS_005d-L3_isothermal.csv
#EXPORTTYPE:                 ,DATA ALL
#FILE:                       ,2025_07_19_SL_PS_Tosoh_L3_isothermal.ngb-ss5
#FORMAT:                     ,NETZSCH5
#FTYPE:                      ,ASCII
#IDENTITY:                   ,PS-005d-L3
#DECIMAL:                    ,POINT
#SEPARATOR:                  ,COMMA
#MTYPE:                      ,DSC
#INSTRUMENT:                 ,NETZSCH STA 449F5
#PROJECT:                    ,
#DATE/TIME:                  ,7/19/2025 1:16:54 PM (UTC-4)
#CORR. FILE:                 ,
#TEMPCAL:                    ,05-05-2025 14:38
#SENSITIVITY:                ,28-06-2023 13:53
#LABORATORY:                 ,Tran/AAG
#OPERATOR:                   ,Stan
#REMARK:                     ,2025_03_29_SL_005d_M1_isothermal
#SAMPLE:                     ,PS-005d-L3
#SAMPLE MASS /mg:            ,4.79
#MATERIAL:                   ,Polystyrene
#REFERENCE:                  ,
#REFERENCE MASS /mg:         ,0
#TYPE OF CRUCIBLE:           ,Al2O3 85 ‘l, open
#SAMPLE CRUCIBLE MASS /mg:   ,0
#REFERENCE CRUCIBLE MASS /mg:,0
#DSC RANGE /‘V:              ,5000
#TG RANGE /mg:               ,35000
#TAU-R:                      ,---
#CORR. CODE:                 ,000
#EXO:                        ,-1
#RANGE:                      ,30›C....800›C/0.0....20.0K/min
#SEGMENT:                    ,S1-5/5
#SEG. 1:                     ,30›C/10.0(K/min)/100›C
#SEG. 2:                     ,100›C/00:10/100›C
#SEG. 3:                     ,100›C/5.0(K/min)/300›C
#SEG. 4:                     ,300›C/20:00/300›C
#SEG. 5:                     ,300›C/20.0(K/min)/800›C

##Temp./›C,Time/min,DSC/(mW/mg),Mass/%,Gas Flow(purge2)/(ml/min),Gas Flow(protective)/(ml/min),TIC(scan:1)/A,Sensit./(uV/mW),Segment
 29.49100,   0.00000,      0.60661,    100.00000,50.00000,50.00000,            ,0.92346,1
 33.36200,   1.36000,      0.74198,     91.80438,50.00000,50.00000,1.782754e-08,0.92358,1
 40.64300,   2.72000,      1.38970,     93.79541,50.00000,50.00000,1.783977e-08,0.92372,1
 50.82000,   4.08000,      2.07542,     94.99061,50.00000,50.00000,1.786190e-08,0.92389,1
 64.26100,   5.44000,      2.85566,     96.06284,50.00000,50.00000,1.782793e-08,0.92409,1
 79.81900,   6.80000,      3.51077,     96.87766,50.00000,50.00000,1.786054e-08,0.92431,1
 88.78900,   7.56083,      3.64389,     96.84217,50.00000,50.00000,1.786072e-08,0.92446,2
 95.17100,   8.24083,      3.12975,     95.95407,50.00000,50.00000,1.787946e-08,0.92458,2
 99.60100,   8.92083,      2.38088,     95.10856,50.00000,50.00000,1.789734e-08,0.92470,2
102.96200,   9.60083,      1.82821,     94.46848,50.00000,50.00000,1.788015e-08,0.92483,2
105.70900,  10.28083,      1.47737,     93.95365,50.00000,50.00000,1.787395e-08,0.92495,2
107.79000,  10.96083,      1.14466,     93.38434,50.00000,50.00000,1.788973e-08,0.92506,2
109.12800,  11.64083,      0.78551,     92.76326,50.00000,50.00000,1.787237e-08,0.92518,2
109.84200,  12.32083,      0.45442,     92.19395,50.00000,50.00000,1.785616e-08,0.92530,2
110.11000,  13.00083,      0.18872,     91.67912,50.00000,50.00000,1.788470e-08,0.92541,2
110.02800,  13.68083,-1.786574e-02,     91.18789,50.00000,50.00000,1.786866e-08,0.92552,2
109.66400,  14.36083,     -0.17933,     90.78643,50.00000,50.00000,1.784710e-08,0.92563,2
109.10500,  15.04083,     -0.30432,     90.38017,50.00000,50.00000,1.785651e-08,0.92573,2
108.39300,  15.72083,     -0.39509,     90.04238,50.00000,50.00000,1.785177e-08,0.92582,2
107.59100,  16.40083,     -0.45427,     89.71879,50.00000,50.00000,1.787573e-08,0.92591,2
106.60500,  17.20083,     -0.48601,     89.40710,50.00000,50.00000,1.784724e-08,0.92600,3
106.68300,  18.56083,      0.10916,     90.02818,50.00000,50.00000,1.785500e-08,0.92612,3
109.46300,  19.92083,      0.76791,     90.60919,50.00000,50.00000,1.788524e-08,0.92619,3
114.02300,  21.28083,      1.30563,     91.15950,50.00000,50.00000,1.786952e-08,0.92620,3
120.26800,  22.64083,      1.79562,     91.66973,50.00000,50.00000,1.783990e-08,0.92613,3
127.55800,  24.00083,      2.13490,     91.92484,50.00000,50.00000,1.786593e-08,0.92600,3
135.45000,  25.36083,      2.35238,     92.03820,50.00000,50.00000,1.787132e-08,0.92578,3
143.53000,  26.72083,      2.47034,     92.04990,50.00000,50.00000,1.785366e-08,0.92547,3
151.55901,  28.08083,      2.52328,     92.04990,50.00000,50.00000,1.786653e-08,0.92507,3
159.37601,  29.44083,      2.52910,     92.10898,50.00000,50.00000,1.783794e-08,0.92457,3
166.92799,  30.80083,      2.51121,     92.12317,50.00000,50.00000,1.783114e-08,0.92428,3
174.25400,  32.16083,      2.49292,     92.15157,50.00000,50.00000,1.783985e-08,0.92398,3
181.37900,  33.52083,      2.47920,     92.20104,50.00000,50.00000,1.783956e-08,0.92367,3
188.38300,  34.88083,      2.47473,     92.21294,50.00000,50.00000,1.780668e-08,0.92336,3
195.27299,  36.24083,      2.47780,     92.25553,50.00000,50.00000,1.782123e-08,0.92304,3
202.11400,  37.60083,      2.49135,     92.29081,50.00000,50.00000,1.779810e-08,0.92270,3
208.90500,  38.96083,      2.50689,     92.31921,50.00000,50.00000,1.780669e-08,0.92240,3
215.68401,  40.32083,      2.52969,     92.35470,50.00000,50.00000,1.778899e-08,0.92212,3
222.43700,  41.68083,      2.54920,     92.35699,50.00000,50.00000,1.779196e-08,0.92186,3
229.17700,  43.04083,      2.57515,     92.44196,50.00000,50.00000,1.783929e-08,0.92160,3
235.96100,  44.40083,      2.60021,     92.47035,50.00000,50.00000,1.781363e-08,0.92137,3
242.72400,  45.76083,      2.62497,     92.52463,50.00000,50.00000,1.777458e-08,0.92115,3
249.49500,  47.12083,      2.64756,     92.53883,50.00000,50.00000,1.779498e-08,0.92094,3
256.26801,  48.48083,      2.67042,     92.62401,50.00000,50.00000,1.780146e-08,0.92073,3
263.03799,  49.84083,      2.69487,     92.65219,50.00000,50.00000,1.774258e-08,0.92053,3
269.82001,  51.20083,      2.71472,     92.69478,50.00000,50.00000,1.779184e-08,0.92034,3
276.60599,  52.56083,      2.73850,     92.75846,50.00000,50.00000,1.776434e-08,0.92015,3
283.37201,  53.92083,      2.75389,     92.73737,50.00000,50.00000,1.777999e-08,0.91997,3
290.14700,  55.28083,      2.77797,     92.76555,50.00000,50.00000,1.777086e-08,0.91980,3
296.90701,  56.64083,      2.79674,     92.73737,50.00000,50.00000,1.775901e-08,0.91962,3
303.20499,  59.56083,      0.52665,     93.59708,50.00000,31.00000,1.776777e-08,0.91928,4
302.78799,  62.96083,     -0.14393,     92.90960,50.00000,30.00000,1.774873e-08,0.91895,4
301.46399,  66.36083,     -0.14249,     92.42547,50.00000,30.00000,1.774891e-08,0.91870,4
300.65500,  69.76083,-6.236690e-02,     92.03111,50.00000,30.00000,1.772271e-08,0.91850,4
300.28400,  73.16083,-1.477526e-02,     91.66263,50.00000,30.00000,1.771714e-08,0.91837,4
300.13400,  76.56083, 1.315372e-02,     91.34384,50.00000,30.00000,1.777260e-08,0.91829,4
300.05499,  79.96083, 2.104398e-02,     91.02965,50.00000,30.00000,1.775181e-08,0.91825,4
300.02600,  83.36083, 2.610174e-02,     90.76743,50.00000,30.00000,1.769496e-08,0.91825,4
300.02499,  86.76083, 2.751808e-02,     90.47704,50.00000,30.00000,1.773139e-08,0.91828,4
300.00101,  90.16083, 2.812429e-02,     90.23612,50.00000,30.00000,1.774290e-08,0.91834,4
300.00500,  93.56083, 3.196877e-02,     90.03758,50.00000,30.00000,1.771080e-08,0.91843,4
300.00699,  96.96083, 3.358753e-02,     89.78246,50.00000,30.00000,1.772402e-08,0.91853,4
300.00900, 100.36083, 3.702730e-02,     89.58184,50.00000,30.00000,1.773136e-08,0.91865,4
300.01300, 103.76083, 3.439711e-02,     89.41879,50.00000,30.00000,1.770435e-08,0.91877,4
300.01099, 107.16083, 3.480170e-02,     89.21566,50.00000,30.00000,1.769791e-08,0.91891,4
300.03500, 110.56083, 3.884951e-02,     89.04572,50.00000,30.00000,1.769684e-08,0.91905,4
300.01901, 113.96083, 3.864644e-02,     88.88267,50.00000,30.00000,1.772130e-08,0.91920,4
300.01001, 117.36083, 3.763435e-02,     88.67724,50.00000,30.00000,1.768872e-08,0.91939,4
300.01001, 120.76083, 3.601567e-02,     88.52610,50.00000,30.00000,1.767979e-08,0.91924,4
300.00601, 124.16083, 3.662250e-02,     88.33236,50.00000,30.00000,1.771542e-08,0.91881,4
300.01501, 127.56083, 3.702756e-02,     88.18351,50.00000,30.00000,1.771436e-08,0.91820,4
300.01999, 130.96083, 3.803947e-02,     88.04196,50.00000,30.00000,1.769988e-08,0.91737,4
300.01300, 134.36083, 3.439711e-02,     87.87182,50.00000,30.00000,1.771918e-08,0.91622,4
300.01599, 137.76083, 3.763462e-02,     87.69457,50.00000,30.00000,1.768212e-08,0.91489,4
300.01401, 141.16083, 3.743219e-02,     87.52463,50.00000,30.00000,1.768072e-08,0.91334,4
300.02100, 144.56083, 3.480211e-02,     87.38288,50.00000,30.00000,1.770533e-08,0.91159,4
300.02100, 147.96083, 3.682549e-02,     87.23173,50.00000,30.00000,1.768839e-08,0.90967,4
300.01599, 151.36083, 3.743228e-02,     87.08058,50.00000,30.00000,1.770657e-08,0.90759,4
300.01700, 154.76083, 3.500428e-02,     86.90104,50.00000,30.00000,1.767844e-08,0.90540,4
300.00601, 158.16083, 4.026451e-02,     86.75929,50.00000,30.00000,1.771220e-08,0.90310,4
300.03400, 161.56083, 3.540967e-02,     86.63173,50.00000,30.00000,1.769899e-08,0.90073,4
300.01801, 164.96083, 3.581367e-02,     86.43340,50.00000,30.00000,1.769608e-08,0.89829,4
300.02200, 168.36083, 3.399280e-02,     86.28225,50.00000,30.00000,1.767781e-08,0.89582,4
300.01401, 171.76083, 3.338547e-02,     86.13820,50.00000,30.00000,1.769724e-08,0.89330,4
300.01099, 175.16083, 3.621804e-02,     85.97056,50.00000,30.00000,1.767603e-08,0.89075,4
300.01999, 178.56083, 3.540908e-02,     85.81232,50.00000,30.00000,1.768354e-08,0.88816,4
300.00201, 181.96083, 3.439666e-02,     85.63507,50.00000,30.00000,1.767279e-08,0.88555,4
300.01700, 185.36083, 3.480194e-02,     85.45094,50.00000,30.00000,1.768046e-08,0.88289,4
300.00900, 188.76083, 3.217126e-02,     85.30919,50.00000,30.00000,1.770720e-08,0.88006,4
300.02200, 192.16083, 3.277877e-02,     85.15094,50.00000,30.00000,1.763651e-08,0.87732,4
300.01999, 195.56083, 2.954129e-02,     85.00919,50.00000,30.00000,1.766101e-08,0.87454,4
300.03101, 198.96083, 2.954168e-02,     84.83674,50.00000,30.00000,1.763762e-08,0.87173,4
300.01999, 202.36083, 2.812493e-02,     84.67140,50.00000,30.00000,1.765575e-08,0.86886,4
300.00699, 205.76083, 3.439686e-02,     84.50856,50.00000,30.00000,1.767444e-08,0.86595,4
300.00699, 209.16083, 3.237352e-02,     84.35261,50.00000,30.00000,1.769795e-08,0.86299,4
300.01199, 212.56083, 2.792232e-02,     84.19207,50.00000,30.00000,1.764905e-08,0.85999,4
300.01401, 215.96083, 2.792239e-02,     84.04802,50.00000,30.00000,1.768357e-08,0.85694,4
300.01401, 219.36083, 3.338547e-02,     83.87307,50.00000,30.00000,1.767411e-08,0.85385,4
300.01401, 222.76083, 2.792239e-02,     83.68894,50.00000,30.00000,1.769976e-08,0.85070,4
300.01001, 226.16083, 2.670825e-02,     83.54008,50.00000,30.00000,1.767713e-08,0.84753,4
300.01801, 229.56083, 2.873187e-02,     83.37244,50.00000,30.00000,1.768375e-08,0.84429,4
300.01901, 232.96083, 3.014827e-02,     83.25908,50.00000,30.00000,1.765621e-08,0.84102,4
300.00601, 236.36083, 2.387544e-02,     83.08894,50.00000,30.00000,1.767492e-08,0.83753,4
300.01501, 239.76083, 2.630373e-02,     82.90480,50.00000,30.00000,1.769668e-08,0.83418,4
300.01099, 243.16083, 2.529193e-02,     82.74885,50.00000,30.00000,1.765549e-08,0.83079,4
300.00601, 246.56083, 2.549412e-02,     82.60710,50.00000,30.00000,1.766712e-08,0.82738,4
300.01001, 249.96083, 2.428023e-02,     82.43006,50.00000,30.00000,1.767611e-08,0.82391,4
300.01501, 253.36083, 2.488738e-02,     82.26701,50.00000,30.00000,1.767943e-08,0.82042,4
300.00900, 256.76083, 2.610121e-02,     82.11837,50.00000,30.00000,1.769340e-08,0.81690,4
300.01901, 260.16083, 2.165010e-02,     81.92923,50.00000,30.00000,1.768324e-08,0.81335,4
300.02600, 263.56083, 2.144794e-02,     81.75219,50.00000,30.00000,1.770888e-08,0.80959,4
300.02600, 266.96083, 2.468536e-02,     81.62234,50.00000,30.00000,1.768439e-08,0.80598,4
300.01401, 270.36083, 2.630370e-02,     81.46159,50.00000,30.00000,1.771067e-08,0.80237,4
300.01501, 273.76083, 2.245934e-02,     81.27745,50.00000,30.00000,1.768132e-08,0.79872,4
300.01901, 277.16083, 2.124542e-02,     81.12630,50.00000,30.00000,1.770380e-08,0.79505,4
300.01099, 280.56083, 1.760318e-02,     80.97516,50.00000,30.00000,1.769318e-08,0.79137,4
300.01300, 283.96083, 2.043593e-02,     80.79791,50.00000,30.00000,1.771140e-08,0.78652,4
300.01801, 287.36083, 1.881735e-02,     80.65386,50.00000,30.00000,1.769650e-08,0.78428,4
300.01300, 290.76083, 2.164994e-02,     80.46722,50.00000,30.00000,1.775346e-08,0.78410,4
300.01599, 294.16083, 1.760329e-02,     80.32317,50.00000,30.00000,1.770953e-08,0.78480,4
300.01801, 297.56083, 1.901969e-02,     80.15324,50.00000,30.00000,1.770571e-08,0.78559,4
300.01401, 300.96083, 1.517521e-02,     79.96889,50.00000,30.00000,1.769241e-08,0.78617,4
300.00299, 304.36083, 1.679368e-02,     79.80605,50.00000,30.00000,1.769662e-08,0.78656,4
300.02200, 307.76083, 1.760341e-02,     79.62881,50.00000,30.00000,1.770218e-08,0.78681,4
300.03201, 311.16083, 1.477086e-02,     79.47307,50.00000,30.00000,1.776228e-08,0.78697,4
300.01599, 314.56083, 1.234254e-02,     79.30772,50.00000,30.00000,1.774379e-08,0.78705,4
300.00699, 317.96083, 1.578209e-02,     79.13528,50.00000,30.00000,1.770247e-08,0.78711,4
300.00699, 321.36083, 1.294941e-02,     78.96514,50.00000,30.00000,1.769344e-08,0.78716,4
300.01901, 324.76083, 1.497297e-02,     78.81879,50.00000,30.00000,1.772395e-08,0.78717,4
300.01599, 328.16083, 9.914495e-03,     78.64635,50.00000,30.00000,1.771739e-08,0.78718,4
300.01501, 331.56083, 8.700466e-03,     78.46910,50.00000,30.00000,1.772380e-08,0.78718,4
300.02301, 334.96083, 1.396134e-02,     78.30626,50.00000,30.00000,1.769104e-08,0.78718,4
300.02100, 338.36083, 1.052157e-02,     78.14092,50.00000,30.00000,1.773952e-08,0.78719,4
300.01901, 341.76083, 1.031921e-02,     77.97557,50.00000,30.00000,1.775926e-08,0.78719,4
300.00900, 345.16083, 8.902739e-03,     77.81962,50.00000,30.00000,1.778373e-08,0.78720,4
300.01199, 348.56083, 1.153313e-02,     77.64718,50.00000,30.00000,1.773158e-08,0.78719,4
300.00800, 351.96083, 5.867707e-03,     77.47015,50.00000,30.00000,1.772571e-08,0.78719,4
300.01001, 355.36083, 1.072377e-02,     77.30710,50.00000,30.00000,1.773731e-08,0.78720,4
300.01501, 358.76083, 5.058410e-03,     77.13466,50.00000,30.00000,1.777043e-08,0.78720,4
300.01300, 362.16083, 4.451390e-03,     76.96472,50.00000,30.00000,1.773836e-08,0.78720,4
300.02100, 365.56083, 8.295852e-03,     76.80167,50.00000,30.00000,1.773725e-08,0.78719,4
300.01401, 368.96083, 5.058404e-03,     76.64572,50.00000,30.00000,1.773974e-08,0.78719,4
300.01700, 372.36083, 6.879454e-03,     76.50418,50.00000,30.00000,1.773211e-08,0.78719,4
300.01300, 375.76083, 6.070078e-03,     76.30334,50.00000,30.00000,1.774904e-08,0.78719,4
300.00699, 379.16083, 1.416341e-03,     76.15449,50.00000,30.00000,1.771988e-08,0.78719,4
300.00601, 382.56083, 4.451354e-03,     75.95616,50.00000,30.00000,1.775710e-08,0.78720,4
300.01300, 385.96083, 3.237375e-03,     75.80960,50.00000,30.00000,1.777080e-08,0.78719,4
300.01501, 389.36083, 2.225701e-03,     75.63257,50.00000,30.00000,1.772188e-08,0.78720,4
300.02399, 392.76083, 1.618708e-03,     75.48372,50.00000,30.00000,1.779944e-08,0.78719,4
300.00800, 396.16083,-1.618678e-03,     75.27119,50.00000,30.00000,1.776204e-08,0.78718,4
300.00699, 399.56083,-1.821010e-03,     75.12004,50.00000,30.00000,1.775831e-08,0.78719,4
300.01599, 402.96083, 3.439723e-03,     74.99248,50.00000,30.00000,1.776232e-08,0.78719,4
300.02802, 406.36083,-2.023395e-03,     74.80125,50.00000,30.00000,1.776793e-08,0.78720,4
300.02200, 409.76083,-6.070142e-04,     74.65240,50.00000,30.00000,1.778909e-08,0.78719,4
300.02100, 413.16083,-4.451433e-03,     74.46347,50.00000,30.00000,1.776057e-08,0.78719,4
300.02802, 416.56083,-5.260827e-03,     74.30042,50.00000,30.00000,1.774394e-08,0.78720,4
300.01001, 419.96083,-6.879397e-03,     74.12338,50.00000,30.00000,1.777346e-08,0.78720,4
300.01599, 423.36083,-2.023366e-03,     73.94614,50.00000,30.00000,1.775530e-08,0.78719,4
300.01300, 426.76083,-7.081757e-03,     73.78789,50.00000,30.00000,1.781137e-08,0.78718,4
300.02301, 430.16083,-1.052159e-02,     73.62505,50.00000,30.00000,1.778606e-08,0.78718,4
300.01901, 433.56083,-5.867784e-03,     73.44071,50.00000,30.00000,1.777217e-08,0.78720,4
300.01401, 436.96083,-8.700455e-03,     73.28017,50.00000,30.00000,1.775398e-08,0.78719,4
300.02301, 440.36083,-1.092627e-02,     73.10292,50.00000,30.00000,1.777656e-08,0.78720,4
300.01700, 443.76083,-9.105160e-03,     72.93299,50.00000,30.00000,1.773026e-08,0.78719,4
300.02100, 447.16083,-1.072391e-02,     72.78413,50.00000,30.00000,1.776966e-08,0.78720,4
300.02600, 450.56083,-1.214034e-02,     72.62818,50.00000,30.00000,1.779322e-08,0.78720,4
300.00500, 453.96083,-1.274704e-02,     72.43695,50.00000,30.00000,1.775692e-08,0.78720,4
300.00500, 457.36083,-1.234237e-02,     72.29290,50.00000,31.00000,1.780989e-08,0.78718,4
300.01901, 460.76083,-1.092622e-02,     72.12985,50.00000,31.00000,1.776564e-08,0.78719,4
300.01700, 464.16083,-1.456826e-02,     71.93862,50.00000,31.00000,1.779174e-08,0.78718,4
300.01099, 467.56083,-1.557983e-02,     71.81106,50.00000,31.00000,1.775637e-08,0.78719,4
300.01199, 470.96083,-1.740087e-02,     71.63152,50.00000,31.00000,1.780417e-08,0.78718,4
300.02899, 474.36083,-1.477080e-02,     71.46388,50.00000,31.00000,1.779753e-08,0.78718,4
300.01099, 477.76083,-2.084055e-02,     71.30084,50.00000,31.00000,1.779346e-08,0.78719,4
300.02100, 481.16083,-1.800807e-02,     71.12129,50.00000,31.00000,1.783121e-08,0.78719,4
300.01999, 484.56083,-1.821038e-02,     70.95136,50.00000,31.00000,1.778519e-08,0.78720,4
300.01001, 487.96083,-1.780550e-02,     70.80251,50.00000,31.00000,1.783615e-08,0.78719,4
300.02301, 491.36083,-1.780577e-02,     70.62547,50.00000,31.00000,1.776830e-08,0.78720,4
300.01501, 494.76083,-1.901962e-02,     70.49081,50.00000,31.00000,1.777849e-08,0.78720,4
300.01801, 498.16083,-2.286410e-02,     70.32067,50.00000,31.00000,1.778369e-08,0.78720,4
300.01901, 501.56083,-2.144776e-02,     70.12944,50.00000,31.00000,1.779669e-08,0.78719,4
300.00699, 504.96083,-2.266146e-02,     69.97349,50.00000,31.00000,1.780844e-08,0.78720,4
300.02399, 508.36083,-2.205490e-02,     69.81044,50.00000,31.00000,1.774648e-08,0.78719,4
300.01999, 511.76083,-2.144778e-02,     69.61211,50.00000,31.00000,1.775165e-08,0.78719,4
300.00900, 515.16083,-2.003116e-02,     69.48935,50.00000,31.00000,1.779273e-08,0.78719,4
300.01599, 518.56083,-2.589909e-02,     69.28852,50.00000,31.00000,1.781270e-08,0.78720,4
300.01001, 521.96083,-2.771992e-02,     69.12568,50.00000,31.00000,1.782477e-08,0.78719,4
300.02399, 525.36083,-2.488764e-02,     68.96973,50.00000,31.00000,1.780334e-08,0.78720,4
300.01801, 528.76083,-2.569681e-02,     68.80668,50.00000,31.00000,1.777621e-08,0.78720,4
300.00000, 532.16083,-2.630326e-02,     68.62255,50.00000,31.00000,1.783350e-08,0.78720,4
300.01001, 535.56083,-2.488723e-02,     68.50209,50.00000,31.00000,1.778129e-08,0.78719,4
300.01401, 538.96083,-2.387567e-02,     68.31775,50.00000,31.00000,1.775135e-08,0.78719,4
300.01501, 542.36083,-2.893410e-02,     68.16200,50.00000,31.00000,1.779103e-08,0.78719,4
300.01700, 545.76083,-2.792249e-02,     68.00605,50.00000,31.00000,1.780794e-08,0.78719,4
300.01199, 549.16083,-2.751765e-02,     67.85720,50.00000,31.00000,1.779494e-08,0.78720,4
300.01700, 552.56083,-2.873184e-02,     67.67537,50.00000,31.00000,1.778723e-08,0.78720,4
300.02600, 555.96083,-3.116021e-02,     67.51253,50.00000,31.00000,1.774746e-08,0.78720,4
300.01501, 559.36083,-3.196915e-02,     67.36117,50.00000,31.00000,1.776045e-08,0.78719,4
300.01401, 562.76083,-3.196911e-02,     67.19123,50.00000,31.00000,1.777520e-08,0.78718,4
300.01599, 566.16083,-3.176685e-02,     67.03528,50.00000,31.00000,1.777556e-08,0.78719,4
300.01801, 569.56083,-3.338563e-02,     66.86534,50.00000,31.00000,1.779137e-08,0.78720,4
300.02200, 572.96083,-3.257643e-02,     66.65971,50.00000,30.00000,1.775747e-08,0.78720,4
300.01599, 576.36083,-3.439723e-02,     66.49687,50.00000,30.00000,1.778121e-08,0.78719,4
300.01801, 579.76083,-3.540900e-02,     66.34092,50.00000,30.00000,1.779357e-08,0.78718,4
300.03000, 583.16083,-3.399312e-02,     66.17098,50.00000,30.00000,1.779842e-08,0.78720,4
300.01199, 586.56083,-3.621809e-02,     66.01962,50.00000,30.00000,1.781962e-08,0.78719,4
300.00800, 589.96083,-3.500391e-02,     65.85198,50.00000,30.00000,1.780512e-08,0.78719,4
300.01901, 593.36083,-3.743241e-02,     65.68914,50.00000,30.00000,1.779990e-08,0.78720,4
300.02100, 596.76083,-3.824185e-02,     65.49770,50.00000,30.00000,1.781193e-08,0.78719,4
300.01999, 600.16083,-3.358804e-02,     65.37015,50.00000,30.00000,1.780083e-08,0.78720,4
300.02399, 603.56083,-4.006303e-02,     65.21441,50.00000,30.00000,1.778246e-08,0.78720,4
300.01199, 606.96083,-3.925312e-02,     65.04426,50.00000,30.00000,1.777740e-08,0.78718,4
300.02600, 610.36083,-3.682571e-02,     64.83883,50.00000,30.00000,1.782193e-08,0.78720,4
300.01801, 613.76083,-3.986041e-02,     64.68998,50.00000,30.00000,1.779109e-08,0.78718,4
300.02499, 617.16083,-4.208647e-02,     64.54363,50.00000,30.00000,1.777970e-08,0.78720,4
300.00900, 620.56083,-4.147867e-02,     64.40647,50.00000,30.00000,1.783878e-08,0.78720,4
300.02301, 623.96083,-4.188403e-02,     64.21524,50.00000,30.00000,1.780182e-08,0.78720,4
300.00800, 627.36083,-4.127628e-02,     64.07349,50.00000,30.00000,1.778928e-08,0.78720,4
300.01700, 630.76083,-3.965803e-02,     63.89645,50.00000,30.00000,1.781001e-08,0.78721,4
300.02600, 634.16083,-4.491926e-02,     63.72630,50.00000,30.00000,1.781238e-08,0.78720,4
300.01199, 637.56083,-4.653721e-02,     63.55386,50.00000,30.00000,1.781443e-08,0.78719,4
300.01901, 640.96083,-4.694227e-02,     63.41921,50.00000,30.00000,1.784205e-08,0.78719,4
300.01001, 644.36083,-4.532309e-02,     63.21148,50.00000,30.00000,1.779951e-08,0.78719,4
300.02100, 647.76083,-4.370497e-02,     63.07912,50.00000,30.00000,1.779211e-08,0.78718,4
300.03000, 651.16083,-4.613352e-02,     62.92338,50.00000,30.00000,1.778142e-08,0.78720,4
300.01999, 654.56083,-4.835869e-02,     62.76033,50.00000,30.00000,1.779285e-08,0.78719,4
300.01901, 657.96083,-4.714461e-02,     62.60919,50.00000,30.00000,1.777457e-08,0.78719,4
300.02802, 661.36083,-4.674043e-02,     62.44384,50.00000,30.00000,1.776418e-08,0.78720,4
300.02701, 664.76083,-5.139418e-02,     62.28079,50.00000,30.00000,1.781077e-08,0.78720,4
300.00601, 668.16083,-4.916722e-02,     62.10376,50.00000,30.00000,1.782461e-08,0.78719,4
300.02200, 671.56083,-5.139387e-02,     61.94071,50.00000,30.00000,1.782682e-08,0.78719,4
300.02399, 674.96083,-5.038230e-02,     61.77077,50.00000,30.00000,1.782706e-08,0.78718,4
300.01001, 678.36083,-5.361883e-02,     61.65741,50.00000,30.00000,1.780828e-08,0.78719,4
300.01700, 681.76083,-5.422628e-02,     61.45887,50.00000,30.00000,1.781424e-08,0.78719,4
300.01501, 685.16083,-5.280980e-02,     61.33132,50.00000,31.00000,1.779680e-08,0.78719,4
300.02499, 688.56083,-5.604784e-02,     61.14008,50.00000,31.00000,1.780121e-08,0.78719,4
300.01599, 691.96083,-5.604725e-02,     60.99833,50.00000,31.00000,1.781133e-08,0.78719,4
300.01801, 695.36083,-5.685673e-02,     60.82359,50.00000,31.00000,1.783304e-08,0.78719,4
300.01401, 698.76083,-5.665412e-02,     60.65344,50.00000,31.00000,1.782042e-08,0.78721,4
300.02802, 702.16083,-6.009484e-02,     60.49061,50.00000,31.00000,1.780513e-08,0.78720,4
300.01901, 705.56083,-5.645212e-02,     60.36305,50.00000,31.00000,1.781015e-08,0.78719,4
300.01501, 708.96083,-5.645186e-02,     60.17411,50.00000,31.00000,1.783348e-08,0.78718,4
300.02600, 712.36083,-5.766662e-02,     60.00397,50.00000,31.00000,1.785393e-08,0.78719,4
300.00400, 715.76083,-5.746279e-02,     59.84342,50.00000,31.00000,1.784491e-08,0.78719,4
300.01501, 719.16083,-5.908223e-02,     59.69457,50.00000,31.00000,1.788185e-08,0.78720,4
300.01700, 722.56083,-6.110574e-02,     59.53403,50.00000,31.00000,1.790486e-08,0.78719,4
300.01501, 725.96083,-5.867756e-02,     59.37098,50.00000,31.00000,1.782349e-08,0.78720,4
300.01901, 729.36083,-6.211757e-02,     59.19854,50.00000,31.00000,1.784220e-08,0.78718,4
300.01199, 732.76083,-6.009370e-02,     59.03570,50.00000,31.00000,1.786330e-08,0.78719,4
300.02701, 736.16083,-6.252284e-02,     58.87265,50.00000,31.00000,1.786906e-08,0.78718,4
300.00400, 739.56083,-6.494914e-02,     58.76868,50.00000,31.00000,1.786286e-08,0.78720,4
300.01401, 742.96083,-6.494991e-02,     58.59165,50.00000,31.00000,1.784474e-08,0.78720,4
300.01901, 746.36083,-6.555731e-02,     58.44990,50.00000,31.00000,1.781635e-08,0.78719,4
300.02399, 749.76083,-6.697406e-02,     58.26576,50.00000,31.00000,1.787677e-08,0.78718,4
300.02301, 753.16083,-6.677165e-02,     58.10042,50.00000,31.00000,1.782989e-08,0.78719,4
300.01801, 756.56083,-6.292685e-02,     57.97996,50.00000,31.00000,1.784437e-08,0.78718,4
300.03201, 759.96083,-6.474895e-02,     57.83111,50.00000,31.00000,1.787985e-08,0.78720,4
300.01300, 763.36083,-6.555684e-02,     57.65386,50.00000,31.00000,1.781801e-08,0.78719,4
300.01501, 766.76083,-6.474765e-02,     57.51232,50.00000,31.00000,1.787088e-08,0.78719,4
300.00800, 770.16083,-6.535412e-02,     57.33507,50.00000,31.00000,1.784423e-08,0.78720,4
300.01501, 773.56083,-6.393830e-02,     57.20042,50.00000,31.00000,1.788939e-08,0.78720,4
300.01999, 776.96083,-6.616439e-02,     57.03758,50.00000,31.00000,1.787350e-08,0.78719,4
300.02200, 780.36083,-6.839027e-02,     56.85324,50.00000,31.00000,1.787607e-08,0.78720,4
300.02100, 783.76083,-6.515278e-02,     56.73278,50.00000,31.00000,1.787190e-08,0.78720,4
300.01099, 787.16083,-6.859172e-02,     56.57704,50.00000,31.00000,1.787878e-08,0.78719,4
300.01199, 790.56083,-7.122216e-02,     56.43528,50.00000,31.00000,1.787394e-08,0.78717,4
300.02200, 793.96083,-7.061599e-02,     56.25574,50.00000,31.00000,1.786873e-08,0.78719,4
300.01599, 797.36083,-7.081783e-02,     56.12109,50.00000,31.00000,1.785235e-08,0.78719,4
299.99600, 800.76083,-7.041149e-02,     55.95094,50.00000,31.00000,1.784579e-08,0.78719,4
300.01001, 804.16083,-7.101966e-02,     55.78100,50.00000,31.00000,1.784458e-08,0.78719,4
300.01300, 807.56083,-7.324560e-02,     55.63925,50.00000,31.00000,1.789931e-08,0.78719,4
300.00400, 810.96083,-7.385183e-02,     55.46931,50.00000,31.00000,1.786978e-08,0.78720,4
300.01901, 814.36083,-7.243678e-02,     55.32046,50.00000,31.00000,1.788294e-08,0.78720,4
300.01099, 817.76083,-7.587579e-02,     55.17871,50.00000,31.00000,1.785974e-08,0.78720,4
300.00699, 821.16083,-7.506609e-02,     55.01566,50.00000,31.00000,1.788538e-08,0.78719,4
300.02600, 824.56083,-7.648416e-02,     54.87411,50.00000,31.00000,1.790207e-08,0.78720,4
300.01001, 827.96083,-7.628037e-02,     54.71816,50.00000,31.00000,1.785659e-08,0.78720,4
300.01801, 831.36083,-7.769745e-02,     54.57641,50.00000,31.00000,1.789186e-08,0.78719,4
300.01801, 834.76083,-7.688811e-02,     54.39937,50.00000,31.00000,1.789518e-08,0.78719,4
300.01599, 838.16083,-7.931596e-02,     54.25762,50.00000,31.00000,1.790166e-08,0.78719,4
300.01300, 841.56083,-7.972035e-02,     54.10167,50.00000,31.00000,1.791945e-08,0.78719,4
300.00900, 844.96083,-7.951764e-02,     53.95992,50.00000,31.00000,1.789209e-08,0.78719,4
300.01700, 848.36083,-7.951839e-02,     53.81127,50.00000,31.00000,1.789488e-08,0.78718,4
300.01700, 851.76083,-8.032774e-02,     53.67891,50.00000,31.00000,1.791785e-08,0.78719,4
300.02899, 855.16083,-7.790080e-02,     53.50877,50.00000,31.00000,1.789976e-08,0.78720,4
300.02399, 858.56083,-7.830502e-02,     53.36242,50.00000,31.00000,1.787945e-08,0.78719,4
300.01501, 861.96083,-8.052989e-02,     53.22547,50.00000,31.00000,1.791751e-08,0.78719,4
300.00900, 865.36083,-8.255266e-02,     53.09562,50.00000,31.00000,1.790301e-08,0.78720,4
300.01401, 868.76083,-8.235082e-02,     52.95136,50.00000,31.00000,1.788185e-08,0.78719,4
300.01599, 872.16083,-8.376737e-02,     52.82401,50.00000,31.00000,1.787512e-08,0.78719,4
300.02200, 875.56083,-8.437498e-02,     52.64676,50.00000,31.00000,1.792191e-08,0.78719,4
300.00800, 878.96083,-8.376657e-02,     52.54760,50.00000,31.00000,1.789786e-08,0.78719,4
300.01401, 882.36083,-8.093446e-02,     52.39165,50.00000,31.00000,1.787981e-08,0.78718,4
300.03000, 885.76083,-8.720853e-02,     52.22171,50.00000,31.00000,1.789485e-08,0.78719,4
300.02499, 889.16083,-8.720802e-02,     52.07516,50.00000,31.00000,1.789481e-08,0.78718,4
300.02200, 892.56083,-8.579134e-02,     51.94050,50.00000,31.00000,1.788370e-08,0.78719,4
300.02200, 895.96083,-8.781472e-02,     51.77516,50.00000,31.00000,1.789033e-08,0.78719,4
300.01700, 899.36083,-8.498149e-02,     51.62651,50.00000,31.00000,1.786853e-08,0.78719,4
300.01999, 902.76083,-9.165893e-02,     51.49415,50.00000,31.00000,1.789173e-08,0.78719,4
300.00601, 906.16083,-8.781306e-02,     51.34301,50.00000,31.00000,1.787213e-08,0.78719,4
300.00900, 909.56083,-8.740870e-02,     51.21545,50.00000,31.00000,1.787044e-08,0.78719,4
300.01901, 912.96083,-8.923077e-02,     51.07370,50.00000,31.00000,1.788194e-08,0.78719,4
300.02100, 916.36083,-8.963566e-02,     50.90376,50.00000,31.00000,1.785526e-08,0.78719,4
300.01700, 919.76083,-9.003991e-02,     50.74781,50.00000,31.00000,1.790102e-08,0.78719,4
300.01801, 923.16083,-9.509845e-02,     50.68413,50.00000,31.00000,1.790412e-08,0.78719,4
300.01501, 926.56083,-9.550279e-02,     50.48559,50.00000,31.00000,1.787655e-08,0.78719,4
300.02301, 929.96083,-8.923120e-02,     50.33695,50.00000,31.00000,1.788457e-08,0.78718,4
300.01300, 933.36083,-8.882547e-02,     50.23048,50.00000,31.00000,1.786869e-08,0.78719,4
300.01700, 936.76083,-9.145627e-02,     50.09603,50.00000,31.00000,1.786445e-08,0.78719,4
300.01099, 940.16083,-9.287197e-02,     49.95428,50.00000,31.00000,1.790765e-08,0.78719,4
300.01999, 943.56083,-9.530101e-02,     49.82672,50.00000,31.00000,1.787193e-08,0.78719,4
300.01901, 946.96083,-9.833596e-02,     49.67787,50.00000,31.00000,1.789811e-08,0.78719,4
300.01199, 950.36083,-9.590711e-02,     49.54322,50.00000,31.00000,1.785527e-08,0.78720,4
300.01501, 953.76083,-9.954951e-02,     49.40856,50.00000,31.00000,1.783290e-08,0.78719,4
300.01099, 957.16083,-9.691868e-02,     49.26701,50.00000,31.00000,1.787840e-08,0.78720,4
300.02200, 960.56083,-9.631293e-02,     49.12985,50.00000,31.00000,1.785410e-08,0.78719,4
300.02301, 963.96083,-9.793175e-02,     48.98831,50.00000,31.00000,1.784596e-08,0.78720,4
300.00400, 967.36083,     -0.10056,     48.84656,50.00000,31.00000,1.785463e-08,0.78719,4
300.01401, 970.76083,-9.691902e-02,     48.64802,50.00000,31.00000,1.793116e-08,0.78719,4
300.00900, 974.16083,-9.813246e-02,     48.53466,50.00000,31.00000,1.788726e-08,0.78719,4
300.01401, 977.56083,-9.833538e-02,     48.42129,50.00000,31.00000,1.789775e-08,0.78719,4
300.01199, 980.96083,-9.712113e-02,     48.26555,50.00000,31.00000,1.791374e-08,0.78719,4
300.02899, 984.36083,-9.813478e-02,     48.13800,50.00000,31.00000,1.786578e-08,0.78719,4
300.00500, 987.76083,     -0.10096,     47.99624,50.00000,31.00000,1.788584e-08,0.78718,4
300.02499, 991.16083,-9.934835e-02,     47.84739,50.00000,31.00000,1.790076e-08,0.78718,4
300.01901, 994.56083,     -0.10400,     47.70564,50.00000,31.00000,1.786816e-08,0.78720,4
300.01001, 997.96083,     -0.10056,     47.59228,50.00000,31.00000,1.788259e-08,0.78719,4
300.01099,1001.36083,     -0.10036,     47.45783,50.00000,31.00000,1.787214e-08,0.78720,4
300.01199,1004.76083,     -0.10137,     47.31608,50.00000,31.00000,1.789287e-08,0.78720,4
300.02301,1008.16083,     -0.10380,     47.17432,50.00000,31.00000,1.790220e-08,0.78719,4
300.02200,1011.56083,     -0.10238,     47.00418,50.00000,31.00000,1.789251e-08,0.78719,4
300.02301,1014.96083,     -0.10198,     46.86973,50.00000,31.00000,1.791726e-08,0.78719,4
300.02301,1018.36083,     -0.10339,     46.72088,50.00000,31.00000,1.789367e-08,0.78719,4
300.00900,1021.76083,     -0.10360,     46.61461,50.00000,31.00000,1.789832e-08,0.78720,4
300.01700,1025.16083,     -0.10319,     46.47286,50.00000,31.00000,1.792386e-08,0.78719,4
300.01999,1028.56083,     -0.10380,     46.35010,50.00000,31.00000,1.787990e-08,0.78720,4
300.01099,1031.96083,     -0.10805,     46.22965,50.00000,31.00000,1.790327e-08,0.78718,4
300.01599,1035.36083,     -0.10117,     46.10209,50.00000,31.00000,1.789865e-08,0.78718,4
300.01300,1038.76083,     -0.10380,     45.98873,50.00000,31.00000,1.785835e-08,0.78719,4
300.01199,1042.16083,     -0.10562,     45.85407,50.00000,31.00000,1.792391e-08,0.78719,4
300.01199,1045.56083,     -0.10562,     45.70292,50.00000,31.00000,1.792663e-08,0.78719,4
300.02802,1048.96083,     -0.10684,     45.55407,50.00000,31.00000,1.792423e-08,0.78719,4
300.01199,1052.36083,     -0.10865,     45.42651,50.00000,31.00000,1.791480e-08,0.78720,4
300.02100,1055.76083,     -0.11088,     45.31315,50.00000,31.00000,1.790585e-08,0.78720,4
300.01401,1059.16083,     -0.11027,     45.17850,50.00000,31.00000,1.789517e-08,0.78718,4
300.02100,1062.56083,     -0.10845,     45.03674,50.00000,31.00000,1.789838e-08,0.78719,4
300.02701,1065.96083,     -0.10845,     44.89520,50.00000,31.00000,1.785031e-08,0.78719,4
300.02499,1069.36083,     -0.10825,     44.78413,50.00000,31.00000,1.792685e-08,0.78720,4
300.01001,1072.76083,     -0.11209,     44.62818,50.00000,31.00000,1.791364e-08,0.78719,4
300.02899,1076.16083,     -0.11250,     44.50063,50.00000,31.00000,1.789522e-08,0.78718,4
300.01501,1079.56083,     -0.11027,     44.38727,50.00000,31.00000,1.789088e-08,0.78719,4
300.02200,1082.96083,     -0.11149,     44.26681,50.00000,31.00000,1.791725e-08,0.78720,4
300.01001,1086.36083,     -0.11412,     44.13925,50.00000,31.00000,1.789801e-08,0.78720,4
300.01999,1089.76083,     -0.11189,     44.00459,50.00000,31.00000,1.789923e-08,0.78720,4
300.00900,1093.16083,     -0.11290,     43.88184,50.00000,31.00000,1.790434e-08,0.78719,4
300.01700,1096.56083,     -0.11452,     43.75428,50.00000,31.00000,1.793477e-08,0.78718,4
300.00101,1099.96083,     -0.11654,     43.63382,50.00000,31.00000,1.790773e-08,0.78719,4
300.00900,1103.36083,     -0.11108,     43.49916,50.00000,31.00000,1.789190e-08,0.78719,4
300.01999,1106.76083,     -0.11412,     43.38580,50.00000,31.00000,1.789685e-08,0.78719,4
300.02499,1110.16083,     -0.11533,     43.28664,50.00000,31.00000,1.789695e-08,0.78719,4
300.01300,1113.56083,     -0.11230,     43.11670,50.00000,31.00000,1.791091e-08,0.78719,4
300.02899,1116.96083,     -0.11655,     42.99624,50.00000,31.00000,1.792612e-08,0.78719,4
300.01901,1120.36083,     -0.11837,     42.87578,50.00000,31.00000,1.789309e-08,0.78719,4
300.01501,1123.76083,     -0.11715,     42.73403,50.00000,31.00000,1.789266e-08,0.78719,4
300.00900,1127.16083,     -0.11918,     42.60647,50.00000,31.00000,1.789773e-08,0.78719,4
300.01999,1130.56083,     -0.11877,     42.47891,50.00000,31.00000,1.789395e-08,0.78719,4
300.01700,1133.96083,     -0.11958,     42.34906,50.00000,31.00000,1.789560e-08,0.78719,4
300.01001,1137.36083,     -0.12241,     42.21441,50.00000,31.00000,1.789064e-08,0.78718,4
300.00800,1140.76083,     -0.12160,     42.05846,50.00000,31.00000,1.785294e-08,0.78719,4
300.01599,1144.16083,     -0.12079,     41.97349,50.00000,31.00000,1.789789e-08,0.78719,4
300.00000,1147.56083,     -0.11594,     41.85762,50.00000,31.00000,1.790005e-08,0.78719,4
300.00900,1150.96083,     -0.11756,     41.73027,50.00000,31.00000,1.786893e-08,0.78719,4
300.01700,1154.36083,     -0.11999,     41.60271,50.00000,31.00000,1.788622e-08,0.78719,4
300.02499,1157.76083,     -0.12464,     41.51044,50.00000,31.00000,1.785721e-08,0.78719,4
300.01199,1161.16083,     -0.12181,     41.39708,50.00000,31.00000,1.786298e-08,0.78719,4
300.01901,1164.56083,     -0.12100,     41.27432,50.00000,31.00000,1.789643e-08,0.78719,4
300.01599,1167.96083,     -0.12565,     41.13967,50.00000,31.00000,1.787181e-08,0.78719,4
300.01300,1171.36083,     -0.12140,     41.01921,50.00000,31.00000,1.788599e-08,0.78719,4
300.01700,1174.76083,     -0.12464,     40.89875,50.00000,31.00000,1.788140e-08,0.78718,4
300.01901,1178.16083,     -0.12484,     40.78539,50.00000,31.00000,1.786703e-08,0.78718,4
300.01999,1181.56083,     -0.12464,     40.67912,50.00000,31.00000,1.789353e-08,0.78719,4
300.02701,1184.96083,     -0.12383,     40.54447,50.00000,31.00000,1.783738e-08,0.78719,4
300.01199,1188.36083,     -0.12545,     40.41691,50.00000,31.00000,1.784708e-08,0.78720,4
300.00299,1191.76083,     -0.12767,     40.28225,50.00000,31.00000,1.788515e-08,0.78718,4
300.01001,1195.16083,     -0.12484,     40.19019,50.00000,31.00000,1.787467e-08,0.78719,4
300.02701,1198.56083,     -0.12444,     40.06263,50.00000,31.00000,1.789720e-08,0.78720,4
300.01099,1201.96083,     -0.12808,     39.91628,50.00000,31.00000,1.785238e-08,0.78718,4
300.01099,1205.36083,     -0.12545,     39.79353,50.00000,31.00000,1.791151e-08,0.78718,4
300.01001,1208.76083,     -0.12788,     39.68706,50.00000,31.00000,1.787426e-08,0.78719,4
300.02200,1212.16083,     -0.12869,     39.58079,50.00000,31.00000,1.786141e-08,0.78719,4
300.02100,1215.56083,     -0.12828,     39.43215,50.00000,31.00000,1.789720e-08,0.78720,4
300.01599,1218.96083,     -0.12970,     39.33278,50.00000,31.00000,1.790210e-08,0.78719,4
300.02200,1222.36083,     -0.12727,     39.16764,50.00000,31.00000,1.791408e-08,0.78719,4
300.01300,1225.76083,     -0.13213,     39.08497,50.00000,31.00000,1.786216e-08,0.78719,4
300.01700,1229.16083,     -0.13233,     38.97161,50.00000,31.00000,1.790260e-08,0.78718,4
300.02399,1232.56083,     -0.13253,     38.83695,50.00000,31.00000,1.789398e-08,0.78719,4
300.02200,1235.96083,     -0.13172,     38.74468,50.00000,31.00000,1.787489e-08,0.78719,4
300.00601,1239.36083,     -0.13314,     38.59603,50.00000,31.00000,1.793844e-08,0.78719,4
300.00500,1242.76083,     -0.13091,     38.52505,50.00000,31.00000,1.794629e-08,0.78719,4
300.01700,1246.16083,     -0.13233,     38.39520,50.00000,31.00000,1.789072e-08,0.78720,4
300.01001,1249.56083,     -0.13253,     38.28894,50.00000,31.00000,1.790697e-08,0.78720,4
300.02802,1252.96083,     -0.13253,     38.17557,50.00000,31.00000,1.789906e-08,0.78719,4
300.00800,1256.36083,     -0.13617,     38.04802,50.00000,31.00000,1.783965e-08,0.78719,4
300.03500,1257.10083,     -0.10765,     37.90626,50.00000,50.00000,1.787752e-08,0.78719,5
300.29501,1257.27083,      0.15565,     37.78121,50.00000,50.00000,1.785615e-08,0.78718,5
301.00800,1257.44083,      0.80382,     37.66785,50.00000,50.00000,1.789545e-08,0.78719,5
302.29800,1257.61083,      1.83348,     37.66785,50.00000,50.00000,1.788494e-08,0.78718,5
304.17300,1257.78083,      3.14485,     37.80480,50.00000,50.00000,1.786338e-08,0.78719,5
306.59201,1257.95083,      4.57497,     38.00084,50.00000,50.00000,1.786813e-08,0.78718,5
309.37601,1258.12083,      5.95226,     38.24405,50.00000,50.00000,1.790492e-08,0.78719,5
312.39401,1258.29083,      7.13705,     38.39040,50.00000,50.00000,1.789306e-08,0.78718,5
315.49200,1258.46083,      8.05192,     38.54154,50.00000,50.00000,1.788271e-08,0.78718,5
318.57300,1258.63083,      8.67358,     38.59123,50.00000,50.00000,1.789895e-08,0.78718,5
321.58301,1258.80083,      9.04563,     38.64802,50.00000,50.00000,1.787080e-08,0.78719,5
324.51700,1258.97083,      9.23139,     38.67620,50.00000,50.00000,1.783763e-08,0.78718,5
327.40500,1259.14083,      9.31655,     38.70459,50.00000,50.00000,1.788974e-08,0.78719,5
330.25601,1259.31083,      9.37717,     38.73299,50.00000,50.00000,1.783869e-08,0.78719,5
333.14499,1259.48083,      9.47873,     38.78956,50.00000,50.00000,1.786355e-08,0.78719,5
336.14301,1259.65083,      9.66298,     38.84635,50.00000,50.00000,1.790150e-08,0.78718,5
339.25500,1259.82083,      9.93630,     38.92672,50.00000,50.00000,1.784863e-08,0.78719,5
342.51099,1259.99083,     10.29173,     39.01169,50.00000,50.00000,1.784679e-08,0.78719,5
345.90201,1260.16083,     10.69804,     39.07787,50.00000,50.00000,1.789771e-08,0.78719,5
349.42700,1260.33083,     11.12293,     39.13445,50.00000,50.00000,1.785135e-08,0.78718,5
353.02802,1260.50083,     11.53274,     39.19123,50.00000,50.00000,1.787079e-08,0.78718,5
356.68600,1260.67083,     11.89642,     39.21942,50.00000,50.00000,1.787813e-08,0.78718,5
360.38699,1260.84083,     12.19897,     39.21942,50.00000,50.00000,1.788446e-08,0.78718,5
364.09201,1261.01083,     12.43759,     39.19123,50.00000,50.00000,1.787840e-08,0.78719,5
367.80399,1261.18083,     12.62194,     39.13445,50.00000,50.00000,1.789169e-08,0.78717,5
371.51099,1261.35083,     12.76385,     39.04948,50.00000,50.00000,1.786879e-08,0.78718,5
375.20801,1261.52083,     12.87727,     38.87474,50.00000,50.00000,1.786787e-08,0.78720,5
378.89499,1261.69083,     12.98189,     38.69040,50.00000,50.00000,1.784952e-08,0.78718,5
382.59399,1261.86083,     13.09365,     38.42129,50.00000,50.00000,1.787197e-08,0.78719,5
386.31500,1262.03083,     13.21239,     38.06931,50.00000,50.00000,1.787558e-08,0.78720,5
390.03400,1262.20083,     13.33866,     37.65825,50.00000,50.00000,1.792150e-08,0.78720,5
393.76501,1262.37083,     13.47464,     37.11503,50.00000,50.00000,1.787928e-08,0.78719,5
397.50500,1262.54083,     13.62568,     36.50814,50.00000,50.00000,1.784370e-08,0.78719,5
401.24701,1262.71083,     13.77733,     35.71921,50.00000,50.00000,1.784370e-08,0.78719,5
404.99301,1262.88083,     13.93263,     34.75324,50.00000,50.00000,1.785473e-08,0.78719,5
408.72101,1263.05083,     14.10097,     33.60543,50.00000,50.00000,1.786093e-08,0.78719,5
412.45499,1263.22083,     14.27431,     32.22129,50.00000,50.00000,1.786400e-08,0.78719,5
416.17099,1263.39083,     14.45203,     30.42630,50.00000,50.00000,1.786480e-08,0.78720,5
419.88699,1263.56083,     14.62598,     28.55553,50.00000,50.00000,1.783411e-08,0.78720,5
423.58200,1263.73083,     14.80422,     26.40626,50.00000,50.00000,1.787428e-08,0.78719,5
427.25500,1263.90083,     14.96839,     23.94990,50.00000,50.00000,1.788035e-08,0.78720,5
430.92300,1264.07083,     15.13561,     21.21482,50.00000,50.00000,1.790796e-08,0.78719,5
434.58200,1264.24083,     15.27642,     18.26013,50.00000,50.00000,1.786628e-08,0.78718,5
438.23499,1264.41083,     15.37352,     15.18038,50.00000,50.00000,1.787583e-08,0.78719,5
441.88199,1264.58083,     15.39315,     12.28476,50.00000,50.00000,1.787577e-08,0.78719,5
445.49500,1264.75083,     15.34752,      9.44802,50.00000,50.00000,1.787449e-08,0.78719,5
449.11899,1264.92083,     15.22480,      6.79562,50.00000,50.00000,1.783381e-08,0.78719,5
452.73599,1265.09083,     15.03758,      4.59436,50.00000,50.00000,1.785014e-08,0.78718,5
456.34100,1265.26083,     14.78929,      2.73570,50.00000,50.00000,1.785835e-08,0.78719,5
459.93701,1265.43083,     14.49982,      1.25699,50.00000,50.00000,1.784512e-08,0.78718,5
463.53400,1265.60083,     14.19509,      0.12109,50.00000,50.00000,1.786897e-08,0.78719,5
467.12000,1265.77083,     13.89354,     -0.68205,50.00000,50.00000,1.785981e-08,0.78719,5
470.69901,1265.94083,     13.60445,     -1.19457,50.00000,50.00000,1.785786e-08,0.78719,5
474.26300,1266.11083,     13.33576,     -1.45198,50.00000,50.00000,1.787390e-08,0.78719,5
477.83200,1266.28083,     13.10012,     -1.58894,50.00000,50.00000,1.786190e-08,0.78719,5
481.37201,1266.45083,     12.90977,     -1.62672,50.00000,50.00000,1.787322e-08,0.78718,5
484.91699,1266.62083,     12.75023,     -1.59854,50.00000,50.00000,1.789439e-08,0.78718,5
488.44601,1266.79083,     12.62186,     -1.59854,50.00000,50.00000,1.788703e-08,0.78719,5
491.96701,1266.96083,     12.51302,     -1.57015,50.00000,50.00000,1.785996e-08,0.78719,5
495.47501,1267.13083,     12.42236,     -1.54175,50.00000,50.00000,1.783751e-08,0.78719,5
498.97699,1267.30083,     12.33582,     -1.51336,50.00000,50.00000,1.786517e-08,0.78718,5
502.48099,1267.47083,     12.25571,     -1.45678,50.00000,50.00000,1.788579e-08,0.78719,5
505.96301,1267.64083,     12.18333,     -1.45678,50.00000,50.00000,1.784209e-08,0.78719,5
509.44699,1267.81083,     12.11465,     -1.40710,50.00000,50.00000,1.790216e-08,0.78719,5
512.93701,1267.98083,     12.04285,     -1.37161,50.00000,50.00000,1.790084e-08,0.78719,5
516.40997,1268.15083,     11.97210,     -1.31503,50.00000,50.00000,1.786919e-08,0.78719,5
519.88800,1268.32083,     11.90573,     -1.31503,50.00000,50.00000,1.783956e-08,0.78719,5
523.34998,1268.49083,     11.83942,     -1.25825,50.00000,50.00000,1.783562e-08,0.78719,5
526.81201,1268.66083,     11.77397,     -1.23006,50.00000,50.00000,1.790809e-08,0.78719,5
530.26898,1268.83083,     11.70797,     -1.20167,50.00000,50.00000,1.790712e-08,0.78719,5
533.72198,1269.00083,     11.63649,     -1.15908,50.00000,50.00000,1.785967e-08,0.78719,5
537.16998,1269.17083,     11.56470,     -1.11670,50.00000,50.00000,1.782140e-08,0.78719,5
540.61700,1269.34083,     11.49293,     -1.08831,50.00000,50.00000,1.785954e-08,0.78719,5
544.05798,1269.51083,     11.42612,     -1.02923,50.00000,50.00000,1.784597e-08,0.78719,5
547.50800,1269.68083,     11.35675,     -1.00084,50.00000,50.00000,1.788787e-08,0.78719,5
550.94397,1269.85083,     11.28279,     -0.97265,50.00000,50.00000,1.785891e-08,0.78719,5
554.38098,1270.02083,     11.20582,     -0.94426,50.00000,50.00000,1.783554e-08,0.78719,5
557.81897,1270.19083,     11.13145,     -0.89457,50.00000,50.00000,1.784504e-08,0.78720,5
561.24799,1270.36083,     11.05591,     -0.88747,50.00000,50.00000,1.788242e-08,0.78719,5
564.68500,1270.53083,     10.97800,     -0.83090,50.00000,50.00000,1.786007e-08,0.78719,5
568.12000,1270.70083,     10.90299,     -0.80251,50.00000,50.00000,1.782132e-08,0.78719,5
571.55902,1270.87083,     10.82498,     -0.77411,50.00000,50.00000,1.786498e-08,0.78720,5
574.98297,1271.04083,     10.74689,     -0.75282,50.00000,50.00000,1.785971e-08,0.78719,5
578.40503,1271.21083,     10.66484,     -0.71754,50.00000,50.00000,1.785099e-08,0.78719,5
581.84399,1271.38083,     10.58222,     -0.68914,50.00000,50.00000,1.788584e-08,0.78719,5
585.26300,1271.55083,     10.50412,     -0.66075,50.00000,50.00000,1.787073e-08,0.78718,5
588.70398,1271.72083,     10.41591,     -0.63236,50.00000,50.00000,1.784729e-08,0.78719,5
592.11200,1271.89083,     10.33181,     -0.60418,50.00000,50.00000,1.789964e-08,0.78719,5
595.54102,1272.06083,     10.24425,     -0.57578,50.00000,50.00000,1.785904e-08,0.78719,5
598.97302,1272.23083,     10.15921,     -0.51900,50.00000,50.00000,1.788760e-08,0.78718,5
602.39001,1272.40083,     10.06911,     -0.49081,50.00000,50.00000,1.783508e-08,0.78719,5
605.82098,1272.57083,      9.98168,     -0.49081,50.00000,50.00000,1.784245e-08,0.78719,5
609.24103,1272.74083,      9.89100,     -0.46242,50.00000,50.00000,1.785541e-08,0.78719,5
612.65802,1272.91083,      9.79446,     -0.40564,50.00000,50.00000,1.788078e-08,0.78719,5
616.09003,1273.08083,      9.69669,     -0.37745,50.00000,50.00000,1.786738e-08,0.78719,5
619.50201,1273.25083,      9.59523,     -0.37745,50.00000,50.00000,1.786063e-08,0.78719,5
622.90698,1273.42083,      9.49504,     -0.34906,50.00000,50.00000,1.783189e-08,0.78720,5
626.33600,1273.59083,      9.39433,     -0.32067,50.00000,50.00000,1.785680e-08,0.78718,5
629.74103,1273.76083,      9.29294,     -0.29228,50.00000,50.00000,1.783938e-08,0.78719,5
633.16101,1273.93083,      9.18851,     -0.29228,50.00000,50.00000,1.791230e-08,0.78719,5
636.57800,1274.10083,      9.07714,     -0.20251,50.00000,50.00000,1.787331e-08,0.78719,5
640.00000,1274.27083,      8.97337,     -0.20251,50.00000,50.00000,1.784781e-08,0.78719,5
643.40302,1274.44083,      8.86468,     -0.17432,50.00000,50.00000,1.790136e-08,0.78719,5
646.82397,1274.61083,      8.75044,     -0.14593,50.00000,50.00000,1.784332e-08,0.78719,5
650.23700,1274.78083,      8.63786,     -0.11754,50.00000,50.00000,1.782847e-08,0.78720,5
653.64001,1274.95083,      8.52352,     -0.10334,50.00000,50.00000,1.786171e-08,0.78719,5
657.06598,1275.12083,      8.40519,-6.096033e-02,50.00000,50.00000,1.786006e-08,0.78720,5
660.47302,1275.29083,      8.28090,-3.256785e-02,50.00000,50.00000,1.785691e-08,0.78719,5
663.87799,1275.46083,      8.16026,-4.175365e-03,50.00000,50.00000,1.786954e-08,0.78719,5
667.29602,1275.63083,      8.03930, 2.421712e-02,50.00000,50.00000,1.784584e-08,0.78719,5
670.71698,1275.80083,      7.91764, 5.240084e-02,50.00000,50.00000,1.787443e-08,0.78719,5
674.12201,1275.97083,      7.79675, 5.240084e-02,50.00000,50.00000,1.787175e-08,0.78719,5
677.53699,1276.14083,      7.67747,      0.10919,50.00000,50.00000,1.787779e-08,0.78720,5
680.95001,1276.31083,      7.55301,      0.10919,50.00000,50.00000,1.786646e-08,0.78719,5
684.36499,1276.48083,      7.42916,      0.15177,50.00000,50.00000,1.788435e-08,0.78720,5
687.79303,1276.65083,      7.30310,      0.18706,50.00000,50.00000,1.786713e-08,0.78719,5
691.20898,1276.82083,      7.17045,      0.19415,50.00000,50.00000,1.784255e-08,0.78720,5
694.62000,1276.99083,      7.04259,      0.22255,50.00000,50.00000,1.786377e-08,0.78719,5
698.02399,1277.16083,      6.91434,      0.25094,50.00000,50.00000,1.785510e-08,0.78719,5
701.44702,1277.33083,      6.79344,      0.27933,50.00000,50.00000,1.785680e-08,0.78719,5
704.86401,1277.50083,      6.66927,      0.30752,50.00000,50.00000,1.786085e-08,0.78719,5
708.29199,1277.67083,      6.54292,      0.30752,50.00000,50.00000,1.786572e-08,0.78719,5
711.70398,1277.84083,      6.41652,      0.35720,50.00000,50.00000,1.785625e-08,0.78719,5
715.11798,1278.01083,      6.28689,      0.39269,50.00000,50.00000,1.785832e-08,0.78720,5
718.53497,1278.18083,      6.16266,      0.42338,50.00000,50.00000,1.786145e-08,0.78719,5
721.96698,1278.35083,      6.04664,      0.42338,50.00000,50.00000,1.784503e-08,0.78719,5
725.38300,1278.52083,      5.92903,      0.45157,50.00000,50.00000,1.783456e-08,0.78719,5
728.79797,1278.69083,      5.80486,      0.47996,50.00000,50.00000,1.786870e-08,0.78720,5
732.21802,1278.86083,      5.68154,      0.50835,50.00000,50.00000,1.788225e-08,0.78719,5
735.63702,1279.03083,      5.56277,      0.53674,50.00000,50.00000,1.786392e-08,0.78720,5
739.06299,1279.20083,      5.45067,      0.56514,50.00000,50.00000,1.784236e-08,0.78718,5
742.47900,1279.37083,      5.33538,      0.59332,50.00000,50.00000,1.788175e-08,0.78719,5
745.89899,1279.54083,      5.22683,      0.62171,50.00000,50.00000,1.785762e-08,0.78719,5
749.31097,1279.71083,      5.11409,      0.62171,50.00000,50.00000,1.786842e-08,0.78719,5
752.75098,1279.88083,      5.00861,      0.65010,50.00000,50.00000,1.786117e-08,0.78718,5
756.15302,1280.05083,      4.90054,      0.69248,50.00000,50.00000,1.787476e-08,0.78719,5
759.57397,1280.22083,      4.79287,      0.69248,50.00000,50.00000,1.787020e-08,0.78719,5
762.98602,1280.39083,      4.68931,      0.73507,50.00000,50.00000,1.787313e-08,0.78718,5
766.40900,1280.56083,      4.59173,      0.73507,50.00000,50.00000,1.785403e-08,0.78719,5
769.82501,1280.73083,      4.49174,      0.76347,50.00000,50.00000,1.785322e-08,0.78718,5
773.24500,1280.90083,      4.39461,      0.79186,50.00000,50.00000,1.788968e-08,0.78718,5
776.67401,1281.07083,      4.29409,      0.82004,50.00000,50.00000,1.789143e-08,0.78718,5
780.08099,1281.24083,      4.19741,      0.84843,50.00000,50.00000,1.786242e-08,0.78719,5
783.49597,1281.41083,      4.09839,      0.84843,50.00000,50.00000,1.785819e-08,0.78719,5
786.91803,1281.58083,      3.99594,      0.87683,50.00000,50.00000,1.785578e-08,0.78719,5
790.32599,1281.75083,      3.90060,      0.84843,50.00000,50.00000,            ,0.44877,5
793.75201,1281.92083,      3.80650,      0.85553,50.00000,50.00000,            ,0.44739,5
794.54797,1281.96083,      3.78571,      0.87683,50.00000,50.00000,            ,0.44707,5