File: data/TGA/005d-L_M/ExpDat_2025_07_18_SL_PS_Tosoh_F10_isothermal.csv
#EXPORTTYPE:                 ,DATA ALL
#FILE:                       ,2025_07_18_SL_PS_Tosoh_F10_isothermal.ngb-ss5
#FORMAT:                     ,NETZSCH5
#FTYPE:                      ,ASCII
#IDENTITY:                   ,PS-Tosoh-F10
#DECIMAL:                    ,POINT
#SEPARATOR:                  ,COMMA
#MTYPE:                      ,DSC
#INSTRUMENT:                 ,NETZSCH STA 449F5
#PROJECT:                    ,
#DATE/TIME:                  ,7/18/2025 9:59:08 AM (UTC-4)
#CORR. FILE:                 ,
#TEMPCAL:                    ,05-05-2025 14:38
#SENSITIVITY:                ,28-06-2023 13:53
#LABORATORY:                 ,Tran/AAG
#OPERATOR:                   ,Stan
#REMARK:                     ,2025_03_29_SL_005d_M1_isothermal
#SAMPLE:                     ,PS-Tosoh-F10
#SAMPLE MASS /mg:            ,4.76
#MATERIAL:                   ,Polystyrene
#REFERENCE:                  ,
#REFERENCE MASS /mg:         ,0
#TYPE OF CRUCIBLE:           ,Al2O3 85 ‘l, open
#SAMPLE CRUCIBLE MASS /mg:   ,0
#REFERENCE CRUCIBLE MASS /mg:,0
#DSC RANGE /‘V:              ,5000
#TG RANGE /mg:               ,35000
#TAU-R:                      ,---
#CORR. CODE:                 ,000
#EXO:                        ,-1
#RANGE:                      ,30›C....800›C/0.0....20.0K/min
#SEGMENT:                    ,S4/5
#SEG. 1:                     ,30›C/10.0(K/min)/100›C
#SEG. 2:                     ,100›C/00:10/100›C
#SEG. 3:                     ,100›C/5.0(K/min)/300›C
#SEG. 4:                     ,300›C/20:00/300›C
#SEG. 5:                     ,300›C/20.0(K/min)/800›C

##Temp./›C,Time/min,DSC/(mW/mg),Mass/%,Gas Flow(purge2)/(ml/min),Gas Flow(protective)/(ml/min),TIC(scan:1)/A,Sensit./(uV/mW)
298.99399,  57.10000,      2.71595,97.02668,50.00000,31.00000,1.767713e-08,0.78814
302.89301,  59.10000,      0.63908,97.94412,50.00000,31.00000,1.769890e-08,0.78500
303.48199,  61.10000,      0.13065,97.55189,50.00000,31.00000,1.768152e-08,0.78423
302.75800,  63.10000,-5.106903e-02,97.30945,50.00000,31.00000,1.764210e-08,0.78389
301.92300,  65.10000,-6.101788e-02,97.10987,50.00000,31.00000,1.765161e-08,0.78420
301.25101,  67.10000,-2.610052e-02,96.87941,50.00000,31.00000,1.762945e-08,0.78463
300.79099,  69.10000, 1.895331e-02,96.72962,50.00000,31.00000,1.760850e-08,0.78511
300.49399,  71.10000, 5.419144e-02,96.53004,50.00000,31.00000,1.760865e-08,0.78556
300.30600,  73.10000, 8.412059e-02,96.38508,50.00000,31.00000,1.764547e-08,0.78592
300.18600,  75.10000, 9.897530e-02,96.21387,50.00000,31.00000,1.762836e-08,0.78623
300.11801,  77.10000,      0.11628,96.06408,50.00000,30.00000,1.758831e-08,0.78647
300.05701,  79.10000,      0.12278,95.92395,50.00000,30.00000,1.760292e-08,0.78664
300.04501,  81.10000,      0.12360,95.80273,50.00000,30.00000,1.757645e-08,0.78678
300.03699,  83.10000,      0.12685,95.65777,50.00000,30.00000,1.757306e-08,0.78689
300.02600,  85.10000,      0.12482,95.52227,50.00000,30.00000,1.759214e-08,0.78696
300.02701,  87.10000,      0.12461,95.42248,50.00000,30.00000,1.751725e-08,0.78703
300.02600,  89.10000,      0.12319,95.30840,50.00000,30.00000,1.758226e-08,0.78708
300.00000,  91.10000,      0.11993,95.19433,50.00000,30.00000,1.756731e-08,0.78710
300.00699,  93.10000,      0.11993,95.10147,50.00000,30.00000,1.755624e-08,0.78714
300.00000,  95.10000,      0.11606,94.98739,50.00000,30.00000,1.757809e-08,0.78716
300.01001,  97.10000,      0.11626,94.90189,50.00000,30.00000,1.757796e-08,0.78717
300.00400,  99.10000,      0.11728,94.81639,50.00000,30.00000,1.754952e-08,0.78718
300.00699, 101.10000,      0.11321,94.73067,50.00000,30.00000,1.755647e-08,0.78719
300.01501, 103.10000,      0.11158,94.63803,50.00000,30.00000,1.752600e-08,0.78718
300.00699, 105.10000,      0.11341,94.56912,50.00000,30.00000,1.758344e-08,0.78718
300.01801, 107.10000,      0.10914,94.49076,50.00000,30.00000,1.753134e-08,0.78717
300.02301, 109.10000,      0.10669,94.43361,50.00000,30.00000,1.752040e-08,0.78718
300.01401, 111.10000,      0.10690,94.34097,50.00000,30.00000,1.757438e-08,0.78718
300.01700, 113.10000,      0.10710,94.28403,50.00000,30.00000,1.753837e-08,0.78719
300.01700, 115.10000,      0.10751,94.19118,50.00000,30.00000,1.753514e-08,0.78721
300.01401, 117.10000,      0.10038,94.12710,50.00000,30.00000,1.752432e-08,0.78720
300.01300, 119.10000,      0.10262,94.06996,50.00000,30.00000,1.754398e-08,0.78721
300.01401, 121.10000,      0.10282,93.91324,50.00000,30.00000,1.755386e-08,0.78720
300.00101, 123.10000, 9.956444e-02,93.91786,50.00000,30.00000,1.760266e-08,0.78721
299.98199, 125.10000,      0.10160,93.88929,50.00000,30.00000,1.758552e-08,0.78720
299.99799, 127.10000, 9.997130e-02,93.83718,50.00000,30.00000,1.756890e-08,0.78719
299.98999, 129.10000,      0.10099,93.80147,50.00000,30.00000,1.760272e-08,0.78719
300.00000, 131.10000, 9.854628e-02,93.74433,50.00000,29.00000,1.758975e-08,0.78719
299.98901, 133.10000, 9.997024e-02,93.69454,50.00000,29.00000,1.758220e-08,0.78720
300.00201, 135.10000, 9.915734e-02,93.63025,50.00000,29.00000,1.761122e-08,0.78721
300.01501, 137.10000, 9.936248e-02,93.58761,50.00000,29.00000,1.763364e-08,0.78720
300.00900, 139.10000, 9.671484e-02,93.53046,50.00000,29.00000,1.764110e-08,0.78719
300.01599, 141.10000, 9.630842e-02,93.49475,50.00000,29.00000,1.757808e-08,0.78719
300.01901, 143.10000, 9.814127e-02,93.40924,50.00000,29.00000,1.759014e-08,0.78719
300.00900, 145.10000, 9.467874e-02,93.35231,50.00000,29.00000,1.762579e-08,0.78719
300.01001, 147.10000, 9.386441e-02,93.31660,50.00000,29.00000,1.762613e-08,0.78720
300.01801, 149.10000, 9.325446e-02,93.25231,50.00000,29.00000,1.758244e-08,0.78720
300.01599, 151.10000, 9.162534e-02,93.20966,50.00000,29.00000,1.761744e-08,0.78719
300.01001, 153.10000, 9.040303e-02,93.12878,50.00000,29.00000,1.761092e-08,0.78719
300.00800, 155.10000, 9.101364e-02,93.07416,50.00000,29.00000,1.759667e-08,0.78719
300.01501, 157.10000, 8.979273e-02,93.00756,50.00000,29.00000,1.757732e-08,0.78718
300.00299, 159.10000, 8.979145e-02,92.95777,50.00000,29.00000,1.758990e-08,0.78719
300.01300, 161.10000, 8.612751e-02,92.90063,50.00000,29.00000,1.757666e-08,0.78719
300.01401, 163.10000, 9.040345e-02,92.80315,50.00000,28.00000,1.755238e-08,0.78721
300.00299, 165.10000, 8.470123e-02,92.77227,50.00000,28.00000,1.755854e-08,0.78720
300.01199, 167.10000, 8.897796e-02,92.71534,50.00000,28.00000,1.755834e-08,0.78719
299.99899, 169.10000, 8.714412e-02,92.64391,50.00000,28.00000,1.756157e-08,0.78721
300.00000, 171.10000, 8.755144e-02,92.56555,50.00000,28.00000,1.757921e-08,0.78722
300.00699, 173.10000, 8.205471e-02,92.50840,50.00000,28.00000,1.753801e-08,0.78721
300.01001, 175.10000, 8.734887e-02,92.48950,50.00000,28.00000,1.757561e-08,0.78720
300.01099, 177.10000, 8.694175e-02,92.43235,50.00000,28.00000,1.757503e-08,0.78721
300.01801, 179.10000, 8.796053e-02,92.36828,50.00000,28.00000,1.755616e-08,0.78721
300.01700, 181.10000, 8.368458e-02,92.28992,50.00000,28.00000,1.756708e-08,0.78721
300.01700, 183.10000, 8.164846e-02,92.21849,50.00000,28.00000,1.756877e-08,0.78721
300.02301, 185.10000, 8.409240e-02,92.17584,50.00000,28.00000,1.753559e-08,0.78720
300.01901, 187.10000, 8.287033e-02,92.09013,50.00000,28.00000,1.754909e-08,0.78721
300.01501, 189.10000, 8.368438e-02,92.03067,50.00000,28.00000,1.754329e-08,0.78721
300.02399, 191.10000, 8.348166e-02,91.97143,50.00000,28.00000,1.759229e-08,0.78720
300.01999, 193.10000, 8.185236e-02,91.87857,50.00000,28.00000,1.755316e-08,0.78720
300.01999, 195.10000, 7.940900e-02,91.82878,50.00000,28.00000,1.755031e-08,0.78720
300.02301, 197.10000, 8.083458e-02,91.75735,50.00000,28.00000,1.755465e-08,0.78720
300.01300, 199.10000, 8.124085e-02,91.70273,50.00000,28.00000,1.754030e-08,0.78719
300.01501, 201.10000, 8.124104e-02,91.61239,50.00000,28.00000,1.750535e-08,0.78719
300.01199, 203.10000, 8.001909e-02,91.59811,50.00000,28.00000,1.750690e-08,0.78719
300.01199, 205.10000, 7.879742e-02,91.51975,50.00000,28.00000,1.751592e-08,0.78718
300.01700, 207.10000, 8.266652e-02,91.45567,50.00000,28.00000,1.751977e-08,0.78719
300.02200, 209.10000, 7.940919e-02,91.41282,50.00000,28.00000,1.754523e-08,0.78720
300.01901, 211.10000, 7.900169e-02,91.32731,50.00000,28.00000,1.752220e-08,0.78719
300.00299, 213.10000, 7.553884e-02,91.24160,50.00000,28.00000,1.752172e-08,0.78719
300.01700, 215.10000, 7.981595e-02,91.19895,50.00000,28.00000,1.751350e-08,0.78719
300.01401, 217.10000, 7.961205e-02,91.13004,50.00000,28.00000,1.749933e-08,0.78720
300.02100, 219.10000, 7.818742e-02,91.10147,50.00000,28.00000,1.749865e-08,0.78720
300.01501, 221.10000, 7.574353e-02,91.04433,50.00000,28.00000,1.748861e-08,0.78720
300.02600, 223.10000, 7.676258e-02,90.98025,50.00000,28.00000,1.751636e-08,0.78720
300.02600, 225.10000, 7.757704e-02,90.92311,50.00000,28.00000,1.755535e-08,0.78720
300.01801, 227.10000, 7.554018e-02,90.82332,50.00000,28.00000,1.754189e-08,0.78719
300.00500, 229.10000, 7.492819e-02,90.76639,50.00000,28.00000,1.748062e-08,0.78720
300.01501, 231.10000, 7.513269e-02,90.70924,50.00000,29.00000,1.753154e-08,0.78719
300.02200, 233.10000, 7.309718e-02,90.64517,50.00000,29.00000,1.749710e-08,0.78720
300.00299, 235.10000, 7.431719e-02,90.58803,50.00000,29.00000,1.748594e-08,0.78718
300.01001, 237.10000, 7.492864e-02,90.53824,50.00000,29.00000,1.749588e-08,0.78719
300.01300, 239.10000, 7.431807e-02,90.50966,50.00000,29.00000,1.750941e-08,0.78720
300.02200, 241.10000, 7.350441e-02,90.44538,50.00000,29.00000,1.749433e-08,0.78720
300.01599, 243.10000, 7.106054e-02,90.35987,50.00000,29.00000,1.748933e-08,0.78721
300.01199, 245.10000, 7.187465e-02,90.31008,50.00000,29.00000,1.747015e-08,0.78720
300.00601, 247.10000, 7.370663e-02,90.22920,50.00000,29.00000,1.748604e-08,0.78720
300.01599, 249.10000, 7.391111e-02,90.19349,50.00000,29.00000,1.749865e-08,0.78719
300.00800, 251.10000, 7.268875e-02,90.10567,50.00000,29.00000,1.751287e-08,0.78720
300.01501, 253.10000, 7.228213e-02,90.07710,50.00000,29.00000,1.749093e-08,0.78720
300.01501, 255.10000, 7.126407e-02,89.99160,50.00000,29.00000,1.751153e-08,0.78720
300.02600, 257.10000, 7.350476e-02,89.89874,50.00000,29.00000,1.747970e-08,0.78721
300.01401, 259.10000, 7.553983e-02,89.87038,50.00000,29.00000,1.750439e-08,0.78719
300.02499, 261.10000, 7.309744e-02,89.81324,50.00000,29.00000,1.745862e-08,0.78719
300.01401, 263.10000, 7.126399e-02,89.77038,50.00000,29.00000,1.745029e-08,0.78719
300.01999, 265.10000, 7.350423e-02,89.70147,50.00000,29.00000,1.747457e-08,0.78719
300.02899, 267.10000, 7.493032e-02,89.64685,50.00000,29.00000,1.749459e-08,0.78720
300.02100, 269.10000, 7.411516e-02,89.56849,50.00000,29.00000,1.749202e-08,0.78720
300.01801, 271.10000, 7.024626e-02,89.53992,50.00000,29.00000,1.746998e-08,0.78720
300.00500, 273.10000, 7.085601e-02,89.44727,50.00000,29.00000,1.749147e-08,0.78720
300.02200, 275.10000, 7.289357e-02,89.41870,50.00000,29.00000,1.748188e-08,0.78720
300.02100, 277.10000, 7.492961e-02,89.36155,50.00000,29.00000,1.747448e-08,0.78720
300.00299, 279.10000, 7.309554e-02,89.30462,50.00000,29.00000,1.749658e-08,0.78719
300.00101, 281.10000, 7.248454e-02,89.21660,50.00000,29.00000,1.748431e-08,0.78719
300.02200, 283.10000, 7.350441e-02,89.18824,50.00000,29.00000,1.746160e-08,0.78719
300.01801, 285.10000, 6.943182e-02,89.11218,50.00000,29.00000,1.744794e-08,0.78719
300.00699, 287.10000, 6.963452e-02,89.07647,50.00000,29.00000,1.748043e-08,0.78719
299.99399, 289.10000, 7.452000e-02,89.01933,50.00000,29.00000,1.751638e-08,0.78718
300.01401, 291.10000, 7.126399e-02,88.96008,50.00000,29.00000,1.747953e-08,0.78719
300.00900, 293.10000, 6.983830e-02,88.91954,50.00000,29.00000,1.748744e-08,0.78719
300.01401, 295.10000, 6.820982e-02,88.86261,50.00000,29.00000,1.746928e-08,0.78720
300.02499, 297.10000, 7.004323e-02,88.81975,50.00000,29.00000,1.747611e-08,0.78719
300.01300, 299.10000, 6.698807e-02,88.74139,50.00000,29.00000,1.747122e-08,0.78720
300.01801, 301.10000, 7.228239e-02,88.69853,50.00000,29.00000,1.751049e-08,0.78719
300.01300, 303.10000, 6.637723e-02,88.59874,50.00000,29.00000,1.743079e-08,0.78720
300.03400, 305.10000, 6.861867e-02,88.57500,50.00000,29.00000,1.746782e-08,0.78719
300.01401, 307.10000, 6.841343e-02,88.51071,50.00000,29.00000,1.746104e-08,0.78720
300.01501, 309.10000, 6.902435e-02,88.47521,50.00000,29.00000,1.747817e-08,0.78719
300.02301, 311.10000, 7.085752e-02,88.41092,50.00000,29.00000,1.749987e-08,0.78719
300.00699, 313.10000, 6.658037e-02,88.34685,50.00000,29.00000,1.747674e-08,0.78719
300.01300, 315.10000, 6.739529e-02,88.27542,50.00000,29.00000,1.753847e-08,0.78719
300.01300, 317.10000, 6.820974e-02,88.24685,50.00000,29.00000,1.747661e-08,0.78718
300.00500, 319.10000, 7.004157e-02,88.16134,50.00000,29.00000,1.747840e-08,0.78721
300.01001, 321.10000, 6.861672e-02,88.10441,50.00000,29.00000,1.746025e-08,0.78720
300.01501, 323.10000, 6.637739e-02,88.05210,50.00000,29.00000,1.749543e-08,0.78719
300.01401, 325.10000, 7.085677e-02,88.00924,50.00000,29.00000,1.748816e-08,0.78719
300.01901, 327.10000, 6.535964e-02,87.96660,50.00000,29.00000,1.747793e-08,0.78720
300.01599, 329.10000, 6.963526e-02,87.88088,50.00000,29.00000,1.744018e-08,0.78719
300.01700, 331.10000, 6.780284e-02,87.84538,50.00000,29.00000,1.749620e-08,0.78719
300.01700, 333.10000, 6.556310e-02,87.77878,50.00000,29.00000,1.745121e-08,0.78719
300.02399, 335.10000, 6.495280e-02,87.71450,50.00000,29.00000,1.746164e-08,0.78719
300.02301, 337.10000, 6.780332e-02,87.67899,50.00000,29.00000,1.747807e-08,0.78719
300.03000, 339.10000, 6.780388e-02,87.59580,50.00000,29.00000,1.747541e-08,0.78718
300.02499, 341.10000, 6.678541e-02,87.54097,50.00000,29.00000,1.746421e-08,0.78720
300.02100, 343.10000, 6.698871e-02,87.47689,50.00000,29.00000,1.751165e-08,0.78720
300.01199, 345.10000, 6.658077e-02,87.39601,50.00000,29.00000,1.742920e-08,0.78719
300.01099, 347.10000, 6.922763e-02,87.36765,50.00000,29.00000,1.746982e-08,0.78719
300.01001, 349.10000, 6.963477e-02,87.30336,50.00000,29.00000,1.743499e-08,0.78718
300.00800, 351.10000, 6.882016e-02,87.26765,50.00000,29.00000,1.747076e-08,0.78719
300.01199, 353.10000, 7.085660e-02,87.18214,50.00000,29.00000,1.746942e-08,0.78721
300.01901, 355.10000, 7.085719e-02,87.12521,50.00000,29.00000,1.744167e-08,0.78721
300.01801, 357.10000, 6.821014e-02,87.07290,50.00000,29.00000,1.744614e-08,0.78719
300.01401, 359.10000, 7.268927e-02,86.99433,50.00000,29.00000,1.750333e-08,0.78720
300.01901, 361.10000, 7.146802e-02,86.96597,50.00000,29.00000,1.743297e-08,0.78720
300.01300, 363.10000, 7.248557e-02,86.93971,50.00000,29.00000,1.747755e-08,0.78719
300.02301, 365.10000, 7.391172e-02,86.85420,50.00000,29.00000,1.749207e-08,0.78718
300.02899, 367.10000, 7.350502e-02,86.78992,50.00000,29.00000,1.742301e-08,0.78720
300.01599, 369.10000, 7.594723e-02,86.74727,50.00000,29.00000,1.746023e-08,0.78719
300.00800, 371.10000, 7.513207e-02,86.71155,50.00000,29.00000,1.747054e-08,0.78720
300.01801, 373.10000, 7.411490e-02,86.60462,50.00000,29.00000,1.747736e-08,0.78720
300.03299, 375.10000, 7.594876e-02,86.56660,50.00000,29.00000,1.748469e-08,0.78720
300.00800, 377.10000, 7.065265e-02,86.50945,50.00000,29.00000,1.748877e-08,0.78719
300.02600, 379.10000, 7.431921e-02,86.44538,50.00000,29.00000,1.744527e-08,0.78719
300.01001, 381.10000, 6.800589e-02,86.40252,50.00000,29.00000,1.744577e-08,0.78719
300.01099, 383.10000, 6.861680e-02,86.33845,50.00000,29.00000,1.747980e-08,0.78719
300.01099, 385.10000, 7.248540e-02,86.27185,50.00000,29.00000,1.745991e-08,0.78720
300.01300, 387.10000, 6.922779e-02,86.21723,50.00000,29.00000,1.745637e-08,0.78719
300.01700, 389.10000, 6.861728e-02,86.18634,50.00000,29.00000,1.745535e-08,0.78718
300.01401, 391.10000, 6.861704e-02,86.10777,50.00000,29.00000,1.744019e-08,0.78717
300.01599, 393.10000, 6.739553e-02,86.05084,50.00000,29.00000,1.743270e-08,0.78718
300.01700, 395.10000, 6.454504e-02,85.98655,50.00000,29.00000,1.747316e-08,0.78720
300.01300, 397.10000, 6.841335e-02,85.92962,50.00000,29.00000,1.745566e-08,0.78719
300.01300, 399.10000, 6.597001e-02,85.89391,50.00000,29.00000,1.747488e-08,0.78718
300.02100, 401.10000, 6.474896e-02,85.82269,50.00000,29.00000,1.747064e-08,0.78719
300.01099, 403.10000, 6.128681e-02,85.77269,50.00000,29.00000,1.744884e-08,0.78719
300.01401, 405.10000, 6.291592e-02,85.74412,50.00000,29.00000,1.744487e-08,0.78719
300.00201, 407.10000, 6.413668e-02,85.66576,50.00000,29.00000,1.745234e-08,0.78720
300.00900, 409.10000, 6.495165e-02,85.60168,50.00000,29.00000,1.747831e-08,0.78719
300.01401, 411.10000, 6.454481e-02,85.56597,50.00000,29.00000,1.743724e-08,0.78719
300.00500, 413.10000, 6.698744e-02,85.47332,50.00000,29.00000,1.748683e-08,0.78719
300.00299, 415.10000, 6.780171e-02,85.41618,50.00000,29.00000,1.749927e-08,0.78719
300.00601, 417.10000, 6.983805e-02,85.38761,50.00000,29.00000,1.750407e-08,0.78719
300.01999, 419.10000, 7.004282e-02,85.30210,50.00000,29.00000,1.750101e-08,0.78719
300.01700, 421.10000, 6.556310e-02,85.25945,50.00000,29.00000,1.744417e-08,0.78720
300.02802, 423.10000, 6.922902e-02,85.20231,50.00000,29.00000,1.747699e-08,0.78719
300.02100, 425.10000, 6.719232e-02,85.16912,50.00000,29.00000,1.745990e-08,0.78720
300.01300, 427.10000, 6.943140e-02,85.10483,50.00000,29.00000,1.749119e-08,0.78719
300.00601, 429.10000, 6.841278e-02,85.05504,50.00000,29.00000,1.749468e-08,0.78719
300.02701, 431.10000, 7.513376e-02,84.96933,50.00000,29.00000,1.749360e-08,0.78719
300.02301, 433.10000, 7.004307e-02,84.91954,50.00000,29.00000,1.747348e-08,0.78719
300.01001, 435.10000, 7.248531e-02,84.86954,50.00000,29.00000,1.748540e-08,0.78719
300.02301, 437.10000, 7.065391e-02,84.81261,50.00000,29.00000,1.749398e-08,0.78719
300.02100, 439.10000, 7.248626e-02,84.78403,50.00000,29.00000,1.745470e-08,0.78718
300.01999, 441.10000, 7.472591e-02,84.69853,50.00000,29.00000,1.747235e-08,0.78719
300.00900, 443.10000, 7.065274e-02,84.63424,50.00000,29.00000,1.743568e-08,0.78719
300.01001, 445.10000, 7.248531e-02,84.58445,50.00000,29.00000,1.742088e-08,0.78719
300.01999, 447.10000, 7.778010e-02,84.51534,50.00000,29.00000,1.746559e-08,0.78720
300.01300, 449.10000, 7.472529e-02,84.47269,50.00000,29.00000,1.745735e-08,0.78720
300.01001, 451.10000, 7.757557e-02,84.44412,50.00000,29.00000,1.746156e-08,0.78719
300.02100, 453.10000, 8.144523e-02,84.38718,50.00000,29.00000,1.748069e-08,0.78719
300.01801, 455.10000, 7.818714e-02,84.29433,50.00000,29.00000,1.747622e-08,0.78719
300.01300, 457.10000, 8.205529e-02,84.25882,50.00000,29.00000,1.747347e-08,0.78719
300.01300, 459.10000, 7.920474e-02,84.20168,50.00000,29.00000,1.742142e-08,0.78717
300.01801, 461.10000, 7.920521e-02,84.11618,50.00000,29.00000,1.745162e-08,0.78719
300.01001, 463.10000, 8.205500e-02,84.07332,50.00000,29.00000,1.742454e-08,0.78719
300.02200, 465.10000, 8.327785e-02,83.99958,50.00000,29.00000,1.747040e-08,0.78720
300.03101, 467.10000, 7.961366e-02,83.93782,50.00000,29.00000,1.746232e-08,0.78719
300.03201, 469.10000, 8.103906e-02,83.87605,50.00000,29.00000,1.743330e-08,0.78718
300.01901, 471.10000, 7.492944e-02,83.85462,50.00000,29.00000,1.746921e-08,0.78720
300.01801, 473.10000, 7.777992e-02,83.78340,50.00000,29.00000,1.743311e-08,0.78718
300.02600, 475.10000, 8.063126e-02,83.71218,50.00000,29.00000,1.747655e-08,0.78719
300.02100, 477.10000, 7.655852e-02,83.65504,50.00000,29.00000,1.744388e-08,0.78719
300.01099, 479.10000, 7.431789e-02,83.61471,50.00000,29.00000,1.745319e-08,0.78719
299.99701, 481.10000, 8.022127e-02,83.54097,50.00000,29.00000,1.745117e-08,0.78718
300.00400, 483.10000, 7.920389e-02,83.49811,50.00000,29.00000,1.744927e-08,0.78719
300.02200, 485.10000, 7.879835e-02,83.45546,50.00000,29.00000,1.745060e-08,0.78719
300.01801, 487.10000, 7.635463e-02,83.36261,50.00000,29.00000,1.744076e-08,0.78720
300.02899, 489.10000, 7.737370e-02,83.31996,50.00000,29.00000,1.743249e-08,0.78718
300.03000, 491.10000, 7.228341e-02,83.26996,50.00000,29.00000,1.745538e-08,0.78720
300.02399, 493.10000, 7.635517e-02,83.17731,50.00000,29.00000,1.747586e-08,0.78721
300.02399, 495.10000, 7.248651e-02,83.12038,50.00000,29.00000,1.743571e-08,0.78720
300.00299, 497.10000, 7.574245e-02,83.07038,50.00000,29.00000,1.749588e-08,0.78719
300.00000, 499.10000, 7.553857e-02,83.01324,50.00000,29.00000,1.747591e-08,0.78720
300.01401, 501.10000, 7.757594e-02,82.95630,50.00000,29.00000,1.744070e-08,0.78720
300.01801, 503.10000, 7.920521e-02,82.89916,50.00000,29.00000,1.745323e-08,0.78719
300.01099, 505.10000, 7.777927e-02,82.85651,50.00000,29.00000,1.744559e-08,0.78719
300.02200, 507.10000, 8.327785e-02,82.79706,50.00000,29.00000,1.744265e-08,0.78719
300.03299, 509.10000, 8.063192e-02,82.75420,50.00000,29.00000,1.743168e-08,0.78719
300.00500, 511.10000, 7.676068e-02,82.69958,50.00000,29.00000,1.745431e-08,0.78719
300.02301, 513.10000, 8.144542e-02,82.63298,50.00000,29.00000,1.746654e-08,0.78719
300.02499, 515.10000, 8.226007e-02,82.56891,50.00000,29.00000,1.741798e-08,0.78719
300.01099, 517.10000, 8.205510e-02,82.49286,50.00000,29.00000,1.741215e-08,0.78719
300.01700, 519.10000, 7.981595e-02,82.44286,50.00000,29.00000,1.743862e-08,0.78718
300.01901, 521.10000, 8.490645e-02,82.37164,50.00000,30.00000,1.746093e-08,0.78719
300.00900, 523.10000, 8.103685e-02,82.32164,50.00000,30.00000,1.746938e-08,0.78718
300.02100, 525.10000, 8.205607e-02,82.26471,50.00000,30.00000,1.743780e-08,0.78720
300.01501, 527.10000, 7.961215e-02,82.20042,50.00000,30.00000,1.744321e-08,0.78719
300.01501, 529.10000, 7.818687e-02,82.14349,50.00000,30.00000,1.743076e-08,0.78718
300.01599, 531.10000, 7.615084e-02,82.07920,50.00000,30.00000,1.744668e-08,0.78718
300.02600, 533.10000, 7.737343e-02,82.03655,50.00000,30.00000,1.744315e-08,0.78719
300.02301, 535.10000, 7.452256e-02,81.97227,50.00000,30.00000,1.743604e-08,0.78718
300.01001, 537.10000, 7.452142e-02,81.92962,50.00000,30.00000,1.744345e-08,0.78720
300.01199, 539.10000, 7.472520e-02,81.84391,50.00000,30.00000,1.746413e-08,0.78719
300.01801, 541.10000, 7.513296e-02,81.83676,50.00000,30.00000,1.744341e-08,0.78720
300.02399, 543.10000, 7.411542e-02,81.72983,50.00000,30.00000,1.746947e-08,0.78720
300.01401, 545.10000, 7.146760e-02,81.71324,50.00000,30.00000,1.748403e-08,0.78720
300.00800, 547.10000, 7.391041e-02,81.63487,50.00000,30.00000,1.747227e-08,0.78721
300.01901, 549.10000, 7.187525e-02,81.57773,50.00000,30.00000,1.744038e-08,0.78719
300.01999, 551.10000, 7.696565e-02,81.54202,50.00000,30.00000,1.740039e-08,0.78720
300.00800, 553.10000, 7.594651e-02,81.47080,50.00000,30.00000,1.744126e-08,0.78719
300.01001, 555.10000, 7.635391e-02,81.41387,50.00000,30.00000,1.744275e-08,0.78719
300.01599, 557.10000, 7.777973e-02,81.36870,50.00000,30.00000,1.746485e-08,0.78719
300.02200, 559.10000, 8.022365e-02,81.31155,50.00000,30.00000,1.742160e-08,0.78718
300.02200, 561.10000, 7.594777e-02,81.26408,50.00000,30.00000,1.744652e-08,0.78719
300.02301, 563.10000, 7.920568e-02,81.22605,50.00000,30.00000,1.744995e-08,0.78719
300.01199, 565.10000, 7.859381e-02,81.14034,50.00000,30.00000,1.742601e-08,0.78719
300.01501, 567.10000, 8.225910e-02,81.09286,50.00000,30.00000,1.742345e-08,0.78719
300.02899, 569.10000, 8.368576e-02,81.05966,50.00000,30.00000,1.742563e-08,0.78719
300.01801, 571.10000, 7.920521e-02,81.00252,50.00000,30.00000,1.747522e-08,0.78719
300.02301, 573.10000, 8.124181e-02,80.95021,50.00000,30.00000,1.744035e-08,0.78718
300.02499, 575.10000, 8.185284e-02,80.87185,50.00000,30.00000,1.747711e-08,0.78720
300.02499, 577.10000, 8.002032e-02,80.83613,50.00000,30.00000,1.748937e-08,0.78719
300.01599, 579.10000, 7.615084e-02,80.75063,50.00000,30.00000,1.744059e-08,0.78720
300.02301, 581.10000, 7.492979e-02,80.69370,50.00000,30.00000,1.746260e-08,0.78718
300.03400, 583.10000, 7.228376e-02,80.62941,50.00000,30.00000,1.744059e-08,0.78719
300.02301, 585.10000, 7.228282e-02,80.55819,50.00000,30.00000,1.741965e-08,0.78720
300.03101, 587.10000, 7.533773e-02,80.50819,50.00000,30.00000,1.746595e-08,0.78720
300.02899, 589.10000, 7.187610e-02,80.46786,50.00000,31.00000,1.743658e-08,0.78719
300.03500, 591.10000, 7.309831e-02,80.42500,50.00000,31.00000,1.743995e-08,0.78719
300.02200, 593.10000, 7.248634e-02,80.36324,50.00000,31.00000,1.744914e-08,0.78719
300.03101, 595.10000, 7.554135e-02,80.31324,50.00000,31.00000,1.745107e-08,0.78719
300.01801, 597.10000, 7.472574e-02,80.23718,50.00000,31.00000,1.743701e-08,0.78718
300.00601, 599.10000, 7.961130e-02,80.20168,50.00000,31.00000,1.744772e-08,0.78719
300.02399, 601.10000, 7.594795e-02,80.15168,50.00000,31.00000,1.741161e-08,0.78719
300.01901, 603.10000, 7.737279e-02,80.09475,50.00000,31.00000,1.743465e-08,0.78719
300.01901, 605.10000, 8.164865e-02,80.04475,50.00000,31.00000,1.745151e-08,0.78719
300.01700, 607.10000, 8.042678e-02,79.98067,50.00000,31.00000,1.744412e-08,0.78720
300.01099, 609.10000, 8.042621e-02,79.93067,50.00000,31.00000,1.745704e-08,0.78719
300.01199, 611.10000, 8.490575e-02,79.89496,50.00000,31.00000,1.745402e-08,0.78719
300.00601, 613.10000, 8.205461e-02,79.86639,50.00000,31.00000,1.742270e-08,0.78719
300.01300, 615.10000, 8.429501e-02,79.77857,50.00000,31.00000,1.743597e-08,0.78719
300.01401, 617.10000, 8.144456e-02,79.72143,50.00000,31.00000,1.748768e-08,0.78720
300.02100, 619.10000, 7.920549e-02,79.66450,50.00000,31.00000,1.745189e-08,0.78719
300.02399, 621.10000, 8.348166e-02,79.62878,50.00000,31.00000,1.747573e-08,0.78720
300.01599, 623.10000, 8.246281e-02,79.58613,50.00000,31.00000,1.745610e-08,0.78719
300.01801, 625.10000, 7.798353e-02,79.52899,50.00000,31.00000,1.743902e-08,0.78719
300.02200, 627.10000, 7.370802e-02,79.50042,50.00000,31.00000,1.742014e-08,0.78720
300.01901, 629.10000, 7.492944e-02,79.44580,50.00000,31.00000,1.741332e-08,0.78719
300.01199, 631.10000, 7.329993e-02,79.36744,50.00000,31.00000,1.743188e-08,0.78720
300.01099, 633.10000, 7.676122e-02,79.33403,50.00000,31.00000,1.741652e-08,0.78719
300.02100, 635.10000, 7.574406e-02,79.27458,50.00000,31.00000,1.744247e-08,0.78719
300.02200, 637.10000, 7.411525e-02,79.22479,50.00000,31.00000,1.746469e-08,0.78718
300.01801, 639.10000, 7.289322e-02,79.19622,50.00000,31.00000,1.745918e-08,0.78720
300.02499, 641.10000, 7.676249e-02,79.13214,50.00000,31.00000,1.744736e-08,0.78720
300.03000, 643.10000, 7.431957e-02,79.08929,50.00000,31.00000,1.745573e-08,0.78719
300.01700, 645.10000, 7.330036e-02,79.01807,50.00000,31.00000,1.742851e-08,0.78719
300.02802, 647.10000, 7.452301e-02,78.98466,50.00000,31.00000,1.742492e-08,0.78718
300.01099, 649.10000, 7.228179e-02,78.89916,50.00000,31.00000,1.746688e-08,0.78719
300.01401, 651.10000, 7.533622e-02,78.87773,50.00000,31.00000,1.743460e-08,0.78719
300.02301, 653.10000, 7.757677e-02,78.83487,50.00000,31.00000,1.743255e-08,0.78719
299.99799, 655.10000, 7.676004e-02,78.74937,50.00000,31.00000,1.743464e-08,0.78720
300.00699, 657.10000, 7.716808e-02,78.70189,50.00000,31.00000,1.741962e-08,0.78720
300.00900, 659.10000, 7.655743e-02,78.65189,50.00000,31.00000,1.742056e-08,0.78720
300.01801, 661.10000, 7.635463e-02,78.62353,50.00000,31.00000,1.743108e-08,0.78719
300.01001, 663.10000, 7.431781e-02,78.55210,50.00000,31.00000,1.744858e-08,0.78719
300.02802, 665.10000, 7.472662e-02,78.53067,50.00000,31.00000,1.741479e-08,0.78719
300.01199, 667.10000, 7.106021e-02,78.45945,50.00000,31.00000,1.744564e-08,0.78718
300.01501, 669.10000, 7.330019e-02,78.40231,50.00000,31.00000,1.744819e-08,0.78718
300.01999, 671.10000, 7.594759e-02,78.35966,50.00000,31.00000,1.743355e-08,0.78719
300.02899, 673.10000, 7.574478e-02,78.33109,50.00000,31.00000,1.738770e-08,0.78719
300.01901, 675.10000, 7.859446e-02,78.22416,50.00000,31.00000,1.742464e-08,0.78719
300.00601, 677.10000, 7.492828e-02,78.20987,50.00000,31.00000,1.740666e-08,0.78719
300.00601, 679.10000, 7.757521e-02,78.13151,50.00000,31.00000,1.743760e-08,0.78720
300.01199, 681.10000, 7.981547e-02,78.07437,50.00000,31.00000,1.743710e-08,0.78721
300.01901, 683.10000, 8.287033e-02,78.04580,50.00000,31.00000,1.744393e-08,0.78720
300.02100, 685.10000, 8.042716e-02,77.97941,50.00000,31.00000,1.743564e-08,0.78719
300.01300, 687.10000, 8.286974e-02,77.93424,50.00000,31.00000,1.743717e-08,0.78719
300.02399, 689.10000, 8.307443e-02,77.86282,50.00000,31.00000,1.741526e-08,0.78719
300.01999, 691.10000, 8.144513e-02,77.82731,50.00000,31.00000,1.736927e-08,0.78719
300.01099, 693.10000, 8.083343e-02,77.80588,50.00000,31.00000,1.742420e-08,0.78719
300.01401, 695.10000, 8.327706e-02,77.73697,50.00000,31.00000,1.740055e-08,0.78719
300.01501, 697.10000, 7.900131e-02,77.67983,50.00000,31.00000,1.747464e-08,0.78719
300.00500, 699.10000, 7.553902e-02,77.62290,50.00000,31.00000,1.742966e-08,0.78719
300.01001, 701.10000, 7.513225e-02,77.59433,50.00000,31.00000,1.734992e-08,0.78719
300.01801, 703.10000, 7.737270e-02,77.50630,50.00000,31.00000,1.742080e-08,0.78719
300.01401, 705.10000, 7.676149e-02,77.46597,50.00000,31.00000,1.742109e-08,0.78720
300.02701, 707.10000, 7.594822e-02,77.43025,50.00000,31.00000,1.743149e-08,0.78720
300.01599, 709.10000, 7.513278e-02,77.34475,50.00000,31.00000,1.741926e-08,0.78720
300.01001, 711.10000, 7.920446e-02,77.31618,50.00000,31.00000,1.743168e-08,0.78720
300.00900, 713.10000, 7.615021e-02,77.23298,50.00000,31.00000,1.743884e-08,0.78719
300.01199, 715.10000, 7.452159e-02,77.20441,50.00000,31.00000,1.741344e-08,0.78719
300.01199, 717.10000, 7.981547e-02,77.14748,50.00000,31.00000,1.744046e-08,0.78721
300.01700, 719.10000, 7.696538e-02,77.12605,50.00000,31.00000,1.745133e-08,0.78720
300.01999, 721.10000, 7.676204e-02,77.06197,50.00000,31.00000,1.744938e-08,0.78719
300.02301, 723.10000, 8.103820e-02,76.99055,50.00000,31.00000,1.744476e-08,0.78719
300.02100, 725.10000, 7.798381e-02,76.99055,50.00000,31.00000,1.743155e-08,0.78719
300.00800, 727.10000, 7.940788e-02,76.92647,50.00000,31.00000,1.740270e-08,0.78719
300.01300, 729.10000, 8.042640e-02,76.87899,50.00000,31.00000,1.743856e-08,0.78719
300.01501, 731.10000, 8.286993e-02,76.80756,50.00000,31.00000,1.743030e-08,0.78720
300.01199, 733.10000, 8.307325e-02,76.76492,50.00000,31.00000,1.742774e-08,0.78719
300.00500, 735.10000, 8.388700e-02,76.71492,50.00000,31.00000,1.742565e-08,0.78719
300.01099, 737.10000, 8.490564e-02,76.66975,50.00000,31.00000,1.741108e-08,0.78719
300.00500, 739.10000, 8.510865e-02,76.61261,50.00000,31.00000,1.740110e-08,0.78719
300.01001, 741.10000, 8.714526e-02,76.54139,50.00000,31.00000,1.741954e-08,0.78719
300.02600, 743.10000, 8.694330e-02,76.49853,50.00000,31.00000,1.745487e-08,0.78719
300.01801, 745.10000, 8.857137e-02,76.47731,50.00000,31.00000,1.745763e-08,0.78717
300.01099, 747.10000, 8.979230e-02,76.39160,50.00000,31.00000,1.741351e-08,0.78719
300.02802, 749.10000, 8.897965e-02,76.35840,50.00000,31.00000,1.740408e-08,0.78716
300.01801, 751.10000, 8.714609e-02,76.29412,50.00000,31.00000,1.747776e-08,0.78718
300.01199, 753.10000, 8.938518e-02,76.23004,50.00000,31.00000,1.740730e-08,0.78718
300.01501, 755.10000, 8.877467e-02,76.19202,50.00000,31.00000,1.743602e-08,0.78718
300.01700, 757.10000, 8.551708e-02,76.13487,50.00000,31.00000,1.741744e-08,0.78719
300.01999, 759.10000, 8.449932e-02,76.10651,50.00000,31.00000,1.744298e-08,0.78719
300.01999, 761.10000, 8.653545e-02,76.01849,50.00000,31.00000,1.742290e-08,0.78718
300.01501, 763.10000, 9.162524e-02,75.96155,50.00000,31.00000,1.742702e-08,0.78719
300.01501, 765.10000, 9.834442e-02,75.92584,50.00000,31.00000,1.741613e-08,0.78720
300.00900, 767.10000, 9.691845e-02,75.88298,50.00000,31.00000,1.742866e-08,0.78719
300.01099, 769.10000, 9.081035e-02,75.82605,50.00000,31.00000,1.741163e-08,0.78720
300.00699, 771.10000, 8.470163e-02,75.79748,50.00000,31.00000,1.743215e-08,0.78720
300.01501, 773.10000, 8.246271e-02,75.71912,50.00000,31.00000,1.742903e-08,0.78720
300.01901, 775.10000, 8.246310e-02,75.66912,50.00000,31.00000,1.745099e-08,0.78720
300.01099, 777.10000, 8.307315e-02,75.63109,50.00000,31.00000,1.741970e-08,0.78719
300.01001, 779.10000, 8.307305e-02,75.55987,50.00000,31.00000,1.742874e-08,0.78719
300.00699, 781.10000, 8.347997e-02,75.50042,50.00000,31.00000,1.744314e-08,0.78718
300.01001, 783.10000, 8.449833e-02,75.47185,50.00000,31.00000,1.741805e-08,0.78719
300.01599, 785.10000, 8.185197e-02,75.40777,50.00000,31.00000,1.741283e-08,0.78719
300.02600, 787.10000, 8.470354e-02,75.35777,50.00000,31.00000,1.742094e-08,0.78719
300.02399, 789.10000, 8.164913e-02,75.30063,50.00000,31.00000,1.741829e-08,0.78719
300.03201, 791.10000, 8.287160e-02,75.27941,50.00000,31.00000,1.742760e-08,0.78718
300.01199, 793.10000, 8.449852e-02,75.19370,50.00000,31.00000,1.745842e-08,0.78718
300.00500, 795.10000, 8.022203e-02,75.15819,50.00000,31.00000,1.737303e-08,0.78719
300.01099, 797.10000, 8.612731e-02,75.10819,50.00000,31.00000,1.744625e-08,0.78719
300.00900, 799.10000, 8.490544e-02,75.02983,50.00000,31.00000,1.743990e-08,0.78720
300.01001, 801.10000, 8.429471e-02,74.99412,50.00000,31.00000,1.744287e-08,0.78721
300.01599, 803.10000, 8.734949e-02,74.95378,50.00000,31.00000,1.740391e-08,0.78719
300.01801, 805.10000, 8.510996e-02,74.90378,50.00000,31.00000,1.742315e-08,0.78719
300.01401, 807.10000, 8.572039e-02,74.84685,50.00000,31.00000,1.740573e-08,0.78719
300.01901, 809.10000, 8.816425e-02,74.78971,50.00000,31.00000,1.743400e-08,0.78719
300.01801, 811.10000, 8.836776e-02,74.74685,50.00000,31.00000,1.740580e-08,0.78720
300.01801, 813.10000, 8.429551e-02,74.68277,50.00000,31.00000,1.742859e-08,0.78719
300.02600, 815.10000, 8.592522e-02,74.63277,50.00000,31.00000,1.739802e-08,0.78719
300.03000, 817.10000, 8.531479e-02,74.59013,50.00000,31.00000,1.739787e-08,0.78719
300.01300, 819.10000, 8.694196e-02,74.54013,50.00000,31.00000,1.740909e-08,0.78719
300.01801, 821.10000, 8.429551e-02,74.47605,50.00000,31.00000,1.741475e-08,0.78720
300.00699, 823.10000, 8.633051e-02,74.41891,50.00000,31.00000,1.742810e-08,0.78720
300.01999, 825.10000, 8.734990e-02,74.37626,50.00000,31.00000,1.741865e-08,0.78719
300.01199, 827.10000, 8.449852e-02,74.31197,50.00000,31.00000,1.743910e-08,0.78718
300.02200, 829.10000, 8.205617e-02,74.25504,50.00000,31.00000,1.748960e-08,0.78719
300.01700, 831.10000, 8.531347e-02,74.21933,50.00000,31.00000,1.743666e-08,0.78719
300.02399, 833.10000, 8.673947e-02,74.14790,50.00000,31.00000,1.744556e-08,0.78719
300.01401, 835.10000, 8.490595e-02,74.11471,50.00000,31.00000,1.742803e-08,0.78720
300.01901, 837.10000, 8.490645e-02,74.06471,50.00000,31.00000,1.742510e-08,0.78719
300.01599, 839.10000, 8.796032e-02,74.00063,50.00000,31.00000,1.742698e-08,0.78720
300.01999, 841.10000, 8.572100e-02,73.94370,50.00000,31.00000,1.746931e-08,0.78719
300.02100, 843.10000, 8.612833e-02,73.89370,50.00000,31.00000,1.743069e-08,0.78719
300.02301, 845.10000, 8.755383e-02,73.83655,50.00000,31.00000,1.741407e-08,0.78719
300.01300, 847.10000, 8.755279e-02,73.78908,50.00000,31.00000,1.745012e-08,0.78718
300.01401, 849.10000, 8.755290e-02,73.74643,50.00000,31.00000,1.745079e-08,0.78719
300.01501, 851.10000, 8.857106e-02,73.68929,50.00000,31.00000,1.744622e-08,0.78718
300.01199, 853.10000, 9.019963e-02,73.63214,50.00000,31.00000,1.744872e-08,0.78718
300.01501, 855.10000, 9.243969e-02,73.58950,50.00000,31.00000,1.748808e-08,0.78719
300.01001, 857.10000, 8.897775e-02,73.53950,50.00000,31.00000,1.741945e-08,0.78718
300.02200, 859.10000, 9.142238e-02,73.49685,50.00000,31.00000,1.742922e-08,0.78719
300.01300, 861.10000, 9.223585e-02,73.44685,50.00000,31.00000,1.741583e-08,0.78719
300.01199, 863.10000, 9.040324e-02,73.38971,50.00000,31.00000,1.746127e-08,0.78719
300.02200, 865.10000, 9.040431e-02,73.33992,50.00000,31.00000,1.743583e-08,0.78719
300.00900, 867.10000, 9.101375e-02,73.26870,50.00000,31.00000,1.742432e-08,0.78720
300.01199, 869.10000, 8.938518e-02,73.23298,50.00000,31.00000,1.742258e-08,0.78719
300.01401, 871.10000, 9.243957e-02,73.21155,50.00000,31.00000,1.745833e-08,0.78720
300.01700, 873.10000, 8.999655e-02,73.11891,50.00000,31.00000,1.743847e-08,0.78718
300.01199, 875.10000, 8.999602e-02,73.09034,50.00000,31.00000,1.747865e-08,0.78719
300.01901, 877.10000, 9.162567e-02,73.03319,50.00000,31.00000,1.742130e-08,0.78719
300.01999, 879.10000, 9.182939e-02,72.96912,50.00000,31.00000,1.745070e-08,0.78719
300.01599, 881.10000, 9.345785e-02,72.94055,50.00000,31.00000,1.742971e-08,0.78720
300.01300, 883.10000, 9.264308e-02,72.85504,50.00000,31.00000,1.744213e-08,0.78719
300.01700, 885.10000, 9.366157e-02,72.80504,50.00000,31.00000,1.745167e-08,0.78718
300.01099, 887.10000, 9.732590e-02,72.77668,50.00000,31.00000,1.741169e-08,0.78721
300.02100, 889.10000, 9.447647e-02,72.72668,50.00000,31.00000,1.744138e-08,0.78719
300.03000, 891.10000, 9.508832e-02,72.66261,50.00000,31.00000,1.742433e-08,0.78720
300.01199, 893.10000, 9.386463e-02,72.63403,50.00000,31.00000,1.741349e-08,0.78718
300.01099, 895.10000, 9.590062e-02,72.57458,50.00000,31.00000,1.740080e-08,0.78719
300.01599, 897.10000, 9.773370e-02,72.51050,50.00000,31.00000,1.741731e-08,0.78719
300.02200, 899.10000, 9.630910e-02,72.48193,50.00000,31.00000,1.739714e-08,0.78719
300.01501, 901.10000, 9.630831e-02,72.45105,50.00000,31.00000,1.741012e-08,0.78718
300.01801, 903.10000, 9.915922e-02,72.36534,50.00000,31.00000,1.741894e-08,0.78719
300.01501, 905.10000, 9.814081e-02,72.30126,50.00000,31.00000,1.741058e-08,0.78719
300.00299, 907.10000, 9.793580e-02,72.27269,50.00000,31.00000,1.737180e-08,0.78720
300.01401, 909.10000, 9.712264e-02,72.22752,50.00000,31.00000,1.742394e-08,0.78719
300.01801, 911.10000,      0.10099,72.17059,50.00000,31.00000,1.742934e-08,0.78719
300.01801, 913.10000, 9.691948e-02,72.10630,50.00000,31.00000,1.745042e-08,0.78719
300.02301, 915.10000, 9.834535e-02,72.05651,50.00000,31.00000,1.739518e-08,0.78718
300.01599, 917.10000,      0.10120,72.02080,50.00000,31.00000,1.741320e-08,0.78718
300.02701, 919.10000, 9.692052e-02,71.96366,50.00000,31.00000,1.740910e-08,0.78718
300.01300, 921.10000,      0.10058,71.91155,50.00000,31.00000,1.742831e-08,0.78718
300.01199, 923.10000, 9.793685e-02,71.85441,50.00000,31.00000,1.739012e-08,0.78718
300.01801, 925.10000, 9.793754e-02,71.79034,50.00000,31.00000,1.741181e-08,0.78718
300.02200, 927.10000,      0.10201,71.73319,50.00000,31.00000,1.737237e-08,0.78719
300.02701, 929.10000, 9.895666e-02,71.68319,50.00000,31.00000,1.744385e-08,0.78718
300.01801, 931.10000, 9.895561e-02,71.64769,50.00000,31.00000,1.741778e-08,0.78719
300.01501, 933.10000, 9.895526e-02,71.61197,50.00000,31.00000,1.736820e-08,0.78719
300.00900, 935.10000,      0.10343,71.55021,50.00000,31.00000,1.741310e-08,0.78718
300.00800, 937.10000,      0.10180,71.51450,50.00000,31.00000,1.744851e-08,0.78718
300.01401, 939.10000,      0.10242,71.45042,50.00000,31.00000,1.741923e-08,0.78718
300.02802, 941.10000,      0.10466,71.40756,50.00000,31.00000,1.743497e-08,0.78718
300.01901, 943.10000, 9.854850e-02,71.34580,50.00000,31.00000,1.740816e-08,0.78718
300.02499, 945.10000,      0.10038,71.29580,50.00000,31.00000,1.739241e-08,0.78718
300.01401, 947.10000,      0.10018,71.28866,50.00000,31.00000,1.740227e-08,0.78717
300.01001, 949.10000, 9.956550e-02,71.20315,50.00000,31.00000,1.746350e-08,0.78718
300.00601, 951.10000,      0.10058,71.15336,50.00000,31.00000,1.741757e-08,0.78718
300.01599, 953.10000, 9.895537e-02,71.09391,50.00000,31.00000,1.745058e-08,0.78718
300.02301, 955.10000, 9.814174e-02,71.03676,50.00000,31.00000,1.742234e-08,0.78718
300.02499, 957.10000, 9.895642e-02,71.00819,50.00000,31.00000,1.739022e-08,0.78718
300.00101, 959.10000,      0.10343,70.97269,50.00000,31.00000,1.742187e-08,0.78718
300.01501, 961.10000,      0.10445,70.90126,50.00000,31.00000,1.742427e-08,0.78718
300.01401, 963.10000,      0.10975,70.83718,50.00000,31.00000,1.742191e-08,0.78718
300.01099, 965.10000,      0.11178,70.78718,50.00000,31.00000,1.742285e-08,0.78719
300.01199, 967.10000,      0.10669,70.73025,50.00000,31.00000,1.741092e-08,0.78720
300.01401, 969.10000,      0.10466,70.69454,50.00000,31.00000,1.741829e-08,0.78720
300.01801, 971.10000,      0.10405,70.65882,50.00000,31.00000,1.742903e-08,0.78719
300.01300, 973.10000,      0.10588,70.60189,50.00000,31.00000,1.744722e-08,0.78719
300.01599, 975.10000,      0.10079,70.55672,50.00000,31.00000,1.742774e-08,0.78719
300.01300, 977.10000,      0.10160,70.47836,50.00000,31.00000,1.743983e-08,0.78719
300.01300, 979.10000,      0.10242,70.44265,50.00000,31.00000,1.748290e-08,0.78719
300.02100, 981.10000,      0.10120,70.39979,50.00000,31.00000,1.747492e-08,0.78719
300.02100, 983.10000,      0.10323,70.35714,50.00000,31.00000,1.743604e-08,0.78720
300.01801, 985.10000,      0.10018,70.30000,50.00000,31.00000,1.742806e-08,0.78719
300.02802, 987.10000,      0.10079,70.22878,50.00000,31.00000,1.746678e-08,0.78719
300.01001, 989.10000,      0.10201,70.19307,50.00000,31.00000,1.745016e-08,0.78718
300.01599, 991.10000,      0.10506,70.15021,50.00000,31.00000,1.749249e-08,0.78719
300.01599, 993.10000,      0.10221,70.08613,50.00000,31.00000,1.744853e-08,0.78719
300.00800, 995.10000,      0.10547,70.03613,50.00000,31.00000,1.742342e-08,0.78719
300.02100, 997.10000,      0.10506,69.99349,50.00000,31.00000,1.743749e-08,0.78719
300.01599, 999.10000,      0.10303,69.92920,50.00000,31.00000,1.747096e-08,0.78719
300.01501,1001.10000,      0.10323,69.87227,50.00000,31.00000,1.748170e-08,0.78719
300.01501,1003.10000,      0.10669,69.85798,50.00000,31.00000,1.745785e-08,0.78719
300.00601,1005.10000,      0.10608,69.79370,50.00000,31.00000,1.745787e-08,0.78719
300.02399,1007.10000,      0.10873,69.74391,50.00000,31.00000,1.744957e-08,0.78719
300.01300,1009.10000,      0.10791,69.68676,50.00000,31.00000,1.744452e-08,0.78719
300.00699,1011.10000,      0.10771,69.62017,50.00000,31.00000,1.745528e-08,0.78718
300.01099,1013.10000,      0.10832,69.57752,50.00000,31.00000,1.745422e-08,0.78719
300.00601,1015.10000,      0.10791,69.50609,50.00000,31.00000,1.748887e-08,0.78719
300.00699,1017.10000,      0.10913,69.47773,50.00000,31.00000,1.744880e-08,0.78719
300.02600,1019.10000,      0.11056,69.43256,50.00000,31.00000,1.747431e-08,0.78720
300.01501,1021.10000,      0.11015,69.37542,50.00000,31.00000,1.744605e-08,0.78720
300.02200,1023.10000,      0.10792,69.34685,50.00000,31.00000,1.745205e-08,0.78719
300.04001,1025.10000,      0.10832,69.30420,50.00000,31.00000,1.743879e-08,0.78721
300.01001,1027.10000,      0.10954,69.24706,50.00000,31.00000,1.749767e-08,0.78719
300.03201,1029.10000,      0.10649,69.19013,50.00000,31.00000,1.749959e-08,0.78720
300.01599,1031.10000,      0.10812,69.14727,50.00000,31.00000,1.744841e-08,0.78719
300.01801,1033.10000,      0.10853,69.09748,50.00000,31.00000,1.745999e-08,0.78719
300.01901,1035.10000,      0.11178,69.02605,50.00000,31.00000,1.743759e-08,0.78720
300.02399,1037.10000,      0.11016,68.99748,50.00000,31.00000,1.746442e-08,0.78719
300.02399,1039.10000,      0.11036,68.94055,50.00000,31.00000,1.747024e-08,0.78719
300.00699,1041.10000,      0.11097,68.89769,50.00000,31.00000,1.747993e-08,0.78718
300.01501,1043.10000,      0.11484,68.84076,50.00000,31.00000,1.746548e-08,0.78718
300.02600,1045.10000,      0.11178,68.77647,50.00000,31.00000,1.743224e-08,0.78718
300.02301,1047.10000,      0.11138,68.74097,50.00000,31.00000,1.746743e-08,0.78718
300.01099,1049.10000,      0.11382,68.70525,50.00000,31.00000,1.745816e-08,0.78718
300.01599,1051.10000,      0.11260,68.64811,50.00000,31.00000,1.741675e-08,0.78717
300.01001,1053.10000,      0.11321,68.58403,50.00000,31.00000,1.744815e-08,0.78718
300.01999,1055.10000,      0.11565,68.56261,50.00000,31.00000,1.743660e-08,0.78718
300.02200,1057.10000,      0.11748,68.49853,50.00000,31.00000,1.743868e-08,0.78719
300.01501,1059.10000,      0.11565,68.47710,50.00000,31.00000,1.747877e-08,0.78718
300.00699,1061.10000,      0.11524,68.41996,50.00000,31.00000,1.746867e-08,0.78719
300.01801,1063.10000,      0.11484,68.37962,50.00000,31.00000,1.744595e-08,0.78719
300.01199,1065.10000,      0.11626,68.32962,50.00000,31.00000,1.743105e-08,0.78719
300.01401,1067.10000,      0.11341,68.25840,50.00000,31.00000,1.746191e-08,0.78720
300.02600,1069.10000,      0.11565,68.20609,50.00000,31.00000,1.740751e-08,0.78719
300.01199,1071.10000,      0.11443,68.17752,50.00000,31.00000,1.743948e-08,0.78719
300.01001,1073.10000,      0.11585,68.14895,50.00000,31.00000,1.747846e-08,0.78718
300.01599,1075.10000,      0.11382,68.06345,50.00000,31.00000,1.745424e-08,0.78720
300.01901,1077.10000,      0.11687,68.03487,50.00000,31.00000,1.742986e-08,0.78720
300.01099,1079.10000,      0.11504,67.97794,50.00000,31.00000,1.746627e-08,0.78719
300.01401,1081.10000,      0.11667,67.91366,50.00000,31.00000,1.746269e-08,0.78719
300.02100,1083.10000,      0.11606,67.88529,50.00000,31.00000,1.748062e-08,0.78719
300.00900,1085.10000,      0.11748,67.82815,50.00000,31.00000,1.745920e-08,0.78719
300.01401,1087.10000,      0.11687,67.77122,50.00000,31.00000,1.745936e-08,0.78719
300.01801,1089.10000,      0.12115,67.70693,50.00000,31.00000,1.746465e-08,0.78720
300.02200,1091.10000,      0.11626,67.67836,50.00000,31.00000,1.743764e-08,0.78719
300.01599,1093.10000,      0.11830,67.63571,50.00000,31.00000,1.746925e-08,0.78720
300.02399,1095.10000,      0.11932,67.58571,50.00000,31.00000,1.746196e-08,0.78719
300.01501,1097.10000,      0.12074,67.52878,50.00000,31.00000,1.744832e-08,0.78718
300.01901,1099.10000,      0.11993,67.49307,50.00000,31.00000,1.746375e-08,0.78719
300.01999,1101.10000,      0.12074,67.40756,50.00000,31.00000,1.742655e-08,0.78720
300.01199,1103.10000,      0.11932,67.37185,50.00000,31.00000,1.744352e-08,0.78719
300.02200,1105.10000,      0.12196,67.32899,50.00000,31.00000,1.741727e-08,0.78720
300.00800,1107.10000,      0.12074,67.27206,50.00000,31.00000,1.742962e-08,0.78719
300.02600,1109.10000,      0.12095,67.25063,50.00000,31.00000,1.740742e-08,0.78719
300.01700,1111.10000,      0.11708,67.15315,50.00000,31.00000,1.741535e-08,0.78719
300.01700,1113.10000,      0.12156,67.12458,50.00000,31.00000,1.744422e-08,0.78718
300.01300,1115.10000,      0.12217,67.08193,50.00000,31.00000,1.744998e-08,0.78719
300.02600,1117.10000,      0.11708,67.06050,50.00000,31.00000,1.741633e-08,0.78719
300.01501,1119.10000,      0.11993,66.96786,50.00000,31.00000,1.742573e-08,0.78720
300.01801,1121.10000,      0.12135,66.93929,50.00000,31.00000,1.741158e-08,0.78719
300.00800,1123.10000,      0.12257,66.88214,50.00000,31.00000,1.747355e-08,0.78719
300.01700,1125.10000,      0.12359,66.85378,50.00000,31.00000,1.743036e-08,0.78720
300.02802,1127.10000,      0.12543,66.80378,50.00000,31.00000,1.741226e-08,0.78720
300.01700,1129.10000,      0.12665,66.75399,50.00000,31.00000,1.745893e-08,0.78720
300.00699,1131.10000,      0.12950,66.66828,50.00000,31.00000,1.747601e-08,0.78719
300.02802,1133.10000,      0.12583,66.63971,50.00000,31.00000,1.743611e-08,0.78720
300.02802,1135.10000,      0.12298,66.60420,50.00000,31.00000,1.742683e-08,0.78720
300.01599,1137.10000,      0.12196,66.53992,50.00000,31.00000,1.743309e-08,0.78720
300.02200,1139.10000,      0.12054,66.50441,50.00000,31.00000,1.746246e-08,0.78719
300.01901,1141.10000,      0.12461,66.43298,50.00000,31.00000,1.741304e-08,0.78718
300.01099,1143.10000,      0.12196,66.39748,50.00000,31.00000,1.745259e-08,0.78721
300.01199,1145.10000,      0.12542,66.35462,50.00000,31.00000,1.743393e-08,0.78719
300.01099,1147.10000,      0.12135,66.31176,50.00000,31.00000,1.741366e-08,0.78718
300.00601,1149.10000,      0.12603,66.25483,50.00000,31.00000,1.744798e-08,0.78719
300.02802,1151.10000,      0.12767,66.22626,50.00000,31.00000,1.743725e-08,0.78719
300.02100,1153.10000,      0.12543,66.14790,50.00000,31.00000,1.741806e-08,0.78718
300.03500,1155.10000,      0.12074,66.09076,50.00000,31.00000,1.741171e-08,0.78719
300.01599,1157.10000,      0.12298,66.05273,50.00000,31.00000,1.744031e-08,0.78719
300.01401,1159.10000,      0.12502,66.03845,50.00000,31.00000,1.743558e-08,0.78719
300.01501,1161.10000,      0.12604,65.98151,50.00000,31.00000,1.740192e-08,0.78719
300.01801,1163.10000,      0.12522,65.93151,50.00000,31.00000,1.742059e-08,0.78719
300.01401,1165.10000,      0.12563,65.88151,50.00000,31.00000,1.741430e-08,0.78719
300.01801,1167.10000,      0.12746,65.83403,50.00000,31.00000,1.742339e-08,0.78719
300.01999,1169.10000,      0.13072,65.78424,50.00000,31.00000,1.741022e-08,0.78719
300.01001,1171.10000,      0.12990,65.74853,50.00000,31.00000,1.742268e-08,0.78720
300.02200,1173.10000,      0.12848,65.72710,50.00000,31.00000,1.738659e-08,0.78718
300.01401,1175.10000,      0.12929,65.66303,50.00000,31.00000,1.738359e-08,0.78718
300.01300,1177.10000,      0.13072,65.60588,50.00000,31.00000,1.739961e-08,0.78719
300.01599,1179.10000,      0.13194,65.57731,50.00000,31.00000,1.741349e-08,0.78720
300.00900,1181.10000,      0.13377,65.49181,50.00000,31.00000,1.741326e-08,0.78719
300.01801,1183.10000,      0.12990,65.43487,50.00000,31.00000,1.738552e-08,0.78719
300.01401,1185.10000,      0.12868,65.39202,50.00000,31.00000,1.742444e-08,0.78719
300.01099,1187.10000,      0.13011,65.35630,50.00000,31.00000,1.737641e-08,0.78719
300.01599,1189.10000,      0.12889,65.29937,50.00000,31.00000,1.740087e-08,0.78719
300.02100,1191.10000,      0.12868,65.25651,50.00000,31.00000,1.742649e-08,0.78721
300.01099,1193.10000,      0.13235,65.19958,50.00000,31.00000,1.745955e-08,0.78719
300.01599,1195.10000,      0.13296,65.15672,50.00000,31.00000,1.743290e-08,0.78720
300.02200,1197.10000,      0.13174,65.11387,50.00000,31.00000,1.739586e-08,0.78719
300.00500,1199.10000,      0.13051,65.07122,50.00000,31.00000,1.740200e-08,0.78720
300.01999,1201.10000,      0.13601,65.04265,50.00000,31.00000,1.741855e-08,0.78719
300.00299,1203.10000,      0.13133,64.99265,50.00000,31.00000,1.741043e-08,0.78719
300.01700,1205.10000,      0.13398,64.93571,50.00000,31.00000,1.743908e-08,0.78720
300.02802,1207.10000,      0.13439,64.86429,50.00000,31.00000,1.741862e-08,0.78720
300.01901,1209.10000,      0.13581,64.85000,50.00000,31.00000,1.743917e-08,0.78720
300.03601,1211.10000,      0.13418,64.80021,50.00000,31.00000,1.739248e-08,0.78719
300.01801,1213.10000,      0.13520,64.74307,50.00000,31.00000,1.742136e-08,0.78719
300.01401,1215.10000,      0.13622,64.70756,50.00000,31.00000,1.738699e-08,0.78719
300.02701,1217.10000,      0.13988,64.68613,50.00000,31.00000,1.740314e-08,0.78720
300.01901,1219.10000,      0.13601,64.62185,50.00000,31.00000,1.741054e-08,0.78718
300.01599,1221.10000,      0.13683,64.56492,50.00000,31.00000,1.742205e-08,0.78719
299.99701,1223.10000,      0.13866,64.52920,50.00000,31.00000,1.741658e-08,0.78719
300.01099,1225.10000,      0.13988,64.47941,50.00000,31.00000,1.740038e-08,0.78720
300.01599,1227.10000,      0.13764,64.42941,50.00000,31.00000,1.736607e-08,0.78720
300.02200,1229.10000,      0.13907,64.41513,50.00000,31.00000,1.739469e-08,0.78719
300.02499,1231.10000,      0.14090,64.34391,50.00000,31.00000,1.737529e-08,0.78718
300.01901,1233.10000,      0.13927,64.31765,50.00000,31.00000,1.736452e-08,0.78718
300.00800,1235.10000,      0.13947,64.24643,50.00000,31.00000,1.741348e-08,0.78718
300.01501,1237.10000,      0.14151,64.21071,50.00000,31.00000,1.744648e-08,0.78718
300.01801,1239.10000,      0.14395,64.15378,50.00000,31.00000,1.738269e-08,0.78719
300.01801,1241.10000,      0.14131,64.13235,50.00000,31.00000,1.742132e-08,0.78719
300.00400,1243.10000,      0.14273,64.05378,50.00000,31.00000,1.738754e-08,0.78718
300.03000,1245.10000,      0.14009,64.01828,50.00000,31.00000,1.740991e-08,0.78718
300.03299,1247.10000,      0.14009,63.96113,50.00000,31.00000,1.739537e-08,0.78719
300.01001,1249.10000,      0.13499,63.90420,50.00000,31.00000,1.737452e-08,0.78719
300.01199,1251.10000,      0.14212,63.85189,50.00000,31.00000,1.737504e-08,0.78720
300.01199,1253.10000,      0.14273,63.84475,50.00000,31.00000,1.741784e-08,0.78720
300.01099,1255.10000,      0.14232,63.78298,50.00000,31.00000,1.737690e-08,0.78719
300.02100,1257.00000,      0.13968,63.74727,50.00000,31.00000,1.742322e-08,0.78720