File: data/TGA/005d-L_M/ExpDat_2025_03_29_SL_005d_M1_isothermal.csv
#EXPORTTYPE:                 ,DATA ALL
#FILE:                       ,2025_03_29_SL_005d_M1_isothermal.ngb-ss5
#FORMAT:                     ,NETZSCH5
#FTYPE:                      ,ASCII
#IDENTITY:                   ,2025_03_29_SL_005d_M1
#DECIMAL:                    ,POINT
#SEPARATOR:                  ,COMMA
#MTYPE:                      ,DSC
#INSTRUMENT:                 ,NETZSCH STA 449F5
#PROJECT:                    ,PS
#DATE/TIME:                  ,3/29/2025 5:33:52 PM (UTC-4)
#CORR. FILE:                 ,
#TEMPCAL:                    ,13-11-2024 10:37
#SENSITIVITY:                ,28-06-2023 13:53
#LABORATORY:                 ,Tran/Aspuru
#OPERATOR:                   ,Stanley
#REMARK:                     ,2025_03_29_SL_005d_M1_isothermal
#SAMPLE:                     ,2025_03_29_SL_005d_M1
#SAMPLE MASS /mg:            ,5.00
#MATERIAL:                   ,Polystyrene
#REFERENCE:                  ,
#REFERENCE MASS /mg:         ,0
#TYPE OF CRUCIBLE:           ,Al2O3 85 ‘l, open
#SAMPLE CRUCIBLE MASS /mg:   ,0
#REFERENCE CRUCIBLE MASS /mg:,0
#DSC RANGE /‘V:              ,5000
#TG RANGE /mg:               ,35000
#TAU-R:                      ,---
#CORR. CODE:                 ,000
#EXO:                        ,-1
#RANGE:                      ,30›C....800›C/0.0....20.0K/min
#SEGMENT:                    ,S1-5/5
#SEG. 1:                     ,30›C/10.0(K/min)/100›C
#SEG. 2:                     ,100›C/00:10/100›C
#SEG. 3:                     ,100›C/5.0(K/min)/300›C
#SEG. 4:                     ,300›C/20:00/300›C
#SEG. 5:                     ,300›C/20.0(K/min)/800›C

##Temp./›C,Time/min,DSC/(mW/mg),Mass/%,Gas Flow(purge2)/(ml/min),Gas Flow(protective)/(ml/min),TIC(scan:1)/A,Sensit./(uV/mW),Segment
 28.63900,   0.00000,     -0.24575,100.00000,50.00000,50.00000,            ,0.92330,1
 31.42000,   1.32000,-4.938653e-02, 93.62840,50.00000,50.00000,3.070030e-10,0.92338,1
 38.34800,   2.64000,      0.27717, 94.36820,50.00000,50.00000,3.079071e-10,0.92347,1
 48.39100,   3.96000,      0.49277, 95.61960,50.00000,50.00000,3.066634e-10,0.92361,1
 61.60700,   5.28000,      0.68042, 96.63540,50.00000,50.00000,3.062324e-10,0.92379,1
 76.95100,   6.60000,      0.75867, 97.30740,50.00000,50.00000,3.064098e-10,0.92401,1
 87.46700,   7.46000,      0.72505, 97.46580,50.00000,50.00000,3.070869e-10,0.92420,2
 94.15600,   8.12000,      0.40398, 96.65800,50.00000,50.00000,3.069916e-10,0.92433,2
 98.97600,   8.78000, 6.161304e-02, 95.68280,50.00000,50.00000,3.067151e-10,0.92446,2
102.49700,   9.44000,     -0.10627, 94.96340,50.00000,50.00000,3.070392e-10,0.92460,2
105.33900,  10.10000,     -0.15199, 94.42260,50.00000,50.00000,3.067417e-10,0.92474,2
107.57800,  10.76000,     -0.19626, 93.91340,50.00000,50.00000,3.076020e-10,0.92487,2
109.11100,  11.42000,     -0.26712, 93.33420,50.00000,50.00000,3.073025e-10,0.92501,2
110.02600,  12.08000,     -0.33333, 92.79580,50.00000,50.00000,3.072223e-10,0.92510,2
110.40500,  12.74000,     -0.37542, 92.34100,50.00000,50.00000,3.069363e-10,0.92524,2
110.40200,  13.40000,     -0.40085, 91.90880,50.00000,50.00000,3.069591e-10,0.92539,2
110.09700,  14.06000,     -0.41709, 91.54220,50.00000,50.00000,3.076077e-10,0.92551,2
109.60100,  14.72000,     -0.43032, 91.18020,50.00000,50.00000,3.075982e-10,0.92563,2
108.93400,  15.38000,     -0.43720, 90.87020,50.00000,50.00000,3.069534e-10,0.92574,2
108.17300,  16.04000,     -0.43958, 90.53980,50.00000,50.00000,3.060379e-10,0.92584,2
107.33500,  16.70000,     -0.44096, 90.25700,50.00000,50.00000,3.075256e-10,0.92593,2
106.24300,  17.72000,     -0.39816, 90.12580,50.00000,50.00000,3.072090e-10,0.92604,3
107.33800,  19.04000,     -0.17599, 90.86340,50.00000,50.00000,3.070926e-10,0.92615,3
110.59800,  20.36000,     -0.10055, 91.33180,50.00000,50.00000,3.076553e-10,0.92620,3
115.59800,  21.68000,-4.661712e-03, 91.84080,50.00000,50.00000,3.070658e-10,0.92618,3
122.04900,  23.00000, 6.893012e-02, 92.25720,50.00000,50.00000,3.083400e-10,0.92607,3
129.33600,  24.32000,      0.11753, 92.50160,50.00000,50.00000,3.075504e-10,0.92589,3
137.12601,  25.64000,      0.15761, 92.62380,50.00000,50.00000,3.076687e-10,0.92561,3
144.96700,  26.96000,      0.19148, 92.68260,50.00000,50.00000,3.075981e-10,0.92523,3
152.73399,  28.28000,      0.22551, 92.66900,50.00000,50.00000,3.083496e-10,0.92476,3
160.27800,  29.60000,      0.26499, 92.66220,50.00000,50.00000,3.074874e-10,0.92437,3
167.56900,  30.92000,      0.30999, 92.63500,50.00000,50.00000,3.078822e-10,0.92407,3
174.66400,  32.24000,      0.36250, 92.63500,50.00000,50.00000,3.081303e-10,0.92375,3
181.55701,  33.56000,      0.42090, 92.63500,50.00000,50.00000,3.077317e-10,0.92339,3
188.34000,  34.88000,      0.48844, 92.63500,50.00000,50.00000,3.078747e-10,0.92307,3
195.03500,  36.20000,      0.56319, 92.64180,50.00000,50.00000,3.081150e-10,0.92275,3
201.66701,  37.52000,      0.64459, 92.61460,50.00000,50.00000,3.077335e-10,0.92245,3
208.26900,  38.84000,      0.73386, 92.61460,50.00000,50.00000,3.074780e-10,0.92215,3
214.83400,  40.16000,      0.83239, 92.55580,50.00000,50.00000,3.080863e-10,0.92188,3
221.41100,  41.48000,      0.93880, 92.46760,50.00000,50.00000,3.079128e-10,0.92161,3
227.97000,  42.80000,      1.05434, 92.38620,50.00000,50.00000,3.074645e-10,0.92137,3
234.53900,  44.12000,      1.17797, 92.23000,50.00000,50.00000,3.082770e-10,0.92113,3
241.10100,  45.44000,      1.30859, 92.07400,50.00000,50.00000,3.082410e-10,0.92091,3
247.67700,  46.76000,      1.44604, 91.89740,50.00000,50.00000,3.084812e-10,0.92070,3
254.24800,  48.08000,      1.58790, 91.70740,50.00000,50.00000,3.076496e-10,0.92049,3
260.83099,  49.40000,      1.72283, 91.52400,50.00000,50.00000,3.079415e-10,0.92030,3
267.41000,  50.72000,      1.87812, 91.31140,50.00000,50.00000,3.082275e-10,0.92010,3
273.98901,  52.04000,      2.05089, 91.03760,50.00000,50.00000,3.082676e-10,0.91992,3
280.57300,  53.36000,      2.17122, 90.74580,50.00000,50.00000,3.077660e-10,0.91974,3
287.14801,  54.68000,      2.34507, 90.32940,50.00000,50.00000,3.083210e-10,0.91956,3
293.70599,  56.00000,      2.53418, 89.77960,50.00000,50.00000,3.080139e-10,0.91940,3
301.74301,  57.80000,      2.58878, 90.54660,50.00000,27.00000,3.081226e-10,0.91919,4
303.42499,  61.10000,      2.46435, 87.50320,50.00000,27.00000,3.077030e-10,0.91885,4
302.14600,  64.40000,      2.51948, 85.43520,50.00000,27.00000,3.081722e-10,0.91858,4
301.05499,  67.70000,      2.56376, 83.80380,50.00000,27.00000,3.081379e-10,0.91838,4
300.48999,  71.00000,      2.60336, 82.38060,50.00000,27.00000,3.087788e-10,0.91825,4
300.23901,  74.30000,      2.63419, 81.13160,50.00000,27.00000,3.082428e-10,0.91818,4
300.10599,  77.60000,      2.66382, 79.95040,50.00000,27.00000,3.087902e-10,0.91815,4
300.05099,  80.90000,      2.68923, 78.85300,50.00000,27.00000,3.090649e-10,0.91815,4
300.02301,  84.20000,      2.70911, 77.83260,50.00000,27.00000,3.083706e-10,0.91820,4
300.02301,  87.50000,      2.72714, 76.88460,50.00000,26.00000,3.091050e-10,0.91827,4
300.00601,  90.80000,      2.73929, 76.01340,50.00000,26.00000,3.086358e-10,0.91836,4
300.00500,  94.10000,      2.74879, 75.16720,50.00000,27.00000,3.089237e-10,0.91847,4
300.00500,  97.40000,      2.79628, 74.35040,50.00000,26.00000,3.088513e-10,0.91860,4
300.01501, 100.70000,      2.80445, 73.52900,50.00000,26.00000,3.090420e-10,0.91873,4
300.00201, 104.00000,      2.81623, 72.76420,50.00000,26.00000,3.089676e-10,0.91888,4
300.01401, 107.30000,      2.81899, 71.99500,50.00000,26.00000,3.095684e-10,0.91903,4
300.01300, 110.60000,      2.81259, 71.20520,50.00000,26.00000,3.094863e-10,0.91918,4
300.01599, 113.90000,      2.82248, 70.47220,50.00000,26.00000,3.094844e-10,0.91938,4
300.01801, 117.20000,      2.82268, 69.76620,50.00000,26.00000,3.098946e-10,0.91926,4
300.01801, 120.50000,      2.82675, 69.06020,50.00000,26.00000,3.101253e-10,0.91885,4
300.01401, 123.80000,      2.83004, 68.32720,50.00000,27.00000,3.089656e-10,0.91821,4
300.02600, 127.10000,      2.82232, 67.64160,50.00000,27.00000,3.094501e-10,0.91736,4
300.01099, 130.40000,      2.82789, 66.93560,50.00000,27.00000,3.104629e-10,0.91627,4
300.00201, 133.70000,      2.82011, 66.25680,50.00000,27.00000,3.095074e-10,0.91492,4
300.01199, 137.00000,      2.81976, 65.58480,50.00000,27.00000,3.106842e-10,0.91336,4
300.01901, 140.30000,      2.81784, 64.95340,50.00000,27.00000,3.098908e-10,0.91161,4
300.02200, 143.60000,      2.81494, 64.35620,50.00000,27.00000,3.095628e-10,0.90968,4
300.01099, 146.90000,      2.81374, 63.64780,50.00000,27.00000,3.103523e-10,0.90749,4
299.99799, 150.20000,      2.80692, 63.05740,50.00000,27.00000,3.112317e-10,0.90528,4
300.00500, 153.50000,      2.79860, 62.44420,50.00000,27.00000,3.103275e-10,0.90299,4
300.04501, 156.80000,      2.80959, 61.88080,50.00000,27.00000,3.113365e-10,0.90060,4
300.01501, 160.10000,      2.80678, 61.29240,50.00000,27.00000,3.108406e-10,0.89816,4
300.01901, 163.40000,      2.80078, 60.72000,50.00000,27.00000,3.114300e-10,0.89569,4
300.01999, 166.70000,      2.80195, 60.12260,50.00000,27.00000,3.112049e-10,0.89318,4
300.00201, 170.00000,      2.79355, 59.60680,50.00000,27.00000,3.110351e-10,0.89050,4
300.01700, 173.30000,      2.79729, 59.06140,50.00000,27.00000,3.114148e-10,0.88792,4
300.02802, 176.60000,      2.79538, 58.55240,50.00000,27.00000,3.111399e-10,0.88530,4
300.00900, 179.90000,      2.78951, 57.98220,50.00000,27.00000,3.107376e-10,0.88264,4
300.02301, 183.20000,      2.78703, 57.46180,50.00000,27.00000,3.120670e-10,0.87995,4
300.02100, 186.50000,      2.78955, 56.95940,50.00000,27.00000,3.121738e-10,0.87722,4
300.02200, 189.80000,      2.78296, 56.46840,50.00000,27.00000,3.118687e-10,0.87442,4
300.01501, 193.10000,      2.78255, 55.95260,50.00000,27.00000,3.114795e-10,0.87161,4
300.01300, 196.40000,      2.78022, 55.49100,50.00000,27.00000,3.119506e-10,0.86860,4
300.00201, 199.70000,      2.77824, 55.02020,50.00000,27.00000,3.118153e-10,0.86568,4
300.02600, 203.00000,      2.77580, 54.52480,50.00000,27.00000,3.112889e-10,0.86272,4
300.00201, 206.30000,      2.77301, 54.08120,50.00000,27.00000,3.126698e-10,0.85972,4
300.00699, 209.60000,      2.77128, 53.56320,50.00000,27.00000,3.113822e-10,0.85666,4
300.00699, 212.90000,      2.77186, 53.15580,50.00000,27.00000,3.119336e-10,0.85356,4
300.00900, 216.20000,      2.76974, 52.70780,50.00000,27.00000,3.118381e-10,0.85025,4
299.99799, 219.50000,      2.76640, 52.25300,50.00000,27.00000,3.122196e-10,0.84706,4
300.02200, 222.80000,      2.76493, 51.84120,50.00000,27.00000,3.115578e-10,0.84382,4
300.01999, 226.10000,      2.76241, 51.45880,50.00000,27.00000,3.113080e-10,0.84055,4
300.00900, 229.40000,      2.76101, 51.06520,50.00000,27.00000,3.118667e-10,0.83723,4
300.01300, 232.70000,      2.75967, 50.68500,50.00000,27.00000,3.121681e-10,0.83369,4
300.01700, 236.00000,      2.75833, 50.27540,50.00000,27.00000,3.126049e-10,0.83031,4
300.01199, 239.30000,      2.75637, 49.86140,50.00000,27.00000,3.121376e-10,0.82687,4
300.02399, 242.60000,      2.75525, 49.49260,50.00000,27.00000,3.122672e-10,0.82340,4
300.02399, 245.90000,      2.75525, 49.10340,50.00000,27.00000,3.119946e-10,0.81991,4
300.00101, 249.20000,      2.75381, 48.75040,50.00000,27.00000,3.123722e-10,0.81638,4
300.02200, 252.50000,      2.75214, 48.36120,50.00000,27.00000,3.130055e-10,0.81283,4
300.02802, 255.80000,      2.75274, 47.97440,50.00000,27.00000,3.130035e-10,0.80926,4
300.01099, 259.10000,      2.75268, 47.62140,50.00000,27.00000,3.130627e-10,0.80565,4
300.02200, 262.40000,      2.75098, 47.27520,50.00000,27.00000,3.129348e-10,0.80185,4
300.01001, 265.70000,      2.75423, 46.89500,50.00000,27.00000,3.129864e-10,0.79819,4
300.01001, 269.00000,      2.75074, 46.56920,50.00000,27.00000,3.098431e-10,0.79452,4
300.01599, 272.30000,      2.74999, 46.18900,50.00000,27.00000,2.951430e-10,0.79084,4
300.01901, 275.60000,      2.74980, 45.87680,50.00000,27.00000,2.945366e-10,0.78579,4
300.01801, 278.90000,      2.74902, 45.51020,50.00000,27.00000,2.949086e-10,0.78411,4
300.02899, 282.20000,      2.74848, 45.17080,50.00000,27.00000,2.950707e-10,0.78418,4
300.01501, 285.50000,      2.74824, 44.84500,50.00000,27.00000,2.954636e-10,0.78497,4
300.01901, 288.80000,      2.74728, 44.51920,50.00000,27.00000,2.948360e-10,0.78569,4
300.02100, 292.10000,      2.74186, 44.20020,50.00000,27.00000,2.940159e-10,0.78624,4
300.02899, 295.40000,      2.74053, 43.86520,50.00000,27.00000,2.937870e-10,0.78660,4
300.02399, 298.70000,      2.74051, 43.56660,50.00000,27.00000,2.949619e-10,0.78683,4
300.01501, 302.00000,      2.73622, 43.25440,50.00000,27.00000,2.943306e-10,0.78696,4
300.00800, 305.30000,      2.69472, 42.93540,50.00000,27.00000,2.941609e-10,0.78705,4
300.01901, 308.60000,      2.69088, 42.62980,50.00000,27.00000,2.935639e-10,0.78711,4
300.02200, 311.90000,      2.68895, 42.31540,50.00000,27.00000,2.944699e-10,0.78715,4
300.01901, 315.20000,      2.68739, 42.01900,50.00000,27.00000,2.948169e-10,0.78716,4
300.01401, 318.50000,      2.68427, 41.70440,50.00000,27.00000,2.948817e-10,0.78718,4
300.02499, 321.80000,      2.68411, 41.43300,50.00000,27.00000,2.950859e-10,0.78719,4
300.01501, 325.10000,      2.68175, 41.14780,50.00000,27.00000,2.947255e-10,0.78719,4
300.01801, 328.40000,      2.68002, 40.84920,50.00000,27.00000,2.951659e-10,0.78720,4
300.00400, 331.70000,      2.67823, 40.57080,50.00000,27.00000,2.953166e-10,0.78720,4
300.01999, 335.00000,      2.67905, 40.29260,50.00000,27.00000,2.950153e-10,0.78720,4
300.03601, 338.30000,      2.67717, 40.00740,50.00000,27.00000,2.950363e-10,0.78719,4
300.03900, 341.60000,      2.67524, 39.78340,50.00000,27.00000,2.951470e-10,0.78720,4
300.03500, 344.90000,      2.67271, 39.53220,50.00000,26.00000,2.944070e-10,0.78720,4
300.03900, 348.20000,      2.67020, 39.23360,50.00000,26.00000,2.947254e-10,0.78719,4
300.04999, 351.50000,      2.66810, 39.00960,50.00000,26.00000,2.947140e-10,0.78720,4
300.03400, 354.80000,      2.66495, 38.71100,50.00000,26.00000,2.941780e-10,0.78721,4
300.03601, 358.10000,      2.66263, 38.53440,50.00000,26.00000,2.951869e-10,0.78720,4
300.01999, 361.40000,      2.65870, 38.27640,50.00000,26.00000,2.940426e-10,0.78719,4
300.02399, 364.70000,      2.65794, 37.99140,50.00000,26.00000,2.944870e-10,0.78721,4
300.03500, 368.00000,      2.65565, 37.73340,50.00000,26.00000,2.944202e-10,0.78720,4
300.01801, 371.30000,      2.65346, 37.49580,50.00000,26.00000,2.946433e-10,0.78720,4
300.02701, 374.60000,      2.64942, 37.29900,50.00000,26.00000,2.947674e-10,0.78719,4
300.00601, 377.90000,      2.64703, 37.08180,50.00000,26.00000,2.947522e-10,0.78719,4
300.02399, 381.20000,      2.64437, 36.86460,50.00000,26.00000,2.949886e-10,0.78720,4
300.01599, 384.50000,      2.63911, 36.65180,50.00000,26.00000,2.947101e-10,0.78720,4
300.01401, 387.80000,      2.63542, 36.36680,50.00000,26.00000,2.952975e-10,0.78719,4
300.02499, 391.10000,      2.63197, 36.18800,50.00000,26.00000,2.953319e-10,0.78720,4
300.02100, 394.40000,      2.63060, 35.93680,50.00000,26.00000,2.943077e-10,0.78718,4
300.01401, 397.70000,      2.62767, 35.69240,50.00000,26.00000,2.954406e-10,0.78720,4
300.00299, 401.00000,      2.62550, 35.50240,50.00000,26.00000,2.952823e-10,0.78720,4
300.02100, 404.30000,      2.62343, 35.31240,50.00000,26.00000,2.947942e-10,0.78719,4
300.01001, 407.60000,      2.62048, 35.07940,50.00000,26.00000,2.948381e-10,0.78720,4
300.03299, 410.90000,      2.61804, 34.91640,50.00000,26.00000,2.958966e-10,0.78719,4
300.02100, 414.20000,      2.61625, 34.69240,50.00000,26.00000,2.946302e-10,0.78719,4
300.00900, 417.50000,      2.61370, 34.46840,50.00000,26.00000,2.944812e-10,0.78720,4
300.01501, 420.80000,      2.61197, 34.25120,50.00000,26.00000,2.941532e-10,0.78719,4
300.01199, 424.10000,      2.61060, 34.06780,50.00000,26.00000,2.946244e-10,0.78719,4
300.01599, 427.40000,      2.60771, 33.87780,50.00000,26.00000,2.953396e-10,0.78720,4
300.02499, 430.70000,      2.60347, 33.68100,50.00000,26.00000,2.948323e-10,0.78720,4
300.01401, 434.00000,      2.60247, 33.47060,50.00000,26.00000,2.948514e-10,0.78720,4
300.01700, 437.30000,      2.60073, 33.28040,50.00000,26.00000,2.953395e-10,0.78719,4
300.01199, 440.60000,      2.59917, 33.06320,50.00000,26.00000,2.943172e-10,0.78719,4
300.01999, 443.90000,      2.59861, 32.88000,50.00000,26.00000,2.945366e-10,0.78719,4
300.01099, 447.20000,      2.59606, 32.69680,50.00000,26.00000,2.949809e-10,0.78719,4
300.01501, 450.50000,      2.59375, 32.50660,50.00000,26.00000,2.951241e-10,0.78720,4
300.00900, 453.80000,      2.59141, 32.33020,50.00000,26.00000,2.949238e-10,0.78717,4
300.01401, 457.10000,      2.59161, 32.16040,50.00000,26.00000,2.955475e-10,0.78720,4
300.02200, 460.40000,      2.58951, 31.97720,50.00000,26.00000,2.947159e-10,0.78720,4
300.01901, 463.70000,      2.58795, 31.80740,50.00000,26.00000,2.952156e-10,0.78719,4
300.02301, 467.00000,      2.58486, 31.65140,50.00000,26.00000,2.953549e-10,0.78720,4
300.04901, 470.30000,      2.58125, 31.48160,50.00000,26.00000,2.961425e-10,0.78720,4
300.01001, 473.60000,      2.57803, 31.26440,50.00000,26.00000,2.965775e-10,0.78720,4
299.99701, 476.90000,      2.57470, 31.10160,50.00000,26.00000,2.960414e-10,0.78720,4
300.00500, 480.20000,      2.57317, 30.95220,50.00000,26.00000,2.963448e-10,0.78718,4
299.99701, 483.50000,      2.57218, 30.76900,50.00000,26.00000,2.964420e-10,0.78719,4
300.00601, 486.80000,      2.56969, 30.58560,50.00000,26.00000,2.965602e-10,0.78718,4
300.03101, 490.10000,      2.56996, 30.44980,50.00000,26.00000,2.964478e-10,0.78718,4
300.03201, 493.40000,      2.56821, 30.28020,50.00000,26.00000,2.960720e-10,0.78718,4
300.02899, 496.70000,      2.56491, 30.11720,50.00000,26.00000,2.955266e-10,0.78718,4
300.02701, 500.00000,      2.56374, 29.97240,50.00000,26.00000,2.964381e-10,0.78718,4
300.03699, 503.30000,      2.56183, 29.82320,50.00000,26.00000,2.964344e-10,0.78719,4
300.00101, 506.60000,      2.55785, 29.67380,50.00000,26.00000,2.962073e-10,0.78720,4
300.01801, 509.90000,      2.55771, 29.52440,50.00000,26.00000,2.968445e-10,0.78719,4
300.00699, 513.20000,      2.55476, 29.42260,50.00000,26.00000,2.956105e-10,0.78718,4
300.01801, 516.50000,      2.55208, 29.23940,50.00000,26.00000,2.958966e-10,0.78720,4
300.01599, 519.80000,      2.55091, 29.11720,50.00000,26.00000,2.962952e-10,0.78720,4
300.02499, 523.10000,      2.54842, 28.97460,50.00000,26.00000,2.963466e-10,0.78720,4
300.01801, 526.40000,      2.54627, 28.81840,50.00000,26.00000,2.959138e-10,0.78720,4
300.01001, 529.70000,      2.54469, 28.68280,50.00000,26.00000,2.966328e-10,0.78720,4
300.02301, 533.00000,      2.54183, 28.55380,50.00000,26.00000,2.957229e-10,0.78720,4
300.02600, 536.30000,      2.53796, 28.39540,50.00000,26.00000,2.961006e-10,0.78719,4
300.01001, 539.60000,      2.53539, 28.29360,50.00000,26.00000,2.965851e-10,0.78720,4
300.01801, 542.90000,      2.53173, 28.15780,50.00000,26.00000,2.966575e-10,0.78719,4
300.00299, 546.20000,      2.53033, 27.98800,50.00000,26.00000,2.966060e-10,0.78719,4
300.01901, 549.50000,      2.52689, 27.85920,50.00000,26.00000,2.966250e-10,0.78719,4
300.00500, 552.80000,      2.52374, 27.75040,50.00000,26.00000,2.973880e-10,0.78719,4
300.00800, 556.10000,      2.52065, 27.60800,50.00000,26.00000,2.966996e-10,0.78719,4
300.01401, 559.40000,      2.51796, 27.46540,50.00000,26.00000,2.970810e-10,0.78718,4
300.01501, 562.70000,      2.51525, 27.35000,50.00000,26.00000,2.973556e-10,0.78719,4
300.01199, 566.00000,      2.51446, 27.19380,50.00000,26.00000,2.973062e-10,0.78718,4
300.01599, 569.30000,      2.51137, 27.07840,50.00000,26.00000,2.978095e-10,0.78719,4
300.02100, 572.60000,      2.51042, 26.89520,50.00000,26.00000,2.962703e-10,0.78719,4
300.01999, 575.90000,      2.50925, 26.79340,50.00000,26.00000,2.971305e-10,0.78719,4
300.03699, 579.20000,      2.50833, 26.67800,50.00000,26.00000,2.971878e-10,0.78719,4
300.02100, 582.50000,      2.50538, 26.56260,50.00000,26.00000,2.967682e-10,0.78719,4
300.01700, 585.80000,      2.50168, 26.43360,50.00000,26.00000,2.969131e-10,0.78717,4
300.01700, 589.10000,      2.49916, 26.32500,50.00000,26.00000,2.975616e-10,0.78719,4
300.00299, 592.40000,      2.49893, 26.20960,50.00000,26.00000,2.971838e-10,0.78719,4
300.01999, 595.70000,      2.49297, 26.08740,50.00000,26.00000,2.972602e-10,0.78719,4
300.00000, 599.00000,      2.49078, 25.98780,50.00000,26.00000,2.976437e-10,0.78719,4
300.02499, 602.30000,      2.48949, 25.87240,50.00000,26.00000,2.970295e-10,0.78719,4
300.01199, 605.60000,      2.48539, 25.75700,50.00000,26.00000,2.969914e-10,0.78720,4
300.01099, 608.90000,      2.48383, 25.65520,50.00000,26.00000,2.965793e-10,0.78720,4
300.01300, 612.20000,      2.48112, 25.54660,50.00000,26.00000,2.977925e-10,0.78719,4
300.01001, 615.50000,      2.48092, 25.44480,50.00000,26.00000,2.973289e-10,0.78719,4
300.03799, 618.80000,      2.47596, 25.34300,50.00000,26.00000,2.979755e-10,0.78719,4
300.02100, 622.10000,      2.47475, 25.22080,50.00000,26.00000,2.973252e-10,0.78718,4
300.01599, 625.40000,      2.47125, 25.11220,50.00000,26.00000,2.970773e-10,0.78719,4
299.99899, 628.70000,      2.46926, 25.01720,50.00000,26.00000,2.980899e-10,0.78719,4
300.00800, 632.00000,      2.46793, 24.91540,50.00000,26.00000,2.978782e-10,0.78719,4
300.01501, 635.30000,      2.46504, 24.82040,50.00000,26.00000,2.981490e-10,0.78720,4
300.02399, 638.60000,      2.46197, 24.70500,50.00000,26.00000,2.979144e-10,0.78718,4
300.01599, 641.90000,      2.46020, 24.60980,50.00000,26.00000,2.980060e-10,0.78718,4
300.01001, 645.20000,      2.45785, 24.47420,50.00000,26.00000,2.974204e-10,0.78719,4
300.01501, 648.50000,      2.45593, 24.37920,50.00000,26.00000,2.980251e-10,0.78720,4
300.02301, 651.80000,      2.45460, 24.29080,50.00000,26.00000,2.982159e-10,0.78720,4
300.01901, 655.10000,      2.45090, 24.17540,50.00000,26.00000,2.985478e-10,0.78719,4
300.00101, 658.40000,      2.45008, 24.06680,50.00000,26.00000,2.985096e-10,0.78719,4
300.01700, 661.70000,      2.44605, 23.97860,50.00000,26.00000,2.979813e-10,0.78717,4
300.00800, 665.00000,      2.44467, 23.86320,50.00000,26.00000,2.979697e-10,0.78719,4
300.01501, 668.30000,      2.44256, 23.76820,50.00000,26.00000,2.981587e-10,0.78719,4
300.02600, 671.60000,      2.43929, 23.65280,50.00000,26.00000,2.987232e-10,0.78719,4
300.01099, 674.90000,      2.43634, 23.56460,50.00000,26.00000,2.988529e-10,0.78718,4
300.01401, 678.20000,      2.43499, 23.50340,50.00000,26.00000,2.982120e-10,0.78719,4
300.01099, 681.50000,      2.43188, 23.38800,50.00000,26.00000,2.984389e-10,0.78720,4
300.02802, 684.80000,      2.42902, 23.31340,50.00000,26.00000,2.975597e-10,0.78720,4
300.02200, 688.10000,      2.42610, 23.18440,50.00000,26.00000,2.983073e-10,0.78720,4
300.02899, 691.40000,      2.42399, 23.13020,50.00000,26.00000,2.983818e-10,0.78719,4
300.02301, 694.70000,      2.42087, 23.02820,50.00000,26.00000,2.989578e-10,0.78719,4
300.02802, 698.00000,      2.41895, 22.94680,50.00000,26.00000,2.988395e-10,0.78719,4
300.02301, 701.30000,      2.41467, 22.83820,50.00000,26.00000,2.993621e-10,0.78719,4
300.01599, 704.60000,      2.41290, 22.75000,50.00000,26.00000,2.994003e-10,0.78720,4
300.01801, 707.90000,      2.41039, 22.63460,50.00000,26.00000,2.989329e-10,0.78718,4
300.02301, 711.20000,      2.40788, 22.55320,50.00000,26.00000,2.988222e-10,0.78718,4
300.00400, 714.50000,      2.40511, 22.47160,50.00000,26.00000,2.980900e-10,0.78720,4
300.01501, 717.80000,      2.40263, 22.39020,50.00000,26.00000,2.995510e-10,0.78718,4
300.02200, 721.10000,      2.39896, 22.29520,50.00000,26.00000,2.993965e-10,0.78718,4
300.01501, 724.40000,      2.39623, 22.19340,50.00000,26.00000,2.994212e-10,0.78718,4
300.01700, 727.70000,      2.39313, 22.11860,50.00000,26.00000,2.994900e-10,0.78719,4
300.00800, 731.00000,      2.38981, 22.02360,50.00000,26.00000,2.994652e-10,0.78719,4
300.02701, 734.30000,      2.38735, 21.93540,50.00000,26.00000,2.994500e-10,0.78717,4
300.01700, 737.60000,      2.38267, 21.84040,50.00000,26.00000,2.996712e-10,0.78716,4
300.01401, 740.90000,      2.38072, 21.77260,50.00000,26.00000,2.994443e-10,0.78717,4
300.01801, 744.20000,      2.37685, 21.67060,50.00000,26.00000,2.989025e-10,0.78717,4
300.01801, 747.50000,      2.37181, 21.58920,50.00000,26.00000,2.994633e-10,0.78716,4
300.03201, 750.80000,      2.36875, 21.52820,50.00000,26.00000,3.003235e-10,0.78718,4
300.01801, 754.10000,      2.36503, 21.43300,50.00000,26.00000,3.000182e-10,0.78717,4
300.01099, 757.40000,      2.36075, 21.37200,50.00000,26.00000,3.008347e-10,0.78716,4
300.00601, 760.70000,      2.35744, 21.27700,50.00000,26.00000,2.999460e-10,0.78717,4
300.01300, 764.00000,      2.35435, 21.16160,50.00000,26.00000,3.005277e-10,0.78717,4
300.02200, 767.30000,      2.35147, 21.12320,50.00000,26.00000,3.001862e-10,0.78718,4
300.01401, 770.60000,      2.35087, 21.02120,50.00000,26.00000,3.002261e-10,0.78718,4
300.01501, 773.90000,      2.35048, 20.93300,50.00000,26.00000,3.006440e-10,0.78719,4
300.02100, 777.20000,      2.35224, 20.85160,50.00000,26.00000,3.003446e-10,0.78719,4
300.01199, 780.50000,      2.35726, 20.81080,50.00000,26.00000,3.006229e-10,0.78718,4
300.02600, 783.80000,      2.35478, 20.68860,50.00000,26.00000,2.999076e-10,0.78718,4
300.02701, 787.10000,      2.35672, 20.62760,50.00000,26.00000,3.000469e-10,0.78718,4
300.00601, 790.40000,      2.35608, 20.55980,50.00000,26.00000,3.003635e-10,0.78719,4
300.01901, 793.70000,      2.35340, 20.48500,50.00000,26.00000,3.002568e-10,0.78720,4
300.01801, 797.00000,      2.35301, 20.43080,50.00000,26.00000,3.004093e-10,0.78719,4
300.01599, 800.30000,      2.35107, 20.34920,50.00000,26.00000,3.001481e-10,0.78720,4
300.01901, 803.60000,      2.35049, 20.26780,50.00000,26.00000,2.998791e-10,0.78719,4
300.02100, 806.90000,      2.34972, 20.18640,50.00000,26.00000,3.016433e-10,0.78719,4
300.00400, 810.20000,      2.34871, 20.12520,50.00000,26.00000,3.010235e-10,0.78718,4
300.01801, 813.50000,      2.36232, 20.05740,50.00000,26.00000,3.004761e-10,0.78720,4
300.02301, 816.80000,      2.36039, 19.99620,50.00000,26.00000,3.013497e-10,0.78720,4
300.00000, 820.10000,      2.35936, 19.91480,50.00000,26.00000,3.009948e-10,0.78719,4
300.01501, 823.40000,      2.35688, 19.86060,50.00000,26.00000,3.009491e-10,0.78718,4
300.01099, 826.70000,      2.35590, 19.77220,50.00000,26.00000,3.001499e-10,0.78719,4
300.01099, 830.00000,      2.35551, 19.66360,50.00000,26.00000,3.009739e-10,0.78719,4
300.02499, 833.30000,      2.35594, 19.62980,50.00000,26.00000,3.003750e-10,0.78718,4
300.02301, 836.60000,      2.35380, 19.57540,50.00000,26.00000,3.005218e-10,0.78720,4
300.03900, 839.90000,      2.35307, 19.47360,50.00000,26.00000,3.012429e-10,0.78720,4
300.01099, 843.20000,      2.35067, 19.41260,50.00000,26.00000,3.008308e-10,0.78719,4
300.01199, 846.50000,      2.35164, 19.35140,50.00000,26.00000,3.007183e-10,0.78719,4
300.02802, 849.80000,      2.35129, 19.23600,50.00000,26.00000,3.011932e-10,0.78720,4
300.03101, 853.10000,      2.34995, 19.20200,50.00000,26.00000,3.010196e-10,0.78718,4
300.01401, 856.40000,      2.34932, 19.12740,50.00000,26.00000,3.010940e-10,0.78719,4
300.01901, 859.70000,      2.34720, 19.07320,50.00000,26.00000,3.008670e-10,0.78719,4
300.02301, 863.00000,      2.34721, 18.99400,50.00000,26.00000,3.010806e-10,0.78719,4
300.02499, 866.30000,      2.34625, 18.89900,50.00000,26.00000,3.013420e-10,0.78720,4
300.01801, 869.60000,      2.34526, 18.86500,50.00000,26.00000,3.016109e-10,0.78720,4
300.01700, 872.90000,      2.34370, 18.81740,50.00000,26.00000,3.015996e-10,0.78718,4
300.01501, 876.20000,      2.34176, 18.72920,50.00000,26.00000,3.014527e-10,0.78719,4
300.02301, 879.50000,      2.34159, 18.64780,50.00000,26.00000,3.013096e-10,0.78718,4
300.00601, 882.80000,      2.34154, 18.60700,50.00000,26.00000,3.021413e-10,0.78719,4
300.02899, 886.10000,      2.34141, 18.53240,50.00000,26.00000,3.021335e-10,0.78719,4
300.01901, 889.40000,      2.33964, 18.46440,50.00000,26.00000,3.017406e-10,0.78719,4
300.01999, 892.70000,      2.33964, 18.40340,50.00000,26.00000,3.018437e-10,0.78720,4
300.00800, 896.00000,      2.33728, 18.33540,50.00000,26.00000,3.017959e-10,0.78719,4
300.01099, 899.30000,      2.33535, 18.26080,50.00000,26.00000,3.020953e-10,0.78719,4
300.02200, 902.60000,      2.33344, 18.22680,50.00000,26.00000,3.015061e-10,0.78718,4
300.02200, 905.90000,      2.33325, 18.14540,50.00000,26.00000,3.023548e-10,0.78720,4
300.01401, 909.20000,      2.33207, 18.08440,50.00000,26.00000,3.016567e-10,0.78719,4
300.01300, 912.50000,      2.33051, 18.02780,50.00000,26.00000,3.026142e-10,0.78720,4
300.01700, 915.80000,      2.32762, 17.97340,50.00000,26.00000,3.020649e-10,0.78719,4
300.02802, 919.10000,      2.32803, 17.91240,50.00000,26.00000,3.022746e-10,0.78719,4
300.01401, 922.40000,      2.32761, 17.85800,50.00000,26.00000,3.024959e-10,0.78719,4
300.00800, 925.70000,      2.32662, 17.80380,50.00000,26.00000,3.017825e-10,0.78720,4
300.01401, 929.00000,      2.32528, 17.73140,50.00000,26.00000,3.016243e-10,0.78721,4
300.01199, 932.30000,      2.32431, 17.67020,50.00000,26.00000,3.025876e-10,0.78719,4
300.01099, 935.60000,      2.32333, 17.62040,50.00000,26.00000,3.024635e-10,0.78720,4
300.02701, 938.90000,      2.32338, 17.53900,50.00000,26.00000,3.034229e-10,0.78719,4
300.01199, 942.20000,      2.32237, 17.49840,50.00000,26.00000,3.028430e-10,0.78719,4
300.01700, 945.50000,      2.32025, 17.45980,50.00000,26.00000,3.022136e-10,0.78719,4
300.01999, 948.80000,      2.31929, 17.37160,50.00000,26.00000,3.029060e-10,0.78719,4
300.01099, 952.10000,      2.32023, 17.32640,50.00000,26.00000,3.033179e-10,0.78719,4
300.00400, 955.40000,      2.31711, 17.24480,50.00000,26.00000,3.036841e-10,0.78720,4
300.01199, 958.70000,      2.31752, 17.16800,50.00000,26.00000,3.031502e-10,0.78721,4
300.01501, 962.00000,      2.31637, 17.10680,50.00000,26.00000,3.036251e-10,0.78720,4
300.01999, 965.30000,      2.31483, 17.05940,50.00000,26.00000,3.036977e-10,0.78720,4
300.02600, 968.60000,      2.31485, 16.97780,50.00000,27.00000,3.028831e-10,0.78721,4
300.01099, 971.90000,      2.31306, 16.93040,50.00000,27.00000,3.036652e-10,0.78722,4
300.01401, 975.20000,      2.31210, 16.86920,50.00000,27.00000,3.045330e-10,0.78721,4
300.02301, 978.50000,      2.31174, 16.81500,50.00000,27.00000,3.034802e-10,0.78720,4
300.01099, 981.80000,      2.30977, 16.75160,50.00000,27.00000,3.039932e-10,0.78719,4
300.02399, 985.10000,      2.30922, 16.71080,50.00000,27.00000,3.041629e-10,0.78718,4
300.02200, 988.40000,      2.30728, 16.63620,50.00000,27.00000,3.037814e-10,0.78716,4
300.02600, 991.70000,      2.30729, 16.57520,50.00000,27.00000,3.034536e-10,0.78719,4
300.00299, 995.00000,      2.30761, 16.51400,50.00000,27.00000,3.038254e-10,0.78719,4
300.00601, 998.30000,      2.30665, 16.46660,50.00000,27.00000,3.037300e-10,0.78719,4
300.01300,1001.60000,      2.30609, 16.44840,50.00000,27.00000,3.038062e-10,0.78719,4
300.02701,1004.90000,      2.30477, 16.35340,50.00000,27.00000,3.050137e-10,0.78717,4
300.00699,1008.20000,      2.30433, 16.31260,50.00000,26.00000,3.037796e-10,0.78719,4
300.01001,1011.50000,      2.30337, 16.25160,50.00000,26.00000,3.040256e-10,0.78719,4
300.00699,1014.80000,      2.30297, 16.17020,50.00000,26.00000,3.035431e-10,0.78719,4
300.01801,1018.10000,      2.30300, 16.12940,50.00000,26.00000,3.046799e-10,0.78718,4
300.02200,1021.40000,      2.30107, 16.07500,50.00000,26.00000,3.033562e-10,0.78719,4
300.01999,1024.70000,      2.30049, 16.02760,50.00000,26.00000,3.031425e-10,0.78719,4
300.02600,1028.00000,      2.30089, 15.95960,50.00000,26.00000,3.039817e-10,0.78719,4
300.01999,1031.30000,      2.29952, 15.91220,50.00000,26.00000,3.043366e-10,0.78719,4
300.03101,1034.60000,      2.29955, 15.86460,50.00000,26.00000,3.039302e-10,0.78719,4
300.01700,1037.90000,      2.30106, 15.77640,50.00000,26.00000,3.047429e-10,0.78718,4
300.03201,1041.20000,      2.29994, 15.72220,50.00000,26.00000,3.034725e-10,0.78719,4
300.01300,1044.50000,      2.29911, 15.69500,50.00000,26.00000,3.042259e-10,0.78719,4
300.01901,1047.80000,      2.29874, 15.63380,50.00000,26.00000,3.042679e-10,0.78720,4
300.01001,1051.10000,      2.29852, 15.55920,50.00000,26.00000,3.045502e-10,0.78719,4
300.01700,1054.40000,      2.29873, 15.51160,50.00000,26.00000,3.039780e-10,0.78719,4
300.02499,1057.70000,      2.29720, 15.48460,50.00000,26.00000,3.038138e-10,0.78719,4
300.01700,1061.00000,      2.29505, 15.43700,50.00000,26.00000,3.033199e-10,0.78718,4
300.00800,1064.30000,      2.29503, 15.37600,50.00000,26.00000,3.043651e-10,0.78718,4
300.01300,1067.60000,      2.29252, 15.32380,50.00000,26.00000,3.053036e-10,0.78719,4
300.01901,1070.90000,      2.29389, 15.26500,50.00000,26.00000,3.044986e-10,0.78719,4
300.01099,1074.20000,      2.29387, 15.19720,50.00000,26.00000,3.051376e-10,0.78719,4
300.01099,1077.50000,      2.29368, 15.16320,50.00000,27.00000,3.040237e-10,0.78719,4
300.01599,1080.80000,      2.29136, 15.10220,50.00000,27.00000,3.050498e-10,0.78719,4
300.01401,1084.10000,      2.29213, 15.05460,50.00000,27.00000,3.042811e-10,0.78720,4
300.02100,1087.40000,      2.29002, 14.99800,50.00000,27.00000,3.043499e-10,0.78720,4
300.00699,1090.70000,      2.29095, 14.93700,50.00000,27.00000,3.041935e-10,0.78720,4
300.00201,1094.00000,      2.29075, 14.90520,50.00000,27.00000,3.042659e-10,0.78720,4
300.01700,1097.30000,      2.29040, 14.82840,50.00000,27.00000,3.044815e-10,0.78718,4
300.01901,1100.60000,      2.29118, 14.80120,50.00000,27.00000,3.042621e-10,0.78719,4
300.00699,1103.90000,      2.28901, 14.70620,50.00000,27.00000,3.051014e-10,0.78719,4
300.00800,1107.20000,      2.28902, 14.69940,50.00000,27.00000,3.043652e-10,0.78719,4
300.01901,1110.50000,      2.28633, 14.62480,50.00000,27.00000,3.049640e-10,0.78719,4
300.00900,1113.80000,      2.28592, 14.56360,50.00000,27.00000,3.048516e-10,0.78719,4
300.00101,1117.10000,      2.28706, 14.53640,50.00000,27.00000,3.044166e-10,0.78718,4
300.01599,1120.40000,      2.28419, 14.44140,50.00000,27.00000,3.044395e-10,0.78720,4
300.00699,1123.70000,      2.28533, 14.38720,50.00000,27.00000,3.043385e-10,0.78719,4
300.01801,1127.00000,      2.28400, 14.36680,50.00000,27.00000,3.053970e-10,0.78720,4
300.01501,1130.30000,      2.28400, 14.32380,50.00000,27.00000,3.061982e-10,0.78718,4
300.01001,1133.60000,      2.28263, 14.25820,50.00000,27.00000,3.058147e-10,0.78718,4
300.03000,1136.90000,      2.28152, 14.23100,50.00000,27.00000,3.050555e-10,0.78719,4
300.02301,1140.20000,      2.28227, 14.16540,50.00000,27.00000,3.055840e-10,0.78719,4
300.02600,1143.50000,      2.28034, 14.10660,50.00000,27.00000,3.044986e-10,0.78719,4
300.01300,1146.80000,      2.28147, 14.04540,50.00000,27.00000,3.054695e-10,0.78720,4
300.01401,1150.10000,      2.27973, 14.01840,50.00000,27.00000,3.047410e-10,0.78720,4
300.01700,1153.40000,      2.27935, 13.98440,50.00000,27.00000,3.061676e-10,0.78719,4
300.02399,1156.70000,      2.27976, 13.88940,50.00000,27.00000,3.054141e-10,0.78719,4
300.02301,1160.00000,      2.27801, 13.86900,50.00000,27.00000,3.055401e-10,0.78719,4
300.00699,1163.30000,      2.27758, 13.82820,50.00000,27.00000,3.055783e-10,0.78719,4
300.01199,1166.60000,      2.27662, 13.76040,50.00000,27.00000,3.058433e-10,0.78719,4
300.01300,1169.90000,      2.27604, 13.71280,50.00000,27.00000,3.056832e-10,0.78719,4
300.01599,1173.20000,      2.27625, 13.65620,50.00000,27.00000,3.057231e-10,0.78720,4
300.01199,1176.50000,      2.27371, 13.61560,50.00000,27.00000,3.050786e-10,0.78719,4
300.00699,1179.80000,      2.27331, 13.57480,50.00000,27.00000,3.056965e-10,0.78719,4
300.01901,1183.10000,      2.27315, 13.53400,50.00000,27.00000,3.063316e-10,0.78719,4
300.00601,1186.40000,      2.27118, 13.47300,50.00000,27.00000,3.048535e-10,0.78720,4
300.01700,1189.70000,      2.27024, 13.44360,50.00000,27.00000,3.064003e-10,0.78721,4
300.01901,1193.00000,      2.26986, 13.36220,50.00000,27.00000,3.054485e-10,0.78719,4
300.01501,1196.30000,      2.27043, 13.32820,50.00000,27.00000,3.061333e-10,0.78719,4
300.02701,1199.60000,      2.26910, 13.28060,50.00000,27.00000,3.058606e-10,0.78719,4
300.01199,1202.90000,      2.26926, 13.22640,50.00000,27.00000,3.065490e-10,0.78719,4
300.01401,1206.20000,      2.26791, 13.18560,50.00000,27.00000,3.065014e-10,0.78719,4
300.01700,1209.50000,      2.26791, 13.12220,50.00000,27.00000,3.074074e-10,0.78720,4
300.01401,1212.80000,      2.26674, 13.05440,50.00000,27.00000,3.064556e-10,0.78719,4
300.01199,1216.10000,      2.26577, 13.00460,50.00000,27.00000,3.065891e-10,0.78719,4
300.02200,1219.40000,      2.26541, 12.96380,50.00000,27.00000,3.062878e-10,0.78718,4
300.01901,1222.70000,      2.26559, 12.91640,50.00000,27.00000,3.066578e-10,0.78719,4
300.01099,1226.00000,      2.26441, 12.89820,50.00000,27.00000,3.069553e-10,0.78718,4
300.00400,1229.30000,      2.26497, 12.81460,50.00000,27.00000,3.064193e-10,0.78717,4
300.01300,1232.60000,      2.26364, 12.80780,50.00000,27.00000,3.057994e-10,0.78719,4
300.01099,1235.90000,      2.26344, 12.73320,50.00000,27.00000,3.068066e-10,0.78719,4
300.01099,1239.20000,      2.26228, 12.69240,50.00000,27.00000,3.062096e-10,0.78719,4
300.00400,1242.50000,      2.26264, 12.69240,50.00000,27.00000,3.058281e-10,0.78720,4
300.01401,1245.80000,      2.26190, 12.62440,50.00000,27.00000,3.069477e-10,0.78719,4
300.01501,1249.10000,      2.26093, 12.56340,50.00000,27.00000,3.060227e-10,0.78718,4
300.01599,1252.40000,      2.26093, 12.52260,50.00000,27.00000,3.071727e-10,0.78718,4
300.01700,1255.70000,      2.25977, 12.49560,50.00000,27.00000,3.072204e-10,0.78720,4
300.02600,1257.10000,      2.25999, 12.39140,50.00000,50.00000,3.064480e-10,0.78720,5
300.21899,1257.26500,      2.29114, 12.18560,50.00000,50.00000,3.062057e-10,0.78720,5
300.82401,1257.43000,      2.42918, 11.66060,50.00000,50.00000,3.062706e-10,0.78721,5
301.95901,1257.59500,      2.67882, 10.89120,50.00000,50.00000,3.060760e-10,0.78721,5
303.64499,1257.76000,      3.01029, 10.54500,50.00000,50.00000,3.067818e-10,0.78721,5
305.84601,1257.92500,      3.37386, 10.78500,50.00000,50.00000,3.062687e-10,0.78720,5
308.44699,1258.09000,      3.71279, 11.25780,50.00000,50.00000,3.072872e-10,0.78720,5
311.30801,1258.25500,      3.99287, 11.74200,50.00000,50.00000,3.066921e-10,0.78720,5
314.30301,1258.42000,      4.19439, 12.19680,50.00000,50.00000,3.064823e-10,0.78720,5
317.33499,1258.58500,      4.31429, 12.50680,50.00000,50.00000,3.062496e-10,0.78719,5
320.32401,1258.75000,      4.37012, 12.71280,50.00000,50.00000,3.067760e-10,0.78721,5
323.25000,1258.91500,      4.38538, 12.84620,50.00000,50.00000,3.064633e-10,0.78720,5
326.10599,1259.08000,      4.38417, 12.88700,50.00000,50.00000,3.068753e-10,0.78719,5
328.93799,1259.24500,      4.39088, 12.91420,50.00000,50.00000,3.069991e-10,0.78720,5
331.76401,1259.41000,      4.42381, 12.94120,50.00000,50.00000,3.067112e-10,0.78719,5
334.66400,1259.57500,      4.48977, 12.99560,50.00000,50.00000,3.072720e-10,0.78720,5
337.64999,1259.74000,      4.59083, 13.02280,50.00000,50.00000,3.074436e-10,0.78721,5
340.73700,1259.90500,      4.72344, 13.08380,50.00000,50.00000,3.065776e-10,0.78720,5
343.95801,1260.07000,      4.88106, 13.15840,50.00000,50.00000,3.066406e-10,0.78720,5
347.29800,1260.23500,      5.04508, 13.23540,50.00000,50.00000,3.074741e-10,0.78720,5
350.73001,1260.40000,      5.21753, 13.29660,50.00000,50.00000,3.074608e-10,0.78720,5
354.25201,1260.56500,      5.38425, 13.35080,50.00000,50.00000,3.069534e-10,0.78718,5
357.82401,1260.73000,      5.53348, 13.37800,50.00000,50.00000,3.067074e-10,0.78719,5
361.42200,1260.89500,      5.67359, 13.41200,50.00000,50.00000,3.064937e-10,0.78719,5
365.03201,1261.06000,      5.79679, 13.41860,50.00000,50.00000,3.069399e-10,0.78720,5
368.63599,1261.22500,      5.91326, 13.40520,50.00000,50.00000,3.081513e-10,0.78720,5
372.23199,1261.39000,      6.02670, 13.40520,50.00000,50.00000,3.067666e-10,0.78719,5
375.82101,1261.55500,      6.13898, 13.35080,50.00000,50.00000,3.066923e-10,0.78719,5
379.43100,1261.72000,      6.25672, 13.32360,50.00000,50.00000,3.072529e-10,0.78719,5
383.01901,1261.88500,      6.38030, 13.26940,50.00000,50.00000,3.071766e-10,0.78719,5
386.62701,1262.05000,      6.51164, 13.21280,50.00000,50.00000,3.062267e-10,0.78719,5
390.24701,1262.21500,      6.65058, 13.10200,50.00000,50.00000,3.071919e-10,0.78719,5
393.85800,1262.38000,      6.79157, 12.98660,50.00000,50.00000,3.069495e-10,0.78719,5
397.49899,1262.54500,      6.93936, 12.78060,50.00000,50.00000,3.069878e-10,0.78719,5
401.12701,1262.71000,      7.08946, 12.54760,50.00000,50.00000,3.065089e-10,0.78719,5
404.75800,1262.87500,      7.24580, 12.31680,50.00000,50.00000,3.070793e-10,0.78719,5
408.39600,1263.04000,      7.39648, 11.97060,50.00000,50.00000,3.065854e-10,0.78719,5
412.00000,1263.20500,      7.54791, 11.63800,50.00000,50.00000,3.067989e-10,0.78719,5
415.60101,1263.37000,      7.69860, 11.13800,50.00000,50.00000,3.070945e-10,0.78715,5
419.19299,1263.53500,      7.85207, 10.66960,50.00000,50.00000,3.065204e-10,0.78718,5
422.77802,1263.70000,      8.00995, 10.07680,50.00000,50.00000,3.065204e-10,0.78719,5
426.34100,1263.86500,      8.16528,  9.45440,50.00000,50.00000,3.067627e-10,0.78719,5
429.90701,1264.03000,      8.32102,  8.75760,50.00000,50.00000,3.059558e-10,0.78719,5
433.44501,1264.19500,      8.47335,  8.01760,50.00000,50.00000,3.072203e-10,0.78719,5
436.97699,1264.36000,      8.61943,  7.25060,50.00000,50.00000,3.067341e-10,0.78719,5
440.50500,1264.52500,      8.75778,  6.52440,50.00000,50.00000,3.066216e-10,0.78718,5
444.03601,1264.69000,      8.88836,  5.74360,50.00000,50.00000,3.068256e-10,0.78719,5
447.54401,1264.85500,      9.00392,  5.08300,50.00000,50.00000,3.071575e-10,0.78718,5
451.05200,1265.02000,      9.10945,  4.49460,50.00000,50.00000,3.074493e-10,0.78719,5
454.55099,1265.18500,      9.19734,  3.97880,50.00000,50.00000,3.068599e-10,0.78719,5
458.03101,1265.35000,      9.27482,  3.56920,50.00000,50.00000,3.077279e-10,0.78719,5
461.50699,1265.51500,      9.34719,  3.29100,50.00000,50.00000,3.074531e-10,0.78719,5
464.97699,1265.68000,      9.41529,  3.13480,50.00000,50.00000,3.072318e-10,0.78719,5
468.45801,1265.84500,      9.48966,  3.01940,50.00000,50.00000,3.064900e-10,0.78720,5
471.89899,1266.01000,      9.56633,  2.95600,50.00000,50.00000,3.072223e-10,0.78718,5
475.34799,1266.17500,      9.65128,  2.89960,50.00000,50.00000,3.071995e-10,0.78719,5
478.79300,1266.34000,      9.74570,  2.82940,50.00000,50.00000,3.067798e-10,0.78715,5
482.22601,1266.50500,      9.83212,  2.81580,50.00000,50.00000,3.075333e-10,0.78719,5
485.64001,1266.67000,      9.92888,  2.78860,50.00000,50.00000,3.072910e-10,0.78719,5
489.05600,1266.83500,     10.02320,  2.73440,50.00000,50.00000,3.070888e-10,0.78719,5
492.47000,1267.00000,     10.11875,  2.70720,50.00000,50.00000,3.074074e-10,0.78719,5
495.85999,1267.16500,     10.21647,  2.68000,50.00000,50.00000,3.074322e-10,0.78719,5
499.26801,1267.33000,     10.31493,  2.65280,50.00000,50.00000,3.077754e-10,0.78719,5
502.65201,1267.49500,     10.40928,  2.62580,50.00000,50.00000,3.073082e-10,0.78719,5
506.03500,1267.66000,     10.50558,  2.62580,50.00000,50.00000,3.068905e-10,0.78719,5
509.41501,1267.82500,     10.59568,  2.57140,50.00000,50.00000,3.070487e-10,0.78719,5
512.79401,1267.99000,     10.68744,  2.54420,50.00000,50.00000,3.057671e-10,0.78719,5
516.16498,1268.15500,     10.77152,  2.51720,50.00000,50.00000,3.074208e-10,0.78720,5
519.52802,1268.32000,     10.85736,  2.49000,50.00000,50.00000,3.084241e-10,0.78719,5
522.88800,1268.48500,     10.93987,  2.46280,50.00000,50.00000,3.069953e-10,0.78719,5
526.24103,1268.65000,     11.02257,  2.44240,50.00000,50.00000,3.071900e-10,0.78720,5
529.58899,1268.81500,     11.11018,  2.43560,50.00000,50.00000,3.077317e-10,0.78720,5
532.94598,1268.98000,     11.19482,  2.38140,50.00000,50.00000,3.075448e-10,0.78719,5
536.27301,1269.14500,     11.24353,  2.38820,50.00000,50.00000,3.065909e-10,0.78719,5
539.62000,1269.31000,     11.30200,  2.36780,50.00000,50.00000,3.068104e-10,0.78719,5
542.95599,1269.47500,     11.36834,  2.33380,50.00000,50.00000,3.071632e-10,0.78720,5
546.28101,1269.64000,     11.43251,  2.32700,50.00000,50.00000,3.077107e-10,0.78719,5
549.61798,1269.80500,     11.49025,  2.27960,50.00000,50.00000,3.068314e-10,0.78719,5
552.94598,1269.97000,     11.50490,  2.28640,50.00000,50.00000,3.068981e-10,0.78719,5
556.28302,1270.13500,     11.55821,  2.25920,50.00000,50.00000,3.065529e-10,0.78719,5
559.60901,1270.30000,     11.60377,  2.25920,50.00000,50.00000,3.077545e-10,0.78719,5
562.93201,1270.46500,     11.66552,  2.20480,50.00000,50.00000,3.067075e-10,0.78720,5
566.27502,1270.63000,     11.73524,  2.20480,50.00000,50.00000,3.075619e-10,0.78719,5
569.59900,1270.79500,     11.80041,  2.17780,50.00000,50.00000,3.065605e-10,0.78720,5
572.92401,1270.96000,     11.86814,  2.15060,50.00000,50.00000,3.082027e-10,0.78719,5
576.27002,1271.12500,     11.92767,  2.15060,50.00000,50.00000,3.066463e-10,0.78719,5
579.58197,1271.29000,     11.99118,  2.12340,50.00000,50.00000,3.075027e-10,0.78719,5
582.90002,1271.45500,     12.05314,  2.09620,50.00000,50.00000,3.071480e-10,0.78719,5
586.21198,1271.62000,     12.12007,  2.12340,50.00000,50.00000,3.073121e-10,0.78720,5
589.54602,1271.78500,     12.18763,  2.08260,50.00000,50.00000,3.070678e-10,0.78721,5
592.87299,1271.95000,     12.24869,  2.06920,50.00000,50.00000,3.071441e-10,0.78719,5
596.17499,1272.11500,     12.29783,  2.06920,50.00000,50.00000,3.066674e-10,0.78720,5
599.49200,1272.28000,     12.32357,  2.04200,50.00000,50.00000,3.074169e-10,0.78719,5
602.79999,1272.44500,     12.36430,  2.01480,50.00000,50.00000,3.065644e-10,0.78720,5
606.12799,1272.61000,     12.41086,  1.98760,50.00000,50.00000,3.072224e-10,0.78719,5
609.43799,1272.77500,     12.46251,  1.96040,50.00000,50.00000,3.073845e-10,0.78720,5
612.77100,1272.94000,     12.51412,  1.93340,50.00000,50.00000,3.067570e-10,0.78720,5
616.08099,1273.10500,     12.56391,  1.90620,50.00000,50.00000,3.058299e-10,0.78720,5
619.40100,1273.27000,     12.61665,  1.87900,50.00000,50.00000,3.074474e-10,0.78720,5
622.72998,1273.43500,     12.66915,  1.87900,50.00000,50.00000,3.073939e-10,0.78719,5
626.03900,1273.60000,     12.72482,  1.85180,50.00000,50.00000,3.071118e-10,0.78720,5
629.34601,1273.76500,     12.76785,  1.82480,50.00000,50.00000,3.075904e-10,0.78719,5
632.66803,1273.93000,     12.81770,  1.79760,50.00000,50.00000,3.074760e-10,0.78719,5
635.98102,1274.09500,     12.87414,  1.77040,50.00000,50.00000,3.064519e-10,0.78718,5
639.29303,1274.26000,     12.90806,  1.75680,50.00000,50.00000,3.072223e-10,0.78718,5
642.59100,1274.42500,     12.91225,  1.71840,50.00000,50.00000,3.069209e-10,0.78719,5
645.86798,1274.59000,     12.82623,  1.71160,50.00000,50.00000,3.077411e-10,0.78719,5
648.62201,1274.75500,     10.67185,  1.67760,50.00000,50.00000,3.077773e-10,0.78719,5
650.54199,1274.92000,      4.92554,  1.67080,50.00000,50.00000,3.067208e-10,0.78719,5
653.06897,1275.08500,      1.06102,  1.64380,50.00000,50.00000,3.073197e-10,0.78719,5
655.17798,1275.25000,     -5.38983,  1.63020,50.00000,50.00000,3.070927e-10,0.78719,5
657.51801,1275.41500,    -11.72675,  1.64380,50.00000,50.00000,3.065167e-10,0.78718,5
659.86401,1275.58000,    -18.70701,  1.64380,50.00000,50.00000,3.072090e-10,0.78719,5
661.74200,1275.74500,    -28.16156,  1.64380,50.00000,50.00000,3.073311e-10,0.78719,5
661.52802,1275.91000,    -46.57378,  1.64380,50.00000,50.00000,3.070470e-10,0.78719,5
661.12097,1276.07500,    -67.58472,  1.65060,50.00000,50.00000,3.076249e-10,0.78719,5
662.42603,1276.24000,    -83.47740,  1.69800,50.00000,50.00000,3.073425e-10,0.78718,5
675.98297,1276.40500,    -53.83551,  1.71160,50.00000,50.00000,3.075523e-10,0.78719,5
693.71002,1276.57000,      0.45163,  1.61440,50.00000,50.00000,3.069611e-10,0.78720,5
698.33002,1276.73500,     10.00119,  1.34960,50.00000,50.00000,3.067246e-10,0.78719,5
698.40997,1276.90000,     11.34960,  1.12560,50.00000,50.00000,3.073234e-10,0.78719,5
697.02399,1277.06500,     11.18555,  0.96040,50.00000,50.00000,3.072549e-10,0.78719,5
696.23999,1277.23000,     10.83967,  0.91280,50.00000,50.00000,3.078955e-10,0.78719,5
697.16699,1277.39500,     10.58981,  0.98300,50.00000,50.00000,3.083821e-10,0.78719,5
700.06702,1277.56000,     10.46095,  1.08700,50.00000,50.00000,3.068333e-10,0.78720,5
704.56897,1277.72500,     10.43088,  1.20920,50.00000,50.00000,3.071192e-10,0.78719,5
709.89099,1277.89000,     10.45227,  1.26360,50.00000,50.00000,3.077487e-10,0.78719,5
715.33099,1278.05500,     10.51705,  1.29080,50.00000,50.00000,3.073006e-10,0.78720,5
720.37799,1278.22000,     10.57914,  1.26360,50.00000,50.00000,3.068524e-10,0.78719,5
724.85199,1278.38500,     10.62173,  1.20920,50.00000,50.00000,3.075467e-10,0.78720,5
728.80701,1278.55000,     10.67675,  1.18220,50.00000,50.00000,3.076229e-10,0.78719,5
732.42297,1278.71500,     10.71153,  1.12560,50.00000,50.00000,3.066769e-10,0.78720,5
735.86401,1278.88000,     10.72133,  1.09840,50.00000,50.00000,3.069610e-10,0.78719,5
739.25000,1279.04500,     10.70678,  1.09380,50.00000,50.00000,3.073024e-10,0.78719,5
742.66498,1279.21000,     10.68248,  1.09380,50.00000,50.00000,3.069762e-10,0.78721,5
746.09698,1279.37500,     10.66818,  1.08040,50.00000,50.00000,3.071670e-10,0.78719,5
749.52301,1279.54000,     10.65949,  1.10740,50.00000,50.00000,3.075867e-10,0.78720,5
752.87598,1279.70500,     10.47497,  1.10060,50.00000,50.00000,3.070449e-10,0.78720,5
756.13000,1279.87000,     10.04590,  1.10060,50.00000,50.00000,3.070125e-10,0.78719,5
759.29700,1280.03500,      9.49939,  1.12780,50.00000,50.00000,3.081455e-10,0.78719,5
762.47302,1280.20000,      8.99224,  1.12780,50.00000,50.00000,3.067646e-10,0.78718,5
765.65698,1280.36500,      8.60228,  1.18220,50.00000,50.00000,3.065013e-10,0.78719,5
768.83502,1280.53000,      8.29939,  1.14140,50.00000,50.00000,3.067380e-10,0.78719,5
772.03998,1280.69500,      8.12069,  1.18220,50.00000,50.00000,3.072452e-10,0.78718,5
775.22601,1280.86000,      7.99412,  1.20920,50.00000,50.00000,3.073807e-10,0.78719,5
778.41699,1281.02500,      7.86952,  1.23640,50.00000,50.00000,3.069802e-10,0.78718,5
781.57703,1281.19000,      7.71493,  1.22280,50.00000,50.00000,3.068409e-10,0.78719,5
784.72998,1281.35500,      7.51811,  1.27720,50.00000,50.00000,3.069077e-10,0.78718,5
787.88397,1281.52000,      7.28963,  1.27720,50.00000,50.00000,3.066310e-10,0.78719,5
791.03101,1281.68500,      7.03800,  1.30440,50.00000,50.00000,3.072662e-10,0.78718,5
794.20398,1281.85000,      6.78100,  1.33140,50.00000,50.00000,            ,0.44721,5
797.09601,1282.00000,      6.58313,  1.35180,50.00000,50.00000,            ,0.44605,5