File: data/TGA/005d-L_M/ExpDat_2025_02_20_005d-M1-dynamic-1K.csv
#EXPORTTYPE:                 ,DATA ALL
#FILE:                       ,2025_02_20_005d-M1-dynamic-1K.ngb-ss5
#FORMAT:                     ,NETZSCH5
#FTYPE:                      ,ASCII
#IDENTITY:                   ,005d-M1
#DECIMAL:                    ,POINT
#SEPARATOR:                  ,COMMA
#MTYPE:                      ,DSC
#INSTRUMENT:                 ,NETZSCH STA 449F5
#PROJECT:                    ,PS
#DATE/TIME:                  ,2/20/2025 10:18:49 AM (UTC-5)
#CORR. FILE:                 ,
#TEMPCAL:                    ,13-11-2024 10:37
#SENSITIVITY:                ,28-06-2023 13:53
#LABORATORY:                 ,Tran/Aspuru
#OPERATOR:                   ,Stanley
#REMARK:                     ,
#SAMPLE:                     ,005d-M1
#SAMPLE MASS /mg:            ,4.70
#MATERIAL:                   ,
#REFERENCE:                  ,
#REFERENCE MASS /mg:         ,0
#TYPE OF CRUCIBLE:           ,Al2O3 85 ‘l, open
#SAMPLE CRUCIBLE MASS /mg:   ,0
#REFERENCE CRUCIBLE MASS /mg:,0
#DSC RANGE /‘V:              ,5000
#TG RANGE /mg:               ,35000
#TAU-R:                      ,---
#CORR. CODE:                 ,000
#EXO:                        ,-1
#RANGE:                      ,20›C....800›C/0.0....20.0K/min
#SEGMENT:                    ,S1-4/4
#SEG. 1:                     ,20›C/5.0(K/min)/100›C
#SEG. 2:                     ,100›C/00:05/100›C
#SEG. 3:                     ,100›C/1.0(K/min)/400›C
#SEG. 4:                     ,400›C/20.0(K/min)/800›C

##Temp./›C,Time/min,DSC/(mW/mg),Mass/%,Gas Flow(purge2)/(ml/min),Gas Flow(protective)/(ml/min),TIC(scan:1)/A,Sensit./(uV/mW),Segment
 28.93300,  0.00000,      0.68247,100.00000,50.00000,35.00000,            ,0.92335,1
 30.06900,  1.06667,      0.17049, 99.77362,50.00000,34.00000,1.830692e-10,0.92343,1
 31.19800,  2.13333,      0.10860, 92.85809,50.00000,34.00000,1.839237e-10,0.92353,1
 32.45500,  3.20000,      0.14336, 93.12043,50.00000,34.00000,1.828862e-10,0.92361,1
 34.51600,  4.26667,      0.30452, 93.26489,50.00000,34.00000,1.839161e-10,0.92370,1
 37.67300,  5.33333,      0.51659, 93.79191,50.00000,34.00000,1.838360e-10,0.92377,1
 41.83800,  6.40000,      0.72718, 94.28787,50.00000,34.00000,1.837464e-10,0.92386,1
 46.89600,  7.46667,      0.92039, 94.73064,50.00000,33.00000,1.838971e-10,0.92394,1
 52.66700,  8.53333,      1.08974, 95.13277,50.00000,33.00000,1.836795e-10,0.92406,1
 58.89800,  9.60000,      1.22578, 95.38553,50.00000,33.00000,1.839848e-10,0.92420,1
 65.42300, 10.66667,      1.32851, 95.60213,50.00000,33.00000,1.837330e-10,0.92435,1
 72.02700, 11.73333,      1.40011, 95.73213,50.00000,33.00000,1.851196e-10,0.92454,1
 78.59000, 12.80000,      1.44939, 95.77553,50.00000,33.00000,1.846409e-10,0.92472,1
 85.08100, 13.86667,      1.47840, 95.71766,50.00000,33.00000,1.859437e-10,0.92491,1
 91.45000, 14.93333,      1.48604, 95.51553,50.00000,33.00000,1.853981e-10,0.92513,1
 97.57100, 15.98417,      1.48393, 95.13511,50.00000,33.00000,1.858940e-10,0.92532,2
101.59600, 16.78417,      1.28063, 94.36723,50.00000,33.00000,1.855888e-10,0.92548,2
104.20300, 17.58417,      0.86057, 93.25766,50.00000,33.00000,1.858768e-10,0.92562,2
105.90800, 18.38417,      0.56936, 92.30447,50.00000,33.00000,1.854802e-10,0.92575,2
107.08600, 19.18417,      0.38253, 91.52681,50.00000,33.00000,1.859188e-10,0.92588,2
107.75300, 19.98417,      0.19714, 90.70362,50.00000,33.00000,1.863517e-10,0.92598,2
107.88900, 20.78417, 2.720458e-02, 89.96234,50.00000,33.00000,1.856441e-10,0.92607,2
107.64500, 21.80083,-9.750500e-02, 89.22085,50.00000,33.00000,1.859340e-10,0.92615,3
107.39600, 22.86750,     -0.10545, 88.72511,50.00000,33.00000,1.861134e-10,0.92619,3
107.14200, 23.93417,     -0.10367, 88.28702,50.00000,33.00000,1.866436e-10,0.92620,3
106.97800, 25.00083,-7.752854e-02, 87.96915,50.00000,33.00000,1.862907e-10,0.92617,3
107.00500, 26.06750,-3.002270e-02, 87.73809,50.00000,33.00000,1.862125e-10,0.92608,3
107.23100, 27.13417, 1.942782e-02, 87.56489,50.00000,33.00000,1.863117e-10,0.92597,3
107.63300, 28.20083, 6.871250e-02, 87.39149,50.00000,33.00000,1.862736e-10,0.92578,3
108.21600, 29.26750,      0.11643, 87.25660,50.00000,33.00000,1.865520e-10,0.92559,3
108.94200, 30.33417,      0.15374, 87.14106,50.00000,33.00000,1.865330e-10,0.92531,3
109.80500, 31.40083,      0.18578, 87.05447,50.00000,33.00000,1.860676e-10,0.92504,3
110.76900, 32.46750,      0.21377, 86.93894,50.00000,33.00000,1.864395e-10,0.92467,3
111.79300, 33.53417,      0.23401, 86.85234,50.00000,33.00000,1.867904e-10,0.92432,3
112.87800, 34.60083,      0.24772, 86.74149,50.00000,33.00000,1.866054e-10,0.92387,3
113.96300, 35.66750,      0.25773, 86.64043,50.00000,33.00000,1.863574e-10,0.92345,3
115.09500, 36.73417,      0.26492, 86.56106,50.00000,33.00000,1.862926e-10,0.92293,3
116.22500, 37.80083,      0.26804, 86.47447,50.00000,33.00000,1.867980e-10,0.92245,3
117.33400, 38.86750,      0.26886, 86.38766,50.00000,33.00000,1.872692e-10,0.92185,3
118.46600, 39.93417,      0.27092, 86.30106,50.00000,33.00000,1.867237e-10,0.92135,3
119.58300, 41.00083,      0.26856, 86.22894,50.00000,33.00000,1.868000e-10,0.92096,3
120.69900, 42.06750,      0.26850, 86.15660,50.00000,33.00000,1.874847e-10,0.92063,3
121.81000, 43.13417,      0.26648, 86.10617,50.00000,33.00000,1.875305e-10,0.92029,3
122.88200, 44.20083,      0.26642, 86.04106,50.00000,33.00000,1.871319e-10,0.92005,3
123.97200, 45.26750,      0.26601, 85.97617,50.00000,33.00000,1.867466e-10,0.91981,3
125.06600, 46.33417,      0.26631, 85.91830,50.00000,33.00000,1.869774e-10,0.91963,3
126.12800, 47.40083,      0.26411, 85.89660,50.00000,33.00000,1.871967e-10,0.91945,3
127.19500, 48.46750,      0.26174, 85.84617,50.00000,33.00000,1.878299e-10,0.91931,3
128.28500, 49.53417,      0.26418, 85.83170,50.00000,33.00000,1.884041e-10,0.91917,3
129.31500, 50.60083,      0.26305, 85.78106,50.00000,33.00000,1.879711e-10,0.91906,3
130.40601, 51.66750,      0.26354, 85.80277,50.00000,33.00000,1.880837e-10,0.91899,3
131.45000, 52.73417,      0.26563, 85.77383,50.00000,33.00000,1.876679e-10,0.91894,3
132.53300, 53.80083,      0.26522, 85.75234,50.00000,33.00000,1.872864e-10,0.91891,3
133.59801, 54.86750,      0.26482, 85.74511,50.00000,33.00000,1.883449e-10,0.91890,3
134.67500, 55.93417,      0.26353, 85.75936,50.00000,33.00000,1.877537e-10,0.91892,3
135.74200, 57.00083,      0.26455, 85.75936,50.00000,33.00000,1.888390e-10,0.91895,3
136.81500, 58.06750,      0.26505, 85.75936,50.00000,33.00000,1.882419e-10,0.91899,3
137.88100, 59.13417,      0.26340, 85.75936,50.00000,33.00000,1.888256e-10,0.91902,3
138.93900, 60.20083,      0.26354, 85.75936,50.00000,33.00000,1.887417e-10,0.91905,3
140.01100, 61.26750,      0.26296, 85.79553,50.00000,33.00000,1.883716e-10,0.91908,3
141.08600, 62.33417,      0.26293, 85.78830,50.00000,33.00000,1.886444e-10,0.91910,3
142.14301, 63.40083,      0.26379, 85.81723,50.00000,33.00000,1.887054e-10,0.91913,3
143.22099, 64.46750,      0.26340, 85.83894,50.00000,33.00000,1.885471e-10,0.91916,3
144.27699, 65.53417,      0.26103, 85.83170,50.00000,33.00000,1.891117e-10,0.91917,3
145.35001, 66.60083,      0.26154, 85.86787,50.00000,33.00000,1.884822e-10,0.91917,3
146.41299, 67.66750,      0.26259, 85.89915,50.00000,33.00000,1.891823e-10,0.91917,3
147.48500, 68.73417,      0.26166, 85.92787,50.00000,33.00000,1.893482e-10,0.91915,3
148.54900, 69.80083,      0.26056, 85.95681,50.00000,33.00000,1.885757e-10,0.91913,3
149.60001, 70.86750,      0.26053, 85.97128,50.00000,33.00000,1.889095e-10,0.91910,3
150.68300, 71.93417,      0.25979, 86.01468,50.00000,33.00000,1.894245e-10,0.91906,3
151.73801, 73.00083,      0.25922, 86.00745,50.00000,33.00000,1.889267e-10,0.91900,3
152.82800, 74.06750,      0.25776, 86.03638,50.00000,33.00000,1.890412e-10,0.91894,3
153.88800, 75.13417,      0.25738, 86.06511,50.00000,33.00000,1.896019e-10,0.91887,3
154.96800, 76.20083,      0.25538, 86.11574,50.00000,33.00000,1.891002e-10,0.91880,3
156.02000, 77.26750,      0.25445, 86.13021,50.00000,33.00000,1.887340e-10,0.91871,3
157.10600, 78.33417,      0.25389, 86.17340,50.00000,33.00000,1.899261e-10,0.91862,3
158.16800, 79.40083,      0.25098, 86.20234,50.00000,33.00000,1.892090e-10,0.91852,3
159.23700, 80.46750,      0.24915, 86.23128,50.00000,33.00000,1.895447e-10,0.91842,3
160.30000, 81.53417,      0.24968, 86.26745,50.00000,33.00000,1.895790e-10,0.91831,3
161.39101, 82.60083,      0.24822, 86.27468,50.00000,33.00000,1.896839e-10,0.91819,3
162.44600, 83.66750,      0.24621, 86.28894,50.00000,33.00000,1.897182e-10,0.91807,3
163.51801, 84.73417,      0.24401, 86.34191,50.00000,33.00000,1.893082e-10,0.91795,3
164.56900, 85.80083,      0.24236, 86.37085,50.00000,33.00000,1.894245e-10,0.91781,3
165.65199, 86.86750,      0.24235, 86.37085,50.00000,33.00000,1.890773e-10,0.91769,3
166.71400, 87.93417,      0.23888, 86.39979,50.00000,33.00000,1.892967e-10,0.91755,3
167.78400, 89.00083,      0.23923, 86.43596,50.00000,33.00000,1.895580e-10,0.91741,3
168.84700, 90.06750,      0.23594, 86.47915,50.00000,33.00000,1.892949e-10,0.91726,3
169.90401, 91.13417,      0.23410, 86.50809,50.00000,33.00000,1.896800e-10,0.91712,3
170.97200, 92.20083,      0.23190, 86.50809,50.00000,33.00000,1.902065e-10,0.91697,3
172.03200, 93.26750,      0.23151, 86.56574,50.00000,33.00000,1.892853e-10,0.91683,3
173.11099, 94.33417,      0.23077, 86.59468,50.00000,33.00000,1.895905e-10,0.91667,3
174.17300, 95.40083,      0.22984, 86.65255,50.00000,33.00000,1.892624e-10,0.91650,3
175.24200, 96.46750,      0.22636, 86.65255,50.00000,33.00000,1.898594e-10,0.91636,3
176.31300, 97.53417,      0.22470, 86.68851,50.00000,33.00000,1.893501e-10,0.91620,3
177.38200, 98.60083,      0.22431, 86.71021,50.00000,33.00000,1.898288e-10,0.91605,3
178.43800, 99.66750,      0.22100, 86.72468,50.00000,33.00000,1.893826e-10,0.91589,3
179.49200,100.73417,      0.21915, 86.73915,50.00000,33.00000,1.896248e-10,0.91574,3
180.57100,101.80083,      0.21730, 86.76085,50.00000,33.00000,1.895199e-10,0.91557,3
181.63300,102.86750,      0.21618, 86.78979,50.00000,33.00000,1.902085e-10,0.91542,3
182.71001,103.93417,      0.21378, 86.81851,50.00000,33.00000,1.898308e-10,0.91526,3
183.76601,105.00083,      0.21192, 86.87872,50.00000,33.00000,1.901626e-10,0.91511,3
184.83800,106.06750,      0.21393, 86.86426,50.00000,33.00000,1.897583e-10,0.91493,3
185.90100,107.13417,      0.21133, 86.84021,50.00000,33.00000,1.897144e-10,0.91478,3
186.97400,108.20083,      0.20911, 86.89809,50.00000,33.00000,1.894646e-10,0.91461,3
188.03900,109.26750,      0.20854, 86.91255,50.00000,33.00000,1.902293e-10,0.91446,3
189.10500,110.33417,      0.20612, 86.93404,50.00000,33.00000,1.902256e-10,0.91429,3
190.15700,111.40083,      0.20370, 86.96298,50.00000,33.00000,1.899338e-10,0.91412,3
191.24699,112.46750,      0.20387, 86.99191,50.00000,33.00000,1.903954e-10,0.91396,3
192.31100,113.53417,      0.20015, 86.98468,50.00000,33.00000,1.902561e-10,0.91380,3
193.38499,114.60083,      0.20236, 87.01362,50.00000,33.00000,1.903305e-10,0.91362,3
194.44901,115.66750,      0.19807, 87.01362,50.00000,33.00000,1.901626e-10,0.91347,3
195.52200,116.73417,      0.19676, 87.04255,50.00000,33.00000,1.908703e-10,0.91330,3
196.57700,117.80083,      0.19469, 87.03532,50.00000,33.00000,1.904907e-10,0.91314,3
197.64400,118.86750,      0.19133, 87.07128,50.00000,33.00000,1.908169e-10,0.91296,3
198.70500,119.93417,      0.19410, 87.07128,50.00000,33.00000,1.904220e-10,0.91281,3
199.77200,121.00083,      0.19222, 87.07851,50.00000,33.00000,1.906834e-10,0.91262,3
200.84000,122.06750,      0.19126, 87.07851,50.00000,33.00000,1.905022e-10,0.91247,3
201.90199,123.13417,      0.19069, 87.10745,50.00000,33.00000,1.904412e-10,0.91228,3
202.96400,124.20083,      0.18861, 87.10021,50.00000,33.00000,1.901054e-10,0.91213,3
204.04401,125.26750,      0.18729, 87.09298,50.00000,33.00000,1.898709e-10,0.91194,3
205.14500,126.33417,      0.18596, 87.12191,50.00000,33.00000,1.902656e-10,0.91178,3
206.17999,127.40083,      0.18388, 87.08574,50.00000,33.00000,1.903324e-10,0.91159,3
207.24400,128.46750,      0.18479, 87.12191,50.00000,33.00000,1.903897e-10,0.91144,3
208.30499,129.53417,      0.18421, 87.10255,50.00000,33.00000,1.900749e-10,0.91125,3
209.36400,130.60083,      0.18043, 87.10255,50.00000,33.00000,1.897792e-10,0.91108,3
210.43600,131.66750,      0.17891, 87.07383,50.00000,33.00000,1.902676e-10,0.91089,3
211.50500,132.73417,      0.18095, 87.10255,50.00000,33.00000,1.898975e-10,0.91073,3
212.57001,133.80083,      0.17773, 87.08809,50.00000,33.00000,1.900043e-10,0.91053,3
213.65100,134.86750,      0.17752, 87.06660,50.00000,33.00000,1.901074e-10,0.91036,3
214.69701,135.93417,      0.17222, 87.09532,50.00000,33.00000,1.905213e-10,0.91017,3
215.77100,137.00083,      0.17162, 87.05213,50.00000,33.00000,1.897907e-10,0.91000,3
216.84599,138.06750,      0.17235, 87.03043,50.00000,33.00000,1.908169e-10,0.90980,3
217.91400,139.13417,      0.16949, 87.03766,50.00000,33.00000,1.903228e-10,0.90963,3
218.96400,140.20083,      0.16795, 87.03766,50.00000,33.00000,1.900024e-10,0.90943,3
220.03400,141.26750,      0.17020, 87.02319,50.00000,33.00000,1.901512e-10,0.90925,3
221.09900,142.33417,      0.16903, 87.00149,50.00000,33.00000,1.900272e-10,0.90905,3
222.16901,143.40083,      0.16730, 87.02319,50.00000,33.00000,1.902904e-10,0.90888,3
223.23199,144.46750,      0.17069, 86.99426,50.00000,33.00000,1.906891e-10,0.90868,3
224.29700,145.53417,      0.16934, 87.00149,50.00000,33.00000,1.911716e-10,0.90850,3
225.36900,146.60083,      0.16855, 86.98702,50.00000,33.00000,1.915150e-10,0.90829,3
226.42500,147.66750,      0.16776, 86.97255,50.00000,33.00000,1.914558e-10,0.90812,3
227.49200,148.73417,      0.16908, 86.96532,50.00000,33.00000,1.907577e-10,0.90790,3
228.55800,149.80083,      0.16867, 86.96532,50.00000,33.00000,1.910839e-10,0.90773,3
229.62601,150.86750,      0.17152, 86.96787,50.00000,33.00000,1.910781e-10,0.90756,3
230.70100,151.93417,      0.17150, 86.92447,50.00000,33.00000,1.904717e-10,0.90733,3
231.77200,153.00083,      0.17091, 86.93894,50.00000,33.00000,1.906128e-10,0.90712,3
232.83501,154.06750,      0.17243, 86.91000,50.00000,33.00000,1.909275e-10,0.90694,3
233.89799,155.13417,      0.17318, 86.90277,50.00000,33.00000,1.908970e-10,0.90673,3
234.97400,156.20083,      0.17394, 86.88128,50.00000,33.00000,1.903133e-10,0.90654,3
236.03300,157.26750,      0.17257, 86.88128,50.00000,33.00000,1.911430e-10,0.90632,3
237.08400,158.33417,      0.17333, 86.87404,50.00000,33.00000,1.911202e-10,0.90614,3
238.15401,159.40083,      0.17409, 86.87404,50.00000,33.00000,1.907253e-10,0.90593,3
239.21800,160.46750,      0.17408, 86.85234,50.00000,33.00000,1.906948e-10,0.90574,3
240.28700,161.53417,      0.17581, 86.85702,50.00000,33.00000,1.907901e-10,0.90552,3
241.36099,162.60083,      0.17503, 86.84277,50.00000,33.00000,1.908932e-10,0.90532,3
242.42500,163.66750,      0.17192, 86.84979,50.00000,33.00000,1.911411e-10,0.90510,3
243.47200,164.73417,      0.17462, 86.83553,50.00000,33.00000,1.908417e-10,0.90491,3
244.55400,165.80083,      0.17578, 86.78489,50.00000,33.00000,1.918545e-10,0.90469,3
245.62399,166.86750,      0.17441, 86.81383,50.00000,33.00000,1.912823e-10,0.90450,3
246.67999,167.93417,      0.17538, 86.78723,50.00000,33.00000,1.903629e-10,0.90428,3
247.75000,169.00083,      0.17635, 86.78723,50.00000,33.00000,1.915207e-10,0.90408,3
248.80600,170.06750,      0.17517, 86.73681,50.00000,33.00000,1.913014e-10,0.90385,3
249.89200,171.13417,      0.17732, 86.76553,50.00000,33.00000,1.913681e-10,0.90365,3
250.95000,172.20083,      0.17478, 86.74404,50.00000,33.00000,1.912861e-10,0.90342,3
252.03500,173.26750,      0.17028, 86.75128,50.00000,33.00000,1.915435e-10,0.90323,3
253.09000,174.33417,      0.17281, 86.72234,50.00000,33.00000,1.919212e-10,0.90300,3
254.15601,175.40083,      0.17418, 86.66447,50.00000,33.00000,1.912956e-10,0.90277,3
255.22099,176.46750,      0.17359, 86.63574,50.00000,33.00000,1.920051e-10,0.90256,3
256.28900,177.53417,      0.17241, 86.62851,50.00000,33.00000,1.913719e-10,0.90234,3
257.35901,178.60083,      0.17024, 86.59234,50.00000,33.00000,1.917115e-10,0.90213,3
258.42401,179.66750,      0.17142, 86.56340,50.00000,33.00000,1.915893e-10,0.90189,3
259.49100,180.73417,      0.16846, 86.54170,50.00000,33.00000,1.920185e-10,0.90169,3
260.55099,181.80083,      0.16963, 86.50319,50.00000,33.00000,1.921100e-10,0.90146,3
261.59900,182.86750,      0.16627, 86.50319,50.00000,33.00000,1.919193e-10,0.90125,3
262.67401,183.93417,      0.16745, 86.44298,50.00000,33.00000,1.919689e-10,0.90101,3
263.73499,185.00083,      0.16368, 86.40702,50.00000,33.00000,1.921959e-10,0.90081,3
264.80801,186.06750,      0.15931, 86.36362,50.00000,33.00000,1.917953e-10,0.90055,3
265.87799,187.13417,      0.16188, 86.32043,50.00000,33.00000,1.920471e-10,0.90036,3
266.94101,188.20083,      0.15412, 86.26979,50.00000,33.00000,1.924915e-10,0.90011,3
268.03601,189.26750,      0.14794, 86.21915,50.00000,33.00000,1.922054e-10,0.89990,3
269.07800,190.33417,      0.15030, 86.16149,50.00000,33.00000,1.927013e-10,0.89965,3
270.14600,191.40083,      0.14688, 86.07489,50.00000,33.00000,1.930656e-10,0.89943,3
271.21100,192.46750,      0.14267, 86.01702,50.00000,33.00000,1.923885e-10,0.89919,3
272.27802,193.53417,      0.14044, 85.93043,50.00000,33.00000,1.927260e-10,0.89897,3
273.35501,194.60083,      0.13340, 85.84362,50.00000,33.00000,1.923122e-10,0.89873,3
274.41699,195.66750,      0.11814, 85.77149,50.00000,33.00000,1.920833e-10,0.89851,3
275.47501,196.73417,      0.12309, 85.67043,50.00000,33.00000,1.930676e-10,0.89826,3
276.54300,197.80083,      0.12685, 85.58383,50.00000,33.00000,1.931056e-10,0.89805,3
277.59698,198.86750,      0.12660, 85.45383,50.00000,33.00000,1.929778e-10,0.89779,3
278.67099,199.93417,      0.11689, 85.33830,50.00000,33.00000,1.927910e-10,0.89757,3
279.73099,201.00083,      0.10777, 85.22277,50.00000,33.00000,1.926899e-10,0.89732,3
280.80301,202.06750,      0.12040, 85.07106,50.00000,33.00000,1.931076e-10,0.89710,3
281.86099,203.13417,      0.11368, 84.95553,50.00000,33.00000,1.928406e-10,0.89684,3
282.92801,204.20083,      0.10917, 84.81106,50.00000,33.00000,1.930503e-10,0.89662,3
283.99799,205.26750,      0.10222, 84.63766,50.00000,33.00000,1.933975e-10,0.89636,3
285.07101,206.33417,      0.10133, 84.49340,50.00000,33.00000,1.934509e-10,0.89614,3
286.13901,207.40083, 9.637958e-02, 84.32234,50.00000,33.00000,1.924857e-10,0.89587,3
287.20401,208.46750, 8.898070e-02, 84.14915,50.00000,33.00000,1.925697e-10,0.89565,3
288.27399,209.53417, 8.217455e-02, 83.94702,50.00000,33.00000,1.932087e-10,0.89540,3
289.32999,210.60083, 6.455709e-02, 83.77362,50.00000,33.00000,1.921577e-10,0.89516,3
290.40799,211.66750, 5.933609e-02, 83.57149,50.00000,33.00000,1.924305e-10,0.89490,3
291.48199,212.73417, 6.880127e-02, 83.35468,50.00000,33.00000,1.928730e-10,0.89467,3
292.55301,213.80083, 4.190452e-02, 83.13809,50.00000,33.00000,1.925354e-10,0.89445,3
293.61499,214.86750, 2.148987e-02, 82.93596,50.00000,33.00000,1.918469e-10,0.89418,3
294.66400,215.93417, 2.028672e-02, 82.64702,50.00000,33.00000,1.917190e-10,0.89392,3
295.73199,217.00083,-5.334492e-03, 82.41596,50.00000,33.00000,1.921577e-10,0.89368,3
296.77899,218.06750, 7.148795e-02, 82.14149,50.00000,33.00000,1.917859e-10,0.89341,3
297.86301,219.13417, 5.245028e-02, 81.89596,50.00000,33.00000,1.924877e-10,0.89318,3
298.91901,220.20083, 4.716113e-02, 81.63617,50.00000,33.00000,1.915111e-10,0.89292,3
299.98099,221.26750, 9.485321e-03, 81.34489,50.00000,33.00000,1.922569e-10,0.89269,3
301.04199,222.33417, 4.273767e-02, 81.06809,50.00000,33.00000,1.922169e-10,0.89242,3
302.11099,223.40083, 2.542713e-02, 80.76000,50.00000,33.00000,1.925048e-10,0.89218,3
303.17801,224.46750, 1.552406e-02, 80.47106,50.00000,33.00000,1.926194e-10,0.89191,3
304.25900,225.53417, 2.217627e-02, 80.17979,50.00000,33.00000,1.921406e-10,0.89167,3
305.31900,226.60083, 1.639391e-02, 79.83319,50.00000,33.00000,1.920337e-10,0.89140,3
306.39600,227.66750, 7.688088e-03, 79.48660,50.00000,33.00000,1.918831e-10,0.89116,3
307.45801,228.73417,-2.496619e-03, 79.11106,50.00000,33.00000,1.926079e-10,0.89088,3
308.51099,229.80083,-4.437125e-02, 78.76191,50.00000,33.00000,1.926880e-10,0.89065,3
309.58600,230.86750, 7.926279e-03, 78.35277,50.00000,33.00000,1.930504e-10,0.89037,3
310.65100,231.93417,-3.634082e-02, 77.94596,50.00000,33.00000,1.932164e-10,0.89013,3
311.70499,233.00083,-2.258522e-02, 77.57043,50.00000,33.00000,1.928520e-10,0.88989,3
312.78400,234.06750,-5.716533e-02, 77.13723,50.00000,33.00000,1.924324e-10,0.88961,3
313.86499,235.13417,-3.249926e-02, 76.67021,50.00000,33.00000,1.930618e-10,0.88937,3
314.93600,236.20083,-6.382386e-02, 76.20319,50.00000,33.00000,1.935940e-10,0.88907,3
315.99600,237.26750,-6.453730e-02, 75.76511,50.00000,33.00000,1.927280e-10,0.88884,3
317.07401,238.33417,-6.862206e-02, 75.23553,50.00000,33.00000,1.934070e-10,0.88855,3
318.12601,239.40083,-6.913230e-02, 74.73979,50.00000,33.00000,1.936150e-10,0.88830,3
319.19699,240.46750,-7.048973e-02, 74.23426,50.00000,33.00000,1.933613e-10,0.88802,3
320.26001,241.53417,-7.375201e-02, 73.65894,50.00000,33.00000,1.937446e-10,0.88777,3
321.32300,242.60083,-9.966427e-02, 73.11489,50.00000,33.00000,1.928138e-10,0.88749,3
322.39001,243.66750,-9.788902e-02, 72.43383,50.00000,33.00000,1.930370e-10,0.88724,3
323.46100,244.73417,     -0.10438, 71.76702,50.00000,33.00000,1.931973e-10,0.88695,3
324.53101,245.80083,     -0.11153, 71.10255,50.00000,32.00000,1.925659e-10,0.88666,3
325.60101,246.86750,     -0.12253, 70.46000,50.00000,33.00000,1.930771e-10,0.88641,3
326.67700,247.93417,     -0.13313, 69.74511,50.00000,33.00000,1.933899e-10,0.88612,3
327.74500,249.00083,     -0.13608, 68.92426,50.00000,33.00000,1.935444e-10,0.88586,3
328.79901,250.06750,     -0.14118, 68.13936,50.00000,33.00000,1.930923e-10,0.88557,3
329.85699,251.13417,     -0.15163, 67.33787,50.00000,33.00000,1.940498e-10,0.88531,3
330.92801,252.20083,     -0.14584, 66.51234,50.00000,33.00000,1.934376e-10,0.88502,3
331.99600,253.26750,     -0.15311, 65.64809,50.00000,32.00000,1.933822e-10,0.88477,3
333.05600,254.33417,     -0.17071, 64.72128,50.00000,32.00000,1.938476e-10,0.88447,3
334.12399,255.40083,     -0.17502, 63.76340,50.00000,32.00000,1.937770e-10,0.88421,3
335.19699,256.46750,     -0.17590, 62.79809,50.00000,33.00000,1.932812e-10,0.88392,3
336.26401,257.53417,     -0.18822, 61.79915,50.00000,32.00000,1.943493e-10,0.88366,3
337.32800,258.60083,     -0.19214, 60.74000,50.00000,32.00000,1.940747e-10,0.88336,3
338.39401,259.66750,     -0.20840, 59.70745,50.00000,33.00000,1.939144e-10,0.88310,3
339.45999,260.73417,     -0.21647, 58.59043,50.00000,33.00000,1.942749e-10,0.88280,3
340.52399,261.80083,     -0.22479, 57.48809,50.00000,33.00000,1.945954e-10,0.88253,3
341.59201,262.86750,     -0.23030, 56.25809,50.00000,33.00000,1.945286e-10,0.88224,3
342.66000,263.93417,     -0.25083, 55.07362,50.00000,33.00000,1.944905e-10,0.88198,3
343.71899,265.00083,     -0.25988, 53.83894,50.00000,33.00000,1.940708e-10,0.88167,3
344.78299,266.06750,     -0.27048, 52.57745,50.00000,33.00000,1.946602e-10,0.88142,3
345.86401,267.13417,     -0.29028, 51.28723,50.00000,33.00000,1.944542e-10,0.88109,3
346.92001,268.20083,     -0.30182, 49.93213,50.00000,33.00000,1.948051e-10,0.88079,3
347.98999,269.26750,     -0.31624, 48.58170,50.00000,33.00000,1.945324e-10,0.88053,3
349.05099,270.33417,     -0.33311, 47.18553,50.00000,33.00000,1.947899e-10,0.88023,3
350.12201,271.40083,     -0.35595, 45.75574,50.00000,33.00000,1.947746e-10,0.87996,3
351.17999,272.46750,     -0.37643, 44.30681,50.00000,33.00000,1.946964e-10,0.87969,3
352.25400,273.53417,     -0.40336, 42.90106,50.00000,33.00000,1.944351e-10,0.87938,3
353.32199,274.60083,     -0.42420, 41.50234,50.00000,33.00000,1.950359e-10,0.87907,3
354.36801,275.66750,     -0.45280, 40.03894,50.00000,33.00000,1.947308e-10,0.87880,3
355.44901,276.73417,     -0.48415, 38.62106,50.00000,33.00000,1.952381e-10,0.87849,3
356.51401,277.80083,     -0.51181, 37.17936,50.00000,33.00000,1.954460e-10,0.87822,3
357.58401,278.86750,     -0.54244, 35.79511,50.00000,33.00000,1.950931e-10,0.87790,3
358.64001,279.93417,     -0.58157, 34.38936,50.00000,33.00000,1.946011e-10,0.87763,3
359.75500,281.00083,     -0.62131, 33.02702,50.00000,33.00000,1.951369e-10,0.87730,3
360.78500,282.06750,     -0.66108, 31.64766,50.00000,33.00000,1.948395e-10,0.87703,3
361.85999,283.13417,     -0.70323, 30.28298,50.00000,33.00000,1.953315e-10,0.87672,3
362.93100,284.20083,     -0.76134, 28.96617,50.00000,33.00000,1.954460e-10,0.87644,3
363.99200,285.26750,     -0.80418, 27.67128,50.00000,33.00000,1.953430e-10,0.87611,3
365.07101,286.33417,     -0.87088, 26.38106,50.00000,33.00000,1.953259e-10,0.87585,3
366.12299,287.40083,     -0.92609, 25.13170,50.00000,33.00000,1.954460e-10,0.87552,3
367.20099,288.46750,     -0.98170, 23.83681,50.00000,33.00000,1.951102e-10,0.87525,3
368.27200,289.53417,     -1.04398, 22.64043,50.00000,33.00000,1.954747e-10,0.87498,3
369.32401,290.60083,     -1.10933, 21.42723,50.00000,33.00000,1.956672e-10,0.87466,3
370.39099,291.66750,     -1.17060, 20.21638,50.00000,33.00000,1.952590e-10,0.87438,3
371.45300,292.73417,     -1.24174, 19.07787,50.00000,33.00000,1.955471e-10,0.87406,3
372.50400,293.80083,     -1.30086, 17.92723,50.00000,33.00000,1.957264e-10,0.87378,3
373.58701,294.86750,     -1.37445, 16.79596,50.00000,33.00000,1.956291e-10,0.87346,3
374.64099,295.93417,     -1.45160, 15.68149,50.00000,33.00000,1.964111e-10,0.87317,3
375.71399,297.00083,     -1.52968, 14.67043,50.00000,33.00000,1.962814e-10,0.87286,3
376.79199,298.06750,     -1.62322, 13.63787,50.00000,33.00000,1.963253e-10,0.87257,3
377.84900,299.13417,     -1.73381, 12.63404,50.00000,33.00000,1.953010e-10,0.87224,3
378.90601,300.20083,     -1.81486, 11.60383,50.00000,33.00000,1.965122e-10,0.87195,3
379.98300,301.26750,     -1.85557, 10.61936,50.00000,33.00000,1.967239e-10,0.87164,3
381.05499,302.33417,     -1.90483,  9.61787,50.00000,33.00000,1.960506e-10,0.87134,3
382.11499,303.40083,     -1.94985,  8.68638,50.00000,33.00000,1.963844e-10,0.87100,3
383.19400,304.46750,     -1.99643,  7.78128,50.00000,33.00000,1.965866e-10,0.87072,3
384.24899,305.53417,     -2.04811,  6.93638,50.00000,33.00000,1.962357e-10,0.87039,3
385.31500,306.60083,     -2.09239,  6.09404,50.00000,33.00000,1.963539e-10,0.87011,3
386.39801,307.66750,     -2.14052,  5.34532,50.00000,33.00000,1.963424e-10,0.86978,3
387.45001,308.73417,     -2.18985,  4.64723,50.00000,33.00000,1.966153e-10,0.86949,3
388.51999,309.80083,     -2.24099,  3.94681,50.00000,33.00000,1.957111e-10,0.86915,3
389.58200,310.86750,     -2.29432,  3.38106,50.00000,33.00000,1.968574e-10,0.86886,3
390.65201,311.93417,     -2.34182,  2.78426,50.00000,33.00000,1.975536e-10,0.86853,3
391.71399,313.00083,     -2.39359,  2.31489,50.00000,33.00000,1.971874e-10,0.86823,3
392.78799,314.06750,     -2.43649,  1.87191,50.00000,33.00000,1.967430e-10,0.86790,3
393.85999,315.13417,     -2.48554,  1.49404,50.00000,33.00000,1.973858e-10,0.86760,3
394.92099,316.20083,     -2.53517,  1.17383,50.00000,33.00000,1.974124e-10,0.86727,3
395.97501,317.26750,     -2.57348,  0.89936,50.00000,33.00000,1.973628e-10,0.86692,3
397.04099,318.33417,     -2.61754,  0.68277,50.00000,33.00000,1.967354e-10,0.86664,3
398.11200,319.40083,     -2.65122,  0.53830,50.00000,33.00000,1.967984e-10,0.86634,3
399.16501,320.46750,     -2.68283,  0.39383,50.00000,33.00000,1.969719e-10,0.86600,3
399.69501,320.97917,     -2.69902,  0.35787,50.00000,33.00000,1.972961e-10,0.86585,4
399.84000,321.05917,     -2.65995,  0.32894,50.00000,33.00000,1.972008e-10,0.86581,4
400.09399,321.13917,     -2.47332,  0.35787,50.00000,33.00000,1.972008e-10,0.86581,4
400.51901,321.21917,     -2.11141,  0.42043,50.00000,33.00000,1.972008e-10,0.86581,4
401.12000,321.29917,     -1.58542,  0.44936,50.00000,33.00000,1.971264e-10,0.86575,4
401.93600,321.37917,     -0.91719,  0.54553,50.00000,33.00000,1.971264e-10,0.86575,4
402.91101,321.45917,     -0.13977,  0.66362,50.00000,33.00000,1.974830e-10,0.86571,4
404.04901,321.53917,      0.70392,  0.76936,50.00000,33.00000,1.974830e-10,0.86571,4
405.35300,321.61917,      1.57722,  0.86340,50.00000,33.00000,1.975022e-10,0.86566,4
406.76001,321.69917,      2.43451,  0.98617,50.00000,33.00000,1.975022e-10,0.86566,4
408.26401,321.77917,      3.24808,  1.10404,50.00000,33.00000,1.971894e-10,0.86561,4
409.83499,321.85917,      3.97836,  1.16426,50.00000,33.00000,1.971894e-10,0.86561,4
411.45001,321.93917,      4.61418,  1.27489,50.00000,33.00000,1.972542e-10,0.86556,4
413.07401,322.01917,      5.13663,  1.30383,50.00000,33.00000,1.972542e-10,0.86556,4
414.70200,322.09917,      5.53946,  1.36638,50.00000,33.00000,1.971817e-10,0.86551,4
416.34000,322.17917,      5.82888,  1.39532,50.00000,33.00000,1.971817e-10,0.86551,4
417.88000,322.25917,      6.00445,  1.45298,50.00000,33.00000,1.972122e-10,0.86545,4
419.40799,322.33917,      6.08176,  1.47468,50.00000,33.00000,1.972122e-10,0.86545,4
420.90100,322.41917,      6.08530,  1.51553,50.00000,33.00000,1.969414e-10,0.86540,4
422.35699,322.49917,      6.01800,  1.48191,50.00000,33.00000,1.969414e-10,0.86540,4
423.75299,322.57917,      5.90493,  1.48191,50.00000,33.00000,1.966171e-10,0.86536,4
425.13400,322.65917,      5.76705,  1.48191,50.00000,33.00000,1.966171e-10,0.86536,4
426.48901,322.73917,      5.61362,  1.48191,50.00000,33.00000,1.970596e-10,0.86531,4
427.82001,322.81917,      5.46260,  1.48191,50.00000,33.00000,1.970596e-10,0.86531,4
429.13800,322.89917,      5.32725,  1.48191,50.00000,33.00000,1.972561e-10,0.86526,4
430.47501,322.97917,      5.21377,  1.45298,50.00000,33.00000,1.972561e-10,0.86526,4
431.79099,323.05917,      5.12906,  1.45298,50.00000,33.00000,1.970443e-10,0.86521,4
433.14301,323.13917,      5.08055,  1.48191,50.00000,33.00000,1.970443e-10,0.86521,4
434.52499,323.21917,      5.06469,  1.51085,50.00000,33.00000,1.966782e-10,0.86516,4
435.90500,323.29917,      5.08073,  1.51085,50.00000,33.00000,1.966782e-10,0.86516,4
437.31799,323.37917,      5.13251,  1.53979,50.00000,33.00000,1.971607e-10,0.86512,4
438.76801,323.45917,      5.20645,  1.56851,50.00000,33.00000,1.971607e-10,0.86512,4
440.24100,323.53917,      5.30457,  1.56851,50.00000,33.00000,1.977902e-10,0.86506,4
441.75000,323.61917,      5.41819,  1.59745,50.00000,33.00000,1.977902e-10,0.86506,4
443.28500,323.69917,      5.54014,  1.62638,50.00000,33.00000,1.977024e-10,0.86502,4
444.84500,323.77917,      5.66897,  1.68660,50.00000,33.00000,1.977024e-10,0.86502,4
446.43900,323.85917,      5.79333,  1.68660,50.00000,33.00000,1.971435e-10,0.86498,4
448.02899,323.93917,      5.91091,  1.71532,50.00000,33.00000,1.971435e-10,0.86498,4
449.67099,324.01917,      6.01835,  1.73702,50.00000,33.00000,1.970043e-10,0.86492,4
451.26501,324.09917,      6.11302,  1.73702,50.00000,33.00000,1.970043e-10,0.86492,4
452.89899,324.17917,      6.19330,  1.77319,50.00000,33.00000,1.969871e-10,0.86486,4
454.51901,324.25917,      6.26065,  1.79489,50.00000,33.00000,1.969871e-10,0.86486,4
456.16599,324.33917,      6.30827,  1.80213,50.00000,33.00000,1.971684e-10,0.86482,4
457.79901,324.41917,      6.33972,  1.83106,50.00000,33.00000,1.971684e-10,0.86482,4
459.45300,324.49917,      6.36155,  1.85979,50.00000,33.00000,1.967030e-10,0.86477,4
461.09100,324.57917,      6.36828,  1.85979,50.00000,33.00000,1.967030e-10,0.86477,4
462.73300,324.65917,      6.36739,  1.86702,50.00000,33.00000,1.967030e-10,0.86477,4
464.36899,324.73917,      6.35720,  1.88872,50.00000,33.00000,1.976337e-10,0.86472,4
466.03101,324.81917,      6.34176,  1.91766,50.00000,33.00000,1.976337e-10,0.86472,4
467.66699,324.89917,      6.31829,  1.91766,50.00000,33.00000,1.971817e-10,0.86467,4
469.29501,324.97917,      6.29564,  1.89596,50.00000,33.00000,1.971817e-10,0.86467,4
470.94299,325.05917,      6.27223,  1.91766,50.00000,33.00000,1.971970e-10,0.86463,4
472.58301,325.13917,      6.24758,  1.94660,50.00000,33.00000,1.971970e-10,0.86463,4
474.22501,325.21917,      6.22072,  1.94660,50.00000,33.00000,1.976681e-10,0.86458,4
475.86600,325.29917,      6.19655,  1.94660,50.00000,33.00000,1.976681e-10,0.86458,4
477.50601,325.37917,      6.17325,  1.94660,50.00000,33.00000,1.974545e-10,0.86453,4
479.16199,325.45917,      6.15306,  1.94660,50.00000,33.00000,1.974545e-10,0.86453,4
480.81299,325.53917,      6.13531,  1.97532,50.00000,33.00000,1.964971e-10,0.86447,4
482.48099,325.61917,      6.11679,  1.97532,50.00000,33.00000,1.964971e-10,0.86447,4
484.13501,325.69917,      6.09828,  1.97532,50.00000,33.00000,1.980419e-10,0.86444,4
485.79800,325.77917,      6.08287,  2.00426,50.00000,33.00000,1.980419e-10,0.86444,4
487.45999,325.85917,      6.05997,  2.00426,50.00000,33.00000,1.966400e-10,0.86437,4
489.12201,325.93917,      6.03797,  2.01149,50.00000,33.00000,1.966400e-10,0.86437,4
490.82599,326.01917,      6.01562,  2.01149,50.00000,33.00000,1.969891e-10,0.86432,4
492.46600,326.09917,      5.98892,  2.03319,50.00000,33.00000,1.969891e-10,0.86432,4
494.13400,326.17917,      5.96041,  2.03319,50.00000,33.00000,1.979084e-10,0.86428,4
495.80801,326.25917,      5.93070,  2.04766,50.00000,33.00000,1.979084e-10,0.86428,4
497.47400,326.33917,      5.89676,  2.04766,50.00000,33.00000,1.973037e-10,0.86422,4
499.14099,326.41917,      5.85969,  2.06213,50.00000,33.00000,1.973037e-10,0.86422,4
500.81500,326.49917,      5.81817,  2.06213,50.00000,33.00000,1.976567e-10,0.86418,4
502.48199,326.57917,      5.77234,  2.06213,50.00000,33.00000,1.976567e-10,0.86418,4
504.16199,326.65917,      5.72987,  2.06213,50.00000,33.00000,1.967564e-10,0.86413,4
505.83099,326.73917,      5.68276,  2.06936,50.00000,33.00000,1.967564e-10,0.86413,4
507.49200,326.81917,      5.63805,  2.09085,50.00000,33.00000,1.973992e-10,0.86407,4
509.15500,326.89917,      5.58905,  2.09085,50.00000,33.00000,1.973992e-10,0.86407,4
510.82199,326.97917,      5.54525,  2.09085,50.00000,33.00000,1.970463e-10,0.86400,4
512.49200,327.05917,      5.49716,  2.11255,50.00000,33.00000,1.970463e-10,0.86400,4
514.15198,327.13917,      5.45065,  2.13426,50.00000,33.00000,1.973896e-10,0.86398,4
515.80603,327.21917,      5.39977,  2.10298,50.00000,33.00000,1.973896e-10,0.86398,4
517.47302,327.29917,      5.34542,  2.10298,50.00000,33.00000,1.971950e-10,0.86393,4
519.13599,327.37917,      5.29571,  2.10298,50.00000,33.00000,1.971950e-10,0.86393,4
520.79401,327.45917,      5.24187,  2.13191,50.00000,33.00000,1.979656e-10,0.86388,4
522.44702,327.53917,      5.19240,  2.10298,50.00000,33.00000,1.979656e-10,0.86388,4
524.12299,327.61917,      5.13538,  2.10298,50.00000,33.00000,1.969242e-10,0.86384,4
525.77698,327.69917,      5.08512,  2.13191,50.00000,33.00000,1.969242e-10,0.86384,4
527.43500,327.77917,      5.02882,  2.11745,50.00000,33.00000,1.972981e-10,0.86378,4
529.09900,327.85917,      4.97783,  2.10298,50.00000,33.00000,1.972981e-10,0.86378,4
530.74799,327.93917,      4.92649,  2.13191,50.00000,33.00000,1.972485e-10,0.86373,4
532.40997,328.01917,      4.86913,  2.13191,50.00000,33.00000,1.972485e-10,0.86373,4
534.07202,328.09917,      4.81288,  2.16064,50.00000,33.00000,1.972485e-10,0.86373,4
535.71698,328.17917,      4.75653,  2.16064,50.00000,33.00000,1.973515e-10,0.86367,4
537.37903,328.25917,      4.69945,  2.16064,50.00000,33.00000,1.973515e-10,0.86367,4
539.02502,328.33917,      4.63920,  2.16064,50.00000,33.00000,1.970272e-10,0.86363,4
540.66602,328.41917,      4.58116,  2.16787,50.00000,33.00000,1.970272e-10,0.86363,4
542.32501,328.49917,      4.52154,  2.27383,50.00000,33.00000,1.971798e-10,0.86359,4
543.98199,328.57917,      4.45994,  2.21128,50.00000,33.00000,1.971798e-10,0.86359,4
545.62799,328.65917,      4.39968,  2.21128,50.00000,33.00000,1.974258e-10,0.86353,4
547.28101,328.73917,      4.33975,  2.24021,50.00000,33.00000,1.974258e-10,0.86353,4
548.94202,328.81917,      4.27787,  2.24021,50.00000,33.00000,1.969471e-10,0.86348,4
550.58099,328.89917,      4.21246,  2.24021,50.00000,33.00000,1.969471e-10,0.86348,4
552.21899,328.97917,      4.15161,  2.26191,50.00000,33.00000,1.978608e-10,0.86344,4
553.87201,329.05917,      4.08454,  2.26191,50.00000,33.00000,1.978608e-10,0.86344,4
555.52301,329.13917,      4.02003,  2.26191,50.00000,33.00000,1.972847e-10,0.86338,4
557.17200,329.21917,      3.95350,  2.26191,50.00000,33.00000,1.972847e-10,0.86338,4
558.82001,329.29917,      3.88436,  2.29787,50.00000,33.00000,1.975288e-10,0.86333,4
560.45599,329.37917,      3.82495,  2.29787,50.00000,33.00000,1.975288e-10,0.86333,4
562.09802,329.45917,      3.75838,  2.32681,50.00000,33.00000,1.974334e-10,0.86329,4
563.73199,329.53917,      3.69408,  2.32681,50.00000,33.00000,1.974334e-10,0.86329,4
565.37799,329.61917,      3.62984,  2.35574,50.00000,33.00000,1.980438e-10,0.86323,4
567.02600,329.69917,      3.56359,  2.35574,50.00000,33.00000,1.980438e-10,0.86323,4
568.66400,329.77917,      3.49613,  2.38468,50.00000,33.00000,1.978054e-10,0.86318,4
570.29700,329.85917,      3.42983,  2.39894,50.00000,33.00000,1.978054e-10,0.86318,4
571.93799,329.93917,      3.35684,  2.41340,50.00000,33.00000,1.973743e-10,0.86314,4
573.58197,330.01917,      3.29557,  2.41340,50.00000,33.00000,1.973743e-10,0.86314,4
575.22900,330.09917,      3.22377,  2.44234,50.00000,33.00000,1.972694e-10,0.86308,4
576.85199,330.17917,      3.15894,  2.47128,50.00000,33.00000,1.972694e-10,0.86308,4
578.49402,330.25917,      3.08801,  2.47128,50.00000,33.00000,1.972827e-10,0.86303,4
580.12701,330.33917,      3.02059,  2.49298,50.00000,33.00000,1.972827e-10,0.86303,4
581.76398,330.41917,      2.95291,  2.50021,50.00000,33.00000,1.976300e-10,0.86298,4
583.39502,330.49917,      2.88256,  2.50021,50.00000,33.00000,1.976300e-10,0.86298,4
585.03302,330.57917,      2.81491,  2.51468,50.00000,33.00000,1.978970e-10,0.86294,4
586.66400,330.65917,      2.74222,  2.51468,50.00000,33.00000,1.978970e-10,0.86294,4
588.29498,330.73917,      2.67250,  2.53617,50.00000,33.00000,1.974201e-10,0.86288,4
589.93701,330.81917,      2.60045,  2.57234,50.00000,33.00000,1.974201e-10,0.86288,4
591.56000,330.89917,      2.53523,  2.58681,50.00000,33.00000,1.976166e-10,0.86283,4
593.19598,330.97917,      2.46949,  2.61574,50.00000,33.00000,1.976166e-10,0.86283,4
594.82703,331.05917,      2.39808,  2.61574,50.00000,33.00000,1.973953e-10,0.86277,4
596.45099,331.13917,      2.32607,  2.64447,50.00000,33.00000,1.973953e-10,0.86277,4
598.09198,331.21917,      2.25201,  2.64447,50.00000,33.00000,1.972961e-10,0.86273,4
599.71997,331.29917,      2.17733,  2.67340,50.00000,33.00000,1.972961e-10,0.86273,4
601.34100,331.37917,      2.10326,  2.70234,50.00000,33.00000,1.971397e-10,0.86267,4
602.95599,331.45917,      2.03283,  2.70234,50.00000,33.00000,1.971397e-10,0.86267,4
604.60101,331.53917,      1.95856,  2.73128,50.00000,33.00000,1.971397e-10,0.86267,4
606.23199,331.61917,      1.88428,  2.76000,50.00000,33.00000,1.978913e-10,0.86263,4
607.86102,331.69917,      1.80667,  2.76000,50.00000,33.00000,1.978913e-10,0.86263,4
609.48602,331.77917,      1.73273,  2.78894,50.00000,33.00000,1.973953e-10,0.86259,4
611.10699,331.85917,      1.66004,  2.78894,50.00000,33.00000,1.973953e-10,0.86259,4
612.73297,331.93917,      1.58525,  2.78894,50.00000,33.00000,1.971512e-10,0.86253,4
614.36200,332.01917,      1.50406,  2.81787,50.00000,33.00000,1.971512e-10,0.86253,4
615.99200,332.09917,      1.42688,  2.84681,50.00000,33.00000,1.974964e-10,0.86248,4
617.60498,332.17917,      1.34939,  2.84681,50.00000,33.00000,1.974964e-10,0.86248,4
619.23102,332.25917,      1.27195,  2.87574,50.00000,33.00000,1.974430e-10,0.86243,4
620.85303,332.33917,      1.19084,  2.89723,50.00000,33.00000,1.974430e-10,0.86243,4
622.48297,332.41917,      1.11593,  2.89723,50.00000,33.00000,1.976299e-10,0.86239,4
624.09698,332.49917,      1.03734,  2.90447,50.00000,33.00000,1.976299e-10,0.86239,4
625.72998,332.57917,      0.95508,  2.93340,50.00000,33.00000,1.980076e-10,0.86233,4
627.34399,332.65917,      0.88152,  2.93340,50.00000,33.00000,1.980076e-10,0.86233,4
628.96600,332.73917,      0.79527,  2.93340,50.00000,33.00000,1.973495e-10,0.86228,4
630.59399,332.81917,      0.71371,  2.96234,50.00000,33.00000,1.973495e-10,0.86228,4
632.20502,332.89917,      0.63748,  3.04404,50.00000,33.00000,1.975784e-10,0.86223,4
633.82898,332.97917,      0.55193,  3.04404,50.00000,33.00000,1.975784e-10,0.86223,4
635.45001,333.05917,      0.46702,  3.04404,50.00000,33.00000,1.979084e-10,0.86218,4
637.06201,333.13917,      0.38403,  3.04404,50.00000,33.00000,1.979084e-10,0.86218,4
638.68298,333.21917,      0.29227,  3.04404,50.00000,33.00000,1.978722e-10,0.86213,4
640.30200,333.29917,      0.20713,  3.07298,50.00000,33.00000,1.978722e-10,0.86213,4
641.92297,333.37917,      0.11982,  3.10191,50.00000,33.00000,1.976928e-10,0.86208,4
643.53802,333.45917, 3.316128e-02,  3.13085,50.00000,33.00000,1.976928e-10,0.86208,4
645.16199,333.53917,-4.903275e-02,  3.10915,50.00000,33.00000,1.979542e-10,0.86203,4
646.77600,333.61917,     -0.13530,  3.10915,50.00000,33.00000,1.979542e-10,0.86203,4
648.39801,333.69917,     -0.22184,  3.14043,50.00000,33.00000,1.976051e-10,0.86198,4
650.00403,333.77917,     -0.30390,  3.14043,50.00000,33.00000,1.976051e-10,0.86198,4
651.61700,333.85917,     -0.38908,  3.14043,50.00000,33.00000,1.976585e-10,0.86192,4
653.23798,333.93917,     -0.47805,  3.16936,50.00000,33.00000,1.976585e-10,0.86192,4
654.85602,334.01917,     -0.56570,  3.19830,50.00000,33.00000,1.981811e-10,0.86187,4
656.46899,334.09917,     -0.65746,  3.22702,50.00000,33.00000,1.981811e-10,0.86187,4
658.09399,334.17917,     -0.73350,  3.22702,50.00000,33.00000,1.980305e-10,0.86182,4
659.70697,334.25917,     -0.82197,  3.22702,50.00000,33.00000,1.980305e-10,0.86182,4
661.32098,334.33917,     -0.91232,  3.25596,50.00000,33.00000,1.980305e-10,0.86182,4
662.94098,334.41917,     -1.00006,  3.28489,50.00000,33.00000,1.979312e-10,0.86178,4
664.54602,334.49917,     -1.09224,  3.28489,50.00000,33.00000,1.979312e-10,0.86178,4
666.16400,334.57917,     -1.17762,  3.31383,50.00000,33.00000,1.977291e-10,0.86173,4
667.77301,334.65917,     -1.26681,  3.32106,50.00000,33.00000,1.977291e-10,0.86173,4
669.40198,334.73917,     -1.35629,  3.34255,50.00000,33.00000,1.977119e-10,0.86168,4
671.01202,334.81917,     -1.44959,  3.37149,50.00000,33.00000,1.977119e-10,0.86168,4
672.62701,334.89917,     -1.54480,  3.37149,50.00000,33.00000,1.973458e-10,0.86163,4
674.24200,334.97917,     -1.63510,  3.40043,50.00000,33.00000,1.973458e-10,0.86163,4
675.84698,335.05917,     -1.73412,  3.42936,50.00000,33.00000,1.978245e-10,0.86157,4
677.47601,335.13917,     -1.82695,  3.40043,50.00000,33.00000,1.978245e-10,0.86157,4
679.08801,335.21917,     -1.92591,  3.42936,50.00000,33.00000,1.978587e-10,0.86152,4
680.69800,335.29917,     -2.02188,  3.45809,50.00000,33.00000,1.978587e-10,0.86152,4
682.30200,335.37917,     -2.12042,  3.45809,50.00000,33.00000,1.977024e-10,0.86148,4
683.91498,335.45917,     -2.21434,  3.45809,50.00000,33.00000,1.977024e-10,0.86148,4
685.52899,335.53917,     -2.30953,  3.48702,50.00000,33.00000,1.977330e-10,0.86143,4
687.13300,335.61917,     -2.40727,  3.48702,50.00000,33.00000,1.977330e-10,0.86143,4
688.74902,335.69917,     -2.50368,  3.51596,50.00000,33.00000,1.975785e-10,0.86137,4
690.35498,335.77917,     -2.60133,  3.54489,50.00000,33.00000,1.975785e-10,0.86137,4
691.97302,335.85917,     -2.69366,  3.55213,50.00000,33.00000,1.973152e-10,0.86133,4
693.59601,335.93917,     -2.79026,  3.57362,50.00000,33.00000,1.973152e-10,0.86133,4
695.20099,336.01917,     -2.88176,  3.57362,50.00000,33.00000,1.975555e-10,0.86127,4
696.82397,336.09917,     -2.97857,  3.57362,50.00000,33.00000,1.975555e-10,0.86127,4
698.42401,336.17917,     -3.07292,  3.60255,50.00000,33.00000,1.976356e-10,0.86123,4
700.04901,336.25917,     -3.16594,  3.60255,50.00000,33.00000,1.976356e-10,0.86123,4
701.66803,336.33917,     -3.25821,  3.63149,50.00000,33.00000,1.974906e-10,0.86117,4
703.28003,336.41917,     -3.35640,  3.66043,50.00000,33.00000,1.974906e-10,0.86117,4
704.88202,336.49917,     -3.45182,  3.66043,50.00000,33.00000,1.976261e-10,0.86112,4
706.49902,336.57917,     -3.54721,  3.68915,50.00000,33.00000,1.976261e-10,0.86112,4
708.12402,336.65917,     -3.64223,  3.70362,50.00000,33.00000,1.975708e-10,0.86107,4
709.73499,336.73917,     -3.74958,  3.71809,50.00000,33.00000,1.975708e-10,0.86107,4
711.34900,336.81917,     -3.84579,  3.71809,50.00000,33.00000,1.977043e-10,0.86103,4
712.96503,336.89917,     -3.93788,  3.71809,50.00000,33.00000,1.977043e-10,0.86103,4
714.57202,336.97917,     -4.03593,  3.74702,50.00000,33.00000,1.977863e-10,0.86098,4
716.19501,337.05917,     -4.13195,  3.77596,50.00000,33.00000,1.977863e-10,0.86098,4
717.81201,337.13917,     -4.23601,  3.77596,50.00000,33.00000,1.977920e-10,0.86092,4
719.40900,337.21917,     -4.33179,  3.79043,50.00000,33.00000,1.977920e-10,0.86092,4
721.03003,337.29917,     -4.43200,  3.83362,50.00000,33.00000,1.977768e-10,0.86088,4
722.64502,337.37917,     -4.52566,  3.83362,50.00000,33.00000,1.977768e-10,0.86088,4
724.25000,337.45917,     -4.61987,  3.83362,50.00000,33.00000,1.970863e-10,0.86084,4
725.86700,337.53917,     -4.71643,  3.86255,50.00000,33.00000,1.970863e-10,0.86084,4
727.48602,337.61917,     -4.81122,  3.86255,50.00000,33.00000,1.979332e-10,0.86077,4
729.09302,337.69917,     -4.91066,  3.88426,50.00000,33.00000,1.979332e-10,0.86077,4
730.70001,337.77917,     -5.00694,  3.88426,50.00000,33.00000,1.977615e-10,0.86071,4
732.31799,337.85917,     -5.10079,  3.89149,50.00000,33.00000,1.977615e-10,0.86071,4
733.92798,337.93917,     -5.19726,  3.92043,50.00000,33.00000,1.975498e-10,0.86066,4
735.54303,338.01917,     -5.28919,  3.92043,50.00000,33.00000,1.975498e-10,0.86066,4
737.15900,338.09917,     -5.38034,  3.94915,50.00000,33.00000,1.985417e-10,0.86062,4
738.77399,338.17917,     -5.46551,  3.97809,50.00000,33.00000,1.985417e-10,0.86062,4
740.39502,338.25917,     -5.55683,  3.97085,50.00000,33.00000,1.977673e-10,0.86058,4
742.01801,338.33917,     -5.64840,  3.99979,50.00000,33.00000,1.977673e-10,0.86058,4
743.63898,338.41917,     -5.74506,  3.99979,50.00000,33.00000,1.975956e-10,0.86053,4
745.24799,338.49917,     -5.84088,  4.02872,50.00000,33.00000,1.975956e-10,0.86053,4
746.86798,338.57917,     -5.94711,  4.02872,50.00000,33.00000,1.974716e-10,0.86047,4
748.47803,338.65917,     -6.04452,  4.02872,50.00000,33.00000,1.974716e-10,0.86047,4
750.09802,338.73917,     -6.14259,  4.05745,50.00000,33.00000,1.976394e-10,0.86042,4
751.70203,338.81917,     -6.24503,  4.08638,50.00000,33.00000,1.976394e-10,0.86042,4
753.30103,338.89917,     -6.34247,  4.08638,50.00000,33.00000,1.982250e-10,0.86036,4
754.90601,338.97917,     -6.45318,  4.08638,50.00000,33.00000,1.982250e-10,0.86036,4
756.52100,339.05917,     -6.54318,  4.11532,50.00000,33.00000,1.974049e-10,0.86033,4
758.13800,339.13917,     -6.63204,  4.11532,50.00000,33.00000,1.974049e-10,0.86033,4
759.72302,339.21917,     -6.72551,  4.14426,50.00000,33.00000,1.979828e-10,0.86027,4
761.33698,339.29917,     -6.81977,  4.17298,50.00000,33.00000,1.979828e-10,0.86027,4
762.93597,339.37917,     -6.91030,  4.17298,50.00000,33.00000,1.979828e-10,0.86027,4
764.54901,339.45917,     -7.00046,  4.20191,50.00000,33.00000,1.977386e-10,0.86022,4
766.15302,339.53917,     -7.08586,  4.20191,50.00000,33.00000,1.977386e-10,0.86022,4
767.76202,339.61917,     -7.17434,  4.23085,50.00000,33.00000,1.976852e-10,0.86016,4
769.36798,339.69917,     -7.26518,  4.23085,50.00000,33.00000,1.976852e-10,0.86016,4
770.96899,339.77917,     -7.34877,  4.25979,50.00000,33.00000,1.980762e-10,0.86011,4
772.58698,339.85917,     -7.43626,  4.28851,50.00000,33.00000,1.980762e-10,0.86011,4
774.19098,339.93917,     -7.51926,  4.28851,50.00000,33.00000,1.979542e-10,0.86006,4
775.79901,340.01917,     -7.60108,  4.31745,50.00000,33.00000,1.979542e-10,0.86006,4
777.41498,340.09917,     -7.68354,  4.31745,50.00000,33.00000,1.976375e-10,0.86001,4
779.02301,340.17917,     -7.77047,  4.34638,50.00000,33.00000,1.976375e-10,0.86001,4
780.63599,340.25917,     -7.85157,  4.37532,50.00000,33.00000,1.983013e-10,0.85996,4
782.23999,340.33917,     -7.93176,  4.37532,50.00000,33.00000,1.983013e-10,0.85996,4
783.84802,340.41917,     -8.01256,  4.37532,50.00000,33.00000,1.982784e-10,0.85992,4
785.45599,340.49917,     -8.09466,  4.40426,50.00000,33.00000,1.982784e-10,0.85992,4
787.06897,340.57917,     -8.17666,  4.43298,50.00000,33.00000,1.974525e-10,0.85987,4
788.66699,340.65917,     -8.25481,  4.43298,50.00000,33.00000,1.974525e-10,0.85987,4
790.27502,340.73917,     -8.33289,  4.43298,50.00000,33.00000,1.980534e-10,0.85982,4
791.88300,340.81917,     -8.40757,  4.46191,50.00000,33.00000,            ,0.44814,4
793.49402,340.89917,     -8.48031,  4.46191,50.00000,33.00000,            ,0.44750,4
794.20099,340.93417,     -8.51727,  4.46191,50.00000,33.00000,            ,0.44721,4