File: data/TGA/005d-L_M/ExpDat_2025_03_20_Styrofoam_dynamic.csv
#EXPORTTYPE:                 ,DATA ALL
#FILE:                       ,2025_03_20_Styrofoam_dynamic.ngb-ss5
#FORMAT:                     ,NETZSCH5
#FTYPE:                      ,ASCII
#IDENTITY:                   ,2025_03_20_Styrofoam
#DECIMAL:                    ,POINT
#SEPARATOR:                  ,COMMA
#MTYPE:                      ,DSC
#INSTRUMENT:                 ,NETZSCH STA 449F5
#PROJECT:                    ,PS
#DATE/TIME:                  ,3/20/2025 5:53:13 PM (UTC-4)
#CORR. FILE:                 ,
#TEMPCAL:                    ,13-11-2024 10:37
#SENSITIVITY:                ,28-06-2023 13:53
#LABORATORY:                 ,Tran/Aspuru
#OPERATOR:                   ,Stanley
#REMARK:                     ,2025_03_20_Styrofoam_dynamic
#SAMPLE:                     ,2025_03_20_Styrofoam
#SAMPLE MASS /mg:            ,5.09
#MATERIAL:                   ,Polystyrene
#REFERENCE:                  ,
#REFERENCE MASS /mg:         ,0
#TYPE OF CRUCIBLE:           ,Al2O3 85 ‘l, open
#SAMPLE CRUCIBLE MASS /mg:   ,0
#REFERENCE CRUCIBLE MASS /mg:,0
#DSC RANGE /‘V:              ,5000
#TG RANGE /mg:               ,35000
#TAU-R:                      ,---
#CORR. CODE:                 ,000
#EXO:                        ,-1
#RANGE:                      ,20›C....800›C/0.0....20.0K/min
#SEGMENT:                    ,S1-4/4
#SEG. 1:                     ,20›C/5.0(K/min)/100›C
#SEG. 2:                     ,100›C/00:05/100›C
#SEG. 3:                     ,100›C/1.0(K/min)/400›C
#SEG. 4:                     ,400›C/20.0(K/min)/800›C

##Temp./›C,Time/min,DSC/(mW/mg),Mass/%,Gas Flow(purge2)/(ml/min),Gas Flow(protective)/(ml/min),TIC(scan:1)/A,Sensit./(uV/mW),Segment
 29.65000,  0.00000, 4.122632e-02,100.00000,50.00000,25.00000,            ,0.92349,1
 31.18600,  1.06667, 1.152039e-02, 99.82652,50.00000,25.00000,2.793502e-10,0.92360,1
 32.38600,  2.13333,-6.326677e-03, 94.16994,50.00000,25.00000,2.780914e-10,0.92372,1
 33.46400,  3.20000,-8.271744e-03, 93.41415,50.00000,25.00000,2.784042e-10,0.92382,1
 35.15200,  4.26667, 2.837529e-02, 93.63654,50.00000,25.00000,2.785091e-10,0.92391,1
 37.80000,  5.33333, 9.368119e-02, 94.04106,50.00000,25.00000,2.785415e-10,0.92398,1
 41.55800,  6.40000,      0.16653, 94.52770,50.00000,25.00000,2.791939e-10,0.92405,1
 46.27000,  7.46667,      0.24288, 95.03006,50.00000,25.00000,2.794265e-10,0.92413,1
 51.78100,  8.53333,      0.31158, 95.49234,50.00000,25.00000,2.797909e-10,0.92422,1
 57.88800,  9.60000,      0.37076, 95.89253,50.00000,25.00000,2.796554e-10,0.92433,1
 64.41000, 10.66667,      0.41903, 96.11473,50.00000,25.00000,2.785072e-10,0.92444,1
 71.06700, 11.73333,      0.45077, 96.35697,50.00000,25.00000,2.786904e-10,0.92460,1
 77.73600, 12.80000,      0.47474, 96.47269,50.00000,25.00000,2.796935e-10,0.92475,1
 84.33900, 13.86667,      0.48931, 96.53929,50.00000,25.00000,2.794209e-10,0.92494,1
 90.84300, 14.93333,      0.49641, 96.60589,50.00000,25.00000,2.800350e-10,0.92511,1
 97.09700, 15.98333,      0.50217, 96.63929,50.00000,25.00000,2.793885e-10,0.92532,2
101.30300, 16.78333,      0.44314, 96.32593,50.00000,25.00000,2.804222e-10,0.92546,2
104.17700, 17.58333,      0.28758, 95.67466,50.00000,25.00000,2.797908e-10,0.92557,2
106.05500, 18.38333,      0.15928, 95.23458,50.00000,25.00000,2.803383e-10,0.92571,2
107.36800, 19.18333, 7.502188e-02, 94.83890,50.00000,25.00000,2.791539e-10,0.92583,2
108.11500, 19.98333,-1.468165e-03, 94.46110,50.00000,25.00000,2.805271e-10,0.92594,2
108.33600, 20.78333,-7.161889e-02, 94.04538,50.00000,25.00000,2.806301e-10,0.92603,2
108.09500, 21.80000,     -0.12806, 93.64538,50.00000,25.00000,2.809829e-10,0.92612,3
107.80100, 22.86667,     -0.13522, 93.42986,50.00000,25.00000,2.797319e-10,0.92618,3
107.46700, 23.93333,     -0.13586, 93.24303,50.00000,25.00000,2.804662e-10,0.92620,3
107.23700, 25.00000,     -0.12672, 93.08310,50.00000,25.00000,2.800006e-10,0.92618,3
107.15000, 26.06667,     -0.10780, 93.00295,50.00000,25.00000,2.806321e-10,0.92612,3
107.30200, 27.13333,-8.643646e-02, 92.94303,50.00000,25.00000,2.809505e-10,0.92600,3
107.63100, 28.20000,-6.638353e-02, 92.90295,50.00000,25.00000,2.798309e-10,0.92585,3
108.16900, 29.26667,-4.551391e-02, 92.87642,50.00000,25.00000,2.811890e-10,0.92563,3
108.84800, 30.33333,-2.871753e-02, 92.85403,50.00000,25.00000,2.808438e-10,0.92540,3
109.69000, 31.40000,-1.534197e-02, 92.80079,50.00000,25.00000,2.804623e-10,0.92514,3
110.63700, 32.46667,-3.265271e-03, 92.77407,50.00000,25.00000,2.809792e-10,0.92478,3
111.65600, 33.53333, 4.899585e-03, 92.74735,50.00000,25.00000,2.815113e-10,0.92443,3
112.74300, 34.60000, 1.127325e-02, 92.71415,50.00000,25.00000,2.819443e-10,0.92399,3
113.85500, 35.66667, 1.421962e-02, 92.68743,50.00000,25.00000,2.809009e-10,0.92350,3
114.97000, 36.73333, 1.520632e-02, 92.64735,50.00000,25.00000,2.818050e-10,0.92305,3
116.11400, 37.80000, 1.570336e-02, 92.61415,50.00000,25.00000,2.809658e-10,0.92256,3
117.25400, 38.86667, 1.423717e-02, 92.58743,50.00000,25.00000,2.816315e-10,0.92197,3
118.39100, 39.93333, 1.211496e-02, 92.54067,50.00000,25.00000,2.808647e-10,0.92152,3
119.51600, 41.00000, 1.162883e-02, 92.56071,50.00000,25.00000,2.814999e-10,0.92106,3
120.63700, 42.06667, 9.503761e-03, 92.53399,50.00000,25.00000,2.816448e-10,0.92070,3
121.74700, 43.13333, 7.868644e-03, 92.50747,50.00000,25.00000,2.809773e-10,0.92034,3
122.83700, 44.20000, 4.428057e-03, 92.45403,50.00000,25.00000,2.813740e-10,0.92007,3
123.92700, 45.26667, 2.789281e-03, 92.44735,50.00000,25.00000,2.816068e-10,0.91980,3
125.01300, 46.33333, 1.641495e-04, 92.44735,50.00000,25.00000,2.819709e-10,0.91961,3
126.08100, 47.40000,-2.791799e-03, 92.47407,50.00000,25.00000,2.821865e-10,0.91940,3
127.15000, 48.46667,-4.928961e-03, 92.48075,50.00000,25.00000,2.817248e-10,0.91925,3
128.23300, 49.53333,-5.753163e-03, 92.50079,50.00000,25.00000,2.821275e-10,0.91910,3
129.28900, 50.60000,-8.058179e-03, 92.48743,50.00000,25.00000,2.818718e-10,0.91899,3
130.36700, 51.66667,-1.085911e-02, 92.47407,50.00000,25.00000,2.818221e-10,0.91889,3
131.42900, 52.73333,-1.382734e-02, 92.46739,50.00000,25.00000,2.820912e-10,0.91884,3
132.49001, 53.80000,-1.531630e-02, 92.46739,50.00000,25.00000,2.826614e-10,0.91880,3
133.55400, 54.86667,-1.647730e-02, 92.52063,50.00000,25.00000,2.823925e-10,0.91878,3
134.63300, 55.93333,-1.961797e-02, 92.49411,50.00000,25.00000,2.816143e-10,0.91879,3
135.69400, 57.00000,-2.160720e-02, 92.51395,50.00000,25.00000,2.830086e-10,0.91882,3
136.75800, 58.06667,-2.343360e-02, 92.51395,50.00000,25.00000,2.819900e-10,0.91886,3
137.82401, 59.13333,-2.691318e-02, 92.54067,50.00000,25.00000,2.827281e-10,0.91889,3
138.87700, 60.20000,-2.957041e-02, 92.56071,50.00000,25.00000,2.828636e-10,0.91893,3
139.95599, 61.26667,-3.123930e-02, 92.60079,50.00000,25.00000,2.822570e-10,0.91897,3
141.03101, 62.33333,-3.472929e-02, 92.60747,50.00000,25.00000,2.830829e-10,0.91900,3
142.09700, 63.40000,-3.789222e-02, 92.63399,50.00000,25.00000,2.832355e-10,0.91903,3
143.16701, 64.46667,-4.023115e-02, 92.64735,50.00000,25.00000,2.833633e-10,0.91907,3
144.24600, 65.53333,-4.472665e-02, 92.68743,50.00000,25.00000,2.823601e-10,0.91909,3
145.31700, 66.60000,-4.773562e-02, 92.70079,50.00000,25.00000,2.831116e-10,0.91911,3
146.37801, 67.66667,-5.091389e-02, 92.73399,50.00000,25.00000,2.832641e-10,0.91912,3
147.44299, 68.73333,-5.426217e-02, 92.74735,50.00000,25.00000,2.836247e-10,0.91911,3
148.51300, 69.80000,-5.811294e-02, 92.78075,50.00000,25.00000,2.841817e-10,0.91910,3
149.56900, 70.86667,-6.180199e-02, 92.79411,50.00000,25.00000,2.829246e-10,0.91908,3
150.64101, 71.93333,-6.533012e-02, 92.79411,50.00000,25.00000,2.842292e-10,0.91905,3
151.70799, 73.00000,-6.786469e-02, 92.84735,50.00000,25.00000,2.841149e-10,0.91901,3
152.77100, 74.06667,-7.156764e-02, 92.87407,50.00000,25.00000,2.846031e-10,0.91896,3
153.84100, 75.13333,-7.544238e-02, 92.88075,50.00000,25.00000,2.837468e-10,0.91889,3
154.91000, 76.20000,-7.965563e-02, 92.94754,50.00000,25.00000,2.839374e-10,0.91882,3
155.97099, 77.26667,-8.354074e-02, 92.96739,50.00000,25.00000,2.838288e-10,0.91874,3
157.04700, 78.33333,-8.659773e-02, 92.99411,50.00000,25.00000,2.837086e-10,0.91866,3
158.12100, 79.40000,-9.149564e-02, 93.02750,50.00000,25.00000,2.842064e-10,0.91856,3
159.18600, 80.46667,-9.589871e-02, 93.04754,50.00000,25.00000,2.833290e-10,0.91847,3
160.25900, 81.53333,-9.963982e-02, 93.06090,50.00000,25.00000,2.834072e-10,0.91835,3
161.32401, 82.60000,     -0.10506, 93.10747,50.00000,25.00000,2.845040e-10,0.91825,3
162.39301, 83.66667,     -0.10965, 93.15422,50.00000,25.00000,2.854995e-10,0.91814,3
163.45900, 84.73333,     -0.11475, 93.15422,50.00000,25.00000,2.844600e-10,0.91801,3
164.52100, 85.80000,     -0.12069, 93.18075,50.00000,25.00000,2.841015e-10,0.91789,3
165.58800, 86.86667,     -0.12413, 93.19411,50.00000,25.00000,2.848109e-10,0.91775,3
166.67000, 87.93333,     -0.12942, 93.24086,50.00000,25.00000,2.849731e-10,0.91760,3
167.72301, 89.00000,     -0.13572, 93.24086,50.00000,25.00000,2.844257e-10,0.91748,3
168.78500, 90.06667,     -0.14019, 93.27426,50.00000,25.00000,2.842883e-10,0.91734,3
169.86600, 91.13333,     -0.14416, 93.32083,50.00000,25.00000,2.849045e-10,0.91719,3
170.93800, 92.20000,     -0.14931, 93.34754,50.00000,25.00000,2.854805e-10,0.91705,3
172.00900, 93.26667,     -0.15616, 93.37426,50.00000,25.00000,2.844295e-10,0.91689,3
173.06799, 94.33333,     -0.16167, 93.40747,50.00000,25.00000,2.844506e-10,0.91675,3
174.11501, 95.40000,     -0.16600, 93.40747,50.00000,25.00000,2.852402e-10,0.91659,3
175.17500, 96.46667,     -0.17169, 93.46090,50.00000,25.00000,2.843589e-10,0.91645,3
176.25500, 97.53333,     -0.17655, 93.48762,50.00000,25.00000,2.851162e-10,0.91628,3
177.33000, 98.60000,     -0.18277, 93.50766,50.00000,25.00000,2.847118e-10,0.91611,3
178.38300, 99.66667,     -0.19103, 93.53418,50.00000,25.00000,2.854480e-10,0.91597,3
179.45000,100.73333,     -0.19727, 93.56090,50.00000,25.00000,2.858754e-10,0.91580,3
180.53000,101.80000,     -0.20115, 93.59430,50.00000,25.00000,2.848358e-10,0.91565,3
181.59100,102.86667,     -0.21013, 93.62534,50.00000,25.00000,2.850265e-10,0.91548,3
182.64101,103.93333,     -0.21606, 93.65206,50.00000,25.00000,2.851143e-10,0.91533,3
183.70900,105.00000,     -0.22149, 93.67210,50.00000,25.00000,2.854138e-10,0.91516,3
184.77800,106.06667,     -0.23000, 93.70530,50.00000,25.00000,2.852478e-10,0.91501,3
185.85400,107.13333,     -0.23597, 93.73870,50.00000,25.00000,2.853260e-10,0.91483,3
186.92400,108.20000,     -0.24280, 93.73202,50.00000,25.00000,2.854976e-10,0.91468,3
187.97800,109.26667,     -0.25015, 93.76542,50.00000,25.00000,2.856846e-10,0.91450,3
189.05400,110.33333,     -0.25649, 93.79214,50.00000,25.00000,2.859439e-10,0.91435,3
190.12000,111.40000,     -0.26267, 93.84538,50.00000,25.00000,2.853660e-10,0.91418,3
191.18500,112.46667,     -0.26955, 93.88546,50.00000,25.00000,2.850666e-10,0.91403,3
192.25999,113.53333,     -0.27815, 93.89882,50.00000,25.00000,2.860621e-10,0.91388,3
193.31000,114.60000,     -0.28334, 93.92534,50.00000,25.00000,2.861576e-10,0.91369,3
194.38400,115.66667,     -0.29163, 93.93438,50.00000,25.00000,2.856922e-10,0.91354,3
195.45100,116.73333,     -0.29770, 93.95442,50.00000,25.00000,2.864342e-10,0.91336,3
196.52400,117.80000,     -0.30430, 93.99430,50.00000,25.00000,2.864437e-10,0.91321,3
197.59100,118.86667,     -0.31349, 94.01434,50.00000,25.00000,2.858542e-10,0.91302,3
198.66000,119.93333,     -0.31943, 94.02102,50.00000,25.00000,2.858085e-10,0.91287,3
199.73801,121.00000,     -0.32693, 94.02770,50.00000,25.00000,2.864361e-10,0.91270,3
200.79401,122.06667,     -0.33444, 94.08094,50.00000,25.00000,2.866994e-10,0.91253,3
201.86099,123.13333,     -0.34146, 94.10098,50.00000,25.00000,2.869205e-10,0.91235,3
202.92700,124.20000,     -0.34917, 94.12102,50.00000,25.00000,2.859001e-10,0.91219,3
204.00101,125.26667,     -0.35725, 94.13438,50.00000,25.00000,2.864037e-10,0.91201,3
205.06200,126.33333,     -0.36448, 94.14774,50.00000,25.00000,2.865868e-10,0.91185,3
206.13600,127.40000,     -0.37345, 94.14774,50.00000,25.00000,2.861538e-10,0.91166,3
207.19600,128.46667,     -0.38140, 94.20098,50.00000,25.00000,2.870313e-10,0.91149,3
208.26199,129.53333,     -0.38919, 94.23438,50.00000,25.00000,2.868920e-10,0.91131,3
209.31700,130.60000,     -0.39804, 94.24106,50.00000,25.00000,2.866364e-10,0.91115,3
210.40601,131.66667,     -0.40657, 94.24106,50.00000,25.00000,2.868499e-10,0.91096,3
211.44600,132.73333,     -0.41457, 94.26778,50.00000,25.00000,2.862472e-10,0.91079,3
212.52000,133.80000,     -0.42330, 94.27662,50.00000,25.00000,2.873554e-10,0.91060,3
213.59900,134.86667,     -0.43049, 94.29666,50.00000,25.00000,2.872239e-10,0.91044,3
214.65601,135.93333,     -0.43960, 94.31670,50.00000,25.00000,2.866363e-10,0.91024,3
215.71500,137.00000,     -0.44890, 94.28998,50.00000,25.00000,2.868729e-10,0.91007,3
216.77699,138.06667,     -0.45595, 94.34322,50.00000,25.00000,2.869663e-10,0.90987,3
217.84900,139.13333,     -0.46635, 94.37662,50.00000,25.00000,2.874299e-10,0.90970,3
218.91800,140.20000,     -0.47501, 94.37662,50.00000,25.00000,2.871685e-10,0.90950,3
219.98199,141.26667,     -0.48492, 94.36994,50.00000,25.00000,2.873001e-10,0.90933,3
221.05200,142.33333,     -0.49327, 94.39666,50.00000,25.00000,2.869739e-10,0.90912,3
222.12900,143.40000,     -0.50147, 94.39666,50.00000,25.00000,2.884445e-10,0.90896,3
223.19099,144.46667,     -0.51178, 94.43674,50.00000,25.00000,2.875595e-10,0.90875,3
224.28000,145.53333,     -0.52073, 94.42338,50.00000,25.00000,2.879237e-10,0.90858,3
225.31599,146.60000,     -0.53037, 94.44990,50.00000,25.00000,2.875385e-10,0.90840,3
226.36700,147.66667,     -0.54145, 94.44322,50.00000,25.00000,2.884865e-10,0.90820,3
227.43800,148.73333,     -0.54851, 94.46994,50.00000,25.00000,2.875138e-10,0.90802,3
228.51300,149.80000,     -0.55700, 94.46994,50.00000,25.00000,2.879715e-10,0.90781,3
229.58299,150.86667,     -0.56745, 94.49666,50.00000,25.00000,2.879696e-10,0.90763,3
230.65100,151.93333,     -0.57598, 94.51670,50.00000,25.00000,2.877159e-10,0.90742,3
231.71400,153.00000,     -0.58611, 94.49666,50.00000,25.00000,2.875958e-10,0.90721,3
232.75800,154.06667,     -0.59609, 94.49666,50.00000,25.00000,2.875520e-10,0.90703,3
233.84500,155.13333,     -0.60681, 94.52338,50.00000,25.00000,2.878704e-10,0.90684,3
234.91200,156.20000,     -0.61560, 94.52338,50.00000,25.00000,2.882996e-10,0.90663,3
235.97099,157.26667,     -0.62547, 94.51670,50.00000,25.00000,2.886104e-10,0.90644,3
237.03600,158.33333,     -0.63696, 94.52338,50.00000,25.00000,2.882786e-10,0.90623,3
238.11099,159.40000,     -0.64653, 94.52338,50.00000,25.00000,2.885627e-10,0.90604,3
239.18201,160.46667,     -0.65844, 94.54342,50.00000,25.00000,2.887078e-10,0.90582,3
240.24300,161.53333,     -0.66912, 94.53006,50.00000,25.00000,2.888527e-10,0.90563,3
241.30499,162.60000,     -0.67946, 94.55010,50.00000,25.00000,2.886810e-10,0.90541,3
242.36700,163.66667,     -0.69090, 94.55010,50.00000,25.00000,2.879104e-10,0.90522,3
243.44000,164.73333,     -0.70113, 94.52338,50.00000,25.00000,2.880745e-10,0.90499,3
244.50301,165.80000,     -0.71316, 94.52338,50.00000,25.00000,2.883625e-10,0.90481,3
245.57201,166.86667,     -0.72218, 94.52102,50.00000,25.00000,2.880630e-10,0.90459,3
246.65199,167.93333,     -0.73410, 94.54774,50.00000,25.00000,2.888355e-10,0.90439,3
247.71001,169.00000,     -0.74621, 94.54106,50.00000,25.00000,2.889633e-10,0.90416,3
248.77100,170.06667,     -0.75619, 94.54106,50.00000,25.00000,2.900085e-10,0.90397,3
249.83501,171.13333,     -0.76710, 94.53438,50.00000,25.00000,2.882633e-10,0.90374,3
250.89999,172.20000,     -0.77965, 94.52770,50.00000,25.00000,2.890472e-10,0.90355,3
251.97099,173.26667,     -0.79171, 94.52770,50.00000,25.00000,2.890968e-10,0.90331,3
253.04201,174.33333,     -0.80198, 94.52102,50.00000,25.00000,2.891503e-10,0.90312,3
254.11200,175.40000,     -0.81318, 94.54106,50.00000,25.00000,2.895642e-10,0.90289,3
255.17599,176.46667,     -0.82585, 94.51434,50.00000,25.00000,2.896576e-10,0.90268,3
256.23901,177.53333,     -0.83729, 94.53438,50.00000,25.00000,2.892437e-10,0.90246,3
257.29800,178.60000,     -0.85002, 94.54106,50.00000,25.00000,2.906456e-10,0.90226,3
258.37100,179.66667,     -0.85988, 94.50786,50.00000,25.00000,2.887307e-10,0.90202,3
259.43500,180.73333,     -0.87322, 94.53438,50.00000,25.00000,2.895413e-10,0.90181,3
260.49600,181.80000,     -0.88549, 94.50786,50.00000,25.00000,2.895508e-10,0.90157,3
261.56699,182.86667,     -0.89507, 94.53438,50.00000,25.00000,2.901115e-10,0.90137,3
262.63400,183.93333,     -0.90850, 94.52770,50.00000,25.00000,2.894478e-10,0.90113,3
263.70099,185.00000,     -0.92033, 94.52102,50.00000,25.00000,2.899284e-10,0.90093,3
264.76199,186.06667,     -0.93510, 94.50786,50.00000,25.00000,2.887364e-10,0.90068,3
265.83701,187.13333,     -0.94681, 94.49450,50.00000,25.00000,2.903806e-10,0.90048,3
266.89899,188.20000,     -0.95798, 94.51434,50.00000,25.00000,2.899895e-10,0.90023,3
267.96701,189.26667,     -0.97176, 94.50786,50.00000,25.00000,2.907543e-10,0.90003,3
269.03601,190.33333,     -0.98539, 94.50786,50.00000,25.00000,2.903481e-10,0.89978,3
270.10300,191.40000,     -0.99666, 94.50786,50.00000,25.00000,2.901688e-10,0.89957,3
271.16901,192.46667,     -1.00851, 94.51434,50.00000,25.00000,2.903442e-10,0.89933,3
272.23300,193.53333,     -1.02261, 94.52102,50.00000,25.00000,2.899361e-10,0.89911,3
273.30099,194.60000,     -1.03489, 94.47446,50.00000,25.00000,2.907372e-10,0.89886,3
274.35999,195.66667,     -1.04535, 94.51434,50.00000,25.00000,2.901783e-10,0.89865,3
275.42599,196.73333,     -1.05973, 94.48782,50.00000,25.00000,2.906514e-10,0.89840,3
276.49701,197.80000,     -1.07360, 94.50786,50.00000,25.00000,2.901840e-10,0.89818,3
277.57300,198.86667,     -1.08843, 94.50118,50.00000,25.00000,2.905006e-10,0.89793,3
278.63101,199.93333,     -1.10273, 94.49450,50.00000,25.00000,2.911720e-10,0.89771,3
279.70200,201.00000,     -1.11503, 94.48782,50.00000,25.00000,2.908267e-10,0.89745,3
280.76801,202.06667,     -1.12997, 94.48114,50.00000,25.00000,2.907791e-10,0.89724,3
281.81000,203.13333,     -1.14435, 94.44990,50.00000,25.00000,2.908058e-10,0.89698,3
282.88199,204.20000,     -1.15545, 94.46994,50.00000,25.00000,2.904988e-10,0.89676,3
283.96399,205.26667,     -1.17032, 94.47878,50.00000,25.00000,2.901153e-10,0.89651,3
285.02200,206.33333,     -1.18502, 94.47878,50.00000,25.00000,2.913476e-10,0.89628,3
286.09399,207.40000,     -1.19622, 94.45894,50.00000,25.00000,2.915611e-10,0.89602,3
287.15601,208.46667,     -1.21080, 94.47230,50.00000,25.00000,2.908307e-10,0.89580,3
288.22900,209.53333,     -1.22394, 94.47230,50.00000,25.00000,2.908460e-10,0.89553,3
289.29401,210.60000,     -1.23823, 94.41886,50.00000,25.00000,2.914524e-10,0.89531,3
290.36401,211.66667,     -1.25144, 94.42554,50.00000,25.00000,2.907256e-10,0.89505,3
291.41901,212.73333,     -1.26730, 94.39882,50.00000,25.00000,2.906838e-10,0.89482,3
292.47900,213.80000,     -1.28245, 94.45226,50.00000,25.00000,2.914086e-10,0.89456,3
293.55399,214.86667,     -1.29747, 94.41218,50.00000,25.00000,2.917117e-10,0.89432,3
294.61801,215.93333,     -1.31025, 94.37210,50.00000,25.00000,2.906438e-10,0.89407,3
295.68701,217.00000,     -1.32344, 94.37210,50.00000,25.00000,2.907295e-10,0.89383,3
296.74701,218.06667,     -1.34008, 94.34558,50.00000,25.00000,2.910462e-10,0.89357,3
297.81699,219.13333,     -1.35392, 94.34558,50.00000,25.00000,2.917462e-10,0.89333,3
298.88699,220.20000,     -1.36875, 94.31218,50.00000,25.00000,2.914562e-10,0.89307,3
299.95499,221.26667,     -1.38190, 94.28546,50.00000,25.00000,2.917976e-10,0.89283,3
301.01099,222.33333,     -1.39584, 94.28546,50.00000,25.00000,2.919635e-10,0.89256,3
302.08200,223.40000,     -1.41059, 94.25874,50.00000,25.00000,2.915688e-10,0.89233,3
303.14600,224.46667,     -1.42748, 94.19214,50.00000,25.00000,2.914620e-10,0.89206,3
304.20801,225.53333,     -1.44326, 94.19882,50.00000,25.00000,2.918911e-10,0.89182,3
305.27399,226.60000,     -1.45564, 94.16542,50.00000,25.00000,2.906666e-10,0.89154,3
306.34698,227.66667,     -1.47229, 94.13890,50.00000,25.00000,2.918701e-10,0.89131,3
307.41599,228.73333,     -1.49089, 94.11218,50.00000,25.00000,2.921010e-10,0.89107,3
308.47699,229.80000,     -1.50434, 94.07210,50.00000,25.00000,2.924385e-10,0.89079,3
309.54800,230.86667,     -1.51939, 94.00550,50.00000,25.00000,2.924175e-10,0.89056,3
310.62399,231.93333,     -1.53486, 93.96542,50.00000,25.00000,2.922478e-10,0.89027,3
311.69000,233.00000,     -1.55075, 93.91218,50.00000,25.00000,2.919350e-10,0.89003,3
312.75601,234.06667,     -1.56746, 93.86542,50.00000,25.00000,2.915497e-10,0.88975,3
313.82300,235.13333,     -1.58208, 93.79882,50.00000,25.00000,2.921295e-10,0.88947,3
314.89001,236.20000,     -1.60023, 93.73202,50.00000,25.00000,2.916260e-10,0.88923,3
315.96399,237.26667,     -1.61456, 93.67878,50.00000,25.00000,2.923755e-10,0.88895,3
317.02301,238.33333,     -1.63318, 93.59194,50.00000,25.00000,2.924176e-10,0.88871,3
318.10901,239.40000,     -1.64820, 93.54538,50.00000,25.00000,2.924576e-10,0.88842,3
319.17401,240.46667,     -1.66225, 93.46542,50.00000,25.00000,2.924787e-10,0.88818,3
320.22400,241.53333,     -1.68138, 93.38527,50.00000,25.00000,2.925052e-10,0.88789,3
321.28900,242.60000,     -1.69551, 93.27426,50.00000,25.00000,2.925414e-10,0.88765,3
322.36200,243.66667,     -1.71302, 93.20530,50.00000,25.00000,2.922496e-10,0.88736,3
323.42099,244.73333,     -1.72879, 93.09862,50.00000,25.00000,2.920247e-10,0.88711,3
324.49701,245.80000,     -1.74464, 92.99194,50.00000,25.00000,2.920227e-10,0.88682,3
325.55899,246.86667,     -1.76108, 92.88527,50.00000,25.00000,2.921238e-10,0.88656,3
326.61899,247.93333,     -1.77698, 92.75187,50.00000,25.00000,2.922992e-10,0.88627,3
327.68100,249.00000,     -1.78446, 92.61847,50.00000,25.00000,2.934646e-10,0.88602,3
328.76199,250.06667,     -1.80108, 92.53851,50.00000,25.00000,2.932396e-10,0.88573,3
329.81900,251.13333,     -1.81689, 92.40511,50.00000,25.00000,2.919464e-10,0.88548,3
330.89401,252.20000,     -1.83180, 92.24519,50.00000,25.00000,2.931709e-10,0.88518,3
331.96399,253.26667,     -1.84991, 92.05835,50.00000,25.00000,2.929268e-10,0.88493,3
333.01599,254.33333,     -1.86743, 91.91611,50.00000,25.00000,2.928372e-10,0.88462,3
334.09000,255.40000,     -1.88207, 91.74047,50.00000,25.00000,2.932128e-10,0.88438,3
335.15701,256.46667,     -1.89912, 91.51375,50.00000,25.00000,2.937164e-10,0.88408,3
336.22198,257.53333,     -1.91323, 91.35383,50.00000,25.00000,2.936688e-10,0.88382,3
337.28799,258.60000,     -1.93057, 91.08703,50.00000,25.00000,2.930680e-10,0.88353,3
338.36401,259.66667,     -1.94678, 90.87367,50.00000,25.00000,2.917137e-10,0.88326,3
339.42401,260.73333,     -1.96400, 90.63360,50.00000,25.00000,2.933255e-10,0.88296,3
340.47699,261.80000,     -1.98064, 90.38703,50.00000,25.00000,2.928562e-10,0.88270,3
341.55399,262.86667,     -1.99599, 90.05796,50.00000,25.00000,2.937393e-10,0.88240,3
342.61301,263.93333,     -2.00893, 89.73576,50.00000,25.00000,2.931442e-10,0.88214,3
343.69501,265.00000,     -2.02779, 89.35344,50.00000,25.00000,2.935715e-10,0.88184,3
344.75601,266.06667,     -2.04785, 88.95108,50.00000,25.00000,2.934513e-10,0.88158,3
345.81201,267.13333,     -2.05849, 88.51552,50.00000,25.00000,2.935562e-10,0.88127,3
346.86700,268.20000,     -2.07520, 88.08428,50.00000,25.00000,2.933941e-10,0.88101,3
347.94299,269.26667,     -2.08798, 87.62417,50.00000,25.00000,2.939491e-10,0.88069,3
349.01001,270.33333,     -2.09995, 87.07073,50.00000,25.00000,2.932490e-10,0.88044,3
350.08899,271.40000,     -2.11098, 86.46837,50.00000,25.00000,2.930355e-10,0.88013,3
351.14301,272.46667,     -2.12198, 85.83929,50.00000,25.00000,2.936343e-10,0.87986,3
352.21899,273.53333,     -2.13407, 85.10138,50.00000,25.00000,2.937336e-10,0.87960,3
353.28400,274.60000,     -2.14271, 84.31454,50.00000,25.00000,2.944069e-10,0.87928,3
354.34399,275.66667,     -2.10267, 83.54774,50.00000,25.00000,2.932968e-10,0.87902,3
355.41101,276.73333,     -2.09375, 82.58310,50.00000,25.00000,2.937546e-10,0.87870,3
356.49701,277.80000,     -2.10263, 81.45855,50.00000,25.00000,2.940235e-10,0.87843,3
357.54700,278.86667,     -2.12126, 80.32927,50.00000,25.00000,2.932873e-10,0.87812,3
358.61700,279.93333,     -2.13487, 79.11356,50.00000,25.00000,2.940597e-10,0.87784,3
359.67099,281.00000,     -2.14006, 77.77328,50.00000,25.00000,2.939758e-10,0.87753,3
360.73401,282.06667,     -2.15392, 76.34853,50.00000,25.00000,2.942200e-10,0.87726,3
361.81601,283.13333,     -2.16191, 74.79273,50.00000,25.00000,2.941589e-10,0.87695,3
362.88699,284.20000,     -2.12826, 73.22358,50.00000,25.00000,2.939148e-10,0.87667,3
363.94800,285.26667,     -2.13762, 71.41866,50.00000,25.00000,2.938746e-10,0.87635,3
365.00900,286.33333,     -2.13584, 69.47603,50.00000,25.00000,2.944354e-10,0.87608,3
366.07401,287.40000,     -2.14793, 67.34460,50.00000,25.00000,2.936935e-10,0.87576,3
367.13400,288.46667,     -2.16294, 65.13969,50.00000,25.00000,2.943211e-10,0.87548,3
368.21899,289.53333,     -2.18075, 62.82574,50.00000,25.00000,2.943230e-10,0.87521,3
369.27600,290.60000,     -2.18732, 60.40314,50.00000,25.00000,2.944355e-10,0.87488,3
370.33801,291.66667,     -2.19954, 57.73595,50.00000,25.00000,2.943268e-10,0.87461,3
371.38699,292.73333,     -2.21904, 54.96876,50.00000,25.00000,2.943421e-10,0.87429,3
372.46301,293.80000,     -2.22469, 52.06149,50.00000,25.00000,2.944927e-10,0.87400,3
373.54199,294.86667,     -2.24458, 49.05639,50.00000,25.00000,2.947349e-10,0.87368,3
374.60199,295.93333,     -2.27095, 45.93576,50.00000,25.00000,2.942924e-10,0.87340,3
375.66699,297.00000,     -2.28798, 42.71513,50.00000,25.00000,2.950630e-10,0.87307,3
376.73999,298.06667,     -2.32543, 39.47662,50.00000,25.00000,2.947941e-10,0.87278,3
377.80301,299.13333,     -2.36085, 36.23595,50.00000,25.00000,2.949390e-10,0.87245,3
378.87799,300.20000,     -2.40041, 33.01984,50.00000,25.00000,2.873439e-10,0.87218,3
379.95999,301.26667,     -2.42198, 29.80589,50.00000,25.00000,2.875824e-10,0.87184,3
381.01001,302.33333,     -2.46883, 26.72515,50.00000,25.00000,2.862663e-10,0.87156,3
382.08200,303.40000,     -2.51926, 23.68468,50.00000,25.00000,2.858334e-10,0.87123,3
383.14700,304.46667,     -2.57763, 20.89077,50.00000,25.00000,2.867546e-10,0.87095,3
384.21399,305.53333,     -2.63279, 18.19686,50.00000,25.00000,2.856674e-10,0.87062,3
385.28101,306.60000,     -2.69404, 15.69194,50.00000,25.00000,2.866001e-10,0.87031,3
386.35501,307.66667,     -2.75081, 13.45147,50.00000,25.00000,2.868214e-10,0.87000,3
387.41101,308.73333,     -2.81512, 11.41100,50.00000,25.00000,2.868767e-10,0.86970,3
388.47400,309.80000,     -2.87176,  9.61729,50.00000,25.00000,2.863560e-10,0.86938,3
389.55200,310.86667,     -2.92818,  8.05933,50.00000,25.00000,2.869282e-10,0.86907,3
390.61200,311.93333,     -2.97977,  6.74126,50.00000,25.00000,2.857455e-10,0.86875,3
391.67700,313.00000,     -3.03195,  5.59882,50.00000,25.00000,2.868556e-10,0.86846,3
392.75400,314.06667,     -3.07704,  4.61847,50.00000,25.00000,2.873478e-10,0.86812,3
393.82300,315.13333,     -3.12351,  3.82063,50.00000,25.00000,2.871437e-10,0.86783,3
394.88300,316.20000,     -3.16621,  3.16719,50.00000,25.00000,2.873287e-10,0.86748,3
395.95300,317.26667,     -3.20217,  2.59587,50.00000,25.00000,2.870959e-10,0.86720,3
397.01901,318.33333,     -3.24253,  2.13143,50.00000,25.00000,2.871552e-10,0.86686,3
398.08301,319.40000,     -3.27780,  1.75580,50.00000,25.00000,2.875500e-10,0.86656,3
399.14001,320.46667,     -3.31141,  1.43340,50.00000,25.00000,2.875252e-10,0.86627,3
399.64700,320.97833,     -3.32902,  1.30020,50.00000,25.00000,2.872296e-10,0.86608,4
399.76999,321.05833,     -3.33606,  1.27348,50.00000,25.00000,2.872296e-10,0.86608,4
399.98300,321.13833,     -3.29503,  1.27348,50.00000,25.00000,2.871132e-10,0.86603,4
400.32300,321.21833,     -3.18697,  1.27348,50.00000,25.00000,2.871132e-10,0.86603,4
400.79401,321.29833,     -3.01133,  1.33792,50.00000,25.00000,2.866687e-10,0.86598,4
401.43600,321.37833,     -2.76043,  1.39568,50.00000,25.00000,2.866687e-10,0.86598,4
402.25299,321.45833,     -2.44695,  1.48684,50.00000,25.00000,2.866687e-10,0.86598,4
403.23599,321.53833,     -2.08304,  1.58684,50.00000,25.00000,2.863940e-10,0.86593,4
404.37100,321.61833,     -1.68260,  1.70020,50.00000,25.00000,2.863940e-10,0.86593,4
405.64001,321.69833,     -1.26961,  1.82240,50.00000,25.00000,2.860183e-10,0.86588,4
407.02301,321.77833,     -0.85118,  1.88251,50.00000,25.00000,2.860183e-10,0.86588,4
408.51501,321.85833,     -0.44834,  1.93792,50.00000,25.00000,2.871283e-10,0.86583,4
410.07199,321.93833,-7.634161e-02,  2.01807,50.00000,25.00000,2.871283e-10,0.86583,4
411.66199,322.01833,      0.25699,  2.09136,50.00000,25.00000,2.872371e-10,0.86578,4
413.28000,322.09833,      0.53846,  2.12475,50.00000,25.00000,2.872371e-10,0.86578,4
414.89401,322.17833,      0.76794,  2.17132,50.00000,25.00000,2.871570e-10,0.86574,4
416.50000,322.25833,      0.94064,  2.17132,50.00000,25.00000,2.871570e-10,0.86574,4
418.06799,322.33833,      1.05816,  2.18468,50.00000,25.00000,2.877101e-10,0.86568,4
419.62299,322.41833,      1.12437,  2.18468,50.00000,25.00000,2.877101e-10,0.86568,4
421.13501,322.49833,      1.14625,  2.15815,50.00000,25.00000,2.863216e-10,0.86564,4
422.58801,322.57833,      1.13488,  2.15147,50.00000,25.00000,2.863216e-10,0.86564,4
424.02200,322.65833,      1.09013,  2.10472,50.00000,25.00000,2.872754e-10,0.86559,4
425.42899,322.73833,      1.02389,  2.07800,50.00000,25.00000,2.872754e-10,0.86559,4
426.78400,322.81833,      0.94611,  2.07132,50.00000,25.00000,2.865315e-10,0.86554,4
428.13300,322.89833,      0.86489,  2.02475,50.00000,25.00000,2.865315e-10,0.86554,4
429.46701,322.97833,      0.78493,  1.99804,50.00000,25.00000,2.866287e-10,0.86548,4
430.80499,323.05833,      0.71145,  1.94460,50.00000,25.00000,2.866287e-10,0.86548,4
432.14700,323.13833,      0.64992,  1.91572,50.00000,25.00000,2.874813e-10,0.86544,4
433.49600,323.21833,      0.60491,  1.88919,50.00000,25.00000,2.874813e-10,0.86544,4
434.86499,323.29833,      0.57699,  1.88919,50.00000,25.00000,2.864227e-10,0.86539,4
436.26501,323.37833,      0.56603,  1.88919,50.00000,25.00000,2.864227e-10,0.86539,4
437.67700,323.45833,      0.57143,  1.86248,50.00000,25.00000,2.874012e-10,0.86535,4
439.12500,323.53833,      0.59627,  1.83576,50.00000,25.00000,2.874012e-10,0.86535,4
440.61200,323.61833,      0.63288,  1.86248,50.00000,25.00000,2.869568e-10,0.86529,4
442.12601,323.69833,      0.68135,  1.83576,50.00000,25.00000,2.869568e-10,0.86529,4
443.66901,323.77833,      0.73462,  1.83576,50.00000,25.00000,2.864933e-10,0.86524,4
445.22699,323.85833,      0.79388,  1.83576,50.00000,25.00000,2.864933e-10,0.86524,4
446.82199,323.93833,      0.85527,  1.86248,50.00000,25.00000,2.849789e-10,0.86520,4
448.44199,324.01833,      0.91625,  1.83576,50.00000,25.00000,2.849789e-10,0.86520,4
450.06400,324.09833,      0.96893,  1.83576,50.00000,25.00000,2.764950e-10,0.86514,4
451.70901,324.17833,      1.01908,  1.83576,50.00000,25.00000,2.764950e-10,0.86514,4
453.36200,324.25833,      1.06341,  1.80904,50.00000,25.00000,2.759571e-10,0.86509,4
455.00299,324.33833,      1.09580,  1.80904,50.00000,25.00000,2.759571e-10,0.86509,4
456.66800,324.41833,      1.12182,  1.80904,50.00000,25.00000,2.757417e-10,0.86505,4
458.33801,324.49833,      1.13531,  1.80236,50.00000,25.00000,2.757417e-10,0.86505,4
459.99701,324.57833,      1.14298,  1.80236,50.00000,25.00000,2.757417e-10,0.86505,4
461.65201,324.65833,      1.14150,  1.80236,50.00000,25.00000,2.757568e-10,0.86499,4
463.30301,324.73833,      1.13057,  1.78251,50.00000,25.00000,2.757568e-10,0.86499,4
464.95999,324.81833,      1.11842,  1.78251,50.00000,25.00000,2.765750e-10,0.86495,4
466.60699,324.89833,      1.09909,  1.78251,50.00000,25.00000,2.765750e-10,0.86495,4
468.26401,324.97833,      1.07684,  1.78251,50.00000,25.00000,2.762204e-10,0.86489,4
469.92700,325.05833,      1.05211,  1.78251,50.00000,25.00000,2.762204e-10,0.86489,4
471.57101,325.13833,      1.02272,  1.80904,50.00000,25.00000,2.766819e-10,0.86485,4
473.23199,325.21833,      0.99489,  1.78251,50.00000,25.00000,2.766819e-10,0.86485,4
474.87799,325.29833,      0.96929,  1.80904,50.00000,25.00000,2.754993e-10,0.86480,4
476.54300,325.37833,      0.94385,  1.80904,50.00000,25.00000,2.754993e-10,0.86480,4
478.20001,325.45833,      0.91563,  1.86248,50.00000,25.00000,2.760925e-10,0.86475,4
479.85501,325.53833,      0.89306,  1.86248,50.00000,25.00000,2.760925e-10,0.86475,4
481.52200,325.61833,      0.86798,  1.86248,50.00000,25.00000,2.755624e-10,0.86470,4
483.19800,325.69833,      0.84643,  1.88251,50.00000,25.00000,2.755624e-10,0.86470,4
484.85999,325.77833,      0.82379,  1.91572,50.00000,25.00000,2.756958e-10,0.86464,4
486.52701,325.85833,      0.80372,  1.94244,50.00000,25.00000,2.756958e-10,0.86464,4
488.21100,325.93833,      0.78284,  1.94244,50.00000,25.00000,2.750798e-10,0.86461,4
489.87399,326.01833,      0.76160,  1.96916,50.00000,25.00000,2.750798e-10,0.86461,4
491.56900,326.09833,      0.74054,  1.97583,50.00000,25.00000,2.757111e-10,0.86456,4
493.24799,326.17833,      0.72133,  2.00255,50.00000,25.00000,2.757111e-10,0.86456,4
494.92099,326.25833,      0.69588,  2.02240,50.00000,25.00000,2.752132e-10,0.86452,4
496.60901,326.33833,      0.67402,  2.04912,50.00000,25.00000,2.752132e-10,0.86452,4
498.29700,326.41833,      0.65255,  2.08035,50.00000,25.00000,2.755737e-10,0.86446,4
499.97699,326.49833,      0.62628,  2.08035,50.00000,25.00000,2.755737e-10,0.86446,4
501.66000,326.57833,      0.59667,  2.10020,50.00000,25.00000,2.757338e-10,0.86441,4
503.34000,326.65833,      0.56668,  2.13360,50.00000,25.00000,2.757338e-10,0.86441,4
505.05600,326.73833,      0.53683,  2.15363,50.00000,25.00000,2.753677e-10,0.86435,4
506.70200,326.81833,      0.51103,  2.16031,50.00000,25.00000,2.753677e-10,0.86435,4
508.38199,326.89833,      0.47590,  2.16031,50.00000,25.00000,2.753677e-10,0.86435,4
510.06400,326.97833,      0.44463,  2.21356,50.00000,25.00000,2.754668e-10,0.86430,4
511.74600,327.05833,      0.41196,  2.21356,50.00000,25.00000,2.754668e-10,0.86430,4
513.42297,327.13833,      0.37361,  2.21356,50.00000,25.00000,2.757759e-10,0.86426,4
515.08801,327.21833,      0.33560,  2.24028,50.00000,25.00000,2.757759e-10,0.86426,4
516.76898,327.29833,      0.29843,  2.26699,50.00000,25.00000,2.751541e-10,0.86421,4
518.44501,327.37833,      0.25782,  2.26699,50.00000,25.00000,2.751541e-10,0.86421,4
520.11603,327.45833,      0.22058,  2.29371,50.00000,25.00000,2.753525e-10,0.86416,4
521.79602,327.53833,      0.18548,  2.29371,50.00000,25.00000,2.753525e-10,0.86416,4
523.45898,327.61833,      0.15404,  2.29371,50.00000,25.00000,2.753411e-10,0.86411,4
525.13501,327.69833,      0.11941,  2.32024,50.00000,25.00000,2.753411e-10,0.86411,4
526.79700,327.77833, 8.309161e-02,  2.32024,50.00000,25.00000,2.752152e-10,0.86406,4
528.47498,327.85833, 5.072738e-02,  2.34695,50.00000,25.00000,2.752152e-10,0.86406,4
530.13898,327.93833, 1.206615e-02,  2.36699,50.00000,25.00000,2.744618e-10,0.86401,4
531.81299,328.01833,-2.521123e-02,  2.37367,50.00000,25.00000,2.744618e-10,0.86401,4
533.47900,328.09833,-6.032182e-02,  2.40039,50.00000,25.00000,2.757225e-10,0.86396,4
535.14502,328.17833,-9.841740e-02,  2.42692,50.00000,25.00000,2.757225e-10,0.86396,4
536.81097,328.25833,     -0.13486,  2.42692,50.00000,25.00000,2.755242e-10,0.86391,4
538.48199,328.33833,     -0.16807,  2.45363,50.00000,25.00000,2.755242e-10,0.86391,4
540.13702,328.41833,     -0.20220,  2.48035,50.00000,25.00000,2.755509e-10,0.86386,4
541.80701,328.49833,     -0.23985,  2.48035,50.00000,25.00000,2.755509e-10,0.86386,4
543.46899,328.57833,     -0.27660,  2.49371,50.00000,25.00000,2.749939e-10,0.86380,4
545.13501,328.65833,     -0.31900,  2.51375,50.00000,25.00000,2.749939e-10,0.86380,4
546.79199,328.73833,     -0.35815,  2.53360,50.00000,25.00000,2.755432e-10,0.86376,4
548.44702,328.81833,     -0.39798,  2.56031,50.00000,25.00000,2.755432e-10,0.86376,4
550.10797,328.89833,     -0.44033,  2.56031,50.00000,25.00000,2.753830e-10,0.86371,4
551.76801,328.97833,     -0.47837,  2.56031,50.00000,25.00000,2.753830e-10,0.86371,4
553.42798,329.05833,     -0.51761,  2.59371,50.00000,25.00000,2.750206e-10,0.86367,4
555.08099,329.13833,     -0.55382,  2.61375,50.00000,25.00000,2.750206e-10,0.86367,4
556.73999,329.21833,     -0.59230,  2.61375,50.00000,25.00000,2.750740e-10,0.86362,4
558.38397,329.29833,     -0.63091,  2.64047,50.00000,25.00000,2.750740e-10,0.86362,4
560.04199,329.37833,     -0.66967,  2.66699,50.00000,25.00000,2.756729e-10,0.86356,4
561.69598,329.45833,     -0.70965,  2.66699,50.00000,25.00000,2.756729e-10,0.86356,4
563.35101,329.53833,     -0.74844,  2.69371,50.00000,25.00000,2.758960e-10,0.86351,4
565.00800,329.61833,     -0.78871,  2.72043,50.00000,25.00000,2.758960e-10,0.86351,4
566.66101,329.69833,     -0.82725,  2.72043,50.00000,25.00000,2.758960e-10,0.86351,4
568.30499,329.77833,     -0.86968,  2.74715,50.00000,25.00000,2.753431e-10,0.86344,4
569.98602,329.85833,     -0.91043,  2.74715,50.00000,25.00000,2.753431e-10,0.86344,4
571.61700,329.93833,     -0.95180,  2.74715,50.00000,25.00000,2.750740e-10,0.86342,4
573.25000,330.01833,     -0.98901,  2.77367,50.00000,25.00000,2.750740e-10,0.86342,4
574.89600,330.09833,     -1.03259,  2.80039,50.00000,25.00000,2.756862e-10,0.86337,4
576.54102,330.17833,     -1.07306,  2.81375,50.00000,25.00000,2.756862e-10,0.86337,4
578.20898,330.25833,     -1.11453,  2.82711,50.00000,24.00000,2.748451e-10,0.86332,4
579.83801,330.33833,     -1.15827,  2.82711,50.00000,25.00000,2.748451e-10,0.86332,4
581.49402,330.41833,     -1.20056,  2.85599,50.00000,25.00000,2.753964e-10,0.86327,4
583.13397,330.49833,     -1.24407,  2.88271,50.00000,25.00000,2.753964e-10,0.86327,4
584.78003,330.57833,     -1.28172,  2.88271,50.00000,25.00000,2.750396e-10,0.86323,4
586.42603,330.65833,     -1.32416,  2.90255,50.00000,25.00000,2.750396e-10,0.86323,4
588.07001,330.73833,     -1.36839,  2.90923,50.00000,25.00000,2.760830e-10,0.86317,4
589.70599,330.81833,     -1.41276,  2.93595,50.00000,25.00000,2.760830e-10,0.86317,4
591.34698,330.89833,     -1.45535,  2.93595,50.00000,25.00000,2.757167e-10,0.86312,4
592.99298,330.97833,     -1.50363,  2.96267,50.00000,24.00000,2.757167e-10,0.86312,4
594.63098,331.05833,     -1.54541,  2.94263,50.00000,25.00000,2.754669e-10,0.86307,4
596.26501,331.13833,     -1.59148,  2.96935,50.00000,25.00000,2.754669e-10,0.86307,4
597.90503,331.21833,     -1.63744,  3.01591,50.00000,25.00000,2.750016e-10,0.86303,4
599.54303,331.29833,     -1.68131,  2.99607,50.00000,25.00000,2.750016e-10,0.86303,4
601.18402,331.37833,     -1.72590,  3.02259,50.00000,25.00000,2.760620e-10,0.86298,4
602.81897,331.45833,     -1.77257,  3.04931,50.00000,25.00000,2.760620e-10,0.86298,4
604.45898,331.53833,     -1.81857,  3.04931,50.00000,25.00000,2.748928e-10,0.86292,4
606.08398,331.61833,     -1.86356,  3.07603,50.00000,25.00000,2.748928e-10,0.86292,4
607.72601,331.69833,     -1.90845,  3.10275,50.00000,25.00000,2.755413e-10,0.86287,4
609.35101,331.77833,     -1.95233,  3.10275,50.00000,25.00000,2.755413e-10,0.86287,4
610.98102,331.85833,     -2.00001,  3.11611,50.00000,24.00000,2.751046e-10,0.86282,4
612.61603,331.93833,     -2.04532,  3.11611,50.00000,25.00000,2.751046e-10,0.86282,4
614.26001,332.01833,     -2.08682,  3.11611,50.00000,25.00000,2.752418e-10,0.86276,4
615.88702,332.09833,     -2.13579,  3.11611,50.00000,25.00000,2.752418e-10,0.86276,4
617.52100,332.17833,     -2.18265,  3.12927,50.00000,25.00000,2.751236e-10,0.86271,4
619.15900,332.25833,     -2.22852,  3.15835,50.00000,24.00000,2.751236e-10,0.86271,4
620.78497,332.33833,     -2.27651,  3.18487,50.00000,24.00000,2.751236e-10,0.86271,4
622.41699,332.41833,     -2.32380,  3.18487,50.00000,25.00000,2.755374e-10,0.86267,4
624.04797,332.49833,     -2.37123,  3.18487,50.00000,25.00000,2.755374e-10,0.86267,4
625.66803,332.57833,     -2.42249,  3.21159,50.00000,25.00000,2.755756e-10,0.86262,4
627.29498,332.65833,     -2.46963,  3.23831,50.00000,25.00000,2.755756e-10,0.86262,4
628.92700,332.73833,     -2.52296,  3.23831,50.00000,25.00000,2.751103e-10,0.86257,4
630.55603,332.81833,     -2.57125,  3.26503,50.00000,25.00000,2.751103e-10,0.86257,4
632.18500,332.89833,     -2.62085,  3.26503,50.00000,25.00000,2.754745e-10,0.86252,4
633.80798,332.97833,     -2.67432,  3.29155,50.00000,25.00000,2.754745e-10,0.86252,4
635.43500,333.05833,     -2.71900,  3.29155,50.00000,25.00000,2.757473e-10,0.86246,4
637.06097,333.13833,     -2.77047,  3.32495,50.00000,25.00000,2.757473e-10,0.86246,4
638.68103,333.21833,     -2.81917,  3.34499,50.00000,25.00000,2.746297e-10,0.86242,4
640.30798,333.29833,     -2.86919,  3.34499,50.00000,25.00000,2.746297e-10,0.86242,4
641.93799,333.37833,     -2.91733,  3.37171,50.00000,24.00000,2.754326e-10,0.86237,4
643.56000,333.45833,     -2.96121,  3.37171,50.00000,24.00000,2.754326e-10,0.86237,4
645.18402,333.53833,     -3.01164,  3.37171,50.00000,24.00000,2.751522e-10,0.86231,4
646.80499,333.61833,     -3.06279,  3.37171,50.00000,24.00000,2.751522e-10,0.86231,4
648.42902,333.69833,     -3.11175,  3.39823,50.00000,24.00000,2.758846e-10,0.86227,4
650.06403,333.77833,     -3.15912,  3.39823,50.00000,24.00000,2.758846e-10,0.86227,4
651.66998,333.85833,     -3.20770,  3.42495,50.00000,24.00000,2.750359e-10,0.86222,4
653.29797,333.93833,     -3.25914,  3.45167,50.00000,24.00000,2.750359e-10,0.86222,4
654.91199,334.01833,     -3.31127,  3.45167,50.00000,24.00000,2.761516e-10,0.86217,4
656.53497,334.09833,     -3.36446,  3.47171,50.00000,24.00000,2.761516e-10,0.86217,4
658.15503,334.17833,     -3.40831,  3.47839,50.00000,24.00000,2.753563e-10,0.86212,4
659.77899,334.25833,     -3.46030,  3.50491,50.00000,25.00000,2.753563e-10,0.86212,4
661.39899,334.33833,     -3.49935,  3.50491,50.00000,24.00000,2.749405e-10,0.86206,4
663.01599,334.41833,     -3.54385,  3.50491,50.00000,24.00000,2.749405e-10,0.86206,4
664.64001,334.49833,     -3.58968,  3.51159,50.00000,24.00000,2.759629e-10,0.86201,4
666.26599,334.57833,     -3.63623,  3.53163,50.00000,25.00000,2.759629e-10,0.86201,4
667.88098,334.65833,     -3.68884,  3.53163,50.00000,25.00000,2.755127e-10,0.86196,4
669.50598,334.73833,     -3.73445,  3.55835,50.00000,25.00000,2.755127e-10,0.86196,4
671.12299,334.81833,     -3.78614,  3.57839,50.00000,25.00000,2.751293e-10,0.86192,4
672.74902,334.89833,     -3.83260,  3.61159,50.00000,25.00000,2.751293e-10,0.86192,4
674.36603,334.97833,     -3.87554,  3.61159,50.00000,25.00000,2.758027e-10,0.86186,4
675.99298,335.05833,     -3.92495,  3.63831,50.00000,24.00000,2.758027e-10,0.86186,4
677.61499,335.13833,     -3.97688,  3.63831,50.00000,25.00000,2.755108e-10,0.86181,4
679.21899,335.21833,     -4.03763,  3.63831,50.00000,24.00000,2.755108e-10,0.86181,4
680.84399,335.29833,     -4.09077,  3.65835,50.00000,24.00000,2.751464e-10,0.86176,4
682.46399,335.37833,     -4.13615,  3.65835,50.00000,24.00000,2.751464e-10,0.86176,4
684.08002,335.45833,     -4.18254,  3.65835,50.00000,24.00000,2.744960e-10,0.86171,4
685.69897,335.53833,     -4.23209,  3.65835,50.00000,24.00000,2.744960e-10,0.86171,4
687.31097,335.61833,     -4.29240,  3.67171,50.00000,24.00000,2.752152e-10,0.86167,4
688.93103,335.69833,     -4.34193,  3.69175,50.00000,24.00000,2.752152e-10,0.86167,4
690.55298,335.77833,     -4.39128,  3.69175,50.00000,24.00000,2.747841e-10,0.86161,4
692.16400,335.85833,     -4.44377,  3.73163,50.00000,24.00000,2.747841e-10,0.86161,4
693.78302,335.93833,     -4.48602,  3.74499,50.00000,24.00000,2.756461e-10,0.86156,4
695.41101,336.01833,     -4.53025,  3.74499,50.00000,24.00000,2.756461e-10,0.86156,4
697.02100,336.09833,     -4.57114,  3.76503,50.00000,24.00000,2.763863e-10,0.86151,4
698.64398,336.17833,     -4.61802,  3.76503,50.00000,24.00000,2.763863e-10,0.86151,4
700.26599,336.25833,     -4.66409,  3.77171,50.00000,24.00000,2.748031e-10,0.86146,4
701.88898,336.33833,     -4.70905,  3.79843,50.00000,24.00000,2.748031e-10,0.86146,4
703.50000,336.41833,     -4.75653,  3.79843,50.00000,24.00000,2.752362e-10,0.86141,4
705.11298,336.49833,     -4.80507,  3.82515,50.00000,24.00000,2.752362e-10,0.86141,4
706.73798,336.57833,     -4.85224,  3.82515,50.00000,24.00000,2.752362e-10,0.86141,4
708.34900,336.65833,     -4.89511,  3.85167,50.00000,24.00000,2.752285e-10,0.86137,4
709.97198,336.73833,     -4.93876,  3.85167,50.00000,24.00000,2.752285e-10,0.86137,4
711.58301,336.81833,     -4.98185,  3.87171,50.00000,24.00000,2.751828e-10,0.86131,4
713.18799,336.89833,     -5.02625,  3.87839,50.00000,24.00000,2.751828e-10,0.86131,4
714.82098,336.97833,     -5.06590,  3.89843,50.00000,24.00000,2.753315e-10,0.86126,4
716.43701,337.05833,     -5.11213,  3.90511,50.00000,24.00000,2.753315e-10,0.86126,4
718.06097,337.13833,     -5.16164,  3.90511,50.00000,24.00000,2.754098e-10,0.86121,4
719.66901,337.21833,     -5.21653,  3.90511,50.00000,24.00000,2.754098e-10,0.86121,4
721.29102,337.29833,     -5.26911,  3.93183,50.00000,24.00000,2.757644e-10,0.86117,4
722.90198,337.37833,     -5.31423,  3.93183,50.00000,25.00000,2.757644e-10,0.86117,4
724.52197,337.45833,     -5.35572,  3.94499,50.00000,24.00000,2.746715e-10,0.86111,4
726.13898,337.53833,     -5.40234,  3.95167,50.00000,24.00000,2.746715e-10,0.86111,4
727.75897,337.61833,     -5.44024,  3.97839,50.00000,24.00000,2.744770e-10,0.86107,4
729.37500,337.69833,     -5.48581,  3.97839,50.00000,24.00000,2.744770e-10,0.86107,4
730.97601,337.77833,     -5.52381,  3.97839,50.00000,25.00000,2.750453e-10,0.86102,4
732.60498,337.85833,     -5.56490,  3.98507,50.00000,24.00000,2.750453e-10,0.86102,4
734.21899,337.93833,     -5.61205,  4.01179,50.00000,24.00000,2.755508e-10,0.86096,4
735.82800,338.01833,     -5.65515,  4.03851,50.00000,24.00000,2.755508e-10,0.86096,4
737.45099,338.09833,     -5.69715,  4.03851,50.00000,24.00000,2.761021e-10,0.86091,4
739.06500,338.17833,     -5.73953,  4.06503,50.00000,24.00000,2.761021e-10,0.86091,4
740.66901,338.25833,     -5.78835,  4.06503,50.00000,24.00000,2.750149e-10,0.86087,4
742.29797,338.33833,     -5.83455,  4.09175,50.00000,24.00000,2.750149e-10,0.86087,4
743.91602,338.41833,     -5.88465,  4.09175,50.00000,24.00000,2.753754e-10,0.86081,4
745.53302,338.49833,     -5.92781,  4.09175,50.00000,24.00000,2.753754e-10,0.86081,4
747.14099,338.57833,     -5.97681,  4.11847,50.00000,24.00000,2.755565e-10,0.86076,4
748.75800,338.65833,     -6.02566,  4.13851,50.00000,24.00000,2.755565e-10,0.86076,4
750.36798,338.73833,     -6.06848,  4.14519,50.00000,24.00000,2.756367e-10,0.86072,4
751.97699,338.81833,     -6.11204,  4.17171,50.00000,24.00000,2.756367e-10,0.86072,4
753.59100,338.89833,     -6.16059,  4.17171,50.00000,24.00000,2.760124e-10,0.86066,4
755.21100,338.97833,     -6.20152,  4.17171,50.00000,24.00000,2.760124e-10,0.86066,4
756.82001,339.05833,     -6.25222,  4.19843,50.00000,24.00000,2.756615e-10,0.86061,4
758.44202,339.13833,     -6.28949,  4.22515,50.00000,24.00000,2.756615e-10,0.86061,4
760.05200,339.21833,     -6.33784,  4.22515,50.00000,24.00000,2.758789e-10,0.86056,4
761.66998,339.29833,     -6.37496,  4.22515,50.00000,24.00000,2.758789e-10,0.86056,4
763.27399,339.37833,     -6.41112,  4.22515,50.00000,24.00000,2.755967e-10,0.86051,4
764.90100,339.45833,     -6.46023,  4.22515,50.00000,24.00000,2.755967e-10,0.86051,4
766.50702,339.53833,     -6.50771,  4.25187,50.00000,24.00000,2.755967e-10,0.86051,4
768.12299,339.61833,     -6.56226,  4.27839,50.00000,24.00000,2.759685e-10,0.86046,4
769.72998,339.69833,     -6.61099,  4.27839,50.00000,24.00000,2.759685e-10,0.86046,4
771.33698,339.77833,     -6.65427,  4.30511,50.00000,24.00000,2.755261e-10,0.86041,4
772.95398,339.85833,     -6.70857,  4.30511,50.00000,24.00000,2.755261e-10,0.86041,4
774.57202,339.93833,     -6.74425,  4.33399,50.00000,24.00000,2.756328e-10,0.86035,4
776.17902,340.01833,     -6.79150,  4.34735,50.00000,24.00000,2.756328e-10,0.86035,4
777.78998,340.09833,     -6.83494,  4.36071,50.00000,24.00000,2.757778e-10,0.86030,4
779.40601,340.17833,     -6.87786,  4.36071,50.00000,24.00000,2.757778e-10,0.86030,4
781.01300,340.25833,     -6.91919,  4.36071,50.00000,24.00000,2.752858e-10,0.86025,4
782.63300,340.33833,     -6.96767,  4.37407,50.00000,24.00000,2.752858e-10,0.86025,4
784.24103,340.41833,     -7.00459,  4.41631,50.00000,24.00000,2.751941e-10,0.86020,4
785.85699,340.49833,     -7.04531,  4.41631,50.00000,24.00000,2.751941e-10,0.86020,4
787.47400,340.57833,     -7.08615,  4.41631,50.00000,24.00000,2.751655e-10,0.86015,4
789.07703,340.65833,     -7.13235,  4.41631,50.00000,24.00000,2.751655e-10,0.86015,4
790.69702,340.73833,     -7.17344,  4.43635,50.00000,24.00000,2.755032e-10,0.86010,4
792.30402,340.81833,     -7.21523,  4.44303,50.00000,24.00000,            ,0.44797,4
793.91602,340.89833,     -7.26253,  4.46955,50.00000,24.00000,            ,0.44733,4
794.62201,340.93333,     -7.28255,  4.46955,50.00000,24.00000,            ,0.44704,4