File: data/TGA/005d-L_M/ExpDat_2025_03_19_SL_005F_J1_isothermal_run_2.csv
#EXPORTTYPE:                 ,DATA ALL
#FILE:                       ,2025_03_19_SL_005F_J1_isothermal_run_2.ngb-ss5
#FORMAT:                     ,NETZSCH5
#FTYPE:                      ,ASCII
#IDENTITY:                   ,2025_03_19_SL_005F_J1_i
#DECIMAL:                    ,POINT
#SEPARATOR:                  ,COMMA
#MTYPE:                      ,DSC
#INSTRUMENT:                 ,NETZSCH STA 449F5
#PROJECT:                    ,PS
#DATE/TIME:                  ,3/19/2025 2:59:33 PM (UTC-4)
#CORR. FILE:                 ,
#TEMPCAL:                    ,13-11-2024 10:37
#SENSITIVITY:                ,28-06-2023 13:53
#LABORATORY:                 ,Tran/Aspuru
#OPERATOR:                   ,Stanley
#REMARK:                     ,2025_03_19_SL_005F_J1_isothermal_run_2
#SAMPLE:                     ,2025_03_19_SL_005F_J1_i
#SAMPLE MASS /mg:            ,5.01
#MATERIAL:                   ,Polystyrene
#REFERENCE:                  ,
#REFERENCE MASS /mg:         ,0
#TYPE OF CRUCIBLE:           ,Al2O3 85 ‘l, open
#SAMPLE CRUCIBLE MASS /mg:   ,0
#REFERENCE CRUCIBLE MASS /mg:,0
#DSC RANGE /‘V:              ,5000
#TG RANGE /mg:               ,35000
#TAU-R:                      ,---
#CORR. CODE:                 ,000
#EXO:                        ,-1
#RANGE:                      ,30›C....800›C/0.0....20.0K/min
#SEGMENT:                    ,S1-5/5
#SEG. 1:                     ,30›C/10.0(K/min)/100›C
#SEG. 2:                     ,100›C/00:10/100›C
#SEG. 3:                     ,100›C/5.0(K/min)/300›C
#SEG. 4:                     ,300›C/20:00/300›C
#SEG. 5:                     ,300›C/20.0(K/min)/800›C

##Temp./›C,Time/min,DSC/(mW/mg),Mass/%,Gas Flow(purge2)/(ml/min),Gas Flow(protective)/(ml/min),TIC(scan:1)/A,Sensit./(uV/mW),Segment
 33.14600,   0.00000,-2.455374e-02,100.00000,50.00000,43.00000,            ,0.92410,1
 35.16200,   1.32000, 4.052442e-02, 99.16886,50.00000,50.00000,2.732506e-10,0.92414,1
 40.79200,   2.64000,      0.22945,100.22355,50.00000,50.00000,2.732830e-10,0.92420,1
 49.50700,   3.96000,      0.43600,101.46547,50.00000,50.00000,2.724457e-10,0.92428,1
 61.67100,   5.28000,      0.67890,102.68723,50.00000,50.00000,2.731227e-10,0.92440,1
 76.40500,   6.60000,      0.90622,103.65589,50.00000,50.00000,2.736874e-10,0.92456,1
 86.70900,   7.45917,      0.98758,103.89521,50.00000,50.00000,2.728996e-10,0.92467,2
 93.50600,   8.11917,      0.84205,103.24271,50.00000,50.00000,2.729512e-10,0.92476,2
 98.54300,   8.77917,      0.60855,102.48623,50.00000,50.00000,2.742500e-10,0.92485,2
102.21700,   9.43917,      0.41906,101.83353,50.00000,50.00000,2.729912e-10,0.92495,2
105.14600,  10.09917,      0.29788,101.37745,50.00000,50.00000,2.734890e-10,0.92505,2
107.44200,  10.75917,      0.20646,100.99581,50.00000,50.00000,2.739392e-10,0.92515,2
109.06600,  11.41917,      0.11041,100.50798,50.00000,50.00000,2.742158e-10,0.92525,2
110.04800,  12.07917, 2.089561e-02, 99.99541,50.00000,50.00000,2.735862e-10,0.92535,2
110.48100,  12.73917,-5.556374e-02, 99.60259,50.00000,50.00000,2.734261e-10,0.92544,2
110.53400,  13.39917,     -0.11163, 99.16447,50.00000,50.00000,2.733726e-10,0.92554,2
110.27100,  14.05917,     -0.15308, 98.85269,50.00000,50.00000,2.734604e-10,0.92563,2
109.78600,  14.71917,     -0.18722, 98.44172,50.00000,50.00000,2.734031e-10,0.92572,2
109.15900,  15.37917,     -0.21155, 98.18443,50.00000,50.00000,2.738018e-10,0.92581,2
108.36400,  16.03917,     -0.22707, 98.00599,50.00000,50.00000,2.742786e-10,0.92589,2
107.52600,  16.69917,     -0.23563, 97.71477,50.00000,50.00000,2.739812e-10,0.92597,2
106.39400,  17.71917,     -0.21335, 97.61297,50.00000,50.00000,2.734203e-10,0.92608,3
107.29700,  19.03917,-1.607208e-02, 98.32216,50.00000,50.00000,2.744331e-10,0.92616,3
110.42500,  20.35917,      0.13285, 98.92515,50.00000,50.00000,2.735634e-10,0.92620,3
115.35200,  21.67917,      0.28061, 99.51677,50.00000,50.00000,2.738171e-10,0.92618,3
121.77100,  22.99917,      0.40488,100.02255,50.00000,50.00000,2.738151e-10,0.92608,3
129.10001,  24.31917,      0.48800,100.42216,50.00000,50.00000,2.735309e-10,0.92590,3
136.87801,  25.63917,      0.53587,100.55768,50.00000,50.00000,2.739887e-10,0.92564,3
144.79601,  26.95917,      0.55084,100.72255,50.00000,50.00000,2.733536e-10,0.92534,3
152.60500,  28.27917,      0.53902,100.76327,50.00000,50.00000,2.736817e-10,0.92484,3
160.20200,  29.59917,      0.51497,100.85569,50.00000,50.00000,2.740022e-10,0.92448,3
167.52200,  30.91917,      0.48034,100.88064,50.00000,50.00000,2.740135e-10,0.92418,3
174.60800,  32.23917,      0.44337,100.90778,50.00000,50.00000,2.734490e-10,0.92388,3
181.51100,  33.55917,      0.40609,100.99581,50.00000,50.00000,2.742004e-10,0.92357,3
188.28700,  34.87917,      0.37333,101.00699,50.00000,50.00000,2.742233e-10,0.92329,3
194.97099,  36.19917,      0.34011,101.06347,50.00000,50.00000,2.737598e-10,0.92297,3
201.60201,  37.51917,      0.30816,101.09062,50.00000,50.00000,2.745209e-10,0.92266,3
208.17599,  38.83917,      0.27713,101.15609,50.00000,50.00000,2.739620e-10,0.92236,3
214.75800,  40.15917,      0.24563,101.11537,50.00000,50.00000,2.729225e-10,0.92207,3
221.29500,  41.47917,      0.21218,101.21477,50.00000,50.00000,2.738209e-10,0.92180,3
227.86200,  42.79917,      0.17765,101.15609,50.00000,50.00000,2.741719e-10,0.92154,3
234.40500,  44.11917,      0.14056,101.10200,50.00000,50.00000,2.745666e-10,0.92129,3
240.96201,  45.43917,      0.10211,101.02974,50.00000,50.00000,2.741470e-10,0.92106,3
247.52699,  46.75917, 6.024407e-02,100.94830,50.00000,50.00000,2.742118e-10,0.92080,3
254.10600,  48.07917, 1.543882e-02,100.89421,50.00000,50.00000,2.742405e-10,0.92059,3
260.68201,  49.39917,-3.386781e-02,100.76088,50.00000,50.00000,2.741050e-10,0.92039,3
267.25201,  50.71917,-8.592135e-02,100.59840,50.00000,50.00000,2.737866e-10,0.92019,3
273.82700,  52.03917,     -0.14155,100.40858,50.00000,50.00000,2.740784e-10,0.92000,3
280.39499,  53.35917,     -0.19535,100.13094,50.00000,50.00000,2.738761e-10,0.91982,3
286.95901,  54.67917,     -0.24978, 99.77405,50.00000,50.00000,2.743016e-10,0.91964,3
293.53000,  55.99917,     -0.30890, 99.33832,50.00000,50.00000,2.738952e-10,0.91947,3
301.57401,  57.79917,     -0.64539,100.46287,50.00000,26.00000,2.740479e-10,0.91925,4
303.32501,  61.09917,     -1.47719, 97.59960,50.00000,26.00000,2.740554e-10,0.91890,4
302.10199,  64.39917,     -1.55901, 95.87645,50.00000,25.00000,2.535134e-10,0.91862,4
301.04401,  67.69917,     -1.53691, 94.54431,50.00000,25.00000,2.531356e-10,0.91841,4
300.47299,  70.99917,     -1.51400, 93.43553,50.00000,25.00000,2.527561e-10,0.91825,4
300.20200,  74.29917,     -1.50268, 92.44192,50.00000,25.00000,2.527618e-10,0.91816,4
300.09799,  77.59917,     -1.49823, 91.56347,50.00000,25.00000,2.524281e-10,0.91812,4
300.04999,  80.89917,     -1.49815, 90.71657,50.00000,25.00000,2.524567e-10,0.91812,4
300.02100,  84.19917,     -1.49945, 89.97146,50.00000,25.00000,2.522449e-10,0.91815,4
300.00601,  87.49917,     -1.50001, 89.23533,50.00000,25.00000,2.525425e-10,0.91820,4
300.01801,  90.79917,     -1.50177, 88.55788,50.00000,25.00000,2.515735e-10,0.91829,4
300.01700,  94.09917,     -1.50254, 87.94591,50.00000,25.00000,2.519837e-10,0.91840,4
300.01199,  97.39917,     -1.50311, 87.34750,50.00000,25.00000,2.523575e-10,0.91852,4
300.02100, 100.69917,     -1.50351, 86.74910,50.00000,25.00000,2.528706e-10,0.91866,4
300.01099, 103.99917,     -1.50466, 86.23413,50.00000,25.00000,2.516708e-10,0.91880,4
300.02100, 107.29917,     -1.50584, 85.74651,50.00000,25.00000,2.526684e-10,0.91895,4
300.00800, 110.59917,     -1.50562, 85.21796,50.00000,25.00000,2.525424e-10,0.91910,4
300.01300, 113.89917,     -1.50660, 84.73034,50.00000,25.00000,2.526626e-10,0.91933,4
300.00800, 117.19917,     -1.50717, 84.24251,50.00000,25.00000,2.517547e-10,0.91929,4
300.00699, 120.49917,     -1.50775, 83.82695,50.00000,25.00000,2.522945e-10,0.91895,4
300.01801, 123.79917,     -1.50854, 83.40479,50.00000,25.00000,2.528077e-10,0.91839,4
300.01199, 127.09917,     -1.50814, 82.96886,50.00000,26.00000,2.526283e-10,0.91762,4
300.02100, 130.39917,     -1.50971, 82.54651,50.00000,26.00000,2.535877e-10,0.91658,4
300.00900, 133.69917,     -1.50852, 82.15369,50.00000,26.00000,2.525749e-10,0.91530,4
300.01999, 136.99917,     -1.51009, 81.73812,50.00000,26.00000,2.524223e-10,0.91379,4
300.01199, 140.29917,     -1.51027, 81.36786,50.00000,26.00000,2.536602e-10,0.91199,4
300.01401, 143.59917,     -1.51298, 80.97265,50.00000,26.00000,2.527924e-10,0.91008,4
300.00601, 146.89917,     -1.51200, 80.65868,50.00000,26.00000,2.533396e-10,0.90802,4
300.01801, 150.19917,     -1.51183, 80.27944,50.00000,26.00000,2.537384e-10,0.90582,4
300.01700, 153.49917,     -1.51473, 79.94072,50.00000,26.00000,2.540093e-10,0.90353,4
300.01801, 156.79917,     -1.51318, 79.58164,50.00000,26.00000,2.533855e-10,0.90115,4
300.02499, 160.09917,     -1.51377, 79.24970,50.00000,26.00000,2.524795e-10,0.89871,4
300.02802, 163.39917,     -1.51513, 78.89062,50.00000,26.00000,2.534256e-10,0.89623,4
300.01099, 166.69917,     -1.51452, 78.57904,50.00000,26.00000,2.536354e-10,0.89371,4
300.01401, 169.99917,     -1.51472, 78.24711,50.00000,26.00000,2.542647e-10,0.89117,4
300.01501, 173.29917,     -1.51376, 77.94890,50.00000,26.00000,2.537441e-10,0.88846,4
300.01199, 176.59917,     -1.51549, 77.62375,50.00000,26.00000,2.534296e-10,0.88585,4
300.01501, 179.89917,     -1.51666, 77.32575,50.00000,26.00000,2.535038e-10,0.88321,4
300.00800, 183.19917,     -1.51568, 76.99820,50.00000,26.00000,2.538642e-10,0.88052,4
300.02701, 186.49917,     -1.51552, 76.70699,50.00000,26.00000,2.535973e-10,0.87779,4
300.01501, 189.79917,     -1.51917, 76.41337,50.00000,26.00000,2.539101e-10,0.87503,4
300.02301, 193.09917,     -1.51841, 76.10858,50.00000,26.00000,2.533379e-10,0.87223,4
300.01099, 196.39917,     -1.51878, 75.85110,50.00000,26.00000,2.542687e-10,0.86937,4
300.00800, 199.69917,     -1.52013, 75.55090,50.00000,26.00000,2.538529e-10,0.86647,4
300.00601, 202.99917,     -1.51800, 75.25269,50.00000,26.00000,2.539826e-10,0.86353,4
300.01801, 206.29917,     -1.51879, 74.97505,50.00000,26.00000,2.537822e-10,0.86053,4
300.01300, 209.59917,     -1.52110, 74.69042,50.00000,26.00000,2.543145e-10,0.85750,4
300.01901, 212.89917,     -1.52189, 74.41277,50.00000,26.00000,2.542114e-10,0.85427,4
300.01801, 216.19917,     -1.52227, 74.16208,50.00000,26.00000,2.542858e-10,0.85113,4
300.01801, 219.49917,     -1.52169, 73.92275,50.00000,26.00000,2.548599e-10,0.84797,4
300.02701, 222.79917,     -1.52345, 73.63812,50.00000,27.00000,2.543392e-10,0.84475,4
300.02301, 226.09917,     -1.52480, 73.37385,50.00000,27.00000,2.544117e-10,0.84148,4
300.01901, 229.39917,     -1.52518, 73.13014,50.00000,27.00000,2.552547e-10,0.83817,4
300.01999, 232.69917,     -1.52441, 72.87725,50.00000,27.00000,2.544193e-10,0.83484,4
300.01801, 235.99917,     -1.52595, 72.64451,50.00000,27.00000,2.551689e-10,0.83146,4
300.01099, 239.29917,     -1.52690, 72.38723,50.00000,27.00000,2.550926e-10,0.82803,4
300.02301, 242.59917,     -1.52557, 72.14331,50.00000,27.00000,2.551613e-10,0.82459,4
300.02200, 245.89917,     -1.52634, 71.92196,50.00000,27.00000,2.552986e-10,0.82110,4
300.01700, 249.19917,     -1.53059, 71.68483,50.00000,27.00000,2.554703e-10,0.81759,4
300.00201, 252.49917,     -1.52824, 71.45230,50.00000,27.00000,2.560558e-10,0.81404,4
300.02499, 255.79917,     -1.52828, 71.22415,50.00000,27.00000,2.564468e-10,0.81047,4
300.01599, 259.09917,     -1.52982, 71.00279,50.00000,27.00000,2.560578e-10,0.80670,4
300.01001, 262.39917,     -1.53097, 70.76587,50.00000,27.00000,2.562999e-10,0.80307,4
300.01901, 265.69917,     -1.53156, 70.55569,50.00000,27.00000,2.564678e-10,0.79944,4
300.02600, 268.99917,     -1.53312, 70.35250,50.00000,27.00000,2.559509e-10,0.79578,4
300.01801, 272.29917,     -1.53059, 70.11537,50.00000,27.00000,2.560063e-10,0.79210,4
300.02301, 275.59917,     -1.53176, 69.89182,50.00000,27.00000,2.572765e-10,0.78813,4
300.02600, 278.89917,     -1.52983, 69.70220,50.00000,27.00000,2.569676e-10,0.78461,4
300.01501, 282.19917,     -1.53349, 69.48323,50.00000,27.00000,2.564258e-10,0.78413,4
300.01001, 285.49917,     -1.53367, 69.30020,50.00000,27.00000,2.567292e-10,0.78479,4
300.02200, 288.79917,     -1.53253, 69.08343,50.00000,27.00000,2.583179e-10,0.78553,4
300.02802, 292.09917,     -1.53390, 68.86447,50.00000,27.00000,2.576008e-10,0.78612,4
300.02600, 295.39917,     -1.53583, 68.64311,50.00000,27.00000,2.571144e-10,0.78652,4
300.02100, 298.69917,     -1.53524, 68.43313,50.00000,27.00000,2.572881e-10,0.78679,4
300.01099, 301.99917,     -1.53561, 68.23214,50.00000,27.00000,2.573663e-10,0.78694,4
300.01099, 305.29917,     -1.53735, 68.04930,50.00000,27.00000,2.614841e-10,0.78706,4
300.00500, 308.59917,     -1.53657, 67.82575,50.00000,27.00000,2.616329e-10,0.78712,4
300.02200, 311.89917,     -1.53737, 67.60200,50.00000,27.00000,2.614307e-10,0.78715,4
300.00900, 315.19917,     -1.53889, 67.43054,50.00000,27.00000,2.627906e-10,0.78717,4
300.01901, 318.49917,     -1.53969, 67.23393,50.00000,27.00000,2.617683e-10,0.78719,4
300.02100, 321.79917,     -1.54085, 67.06467,50.00000,27.00000,2.619610e-10,0.78719,4
300.02600, 325.09917,     -1.53893, 66.86826,50.00000,27.00000,2.614574e-10,0.78720,4
300.02802, 328.39917,     -1.54028, 66.64232,50.00000,27.00000,2.620144e-10,0.78721,4
300.01300, 331.69917,     -1.53987, 66.45948,50.00000,27.00000,2.615795e-10,0.78720,4
300.01801, 334.99917,     -1.54046, 66.27665,50.00000,27.00000,2.620963e-10,0.78719,4
300.03900, 338.29917,     -1.54224, 66.14112,50.00000,27.00000,2.620755e-10,0.78721,4
300.01501, 341.59917,     -1.54277, 65.94910,50.00000,27.00000,2.624035e-10,0.78721,4
300.01700, 344.89917,     -1.54123, 65.76627,50.00000,27.00000,2.625636e-10,0.78719,4
300.00400, 348.19917,     -1.54295, 65.57425,50.00000,27.00000,2.625752e-10,0.78719,4
300.02399, 351.49917,     -1.54105, 65.38224,50.00000,27.00000,2.633496e-10,0.78720,4
300.00101, 354.79917,     -1.54372, 65.19940,50.00000,27.00000,2.635592e-10,0.78718,4
300.00699, 358.09917,     -1.54411, 65.01657,50.00000,27.00000,2.626057e-10,0.78719,4
300.00400, 361.39917,     -1.54450, 64.85389,50.00000,27.00000,2.633457e-10,0.78721,4
300.00101, 364.69917,     -1.54391, 64.66427,50.00000,27.00000,2.624283e-10,0.78719,4
300.01999, 367.99917,     -1.54414, 64.50399,50.00000,26.00000,2.632122e-10,0.78718,4
300.01999, 371.29917,     -1.54491, 64.33453,50.00000,26.00000,2.635155e-10,0.78719,4
300.00699, 374.59917,     -1.54450, 64.13134,50.00000,26.00000,2.638188e-10,0.78720,4
300.02899, 377.89917,     -1.54590, 63.95509,50.00000,26.00000,2.630348e-10,0.78719,4
300.01700, 381.19917,     -1.54394, 63.83992,50.00000,26.00000,2.630883e-10,0.78718,4
300.02600, 384.49917,     -1.54454, 63.65030,50.00000,26.00000,2.640458e-10,0.78720,4
300.01501, 387.79917,     -1.54664, 63.50120,50.00000,26.00000,2.638149e-10,0.78720,4
300.01999, 391.09917,     -1.54569, 63.33633,50.00000,26.00000,2.643775e-10,0.78720,4
300.02399, 394.39917,     -1.54531, 63.16028,50.00000,26.00000,2.644958e-10,0.78718,4
300.01099, 397.69917,     -1.54606, 63.01796,50.00000,26.00000,2.633342e-10,0.78719,4
300.02600, 400.99917,     -1.54434, 62.84192,50.00000,26.00000,2.639122e-10,0.78720,4
300.02600, 404.29917,     -1.54338, 62.67246,50.00000,26.00000,2.635517e-10,0.78720,4
300.01300, 407.59917,     -1.54471, 62.48283,50.00000,26.00000,2.636471e-10,0.78720,4
300.02200, 410.89917,     -1.54279, 62.35409,50.00000,26.00000,2.635803e-10,0.78719,4
300.02499, 414.19917,     -1.54279, 62.21178,50.00000,26.00000,2.641926e-10,0.78719,4
300.01099, 417.49917,     -1.54161, 62.05609,50.00000,26.00000,2.646199e-10,0.78719,4
300.01401, 420.79917,     -1.54277, 61.90020,50.00000,26.00000,2.644272e-10,0.78720,4
300.02802, 424.09917,     -1.54531, 61.71737,50.00000,26.00000,2.645016e-10,0.78720,4
300.00800, 427.39917,     -1.54508, 61.55469,50.00000,26.00000,2.651081e-10,0.78719,4
300.01700, 430.69917,     -1.54413, 61.39222,50.00000,26.00000,2.648526e-10,0.78719,4
300.01300, 433.99917,     -1.54645, 61.20699,50.00000,26.00000,2.658290e-10,0.78720,4
300.01199, 437.29917,     -1.54374, 61.05110,50.00000,26.00000,2.656383e-10,0.78719,4
300.00601, 440.59917,     -1.54721, 60.86607,50.00000,26.00000,2.650852e-10,0.78719,4
300.01401, 443.89917,     -1.54896, 60.70798,50.00000,26.00000,2.657891e-10,0.78718,4
300.00900, 447.19917,     -1.54837, 60.56347,50.00000,26.00000,2.670345e-10,0.78719,4
300.02200, 450.49917,     -1.54801, 60.38723,50.00000,26.00000,2.663194e-10,0.78719,4
300.01801, 453.79917,     -1.55032, 60.21118,50.00000,26.00000,2.660484e-10,0.78719,4
300.02399, 457.09917,     -1.54879, 60.10040,50.00000,26.00000,2.657451e-10,0.78720,4
300.01401, 460.39917,     -1.54916, 59.95828,50.00000,26.00000,2.662639e-10,0.78720,4
300.01001, 463.69917,     -1.54876, 59.78882,50.00000,26.00000,2.663078e-10,0.78719,4
300.02100, 466.99917,     -1.54936, 59.66008,50.00000,26.00000,2.662411e-10,0.78719,4
300.01999, 470.29917,     -1.55130, 59.54491,50.00000,26.00000,2.666627e-10,0.78719,4
300.00800, 473.59917,     -1.55282, 59.35070,50.00000,26.00000,2.663955e-10,0.78719,4
300.00601, 476.89917,     -1.55185, 59.26727,50.00000,26.00000,2.665824e-10,0.78719,4
300.02899, 480.19917,     -1.55209, 59.05050,50.00000,26.00000,2.665674e-10,0.78720,4
300.02399, 483.49917,     -1.55130, 58.97585,50.00000,26.00000,2.667923e-10,0.78718,4
300.01801, 486.79917,     -1.55187, 58.83373,50.00000,26.00000,2.665806e-10,0.78720,4
300.02600, 490.09917,     -1.55227, 58.69361,50.00000,26.00000,2.667236e-10,0.78719,4
300.02802, 493.39917,     -1.55286, 58.59880,50.00000,26.00000,2.679329e-10,0.78720,4
300.01801, 496.69917,     -1.55361, 58.47006,50.00000,26.00000,2.675819e-10,0.78719,4
300.01801, 499.99917,     -1.55129, 58.30758,50.00000,26.00000,2.679328e-10,0.78719,4
300.03101, 503.29917,     -1.55267, 58.21936,50.00000,26.00000,2.670383e-10,0.78718,4
300.02301, 506.59917,     -1.55227, 58.08403,50.00000,26.00000,2.663498e-10,0.78719,4
300.01599, 509.89917,     -1.55361, 57.95529,50.00000,26.00000,2.673493e-10,0.78719,4
300.02301, 513.19917,     -1.55169, 57.85369,50.00000,26.00000,2.678661e-10,0.78720,4
300.01501, 516.49917,     -1.55264, 57.69780,50.00000,26.00000,2.679367e-10,0.78719,4
300.01599, 519.79917,     -1.55148, 57.56228,50.00000,26.00000,2.677346e-10,0.78720,4
300.01700, 523.09917,     -1.55226, 57.44711,50.00000,25.00000,2.667674e-10,0.78719,4
300.01099, 526.39917,     -1.54934, 57.30479,50.00000,25.00000,2.679768e-10,0.78719,4
300.02200, 529.69917,     -1.55130, 57.17625,50.00000,25.00000,2.672748e-10,0.78718,4
300.00699, 532.99917,     -1.55108, 57.03154,50.00000,25.00000,2.683125e-10,0.78720,4
300.01901, 536.29917,     -1.54897, 56.88942,50.00000,25.00000,2.675762e-10,0.78718,4
300.02100, 539.59917,     -1.54936, 56.79461,50.00000,25.00000,2.685775e-10,0.78719,4
300.01001, 542.89917,     -1.55070, 56.64551,50.00000,25.00000,2.686271e-10,0.78719,4
300.01001, 546.19917,     -1.55186, 56.48962,50.00000,25.00000,2.686081e-10,0.78719,4
300.01599, 549.49917,     -1.55090, 56.34970,50.00000,25.00000,2.679367e-10,0.78718,4
300.00800, 552.79917,     -1.55301, 56.20060,50.00000,25.00000,2.687606e-10,0.78719,4
300.01501, 556.09917,     -1.55535, 56.09222,50.00000,26.00000,2.692738e-10,0.78718,4
300.00900, 559.39917,     -1.55379, 55.95669,50.00000,26.00000,2.684993e-10,0.78719,4
300.00500, 562.69917,     -1.55398, 55.83253,50.00000,26.00000,2.686424e-10,0.78719,4
300.01001, 565.99917,     -1.55631, 55.69022,50.00000,26.00000,2.690678e-10,0.78720,4
300.01300, 569.29917,     -1.55612, 55.58184,50.00000,26.00000,2.693920e-10,0.78719,4
300.00201, 572.59917,     -1.55610, 55.48703,50.00000,26.00000,2.699471e-10,0.78719,4
300.02301, 575.89917,     -1.55556, 55.35609,50.00000,26.00000,2.695256e-10,0.78719,4
300.01401, 579.19917,     -1.55709, 55.24311,50.00000,26.00000,2.700444e-10,0.78720,4
300.00299, 582.49917,     -1.55862, 55.11677,50.00000,26.00000,2.699413e-10,0.78718,4
299.99799, 585.79917,     -1.55783, 55.02415,50.00000,26.00000,2.699891e-10,0.78718,4
300.01801, 589.09917,     -1.55671, 54.94291,50.00000,26.00000,2.708988e-10,0.78719,4
300.01901, 592.39917,     -1.55768, 54.84571,50.00000,26.00000,2.703973e-10,0.78720,4
300.00900, 595.69917,     -1.55766, 54.73054,50.00000,26.00000,2.695846e-10,0.78721,4
300.02100, 598.99917,     -1.55613, 54.64711,50.00000,26.00000,2.704602e-10,0.78719,4
300.02600, 602.29917,     -1.55479, 54.50020,50.00000,26.00000,2.705517e-10,0.78718,4
300.01801, 605.59917,     -1.55497, 54.39641,50.00000,26.00000,2.708015e-10,0.78720,4
300.03299, 608.89917,     -1.55654, 54.28802,50.00000,26.00000,2.705594e-10,0.78720,4
300.02802, 612.19917,     -1.55692, 54.20000,50.00000,25.00000,2.709466e-10,0.78719,4
300.01901, 615.49917,     -1.55652, 54.07345,50.00000,25.00000,2.703191e-10,0.78719,4
300.03000, 618.79917,     -1.55596, 53.96966,50.00000,25.00000,2.706852e-10,0.78718,4
300.02600, 622.09917,     -1.55595, 53.85449,50.00000,25.00000,2.709655e-10,0.78719,4
300.01501, 625.39917,     -1.55574, 53.70758,50.00000,25.00000,2.705993e-10,0.78719,4
300.00299, 628.69917,     -1.55571, 53.63313,50.00000,25.00000,2.705154e-10,0.78719,4
300.01199, 631.99917,     -1.55283, 53.49301,50.00000,25.00000,2.713642e-10,0.78720,4
300.01999, 635.29917,     -1.55516, 53.41178,50.00000,25.00000,2.706203e-10,0.78719,4
300.02701, 638.59917,     -1.55576, 53.25828,50.00000,25.00000,2.709694e-10,0.78719,4
300.00299, 641.89917,     -1.55359, 53.13633,50.00000,25.00000,2.708587e-10,0.78720,4
300.01999, 645.19917,     -1.55381, 53.02575,50.00000,25.00000,2.715397e-10,0.78719,4
300.00400, 648.49917,     -1.55359, 52.91717,50.00000,25.00000,2.709122e-10,0.78719,4
300.01700, 651.79917,     -1.55516, 52.79082,50.00000,25.00000,2.709618e-10,0.78719,4
300.00900, 655.09917,     -1.55437, 52.68922,50.00000,25.00000,2.716904e-10,0.78720,4
300.02600, 658.39917,     -1.55266, 52.58084,50.00000,25.00000,2.714557e-10,0.78719,4
300.00699, 661.69917,     -1.55340, 52.47685,50.00000,25.00000,2.716026e-10,0.78718,4
300.01999, 664.99917,     -1.55497, 52.31437,50.00000,25.00000,2.718047e-10,0.78719,4
300.01801, 668.29917,     -1.55439, 52.24651,50.00000,25.00000,2.718525e-10,0.78719,4
300.01501, 671.59917,     -1.55303, 52.13134,50.00000,25.00000,2.710819e-10,0.78719,4
300.00699, 674.89917,     -1.55321, 52.03653,50.00000,25.00000,2.716293e-10,0.78719,4
300.01801, 678.19917,     -1.55265, 51.92136,50.00000,25.00000,2.719785e-10,0.78720,4
300.01099, 681.49917,     -1.55321, 51.84691,50.00000,25.00000,2.722779e-10,0.78720,4
300.01700, 684.79917,     -1.55110, 51.74531,50.00000,25.00000,2.721958e-10,0.78719,4
300.01801, 688.09917,     -1.55129, 51.60299,50.00000,25.00000,2.730770e-10,0.78720,4
300.01401, 691.39917,     -1.55303, 51.52854,50.00000,25.00000,2.722530e-10,0.78718,4
300.01300, 694.69917,     -1.55476, 51.40439,50.00000,25.00000,2.726365e-10,0.78718,4
300.01099, 697.99917,     -1.55167, 51.32295,50.00000,25.00000,2.727280e-10,0.78720,4
300.00601, 701.29917,     -1.55301, 51.22814,50.00000,25.00000,2.743110e-10,0.78720,4
300.01599, 704.59917,     -1.55593, 51.07226,50.00000,25.00000,2.740402e-10,0.78719,4
300.02399, 707.89917,     -1.55595, 50.94371,50.00000,25.00000,2.739906e-10,0.78719,4
300.02100, 711.19917,     -1.55807, 50.88942,50.00000,25.00000,2.737140e-10,0.78717,4
300.02301, 714.49917,     -1.55788, 50.75389,50.00000,26.00000,2.741013e-10,0.78718,4
300.02499, 717.79917,     -1.55711, 50.67944,50.00000,26.00000,2.727242e-10,0.78720,4
300.01901, 721.09917,     -1.55903, 50.56427,50.00000,26.00000,2.743664e-10,0.78718,4
300.02499, 724.39917,     -1.55808, 50.49661,50.00000,26.00000,2.741795e-10,0.78719,4
300.02399, 727.69917,     -1.55981, 50.39481,50.00000,26.00000,2.745036e-10,0.78720,4
300.01001, 730.99917,     -1.55824, 50.29321,50.00000,26.00000,2.735520e-10,0.78719,4
300.02600, 734.29917,     -1.55808, 50.21657,50.00000,26.00000,2.736378e-10,0.78719,4
300.01199, 737.59917,     -1.55863, 50.12834,50.00000,26.00000,2.744674e-10,0.78717,4
300.01501, 740.89917,     -1.55960, 50.05389,50.00000,25.00000,2.738685e-10,0.78719,4
300.00800, 744.19917,     -1.55708, 49.91836,50.00000,25.00000,2.738953e-10,0.78719,4
300.00900, 747.49917,     -1.55631, 49.83713,50.00000,25.00000,2.729015e-10,0.78720,4
300.02701, 750.79917,     -1.55614, 49.74910,50.00000,25.00000,2.737694e-10,0.78719,4
300.02301, 754.09917,     -1.55594, 49.66786,50.00000,25.00000,2.741985e-10,0.78719,4
300.00800, 757.39917,     -1.55688, 49.53234,50.00000,25.00000,2.733460e-10,0.78719,4
300.01099, 760.69917,     -1.55495, 49.45090,50.00000,25.00000,2.745381e-10,0.78719,4
300.01199, 763.99917,     -1.55515, 49.35609,50.00000,25.00000,2.740517e-10,0.78721,4
300.02600, 767.29917,     -1.55518, 49.27485,50.00000,25.00000,2.739258e-10,0.78719,4
300.00900, 770.59917,     -1.55476, 49.20479,50.00000,25.00000,2.745266e-10,0.78719,4
300.02200, 773.89917,     -1.55459, 49.08962,50.00000,25.00000,2.745666e-10,0.78719,4
300.02600, 777.19917,     -1.55440, 49.00838,50.00000,25.00000,2.748661e-10,0.78718,4
300.00800, 780.49917,     -1.55418, 48.92715,50.00000,25.00000,2.750416e-10,0.78719,4
300.01501, 783.79917,     -1.55380, 48.82555,50.00000,25.00000,2.740651e-10,0.78719,4
300.01501, 787.09917,     -1.55341, 48.74411,50.00000,25.00000,2.753333e-10,0.78718,4
300.00900, 790.39917,     -1.55553, 48.61537,50.00000,25.00000,2.750320e-10,0.78719,4
300.01300, 793.69917,     -1.55476, 48.52735,50.00000,25.00000,2.750607e-10,0.78720,4
300.00699, 796.99917,     -1.55669, 48.43253,50.00000,25.00000,2.743015e-10,0.78720,4
300.02399, 800.29917,     -1.55672, 48.47325,50.00000,25.00000,2.755832e-10,0.78720,4
300.01599, 803.59917,     -1.55748, 48.28802,50.00000,25.00000,2.748985e-10,0.78719,4
300.01199, 806.89917,     -1.55728, 48.17964,50.00000,25.00000,2.758789e-10,0.78719,4
300.02399, 810.19917,     -1.55749, 48.09840,50.00000,26.00000,2.761001e-10,0.78719,4
300.01999, 813.49917,     -1.55961, 48.01038,50.00000,26.00000,2.752361e-10,0.78719,4
300.01401, 816.79917,     -1.55960, 47.91537,50.00000,26.00000,2.764872e-10,0.78718,4
300.01001, 820.09917,     -1.55998, 47.84770,50.00000,26.00000,2.766267e-10,0.78719,4
300.00000, 823.39917,     -1.56151, 47.73253,50.00000,26.00000,2.762985e-10,0.78718,4
300.01801, 826.69917,     -1.55942, 47.67146,50.00000,26.00000,2.763119e-10,0.78719,4
300.02600, 829.99917,     -1.55982, 47.57904,50.00000,26.00000,2.771358e-10,0.78718,4
300.02301, 833.29917,     -1.55962, 47.49760,50.00000,26.00000,2.764836e-10,0.78719,4
300.01401, 836.59917,     -1.56173, 47.43673,50.00000,26.00000,2.755184e-10,0.78720,4
300.02301, 839.89917,     -1.56039, 47.38244,50.00000,26.00000,2.761573e-10,0.78719,4
300.02301, 843.19917,     -1.55981, 47.31477,50.00000,26.00000,2.767696e-10,0.78719,4
300.02301, 846.49917,     -1.55962, 47.26048,50.00000,25.00000,2.769394e-10,0.78718,4
300.02399, 849.79917,     -1.55749, 47.15888,50.00000,25.00000,2.765884e-10,0.78718,4
300.01001, 853.09917,     -1.55921, 47.10699,50.00000,25.00000,2.767639e-10,0.78719,4
300.00800, 856.39917,     -1.56114, 47.02575,50.00000,25.00000,2.772789e-10,0.78720,4
300.01501, 859.69917,     -1.55941, 46.98503,50.00000,25.00000,2.775307e-10,0.78720,4
300.01199, 862.99917,     -1.55960, 46.91737,50.00000,25.00000,2.777576e-10,0.78720,4
300.01700, 866.29917,     -1.56038, 46.86307,50.00000,25.00000,2.775478e-10,0.78720,4
300.01999, 869.59917,     -1.55961, 46.76148,50.00000,25.00000,2.779789e-10,0.78719,4
300.01901, 872.89917,     -1.56135, 46.69381,50.00000,25.00000,2.783089e-10,0.78719,4
300.01599, 876.19917,     -1.56077, 46.60579,50.00000,25.00000,2.779464e-10,0.78717,4
300.01501, 879.49917,     -1.55999, 46.47705,50.00000,25.00000,2.785090e-10,0.78719,4
300.01700, 882.79917,     -1.55961, 46.39561,50.00000,25.00000,2.784500e-10,0.78720,4
300.02100, 886.09917,     -1.55942, 46.34371,50.00000,25.00000,2.772865e-10,0.78720,4
300.00101, 889.39917,     -1.55958, 46.26248,50.00000,25.00000,2.783184e-10,0.78719,4
300.01099, 892.69917,     -1.55863, 46.18802,50.00000,25.00000,2.781505e-10,0.78718,4
300.00299, 895.99917,     -1.55842, 46.08862,50.00000,25.00000,2.787284e-10,0.78720,4
300.01099, 899.29917,     -1.55902, 46.00060,50.00000,25.00000,2.789688e-10,0.78720,4
300.01401, 902.59917,     -1.56096, 45.93273,50.00000,25.00000,2.784004e-10,0.78719,4
300.02100, 905.89917,     -1.56058, 45.83792,50.00000,25.00000,2.778053e-10,0.78720,4
300.01099, 909.19917,     -1.56269, 45.74311,50.00000,25.00000,2.792034e-10,0.78720,4
300.01001, 912.49917,     -1.56443, 45.65509,50.00000,25.00000,2.793273e-10,0.78719,4
300.00101, 915.79917,     -1.56383, 45.55569,50.00000,26.00000,2.793330e-10,0.78719,4
300.01199, 919.09917,     -1.56637, 45.49461,50.00000,26.00000,2.793732e-10,0.78719,4
300.01199, 922.39917,     -1.56676, 45.39980,50.00000,26.00000,2.794685e-10,0.78718,4
300.00601, 925.69917,     -1.56829, 45.31856,50.00000,26.00000,2.794457e-10,0.78718,4
300.00800, 928.99917,     -1.56675, 45.26427,50.00000,26.00000,2.791138e-10,0.78719,4
300.01700, 932.29917,     -1.56677, 45.20120,50.00000,26.00000,2.789534e-10,0.78719,4
300.01300, 935.59917,     -1.56715, 45.14012,50.00000,26.00000,2.803077e-10,0.78719,4
300.01999, 938.89917,     -1.56542, 45.06786,50.00000,26.00000,2.788601e-10,0.78719,4
300.03101, 942.19917,     -1.56795, 44.98443,50.00000,26.00000,2.795659e-10,0.78720,4
300.03101, 945.49917,     -1.56853, 44.94152,50.00000,26.00000,2.798862e-10,0.78719,4
300.01801, 948.79917,     -1.56464, 44.84890,50.00000,26.00000,2.797012e-10,0.78719,4
300.01199, 952.09917,     -1.56676, 44.81497,50.00000,25.00000,2.802009e-10,0.78720,4
300.00601, 955.39917,     -1.56578, 44.71337,50.00000,25.00000,2.788696e-10,0.78720,4
300.00299, 958.69917,     -1.56403, 44.70659,50.00000,25.00000,2.791672e-10,0.78719,4
300.02301, 961.99917,     -1.56504, 44.63892,50.00000,25.00000,2.792854e-10,0.78720,4
300.01401, 965.29917,     -1.56734, 44.52375,50.00000,25.00000,2.792395e-10,0.78719,4
300.01099, 968.59917,     -1.56579, 44.48084,50.00000,25.00000,2.792300e-10,0.78718,4
300.00699, 971.89917,     -1.56578, 44.39940,50.00000,25.00000,2.802486e-10,0.78719,4
300.01999, 975.19917,     -1.56658, 44.35210,50.00000,25.00000,2.793331e-10,0.78718,4
300.01099, 978.49917,     -1.56559, 44.25050,50.00000,25.00000,2.805024e-10,0.78718,4
300.01901, 981.79917,     -1.56426, 44.17585,50.00000,25.00000,2.803860e-10,0.78719,4
300.01801, 985.09917,     -1.56677, 44.12176,50.00000,25.00000,2.812270e-10,0.78719,4
300.01001, 988.39917,     -1.56656, 44.06747,50.00000,25.00000,2.807598e-10,0.78718,4
300.00900, 991.69917,     -1.56385, 43.99760,50.00000,25.00000,2.812672e-10,0.78718,4
300.01599, 994.99917,     -1.56618, 43.91178,50.00000,25.00000,2.804910e-10,0.78718,4
300.02899, 998.29917,     -1.56621, 43.85070,50.00000,25.00000,2.809163e-10,0.78718,4
300.01801,1001.59917,     -1.56677, 43.76048,50.00000,25.00000,2.788468e-10,0.78719,4
300.02600,1004.89917,     -1.56775, 43.68583,50.00000,25.00000,2.726421e-10,0.78718,4
300.00800,1008.19917,     -1.56830, 43.64970,50.00000,25.00000,2.726040e-10,0.78718,4
300.00800,1011.49917,     -1.56849, 43.58204,50.00000,25.00000,2.722435e-10,0.78720,4
300.01300,1014.79917,     -1.56908, 43.49621,50.00000,25.00000,2.719822e-10,0.78718,4
300.01401,1018.09917,     -1.56908, 43.39461,50.00000,25.00000,2.715130e-10,0.78718,4
300.01001,1021.39917,     -1.56907, 43.32695,50.00000,25.00000,2.719574e-10,0.78719,4
300.02301,1024.69917,     -1.56813, 43.28842,50.00000,25.00000,2.719364e-10,0.78718,4
300.01199,1027.99917,     -1.56947, 43.19361,50.00000,25.00000,2.638797e-10,0.78719,4
300.00601,1031.29917,     -1.56907, 43.12595,50.00000,25.00000,2.627334e-10,0.78718,4
300.02600,1034.59917,     -1.56910, 43.04451,50.00000,25.00000,2.641753e-10,0.78720,4
300.02200,1037.89917,     -1.56736, 42.99042,50.00000,25.00000,2.632981e-10,0.78718,4
300.01199,1041.19917,     -1.56908, 42.92934,50.00000,25.00000,2.632750e-10,0.78719,4
300.02200,1044.49917,     -1.56948, 42.84810,50.00000,25.00000,2.630634e-10,0.78720,4
300.02399,1047.79917,     -1.56813, 42.78044,50.00000,25.00000,2.632179e-10,0.78720,4
300.03299,1051.09917,     -1.56796, 42.74870,50.00000,25.00000,2.629490e-10,0.78719,4
300.02200,1054.39917,     -1.56852, 42.70140,50.00000,25.00000,2.630805e-10,0.78718,4
300.00000,1057.69917,     -1.57060, 42.62675,50.00000,25.00000,2.625103e-10,0.78719,4
300.02600,1060.99917,     -1.56988, 42.58623,50.00000,25.00000,2.631054e-10,0.78720,4
300.01099,1064.29917,     -1.56927, 42.49361,50.00000,25.00000,2.634449e-10,0.78719,4
300.01599,1067.59917,     -1.57121, 42.44391,50.00000,25.00000,2.639352e-10,0.78719,4
300.01001,1070.89917,     -1.57101, 42.38962,50.00000,25.00000,2.626476e-10,0.78719,4
300.02499,1074.19917,     -1.57239, 42.30160,50.00000,25.00000,2.630253e-10,0.78719,4
300.01001,1077.49917,     -1.57024, 42.20459,50.00000,25.00000,2.636127e-10,0.78720,4
300.00800,1080.79917,     -1.57043, 42.14132,50.00000,25.00000,2.628785e-10,0.78720,4
300.01599,1084.09917,     -1.57063, 42.09840,50.00000,25.00000,2.636071e-10,0.78720,4
300.02200,1087.39917,     -1.57084, 42.00359,50.00000,25.00000,2.637768e-10,0.78719,4
300.00500,1090.69917,     -1.57139, 41.97645,50.00000,25.00000,2.634831e-10,0.78719,4
300.00699,1093.99917,     -1.57236, 41.91996,50.00000,25.00000,2.634621e-10,0.78719,4
300.01001,1097.29917,     -1.57256, 41.83653,50.00000,25.00000,2.637081e-10,0.78719,4
300.02499,1100.59917,     -1.57200, 41.67385,50.00000,25.00000,2.639942e-10,0.78719,4
300.01001,1103.89917,     -1.57082, 41.70559,50.00000,25.00000,2.636948e-10,0.78718,4
300.01999,1107.19917,     -1.57296, 41.62196,50.00000,25.00000,2.640266e-10,0.78719,4
300.01501,1110.49917,     -1.57295, 41.56327,50.00000,25.00000,2.637617e-10,0.78719,4
300.01300,1113.79917,     -1.57392, 41.52255,50.00000,25.00000,2.632274e-10,0.78720,4
300.01599,1117.09917,     -1.57315, 41.42774,50.00000,26.00000,2.632809e-10,0.78719,4
300.01599,1120.39917,     -1.57179, 41.41637,50.00000,26.00000,2.646198e-10,0.78718,4
300.01401,1123.69917,     -1.57334, 41.35549,50.00000,26.00000,2.639847e-10,0.78720,4
300.01700,1126.99917,     -1.57605, 41.26747,50.00000,26.00000,2.637786e-10,0.78720,4
300.00201,1130.29917,     -1.57486, 41.18603,50.00000,26.00000,2.639140e-10,0.78718,4
300.01501,1133.59917,     -1.57508, 41.13194,50.00000,26.00000,2.642364e-10,0.78719,4
300.01700,1136.89917,     -1.57431, 41.09800,50.00000,26.00000,2.645663e-10,0.78719,4
300.00101,1140.19917,     -1.57544, 41.02355,50.00000,26.00000,2.647571e-10,0.78719,4
300.01099,1143.49917,     -1.57623, 40.98283,50.00000,26.00000,2.641620e-10,0.78720,4
300.00299,1146.79917,     -1.57487, 40.94232,50.00000,26.00000,2.646045e-10,0.78720,4
300.01300,1150.09917,     -1.57411, 40.87685,50.00000,26.00000,2.652035e-10,0.78719,4
300.01501,1153.39917,     -1.57411, 40.84970,50.00000,26.00000,2.648792e-10,0.78719,4
300.02301,1156.69917,     -1.57897, 40.76168,50.00000,26.00000,2.653503e-10,0.78719,4
300.01901,1159.99917,     -1.57915, 40.70060,50.00000,26.00000,2.648333e-10,0.78719,4
300.02200,1163.29917,     -1.58032, 40.64651,50.00000,26.00000,2.654019e-10,0.78719,4
300.01599,1166.59917,     -1.58127, 40.55389,50.00000,26.00000,2.647705e-10,0.78718,4
300.02499,1169.89917,     -1.58090, 40.47924,50.00000,26.00000,2.646999e-10,0.78718,4
300.02399,1173.19917,     -1.57974, 40.43872,50.00000,26.00000,2.650452e-10,0.78719,4
300.00800,1176.49917,     -1.57932, 40.38443,50.00000,26.00000,2.649632e-10,0.78719,4
300.01901,1179.79917,     -1.57915, 40.36188,50.00000,26.00000,2.650871e-10,0.78719,4
300.02301,1183.09917,     -1.57838, 40.26028,50.00000,25.00000,2.645607e-10,0.78718,4
300.01501,1186.39917,     -1.58011, 40.16547,50.00000,25.00000,2.647018e-10,0.78719,4
300.01099,1189.69917,     -1.57991, 40.15190,50.00000,25.00000,2.649899e-10,0.78719,4
300.01099,1192.99917,     -1.58204, 40.01637,50.00000,25.00000,2.646637e-10,0.78719,4
300.00699,1196.29917,     -1.58029, 39.99601,50.00000,25.00000,2.651348e-10,0.78718,4
300.01501,1199.59917,     -1.57992, 39.89222,50.00000,25.00000,2.650777e-10,0.78719,4
300.02301,1202.89917,     -1.58013, 39.90120,50.00000,25.00000,2.657796e-10,0.78719,4
300.00601,1206.19917,     -1.58029, 39.79281,50.00000,25.00000,2.649402e-10,0.78716,4
300.00601,1209.49917,     -1.58029, 39.75888,50.00000,25.00000,2.647515e-10,0.78720,4
300.02100,1212.79917,     -1.58418, 39.74531,50.00000,25.00000,2.655163e-10,0.78720,4
300.00400,1216.09917,     -1.58202, 39.63693,50.00000,25.00000,2.658463e-10,0.78720,4
300.02600,1219.39917,     -1.58013, 39.54212,50.00000,25.00000,2.658386e-10,0.78720,4
300.02100,1222.69917,     -1.58032, 39.53313,50.00000,25.00000,2.655505e-10,0.78719,4
300.02899,1225.99917,     -1.58091, 39.44731,50.00000,25.00000,2.658729e-10,0.78719,4
300.01199,1229.29917,     -1.57933, 39.35928,50.00000,25.00000,2.654591e-10,0.78719,4
300.02200,1232.59917,     -1.57935, 39.40000,50.00000,25.00000,2.657660e-10,0.78720,4
300.02399,1235.89917,     -1.58071, 39.31856,50.00000,25.00000,2.661743e-10,0.78719,4
300.00400,1239.19917,     -1.57893, 39.26447,50.00000,25.00000,2.663097e-10,0.78719,4
300.01700,1242.49917,     -1.57992, 39.18982,50.00000,25.00000,2.664051e-10,0.78719,4
300.02200,1245.79917,     -1.57916, 39.16048,50.00000,25.00000,2.676163e-10,0.78719,4
300.01401,1249.09917,     -1.58030, 39.05210,50.00000,25.00000,2.669716e-10,0.78719,4
299.99799,1252.39917,     -1.57969, 39.03413,50.00000,25.00000,2.667045e-10,0.78719,4
300.01700,1255.69917,     -1.58050, 38.97984,50.00000,25.00000,2.668610e-10,0.78721,4
300.03000,1257.09917,     -1.58575, 38.90539,50.00000,50.00000,2.669944e-10,0.78719,5
300.23599,1257.26417,     -1.53776, 38.78343,50.00000,50.00000,2.674294e-10,0.78719,5
300.83301,1257.42917,     -1.34889, 38.62535,50.00000,50.00000,2.675094e-10,0.78719,5
301.96301,1257.59417,     -1.00808, 38.05170,50.00000,50.00000,2.675094e-10,0.78719,5
303.65201,1257.75917,     -0.53993, 37.13054,50.00000,50.00000,2.674847e-10,0.78719,5
305.84000,1257.92417,-6.817968e-03, 36.93174,50.00000,50.00000,2.675437e-10,0.78719,5
308.41400,1258.08917,      0.52094, 37.43074,50.00000,50.00000,2.682495e-10,0.78718,5
311.26700,1258.25417,      0.99118, 38.00439,50.00000,50.00000,2.673625e-10,0.78719,5
314.25201,1258.41917,      1.36160, 38.53054,50.00000,50.00000,2.678337e-10,0.78720,5
317.26099,1258.58417,      1.61905, 38.87824,50.00000,50.00000,2.671508e-10,0.78718,5
320.23001,1258.74917,      1.76573, 39.08383,50.00000,50.00000,2.674865e-10,0.78719,5
323.12701,1258.91417,      1.82897, 39.14251,50.00000,50.00000,2.678108e-10,0.78719,5
325.97299,1259.07917,      1.83166, 39.16966,50.00000,50.00000,2.667770e-10,0.78719,5
328.78201,1259.24417,      1.81065, 39.19661,50.00000,50.00000,2.663059e-10,0.78719,5
331.61600,1259.40917,      1.79317, 39.22375,50.00000,50.00000,2.674942e-10,0.78719,5
334.50101,1259.57417,      1.79708, 39.22375,50.00000,50.00000,2.671815e-10,0.78718,5
337.46100,1259.73917,      1.83624, 39.30499,50.00000,50.00000,2.672654e-10,0.78719,5
340.54999,1259.90417,      1.90915, 39.34790,50.00000,50.00000,2.673798e-10,0.78720,5
343.75601,1260.06917,      2.01255, 39.38862,50.00000,50.00000,2.674370e-10,0.78719,5
347.09201,1260.23417,      2.13192, 39.46986,50.00000,50.00000,2.670764e-10,0.78719,5
350.51501,1260.39917,      2.25525, 39.52415,50.00000,50.00000,2.674140e-10,0.78719,5
354.02301,1260.56417,      2.36875, 39.55130,50.00000,50.00000,2.671966e-10,0.78720,5
357.57401,1260.72917,      2.46119, 39.59860,50.00000,50.00000,2.673874e-10,0.78720,5
361.14700,1260.89417,      2.53346, 39.57146,50.00000,50.00000,2.670460e-10,0.78720,5
364.73499,1261.05917,      2.58021, 39.55569,50.00000,50.00000,2.673569e-10,0.78720,5
368.33401,1261.22417,      2.60445, 39.52854,50.00000,50.00000,2.671014e-10,0.78720,5
371.92300,1261.38917,      2.60832, 39.47226,50.00000,50.00000,2.677383e-10,0.78720,5
375.49899,1261.55417,      2.60577, 39.41796,50.00000,50.00000,2.678413e-10,0.78717,5
379.09500,1261.71917,      2.59854, 39.26667,50.00000,50.00000,2.674179e-10,0.78719,5
382.65601,1261.88417,      2.59130, 39.11317,50.00000,50.00000,2.671185e-10,0.78720,5
386.24701,1262.04917,      2.58558, 38.90998,50.00000,50.00000,2.669810e-10,0.78720,5
389.85699,1262.21417,      2.58699, 38.66826,50.00000,50.00000,2.672177e-10,0.78719,5
393.45200,1262.37917,      2.59508, 38.36347,50.00000,50.00000,2.678489e-10,0.78720,5
397.06100,1262.54417,      2.60611, 37.96367,50.00000,50.00000,2.682381e-10,0.78719,5
400.68500,1262.70917,      2.62430, 37.49860,50.00000,50.00000,2.668285e-10,0.78720,5
404.30499,1262.87417,      2.64636, 36.91816,50.00000,50.00000,2.671451e-10,0.78719,5
407.91101,1263.03917,      2.66964, 36.27685,50.00000,50.00000,2.675723e-10,0.78718,5
411.53101,1263.20417,      2.69918, 35.40519,50.00000,50.00000,2.674141e-10,0.78718,5
415.13000,1263.36917,      2.72618, 34.47485,50.00000,50.00000,2.672081e-10,0.78719,5
418.71500,1263.53417,      2.75717, 33.30519,50.00000,50.00000,2.674313e-10,0.78720,5
422.28900,1263.69917,      2.78903, 32.02695,50.00000,50.00000,2.673244e-10,0.78719,5
425.84698,1263.86417,      2.82152, 30.60439,50.00000,50.00000,2.668991e-10,0.78719,5
429.41199,1264.02917,      2.84514, 29.02595,50.00000,50.00000,2.673798e-10,0.78718,5
432.94199,1264.19417,      2.85659, 27.37285,50.00000,50.00000,2.673702e-10,0.78719,5
436.47601,1264.35917,      2.85355, 25.59341,50.00000,50.00000,2.665252e-10,0.78719,5
440.00299,1264.52417,      2.83042, 23.82076,50.00000,50.00000,2.661248e-10,0.78718,5
443.51599,1264.68917,      2.78829, 22.01657,50.00000,50.00000,2.680645e-10,0.78720,5
447.01700,1264.85417,      2.72433, 20.25968,50.00000,50.00000,2.663594e-10,0.78719,5
450.51999,1265.01917,      2.63805, 18.64970,50.00000,50.00000,2.676049e-10,0.78718,5
454.00101,1265.18417,      2.53898, 17.12535,50.00000,50.00000,2.670097e-10,0.78719,5
457.51700,1265.34917,      2.42834, 15.71178,50.00000,50.00000,2.669220e-10,0.78719,5
460.96600,1265.51417,      2.31161, 14.41118,50.00000,50.00000,2.674999e-10,0.78720,5
464.43201,1265.67917,      2.19162, 13.25948,50.00000,50.00000,2.672385e-10,0.78719,5
467.88901,1265.84417,      2.07573, 12.15070,50.00000,50.00000,2.670002e-10,0.78719,5
471.35400,1266.00917,      1.96163, 11.21118,50.00000,50.00000,2.674770e-10,0.78719,5
474.80600,1266.17417,      1.85004, 10.32375,50.00000,50.00000,2.666359e-10,0.78719,5
478.24600,1266.33917,      1.73075,  9.60120,50.00000,50.00000,2.678165e-10,0.78720,5
481.67999,1266.50417,      1.60196,  9.01178,50.00000,50.00000,2.672138e-10,0.78720,5
485.09601,1266.66917,      1.45912,  8.60319,50.00000,50.00000,2.673263e-10,0.78719,5
488.49899,1266.83417,      1.31741,  8.30719,50.00000,50.00000,2.675247e-10,0.78719,5
491.90601,1266.99917,      1.17812,  8.14691,50.00000,50.00000,2.671471e-10,0.78718,5
495.31299,1267.16417,      1.05403,  8.09721,50.00000,50.00000,2.675017e-10,0.78720,5
498.70901,1267.32917,      0.94860,  8.06347,50.00000,50.00000,2.668056e-10,0.78719,5
502.10300,1267.49417,      0.85555,  8.06347,50.00000,50.00000,2.663441e-10,0.78718,5
505.50500,1267.65917,      0.76926,  8.06347,50.00000,50.00000,2.675858e-10,0.78719,5
508.89401,1267.82417,      0.69309,  8.06347,50.00000,50.00000,2.678242e-10,0.78718,5
512.27197,1267.98917,      0.61623,  8.11756,50.00000,50.00000,2.672233e-10,0.78719,5
515.63800,1268.15417,      0.53689,  8.13114,50.00000,50.00000,2.676868e-10,0.78719,5
519.00897,1268.31917,      0.45994,  8.11078,50.00000,50.00000,2.674636e-10,0.78719,5
522.36499,1268.48417,      0.37999,  8.11078,50.00000,50.00000,2.671718e-10,0.78720,5
525.73798,1268.64917,      0.30818,  8.08363,50.00000,50.00000,2.676754e-10,0.78719,5
529.09198,1268.81417,      0.23340,  8.08363,50.00000,50.00000,2.669850e-10,0.78718,5
532.45697,1268.97917,      0.16008,  8.08363,50.00000,50.00000,2.673339e-10,0.78719,5
535.80701,1269.14417, 8.851345e-02,  8.08363,50.00000,50.00000,2.674808e-10,0.78719,5
539.16498,1269.30917, 1.213163e-02,  8.04311,50.00000,50.00000,2.675152e-10,0.78719,5
542.50403,1269.47417,-5.905129e-02,  8.02954,50.00000,50.00000,2.672902e-10,0.78718,5
545.85101,1269.63917,     -0.13055,  8.01597,50.00000,50.00000,2.677440e-10,0.78719,5
549.18799,1269.80417,     -0.20795,  8.01597,50.00000,50.00000,2.669086e-10,0.78720,5
552.54102,1269.96917,     -0.27928,  8.02275,50.00000,50.00000,2.675400e-10,0.78720,5
555.87201,1270.13417,     -0.35708,  8.02275,50.00000,50.00000,2.677308e-10,0.78720,5
559.19800,1270.29917,     -0.43278,  8.02275,50.00000,50.00000,2.677193e-10,0.78719,5
562.52698,1270.46417,     -0.50851,  7.99561,50.00000,50.00000,2.662792e-10,0.78719,5
565.86603,1270.62917,     -0.58211,  7.99561,50.00000,50.00000,2.673988e-10,0.78719,5
569.19800,1270.79417,     -0.65517,  7.94152,50.00000,50.00000,2.669658e-10,0.78720,5
572.53003,1270.95917,     -0.72766,  7.94152,50.00000,50.00000,2.668381e-10,0.78720,5
575.85498,1271.12417,     -0.79463,  7.91437,50.00000,50.00000,2.670974e-10,0.78719,5
579.19397,1271.28917,     -0.86236,  7.91437,50.00000,50.00000,2.673168e-10,0.78719,5
582.52600,1271.45417,     -0.93169,  7.91437,50.00000,50.00000,2.675495e-10,0.78719,5
585.85101,1271.61917,     -1.00763,  7.91437,50.00000,50.00000,2.673416e-10,0.78719,5
589.17999,1271.78417,     -1.08214,  7.88723,50.00000,50.00000,2.674655e-10,0.78719,5
592.50000,1271.94917,     -1.16054,  7.88723,50.00000,50.00000,2.676316e-10,0.78720,5
595.82703,1272.11417,     -1.23919,  7.91437,50.00000,50.00000,2.682133e-10,0.78719,5
599.15503,1272.27917,     -1.31698,  7.86008,50.00000,50.00000,2.687855e-10,0.78718,5
602.48499,1272.44417,     -1.39018,  7.88723,50.00000,50.00000,2.670479e-10,0.78719,5
605.84003,1272.60917,     -1.46590,  7.86008,50.00000,50.00000,2.672196e-10,0.78720,5
609.12701,1272.77417,     -1.54114,  7.83313,50.00000,50.00000,2.669716e-10,0.78719,5
612.46899,1272.93917,     -1.61725,  7.86008,50.00000,50.00000,2.681885e-10,0.78719,5
615.78400,1273.10417,     -1.69035,  7.91437,50.00000,50.00000,2.672080e-10,0.78719,5
619.11401,1273.26917,     -1.76538,  7.86008,50.00000,50.00000,2.669010e-10,0.78720,5
622.43103,1273.43417,     -1.84666,  7.90978,50.00000,50.00000,2.672786e-10,0.78719,5
625.75598,1273.59917,     -1.92118,  7.86248,50.00000,50.00000,2.680244e-10,0.78718,5
629.06299,1273.76417,     -2.00050,  7.86248,50.00000,50.00000,2.675437e-10,0.78719,5
632.37500,1273.92917,     -2.08324,  7.88962,50.00000,50.00000,2.674370e-10,0.78719,5
635.69702,1274.09417,     -2.16621,  7.86248,50.00000,50.00000,2.679729e-10,0.78720,5
639.01099,1274.25917,     -2.25024,  7.88962,50.00000,50.00000,2.684784e-10,0.78719,5
642.32001,1274.42417,     -2.33329,  7.91657,50.00000,50.00000,2.677441e-10,0.78720,5
645.63098,1274.58917,     -2.42543,  7.90299,50.00000,50.00000,2.675075e-10,0.78718,5
648.95502,1274.75417,     -2.49908,  7.93014,50.00000,50.00000,2.675246e-10,0.78719,5
652.26703,1274.91917,     -2.58508,  7.93014,50.00000,50.00000,2.678909e-10,0.78719,5
655.60101,1275.08417,     -2.66532,  7.95729,50.00000,50.00000,2.681560e-10,0.78720,5
658.92297,1275.24917,     -2.74569,  7.95729,50.00000,50.00000,2.674637e-10,0.78719,5
662.24902,1275.41417,     -2.83345,  7.98443,50.00000,50.00000,2.675362e-10,0.78718,5
665.54700,1275.57917,     -2.91981,  8.03852,50.00000,50.00000,2.677441e-10,0.78719,5
668.87799,1275.74417,     -3.01039,  8.06567,50.00000,50.00000,2.674770e-10,0.78719,5
672.18402,1275.90917,     -3.11176,  8.09281,50.00000,50.00000,2.687016e-10,0.78720,5
675.50598,1276.07417,     -3.21772,  8.11976,50.00000,50.00000,2.681313e-10,0.78720,5
678.81403,1276.23917,     -3.31042,  8.11976,50.00000,50.00000,2.674904e-10,0.78719,5
682.13000,1276.40417,     -3.41595,  8.14691,50.00000,50.00000,2.681007e-10,0.78720,5
685.45300,1276.56917,     -3.51376,  8.14691,50.00000,50.00000,2.684097e-10,0.78719,5
688.76300,1276.73417,     -3.61886,  8.20120,50.00000,50.00000,2.679330e-10,0.78719,5
692.07599,1276.89917,     -3.73417,  8.20120,50.00000,50.00000,2.678947e-10,0.78719,5
695.39502,1277.06417,     -3.83954,  8.22156,50.00000,50.00000,2.685834e-10,0.78720,5
698.72302,1277.22917,     -3.94051,  8.25529,50.00000,50.00000,2.672061e-10,0.78719,5
702.05103,1277.39417,     -4.04483,  8.25529,50.00000,50.00000,2.680816e-10,0.78719,5
705.36499,1277.55917,     -4.16538,  8.30279,50.00000,50.00000,2.671776e-10,0.78720,5
708.69098,1277.72417,     -4.28064,  8.29601,50.00000,50.00000,2.675915e-10,0.78719,5
712.01099,1277.88917,     -4.40060,  8.26886,50.00000,50.00000,2.676449e-10,0.78719,5
715.32800,1278.05417,     -4.51929,  8.29601,50.00000,50.00000,2.677250e-10,0.78719,5
718.64301,1278.21917,     -4.64783,  8.35010,50.00000,50.00000,2.676944e-10,0.78719,5
721.95502,1278.38417,     -4.76620,  8.37725,50.00000,50.00000,2.683239e-10,0.78719,5
725.28998,1278.54917,     -4.88850,  8.37725,50.00000,50.00000,2.690620e-10,0.78720,5
728.60602,1278.71417,     -5.00849,  8.37725,50.00000,50.00000,2.687016e-10,0.78720,5
731.92999,1278.87917,     -5.12978,  8.40439,50.00000,50.00000,2.681884e-10,0.78720,5
735.25000,1279.04417,     -5.25106,  8.40439,50.00000,50.00000,2.677899e-10,0.78719,5
738.56299,1279.20917,     -5.37652,  8.43154,50.00000,50.00000,2.675228e-10,0.78719,5
741.88300,1279.37417,     -5.50756,  8.45848,50.00000,50.00000,2.674961e-10,0.78719,5
745.20099,1279.53917,     -5.64157,  8.48563,50.00000,50.00000,2.685242e-10,0.78719,5
748.52399,1279.70417,     -5.77013,  8.51737,50.00000,50.00000,2.674579e-10,0.78719,5
751.84198,1279.86917,     -5.89640,  8.51058,50.00000,50.00000,2.678947e-10,0.78719,5
755.16400,1280.03417,     -6.02633,  8.51737,50.00000,50.00000,2.675495e-10,0.78720,5
758.49597,1280.19917,     -6.14383,  8.54431,50.00000,50.00000,2.684345e-10,0.78719,5
761.81403,1280.36417,     -6.26585,  8.59860,50.00000,50.00000,2.685604e-10,0.78718,5
765.13898,1280.52917,     -6.38593,  8.59860,50.00000,50.00000,2.674694e-10,0.78719,5
768.45801,1280.69417,     -6.51428,  8.65269,50.00000,50.00000,2.673817e-10,0.78720,5
771.77197,1280.85917,     -6.63564,  8.67305,50.00000,50.00000,2.674484e-10,0.78719,5
775.08698,1281.02417,     -6.75667,  8.67984,50.00000,50.00000,2.678585e-10,0.78720,5
778.39801,1281.18917,     -6.87096,  8.67984,50.00000,50.00000,2.682686e-10,0.78719,5
781.71399,1281.35417,     -6.98693,  8.70699,50.00000,50.00000,2.682438e-10,0.78719,5
785.02399,1281.51917,     -7.10486,  8.70699,50.00000,50.00000,2.682705e-10,0.78719,5
788.34497,1281.68417,     -7.21439,  8.73413,50.00000,50.00000,2.686901e-10,0.78718,5
791.64600,1281.84917,     -7.32612,  8.78822,50.00000,50.00000,            ,0.44824,5
794.65601,1281.99917,     -7.43143,  8.80180,50.00000,50.00000,            ,0.44703,5