File: data/TGA/005d-L_M/ExpDat_2025_02_20_005d-L1-dynamic-1K.csv
#EXPORTTYPE:                 ,DATA ALL
#FILE:                       ,2025_02_20_005d-L1-dynamic-1K.ngb-ss5
#FORMAT:                     ,NETZSCH5
#FTYPE:                      ,ASCII
#IDENTITY:                   ,005d-L1
#DECIMAL:                    ,POINT
#SEPARATOR:                  ,COMMA
#MTYPE:                      ,DSC
#INSTRUMENT:                 ,NETZSCH STA 449F5
#PROJECT:                    ,PS
#DATE/TIME:                  ,2/21/2025 9:00:33 AM (UTC-5)
#CORR. FILE:                 ,
#TEMPCAL:                    ,13-11-2024 10:37
#SENSITIVITY:                ,28-06-2023 13:53
#LABORATORY:                 ,Tran/Aspuru
#OPERATOR:                   ,Stanley
#REMARK:                     ,
#SAMPLE:                     ,005d-L1
#SAMPLE MASS /mg:            ,5.31
#MATERIAL:                   ,
#REFERENCE:                  ,
#REFERENCE MASS /mg:         ,0
#TYPE OF CRUCIBLE:           ,Al2O3 85 ‘l, open
#SAMPLE CRUCIBLE MASS /mg:   ,0
#REFERENCE CRUCIBLE MASS /mg:,0
#DSC RANGE /‘V:              ,5000
#TG RANGE /mg:               ,35000
#TAU-R:                      ,---
#CORR. CODE:                 ,000
#EXO:                        ,-1
#RANGE:                      ,20›C....800›C/0.0....20.0K/min
#SEGMENT:                    ,S1-4/4
#SEG. 1:                     ,20›C/5.0(K/min)/100›C
#SEG. 2:                     ,100›C/00:05/100›C
#SEG. 3:                     ,100›C/1.0(K/min)/400›C
#SEG. 4:                     ,400›C/20.0(K/min)/800›C

##Temp./›C,Time/min,DSC/(mW/mg),Mass/%,Gas Flow(purge2)/(ml/min),Gas Flow(protective)/(ml/min),TIC(scan:1)/A,Sensit./(uV/mW),Segment
 28.81400,  0.00000,      0.34312,    100.00000,50.00000,35.00000,            ,0.92333,1
 29.93700,  1.06667,      0.10035,     99.87853,50.00000,34.00000,1.878738e-10,0.92339,1
 31.06800,  2.13333, 7.963649e-02,     94.20056,50.00000,34.00000,1.878491e-10,0.92349,1
 32.33800,  3.20000,      0.11383,     93.99605,50.00000,34.00000,1.876354e-10,0.92357,1
 34.45400,  4.26667,      0.23752,     94.15160,50.00000,34.00000,1.879139e-10,0.92366,1
 37.64800,  5.33333,      0.39681,     94.53936,50.00000,34.00000,1.879654e-10,0.92374,1
 41.87700,  6.40000,      0.55637,     94.93145,50.00000,34.00000,1.876163e-10,0.92382,1
 46.96100,  7.46667,      0.70120,     95.35537,50.00000,34.00000,1.885986e-10,0.92392,1
 52.70900,  8.53333,      0.82988,     95.71337,50.00000,34.00000,1.884269e-10,0.92402,1
 58.97700,  9.60000,      0.93372,     95.94991,50.00000,34.00000,1.884289e-10,0.92417,1
 65.48700, 10.66667,      1.00957,     96.07119,50.00000,34.00000,1.882686e-10,0.92431,1
 72.05900, 11.73333,      1.06512,     96.07759,50.00000,34.00000,1.884784e-10,0.92451,1
 78.62000, 12.80000,      1.10364,     96.07119,50.00000,34.00000,1.892910e-10,0.92469,1
 85.08500, 13.86667,      1.13069,     95.96893,50.00000,34.00000,1.885872e-10,0.92491,1
 91.46300, 14.93333,      1.15249,     95.81563,50.00000,34.00000,1.885186e-10,0.92510,1
 97.29400, 15.93500,      1.16855,     95.63653,50.00000,34.00000,1.883239e-10,0.92529,1
101.39800, 16.73500,      1.03451,     95.18493,50.00000,34.00000,1.891060e-10,0.92545,2
104.06500, 17.53500,      0.69374,     94.46478,50.00000,34.00000,1.891746e-10,0.92560,2
105.81200, 18.33500,      0.45409,     93.99812,50.00000,34.00000,1.892643e-10,0.92573,2
107.01900, 19.13500,      0.30294,     93.59981,50.00000,34.00000,1.896286e-10,0.92586,2
107.69800, 19.93500,      0.16104,     93.19492,50.00000,34.00000,1.886845e-10,0.92596,2
107.87400, 20.73500, 2.517378e-02,     92.79228,50.00000,34.00000,1.882858e-10,0.92605,2
107.65200, 21.73500,-7.379622e-02,     92.43013,50.00000,34.00000,1.884574e-10,0.92614,3
107.40300, 22.80167,-7.644815e-02,     92.22561,50.00000,34.00000,1.883907e-10,0.92619,3
107.12400, 23.86833,-7.097021e-02,     92.04652,50.00000,34.00000,1.890545e-10,0.92620,3
106.98300, 24.93500,-5.205295e-02,     91.89322,50.00000,34.00000,1.892548e-10,0.92616,3
106.97300, 26.00167,-1.422464e-02,     91.81657,50.00000,34.00000,1.893902e-10,0.92609,3
107.20400, 27.06833, 2.641908e-02,     91.74614,50.00000,34.00000,1.893024e-10,0.92596,3
107.59500, 28.13500, 6.754108e-02,     91.71431,50.00000,34.00000,1.891365e-10,0.92581,3
108.15700, 29.20167,      0.10211,     91.68004,50.00000,34.00000,1.893024e-10,0.92558,3
108.89600, 30.26833,      0.13436,     91.65461,50.00000,34.00000,1.891994e-10,0.92535,3
109.74400, 31.33500,      0.16099,     91.57778,50.00000,33.00000,1.891251e-10,0.92503,3
110.69400, 32.40167,      0.18420,     91.59699,50.00000,33.00000,1.893425e-10,0.92467,3
111.72200, 33.46833,      0.20055,     91.57156,50.00000,33.00000,1.895026e-10,0.92432,3
112.79900, 34.53500,      0.21112,     91.55235,50.00000,33.00000,1.892891e-10,0.92387,3
113.89800, 35.60167,      0.21997,     91.50753,50.00000,33.00000,1.902141e-10,0.92345,3
115.00200, 36.66833,      0.22554,     91.47552,50.00000,33.00000,1.893768e-10,0.92293,3
116.14100, 37.73500,      0.22893,     91.46290,50.00000,33.00000,1.896190e-10,0.92245,3
117.26700, 38.80167,      0.23153,     91.40734,50.00000,33.00000,1.899376e-10,0.92185,3
118.38900, 39.86833,      0.23210,     91.38192,50.00000,33.00000,1.902027e-10,0.92147,3
119.50700, 40.93500,      0.23173,     91.33070,50.00000,33.00000,1.897621e-10,0.92103,3
120.60400, 42.00167,      0.23073,     91.33070,50.00000,33.00000,1.897812e-10,0.92068,3
121.72200, 43.06833,      0.23288,     91.31789,50.00000,33.00000,1.894111e-10,0.92033,3
122.81700, 44.13500,      0.23361,     91.29228,50.00000,33.00000,1.898994e-10,0.92009,3
123.90000, 45.20167,      0.23340,     91.29868,50.00000,33.00000,1.904202e-10,0.91984,3
124.97700, 46.26833,      0.23334,     91.27326,50.00000,33.00000,1.906643e-10,0.91966,3
126.06600, 47.33500,      0.23361,     91.26045,50.00000,33.00000,1.900635e-10,0.91947,3
127.13000, 48.40167,      0.23214,     91.27326,50.00000,33.00000,1.895428e-10,0.91931,3
128.19400, 49.46833,      0.23398,     91.27326,50.00000,33.00000,1.902351e-10,0.91919,3
129.25800, 50.53500,      0.23504,     91.27326,50.00000,33.00000,1.904163e-10,0.91908,3
130.30499, 51.60167,      0.23578,     91.28606,50.00000,33.00000,1.905079e-10,0.91900,3
131.39200, 52.66833,      0.23668,     91.27326,50.00000,33.00000,1.901130e-10,0.91896,3
132.47200, 53.73500,      0.23775,     91.29868,50.00000,33.00000,1.898403e-10,0.91892,3
133.53101, 54.80167,      0.23802,     91.30508,50.00000,33.00000,1.905289e-10,0.91891,3
134.60800, 55.86833,      0.23957,     91.30508,50.00000,33.00000,1.912575e-10,0.91892,3
135.67000, 56.93500,      0.23874,     91.33070,50.00000,33.00000,1.908017e-10,0.91895,3
136.72701, 58.00167,      0.23870,     91.33070,50.00000,33.00000,1.909180e-10,0.91899,3
137.80099, 59.06833,      0.23962,     91.33710,50.00000,33.00000,1.906986e-10,0.91902,3
138.86600, 60.13500,      0.24101,     91.36045,50.00000,33.00000,1.907902e-10,0.91905,3
139.93600, 61.20167,      0.24083,     91.38606,50.00000,33.00000,1.903801e-10,0.91908,3
140.98801, 62.26833,      0.24159,     91.39040,50.00000,33.00000,1.907730e-10,0.91910,3
142.06000, 63.33500,      0.24267,     91.41601,50.00000,33.00000,1.901931e-10,0.91914,3
143.13699, 64.40167,      0.24217,     91.42881,50.00000,33.00000,1.902618e-10,0.91915,3
144.21400, 65.46833,      0.24215,     91.47345,50.00000,33.00000,1.906261e-10,0.91917,3
145.25600, 66.53500,      0.24181,     91.51827,50.00000,33.00000,1.911621e-10,0.91918,3
146.33099, 67.60167,      0.24211,     91.47778,50.00000,33.00000,1.914539e-10,0.91918,3
147.41000, 68.66833,      0.24161,     91.52881,50.00000,33.00000,1.905613e-10,0.91916,3
148.46899, 69.73500,      0.24112,     91.49699,50.00000,33.00000,1.910705e-10,0.91914,3
149.53300, 70.80167,      0.24062,     91.54802,50.00000,33.00000,1.914138e-10,0.91910,3
150.61600, 71.86833,      0.24093,     91.57363,50.00000,33.00000,1.906433e-10,0.91907,3
151.68700, 72.93500,      0.24076,     91.59925,50.00000,33.00000,1.911316e-10,0.91902,3
152.75500, 74.00167,      0.23899,     91.60565,50.00000,33.00000,1.904983e-10,0.91895,3
153.81300, 75.06833,      0.23818,     91.61186,50.00000,33.00000,1.916370e-10,0.91889,3
154.89000, 76.13500,      0.23897,     91.63748,50.00000,33.00000,1.908798e-10,0.91883,3
155.97099, 77.20167,      0.23912,     91.67589,50.00000,33.00000,1.908913e-10,0.91873,3
157.03400, 78.26833,      0.23767,     91.68870,50.00000,33.00000,1.912098e-10,0.91865,3
158.11400, 79.33500,      0.23591,     91.71431,50.00000,33.00000,1.913605e-10,0.91855,3
159.17200, 80.40167,      0.23430,     91.73974,50.00000,33.00000,1.908703e-10,0.91845,3
160.23199, 81.46833,      0.23445,     91.72693,50.00000,33.00000,1.910114e-10,0.91834,3
161.29601, 82.53500,      0.23236,     91.75254,50.00000,33.00000,1.906414e-10,0.91821,3
162.40500, 83.60167,      0.23300,     91.77815,50.00000,33.00000,1.909771e-10,0.91811,3
163.44400, 84.66833,      0.23090,     91.77815,50.00000,33.00000,1.915436e-10,0.91797,3
164.50301, 85.73500,      0.22849,     91.82279,50.00000,33.00000,1.912822e-10,0.91785,3
165.56200, 86.80167,      0.22720,     91.82279,50.00000,33.00000,1.910591e-10,0.91771,3
166.63699, 87.86833,      0.22526,     91.84840,50.00000,33.00000,1.911660e-10,0.91758,3
167.71001, 88.93500,      0.22397,     91.87194,50.00000,33.00000,1.912346e-10,0.91743,3
168.77000, 90.00167,      0.22187,     91.88475,50.00000,33.00000,1.909867e-10,0.91730,3
169.82300, 91.06833,      0.21896,     91.88475,50.00000,33.00000,1.906681e-10,0.91715,3
170.88901, 92.13500,      0.21557,     91.88475,50.00000,33.00000,1.907826e-10,0.91702,3
171.97501, 93.20167,      0.21331,     91.91017,50.00000,33.00000,1.905556e-10,0.91686,3
173.02000, 94.26833,      0.20958,     91.95499,50.00000,33.00000,1.909828e-10,0.91672,3
174.09000, 95.33500,      0.20731,     91.98060,50.00000,33.00000,1.912135e-10,0.91655,3
175.16400, 96.40167,      0.20536,     91.98060,50.00000,33.00000,1.910476e-10,0.91642,3
176.23500, 97.46833,      0.20292,     91.99981,50.00000,33.00000,1.911145e-10,0.91625,3
177.29900, 98.53500,      0.20032,     92.01883,50.00000,33.00000,1.910038e-10,0.91610,3
178.35001, 99.60167,      0.19820,     92.01883,50.00000,33.00000,1.906471e-10,0.91594,3
179.41200,100.66833,      0.19396,     92.02524,50.00000,33.00000,1.912441e-10,0.91579,3
180.48900,101.73500,      0.19103,     92.06365,50.00000,33.00000,1.908893e-10,0.91563,3
181.56000,102.80167,      0.18776,     92.05725,50.00000,33.00000,1.906490e-10,0.91548,3
182.63000,103.86833,      0.18579,     92.07006,50.00000,33.00000,1.912136e-10,0.91530,3
183.69099,104.93500,      0.18121,     92.10829,50.00000,33.00000,1.913623e-10,0.91516,3
184.75500,106.00167,      0.17826,     92.11469,50.00000,33.00000,1.913166e-10,0.91499,3
185.83400,107.06833,      0.17563,     92.12109,50.00000,33.00000,1.905727e-10,0.91481,3
186.90401,108.13500,      0.17300,     92.13390,50.00000,33.00000,1.904564e-10,0.91466,3
187.99699,109.20167,      0.16808,     92.15951,50.00000,33.00000,1.902447e-10,0.91452,3
189.05600,110.26833,      0.16429,     92.15951,50.00000,33.00000,1.911698e-10,0.91434,3
190.11000,111.33500,      0.15951,     92.18512,50.00000,33.00000,1.914501e-10,0.91419,3
191.17799,112.40167,      0.15801,     92.18512,50.00000,33.00000,1.909542e-10,0.91401,3
192.24500,113.46833,      0.15355,     92.19793,50.00000,33.00000,1.911583e-10,0.91386,3
193.31100,114.53500,      0.15056,     92.22335,50.00000,33.00000,1.905765e-10,0.91368,3
194.36400,115.60167,      0.14658,     92.22976,50.00000,33.00000,1.918564e-10,0.91350,3
195.44501,116.66833,      0.14457,     92.24256,50.00000,33.00000,1.909485e-10,0.91334,3
196.49800,117.73500,      0.13927,     92.28098,50.00000,33.00000,1.920128e-10,0.91317,3
197.57401,118.80167,      0.13626,     92.29379,50.00000,33.00000,1.916638e-10,0.91302,3
198.63100,119.86833,      0.13341,     92.30659,50.00000,33.00000,1.914768e-10,0.91283,3
199.71001,120.93500,      0.12875,     92.31940,50.00000,33.00000,1.914120e-10,0.91268,3
200.76100,122.00167,      0.12671,     92.31940,50.00000,33.00000,1.920395e-10,0.91249,3
201.83900,123.06833,      0.12204,     92.31940,50.00000,33.00000,1.911029e-10,0.91233,3
202.89600,124.13500,      0.12082,     92.34482,50.00000,33.00000,1.917820e-10,0.91215,3
203.97000,125.20167,      0.11481,     92.39605,50.00000,33.00000,1.917362e-10,0.91199,3
205.02800,126.26833,      0.11243,     92.39605,50.00000,33.00000,1.917496e-10,0.91181,3
206.09801,127.33500,      0.10921,     92.40245,50.00000,33.00000,1.914921e-10,0.91165,3
207.15601,128.40167,      0.10433,     92.42166,50.00000,33.00000,1.913548e-10,0.91146,3
208.23399,129.46833,      0.10078,     92.42787,50.00000,33.00000,1.915093e-10,0.91130,3
209.30499,130.53500, 9.571794e-02,     92.46629,50.00000,33.00000,1.915932e-10,0.91111,3
210.37100,131.60167, 9.264540e-02,     92.44068,50.00000,33.00000,1.917591e-10,0.91094,3
211.42799,132.66833, 8.823506e-02,     92.46629,50.00000,33.00000,1.916618e-10,0.91075,3
212.49001,133.73500, 8.181774e-02,     92.47910,50.00000,33.00000,1.915111e-10,0.91059,3
213.56500,134.80167, 7.955953e-02,     92.48550,50.00000,33.00000,1.920452e-10,0.91039,3
214.63400,135.86833, 7.579445e-02,     92.49831,50.00000,33.00000,1.911964e-10,0.91021,3
215.69000,136.93500, 7.035071e-02,     92.53032,50.00000,33.00000,1.914559e-10,0.91002,3
216.76100,138.00167, 6.573426e-02,     92.52392,50.00000,33.00000,1.914654e-10,0.90985,3
217.82300,139.06833, 6.027167e-02,     92.53653,50.00000,33.00000,1.913051e-10,0.90966,3
218.89200,140.13500, 5.714542e-02,     92.56215,50.00000,33.00000,1.921691e-10,0.90949,3
219.94400,141.20167, 5.183193e-02,     92.56215,50.00000,33.00000,1.920910e-10,0.90929,3
221.02299,142.26833, 4.936404e-02,     92.58136,50.00000,33.00000,1.917114e-10,0.90911,3
222.08600,143.33500, 4.252107e-02,     92.58983,50.00000,33.00000,1.911773e-10,0.90891,3
223.14799,144.40167, 3.919780e-02,     92.62392,50.00000,33.00000,1.916332e-10,0.90873,3
224.21800,145.46833, 3.468968e-02,     92.62185,50.00000,33.00000,1.912251e-10,0.90853,3
225.29900,146.53500, 2.764463e-02,     92.62185,50.00000,33.00000,1.909657e-10,0.90835,3
226.35600,147.60167, 2.345351e-02,     92.61544,50.00000,33.00000,1.912289e-10,0.90816,3
227.41200,148.66833, 1.925421e-02,     92.64105,50.00000,33.00000,1.921807e-10,0.90797,3
228.49400,149.73500, 1.369451e-02,     92.64105,50.00000,33.00000,1.919594e-10,0.90776,3
229.54500,150.80167, 8.292536e-03,     92.66026,50.00000,33.00000,1.915226e-10,0.90759,3
230.62801,151.86833, 2.879952e-03,     92.68569,50.00000,33.00000,1.913929e-10,0.90737,3
231.69000,152.93500,-1.187060e-03,     92.68569,50.00000,33.00000,1.917801e-10,0.90719,3
232.76500,154.00167,-8.317956e-03,     92.67307,50.00000,34.00000,1.922626e-10,0.90698,3
233.82300,155.06833,-1.240464e-02,     92.72411,50.00000,34.00000,1.923561e-10,0.90679,3
234.89600,156.13500,-1.581952e-02,     92.71130,50.00000,34.00000,1.918030e-10,0.90658,3
235.95399,157.20167,-2.332789e-02,     92.73691,50.00000,34.00000,1.914978e-10,0.90640,3
237.02699,158.26833,-2.880677e-02,     92.76252,50.00000,34.00000,1.911945e-10,0.90619,3
238.08501,159.33500,-3.429672e-02,     92.78795,50.00000,34.00000,1.919765e-10,0.90599,3
239.13901,160.40167,-3.962719e-02,     92.81996,50.00000,34.00000,1.912365e-10,0.90577,3
240.21800,161.46833,-4.565390e-02,     92.79661,50.00000,34.00000,1.916962e-10,0.90555,3
241.28300,162.53500,-5.049473e-02,     92.79021,50.00000,34.00000,1.914882e-10,0.90536,3
242.35001,163.60167,-5.517470e-02,     92.87966,50.00000,34.00000,1.915703e-10,0.90515,3
243.42101,164.66833,-6.192344e-02,     92.82637,50.00000,34.00000,1.915226e-10,0.90495,3
244.48599,165.73500,-6.988844e-02,     92.83917,50.00000,34.00000,1.919937e-10,0.90473,3
245.54100,166.80167,-7.546334e-02,     92.83917,50.00000,34.00000,1.915989e-10,0.90454,3
246.61800,167.86833,-8.225675e-02,     92.83917,50.00000,34.00000,1.915168e-10,0.90431,3
247.67599,168.93500,-8.716854e-02,     92.87119,50.00000,34.00000,1.919670e-10,0.90412,3
248.75500,170.00167,-9.347280e-02,     92.87119,50.00000,34.00000,1.921635e-10,0.90389,3
249.81300,171.06833,     -0.10013,     92.89661,50.00000,34.00000,1.915073e-10,0.90369,3
250.88800,172.13500,     -0.10629,     92.89661,50.00000,34.00000,1.918507e-10,0.90346,3
251.94901,173.20167,     -0.11299,     92.91582,50.00000,34.00000,1.920910e-10,0.90327,3
253.01900,174.26833,     -0.11865,     92.92015,50.00000,34.00000,1.918068e-10,0.90303,3
254.08900,175.33500,     -0.12798,     92.92655,50.00000,34.00000,1.917820e-10,0.90284,3
255.14500,176.40167,     -0.13298,     92.90094,50.00000,34.00000,1.920948e-10,0.90264,3
256.22198,177.46833,     -0.13938,     92.91375,50.00000,34.00000,1.918755e-10,0.90240,3
257.27701,178.53500,     -0.14615,     92.92655,50.00000,34.00000,1.928100e-10,0.90217,3
258.33899,179.60167,     -0.15328,     92.93936,50.00000,34.00000,1.923943e-10,0.90196,3
259.41599,180.66833,     -0.15694,     92.93936,50.00000,34.00000,1.931972e-10,0.90173,3
260.46701,181.73500,     -0.16969,     92.93296,50.00000,34.00000,1.932354e-10,0.90152,3
261.53500,182.80167,     -0.17530,     92.92863,50.00000,34.00000,1.933250e-10,0.90128,3
262.60400,183.86833,     -0.18040,     92.92222,50.00000,34.00000,1.934147e-10,0.90108,3
263.66901,184.93500,     -0.18778,     92.94783,50.00000,34.00000,1.927032e-10,0.90084,3
264.75601,186.00167,     -0.19414,     92.92863,50.00000,34.00000,1.926269e-10,0.90063,3
265.81299,187.06833,     -0.20104,     92.93503,50.00000,34.00000,1.932602e-10,0.90038,3
266.87601,188.13500,     -0.20812,     92.96704,50.00000,34.00000,1.922607e-10,0.90017,3
267.94901,189.20167,     -0.21400,     92.94143,50.00000,34.00000,1.935520e-10,0.89997,3
269.02100,190.26833,     -0.21689,     92.94143,50.00000,34.00000,1.933365e-10,0.89972,3
270.07300,191.33500,     -0.22878,     92.95424,50.00000,34.00000,1.931190e-10,0.89951,3
271.15302,192.40167,     -0.23241,     92.94143,50.00000,34.00000,1.932240e-10,0.89926,3
272.21399,193.46833,     -0.23869,     92.92863,50.00000,34.00000,1.935634e-10,0.89905,3
273.27600,194.53500,     -0.24924,     92.92863,50.00000,34.00000,1.933994e-10,0.89880,3
274.34799,195.60167,     -0.25715,     92.92222,50.00000,34.00000,1.928653e-10,0.89858,3
275.41199,196.66833,     -0.26455,     92.91582,50.00000,34.00000,1.933041e-10,0.89833,3
276.46799,197.73500,     -0.27179,     92.89021,50.00000,34.00000,1.930104e-10,0.89812,3
277.54401,198.80167,     -0.28012,     92.86478,50.00000,34.00000,1.934795e-10,0.89787,3
278.60101,199.86833,     -0.28669,     92.91808,50.00000,34.00000,1.929836e-10,0.89765,3
279.67099,200.93500,     -0.29363,     92.86685,50.00000,34.00000,1.935768e-10,0.89739,3
280.73700,202.00167,     -0.30094,     92.87326,50.00000,34.00000,1.935520e-10,0.89717,3
281.80099,203.06833,     -0.30828,     92.82429,50.00000,34.00000,1.931095e-10,0.89692,3
282.86499,204.13500,     -0.31652,     92.81149,50.00000,34.00000,1.931667e-10,0.89670,3
283.92700,205.20167,     -0.32425,     92.79868,50.00000,34.00000,1.927738e-10,0.89644,3
285.01501,206.26833,     -0.33308,     92.77307,50.00000,34.00000,1.938762e-10,0.89621,3
286.06799,207.33500,     -0.34228,     92.73484,50.00000,34.00000,1.927128e-10,0.89596,3
287.13800,208.40167,     -0.35097,     92.70923,50.00000,34.00000,1.932087e-10,0.89570,3
288.20001,209.46833,     -0.35842,     92.70716,50.00000,34.00000,1.932983e-10,0.89547,3
289.25500,210.53500,     -0.36499,     92.66234,50.00000,34.00000,1.934738e-10,0.89525,3
290.33200,211.60167,     -0.36977,     92.63672,50.00000,34.00000,1.935673e-10,0.89498,3
291.39999,212.66833,     -0.37800,     92.58569,50.00000,34.00000,1.932640e-10,0.89476,3
292.46701,213.73500,     -0.38480,     92.52166,50.00000,34.00000,1.935234e-10,0.89450,3
293.53101,214.80167,     -0.39343,     92.48343,50.00000,34.00000,1.933288e-10,0.89427,3
294.58899,215.86833,     -0.39736,     92.45782,50.00000,34.00000,1.937046e-10,0.89400,3
295.66901,216.93500,     -0.39823,     92.42580,50.00000,34.00000,1.933765e-10,0.89377,3
296.72800,218.00167,     -0.40981,     92.37476,50.00000,34.00000,1.933135e-10,0.89350,3
297.78101,219.06833,     -0.41524,     92.32994,50.00000,34.00000,1.938572e-10,0.89327,3
298.87201,220.13500,     -0.42434,     92.27250,50.00000,34.00000,1.938954e-10,0.89300,3
299.92599,221.20167,     -0.42669,     92.21488,50.00000,34.00000,1.930675e-10,0.89277,3
300.99701,222.26833,     -0.41609,     92.13616,50.00000,34.00000,1.939430e-10,0.89250,3
302.04401,223.33500,     -0.42100,     92.08493,50.00000,34.00000,1.935844e-10,0.89226,3
303.12000,224.40167,     -0.42960,     92.02109,50.00000,34.00000,1.931229e-10,0.89199,3
304.19800,225.46833,     -0.43877,     91.93145,50.00000,34.00000,1.939755e-10,0.89175,3
305.25601,226.53500,     -0.45145,     91.86761,50.00000,34.00000,1.939163e-10,0.89148,3
306.31000,227.60167,     -0.45570,     91.80377,50.00000,34.00000,1.938534e-10,0.89124,3
307.40399,228.66833,     -0.46642,     91.70151,50.00000,34.00000,1.945229e-10,0.89096,3
308.45599,229.73500,     -0.47550,     91.61827,50.00000,34.00000,1.933994e-10,0.89073,3
309.53201,230.80167,     -0.48627,     91.51601,50.00000,34.00000,1.946029e-10,0.89049,3
310.58401,231.86833,     -0.49243,     91.38832,50.00000,34.00000,1.933670e-10,0.89020,3
311.65799,232.93500,     -0.50381,     91.28606,50.00000,34.00000,1.939469e-10,0.88996,3
312.72400,234.00167,     -0.51429,     91.18362,50.00000,34.00000,1.939773e-10,0.88969,3
313.78900,235.06833,     -0.52200,     91.10697,50.00000,34.00000,1.937256e-10,0.88941,3
314.86499,236.13500,     -0.53272,     90.92599,50.00000,34.00000,1.938362e-10,0.88917,3
315.91501,237.20167,     -0.54197,     90.76817,50.00000,34.00000,1.945057e-10,0.88889,3
316.98499,238.26833,     -0.54939,     90.67232,50.00000,34.00000,1.938857e-10,0.88864,3
318.06601,239.33500,     -0.56056,     90.48493,50.00000,34.00000,1.939640e-10,0.88836,3
319.10901,240.40167,     -0.56707,     90.30584,50.00000,34.00000,1.938209e-10,0.88811,3
320.19699,241.46833,     -0.57961,     90.15254,50.00000,34.00000,1.934986e-10,0.88782,3
321.25500,242.53500,     -0.58899,     89.97345,50.00000,34.00000,1.937618e-10,0.88758,3
322.32901,243.60167,     -0.60083,     89.85631,50.00000,34.00000,1.936283e-10,0.88729,3
323.38199,244.66833,     -0.60650,     89.55386,50.00000,34.00000,1.933536e-10,0.88703,3
324.45200,245.73500,     -0.61765,     89.34934,50.00000,34.00000,1.939621e-10,0.88675,3
325.52301,246.80167,     -0.62337,     89.10640,50.00000,34.00000,1.937217e-10,0.88650,3
326.59201,247.86833,     -0.63551,     88.83785,50.00000,34.00000,1.940040e-10,0.88621,3
327.67499,248.93500,     -0.62976,     88.59284,50.00000,34.00000,1.937752e-10,0.88596,3
328.72501,250.00167,     -0.64023,     88.28192,50.00000,34.00000,1.940079e-10,0.88566,3
329.79099,251.06833,     -0.65301,     87.94727,50.00000,34.00000,1.938285e-10,0.88542,3
330.85699,252.13500,     -0.65976,     87.61281,50.00000,34.00000,1.938743e-10,0.88512,3
331.92300,253.20167,     -0.66596,     87.25273,50.00000,34.00000,1.948585e-10,0.88486,3
332.99799,254.26833,     -0.67579,     86.89058,50.00000,34.00000,1.950645e-10,0.88457,3
334.06900,255.33500,     -0.68527,     86.50716,50.00000,34.00000,1.938400e-10,0.88431,3
335.13400,256.40167,     -0.69572,     86.06610,50.00000,34.00000,1.941662e-10,0.88401,3
336.17801,257.46833,     -0.70752,     85.61864,50.00000,34.00000,1.943188e-10,0.88376,3
337.26099,258.53500,     -0.71040,     85.12655,50.00000,34.00000,1.944752e-10,0.88350,3
338.33499,259.60167,     -0.72228,     84.63635,50.00000,34.00000,1.946030e-10,0.88320,3
339.38901,260.66833,     -0.73167,     84.10377,50.00000,34.00000,1.947880e-10,0.88293,3
340.45099,261.73500,     -0.73535,     83.57759,50.00000,34.00000,1.945286e-10,0.88263,3
341.50699,262.80167,     -0.74479,     82.93409,50.00000,34.00000,1.947308e-10,0.88237,3
342.58099,263.86833,     -0.75274,     82.34614,50.00000,34.00000,1.941796e-10,0.88206,3
343.64700,264.93500,     -0.76070,     81.63861,50.00000,34.00000,1.948967e-10,0.88181,3
344.70901,266.00167,     -0.76598,     80.92712,50.00000,34.00000,1.946945e-10,0.88151,3
345.78299,267.06833,     -0.77457,     80.16215,50.00000,34.00000,1.940250e-10,0.88124,3
346.84698,268.13500,     -0.78337,     79.37175,50.00000,34.00000,1.944599e-10,0.88094,3
347.92300,269.20167,     -0.78736,     78.54087,50.00000,34.00000,1.938133e-10,0.88067,3
348.98499,270.26833,     -0.79678,     77.63315,50.00000,34.00000,1.939659e-10,0.88036,3
350.06201,271.33500,     -0.80643,     76.68079,50.00000,34.00000,1.942863e-10,0.88010,3
351.12701,272.40167,     -0.81104,     75.68795,50.00000,34.00000,1.943512e-10,0.87977,3
352.17700,273.46833,     -0.82013,     74.62693,50.00000,34.00000,1.939697e-10,0.87951,3
353.23499,274.53500,     -0.82847,     73.49567,50.00000,34.00000,1.948395e-10,0.87919,3
354.31799,275.60167,     -0.83549,     72.31959,50.00000,34.00000,1.949215e-10,0.87892,3
355.37701,276.66833,     -0.84290,     71.07100,50.00000,34.00000,1.948280e-10,0.87862,3
356.44800,277.73500,     -0.85641,     69.76290,50.00000,34.00000,1.951637e-10,0.87835,3
357.50800,278.80167,     -0.86504,     68.38230,50.00000,35.00000,1.956692e-10,0.87808,3
358.58801,279.86833,     -0.87274,     66.94614,50.00000,35.00000,1.948604e-10,0.87776,3
359.64200,280.93500,     -0.88613,     65.45273,50.00000,35.00000,1.946926e-10,0.87744,3
360.71701,282.00167,     -0.89250,     63.83974,50.00000,35.00000,1.953487e-10,0.87718,3
361.78299,283.06833,     -0.90439,     62.18644,50.00000,35.00000,1.946907e-10,0.87686,3
362.84500,284.13500,     -0.91828,     60.44162,50.00000,35.00000,1.956673e-10,0.87659,3
363.91101,285.20167,     -0.92886,     58.62411,50.00000,35.00000,1.957894e-10,0.87627,3
364.98499,286.26833,     -0.94324,     56.79605,50.00000,35.00000,1.950684e-10,0.87600,3
366.03699,287.33500,     -0.95803,     54.85725,50.00000,35.00000,1.955394e-10,0.87568,3
367.11301,288.40167,     -0.97130,     52.86723,50.00000,35.00000,1.960774e-10,0.87540,3
368.17999,289.46833,     -0.98956,     50.84539,50.00000,35.00000,1.956100e-10,0.87508,3
369.23999,290.53500,     -1.00807,     48.74463,50.00000,35.00000,1.960965e-10,0.87481,3
370.30600,291.60167,     -1.03043,     46.62260,50.00000,35.00000,1.964302e-10,0.87448,3
371.37399,292.66833,     -1.05125,     44.44294,50.00000,35.00000,1.967716e-10,0.87420,3
372.45200,293.73500,     -1.07534,     42.21864,50.00000,35.00000,1.954917e-10,0.87387,3
373.50500,294.80167,     -1.10007,     40.05179,50.00000,35.00000,1.965637e-10,0.87359,3
374.58401,295.86833,     -1.13393,     37.84463,50.00000,35.00000,1.970463e-10,0.87327,3
375.63699,296.93500,     -1.16242,     35.65009,50.00000,35.00000,1.959534e-10,0.87300,3
376.71500,298.00167,     -1.19847,     33.43635,50.00000,35.00000,1.961479e-10,0.87267,3
377.77301,299.06833,     -1.23379,     31.31017,50.00000,35.00000,1.968441e-10,0.87239,3
378.83600,300.13500,     -1.26558,     29.18173,50.00000,35.00000,1.969147e-10,0.87205,3
379.91699,301.20167,     -1.30011,     27.08719,50.00000,35.00000,1.969242e-10,0.87177,3
380.98901,302.26833,     -1.33453,     25.05254,50.00000,35.00000,1.969490e-10,0.87144,3
382.05301,303.33500,     -1.36741,     23.07119,50.00000,35.00000,1.968747e-10,0.87116,3
383.12000,304.40167,     -1.40545,     21.15782,50.00000,35.00000,1.970997e-10,0.87087,3
384.17401,305.46833,     -1.44216,     19.33842,50.00000,35.00000,1.969681e-10,0.87055,3
385.23499,306.53500,     -1.47898,     17.55725,50.00000,35.00000,1.968231e-10,0.87025,3
386.30701,307.60167,     -1.51389,     15.84426,50.00000,35.00000,1.969433e-10,0.86992,3
387.37500,308.66833,     -1.55072,     14.21864,50.00000,35.00000,1.978016e-10,0.86964,3
388.43900,309.73500,     -1.59235,     12.66535,50.00000,35.00000,1.974163e-10,0.86930,3
389.50299,310.80167,     -1.62898,     11.18249,50.00000,35.00000,1.976413e-10,0.86901,3
390.57001,311.86833,     -1.66510,      9.77627,50.00000,35.00000,1.976471e-10,0.86865,3
391.64801,312.93500,     -1.70586,      8.45330,50.00000,35.00000,1.983165e-10,0.86839,3
392.72601,314.00167,     -1.74530,      7.19397,50.00000,35.00000,1.979103e-10,0.86805,3
393.77802,315.06833,     -1.79816,      6.01375,50.00000,35.00000,1.981620e-10,0.86776,3
394.83499,316.13500,     -1.85943,      4.87815,50.00000,35.00000,1.977692e-10,0.86742,3
395.90799,317.20167,     -1.93204,      3.79567,50.00000,35.00000,1.971932e-10,0.86713,3
396.98001,318.26833,     -2.00672,      2.87326,50.00000,35.00000,1.978817e-10,0.86678,3
398.03900,319.33500,     -2.07909,      2.01676,50.00000,35.00000,1.985989e-10,0.86649,3
399.10300,320.40167,     -2.15189,      1.28814,50.00000,35.00000,1.982784e-10,0.86615,3
399.68900,320.97500,     -2.18593,      0.91299,50.00000,35.00000,1.983586e-10,0.86596,4
399.81601,321.05500,     -2.16763,      0.86196,50.00000,35.00000,1.983586e-10,0.86596,4
400.07001,321.13500,     -2.03351,      0.86196,50.00000,35.00000,1.983929e-10,0.86589,4
400.48300,321.21500,     -1.75957,      0.84915,50.00000,35.00000,1.983929e-10,0.86589,4
401.07599,321.29500,     -1.35563,      0.84915,50.00000,35.00000,1.983929e-10,0.86589,4
401.85400,321.37500,     -0.83523,      0.87476,50.00000,35.00000,1.977501e-10,0.86585,4
402.81400,321.45500,     -0.22782,      0.92580,50.00000,35.00000,1.977501e-10,0.86585,4
403.92999,321.53500,      0.43693,      0.96422,50.00000,35.00000,1.983013e-10,0.86580,4
405.21701,321.61500,      1.12377,      1.03879,50.00000,35.00000,1.983013e-10,0.86580,4
406.62299,321.69500,      1.79987,      1.06441,50.00000,35.00000,1.982861e-10,0.86575,4
408.12701,321.77500,      2.44089,      1.11977,50.00000,35.00000,1.982861e-10,0.86575,4
409.69400,321.85500,      3.01604,      1.17307,50.00000,35.00000,1.985054e-10,0.86570,4
411.32800,321.93500,      3.51072,      1.17307,50.00000,35.00000,1.985054e-10,0.86570,4
412.95401,322.01500,      3.91991,      1.20075,50.00000,35.00000,1.984139e-10,0.86565,4
414.57700,322.09500,      4.23248,      1.20075,50.00000,35.00000,1.984139e-10,0.86565,4
416.16901,322.17500,      4.45144,      1.20075,50.00000,35.00000,1.986886e-10,0.86561,4
417.73901,322.25500,      4.58216,      1.17514,50.00000,35.00000,1.986886e-10,0.86561,4
419.28799,322.33500,      4.63728,      1.14953,50.00000,35.00000,1.976127e-10,0.86555,4
420.77701,322.41500,      4.62929,      1.09416,50.00000,35.00000,1.976127e-10,0.86555,4
422.22800,322.49500,      4.57015,      1.03879,50.00000,35.00000,1.977578e-10,0.86551,4
423.63400,322.57500,      4.47086,      0.96629,50.00000,35.00000,1.977578e-10,0.86551,4
425.00299,322.65500,      4.35123,      0.89605,50.00000,35.00000,1.987113e-10,0.86546,4
426.36401,322.73500,      4.22292,      0.84068,50.00000,35.00000,1.987113e-10,0.86546,4
427.69299,322.81500,      4.09719,      0.77250,50.00000,35.00000,1.986179e-10,0.86541,4
429.00800,322.89500,      3.98407,      0.68945,50.00000,35.00000,1.986179e-10,0.86541,4
430.33499,322.97500,      3.88746,      0.63390,50.00000,35.00000,1.983490e-10,0.86536,4
431.66101,323.05500,      3.81494,      0.57439,50.00000,35.00000,1.983490e-10,0.86536,4
433.01300,323.13500,      3.77416,      0.52109,50.00000,35.00000,1.983166e-10,0.86531,4
434.35800,323.21500,      3.76056,      0.44859,50.00000,35.00000,1.983166e-10,0.86531,4
435.75400,323.29500,      3.77219,      0.39962,50.00000,35.00000,1.987038e-10,0.86527,4
437.16199,323.37500,      3.81051,      0.33352,50.00000,35.00000,1.987038e-10,0.86527,4
438.61099,323.45500,      3.86796,      0.32072,50.00000,35.00000,1.982059e-10,0.86521,4
440.08801,323.53500,      3.94656,      0.26535,50.00000,35.00000,1.982059e-10,0.86521,4
441.58200,323.61500,      4.03937,      0.20565,50.00000,35.00000,1.991062e-10,0.86517,4
443.10999,323.69500,      4.13338,      0.17382,50.00000,35.00000,1.991062e-10,0.86517,4
444.67700,323.77500,      4.22863,      0.14821,50.00000,35.00000,1.993751e-10,0.86512,4
446.25101,323.85500,      4.32607, 9.924670e-02,50.00000,35.00000,1.993751e-10,0.86512,4
447.86401,323.93500,      4.42169, 7.363465e-02,50.00000,35.00000,1.981239e-10,0.86507,4
449.48001,324.01500,      4.50463, 4.802260e-02,50.00000,35.00000,1.981239e-10,0.86507,4
451.08099,324.09500,      4.57715, 4.161959e-02,50.00000,35.00000,1.981239e-10,0.86507,4
452.71899,324.17500,      4.63615, 2.241055e-02,50.00000,35.00000,1.989021e-10,0.86502,4
454.36600,324.25500,      4.68205,-3.013183e-03,50.00000,35.00000,1.989021e-10,0.86502,4
456.00299,324.33500,      4.71710,-3.013183e-03,50.00000,35.00000,1.990643e-10,0.86497,4
457.62799,324.41500,      4.73852,-3.013183e-03,50.00000,35.00000,1.990643e-10,0.86497,4
459.28000,324.49500,      4.74916,-2.222222e-02,50.00000,35.00000,1.985150e-10,0.86492,4
460.92099,324.57500,      4.74985,-2.222222e-02,50.00000,35.00000,1.985150e-10,0.86492,4
462.56400,324.65500,      4.74262,-2.862524e-02,50.00000,35.00000,1.983165e-10,0.86487,4
464.20300,324.73500,      4.72965,-2.862524e-02,50.00000,35.00000,1.983165e-10,0.86487,4
465.82901,324.81500,      4.71379,-9.416196e-03,50.00000,35.00000,1.990108e-10,0.86482,4
467.47800,324.89500,      4.69093,-3.013183e-03,50.00000,35.00000,1.990108e-10,0.86482,4
469.11801,324.97500,      4.66766,-3.013183e-03,50.00000,35.00000,1.982098e-10,0.86477,4
470.74701,325.05500,      4.64076,-3.013183e-03,50.00000,35.00000,1.982098e-10,0.86477,4
472.39301,325.13500,      4.61793, 2.241055e-02,50.00000,35.00000,1.977443e-10,0.86473,4
474.03601,325.21500,      4.59335, 4.802260e-02,50.00000,35.00000,1.977443e-10,0.86473,4
475.67801,325.29500,      4.57481, 4.802260e-02,50.00000,35.00000,1.983299e-10,0.86468,4
477.32401,325.37500,      4.55458, 7.363465e-02,50.00000,35.00000,1.983299e-10,0.86468,4
478.98700,325.45500,      4.53432, 7.363465e-02,50.00000,35.00000,1.990127e-10,0.86462,4
480.62601,325.53500,      4.51449, 9.924670e-02,50.00000,35.00000,1.990127e-10,0.86462,4
482.28799,325.61500,      4.49838, 9.924670e-02,50.00000,35.00000,1.985759e-10,0.86457,4
483.95599,325.69500,      4.47942,      0.12467,50.00000,35.00000,1.985759e-10,0.86457,4
485.61700,325.77500,      4.46495,      0.15028,50.00000,35.00000,1.992207e-10,0.86452,4
487.28500,325.85500,      4.44715,      0.15028,50.00000,35.00000,1.992207e-10,0.86452,4
488.94000,325.93500,      4.42800,      0.20358,50.00000,35.00000,1.988049e-10,0.86447,4
490.60699,326.01500,      4.40412,      0.20358,50.00000,35.00000,1.988049e-10,0.86447,4
492.28400,326.09500,      4.38180,      0.24200,50.00000,35.00000,1.991577e-10,0.86442,4
493.95401,326.17500,      4.35766,      0.25480,50.00000,35.00000,1.991577e-10,0.86442,4
495.62201,326.25500,      4.32841,      0.25480,50.00000,35.00000,1.985244e-10,0.86438,4
497.29300,326.33500,      4.29785,      0.25480,50.00000,35.00000,1.985244e-10,0.86438,4
498.96701,326.41500,      4.26310,      0.28023,50.00000,35.00000,1.984520e-10,0.86432,4
500.63501,326.49500,      4.23075,      0.30584,50.00000,35.00000,1.984520e-10,0.86432,4
502.29401,326.57500,      4.19675,      0.33145,50.00000,35.00000,1.982288e-10,0.86427,4
503.96799,326.65500,      4.16074,      0.35706,50.00000,35.00000,1.982288e-10,0.86427,4
505.62399,326.73500,      4.12421,      0.38249,50.00000,35.00000,1.982346e-10,0.86423,4
507.30301,326.81500,      4.08880,      0.40169,50.00000,35.00000,1.982346e-10,0.86423,4
508.97400,326.89500,      4.05197,      0.40169,50.00000,35.00000,1.988315e-10,0.86418,4
510.64099,326.97500,      4.01852,      0.40810,50.00000,35.00000,1.988315e-10,0.86418,4
512.30798,327.05500,      3.97937,      0.45932,50.00000,35.00000,1.988315e-10,0.86418,4
513.98297,327.13500,      3.93908,      0.45932,50.00000,35.00000,1.991139e-10,0.86413,4
515.64099,327.21500,      3.89634,      0.46573,50.00000,35.00000,1.991139e-10,0.86413,4
517.29901,327.29500,      3.85337,      0.49755,50.00000,35.00000,1.980610e-10,0.86409,4
518.96802,327.37500,      3.81098,      0.51036,50.00000,35.00000,1.980610e-10,0.86409,4
520.63000,327.45500,      3.76785,      0.53597,50.00000,35.00000,1.993198e-10,0.86404,4
522.28101,327.53500,      3.72690,      0.53597,50.00000,35.00000,1.993198e-10,0.86404,4
523.94598,327.61500,      3.68068,      0.56158,50.00000,35.00000,1.986713e-10,0.86398,4
525.61200,327.69500,      3.63840,      0.58719,50.00000,35.00000,1.986713e-10,0.86398,4
527.25800,327.77500,      3.59312,      0.61262,50.00000,35.00000,1.988736e-10,0.86393,4
528.91498,327.85500,      3.55013,      0.61262,50.00000,35.00000,1.988736e-10,0.86393,4
530.57898,327.93500,      3.50500,      0.61262,50.00000,35.00000,1.990452e-10,0.86388,4
532.23297,328.01500,      3.45935,      0.63823,50.00000,35.00000,1.990452e-10,0.86388,4
533.89502,328.09500,      3.41179,      0.66384,50.00000,35.00000,1.988106e-10,0.86383,4
535.55798,328.17500,      3.36302,      0.68945,50.00000,35.00000,1.988106e-10,0.86383,4
537.19897,328.25500,      3.31865,      0.71488,50.00000,35.00000,1.992188e-10,0.86378,4
538.84698,328.33500,      3.27235,      0.72768,50.00000,35.00000,1.992188e-10,0.86378,4
540.49298,328.41500,      3.22558,      0.74049,50.00000,35.00000,1.989136e-10,0.86373,4
542.14899,328.49500,      3.17789,      0.76610,50.00000,35.00000,1.989136e-10,0.86373,4
543.80103,328.57500,      3.13121,      0.77250,50.00000,35.00000,1.985836e-10,0.86368,4
545.46301,328.65500,      3.08384,      0.79171,50.00000,35.00000,1.985836e-10,0.86368,4
547.10699,328.73500,      3.03519,      0.81714,50.00000,35.00000,1.990299e-10,0.86363,4
548.75500,328.81500,      2.98935,      0.81714,50.00000,35.00000,1.990299e-10,0.86363,4
550.40198,328.89500,      2.93952,      0.84275,50.00000,35.00000,1.985664e-10,0.86358,4
552.04303,328.97500,      2.88237,      0.84275,50.00000,35.00000,1.985664e-10,0.86358,4
553.70300,329.05500,      2.82806,      0.84275,50.00000,35.00000,1.984596e-10,0.86353,4
555.34698,329.13500,      2.77626,      0.86836,50.00000,35.00000,1.984596e-10,0.86353,4
556.98401,329.21500,      2.73412,      0.89397,50.00000,35.00000,1.986256e-10,0.86348,4
558.63300,329.29500,      2.69004,      0.91940,50.00000,35.00000,1.986256e-10,0.86348,4
560.26599,329.37500,      2.64214,      0.94501,50.00000,35.00000,1.984730e-10,0.86343,4
561.91803,329.45500,      2.59691,      0.96422,50.00000,35.00000,1.984730e-10,0.86343,4
563.56598,329.53500,      2.54814,      0.96422,50.00000,35.00000,1.985874e-10,0.86338,4
565.20898,329.61500,      2.49759,      0.97062,50.00000,35.00000,1.985874e-10,0.86338,4
566.84601,329.69500,      2.44450,      0.99623,50.00000,35.00000,1.986542e-10,0.86333,4
568.49701,329.77500,      2.39251,      0.99623,50.00000,35.00000,1.986542e-10,0.86333,4
570.12799,329.85500,      2.34386,      1.02166,50.00000,35.00000,1.983910e-10,0.86329,4
571.76703,329.93500,      2.29348,      1.02806,50.00000,35.00000,1.983910e-10,0.86329,4
573.40601,330.01500,      2.24236,      1.07288,50.00000,35.00000,1.984292e-10,0.86324,4
575.03900,330.09500,      2.19257,      1.09849,50.00000,35.00000,1.984292e-10,0.86324,4
576.67603,330.17500,      2.13973,      1.09849,50.00000,35.00000,1.988239e-10,0.86319,4
578.31299,330.25500,      2.08875,      1.11770,50.00000,35.00000,1.988239e-10,0.86319,4
579.95099,330.33500,      2.03599,      1.12392,50.00000,35.00000,1.982078e-10,0.86314,4
581.58502,330.41500,      1.98563,      1.14953,50.00000,35.00000,1.982078e-10,0.86314,4
583.22699,330.49500,      1.93639,      1.17514,50.00000,35.00000,1.990432e-10,0.86308,4
584.85797,330.57500,      1.88037,      1.17514,50.00000,35.00000,1.990432e-10,0.86308,4
586.49402,330.65500,      1.82755,      1.17514,50.00000,35.00000,1.987534e-10,0.86304,4
588.12903,330.73500,      1.78031,      1.17514,50.00000,35.00000,1.987534e-10,0.86304,4
589.76001,330.81500,      1.72522,      1.20282,50.00000,35.00000,1.986618e-10,0.86298,4
591.38098,330.89500,      1.67413,      1.23258,50.00000,35.00000,1.986618e-10,0.86298,4
593.03400,330.97500,      1.62369,      1.25819,50.00000,35.00000,1.979942e-10,0.86293,4
594.65802,331.05500,      1.57114,      1.25819,50.00000,35.00000,1.979942e-10,0.86293,4
596.29102,331.13500,      1.52053,      1.28380,50.00000,35.00000,1.979942e-10,0.86293,4
597.91998,331.21500,      1.46866,      1.28380,50.00000,35.00000,1.987724e-10,0.86289,4
599.55103,331.29500,      1.41738,      1.30301,50.00000,35.00000,1.987724e-10,0.86289,4
601.18402,331.37500,      1.36538,      1.33710,50.00000,35.00000,1.985168e-10,0.86284,4
602.80798,331.45500,      1.31344,      1.33710,50.00000,35.00000,1.985168e-10,0.86284,4
604.43701,331.53500,      1.26721,      1.33710,50.00000,35.00000,1.987629e-10,0.86278,4
606.05701,331.61500,      1.21461,      1.36271,50.00000,35.00000,1.987629e-10,0.86278,4
607.69501,331.69500,      1.16103,      1.37533,50.00000,35.00000,1.991157e-10,0.86273,4
609.32599,331.77500,      1.11075,      1.38814,50.00000,35.00000,1.991157e-10,0.86273,4
610.94501,331.85500,      1.05892,      1.38814,50.00000,35.00000,1.984406e-10,0.86269,4
612.57599,331.93500,      1.00772,      1.41375,50.00000,35.00000,1.984406e-10,0.86269,4
614.19702,332.01500,      0.95280,      1.43936,50.00000,35.00000,1.988145e-10,0.86264,4
615.83197,332.09500,      0.89987,      1.45857,50.00000,35.00000,1.988145e-10,0.86264,4
617.45099,332.17500,      0.84156,      1.46497,50.00000,35.00000,1.990623e-10,0.86259,4
619.07703,332.25500,      0.78714,      1.49040,50.00000,35.00000,1.990623e-10,0.86259,4
620.69299,332.33500,      0.73088,      1.51601,50.00000,36.00000,1.989803e-10,0.86253,4
622.32397,332.41500,      0.67634,      1.51601,50.00000,35.00000,1.989803e-10,0.86253,4
623.93500,332.49500,      0.62270,      1.51601,50.00000,35.00000,1.988220e-10,0.86249,4
625.56897,332.57500,      0.56805,      1.54162,50.00000,35.00000,1.988220e-10,0.86249,4
627.17902,332.65500,      0.51596,      1.54162,50.00000,35.00000,1.992416e-10,0.86244,4
628.80402,332.73500,      0.45928,      1.56723,50.00000,35.00000,1.992416e-10,0.86244,4
630.43701,332.81500,      0.40490,      1.58625,50.00000,35.00000,1.990662e-10,0.86238,4
632.05103,332.89500,      0.35004,      1.58625,50.00000,35.00000,1.990662e-10,0.86238,4
633.67297,332.97500,      0.29445,      1.58625,50.00000,35.00000,1.987934e-10,0.86234,4
635.28601,333.05500,      0.23728,      1.59266,50.00000,35.00000,1.987934e-10,0.86234,4
636.90698,333.13500,      0.17770,      1.61827,50.00000,35.00000,1.992359e-10,0.86229,4
638.51202,333.21500,      0.12321,      1.64388,50.00000,36.00000,1.992359e-10,0.86229,4
640.14502,333.29500, 6.658063e-02,      1.66949,50.00000,35.00000,1.992092e-10,0.86224,4
641.76300,333.37500, 1.590520e-02,      1.66949,50.00000,35.00000,1.992092e-10,0.86224,4
643.38599,333.45500,-4.024770e-02,      1.66949,50.00000,36.00000,1.990681e-10,0.86219,4
644.99902,333.53500,-9.322464e-02,      1.69492,50.00000,36.00000,1.990681e-10,0.86219,4
646.61102,333.61500,     -0.14721,      1.69492,50.00000,36.00000,1.982726e-10,0.86214,4
648.24103,333.69500,     -0.20138,      1.72053,50.00000,36.00000,1.982726e-10,0.86214,4
649.85999,333.77500,     -0.25854,      1.74614,50.00000,36.00000,1.988392e-10,0.86209,4
651.46802,333.85500,     -0.31474,      1.77175,50.00000,35.00000,1.988392e-10,0.86209,4
653.09497,333.93500,     -0.36606,      1.77175,50.00000,36.00000,1.996250e-10,0.86203,4
654.69897,334.01500,     -0.42459,      1.79736,50.00000,35.00000,1.996250e-10,0.86203,4
656.32098,334.09500,     -0.48077,      1.79736,50.00000,35.00000,1.986904e-10,0.86199,4
657.93799,334.17500,     -0.53570,      1.80358,50.00000,35.00000,1.986904e-10,0.86199,4
659.55798,334.25500,     -0.58967,      1.82919,50.00000,35.00000,1.985702e-10,0.86193,4
661.16901,334.33500,     -0.64609,      1.84840,50.00000,35.00000,1.985702e-10,0.86193,4
662.78900,334.41500,     -0.70496,      1.87401,50.00000,35.00000,1.990299e-10,0.86189,4
664.40198,334.49500,     -0.76229,      1.87401,50.00000,35.00000,1.990299e-10,0.86189,4
666.01801,334.57500,     -0.82123,      1.89962,50.00000,35.00000,1.990299e-10,0.86189,4
667.63702,334.65500,     -0.87778,      1.89962,50.00000,35.00000,1.985149e-10,0.86184,4
669.24500,334.73500,     -0.93478,      1.92505,50.00000,35.00000,1.985149e-10,0.86184,4
670.85901,334.81500,     -0.99281,      1.95066,50.00000,35.00000,1.989250e-10,0.86179,4
672.47998,334.89500,     -1.04844,      1.95066,50.00000,35.00000,1.989250e-10,0.86179,4
674.09998,334.97500,     -1.10107,      1.97627,50.00000,35.00000,1.990032e-10,0.86174,4
675.70203,335.05500,     -1.16220,      1.98908,50.00000,35.00000,1.990032e-10,0.86174,4
677.32098,335.13500,     -1.22093,      2.00188,50.00000,36.00000,1.986751e-10,0.86169,4
678.93597,335.21500,     -1.27665,      2.02731,50.00000,35.00000,1.986751e-10,0.86169,4
680.55298,335.29500,     -1.33456,      2.02731,50.00000,35.00000,1.989879e-10,0.86164,4
682.17401,335.37500,     -1.39323,      2.02731,50.00000,35.00000,1.989879e-10,0.86164,4
683.77899,335.45500,     -1.45467,      2.02731,50.00000,35.00000,1.990452e-10,0.86159,4
685.41803,335.53500,     -1.51400,      2.05932,50.00000,36.00000,1.990452e-10,0.86159,4
687.01300,335.61500,     -1.57286,      2.07853,50.00000,35.00000,1.991405e-10,0.86153,4
688.62097,335.69500,     -1.63424,      2.07853,50.00000,36.00000,1.991405e-10,0.86153,4
690.23798,335.77500,     -1.69494,      2.10414,50.00000,35.00000,1.986122e-10,0.86148,4
691.84399,335.85500,     -1.75580,      2.12957,50.00000,36.00000,1.986122e-10,0.86148,4
693.46198,335.93500,     -1.82389,      2.14237,50.00000,36.00000,1.991005e-10,0.86143,4
695.08197,336.01500,     -1.88718,      2.15518,50.00000,36.00000,1.991005e-10,0.86143,4
696.68103,336.09500,     -1.94356,      2.15518,50.00000,36.00000,1.990242e-10,0.86138,4
698.31299,336.17500,     -2.00693,      2.18079,50.00000,36.00000,1.990242e-10,0.86138,4
699.92700,336.25500,     -2.06720,      2.18079,50.00000,36.00000,1.993789e-10,0.86134,4
701.53699,336.33500,     -2.12941,      2.18079,50.00000,36.00000,1.993789e-10,0.86134,4
703.14600,336.41500,     -2.19268,      2.20640,50.00000,36.00000,1.992168e-10,0.86128,4
704.76501,336.49500,     -2.25141,      2.23183,50.00000,36.00000,1.992168e-10,0.86128,4
706.37701,336.57500,     -2.31176,      2.23183,50.00000,36.00000,1.990108e-10,0.86123,4
707.98901,336.65500,     -2.37140,      2.25104,50.00000,36.00000,1.990108e-10,0.86123,4
709.60303,336.73500,     -2.43120,      2.25744,50.00000,36.00000,1.993503e-10,0.86118,4
711.22400,336.81500,     -2.48969,      2.28305,50.00000,36.00000,1.993503e-10,0.86118,4
712.83698,336.89500,     -2.55102,      2.28305,50.00000,36.00000,1.993503e-10,0.86118,4
714.44598,336.97500,     -2.60921,      2.28305,50.00000,36.00000,1.996994e-10,0.86113,4
716.06598,337.05500,     -2.67029,      2.30866,50.00000,36.00000,1.996994e-10,0.86113,4
717.68701,337.13500,     -2.72613,      2.30866,50.00000,36.00000,1.990013e-10,0.86108,4
719.30603,337.21500,     -2.78213,      2.33409,50.00000,36.00000,1.990013e-10,0.86108,4
720.93201,337.29500,     -2.83589,      2.35970,50.00000,36.00000,1.996537e-10,0.86103,4
722.56201,337.37500,     -2.89492,      2.35970,50.00000,36.00000,1.996537e-10,0.86103,4
724.19000,337.45500,     -2.95231,      2.38531,50.00000,36.00000,1.989555e-10,0.86098,4
725.82397,337.53500,     -3.01772,      2.38531,50.00000,36.00000,1.989555e-10,0.86098,4
727.42798,337.61500,     -3.08142,      2.38531,50.00000,36.00000,1.997642e-10,0.86092,4
729.05402,337.69500,     -3.15323,      2.41299,50.00000,36.00000,1.997642e-10,0.86092,4
730.65997,337.77500,     -3.22488,      2.43861,50.00000,36.00000,1.996479e-10,0.86088,4
732.27600,337.85500,     -3.29706,      2.43861,50.00000,36.00000,1.996479e-10,0.86088,4
733.88898,337.93500,     -3.37248,      2.46422,50.00000,36.00000,1.995754e-10,0.86083,4
735.50403,338.01500,     -3.44597,      2.46422,50.00000,36.00000,1.995754e-10,0.86083,4
737.09802,338.09500,     -3.51349,      2.46422,50.00000,36.00000,1.993465e-10,0.86078,4
738.70898,338.17500,     -3.58308,      2.51525,50.00000,36.00000,1.993465e-10,0.86078,4
740.32202,338.25500,     -3.65531,      2.51525,50.00000,36.00000,1.996212e-10,0.86073,4
741.91901,338.33500,     -3.71910,      2.51525,50.00000,36.00000,1.996212e-10,0.86073,4
743.52698,338.41500,     -3.78495,      2.54087,50.00000,36.00000,1.991958e-10,0.86068,4
745.12201,338.49500,     -3.85554,      2.56648,50.00000,36.00000,1.991958e-10,0.86068,4
746.72900,338.57500,     -3.92328,      2.56648,50.00000,36.00000,1.987686e-10,0.86063,4
748.33197,338.65500,     -3.98779,      2.59190,50.00000,36.00000,1.987686e-10,0.86063,4
749.94000,338.73500,     -4.05559,      2.59190,50.00000,36.00000,1.993942e-10,0.86058,4
751.54199,338.81500,     -4.11613,      2.59190,50.00000,36.00000,1.993942e-10,0.86058,4
753.14801,338.89500,     -4.18303,      2.61751,50.00000,36.00000,1.993217e-10,0.86052,4
754.76202,338.97500,     -4.24271,      2.61751,50.00000,36.00000,1.993217e-10,0.86052,4
756.37299,339.05500,     -4.30532,      2.61751,50.00000,36.00000,1.994629e-10,0.86047,4
757.99200,339.13500,     -4.36908,      2.65593,50.00000,36.00000,1.994629e-10,0.86047,4
759.60498,339.21500,     -4.43952,      2.69416,50.00000,36.00000,1.993542e-10,0.86043,4
761.20801,339.29500,     -4.50637,      2.69416,50.00000,36.00000,1.993542e-10,0.86043,4
762.82300,339.37500,     -4.57658,      2.69416,50.00000,36.00000,1.994571e-10,0.86037,4
764.44098,339.45500,     -4.64449,      2.71977,50.00000,36.00000,1.994571e-10,0.86037,4
766.04498,339.53500,     -4.71221,      2.74539,50.00000,36.00000,1.998863e-10,0.86032,4
767.65802,339.61500,     -4.78047,      2.74539,50.00000,36.00000,1.998863e-10,0.86032,4
769.26202,339.69500,     -4.84730,      2.74539,50.00000,36.00000,1.993542e-10,0.86027,4
770.87201,339.77500,     -4.92599,      2.77100,50.00000,36.00000,1.993542e-10,0.86027,4
772.48700,339.85500,     -4.99514,      2.79021,50.00000,36.00000,1.988926e-10,0.86022,4
774.09900,339.93500,     -5.06700,      2.79642,50.00000,36.00000,1.988926e-10,0.86022,4
775.71002,340.01500,     -5.13874,      2.82203,50.00000,36.00000,1.999340e-10,0.86018,4
777.31702,340.09500,     -5.21192,      2.82203,50.00000,36.00000,1.999340e-10,0.86018,4
778.92700,340.17500,     -5.27676,      2.92222,50.00000,36.00000,1.994399e-10,0.86012,4
780.53198,340.25500,     -5.34335,      2.92222,50.00000,36.00000,1.994399e-10,0.86012,4
782.13599,340.33500,     -5.41901,      2.89661,50.00000,36.00000,1.994399e-10,0.86012,4
783.75403,340.41500,     -5.48986,      2.93070,50.00000,36.00000,1.989707e-10,0.86007,4
785.36298,340.49500,     -5.55832,      2.93070,50.00000,36.00000,1.989707e-10,0.86007,4
786.96198,340.57500,     -5.62883,      2.92429,50.00000,36.00000,1.999245e-10,0.86003,4
788.58502,340.65500,     -5.70094,      2.90508,50.00000,36.00000,1.999245e-10,0.86003,4
790.18597,340.73500,     -5.76737,      2.93070,50.00000,36.00000,1.993713e-10,0.85996,4
791.79602,340.81500,     -5.83533,      2.93070,50.00000,36.00000,            ,0.44818,4
793.39502,340.89500,     -5.91112,      2.95631,50.00000,36.00000,            ,0.44753,4
794.21301,340.93500,     -5.95112,      2.97552,50.00000,36.00000,            ,0.44721,4