File: data/TGA/005d-L_M/ExpDat_2025_03_11_SL_005F_J3_dynamic.csv
#EXPORTTYPE:                 ,DATA ALL
#FILE:                       ,2025_03_11_SL_005F_J3_dynamic.ngb-ss5
#FORMAT:                     ,NETZSCH5
#FTYPE:                      ,ASCII
#IDENTITY:                   ,2025_03_11_SL_005F_J3
#DECIMAL:                    ,POINT
#SEPARATOR:                  ,COMMA
#MTYPE:                      ,DSC
#INSTRUMENT:                 ,NETZSCH STA 449F5
#PROJECT:                    ,PS
#DATE/TIME:                  ,3/11/2025 2:28:48 PM (UTC-4)
#CORR. FILE:                 ,
#TEMPCAL:                    ,13-11-2024 10:37
#SENSITIVITY:                ,28-06-2023 13:53
#LABORATORY:                 ,Tran/Aspuru
#OPERATOR:                   ,Stanley
#REMARK:                     ,2025_03_11_SL_005F_J3_dynamic
#SAMPLE:                     ,2025_03_11_SL_005F_J3
#SAMPLE MASS /mg:            ,5.02
#MATERIAL:                   ,Polystyrene
#REFERENCE:                  ,
#REFERENCE MASS /mg:         ,0
#TYPE OF CRUCIBLE:           ,Al2O3 85 ‘l, open
#SAMPLE CRUCIBLE MASS /mg:   ,0
#REFERENCE CRUCIBLE MASS /mg:,0
#DSC RANGE /‘V:              ,5000
#TG RANGE /mg:               ,35000
#TAU-R:                      ,---
#CORR. CODE:                 ,000
#EXO:                        ,-1
#RANGE:                      ,20›C....800›C/0.0....20.0K/min
#SEGMENT:                    ,S1-4/4
#SEG. 1:                     ,20›C/5.0(K/min)/100›C
#SEG. 2:                     ,100›C/00:05/100›C
#SEG. 3:                     ,100›C/1.0(K/min)/400›C
#SEG. 4:                     ,400›C/20.0(K/min)/800›C

##Temp./›C,Time/min,DSC/(mW/mg),Mass/%,Gas Flow(purge2)/(ml/min),Gas Flow(protective)/(ml/min),TIC(scan:1)/A,Sensit./(uV/mW),Segment
 34.41600,  0.00000,      0.11822,100.00000,50.00000,51.00000,            ,0.92431,1
 35.24800,  1.06667, 7.546095e-02, 99.30598,50.00000,51.00000,2.092762e-10,0.92436,1
 35.88300,  2.13333, 4.043899e-02, 98.76056,50.00000,51.00000,2.091998e-10,0.92441,1
 36.31300,  3.20000, 9.040625e-03, 98.24442,50.00000,51.00000,2.088356e-10,0.92446,1
 37.11300,  4.26667, 8.579326e-02, 98.35259,50.00000,51.00000,2.096977e-10,0.92450,1
 39.03000,  5.33333,      0.28130, 98.68386,50.00000,51.00000,2.096462e-10,0.92453,1
 42.14400,  6.40000,      0.50505, 99.37570,50.00000,51.00000,2.094154e-10,0.92456,1
 46.37600,  7.46667,      0.71860, 99.96394,50.00000,51.00000,2.108365e-10,0.92459,1
 51.54000,  8.53333,      0.91135,100.43725,50.00000,51.00000,2.100258e-10,0.92461,1
 57.44500,  9.60000,      1.07004,100.91275,50.00000,51.00000,2.100373e-10,0.92466,1
 63.83400, 10.66667,      1.19336,101.26215,50.00000,51.00000,2.105255e-10,0.92472,1
 70.45700, 11.73333,      1.27589,101.51235,50.00000,51.00000,2.107296e-10,0.92481,1
 77.15200, 12.80000,      1.32143,101.70159,50.00000,51.00000,2.103767e-10,0.92492,1
 83.81700, 13.86667,      1.33996,101.80976,50.00000,51.00000,2.112465e-10,0.92506,1
 90.40200, 14.93333,      1.32910,101.91793,50.00000,51.00000,2.109928e-10,0.92520,1
 96.69800, 15.98417,      1.30660,101.99004,50.00000,51.00000,2.110939e-10,0.92537,2
100.93600, 16.78417,      1.13507,101.62052,50.00000,51.00000,2.117195e-10,0.92547,2
103.73400, 17.58417,      0.75968,100.94661,50.00000,51.00000,2.115288e-10,0.92559,2
105.61100, 18.38417,      0.48641,100.52749,50.00000,51.00000,2.120838e-10,0.92571,2
106.95700, 19.18417,      0.30870,100.20060,50.00000,51.00000,2.123337e-10,0.92583,2
107.73200, 19.98417,      0.13876, 99.76335,50.00000,51.00000,2.107772e-10,0.92593,2
107.96700, 20.78417,-1.753202e-02, 99.31952,50.00000,51.00000,2.110634e-10,0.92602,2
107.81700, 21.80083,     -0.13661, 98.98825,50.00000,51.00000,2.115536e-10,0.92611,3
107.59100, 22.86750,     -0.15297, 98.85737,50.00000,51.00000,2.120171e-10,0.92618,3
107.35600, 23.93417,     -0.15594, 98.55777,50.00000,51.00000,2.124977e-10,0.92620,3
107.17300, 25.00083,     -0.13890, 98.42928,50.00000,51.00000,2.118302e-10,0.92619,3
107.17300, 26.06750,-9.904772e-02, 98.37510,50.00000,51.00000,2.121219e-10,0.92613,3
107.35000, 27.13417,-5.705068e-02, 98.35717,50.00000,51.00000,2.120037e-10,0.92602,3
107.72800, 28.20083,-1.323071e-02, 98.29622,50.00000,51.00000,2.117195e-10,0.92589,3
108.27800, 29.26750, 2.646605e-02, 98.33227,50.00000,51.00000,2.122707e-10,0.92568,3
108.98900, 30.33417, 6.220941e-02, 98.27829,50.00000,51.00000,2.119674e-10,0.92546,3
109.82300, 31.40083, 8.969858e-02, 98.25797,50.00000,51.00000,2.120323e-10,0.92516,3
110.74100, 32.46750,      0.11207, 98.25797,50.00000,51.00000,2.124405e-10,0.92485,3
111.76100, 33.53417,      0.13066, 98.24442,50.00000,51.00000,2.127628e-10,0.92446,3
112.81400, 34.60083,      0.14081, 98.20378,50.00000,51.00000,2.123890e-10,0.92407,3
113.91600, 35.66750,      0.15081, 98.17012,50.00000,51.00000,2.123355e-10,0.92359,3
115.01300, 36.73417,      0.15385, 98.14303,50.00000,52.00000,2.126350e-10,0.92313,3
116.15300, 37.80083,      0.15591, 98.14303,50.00000,52.00000,2.126293e-10,0.92257,3
117.29400, 38.86750,      0.15498, 98.13625,50.00000,52.00000,2.132053e-10,0.92205,3
118.41400, 39.93417,      0.15289, 98.08884,50.00000,52.00000,2.125702e-10,0.92154,3
119.52100, 41.00083,      0.15079, 98.09562,50.00000,52.00000,2.130108e-10,0.92115,3
120.63200, 42.06750,      0.14753, 98.10020,50.00000,52.00000,2.124481e-10,0.92074,3
121.72100, 43.13417,      0.14511, 98.02590,50.00000,52.00000,2.124939e-10,0.92044,3
122.82900, 44.20083,      0.14201, 98.00558,50.00000,52.00000,2.135124e-10,0.92014,3
123.92500, 45.26750,      0.13808, 98.05956,50.00000,52.00000,2.129746e-10,0.91992,3
125.00900, 46.33417,      0.13531, 98.01912,50.00000,52.00000,2.128697e-10,0.91969,3
126.07600, 47.40083,      0.13288, 98.02590,50.00000,52.00000,2.132397e-10,0.91952,3
127.16900, 48.46750,      0.12894, 98.03944,50.00000,52.00000,2.133999e-10,0.91935,3
128.23700, 49.53417,      0.12517, 98.01912,50.00000,52.00000,2.131652e-10,0.91922,3
129.30299, 50.60083,      0.12406, 98.05956,50.00000,52.00000,2.130509e-10,0.91909,3
130.35899, 51.66750,      0.12028, 98.05956,50.00000,52.00000,2.134762e-10,0.91900,3
131.43300, 52.73417,      0.11784, 98.05956,50.00000,52.00000,2.132874e-10,0.91894,3
132.49400, 53.80083,      0.11589, 98.08446,50.00000,52.00000,2.138271e-10,0.91890,3
133.56400, 54.86750,      0.11344, 98.09801,50.00000,52.00000,2.135010e-10,0.91889,3
134.62300, 55.93417,      0.11032, 98.08446,50.00000,52.00000,2.138271e-10,0.91889,3
135.68500, 57.00083,      0.10820, 98.08446,50.00000,52.00000,2.134038e-10,0.91891,3
136.77699, 58.06750,      0.10625, 98.13167,50.00000,52.00000,2.133560e-10,0.91894,3
137.84200, 59.13417,      0.10447, 98.20837,50.00000,52.00000,2.131653e-10,0.91896,3
138.92000, 60.20083,      0.10168, 98.16096,50.00000,52.00000,2.127743e-10,0.91899,3
139.98000, 61.26750, 9.888053e-02, 98.19482,50.00000,52.00000,2.128639e-10,0.91902,3
141.03900, 62.33417, 9.507700e-02, 98.21514,50.00000,52.00000,2.133178e-10,0.91905,3
142.11700, 63.40083, 9.311638e-02, 98.20837,50.00000,52.00000,2.131843e-10,0.91907,3
143.17799, 64.46750, 8.712445e-02, 98.22869,50.00000,52.00000,2.133083e-10,0.91910,3
144.23700, 65.53417, 8.498947e-02, 98.25578,50.00000,52.00000,2.131023e-10,0.91911,3
145.31900, 66.60083, 8.167720e-02, 98.24223,50.00000,52.00000,2.132186e-10,0.91912,3
146.38100, 67.66750, 7.903337e-02, 98.29622,50.00000,52.00000,2.135830e-10,0.91912,3
147.45100, 68.73417, 7.520953e-02, 98.32112,50.00000,52.00000,2.134743e-10,0.91910,3
148.52600, 69.80083, 7.306539e-02, 98.34821,50.00000,52.00000,2.131767e-10,0.91909,3
149.58701, 70.86750, 6.721263e-02, 98.34821,50.00000,52.00000,2.135106e-10,0.91906,3
150.65199, 71.93417, 6.236478e-02, 98.37510,50.00000,52.00000,2.140618e-10,0.91902,3
151.71899, 73.00083, 5.953539e-02, 98.39542,50.00000,52.00000,2.137718e-10,0.91897,3
152.77100, 74.06750, 5.619615e-02, 98.42470,50.00000,52.00000,2.142945e-10,0.91892,3
153.84700, 75.13417, 5.386708e-02, 98.39761,50.00000,52.00000,2.140522e-10,0.91885,3
154.93100, 76.20083, 4.781833e-02, 98.43825,50.00000,52.00000,2.143421e-10,0.91877,3
155.98399, 77.26750, 4.362121e-02, 98.49681,50.00000,52.00000,2.141074e-10,0.91869,3
157.05600, 78.33417, 3.857362e-02, 98.49681,50.00000,52.00000,2.142696e-10,0.91860,3
158.13300, 79.40083, 3.453562e-02, 98.52390,50.00000,52.00000,2.149219e-10,0.91851,3
159.18401, 80.46750, 3.100027e-02, 98.49681,50.00000,52.00000,2.145710e-10,0.91842,3
160.28101, 81.53417, 2.542716e-02, 98.54422,50.00000,52.00000,2.142830e-10,0.91830,3
161.32100, 82.60083, 2.035483e-02, 98.52610,50.00000,52.00000,2.151146e-10,0.91818,3
162.38499, 83.66750, 1.595522e-02, 98.49920,50.00000,52.00000,2.149982e-10,0.91807,3
163.45399, 84.73417, 1.188955e-02, 98.55319,50.00000,52.00000,2.162438e-10,0.91794,3
164.53300, 85.80083, 6.288791e-03, 98.54641,50.00000,52.00000,2.155247e-10,0.91782,3
165.58501, 86.86750,-5.102462e-04, 98.55319,50.00000,52.00000,2.151489e-10,0.91768,3
166.65700, 87.93417,-4.935802e-03, 98.56892,50.00000,52.00000,2.164402e-10,0.91755,3
167.71500, 89.00083,-9.367468e-03, 98.57570,50.00000,52.00000,2.159977e-10,0.91741,3
168.78500, 90.06750,-1.516895e-02, 98.56215,50.00000,52.00000,2.163143e-10,0.91728,3
169.86099, 91.13417,-2.029656e-02, 98.58247,50.00000,53.00000,2.151546e-10,0.91712,3
170.92300, 92.20083,-2.679686e-02, 98.56892,50.00000,53.00000,2.159043e-10,0.91699,3
171.97800, 93.26750,-3.330641e-02, 98.57570,50.00000,53.00000,2.155170e-10,0.91682,3
173.06599, 94.33417,-3.743335e-02, 98.57570,50.00000,53.00000,2.158126e-10,0.91669,3
174.13000, 95.40083,-4.498702e-02, 98.57570,50.00000,53.00000,2.161122e-10,0.91653,3
175.19901, 96.46750,-5.101156e-02, 98.55777,50.00000,53.00000,2.162933e-10,0.91639,3
176.26700, 97.53417,-5.618873e-02, 98.58466,50.00000,53.00000,2.159175e-10,0.91622,3
177.32600, 98.60083,-6.120211e-02, 98.55777,50.00000,53.00000,2.159824e-10,0.91607,3
178.40500, 99.66750,-6.570953e-02, 98.58028,50.00000,53.00000,2.159290e-10,0.91590,3
179.45900,100.73417,-7.262667e-02, 98.55319,50.00000,53.00000,2.163982e-10,0.91576,3
180.53600,101.80083,-7.732218e-02, 98.54641,50.00000,53.00000,2.160683e-10,0.91559,3
181.59500,102.86750,-8.632328e-02, 98.56454,50.00000,53.00000,2.158757e-10,0.91542,3
182.67101,103.93417,-9.103750e-02, 98.56454,50.00000,53.00000,2.161637e-10,0.91527,3
183.73500,105.00083,-9.730882e-02, 98.57789,50.00000,53.00000,2.161178e-10,0.91510,3
184.80600,106.06750,     -0.10376, 98.59143,50.00000,53.00000,2.158070e-10,0.91495,3
185.87100,107.13417,     -0.11144, 98.57131,50.00000,53.00000,2.162209e-10,0.91478,3
186.92900,108.20083,     -0.11636, 98.56454,50.00000,53.00000,2.162018e-10,0.91463,3
187.99500,109.26750,     -0.12423, 98.56454,50.00000,53.00000,2.158642e-10,0.91446,3
189.06400,110.33417,     -0.13090, 98.57131,50.00000,53.00000,2.156296e-10,0.91430,3
190.13600,111.40083,     -0.13637, 98.58466,50.00000,53.00000,2.153530e-10,0.91413,3
191.20799,112.46750,     -0.14376, 98.61394,50.00000,53.00000,2.155399e-10,0.91398,3
192.27200,113.53417,     -0.14977, 98.58705,50.00000,53.00000,2.162246e-10,0.91381,3
193.33800,114.60083,     -0.15614, 98.58247,50.00000,53.00000,2.166099e-10,0.91362,3
194.41000,115.66750,     -0.16652, 98.58028,50.00000,53.00000,2.162476e-10,0.91347,3
195.46700,116.73417,     -0.17204, 98.57789,50.00000,53.00000,2.159500e-10,0.91331,3
196.52699,117.80083,     -0.18036, 98.47430,50.00000,53.00000,2.167416e-10,0.91313,3
197.60800,118.86750,     -0.18452, 98.47430,50.00000,53.00000,2.167721e-10,0.91295,3
198.67599,119.93417,     -0.19165, 98.50817,50.00000,53.00000,2.171077e-10,0.91279,3
199.75101,121.00083,     -0.20054, 98.53964,50.00000,53.00000,2.169647e-10,0.91264,3
200.81000,122.06750,     -0.20926, 98.47211,50.00000,53.00000,2.167072e-10,0.91245,3
201.87300,123.13417,     -0.21661, 98.39542,50.00000,53.00000,2.167893e-10,0.91227,3
202.93700,124.20083,     -0.22344, 98.39542,50.00000,53.00000,2.172928e-10,0.91211,3
204.00200,125.26750,     -0.23134, 98.39542,50.00000,53.00000,2.163257e-10,0.91192,3
205.08701,126.33417,     -0.23996, 98.36833,50.00000,53.00000,2.164707e-10,0.91177,3
206.14500,127.40083,     -0.25139, 98.36833,50.00000,53.00000,2.174282e-10,0.91157,3
207.21300,128.46750,     -0.25530, 98.34143,50.00000,53.00000,2.163258e-10,0.91141,3
208.26700,129.53417,     -0.26413, 98.30080,50.00000,53.00000,2.167568e-10,0.91122,3
209.33000,130.60083,     -0.27299, 98.28048,50.00000,53.00000,2.164249e-10,0.91106,3
210.39101,131.66750,     -0.28063, 98.28725,50.00000,53.00000,2.169991e-10,0.91087,3
211.45799,132.73417,     -0.28916, 98.24661,50.00000,53.00000,2.162056e-10,0.91071,3
212.52699,133.80083,     -0.29648, 98.21972,50.00000,53.00000,2.167205e-10,0.91051,3
213.59000,134.86750,     -0.30540, 98.16773,50.00000,53.00000,2.166233e-10,0.91035,3
214.65700,135.93417,     -0.31487, 98.17450,50.00000,53.00000,2.173195e-10,0.91015,3
215.71600,137.00083,     -0.32294, 98.12052,50.00000,53.00000,2.170047e-10,0.90998,3
216.78101,138.06750,     -0.33298, 98.11375,50.00000,53.00000,2.172546e-10,0.90979,3
217.85001,139.13417,     -0.34038, 98.05956,50.00000,53.00000,2.173920e-10,0.90959,3
218.91800,140.20083,     -0.34762, 98.03944,50.00000,53.00000,2.174721e-10,0.90942,3
219.98300,141.26750,     -0.35665, 98.02590,50.00000,53.00000,2.177716e-10,0.90922,3
221.05701,142.33417,     -0.36392, 97.97171,50.00000,53.00000,2.177333e-10,0.90904,3
222.12601,143.40083,     -0.37441, 97.94462,50.00000,53.00000,2.174053e-10,0.90884,3
223.20100,144.46750,     -0.38314, 97.91773,50.00000,53.00000,2.179050e-10,0.90866,3
224.26401,145.53417,     -0.39243, 97.85000,50.00000,53.00000,2.172584e-10,0.90846,3
225.33000,146.60083,     -0.40048, 97.80956,50.00000,53.00000,2.175178e-10,0.90828,3
226.39301,147.66750,     -0.41105, 97.78924,50.00000,53.00000,2.173538e-10,0.90807,3
227.46100,148.73417,     -0.41986, 97.74183,50.00000,53.00000,2.172222e-10,0.90790,3
228.52600,149.80083,     -0.42868, 97.71474,50.00000,53.00000,2.177697e-10,0.90768,3
229.58200,150.86750,     -0.43949, 97.66076,50.00000,53.00000,2.170296e-10,0.90750,3
230.64700,151.93417,     -0.44818, 97.59323,50.00000,53.00000,2.172565e-10,0.90729,3
231.72501,153.00083,     -0.45940, 97.57968,50.00000,53.00000,2.175694e-10,0.90711,3
232.77600,154.06750,     -0.47135, 97.53904,50.00000,53.00000,2.181816e-10,0.90690,3
233.84200,155.13417,     -0.48064, 97.48486,50.00000,53.00000,2.181797e-10,0.90671,3
234.89900,156.20083,     -0.48833, 97.45120,50.00000,53.00000,2.175980e-10,0.90650,3
235.97400,157.26750,     -0.49892, 97.40378,50.00000,53.00000,2.188949e-10,0.90631,3
237.03600,158.33417,     -0.50827, 97.34980,50.00000,53.00000,2.182007e-10,0.90610,3
238.10800,159.40083,     -0.51909, 97.29562,50.00000,53.00000,2.185001e-10,0.90590,3
239.17300,160.46750,     -0.52921, 97.26175,50.00000,53.00000,2.176761e-10,0.90569,3
240.25900,161.53417,     -0.53955, 97.21454,50.00000,53.00000,2.184486e-10,0.90550,3
241.31300,162.60083,     -0.55152, 97.12669,50.00000,53.00000,2.189064e-10,0.90529,3
242.38200,163.66750,     -0.56080, 97.09283,50.00000,53.00000,2.183609e-10,0.90506,3
243.43900,164.73417,     -0.57119, 97.04542,50.00000,53.00000,2.193203e-10,0.90487,3
244.51199,165.80083,     -0.58434, 96.98466,50.00000,53.00000,2.191201e-10,0.90464,3
245.57899,166.86750,     -0.59406, 96.93048,50.00000,53.00000,2.187500e-10,0.90445,3
246.64500,167.93417,     -0.60507, 96.87649,50.00000,53.00000,2.184544e-10,0.90422,3
247.71600,169.00083,     -0.61685, 96.79542,50.00000,53.00000,2.186870e-10,0.90404,3
248.77800,170.06750,     -0.62937, 96.76155,50.00000,53.00000,2.191449e-10,0.90380,3
249.84900,171.13417,     -0.63828, 96.70060,50.00000,53.00000,2.190991e-10,0.90361,3
250.91600,172.20083,     -0.65049, 96.61952,50.00000,53.00000,2.181911e-10,0.90338,3
251.97900,173.26750,     -0.66036, 96.57888,50.00000,53.00000,2.191410e-10,0.90319,3
253.05000,174.33417,     -0.67007, 96.52490,50.00000,53.00000,2.187405e-10,0.90295,3
254.12801,175.40083,     -0.68237, 96.44382,50.00000,53.00000,2.189636e-10,0.90274,3
255.18900,176.46750,     -0.69488, 96.38964,50.00000,53.00000,2.189884e-10,0.90252,3
256.25299,177.53417,     -0.70540, 96.29502,50.00000,53.00000,2.184296e-10,0.90231,3
257.32501,178.60083,     -0.71870, 96.22072,50.00000,53.00000,2.193584e-10,0.90208,3
258.37299,179.66750,     -0.73092, 96.13944,50.00000,53.00000,2.185802e-10,0.90188,3
259.44000,180.73417,     -0.74097, 96.07869,50.00000,53.00000,2.189598e-10,0.90164,3
260.49500,181.80083,     -0.75343, 96.01116,50.00000,53.00000,2.194595e-10,0.90144,3
261.56799,182.86750,     -0.76372, 95.90279,50.00000,53.00000,2.187576e-10,0.90120,3
262.64301,183.93417,     -0.77644, 95.83526,50.00000,53.00000,2.191582e-10,0.90099,3
263.70801,185.00083,     -0.78808, 95.75418,50.00000,53.00000,2.194710e-10,0.90075,3
264.77399,186.06750,     -0.80011, 95.64602,50.00000,53.00000,2.188149e-10,0.90054,3
265.82901,187.13417,     -0.81235, 95.53546,50.00000,53.00000,2.192078e-10,0.90030,3
266.90799,188.20083,     -0.82408, 95.42510,50.00000,53.00000,2.184964e-10,0.90006,3
267.97299,189.26750,     -0.83453, 95.31912,50.00000,53.00000,2.186356e-10,0.89984,3
269.03900,190.33417,     -0.84817, 95.23586,50.00000,53.00000,2.187043e-10,0.89960,3
270.10699,191.40083,     -0.85812, 95.07351,50.00000,53.00000,2.186775e-10,0.89939,3
271.16599,192.46750,     -0.87220, 94.96534,50.00000,53.00000,2.194729e-10,0.89918,3
272.22198,193.53417,     -0.88537, 94.83008,50.00000,53.00000,2.186050e-10,0.89892,3
273.30600,194.60083,     -0.90028, 94.72191,50.00000,53.00000,2.192364e-10,0.89868,3
274.35501,195.66750,     -0.90976, 94.55976,50.00000,53.00000,2.189617e-10,0.89846,3
275.42401,196.73417,     -0.92135, 94.39741,50.00000,53.00000,2.201214e-10,0.89821,3
276.50101,197.80083,     -0.93561, 94.25538,50.00000,53.00000,2.195701e-10,0.89798,3
277.55600,198.86750,     -0.94669, 94.07291,50.00000,53.00000,2.187042e-10,0.89774,3
278.63101,199.93417,     -0.96101, 93.90378,50.00000,53.00000,2.195854e-10,0.89752,3
279.68799,201.00083,     -0.97234, 93.72809,50.00000,53.00000,2.199172e-10,0.89727,3
280.75900,202.06750,     -0.98352, 93.52530,50.00000,53.00000,2.194118e-10,0.89705,3
281.83099,203.13417,     -0.99624, 93.36295,50.00000,53.00000,2.199916e-10,0.89678,3
282.89899,204.20083,     -1.01146, 93.17371,50.00000,53.00000,2.198162e-10,0.89656,3
283.95099,205.26750,     -1.02536, 92.98446,50.00000,53.00000,2.196274e-10,0.89632,3
285.02899,206.33417,     -1.03858, 92.75896,50.00000,53.00000,2.197418e-10,0.89610,3
286.09100,207.40083,     -1.05181, 92.54263,50.00000,53.00000,2.199115e-10,0.89584,3
287.14600,208.46750,     -1.06582, 92.32629,50.00000,53.00000,2.202759e-10,0.89561,3
288.23001,209.53417,     -1.07705, 92.10100,50.00000,53.00000,2.201863e-10,0.89536,3
289.28601,210.60083,     -1.09228, 91.82371,50.00000,53.00000,2.204895e-10,0.89513,3
290.34900,211.66750,     -1.10508, 91.60737,50.00000,53.00000,2.204075e-10,0.89486,3
291.42801,212.73417,     -1.11984, 91.39104,50.00000,53.00000,2.203294e-10,0.89464,3
292.49200,213.80083,     -1.13367, 91.12052,50.00000,53.00000,2.201042e-10,0.89437,3
293.55499,214.86750,     -1.14772, 90.90199,50.00000,53.00000,2.198448e-10,0.89413,3
294.61801,215.93417,     -1.16123, 90.65418,50.00000,53.00000,2.204648e-10,0.89387,3
295.69000,217.00083,     -1.17863, 90.38367,50.00000,53.00000,2.205792e-10,0.89360,3
296.75900,218.06750,     -1.19030, 90.10876,50.00000,53.00000,2.199421e-10,0.89338,3
297.81500,219.13417,     -1.20757, 89.86534,50.00000,53.00000,2.207298e-10,0.89311,3
298.88199,220.20083,     -1.22163, 89.56335,50.00000,53.00000,2.206249e-10,0.89287,3
299.95599,221.26750,     -1.23554, 89.27928,50.00000,53.00000,2.215748e-10,0.89261,3
301.01001,222.33417,     -1.25293, 89.00896,50.00000,53.00000,2.210217e-10,0.89237,3
302.07401,223.40083,     -1.26632, 88.74084,50.00000,53.00000,2.210350e-10,0.89214,3
303.14401,224.46750,     -1.28053, 88.44104,50.00000,53.00000,2.209874e-10,0.89186,3
304.20700,225.53417,     -1.29477, 88.13227,50.00000,53.00000,2.205163e-10,0.89163,3
305.28400,226.60083,     -1.30946, 87.80319,50.00000,53.00000,2.205620e-10,0.89135,3
306.36200,227.66750,     -1.32730, 87.52829,50.00000,53.00000,2.206078e-10,0.89111,3
307.41400,228.73417,     -1.34242, 87.20139,50.00000,53.00000,2.211857e-10,0.89083,3
308.48099,229.80083,     -1.35994, 86.84761,50.00000,53.00000,2.205848e-10,0.89056,3
309.55499,230.86750,     -1.37440, 86.54124,50.00000,53.00000,2.210522e-10,0.89031,3
310.61801,231.93417,     -1.38849, 86.19641,50.00000,53.00000,2.212830e-10,0.89004,3
311.69800,233.00083,     -1.40812, 85.81554,50.00000,53.00000,2.202415e-10,0.88980,3
312.75699,234.06750,     -1.42268, 85.45498,50.00000,53.00000,2.205982e-10,0.88951,3
313.82700,235.13417,     -1.43729, 85.08765,50.00000,53.00000,2.213440e-10,0.88926,3
314.89200,236.20083,     -1.45784, 84.69542,50.00000,53.00000,2.204571e-10,0.88899,3
315.95801,237.26750,     -1.47214, 84.28984,50.00000,53.00000,2.208252e-10,0.88873,3
317.02600,238.33417,     -1.49081, 83.85259,50.00000,53.00000,2.210350e-10,0.88845,3
318.08099,239.40083,     -1.50538, 83.46713,50.00000,53.00000,2.211399e-10,0.88821,3
319.15302,240.46750,     -1.52277, 82.99622,50.00000,53.00000,2.211437e-10,0.88792,3
320.22000,241.53417,     -1.53744, 82.55438,50.00000,53.00000,2.209358e-10,0.88768,3
321.28400,242.60083,     -1.55273, 82.09024,50.00000,53.00000,2.211914e-10,0.88739,3
322.35699,243.66750,     -1.56729, 81.62371,50.00000,53.00000,2.210598e-10,0.88714,3
323.42899,244.73417,     -1.58209, 81.14582,50.00000,53.00000,2.209702e-10,0.88685,3
324.49600,245.80083,     -1.59950, 80.58924,50.00000,53.00000,2.216225e-10,0.88661,3
325.55099,246.86750,     -1.61594, 80.06414,50.00000,53.00000,2.209530e-10,0.88631,3
326.61899,247.93417,     -1.63006, 79.52550,50.00000,53.00000,2.212906e-10,0.88606,3
327.69400,249.00083,     -1.64583, 78.95538,50.00000,53.00000,2.220878e-10,0.88577,3
328.75699,250.06750,     -1.66282, 78.39422,50.00000,53.00000,2.213344e-10,0.88551,3
329.81799,251.13417,     -1.68225, 77.74502,50.00000,53.00000,2.217750e-10,0.88523,3
330.88800,252.20083,     -1.69714, 77.13207,50.00000,54.00000,2.213192e-10,0.88497,3
331.93500,253.26750,     -1.71523, 76.44243,50.00000,54.00000,2.224293e-10,0.88467,3
333.02301,254.33417,     -1.72683, 75.77092,50.00000,54.00000,2.217769e-10,0.88436,3
334.08099,255.40083,     -1.74444, 75.09701,50.00000,54.00000,2.215519e-10,0.88411,3
335.13901,256.46750,     -1.76431, 74.36016,50.00000,54.00000,2.223054e-10,0.88382,3
336.21100,257.53417,     -1.77962, 73.61633,50.00000,54.00000,2.226696e-10,0.88356,3
337.27301,258.60083,     -1.79637, 72.85916,50.00000,54.00000,2.220478e-10,0.88326,3
338.34500,259.66750,     -1.81460, 72.02530,50.00000,54.00000,2.225113e-10,0.88301,3
339.41000,260.73417,     -1.83084, 71.17570,50.00000,54.00000,2.221107e-10,0.88270,3
340.48099,261.80083,     -1.84897, 70.32371,50.00000,54.00000,2.219238e-10,0.88243,3
341.54700,262.86750,     -1.86428, 69.46972,50.00000,54.00000,2.221623e-10,0.88213,3
342.60901,263.93417,     -1.88655, 68.53446,50.00000,54.00000,2.224388e-10,0.88187,3
343.68399,265.00083,     -1.90443, 67.61494,50.00000,54.00000,2.227936e-10,0.88156,3
344.75000,266.06750,     -1.92519, 66.63008,50.00000,54.00000,2.225914e-10,0.88129,3
345.81799,267.13417,     -1.94275, 65.65199,50.00000,54.00000,2.228508e-10,0.88099,3
346.87299,268.20083,     -1.96523, 64.62888,50.00000,54.00000,2.231045e-10,0.88069,3
347.93900,269.26750,     -1.98329, 63.57869,50.00000,54.00000,2.227077e-10,0.88042,3
349.01001,270.33417,     -2.00326, 62.50359,50.00000,54.00000,2.230968e-10,0.88012,3
350.07999,271.40083,     -2.02082, 61.42869,50.00000,54.00000,2.231255e-10,0.87985,3
351.13400,272.46750,     -2.03983, 60.27928,50.00000,54.00000,2.228317e-10,0.87954,3
352.20999,273.53417,     -2.05626, 59.17948,50.00000,54.00000,2.229710e-10,0.87927,3
353.29300,274.60083,     -2.07503, 58.03685,50.00000,54.00000,2.228813e-10,0.87896,3
354.34201,275.66750,     -2.09294, 56.85359,50.00000,54.00000,2.229347e-10,0.87869,3
355.41400,276.73417,     -2.10992, 55.62311,50.00000,54.00000,2.231522e-10,0.87838,3
356.47601,277.80083,     -2.13148, 54.48964,50.00000,54.00000,2.235794e-10,0.87811,3
357.54300,278.86750,     -2.15311, 53.26813,50.00000,54.00000,2.226581e-10,0.87781,3
358.60101,279.93417,     -2.17373, 52.08725,50.00000,54.00000,2.240524e-10,0.87753,3
359.67099,281.00083,     -2.19424, 50.85219,50.00000,54.00000,2.234708e-10,0.87721,3
360.73999,282.06750,     -2.21626, 49.64203,50.00000,54.00000,2.232495e-10,0.87693,3
361.80099,283.13417,     -2.23853, 48.44303,50.00000,54.00000,2.240906e-10,0.87661,3
362.88000,284.20083,     -2.26153, 47.19900,50.00000,54.00000,2.232934e-10,0.87635,3
363.94000,285.26750,     -2.28455, 45.99781,50.00000,54.00000,2.228527e-10,0.87602,3
365.00500,286.33417,     -2.30764, 44.76494,50.00000,54.00000,2.236901e-10,0.87574,3
366.07199,287.40083,     -2.32597, 43.53008,50.00000,54.00000,2.230549e-10,0.87542,3
367.14001,288.46750,     -2.35151, 42.30618,50.00000,54.00000,2.237244e-10,0.87515,3
368.19800,289.53417,     -2.37476, 41.07351,50.00000,54.00000,2.235584e-10,0.87483,3
369.26999,290.60083,     -2.39834, 39.89482,50.00000,54.00000,2.237625e-10,0.87455,3
370.33099,291.66750,     -2.42215, 38.66215,50.00000,54.00000,2.235813e-10,0.87422,3
371.40701,292.73417,     -2.44714, 37.41574,50.00000,54.00000,2.237855e-10,0.87395,3
372.45901,293.80083,     -2.47190, 36.21016,50.00000,54.00000,2.238159e-10,0.87363,3
373.51300,294.86750,     -2.49229, 34.98406,50.00000,54.00000,2.234288e-10,0.87335,3
374.59601,295.93417,     -2.51707, 33.79641,50.00000,54.00000,2.239762e-10,0.87301,3
375.66400,297.00083,     -2.54358, 32.61096,50.00000,54.00000,2.239838e-10,0.87272,3
376.73700,298.06750,     -2.56889, 31.40538,50.00000,54.00000,2.236881e-10,0.87240,3
377.80399,299.13417,     -2.59702, 30.24462,50.00000,54.00000,2.234211e-10,0.87212,3
378.86899,300.20083,     -2.62309, 29.05916,50.00000,54.00000,2.236728e-10,0.87179,3
379.93900,301.26750,     -2.65181, 27.88964,50.00000,54.00000,2.236310e-10,0.87150,3
380.99301,302.33417,     -2.68163, 26.74920,50.00000,54.00000,2.228298e-10,0.87118,3
382.06699,303.40083,     -2.71095, 25.58625,50.00000,54.00000,2.114982e-10,0.87089,3
383.13101,304.46750,     -2.74011, 24.49323,50.00000,54.00000,2.122249e-10,0.87055,3
384.19299,305.53417,     -2.77664, 23.40936,50.00000,54.00000,2.115021e-10,0.87027,3
385.27100,306.60083,     -2.80623, 22.31633,50.00000,54.00000,2.116852e-10,0.86993,3
386.32501,307.66750,     -2.83969, 21.22550,50.00000,54.00000,2.118263e-10,0.86965,3
387.40500,308.73417,     -2.86881, 20.20916,50.00000,54.00000,2.104569e-10,0.86932,3
388.46899,309.80083,     -2.92712, 19.17689,50.00000,54.00000,2.112809e-10,0.86903,3
389.54001,310.86750,     -2.96788, 18.20100,50.00000,54.00000,2.109909e-10,0.86870,3
390.59900,311.93417,     -3.00740, 17.25677,50.00000,54.00000,2.114086e-10,0.86840,3
391.66901,313.00083,     -3.05098, 16.36434,50.00000,54.00000,2.110252e-10,0.86806,3
392.73599,314.06750,     -3.09271, 15.47869,50.00000,54.00000,2.110443e-10,0.86772,3
393.80801,315.13417,     -3.14154, 14.66056,50.00000,54.00000,2.110271e-10,0.86744,3
394.87900,316.20083,     -3.19269, 13.86275,50.00000,54.00000,2.112788e-10,0.86710,3
395.93600,317.26750,     -3.24522, 13.07390,50.00000,54.00000,2.110691e-10,0.86681,3
397.00601,318.33417,     -3.29468, 12.41594,50.00000,54.00000,2.109585e-10,0.86647,3
398.06500,319.40083,     -3.34729, 11.76235,50.00000,54.00000,2.113838e-10,0.86616,3
399.14001,320.46750,     -3.39902, 11.17410,50.00000,54.00000,2.112618e-10,0.86583,3
399.66000,320.97917,     -3.42859, 10.91733,50.00000,54.00000,2.108898e-10,0.86569,4
399.77899,321.05917,     -3.42518, 10.89024,50.00000,54.00000,2.108898e-10,0.86569,4
400.01199,321.13917,     -3.33562, 10.84283,50.00000,54.00000,2.115403e-10,0.86563,4
400.37399,321.21917,     -3.13766, 10.83606,50.00000,54.00000,2.115403e-10,0.86563,4
400.90701,321.29917,     -2.82638, 10.88347,50.00000,54.00000,2.119389e-10,0.86558,4
401.61600,321.37917,     -2.40550, 10.91733,50.00000,54.00000,2.119389e-10,0.86558,4
402.49500,321.45917,     -1.89597, 10.97590,50.00000,54.00000,2.110385e-10,0.86553,4
403.54099,321.53917,     -1.32161, 11.06833,50.00000,54.00000,2.110385e-10,0.86553,4
404.75101,321.61917,     -0.71047, 11.12450,50.00000,54.00000,2.115936e-10,0.86548,4
406.08401,321.69917,-8.539993e-02, 11.18765,50.00000,54.00000,2.115936e-10,0.86548,4
407.51801,321.77917,      0.51760, 11.24622,50.00000,54.00000,2.111130e-10,0.86543,4
409.03900,321.85917,      1.08352, 11.30040,50.00000,54.00000,2.111130e-10,0.86543,4
410.60901,321.93917,      1.58797, 11.32749,50.00000,54.00000,2.108460e-10,0.86539,4
412.20401,322.01917,      2.02034, 11.35438,50.00000,54.00000,2.108460e-10,0.86539,4
413.81000,322.09917,      2.37613, 11.38147,50.00000,54.00000,2.119026e-10,0.86534,4
415.40500,322.17917,      2.64111, 11.35438,50.00000,54.00000,2.119026e-10,0.86534,4
416.97800,322.25917,      2.82720, 11.35438,50.00000,54.00000,2.109184e-10,0.86528,4
418.51599,322.33917,      2.93766, 11.32749,50.00000,54.00000,2.109184e-10,0.86528,4
420.01599,322.41917,      2.97853, 11.30040,50.00000,54.00000,2.110653e-10,0.86524,4
421.47601,322.49917,      2.96428, 11.24402,50.00000,54.00000,2.110653e-10,0.86524,4
422.90100,322.57917,      2.90389, 11.18088,50.00000,54.00000,2.111721e-10,0.86519,4
424.28101,322.65917,      2.81542, 11.12231,50.00000,54.00000,2.111721e-10,0.86519,4
425.63699,322.73917,      2.70881, 11.03227,50.00000,54.00000,2.111721e-10,0.86519,4
426.97000,322.81917,      2.59261, 10.97590,50.00000,54.00000,2.109413e-10,0.86514,4
428.29700,322.89917,      2.47962, 10.87211,50.00000,54.00000,2.109413e-10,0.86514,4
429.62399,322.97917,      2.37992, 10.81355,50.00000,54.00000,2.115459e-10,0.86510,4
430.94601,323.05917,      2.29424, 10.74602,50.00000,54.00000,2.115459e-10,0.86510,4
432.27802,323.13917,      2.23625, 10.65797,50.00000,54.00000,2.111321e-10,0.86504,4
433.64801,323.21917,      2.20179, 10.59721,50.00000,54.00000,2.111321e-10,0.86504,4
435.01901,323.29917,      2.19320, 10.51155,50.00000,54.00000,2.111205e-10,0.86499,4
436.42499,323.37917,      2.21140, 10.44622,50.00000,54.00000,2.111205e-10,0.86499,4
437.85999,323.45917,      2.25584, 10.36056,50.00000,54.00000,2.115765e-10,0.86495,4
439.32599,323.53917,      2.31881, 10.32231,50.00000,54.00000,2.115765e-10,0.86495,4
440.83499,323.61917,      2.39652, 10.22988,50.00000,54.00000,2.116204e-10,0.86490,4
442.36700,323.69917,      2.48554, 10.16673,50.00000,54.00000,2.116204e-10,0.86490,4
443.92099,323.77917,      2.58034, 10.10598,50.00000,54.00000,2.113685e-10,0.86485,4
445.50800,323.85917,      2.67680, 10.05857,50.00000,54.00000,2.113685e-10,0.86485,4
447.10400,323.93917,      2.76878,  9.99323,50.00000,54.00000,2.114964e-10,0.86480,4
448.70700,324.01917,      2.85390,  9.89402,50.00000,54.00000,2.114964e-10,0.86480,4
450.33801,324.09917,      2.93033,  9.86693,50.00000,54.00000,2.117329e-10,0.86475,4
451.97101,324.17917,      2.99296,  9.81972,50.00000,54.00000,2.117329e-10,0.86475,4
453.60800,324.25917,      3.04666,  9.74761,50.00000,54.00000,2.116985e-10,0.86471,4
455.24899,324.33917,      3.08547,  9.68904,50.00000,54.00000,2.116985e-10,0.86471,4
456.90201,324.41917,      3.10980,  9.59203,50.00000,54.00000,2.110690e-10,0.86464,4
458.54099,324.49917,      3.12513,  9.59203,50.00000,54.00000,2.110690e-10,0.86464,4
460.19299,324.57917,      3.13034,  9.53566,50.00000,54.00000,2.106761e-10,0.86460,4
461.82800,324.65917,      3.12308,  9.50876,50.00000,54.00000,2.106761e-10,0.86460,4
463.46701,324.73917,      3.10837,  9.48167,50.00000,54.00000,2.113762e-10,0.86456,4
465.10599,324.81917,      3.08711,  9.46135,50.00000,54.00000,2.113762e-10,0.86456,4
466.75500,324.89917,      3.06338,  9.42749,50.00000,54.00000,2.116909e-10,0.86451,4
468.39200,324.97917,      3.03539,  9.42749,50.00000,54.00000,2.116909e-10,0.86451,4
470.04001,325.05917,      3.00706,  9.42749,50.00000,54.00000,2.114811e-10,0.86445,4
471.68399,325.13917,      2.97736,  9.40060,50.00000,54.00000,2.114811e-10,0.86445,4
473.32700,325.21917,      2.95065,  9.42749,50.00000,54.00000,2.113457e-10,0.86441,4
474.98099,325.29917,      2.92190,  9.42749,50.00000,54.00000,2.113457e-10,0.86441,4
476.63800,325.37917,      2.89569,  9.42749,50.00000,54.00000,2.114677e-10,0.86435,4
478.28601,325.45917,      2.86907,  9.42749,50.00000,54.00000,2.114677e-10,0.86435,4
479.95001,325.53917,      2.84555,  9.42749,50.00000,54.00000,2.115459e-10,0.86430,4
481.60501,325.61917,      2.82064,  9.42749,50.00000,54.00000,2.115459e-10,0.86430,4
483.26999,325.69917,      2.79711,  9.44781,50.00000,54.00000,2.114868e-10,0.86426,4
484.93701,325.77917,      2.77322,  9.44781,50.00000,54.00000,2.114868e-10,0.86426,4
486.59500,325.85917,      2.74720,  9.44781,50.00000,54.00000,2.119026e-10,0.86420,4
488.27100,325.93917,      2.72555,  9.44781,50.00000,54.00000,2.119026e-10,0.86420,4
489.94800,326.01917,      2.70502,  9.44781,50.00000,54.00000,2.116242e-10,0.86415,4
491.63101,326.09917,      2.68415,  9.45458,50.00000,54.00000,2.116242e-10,0.86415,4
493.31500,326.17917,      2.65771,  9.45458,50.00000,54.00000,2.118168e-10,0.86411,4
494.99399,326.25917,      2.63310,  9.46813,50.00000,54.00000,2.118168e-10,0.86411,4
496.67300,326.33917,      2.60288,  9.46813,50.00000,54.00000,2.113495e-10,0.86406,4
498.35001,326.41917,      2.57249,  9.46813,50.00000,54.00000,2.113495e-10,0.86406,4
500.02802,326.49917,      2.53745,  9.46813,50.00000,54.00000,2.108593e-10,0.86400,4
501.70999,326.57917,      2.49923,  9.48167,50.00000,54.00000,2.108593e-10,0.86400,4
503.38101,326.65917,      2.46355,  9.50199,50.00000,54.00000,2.121219e-10,0.86395,4
505.06201,326.73917,      2.42067,  9.50876,50.00000,54.00000,2.121219e-10,0.86395,4
506.72501,326.81917,      2.38057,  9.50876,50.00000,54.00000,2.121219e-10,0.86395,4
508.40302,326.89917,      2.33576,  9.48167,50.00000,54.00000,2.109795e-10,0.86391,4
510.07501,326.97917,      2.29477,  9.48167,50.00000,54.00000,2.109795e-10,0.86391,4
511.73999,327.05917,      2.24926,  9.50876,50.00000,54.00000,2.116356e-10,0.86386,4
513.41400,327.13917,      2.20482,  9.50876,50.00000,54.00000,2.116356e-10,0.86386,4
515.08502,327.21917,      2.15992,  9.50876,50.00000,54.00000,2.114602e-10,0.86381,4
516.74701,327.29917,      2.11376,  9.50876,50.00000,54.00000,2.114602e-10,0.86381,4
518.41602,327.37917,      2.06869,  9.50876,50.00000,54.00000,2.110863e-10,0.86376,4
520.08099,327.45917,      2.02314,  9.50876,50.00000,54.00000,2.110863e-10,0.86376,4
521.76099,327.53917,      1.97974,  9.50876,50.00000,54.00000,2.120610e-10,0.86371,4
523.43201,327.61917,      1.94102,  9.50876,50.00000,54.00000,2.120610e-10,0.86371,4
525.10400,327.69917,      1.90497,  9.51554,50.00000,54.00000,2.111454e-10,0.86366,4
526.79303,327.77917,      1.86827,  9.51554,50.00000,54.00000,2.111454e-10,0.86366,4
528.46997,327.85917,      1.83294,  9.51554,50.00000,54.00000,2.116470e-10,0.86361,4
530.14099,327.93917,      1.79482,  9.51554,50.00000,54.00000,2.116470e-10,0.86361,4
531.82703,328.01917,      1.75499,  9.53566,50.00000,54.00000,2.116585e-10,0.86356,4
533.49298,328.09917,      1.70946,  9.53566,50.00000,54.00000,2.116585e-10,0.86356,4
535.17902,328.17917,      1.66480,  9.50876,50.00000,54.00000,2.115993e-10,0.86351,4
536.85101,328.25917,      1.62124,  9.53566,50.00000,54.00000,2.115993e-10,0.86351,4
538.50500,328.33917,      1.56613,  9.53566,50.00000,54.00000,2.113666e-10,0.86347,4
540.18298,328.41917,      1.50978,  9.53566,50.00000,54.00000,2.113666e-10,0.86347,4
541.83801,328.49917,      1.45023,  9.53566,50.00000,54.00000,2.104702e-10,0.86341,4
543.50000,328.57917,      1.39019,  9.56275,50.00000,54.00000,2.104702e-10,0.86341,4
545.14697,328.65917,      1.32880,  9.56275,50.00000,54.00000,2.114715e-10,0.86336,4
546.80499,328.73917,      1.27115,  9.56275,50.00000,54.00000,2.114715e-10,0.86336,4
548.45203,328.81917,      1.21352,  9.56275,50.00000,54.00000,2.115918e-10,0.86331,4
550.10602,328.89917,      1.15565,  9.58984,50.00000,54.00000,2.115918e-10,0.86331,4
551.75598,328.97917,      1.09888,  9.58984,50.00000,54.00000,2.109929e-10,0.86326,4
553.39203,329.05917,      1.04372,  9.58984,50.00000,54.00000,2.109929e-10,0.86326,4
555.04303,329.13917,      0.99158,  9.59661,50.00000,54.00000,2.110539e-10,0.86322,4
556.69897,329.21917,      0.94031,  9.61016,50.00000,54.00000,2.110539e-10,0.86322,4
558.33502,329.29917,      0.88853,  9.61016,50.00000,54.00000,2.111148e-10,0.86316,4
559.97699,329.37917,      0.83656,  9.61016,50.00000,54.00000,2.111148e-10,0.86316,4
561.62598,329.45917,      0.78546,  9.63048,50.00000,54.00000,2.113953e-10,0.86311,4
563.27399,329.53917,      0.73578,  9.67092,50.00000,54.00000,2.113953e-10,0.86311,4
564.92603,329.61917,      0.69052,  9.67092,50.00000,54.00000,2.116928e-10,0.86307,4
566.58197,329.69917,      0.63692,  9.69801,50.00000,54.00000,2.116928e-10,0.86307,4
568.22198,329.77917,      0.58664,  9.69801,50.00000,54.00000,2.116489e-10,0.86302,4
569.87000,329.85917,      0.53371,  9.69801,50.00000,54.00000,2.116489e-10,0.86302,4
571.52600,329.93917,      0.48249,  9.72510,50.00000,54.00000,2.117539e-10,0.86296,4
573.15900,330.01917,      0.43791,  9.75219,50.00000,54.00000,2.117539e-10,0.86296,4
574.80902,330.09917,      0.38712,  9.75876,50.00000,54.00000,2.117634e-10,0.86292,4
576.45001,330.17917,      0.33449,  9.77908,50.00000,54.00000,2.117634e-10,0.86292,4
578.09998,330.25917,      0.28055,  9.77908,50.00000,54.00000,2.110577e-10,0.86287,4
579.73999,330.33917,      0.23027,  9.77908,50.00000,54.00000,2.110577e-10,0.86287,4
581.37701,330.41917,      0.17483,  9.80618,50.00000,54.00000,2.116146e-10,0.86281,4
583.01398,330.49917,      0.12194,  9.83327,50.00000,54.00000,2.116146e-10,0.86281,4
584.65399,330.57917, 6.191613e-02,  9.84681,50.00000,54.00000,2.119979e-10,0.86276,4
586.29700,330.65917, 4.450646e-03,  9.86036,50.00000,54.00000,2.119979e-10,0.86276,4
587.93597,330.73917,-5.127677e-02,  9.86036,50.00000,54.00000,2.119979e-10,0.86276,4
589.58502,330.81917,     -0.10665,  9.88725,50.00000,54.00000,2.113953e-10,0.86272,4
591.21301,330.89917,     -0.15887,  9.91434,50.00000,54.00000,2.113953e-10,0.86272,4
592.85901,330.97917,     -0.21436,  9.92789,50.00000,54.00000,2.123299e-10,0.86266,4
594.47998,331.05917,     -0.27033,  9.92789,50.00000,54.00000,2.123299e-10,0.86266,4
596.13599,331.13917,     -0.32539,  9.92789,50.00000,54.00000,2.117977e-10,0.86261,4
597.76501,331.21917,     -0.38458,  9.94143,50.00000,54.00000,2.117977e-10,0.86261,4
599.39099,331.29917,     -0.44002,  9.96853,50.00000,54.00000,2.124900e-10,0.86257,4
601.04199,331.37917,     -0.49680,  9.99542,50.00000,54.00000,2.124900e-10,0.86257,4
602.66498,331.45917,     -0.55575, 10.02251,50.00000,54.00000,2.119350e-10,0.86251,4
604.30103,331.53917,     -0.60981, 10.02251,50.00000,54.00000,2.119350e-10,0.86251,4
605.92999,331.61917,     -0.66717, 10.04960,50.00000,54.00000,2.116700e-10,0.86246,4
607.56702,331.69917,     -0.72930, 10.04960,50.00000,54.00000,2.116700e-10,0.86246,4
609.19501,331.77917,     -0.78507, 10.07669,50.00000,54.00000,2.113037e-10,0.86242,4
610.83099,331.85917,     -0.84132, 10.09024,50.00000,54.00000,2.113037e-10,0.86242,4
612.45599,331.93917,     -0.90119, 10.13068,50.00000,54.00000,2.118053e-10,0.86236,4
614.08600,332.01917,     -0.95954, 10.13068,50.00000,54.00000,2.118053e-10,0.86236,4
615.71600,332.09917,     -1.00861, 10.11713,50.00000,54.00000,2.119370e-10,0.86232,4
617.34698,332.17917,     -1.06878, 10.11713,50.00000,54.00000,2.119370e-10,0.86232,4
618.96997,332.25917,     -1.12453, 10.15100,50.00000,54.00000,2.115745e-10,0.86227,4
620.59302,332.33917,     -1.18508, 10.17131,50.00000,54.00000,2.115745e-10,0.86227,4
622.22900,332.41917,     -1.24411, 10.18486,50.00000,54.00000,2.116470e-10,0.86222,4
623.85400,332.49917,     -1.30071, 10.19841,50.00000,54.00000,2.116470e-10,0.86222,4
625.47998,332.57917,     -1.35836, 10.22530,50.00000,54.00000,2.119903e-10,0.86216,4
627.10303,332.65917,     -1.41416, 10.24562,50.00000,54.00000,2.119903e-10,0.86216,4
628.72900,332.73917,     -1.47859, 10.25239,50.00000,54.00000,2.121639e-10,0.86211,4
630.34497,332.81917,     -1.53942, 10.25239,50.00000,54.00000,2.121639e-10,0.86211,4
631.97400,332.89917,     -1.59754, 10.27948,50.00000,54.00000,2.108345e-10,0.86206,4
633.60797,332.97917,     -1.65907, 10.30657,50.00000,54.00000,2.108345e-10,0.86206,4
635.22302,333.05917,     -1.71343, 10.30657,50.00000,54.00000,2.122060e-10,0.86202,4
636.85498,333.13917,     -1.76769, 10.33347,50.00000,54.00000,2.122060e-10,0.86202,4
638.47498,333.21917,     -1.82534, 10.33347,50.00000,54.00000,2.116776e-10,0.86197,4
640.10602,333.29917,     -1.88701, 10.33347,50.00000,54.00000,2.116776e-10,0.86197,4
641.72498,333.37917,     -1.94679, 10.36056,50.00000,54.00000,2.119121e-10,0.86191,4
643.34900,333.45917,     -2.00794, 10.38765,50.00000,54.00000,2.119121e-10,0.86191,4
644.97900,333.53917,     -2.06840, 10.41474,50.00000,54.00000,2.116680e-10,0.86184,4
646.59998,333.61917,     -2.12962, 10.41474,50.00000,54.00000,2.116680e-10,0.86184,4
648.22498,333.69917,     -2.19727, 10.41474,50.00000,54.00000,2.123470e-10,0.86181,4
649.84802,333.77917,     -2.25530, 10.44163,50.00000,54.00000,2.123470e-10,0.86181,4
651.47803,333.85917,     -2.32276, 10.46873,50.00000,54.00000,2.117462e-10,0.86177,4
653.08002,333.93917,     -2.38678, 10.49582,50.00000,54.00000,2.117462e-10,0.86177,4
654.71198,334.01917,     -2.45284, 10.49582,50.00000,54.00000,2.113857e-10,0.86171,4
656.33502,334.09917,     -2.51400, 10.49582,50.00000,54.00000,2.113857e-10,0.86171,4
657.95502,334.17917,     -2.57802, 10.49582,50.00000,54.00000,2.117310e-10,0.86167,4
659.57898,334.25917,     -2.63262, 10.52291,50.00000,54.00000,2.117310e-10,0.86167,4
661.19397,334.33917,     -2.69368, 10.54980,50.00000,54.00000,2.120170e-10,0.86162,4
662.81897,334.41917,     -2.75283, 10.57689,50.00000,54.00000,2.120170e-10,0.86162,4
664.44397,334.49917,     -2.81094, 10.59721,50.00000,54.00000,2.120170e-10,0.86162,4
666.06403,334.57917,     -2.87585, 10.59721,50.00000,54.00000,2.118606e-10,0.86157,4
667.67401,334.65917,     -2.93759, 10.59721,50.00000,54.00000,2.118606e-10,0.86157,4
669.29999,334.73917,     -3.00077, 10.60398,50.00000,54.00000,2.117367e-10,0.86152,4
670.92499,334.81917,     -3.06928, 10.63108,50.00000,54.00000,2.117367e-10,0.86152,4
672.54102,334.89917,     -3.13949, 10.65797,50.00000,54.00000,2.109051e-10,0.86146,4
674.16803,334.97917,     -3.20932, 10.65797,50.00000,54.00000,2.109051e-10,0.86146,4
675.79102,335.05917,     -3.28086, 10.65797,50.00000,54.00000,2.118073e-10,0.86141,4
677.39697,335.13917,     -3.34490, 10.65797,50.00000,54.00000,2.118073e-10,0.86141,4
679.04700,335.21917,     -3.41386, 10.68506,50.00000,54.00000,2.118282e-10,0.86136,4
680.63599,335.29917,     -3.48434, 10.71215,50.00000,54.00000,2.118282e-10,0.86136,4
682.25403,335.37917,     -3.56556, 10.71215,50.00000,54.00000,2.114105e-10,0.86131,4
683.86200,335.45917,     -3.63436, 10.71215,50.00000,54.00000,2.114105e-10,0.86131,4
685.47803,335.53917,     -3.70461, 10.73924,50.00000,54.00000,2.119846e-10,0.86127,4
687.10303,335.61917,     -3.77940, 10.73924,50.00000,54.00000,2.119846e-10,0.86127,4
688.73401,335.69917,     -3.84948, 10.76633,50.00000,54.00000,2.114067e-10,0.86123,4
690.34302,335.77917,     -3.91812, 10.76633,50.00000,54.00000,2.114067e-10,0.86123,4
691.95398,335.85917,     -3.98479, 10.82032,50.00000,54.00000,2.115593e-10,0.86116,4
693.58398,335.93917,     -4.04643, 10.82032,50.00000,54.00000,2.115593e-10,0.86116,4
695.18903,336.01917,     -4.11964, 10.82032,50.00000,54.00000,2.117444e-10,0.86111,4
696.81201,336.09917,     -4.19561, 10.84741,50.00000,54.00000,2.117444e-10,0.86111,4
698.43799,336.17917,     -4.26962, 10.84741,50.00000,54.00000,2.110634e-10,0.86107,4
700.04303,336.25917,     -4.34312, 10.87450,50.00000,54.00000,2.110634e-10,0.86107,4
701.65997,336.33917,     -4.42218, 10.87450,50.00000,54.00000,2.124977e-10,0.86102,4
703.28198,336.41917,     -4.50711, 10.90139,50.00000,54.00000,2.124977e-10,0.86102,4
704.90503,336.49917,     -4.58663, 10.90139,50.00000,54.00000,2.119407e-10,0.86096,4
706.52197,336.57917,     -4.66163, 10.91494,50.00000,54.00000,2.119407e-10,0.86096,4
708.13800,336.65917,     -4.73243, 10.92849,50.00000,54.00000,2.117882e-10,0.86091,4
709.75000,336.73917,     -4.80780, 10.92849,50.00000,54.00000,2.117882e-10,0.86091,4
711.37201,336.81917,     -4.88405, 10.95558,50.00000,54.00000,2.113819e-10,0.86085,4
712.97803,336.89917,     -4.95695, 10.97590,50.00000,54.00000,2.113819e-10,0.86085,4
714.60303,336.97917,     -5.03266, 10.98267,50.00000,54.00000,2.124023e-10,0.86081,4
716.22101,337.05917,     -5.10760, 11.00956,50.00000,54.00000,2.124023e-10,0.86081,4
717.84497,337.13917,     -5.18434, 11.00956,50.00000,54.00000,2.115745e-10,0.86076,4
719.45502,337.21917,     -5.25487, 11.03665,50.00000,54.00000,2.115745e-10,0.86076,4
721.07001,337.29917,     -5.33642, 11.03665,50.00000,54.00000,2.124654e-10,0.86070,4
722.67999,337.37917,     -5.41658, 11.06375,50.00000,54.00000,2.124654e-10,0.86070,4
724.30103,337.45917,     -5.49604, 11.06375,50.00000,54.00000,2.121353e-10,0.86066,4
725.91901,337.53917,     -5.57187, 11.09084,50.00000,54.00000,2.121353e-10,0.86066,4
727.53198,337.61917,     -5.64850, 11.09084,50.00000,54.00000,2.118492e-10,0.86061,4
729.15698,337.69917,     -5.73246, 11.11773,50.00000,54.00000,2.118492e-10,0.86061,4
730.77100,337.77917,     -5.81208, 11.14482,50.00000,54.00000,2.115707e-10,0.86056,4
732.38098,337.85917,     -5.88707, 11.14482,50.00000,54.00000,2.115707e-10,0.86056,4
733.99902,337.93917,     -5.96617, 11.14482,50.00000,54.00000,2.116490e-10,0.86051,4
735.61798,338.01917,     -6.04192, 11.17191,50.00000,54.00000,2.116490e-10,0.86051,4
737.22900,338.09917,     -6.11655, 11.19900,50.00000,54.00000,2.116032e-10,0.86046,4
738.85101,338.17917,     -6.19369, 11.22590,50.00000,54.00000,2.116032e-10,0.86046,4
740.46002,338.25917,     -6.26707, 11.22590,50.00000,54.00000,2.114448e-10,0.86041,4
742.08398,338.33917,     -6.34366, 11.22590,50.00000,54.00000,2.114448e-10,0.86041,4
743.70203,338.41917,     -6.41911, 11.27331,50.00000,54.00000,2.116375e-10,0.86036,4
745.31799,338.49917,     -6.49051, 11.28008,50.00000,54.00000,2.116375e-10,0.86036,4
746.93103,338.57917,     -6.55720, 11.28685,50.00000,54.00000,2.116375e-10,0.86036,4
748.54901,338.65917,     -6.62670, 11.30717,50.00000,54.00000,2.115917e-10,0.86031,4
750.16498,338.73917,     -6.70781, 11.33426,50.00000,54.00000,2.115917e-10,0.86031,4
751.77698,338.81917,     -6.78060, 11.33426,50.00000,54.00000,2.126884e-10,0.86026,4
753.39301,338.89917,     -6.85558, 11.33426,50.00000,54.00000,2.126884e-10,0.86026,4
755.00201,338.97917,     -6.92447, 11.33426,50.00000,54.00000,2.111359e-10,0.86021,4
756.62701,339.05917,     -6.99561, 11.36116,50.00000,54.00000,2.111359e-10,0.86021,4
758.22699,339.13917,     -7.06547, 11.36116,50.00000,54.00000,2.120095e-10,0.86015,4
759.84302,339.21917,     -7.13166, 11.38825,50.00000,54.00000,2.120095e-10,0.86015,4
761.45001,339.29917,     -7.19763, 11.40857,50.00000,54.00000,2.120533e-10,0.86010,4
763.07098,339.37917,     -7.27081, 11.41534,50.00000,54.00000,2.120533e-10,0.86010,4
764.68500,339.45917,     -7.33322, 11.46932,50.00000,54.00000,2.114925e-10,0.86006,4
766.29401,339.53917,     -7.39874, 11.46932,50.00000,54.00000,2.114925e-10,0.86006,4
767.91803,339.61917,     -7.46088, 11.45578,50.00000,54.00000,2.119980e-10,0.86001,4
769.52197,339.69917,     -7.53669, 11.48526,50.00000,54.00000,2.119980e-10,0.86001,4
771.14203,339.77917,     -7.60215, 11.51215,50.00000,54.00000,2.125549e-10,0.85996,4
772.75598,339.85917,     -7.66474, 11.51215,50.00000,54.00000,2.125549e-10,0.85996,4
774.37201,339.93917,     -7.73119, 11.53924,50.00000,54.00000,2.115631e-10,0.85990,4
775.97998,340.01917,     -7.79610, 11.56633,50.00000,54.00000,2.115631e-10,0.85990,4
777.59698,340.09917,     -7.85688, 11.59343,50.00000,54.00000,2.121868e-10,0.85985,4
779.20300,340.17917,     -7.91809, 11.59343,50.00000,54.00000,2.121868e-10,0.85985,4
780.81299,340.25917,     -7.97950, 11.59343,50.00000,54.00000,2.116241e-10,0.85980,4
782.45599,340.33917,     -8.04063, 11.62032,50.00000,54.00000,2.116241e-10,0.85980,4
784.03699,340.41917,     -8.09610, 11.62709,50.00000,54.00000,2.113247e-10,0.85976,4
785.64600,340.49917,     -8.15293, 11.67450,50.00000,54.00000,2.113247e-10,0.85976,4
787.25201,340.57917,     -8.20719, 11.67450,50.00000,54.00000,2.122650e-10,0.85970,4
788.86499,340.65917,     -8.26707, 11.67450,50.00000,54.00000,2.122650e-10,0.85970,4
790.48700,340.73917,     -8.32548, 11.70159,50.00000,54.00000,2.121582e-10,0.85964,4
792.08502,340.81917,     -8.37812, 11.70837,50.00000,54.00000,            ,0.44806,4
793.70099,340.89917,     -8.43511, 11.72849,50.00000,54.00000,            ,0.44741,4
794.40900,340.93417,     -8.45543, 11.75558,50.00000,54.00000,            ,0.44713,4