File: data/TGA/005d-L_M/ExpDat_2025_07_05_SL_PS_Tosoh_A1000_isothermal.csv
#EXPORTTYPE:                 ,DATA ALL
#FILE:                       ,2025_07_05_SL_PS_Tosoh_A1000_isothermal.ngb-ss5
#FORMAT:                     ,NETZSCH5
#FTYPE:                      ,ASCII
#IDENTITY:                   ,PS-A1000
#DECIMAL:                    ,POINT
#SEPARATOR:                  ,COMMA
#MTYPE:                      ,DSC
#INSTRUMENT:                 ,NETZSCH STA 449F5
#PROJECT:                    ,PS
#DATE/TIME:                  ,7/5/2025 5:40:11 PM (UTC-4)
#CORR. FILE:                 ,
#TEMPCAL:                    ,05-05-2025 14:38
#SENSITIVITY:                ,28-06-2023 13:53
#LABORATORY:                 ,Tran/AAG
#OPERATOR:                   ,Stanley
#REMARK:                     ,2025_03_29_SL_005d_M1_isothermal
#SAMPLE:                     ,PS-A1000
#SAMPLE MASS /mg:            ,5.16
#MATERIAL:                   ,Polystyrene
#REFERENCE:                  ,
#REFERENCE MASS /mg:         ,0
#TYPE OF CRUCIBLE:           ,Al2O3 85 ‘l, open
#SAMPLE CRUCIBLE MASS /mg:   ,0
#REFERENCE CRUCIBLE MASS /mg:,0
#DSC RANGE /‘V:              ,5000
#TG RANGE /mg:               ,35000
#TAU-R:                      ,---
#CORR. CODE:                 ,000
#EXO:                        ,-1
#RANGE:                      ,30›C....800›C/0.0....20.0K/min
#SEGMENT:                    ,S4/5
#SEG. 1:                     ,30›C/10.0(K/min)/100›C
#SEG. 2:                     ,100›C/00:10/100›C
#SEG. 3:                     ,100›C/5.0(K/min)/300›C
#SEG. 4:                     ,300›C/20:00/300›C
#SEG. 5:                     ,300›C/20.0(K/min)/800›C

##Temp./›C,Time/min,DSC/(mW/mg),Mass/%,Gas Flow(purge2)/(ml/min),Gas Flow(protective)/(ml/min),TIC(scan:1)/A,Sensit./(uV/mW)
299.00101,  57.10000,      2.04881,78.02229,50.00000,46.00000,2.894506e-09,0.78814
302.69299,  59.10000,      0.36555,76.84050,50.00000,46.00000,2.889809e-09,0.78527
303.27701,  61.10000,-3.752292e-02,75.77481,50.00000,46.00000,2.885092e-09,0.78442
302.62299,  63.10000,     -0.17277,74.90659,50.00000,46.00000,2.885237e-09,0.78408
301.84601,  65.10000,     -0.19407,74.19186,50.00000,46.00000,2.879933e-09,0.78436
301.21399,  67.10000,     -0.23813,73.53857,50.00000,46.00000,2.888112e-09,0.78476
300.77399,  69.10000,     -0.20623,73.00795,50.00000,46.00000,2.885372e-09,0.78521
300.48199,  71.10000,     -0.18436,72.45543,50.00000,46.00000,2.878296e-09,0.78560
300.29599,  73.10000,     -0.17117,71.97093,50.00000,46.00000,2.879788e-09,0.78599
300.19501,  75.10000,     -0.16081,71.50388,50.00000,46.00000,2.884896e-09,0.78627
300.10501,  77.10000,     -0.15554,71.05659,50.00000,46.00000,2.887395e-09,0.78650
300.07101,  79.10000,     -0.15290,70.63566,50.00000,46.00000,2.878942e-09,0.78667
300.04401,  81.10000,     -0.14989,70.23876,50.00000,46.00000,2.889602e-09,0.78681
300.04300,  83.10000,     -0.15233,69.85950,50.00000,46.00000,2.878645e-09,0.78691
300.01901,  85.10000,     -0.15233,69.48663,50.00000,46.00000,2.886499e-09,0.78699
300.01099,  87.10000,     -0.15101,69.13159,50.00000,46.00000,2.883096e-09,0.78704
300.01001,  89.10000,     -0.15158,68.81589,50.00000,46.00000,2.877478e-09,0.78709
300.00400,  91.10000,     -0.15308,68.49574,50.00000,46.00000,2.881960e-09,0.78712
300.01099,  93.10000,     -0.15439,68.20620,50.00000,46.00000,2.879278e-09,0.78714
300.01099,  95.10000,     -0.15665,67.89050,50.00000,46.00000,2.885414e-09,0.78716
300.01599,  97.10000,     -0.15402,67.62965,50.00000,46.00000,2.888359e-09,0.78715
300.00101,  99.10000,     -0.15458,67.33140,50.00000,46.00000,2.885399e-09,0.78718
300.01001, 101.10000,     -0.15740,67.10562,50.00000,46.00000,2.884174e-09,0.78718
300.00900, 103.10000,     -0.15740,66.80523,50.00000,46.00000,2.895817e-09,0.78719
300.01099, 105.10000,     -0.15871,66.59477,50.00000,46.00000,2.900777e-09,0.78718
300.00400, 107.10000,     -0.15646,66.33178,50.00000,46.00000,2.897202e-09,0.78719
299.99799, 109.10000,     -0.15702,66.12112,50.00000,46.00000,2.895999e-09,0.78720
300.02301, 111.10000,     -0.15665,65.90853,50.00000,46.00000,2.899162e-09,0.78719
300.01099, 113.10000,     -0.15777,65.68488,50.00000,46.00000,2.902822e-09,0.78720
300.01599, 115.10000,     -0.15853,65.46124,50.00000,46.00000,2.907261e-09,0.78720
300.01501, 117.10000,     -0.15928,65.26395,50.00000,46.00000,2.897994e-09,0.78720
300.01099, 119.10000,     -0.16209,65.06667,50.00000,46.00000,2.900334e-09,0.78721
300.01001, 121.10000,     -0.16266,64.87578,50.00000,46.00000,2.898284e-09,0.78720
300.01999, 123.10000,     -0.15665,64.68081,50.00000,46.00000,2.902274e-09,0.78720
300.03299, 125.10000,     -0.16097,64.46143,50.00000,46.00000,2.904330e-09,0.78720
300.01801, 127.10000,     -0.16078,64.27733,50.00000,46.00000,2.907115e-09,0.78719
300.01599, 129.10000,     -0.15871,64.09322,50.00000,46.00000,2.901000e-09,0.78719
300.02100, 131.10000,     -0.15965,63.93314,50.00000,46.00000,2.904142e-09,0.78720
300.01599, 133.10000,     -0.16172,63.74884,50.00000,46.00000,2.909256e-09,0.78720
300.01999, 135.10000,     -0.15796,63.59109,50.00000,46.00000,2.900672e-09,0.78720
300.00500, 137.10000,     -0.16341,63.41337,50.00000,46.00000,2.902863e-09,0.78721
300.00800, 139.10000,     -0.16003,63.24903,50.00000,46.00000,2.901473e-09,0.78721
300.01401, 141.10000,     -0.16116,63.10213,50.00000,46.00000,2.900171e-09,0.78720
300.01901, 143.10000,     -0.16228,62.91802,50.00000,46.00000,2.895539e-09,0.78720
300.01599, 145.10000,     -0.16454,62.76008,50.00000,46.00000,2.904550e-09,0.78720
300.01999, 147.10000,     -0.16228,62.60213,50.00000,46.00000,2.906880e-09,0.78719
300.02802, 149.10000,     -0.16416,62.44438,50.00000,46.00000,2.905551e-09,0.78719
300.02701, 151.10000,     -0.16454,62.31279,50.00000,46.00000,2.901668e-09,0.78720
300.01901, 153.10000,     -0.16473,62.15504,50.00000,46.00000,2.903642e-09,0.78719
300.02301, 155.10000,     -0.16416,61.99050,50.00000,46.00000,2.902705e-09,0.78719
300.01599, 157.10000,     -0.16266,61.85891,50.00000,46.00000,2.902878e-09,0.78718
300.02499, 159.10000,     -0.16473,61.72733,50.00000,46.00000,2.903934e-09,0.78720
300.01099, 161.10000,     -0.16773,61.58275,50.00000,46.00000,2.906577e-09,0.78718
300.01199, 163.10000,     -0.16548,61.45116,50.00000,46.00000,2.902248e-09,0.78719
300.01999, 165.10000,     -0.16811,61.29322,50.00000,46.00000,2.901237e-09,0.78719
300.01099, 167.10000,     -0.16529,61.15291,50.00000,46.00000,2.902816e-09,0.78719
300.01801, 169.10000,     -0.16867,61.02791,50.00000,46.00000,2.902377e-09,0.78718
300.00601, 171.10000,     -0.17130,60.90310,50.00000,46.00000,2.912495e-09,0.78719
300.01999, 173.10000,     -0.16623,60.75620,50.00000,46.00000,2.899815e-09,0.78720
300.02100, 175.10000,     -0.17074,60.65736,50.00000,46.00000,2.900949e-09,0.78719
300.02100, 177.10000,     -0.16773,60.49961,50.00000,46.00000,2.896174e-09,0.78718
300.01199, 179.10000,     -0.17073,60.40756,50.00000,46.00000,2.903493e-09,0.78719
300.02200, 181.10000,     -0.17017,60.26066,50.00000,46.00000,2.902775e-09,0.78719
300.01099, 183.10000,     -0.17130,60.15543,50.00000,46.00000,2.906636e-09,0.78719
300.01300, 185.10000,     -0.17261,60.04360,50.00000,46.00000,2.900920e-09,0.78718
300.02399, 187.10000,     -0.17149,59.89225,50.00000,46.00000,2.904048e-09,0.78719
300.00699, 189.10000,     -0.17318,59.78043,50.00000,46.00000,2.906599e-09,0.78720
300.02399, 191.10000,     -0.17337,59.68178,50.00000,46.00000,2.897113e-09,0.78721
300.02301, 193.10000,     -0.17224,59.54360,50.00000,46.00000,2.905099e-09,0.78719
300.02600, 195.10000,     -0.17393,59.43837,50.00000,46.00000,2.902174e-09,0.78719
300.01700, 197.10000,     -0.17600,59.31996,50.00000,46.00000,2.897969e-09,0.78719
300.02301, 199.10000,     -0.17506,59.21473,50.00000,46.00000,2.902749e-09,0.78720
300.01099, 201.10000,     -0.17468,59.09632,50.00000,46.00000,2.904034e-09,0.78718
300.01099, 203.10000,     -0.17731,58.99767,50.00000,46.00000,2.906218e-09,0.78720
300.01401, 205.10000,     -0.17506,58.83992,50.00000,46.00000,2.895198e-09,0.78719
300.01599, 207.10000,     -0.17524,58.78062,50.00000,46.00000,2.900036e-09,0.78718
300.02499, 209.10000,     -0.17506,58.66880,50.00000,46.00000,2.896023e-09,0.78718
300.00500, 211.10000,     -0.17787,58.57674,50.00000,46.00000,2.897638e-09,0.78719
300.00400, 213.10000,     -0.17580,58.47151,50.00000,46.00000,2.904657e-09,0.78719
300.00900, 215.10000,     -0.17750,58.35969,50.00000,46.00000,2.902295e-09,0.78719
300.00400, 217.10000,     -0.17712,58.21492,50.00000,46.00000,2.903009e-09,0.78719
300.00800, 219.10000,     -0.17825,58.14922,50.00000,46.00000,2.902970e-09,0.78719
300.02100, 221.10000,     -0.17750,58.04399,50.00000,46.00000,2.904067e-09,0.78720
300.01099, 223.10000,     -0.17881,57.94535,50.00000,46.00000,2.897661e-09,0.78719
300.01501, 225.10000,     -0.17750,57.82035,50.00000,46.00000,2.897778e-09,0.78718
300.01401, 227.10000,     -0.18031,57.75465,50.00000,46.00000,2.901604e-09,0.78718
300.01700, 229.10000,     -0.18125,57.64283,50.00000,46.00000,2.895639e-09,0.78720
300.00601, 231.10000,     -0.18050,57.53101,50.00000,46.00000,2.901363e-09,0.78719
300.01300, 233.10000,     -0.18013,57.43217,50.00000,46.00000,2.900602e-09,0.78719
300.02301, 235.10000,     -0.17975,57.33353,50.00000,46.00000,2.901487e-09,0.78719
300.01700, 237.10000,     -0.18388,57.23934,50.00000,46.00000,2.896260e-09,0.78719
300.00201, 239.10000,     -0.18144,57.12752,50.00000,46.00000,2.894675e-09,0.78720
300.01199, 241.10000,     -0.18257,57.05523,50.00000,46.00000,2.893238e-09,0.78719
300.01801, 243.10000,     -0.18370,56.95000,50.00000,46.00000,2.891981e-09,0.78719
300.02399, 245.10000,     -0.18276,56.86434,50.00000,46.00000,2.891741e-09,0.78720
300.01401, 247.10000,     -0.18445,56.76570,50.00000,46.00000,2.895775e-09,0.78719
300.01700, 249.10000,     -0.18219,56.66705,50.00000,46.00000,2.892232e-09,0.78719
300.02399, 251.10000,     -0.18501,56.57500,50.00000,46.00000,2.894053e-09,0.78719
300.01801, 253.10000,     -0.18238,56.52229,50.00000,46.00000,2.897469e-09,0.78719
300.01401, 255.10000,     -0.18670,56.41705,50.00000,46.00000,2.896229e-09,0.78719
300.00800, 257.10000,     -0.18707,56.31628,50.00000,46.00000,2.890177e-09,0.78719
300.00800, 259.10000,     -0.18445,56.22422,50.00000,46.00000,2.890170e-09,0.78719
300.00800, 261.10000,     -0.18463,56.14535,50.00000,46.00000,2.888096e-09,0.78719
300.02301, 263.10000,     -0.18745,56.07946,50.00000,46.00000,2.891869e-09,0.78718
300.01401, 265.10000,     -0.19027,55.94787,50.00000,46.00000,2.888375e-09,0.78719
300.01001, 267.10000,     -0.18726,55.89961,50.00000,47.00000,2.885925e-09,0.78718
300.01599, 269.10000,     -0.18895,55.79438,50.00000,47.00000,2.892136e-09,0.78719
300.03201, 271.10000,     -0.18858,55.69574,50.00000,47.00000,2.895065e-09,0.78719
300.01199, 273.10000,     -0.19008,55.63663,50.00000,47.00000,2.885155e-09,0.78720
300.01700, 275.10000,     -0.18877,55.53140,50.00000,47.00000,2.887872e-09,0.78719
300.01501, 277.10000,     -0.18914,55.47209,50.00000,47.00000,2.889887e-09,0.78719
300.02399, 279.10000,     -0.18952,55.36686,50.00000,47.00000,2.885989e-09,0.78718
300.01599, 281.10000,     -0.19083,55.28585,50.00000,47.00000,2.889890e-09,0.78718
300.01999, 283.10000,     -0.19102,55.20465,50.00000,47.00000,2.884615e-09,0.78720
300.01199, 285.10000,     -0.19064,55.11919,50.00000,47.00000,2.881391e-09,0.78718
300.01099, 287.10000,     -0.19346,55.02054,50.00000,47.00000,2.889544e-09,0.78719
300.01099, 289.10000,     -0.19196,54.93508,50.00000,47.00000,2.871213e-09,0.78719
300.01700, 291.10000,     -0.19121,54.86260,50.00000,47.00000,2.883127e-09,0.78719
300.01401, 293.10000,     -0.19234,54.78372,50.00000,47.00000,2.881996e-09,0.78719
300.02802, 295.10000,     -0.19271,54.72888,50.00000,47.00000,2.882024e-09,0.78719
300.02100, 297.10000,     -0.19440,54.63682,50.00000,47.00000,2.878010e-09,0.78719
300.01801, 299.10000,     -0.19290,54.51182,50.00000,47.00000,2.880329e-09,0.78720
300.01401, 301.10000,     -0.19215,54.45930,50.00000,47.00000,2.878056e-09,0.78719
300.01001, 303.10000,     -0.19384,54.41318,50.00000,47.00000,2.872432e-09,0.78720
300.01001, 305.10000,     -0.19252,54.31453,50.00000,47.00000,2.872731e-09,0.78720
300.02399, 307.10000,     -0.19084,54.24205,50.00000,47.00000,2.880493e-09,0.78719
300.00699, 309.10000,     -0.19252,54.15659,50.00000,47.00000,2.878972e-09,0.78720
300.02100, 311.10000,     -0.19309,54.09748,50.00000,47.00000,2.879455e-09,0.78719
300.02802, 313.10000,     -0.19553,54.00969,50.00000,47.00000,2.877011e-09,0.78720
300.01901, 315.10000,     -0.19365,53.93740,50.00000,47.00000,2.865930e-09,0.78718
300.02600, 317.10000,     -0.19309,53.86512,50.00000,47.00000,2.872118e-09,0.78719
300.01599, 319.10000,     -0.19290,53.78391,50.00000,47.00000,2.871079e-09,0.78720
300.00800, 321.10000,     -0.19609,53.72481,50.00000,47.00000,2.871718e-09,0.78720
300.01801, 323.10000,     -0.19177,53.63256,50.00000,47.00000,2.873718e-09,0.78720
300.01801, 325.10000,     -0.19684,53.56686,50.00000,47.00000,2.874443e-09,0.78719
300.01501, 327.10000,     -0.19421,53.48798,50.00000,47.00000,2.869606e-09,0.78719
300.02301, 329.10000,     -0.19591,53.38275,50.00000,47.00000,2.873124e-09,0.78719
300.00201, 331.10000,     -0.19233,53.34981,50.00000,47.00000,2.872189e-09,0.78720
300.01599, 333.10000,     -0.19534,53.26434,50.00000,47.00000,2.876750e-09,0.78719
300.01501, 335.10000,     -0.19590,53.19186,50.00000,47.00000,2.873420e-09,0.78718
300.01501, 337.10000,     -0.19572,53.11298,50.00000,47.00000,2.871996e-09,0.78720
300.01801, 339.10000,     -0.19722,53.03411,50.00000,47.00000,2.872828e-09,0.78719
300.00299, 341.10000,     -0.19816,52.98140,50.00000,47.00000,2.869248e-09,0.78720
300.01300, 343.10000,     -0.19609,52.90252,50.00000,47.00000,2.868902e-09,0.78720
300.00800, 345.10000,     -0.19703,52.83023,50.00000,47.00000,2.872474e-09,0.78719
300.01901, 347.10000,     -0.19497,52.76880,50.00000,47.00000,2.862834e-09,0.78719
300.01401, 349.10000,     -0.19741,52.68992,50.00000,47.00000,2.862477e-09,0.78719
300.01599, 351.10000,     -0.19703,52.61085,50.00000,47.00000,2.866038e-09,0.78719
300.01901, 353.10000,     -0.20004,52.54516,50.00000,47.00000,2.862166e-09,0.78719
300.02200, 355.10000,     -0.19760,52.46628,50.00000,47.00000,2.864557e-09,0.78720
300.01801, 357.10000,     -0.20004,52.41357,50.00000,47.00000,2.869576e-09,0.78720
300.01401, 359.10000,     -0.19929,52.33469,50.00000,47.00000,2.863142e-09,0.78720
300.02200, 361.10000,     -0.19760,52.25581,50.00000,47.00000,2.867125e-09,0.78719
300.02399, 363.10000,     -0.19666,52.17016,50.00000,47.00000,2.870785e-09,0.78718
300.01901, 365.10000,     -0.19741,52.12422,50.00000,47.00000,2.863675e-09,0.78718
300.02802, 367.10000,     -0.19779,52.07810,50.00000,47.00000,2.861073e-09,0.78720
300.02100, 369.10000,     -0.20098,51.99922,50.00000,47.00000,2.866724e-09,0.78719
300.02399, 371.10000,     -0.19910,51.93333,50.00000,47.00000,2.861884e-09,0.78720
300.01599, 373.10000,     -0.19797,51.84128,50.00000,47.00000,2.852626e-09,0.78718
300.01599, 375.10000,     -0.19872,51.80853,50.00000,47.00000,2.860968e-09,0.78719
300.02200, 377.10000,     -0.19929,51.72946,50.00000,47.00000,2.859947e-09,0.78719
300.02200, 379.10000,     -0.19835,51.65504,50.00000,47.00000,2.866905e-09,0.78719
300.01099, 381.10000,     -0.20154,51.59574,50.00000,47.00000,2.861298e-09,0.78720
300.00299, 383.10000,     -0.19759,51.55640,50.00000,47.00000,2.861630e-09,0.78719
300.01599, 385.10000,     -0.19835,51.47733,50.00000,47.00000,2.880675e-09,0.78719
300.00699, 387.10000,     -0.19797,51.41163,50.00000,47.00000,2.879286e-09,0.78719
300.00299, 389.10000,     -0.19928,51.35891,50.00000,47.00000,2.887250e-09,0.78719
300.01300, 391.10000,     -0.19684,51.29767,50.00000,47.00000,2.883185e-09,0.78720
300.02399, 393.10000,     -0.19872,51.21860,50.00000,47.00000,2.875640e-09,0.78718
300.01401, 395.10000,     -0.19966,51.17267,50.00000,47.00000,2.879018e-09,0.78719
300.00500, 397.10000,     -0.19722,51.11996,50.00000,47.00000,2.878729e-09,0.78718
300.01401, 399.10000,     -0.19835,51.06085,50.00000,47.00000,2.881962e-09,0.78719
300.01199, 401.10000,     -0.19835,50.98837,50.00000,47.00000,2.877937e-09,0.78720
300.01599, 403.10000,     -0.19778,50.94903,50.00000,47.00000,2.877081e-09,0.78718
300.01700, 405.10000,     -0.20022,50.89632,50.00000,47.00000,2.876993e-09,0.78719
300.01901, 407.10000,     -0.19891,50.82403,50.00000,47.00000,2.882474e-09,0.78719
300.02499, 409.10000,     -0.19910,50.75174,50.00000,47.00000,2.870064e-09,0.78719
300.01801, 411.10000,     -0.20116,50.71221,50.00000,47.00000,2.880584e-09,0.78719
300.01501, 413.10000,     -0.20116,50.62674,50.00000,47.00000,2.878346e-09,0.78719
300.02100, 415.10000,     -0.20041,50.57403,50.00000,47.00000,2.879955e-09,0.78719
300.02899, 417.10000,     -0.20042,50.52151,50.00000,47.00000,2.874838e-09,0.78719
300.01700, 419.10000,     -0.20229,50.44903,50.00000,47.00000,2.877568e-09,0.78719
300.02301, 421.10000,     -0.20060,50.39651,50.00000,47.00000,2.880011e-09,0.78718
300.02100, 423.10000,     -0.20304,50.31764,50.00000,47.00000,2.870324e-09,0.78720
300.01999, 425.10000,     -0.20173,50.25833,50.00000,47.00000,2.875670e-09,0.78719
300.02301, 427.10000,     -0.20210,50.19264,50.00000,47.00000,2.880074e-09,0.78720
300.01501, 429.10000,     -0.20323,50.13992,50.00000,47.00000,2.877151e-09,0.78719
300.01501, 431.10000,     -0.20304,50.08740,50.00000,47.00000,2.876168e-09,0.78719
300.02100, 433.10000,     -0.20229,50.04128,50.00000,47.00000,2.870804e-09,0.78719
300.02301, 435.10000,     -0.20098,49.95581,50.00000,47.00000,2.881738e-09,0.78718
300.01801, 437.10000,     -0.20361,49.90969,50.00000,47.00000,2.882069e-09,0.78719
300.01801, 439.10000,     -0.20248,49.84399,50.00000,47.00000,2.876699e-09,0.78719
300.02200, 441.10000,     -0.20417,49.77810,50.00000,47.00000,2.876169e-09,0.78719
300.02100, 443.10000,     -0.20210,49.74302,50.00000,47.00000,2.877623e-09,0.78719
300.02200, 445.10000,     -0.20436,49.65756,50.00000,47.00000,2.876356e-09,0.78719
300.01501, 447.10000,     -0.20454,49.61822,50.00000,47.00000,2.875437e-09,0.78718
299.99399, 449.10000,     -0.20285,49.54574,50.00000,47.00000,2.877718e-09,0.78719
300.02100, 451.10000,     -0.20304,49.53702,50.00000,47.00000,2.869710e-09,0.78718
300.01801, 453.10000,     -0.20398,49.43837,50.00000,47.00000,2.871515e-09,0.78719
300.01099, 455.10000,     -0.20360,49.38140,50.00000,47.00000,2.878697e-09,0.78719
300.00601, 457.10000,     -0.20548,49.33527,50.00000,47.00000,2.876329e-09,0.78720
300.01700, 459.10000,     -0.20492,49.26957,50.00000,47.00000,2.877911e-09,0.78718
300.00900, 461.10000,     -0.20342,49.21686,50.00000,47.00000,2.870195e-09,0.78720
299.99600, 463.10000,     -0.20492,49.17093,50.00000,47.00000,2.873710e-09,0.78719
300.02200, 465.10000,     -0.20586,49.13585,50.00000,47.00000,2.875860e-09,0.78719
300.02499, 467.10000,     -0.20586,49.05678,50.00000,47.00000,2.878551e-09,0.78719
300.00699, 469.10000,     -0.20511,49.00426,50.00000,47.00000,2.881079e-09,0.78719
300.01801, 471.10000,     -0.20304,48.93837,50.00000,47.00000,2.871147e-09,0.78720
300.01700, 473.10000,     -0.20473,48.88585,50.00000,47.00000,2.871112e-09,0.78719
300.01001, 475.10000,     -0.20717,48.83314,50.00000,47.00000,2.868983e-09,0.78718
300.02301, 477.10000,     -0.20624,48.78934,50.00000,47.00000,2.876308e-09,0.78718
300.02899, 479.10000,     -0.20643,48.72364,50.00000,47.00000,2.881544e-09,0.78719
300.02200, 481.10000,     -0.20943,48.66434,50.00000,47.00000,2.870127e-09,0.78719
300.01501, 483.10000,     -0.20736,48.61841,50.00000,47.00000,2.875525e-09,0.78719
300.01999, 485.10000,     -0.20586,48.56570,50.00000,47.00000,2.880887e-09,0.78719
300.01001, 487.10000,     -0.21055,48.50000,50.00000,47.00000,2.874956e-09,0.78719
300.01999, 489.10000,     -0.20980,48.47364,50.00000,47.00000,2.872178e-09,0.78719
300.01599, 491.10000,     -0.20774,48.40795,50.00000,47.00000,2.876938e-09,0.78720
300.01501, 493.10000,     -0.21093,48.34205,50.00000,47.00000,2.871755e-09,0.78721
300.01300, 495.10000,     -0.21037,48.31570,50.00000,47.00000,2.872225e-09,0.78719
300.01801, 497.10000,     -0.20849,48.25000,50.00000,47.00000,2.876896e-09,0.78719
300.01801, 499.10000,     -0.20868,48.18857,50.00000,47.00000,2.874583e-09,0.78719
300.00400, 501.10000,     -0.21055,48.13605,50.00000,47.00000,2.872190e-09,0.78720
300.02701, 503.10000,     -0.20962,48.08333,50.00000,47.00000,2.878468e-09,0.78719
300.01300, 505.10000,     -0.21055,48.03081,50.00000,47.00000,2.877868e-09,0.78720
300.01501, 507.10000,     -0.21055,47.99128,50.00000,47.00000,2.871205e-09,0.78719
300.01199, 509.10000,     -0.21093,47.93857,50.00000,47.00000,2.872117e-09,0.78719
300.02200, 511.10000,     -0.20981,47.88605,50.00000,47.00000,2.875087e-09,0.78719
300.00800, 513.10000,     -0.21206,47.83333,50.00000,47.00000,2.876509e-09,0.78718
300.01501, 515.10000,     -0.21243,47.77422,50.00000,47.00000,2.874823e-09,0.78718
300.02600, 517.10000,     -0.20849,47.75446,50.00000,47.00000,2.869808e-09,0.78720
300.01700, 519.10000,     -0.21149,47.70194,50.00000,47.00000,2.872445e-09,0.78719
300.01901, 521.10000,     -0.21018,47.62946,50.00000,47.00000,2.869936e-09,0.78719
300.01199, 523.10000,     -0.21224,47.57694,50.00000,47.00000,2.868068e-09,0.78719
300.01300, 525.10000,     -0.21187,47.52422,50.00000,47.00000,2.875203e-09,0.78720
300.01999, 527.10000,     -0.21093,47.46512,50.00000,47.00000,2.872762e-09,0.78720
300.02301, 529.10000,     -0.21225,47.43217,50.00000,47.00000,2.869095e-09,0.78720
300.02499, 531.10000,     -0.21281,47.37306,50.00000,47.00000,2.871356e-09,0.78720
300.02600, 533.10000,     -0.21187,47.30717,50.00000,47.00000,2.867441e-09,0.78720
300.01801, 535.10000,     -0.21431,47.26124,50.00000,47.00000,2.871086e-09,0.78719
300.01401, 537.10000,     -0.21300,47.22171,50.00000,47.00000,2.868824e-09,0.78719
300.01999, 539.10000,     -0.21187,47.16260,50.00000,47.00000,2.872590e-09,0.78718
300.03000, 541.10000,     -0.21694,47.11647,50.00000,47.00000,2.874468e-09,0.78718
300.02802, 543.10000,     -0.21375,47.05078,50.00000,47.00000,2.872272e-09,0.78718
300.02600, 545.10000,     -0.21300,47.03101,50.00000,47.00000,2.869202e-09,0.78718
300.01501, 547.10000,     -0.21356,46.94554,50.00000,47.00000,2.866597e-09,0.78719
300.01199, 549.10000,     -0.21788,46.91919,50.00000,47.00000,2.868629e-09,0.78719
300.02499, 551.10000,     -0.21563,46.85988,50.00000,47.00000,2.866434e-09,0.78719
300.00900, 553.10000,     -0.21525,46.79419,50.00000,47.00000,2.867873e-09,0.78719
300.01501, 555.10000,     -0.21431,46.76783,50.00000,47.00000,2.866718e-09,0.78720
300.01099, 557.10000,     -0.21431,46.71531,50.00000,47.00000,2.870707e-09,0.78719
300.00699, 559.10000,     -0.21788,46.65601,50.00000,47.00000,2.864447e-09,0.78719
300.01700, 561.10000,     -0.21619,46.61008,50.00000,47.00000,2.871006e-09,0.78718
300.01599, 563.10000,     -0.21826,46.56395,50.00000,47.00000,2.868012e-09,0.78719
300.01501, 565.10000,     -0.21750,46.50484,50.00000,47.00000,2.866017e-09,0.78719
300.01300, 567.10000,     -0.21826,46.45213,50.00000,47.00000,2.868719e-09,0.78719
300.01901, 569.10000,     -0.21638,46.39942,50.00000,47.00000,2.869494e-09,0.78719
300.01300, 571.10000,     -0.21919,46.36667,50.00000,47.00000,2.865906e-09,0.78719
300.01501, 573.10000,     -0.21938,46.29419,50.00000,47.00000,2.865601e-09,0.78718
300.01001, 575.10000,     -0.22013,46.24826,50.00000,47.00000,2.862580e-09,0.78719
300.01001, 577.10000,     -0.21938,46.23508,50.00000,47.00000,2.861202e-09,0.78719
300.00800, 579.10000,     -0.21750,46.16279,50.00000,47.00000,2.867621e-09,0.78719
300.01901, 581.10000,     -0.21713,46.14302,50.00000,47.00000,2.867576e-09,0.78719
300.01801, 583.10000,     -0.22295,46.09031,50.00000,47.00000,2.866825e-09,0.78719
300.01501, 585.10000,     -0.21957,46.03120,50.00000,47.00000,2.870629e-09,0.78719
300.02100, 587.10000,     -0.21901,46.00484,50.00000,47.00000,2.869568e-09,0.78719
300.03400, 589.10000,     -0.21976,45.95233,50.00000,47.00000,2.860685e-09,0.78719
300.02399, 591.10000,     -0.22051,45.90620,50.00000,47.00000,2.860690e-09,0.78719
300.01901, 593.10000,     -0.21882,45.83391,50.00000,47.00000,2.867441e-09,0.78719
300.02600, 595.10000,     -0.22089,45.78120,50.00000,47.00000,2.869074e-09,0.78719
300.02200, 597.10000,     -0.22014,45.75484,50.00000,47.00000,2.863652e-09,0.78719
300.01001, 599.10000,     -0.22088,45.72209,50.00000,47.00000,2.868068e-09,0.78720
300.02200, 601.10000,     -0.21938,45.65620,50.00000,47.00000,2.859209e-09,0.78721
300.02301, 603.10000,     -0.22201,45.61027,50.00000,47.00000,2.868153e-09,0.78720
299.99899, 605.10000,     -0.22257,45.55756,50.00000,47.00000,2.866255e-09,0.78719
300.01001, 607.10000,     -0.22126,45.49186,50.00000,47.00000,2.861664e-09,0.78719
300.02301, 609.10000,     -0.22314,45.45891,50.00000,47.00000,2.860971e-09,0.78719
300.03000, 611.10000,     -0.22033,45.42597,50.00000,47.00000,2.862040e-09,0.78718
300.02200, 613.10000,     -0.22145,45.40640,50.00000,47.00000,2.860377e-09,0.78718
300.00699, 615.10000,     -0.22220,45.34050,50.00000,47.00000,2.861738e-09,0.78720
300.01801, 617.10000,     -0.22370,45.29457,50.00000,47.00000,2.866399e-09,0.78719
300.01501, 619.10000,     -0.22295,45.23527,50.00000,47.00000,2.862363e-09,0.78719
300.01300, 621.10000,     -0.22182,45.18275,50.00000,47.00000,2.867474e-09,0.78720
300.01501, 623.10000,     -0.22258,45.14981,50.00000,47.00000,2.866717e-09,0.78720
300.02600, 625.10000,     -0.22220,45.09050,50.00000,47.00000,2.856800e-09,0.78719
300.00400, 627.10000,     -0.22389,45.05775,50.00000,47.00000,2.855075e-09,0.78719
300.01801, 629.10000,     -0.22389,45.03140,50.00000,47.00000,2.860923e-09,0.78720
300.01801, 631.10000,     -0.22352,44.97868,50.00000,47.00000,2.862412e-09,0.78719
300.01401, 633.10000,     -0.22539,44.93275,50.00000,47.00000,2.862340e-09,0.78718
300.02100, 635.10000,     -0.22446,44.89322,50.00000,47.00000,2.869379e-09,0.78719
300.01801, 637.10000,     -0.22577,44.84070,50.00000,47.00000,2.860074e-09,0.78720
300.01300, 639.10000,     -0.22464,44.78798,50.00000,47.00000,2.861955e-09,0.78719
300.01001, 641.10000,     -0.22539,44.76822,50.00000,47.00000,2.855956e-09,0.78720
300.01700, 643.10000,     -0.22389,44.70252,50.00000,47.00000,2.863302e-09,0.78719
300.01599, 645.10000,     -0.22746,44.66298,50.00000,47.00000,2.857388e-09,0.78718
300.00699, 647.10000,     -0.22464,44.61705,50.00000,47.00000,2.857302e-09,0.78718
300.02499, 649.10000,     -0.22727,44.57093,50.00000,47.00000,2.861730e-09,0.78719
300.00800, 651.10000,     -0.22746,44.53140,50.00000,47.00000,2.861924e-09,0.78719
300.01001, 653.10000,     -0.22596,44.51841,50.00000,47.00000,2.859197e-09,0.78718
300.01599, 655.10000,     -0.22802,44.43934,50.00000,47.00000,2.861098e-09,0.78719
300.02301, 657.10000,     -0.22821,44.41977,50.00000,47.00000,2.852369e-09,0.78719
300.01199, 659.10000,     -0.22990,44.36705,50.00000,47.00000,2.860442e-09,0.78719
300.01801, 661.10000,     -0.22784,44.33411,50.00000,47.00000,2.857377e-09,0.78719
300.01401, 663.10000,     -0.22896,44.26182,50.00000,47.00000,2.853040e-09,0.78719
300.02100, 665.10000,     -0.22577,44.24205,50.00000,47.00000,2.855140e-09,0.78719
300.02100, 667.10000,     -0.22784,44.21570,50.00000,47.00000,2.855784e-09,0.78720
300.01901, 669.10000,     -0.22784,44.14341,50.00000,47.00000,2.854227e-09,0.78720
300.02499, 671.10000,     -0.22878,44.11047,50.00000,47.00000,2.852838e-09,0.78719
300.00699, 673.10000,     -0.22934,44.08430,50.00000,47.00000,2.854467e-09,0.78719
300.01199, 675.10000,     -0.22821,44.03159,50.00000,47.00000,2.855363e-09,0.78718
300.01300, 677.10000,     -0.22877,43.97907,50.00000,47.00000,2.852892e-09,0.78719
300.01801, 679.10000,     -0.22727,43.94612,50.00000,47.00000,2.853753e-09,0.78718
300.02200, 681.10000,     -0.23009,43.87364,50.00000,47.00000,2.854594e-09,0.78718
300.02100, 683.10000,     -0.22878,43.84748,50.00000,47.00000,2.849313e-09,0.78719
300.01801, 685.10000,     -0.23122,43.78818,50.00000,47.00000,2.848726e-09,0.78719
300.02600, 687.10000,     -0.22953,43.75543,50.00000,47.00000,2.849669e-09,0.78719
300.01001, 689.10000,     -0.23197,43.75543,50.00000,47.00000,2.858775e-09,0.78719
300.01099, 691.10000,     -0.22934,43.66318,50.00000,47.00000,2.855517e-09,0.78719
300.01300, 693.10000,     -0.23028,43.64360,50.00000,47.00000,2.858828e-09,0.78719
300.01999, 695.10000,     -0.23103,43.57112,50.00000,47.00000,2.850753e-09,0.78719
300.02802, 697.10000,     -0.23178,43.52519,50.00000,47.00000,2.854189e-09,0.78719
300.02399, 699.10000,     -0.22859,43.51202,50.00000,47.00000,2.852842e-09,0.78719
300.01300, 701.10000,     -0.23253,43.45930,50.00000,47.00000,2.851485e-09,0.78720
300.02399, 703.10000,     -0.22953,43.42655,50.00000,47.00000,2.848719e-09,0.78719
300.00299, 705.10000,     -0.22971,43.40019,50.00000,47.00000,2.846287e-09,0.78719
300.01099, 707.10000,     -0.23253,43.34089,50.00000,47.00000,2.864708e-09,0.78719
300.01001, 709.10000,     -0.23140,43.30814,50.00000,47.00000,2.877408e-09,0.78720
300.01999, 711.10000,     -0.23178,43.26202,50.00000,47.00000,2.873469e-09,0.78719
300.01700, 713.10000,     -0.23103,43.23566,50.00000,47.00000,2.882773e-09,0.78719
300.01901, 715.10000,     -0.23103,43.18314,50.00000,47.00000,2.879397e-09,0.78720
300.01001, 717.10000,     -0.23028,43.14360,50.00000,47.00000,2.880520e-09,0.78720
300.00201, 719.10000,     -0.23159,43.10407,50.00000,47.00000,2.877942e-09,0.78719
300.01199, 721.10000,     -0.23178,43.06473,50.00000,47.00000,2.884141e-09,0.78720
300.01501, 723.10000,     -0.23140,43.00543,50.00000,47.00000,2.874889e-09,0.78719
300.00201, 725.10000,     -0.23253,42.99884,50.00000,47.00000,2.878816e-09,0.78719
300.01401, 727.10000,     -0.22990,42.97267,50.00000,47.00000,2.878414e-09,0.78719
300.01901, 729.10000,     -0.23516,42.87829,50.00000,47.00000,2.879298e-09,0.78719
300.00800, 731.10000,     -0.23253,42.86512,50.00000,47.00000,2.884286e-09,0.78719
300.01901, 733.10000,     -0.23310,42.79283,50.00000,47.00000,2.882358e-09,0.78719
300.01700, 735.10000,     -0.23347,42.75988,50.00000,47.00000,2.883155e-09,0.78719
300.01401, 737.10000,     -0.23234,42.70736,50.00000,47.00000,2.881221e-09,0.78718
300.02701, 739.10000,     -0.23291,42.68101,50.00000,47.00000,2.874449e-09,0.78719
300.01599, 741.10000,     -0.23648,42.64147,50.00000,47.00000,2.877625e-09,0.78718
300.01801, 743.10000,     -0.23347,42.58895,50.00000,47.00000,2.880476e-09,0.78719
300.00500, 745.10000,     -0.23497,42.54283,50.00000,47.00000,2.883583e-09,0.78719
300.02499, 747.10000,     -0.23723,42.52306,50.00000,47.00000,2.877171e-09,0.78718
300.01300, 749.10000,     -0.23516,42.50349,50.00000,47.00000,2.882398e-09,0.78719
300.02499, 751.10000,     -0.23667,42.45078,50.00000,47.00000,2.874235e-09,0.78718
300.01999, 753.10000,     -0.23666,42.40465,50.00000,47.00000,2.875996e-09,0.78719
300.01999, 755.10000,     -0.23535,42.37849,50.00000,47.00000,2.874037e-09,0.78719
300.01599, 757.10000,     -0.23460,42.31919,50.00000,47.00000,2.877619e-09,0.78719
300.00900, 759.10000,     -0.23629,42.28643,50.00000,47.00000,2.881481e-09,0.78720
300.01001, 761.10000,     -0.23610,42.25795,50.00000,47.00000,2.874657e-09,0.78718
300.01099, 763.10000,     -0.23441,42.22500,50.00000,47.00000,2.879602e-09,0.78719
300.00400, 765.10000,     -0.23422,42.15252,50.00000,47.00000,2.877867e-09,0.78718
300.00400, 767.10000,     -0.23685,42.13953,50.00000,47.00000,2.879108e-09,0.78719
300.00400, 769.10000,     -0.23666,42.11977,50.00000,47.00000,2.875305e-09,0.78719
300.00101, 771.10000,     -0.23591,42.07364,50.00000,47.00000,2.877905e-09,0.78718
300.01801, 773.10000,     -0.23479,42.02112,50.00000,47.00000,2.877564e-09,0.78719
300.01401, 775.10000,     -0.23798,42.00136,50.00000,47.00000,2.868504e-09,0.78720
300.01300, 777.10000,     -0.23798,41.94438,50.00000,47.00000,2.877929e-09,0.78719
300.01801, 779.10000,     -0.23798,41.91143,50.00000,47.00000,2.870197e-09,0.78719
300.02600, 781.10000,     -0.23704,41.88508,50.00000,47.00000,2.871289e-09,0.78720
300.01401, 783.10000,     -0.23910,41.82597,50.00000,47.00000,2.876039e-09,0.78719
300.02100, 785.10000,     -0.23742,41.77326,50.00000,47.00000,2.874055e-09,0.78719
300.03201, 787.10000,     -0.23855,41.76008,50.00000,47.00000,2.873839e-09,0.78719
300.01801, 789.10000,     -0.24042,41.72074,50.00000,47.00000,2.874415e-09,0.78718
300.02399, 791.10000,     -0.24061,41.70097,50.00000,47.00000,2.872407e-09,0.78719
300.01901, 793.10000,     -0.23967,41.67461,50.00000,47.00000,2.875548e-09,0.78718
300.01401, 795.10000,     -0.23948,41.63508,50.00000,47.00000,2.871235e-09,0.78720
300.03000, 797.10000,     -0.23967,41.58256,50.00000,47.00000,2.877257e-09,0.78720
300.00500, 799.10000,     -0.24060,41.52984,50.00000,47.00000,2.869894e-09,0.78719
300.00500, 801.10000,     -0.23910,41.49709,50.00000,47.00000,2.871335e-09,0.78720
300.00800, 803.10000,     -0.24079,41.47074,50.00000,47.00000,2.874214e-09,0.78719
300.02399, 805.10000,     -0.24023,41.42461,50.00000,47.00000,2.866941e-09,0.78720
300.01599, 807.10000,     -0.24155,41.39845,50.00000,47.00000,2.868502e-09,0.78718
300.01300, 809.10000,     -0.23967,41.34574,50.00000,47.00000,2.869347e-09,0.78720
300.01300, 811.10000,     -0.24173,41.33915,50.00000,47.00000,2.871933e-09,0.78719
300.02899, 813.10000,     -0.23986,41.27345,50.00000,47.00000,2.871126e-09,0.78719
300.01300, 815.10000,     -0.24117,41.24709,50.00000,47.00000,2.868675e-09,0.78719
300.02802, 817.10000,     -0.24080,41.21415,50.00000,47.00000,2.865222e-09,0.78720
300.02100, 819.10000,     -0.24343,41.16163,50.00000,47.00000,2.863995e-09,0.78719
300.01501, 821.10000,     -0.24004,41.16163,50.00000,47.00000,2.865123e-09,0.78719
300.01001, 823.10000,     -0.24136,41.05640,50.00000,47.00000,2.868136e-09,0.78718
300.01401, 825.10000,     -0.24173,41.03663,50.00000,47.00000,2.867662e-09,0.78719
300.01199, 827.10000,     -0.24023,41.01899,50.00000,47.00000,2.869770e-09,0.78718
300.01001, 829.10000,     -0.24192,40.97306,50.00000,47.00000,2.863112e-09,0.78718
300.01401, 831.10000,     -0.24399,40.90717,50.00000,47.00000,2.863359e-09,0.78718
300.02399, 833.10000,     -0.24324,40.90717,50.00000,47.00000,2.866917e-09,0.78719
300.02100, 835.10000,     -0.24192,40.86783,50.00000,47.00000,2.867762e-09,0.78718
300.01401, 837.10000,     -0.24155,40.83488,50.00000,47.00000,2.865856e-09,0.78719
300.00800, 839.10000,     -0.24136,40.78236,50.00000,47.00000,2.860613e-09,0.78720
300.00699, 841.10000,     -0.24136,40.74942,50.00000,47.00000,2.863474e-09,0.78719
300.02301, 843.10000,     -0.24324,40.70988,50.00000,47.00000,2.860427e-09,0.78719
300.01901, 845.10000,     -0.24117,40.66395,50.00000,47.00000,2.870352e-09,0.78719
300.00101, 847.10000,     -0.24492,40.64419,50.00000,47.00000,2.865983e-09,0.78719
300.01199, 849.10000,     -0.24230,40.59806,50.00000,47.00000,2.862981e-09,0.78719
300.01999, 851.10000,     -0.24174,40.56298,50.00000,47.00000,2.865001e-09,0.78717
300.01401, 853.10000,     -0.24380,40.53450,50.00000,47.00000,2.864671e-09,0.78719
300.01901, 855.10000,     -0.24249,40.49516,50.00000,47.00000,2.857070e-09,0.78718
300.02100, 857.10000,     -0.24361,40.46221,50.00000,47.00000,2.866188e-09,0.78719
300.01901, 859.10000,     -0.24249,40.42054,50.00000,47.00000,2.860720e-09,0.78719
300.01901, 861.10000,     -0.24343,40.37888,50.00000,47.00000,2.858016e-09,0.78719
300.00699, 863.10000,     -0.24305,40.35252,50.00000,47.00000,2.862486e-09,0.78719
300.01401, 865.10000,     -0.24361,40.30000,50.00000,47.00000,2.858823e-09,0.78720
300.01599, 867.10000,     -0.24211,40.26705,50.00000,47.00000,2.858950e-09,0.78719
300.02600, 869.10000,     -0.24474,40.26047,50.00000,47.00000,2.859936e-09,0.78720
300.02701, 871.10000,     -0.24456,40.22752,50.00000,47.00000,2.859322e-09,0.78719
300.02200, 873.10000,     -0.24455,40.17500,50.00000,47.00000,2.853375e-09,0.78719
300.00400, 875.10000,     -0.24568,40.15523,50.00000,47.00000,2.859940e-09,0.78719
300.00299, 877.10000,     -0.24511,40.10911,50.00000,47.00000,2.855014e-09,0.78721
300.01401, 879.10000,     -0.24549,40.06977,50.00000,47.00000,2.855200e-09,0.78719
300.01001, 881.10000,     -0.24737,40.03682,50.00000,47.00000,2.858384e-09,0.78720
300.01199, 883.10000,     -0.24718,39.99729,50.00000,47.00000,2.856996e-09,0.78719
300.01599, 885.10000,     -0.24343,39.95795,50.00000,47.00000,2.851825e-09,0.78720
300.02899, 887.10000,     -0.24568,39.93159,50.00000,47.00000,2.853364e-09,0.78719
300.01199, 889.10000,     -0.24793,39.89205,50.00000,47.00000,2.856675e-09,0.78719
300.02600, 891.10000,     -0.24718,39.86589,50.00000,47.00000,2.863880e-09,0.78718
300.00900, 893.10000,     -0.24849,39.81318,50.00000,47.00000,2.862167e-09,0.78719
300.02100, 895.10000,     -0.24850,39.80659,50.00000,47.00000,2.853410e-09,0.78719
300.01300, 897.10000,     -0.24943,39.75407,50.00000,47.00000,2.856272e-09,0.78719
300.02100, 899.10000,     -0.25000,39.70795,50.00000,47.00000,2.853991e-09,0.78718
300.00500, 901.10000,     -0.25075,39.68818,50.00000,47.00000,2.855600e-09,0.78719
300.01801, 903.10000,     -0.24906,39.65543,50.00000,47.00000,2.851492e-09,0.78719
300.00500, 905.10000,     -0.24699,39.61589,50.00000,47.00000,2.853585e-09,0.78719
300.00299, 907.10000,     -0.24812,39.57636,50.00000,47.00000,2.850836e-09,0.78720
300.01401, 909.10000,     -0.24718,39.55000,50.00000,47.00000,2.859565e-09,0.78718
300.01801, 911.10000,     -0.25150,39.51066,50.00000,47.00000,2.854542e-09,0.78719
300.01999, 913.10000,     -0.24887,39.47771,50.00000,47.00000,2.854515e-09,0.78721
300.01801, 915.10000,     -0.25038,39.43818,50.00000,47.00000,2.855513e-09,0.78719
300.02600, 917.10000,     -0.25132,39.38566,50.00000,47.00000,2.853359e-09,0.78719
300.02301, 919.10000,     -0.24944,39.35930,50.00000,47.00000,2.843316e-09,0.78717
300.02600, 921.10000,     -0.25019,39.31337,50.00000,47.00000,2.853778e-09,0.78718
300.03601, 923.10000,     -0.25076,39.30446,50.00000,47.00000,2.849579e-09,0.78720
300.02600, 925.10000,     -0.24981,39.25853,50.00000,47.00000,2.846435e-09,0.78719
300.01801, 927.10000,     -0.25056,39.21899,50.00000,47.00000,2.852762e-09,0.78719
300.02399, 929.10000,     -0.25188,39.18605,50.00000,47.00000,2.847286e-09,0.78720
300.01999, 931.10000,     -0.25132,39.16860,50.00000,47.00000,2.850767e-09,0.78718
300.00400, 933.10000,     -0.25018,39.14225,50.00000,47.00000,2.848336e-09,0.78719
300.03400, 935.10000,     -0.25038,39.10504,50.00000,47.00000,2.843659e-09,0.78719
300.02301, 937.10000,     -0.25075,39.08740,50.00000,47.00000,2.850922e-09,0.78718
299.99301, 939.10000,     -0.25037,39.02829,50.00000,47.00000,2.852556e-09,0.78719
299.99200, 941.10000,     -0.25037,39.01512,50.00000,47.00000,2.844750e-09,0.78719
300.01199, 943.10000,     -0.25019,38.98217,50.00000,47.00000,2.849799e-09,0.78719
300.01401, 945.10000,     -0.24981,38.92306,50.00000,47.00000,2.842669e-09,0.78719
300.00900, 947.10000,     -0.25037,38.89671,50.00000,47.00000,2.853119e-09,0.78720
300.01801, 949.10000,     -0.24906,38.87035,50.00000,47.00000,2.849291e-09,0.78718
300.01401, 951.10000,     -0.25169,38.81783,50.00000,47.00000,2.850018e-09,0.78718
300.01001, 953.10000,     -0.25131,38.79806,50.00000,47.00000,2.848524e-09,0.78720
300.00601, 955.10000,     -0.25469,38.77171,50.00000,47.00000,2.849117e-09,0.78719
300.02301, 957.10000,     -0.25038,38.74535,50.00000,47.00000,2.844980e-09,0.78720
300.01700, 959.10000,     -0.25113,38.69283,50.00000,47.00000,2.842877e-09,0.78721
300.03000, 961.10000,     -0.25151,38.64671,50.00000,47.00000,2.840466e-09,0.78719
300.00900, 963.10000,     -0.25394,38.63353,50.00000,47.00000,2.846492e-09,0.78718
300.01199, 965.10000,     -0.25244,38.58760,50.00000,47.00000,2.853180e-09,0.78719
300.01300, 967.10000,     -0.25225,38.56570,50.00000,47.00000,2.844662e-09,0.78719
300.00900, 969.10000,     -0.25526,38.49322,50.00000,47.00000,2.842967e-09,0.78719
300.00800, 971.10000,     -0.25225,38.49981,50.00000,47.00000,2.839444e-09,0.78718
300.00000, 973.10000,     -0.25206,38.47364,50.00000,47.00000,2.844869e-09,0.78718
300.01099, 975.10000,     -0.25263,38.44729,50.00000,47.00000,2.847393e-09,0.78719
300.00800, 977.10000,     -0.25357,38.41434,50.00000,47.00000,2.846509e-09,0.78719
300.01999, 979.10000,     -0.25150,38.38140,50.00000,47.00000,2.843206e-09,0.78719
300.02301, 981.10000,     -0.25357,38.32888,50.00000,47.00000,2.845216e-09,0.78719
300.02499, 983.10000,     -0.25207,38.30911,50.00000,47.00000,2.847020e-09,0.78719
300.01401, 985.10000,     -0.25357,38.28275,50.00000,47.00000,2.844045e-09,0.78720
300.02399, 987.10000,     -0.25357,38.24341,50.00000,47.00000,2.845345e-09,0.78719
300.01401, 989.10000,     -0.25376,38.22364,50.00000,47.00000,2.848772e-09,0.78720
300.01001, 991.10000,     -0.25319,38.22364,50.00000,47.00000,2.850088e-09,0.78719
300.00101, 993.10000,     -0.25244,38.13585,50.00000,47.00000,2.849877e-09,0.78719
300.00699, 995.10000,     -0.25338,38.12500,50.00000,47.00000,2.848143e-09,0.78718
300.02200, 997.10000,     -0.25338,38.10523,50.00000,47.00000,2.849024e-09,0.78718
300.01401, 999.10000,     -0.25563,38.05911,50.00000,47.00000,2.847372e-09,0.78719
300.01300,1001.10000,     -0.25244,38.02636,50.00000,47.00000,2.844567e-09,0.78720
300.00699,1003.10000,     -0.25413,37.97364,50.00000,47.00000,2.841243e-09,0.78718
300.01300,1005.10000,     -0.25357,37.94729,50.00000,47.00000,2.846775e-09,0.78718
300.02301,1007.10000,     -0.25282,37.90795,50.00000,47.00000,2.844515e-09,0.78717
300.01001,1009.10000,     -0.25413,37.88159,50.00000,47.00000,2.846569e-09,0.78719
300.00900,1011.10000,     -0.25413,37.84205,50.00000,47.00000,2.844656e-09,0.78719
300.03400,1013.10000,     -0.25545,37.81589,50.00000,47.00000,2.845933e-09,0.78718
300.01999,1015.10000,     -0.25488,37.80271,50.00000,47.00000,2.850900e-09,0.78719
300.02100,1017.10000,     -0.25451,37.76764,50.00000,47.00000,2.843307e-09,0.78719
300.02100,1019.10000,     -0.25301,37.71938,50.00000,47.00000,2.843207e-09,0.78719
300.01999,1021.10000,     -0.25639,37.69302,50.00000,47.00000,2.848944e-09,0.78720
300.01501,1023.10000,     -0.25714,37.67984,50.00000,47.00000,2.841474e-09,0.78719
300.02100,1025.10000,     -0.25601,37.65349,50.00000,47.00000,2.835880e-09,0.78718
300.02301,1027.10000,     -0.25601,37.62733,50.00000,47.00000,2.842339e-09,0.78719
300.01501,1029.10000,     -0.25413,37.57461,50.00000,47.00000,2.847012e-09,0.78719
300.02301,1031.10000,     -0.25507,37.53508,50.00000,47.00000,2.842814e-09,0.78719
300.02600,1033.10000,     -0.25357,37.49574,50.00000,47.00000,2.848599e-09,0.78719
300.00800,1035.10000,     -0.25544,37.46938,50.00000,47.00000,2.856851e-09,0.78719
300.01999,1037.10000,     -0.25620,37.42984,50.00000,47.00000,2.850292e-09,0.78718
300.01599,1039.10000,     -0.25451,37.39709,50.00000,47.00000,2.854772e-09,0.78719
300.03400,1041.10000,     -0.25545,37.37074,50.00000,47.00000,2.854062e-09,0.78719
300.02100,1043.10000,     -0.25676,37.34438,50.00000,47.00000,2.854457e-09,0.78719
300.01099,1045.10000,     -0.25714,37.32694,50.00000,47.00000,2.856745e-09,0.78719
300.01599,1047.10000,     -0.25582,37.28740,50.00000,47.00000,2.863091e-09,0.78719
300.01401,1049.10000,     -0.25732,37.25446,50.00000,47.00000,2.860178e-09,0.78718
300.02600,1051.10000,     -0.25770,37.20194,50.00000,47.00000,2.857336e-09,0.78720
300.01001,1053.10000,     -0.25432,37.17558,50.00000,47.00000,2.863649e-09,0.78720
300.01999,1055.10000,     -0.25714,37.14264,50.00000,47.00000,2.853248e-09,0.78718
300.01300,1057.10000,     -0.25545,37.11647,50.00000,47.00000,2.855363e-09,0.78719
300.01099,1059.10000,     -0.25901,37.09012,50.00000,47.00000,2.861811e-09,0.78718
300.01199,1061.10000,     -0.25601,37.07694,50.00000,47.00000,2.857965e-09,0.78720
300.01001,1063.10000,     -0.25713,37.05058,50.00000,47.00000,2.855401e-09,0.78720
300.02701,1065.10000,     -0.26015,37.00465,50.00000,47.00000,2.848649e-09,0.78720
300.01300,1067.10000,     -0.25657,36.96512,50.00000,47.00000,2.854265e-09,0.78718
300.01001,1069.10000,     -0.25920,36.94535,50.00000,47.00000,2.855639e-09,0.78719
300.01300,1071.10000,     -0.25864,36.91240,50.00000,47.00000,2.858069e-09,0.78719
300.02100,1073.10000,     -0.25714,36.88624,50.00000,47.00000,2.851651e-09,0.78720
300.00601,1075.10000,     -0.25826,36.84884,50.00000,47.00000,2.862802e-09,0.78720
300.01901,1077.10000,     -0.25770,36.83566,50.00000,46.00000,2.857945e-09,0.78719
300.00500,1079.10000,     -0.25826,36.81609,50.00000,46.00000,2.856613e-09,0.78720
300.02200,1081.10000,     -0.25695,36.75019,50.00000,46.00000,2.859472e-09,0.78719
300.02301,1083.10000,     -0.25770,36.73702,50.00000,46.00000,2.860641e-09,0.78718
300.02701,1085.10000,     -0.25827,36.68450,50.00000,46.00000,2.862833e-09,0.78719
300.01700,1087.10000,     -0.25939,36.66260,50.00000,46.00000,2.863104e-09,0.78719
300.02200,1089.10000,     -0.26089,36.61647,50.00000,46.00000,2.858684e-09,0.78719
300.01401,1091.10000,     -0.26033,36.58353,50.00000,46.00000,2.858292e-09,0.78718
300.01801,1093.10000,     -0.25808,36.57713,50.00000,46.00000,2.856646e-09,0.78719
300.02301,1095.10000,     -0.25827,36.55078,50.00000,46.00000,2.855909e-09,0.78720
300.01401,1097.10000,     -0.25901,36.47829,50.00000,46.00000,2.850523e-09,0.78719
300.01801,1099.10000,     -0.25864,36.47171,50.00000,46.00000,2.863380e-09,0.78719
300.02399,1101.10000,     -0.25977,36.43895,50.00000,46.00000,2.856528e-09,0.78719
300.00900,1103.10000,     -0.25864,36.41919,50.00000,46.00000,2.857550e-09,0.78719
300.02802,1105.10000,     -0.25827,36.37965,50.00000,46.00000,2.859409e-09,0.78719
300.02600,1107.10000,     -0.25864,36.35116,50.00000,46.00000,2.852419e-09,0.78718
300.02200,1109.10000,     -0.25883,36.33798,50.00000,46.00000,2.857359e-09,0.78719
300.02701,1111.10000,     -0.25996,36.31182,50.00000,46.00000,2.856377e-09,0.78719
300.01199,1113.10000,     -0.25976,36.26570,50.00000,46.00000,2.856130e-09,0.78719
300.02499,1115.10000,     -0.26259,36.22616,50.00000,46.00000,2.862337e-09,0.78719
300.01401,1117.10000,     -0.26108,36.20000,50.00000,46.00000,2.863322e-09,0.78719
300.01901,1119.10000,     -0.25958,36.17364,50.00000,46.00000,2.857474e-09,0.78719
300.02499,1121.10000,     -0.26108,36.14729,50.00000,46.00000,2.855446e-09,0.78719
300.01801,1123.10000,     -0.26108,36.12539,50.00000,46.00000,2.860205e-09,0.78718
300.01199,1125.10000,     -0.26277,36.07713,50.00000,46.00000,2.854708e-09,0.78718
300.01700,1127.10000,     -0.26014,36.04419,50.00000,46.00000,2.853111e-09,0.78721
299.99799,1129.10000,     -0.25845,36.02461,50.00000,46.00000,2.864520e-09,0.78719
300.01901,1131.10000,     -0.25977,35.99826,50.00000,46.00000,2.861014e-09,0.78720
300.02100,1133.10000,     -0.26259,35.95213,50.00000,46.00000,2.856857e-09,0.78719
300.01801,1135.10000,     -0.26183,35.92578,50.00000,46.00000,2.857646e-09,0.78719
300.01199,1137.10000,     -0.26127,35.89302,50.00000,46.00000,2.863588e-09,0.78719
300.02200,1139.10000,     -0.26127,35.84477,50.00000,46.00000,2.866268e-09,0.78719
300.02399,1141.10000,     -0.26090,35.79205,50.00000,46.00000,2.859498e-09,0.78719
300.02499,1143.10000,     -0.26071,35.79864,50.00000,46.00000,2.857814e-09,0.78720
300.01300,1145.10000,     -0.26239,35.76802,50.00000,46.00000,2.863199e-09,0.78719
300.01199,1147.10000,     -0.26371,35.74380,50.00000,46.00000,2.859352e-09,0.78719
300.02399,1149.10000,     -0.26183,35.71764,50.00000,46.00000,2.861361e-09,0.78720
300.01599,1151.10000,     -0.26183,35.68469,50.00000,46.00000,2.853511e-09,0.78719
300.01599,1153.10000,     -0.26427,35.64516,50.00000,46.00000,2.853318e-09,0.78719
300.00299,1155.10000,     -0.25976,35.61240,50.00000,46.00000,2.857590e-09,0.78719
300.01801,1157.10000,     -0.26202,35.56628,50.00000,46.00000,2.859278e-09,0.78719
300.02100,1159.10000,     -0.26296,35.53992,50.00000,46.00000,2.861098e-09,0.78718
300.01501,1161.10000,     -0.26127,35.52674,50.00000,46.00000,2.862300e-09,0.78719
300.01501,1163.10000,     -0.26164,35.48081,50.00000,46.00000,2.853787e-09,0.78719
300.01599,1165.10000,     -0.26127,35.42151,50.00000,46.00000,2.856374e-09,0.78719
300.03299,1167.10000,     -0.26484,35.39535,50.00000,46.00000,2.860512e-09,0.78719
300.01999,1169.10000,     -0.26165,35.36240,50.00000,46.00000,2.858062e-09,0.78718
300.02100,1171.10000,     -0.26165,35.33605,50.00000,46.00000,2.859367e-09,0.78719
300.01999,1173.10000,     -0.26352,35.31628,50.00000,46.00000,2.858138e-09,0.78718
299.99600,1175.10000,     -0.26314,35.26376,50.00000,46.00000,2.863906e-09,0.78719
300.01700,1177.10000,     -0.26334,35.23740,50.00000,46.00000,2.857048e-09,0.78719
300.01599,1179.10000,     -0.26446,35.22422,50.00000,46.00000,2.856527e-09,0.78719
300.01801,1181.10000,     -0.26240,35.21105,50.00000,46.00000,2.859274e-09,0.78719
300.01901,1183.10000,     -0.26258,35.15620,50.00000,46.00000,2.857836e-09,0.78719
300.01199,1185.10000,     -0.26315,35.14961,50.00000,46.00000,2.861802e-09,0.78719
299.99799,1187.10000,     -0.26389,35.09709,50.00000,46.00000,2.851073e-09,0.78719
300.01300,1189.10000,     -0.26390,35.07074,50.00000,46.00000,2.859434e-09,0.78719
300.02600,1191.10000,     -0.26409,35.05756,50.00000,46.00000,2.856869e-09,0.78719
300.01700,1193.10000,     -0.26352,35.01163,50.00000,46.00000,2.855526e-09,0.78718
300.02100,1195.10000,     -0.26315,34.98527,50.00000,47.00000,2.856535e-09,0.78719
300.02301,1197.10000,     -0.26390,34.94574,50.00000,47.00000,2.856982e-09,0.78719
300.01099,1199.10000,     -0.26502,34.91957,50.00000,47.00000,2.864629e-09,0.78718
300.02301,1201.10000,     -0.26240,34.89322,50.00000,47.00000,2.862694e-09,0.78719
300.02200,1203.10000,     -0.26465,34.86473,50.00000,47.00000,2.853961e-09,0.78719
300.01801,1205.10000,     -0.26540,34.81202,50.00000,47.00000,2.865497e-09,0.78720
300.01801,1207.10000,     -0.26352,34.79225,50.00000,47.00000,2.858277e-09,0.78719
300.01199,1209.10000,     -0.26427,34.76163,50.00000,47.00000,2.861464e-09,0.78719
300.01700,1211.10000,     -0.26484,34.72868,50.00000,47.00000,2.860791e-09,0.78719
300.00601,1213.10000,     -0.26671,34.68934,50.00000,47.00000,2.864639e-09,0.78720
300.01801,1215.10000,     -0.26277,34.66957,50.00000,47.00000,2.864196e-09,0.78719
300.01501,1217.10000,     -0.26409,34.64322,50.00000,47.00000,2.865234e-09,0.78720
300.00699,1219.10000,     -0.26221,34.61686,50.00000,47.00000,2.863552e-09,0.78719
300.00400,1221.10000,     -0.26652,34.57093,50.00000,47.00000,2.856129e-09,0.78720
300.01501,1223.10000,     -0.26521,34.51822,50.00000,47.00000,2.861658e-09,0.78720
300.02100,1225.10000,     -0.26409,34.51163,50.00000,47.00000,2.864119e-09,0.78719
300.01199,1227.10000,     -0.26671,34.46570,50.00000,47.00000,2.866696e-09,0.78719
300.01099,1229.10000,     -0.26446,34.46570,50.00000,47.00000,2.864748e-09,0.78721
300.01001,1231.10000,     -0.26333,34.42616,50.00000,47.00000,2.857784e-09,0.78719
300.01099,1233.10000,     -0.26333,34.39981,50.00000,47.00000,2.864170e-09,0.78719
300.01599,1235.10000,     -0.26559,34.34729,50.00000,47.00000,2.863505e-09,0.78720
300.00500,1237.10000,     -0.26521,34.33411,50.00000,47.00000,2.859180e-09,0.78718
300.00699,1239.10000,     -0.26465,34.31647,50.00000,47.00000,2.867303e-09,0.78719
300.01700,1241.10000,     -0.26315,34.27054,50.00000,47.00000,2.857350e-09,0.78719
300.01999,1243.10000,     -0.26540,34.23760,50.00000,47.00000,2.857260e-09,0.78719
300.01901,1245.10000,     -0.26559,34.24419,50.00000,47.00000,2.858650e-09,0.78719
300.01801,1247.10000,     -0.26634,34.20465,50.00000,47.00000,2.864565e-09,0.78719
300.01300,1249.10000,     -0.26465,34.17190,50.00000,47.00000,2.863137e-09,0.78719
300.00601,1251.10000,     -0.26427,34.14554,50.00000,47.00000,2.857026e-09,0.78718
300.01401,1253.10000,     -0.26409,34.10388,50.00000,47.00000,2.862152e-09,0.78719
300.02200,1255.10000,     -0.26522,34.07093,50.00000,47.00000,2.861799e-09,0.78719
300.02200,1257.00000,     -0.26465,34.04477,50.00000,47.00000,2.866107e-09,0.78719