File: data/TGA/005d-L_M/ExpDat_2025_03_22_SL_005d_L4_isothermal.csv
#EXPORTTYPE:                 ,DATA ALL
#FILE:                       ,2025_03_22_SL_005d_L4_isothermal.ngb-ss5
#FORMAT:                     ,NETZSCH5
#FTYPE:                      ,ASCII
#IDENTITY:                   ,2025_03_22_SL_005d_L4_i
#DECIMAL:                    ,POINT
#SEPARATOR:                  ,COMMA
#MTYPE:                      ,DSC
#INSTRUMENT:                 ,NETZSCH STA 449F5
#PROJECT:                    ,PS
#DATE/TIME:                  ,3/22/2025 4:30:26 PM (UTC-4)
#CORR. FILE:                 ,
#TEMPCAL:                    ,13-11-2024 10:37
#SENSITIVITY:                ,28-06-2023 13:53
#LABORATORY:                 ,Tran/Aspuru
#OPERATOR:                   ,Stanley
#REMARK:                     ,2025_03_22_SL_005d_L4_isothermal
#SAMPLE:                     ,2025_03_22_SL_005d_L4_i
#SAMPLE MASS /mg:            ,4.98
#MATERIAL:                   ,Polystyrene
#REFERENCE:                  ,
#REFERENCE MASS /mg:         ,0
#TYPE OF CRUCIBLE:           ,Al2O3 85 ‘l, open
#SAMPLE CRUCIBLE MASS /mg:   ,0
#REFERENCE CRUCIBLE MASS /mg:,0
#DSC RANGE /‘V:              ,5000
#TG RANGE /mg:               ,35000
#TAU-R:                      ,---
#CORR. CODE:                 ,000
#EXO:                        ,-1
#RANGE:                      ,30›C....800›C/0.0....20.0K/min
#SEGMENT:                    ,S1-5/5
#SEG. 1:                     ,30›C/10.0(K/min)/100›C
#SEG. 2:                     ,100›C/00:10/100›C
#SEG. 3:                     ,100›C/5.0(K/min)/300›C
#SEG. 4:                     ,300›C/20:00/300›C
#SEG. 5:                     ,300›C/20.0(K/min)/800›C

##Temp./›C,Time/min,DSC/(mW/mg),Mass/%,Gas Flow(purge2)/(ml/min),Gas Flow(protective)/(ml/min),TIC(scan:1)/A,Sensit./(uV/mW),Segment
 28.67500,   0.00000,-2.887128e-02,100.00000,50.00000,42.00000,            ,0.92330,1
 33.52600,   1.32000,-2.884429e-02, 99.93173,50.00000,50.00000,2.808590e-10,0.92350,1
 40.01400,   2.64000, 1.076451e-02, 92.98695,50.00000,50.00000,2.802716e-10,0.92370,1
 48.99400,   3.96000, 8.438550e-02, 93.80703,50.00000,50.00000,2.806626e-10,0.92390,1
 61.24400,   5.28000,      0.19386, 94.95884,50.00000,50.00000,2.812690e-10,0.92411,1
 76.03400,   6.60000,      0.30366, 95.82450,50.00000,50.00000,2.815799e-10,0.92433,1
 86.36200,   7.46000,      0.34409, 96.04478,50.00000,50.00000,2.815018e-10,0.92450,2
 93.13100,   8.12000,      0.26071, 95.39498,50.00000,50.00000,2.810841e-10,0.92461,2
 98.11200,   8.78000,      0.15811, 94.58414,50.00000,50.00000,2.812481e-10,0.92472,2
101.73600,   9.44000, 9.469052e-02, 93.96847,50.00000,50.00000,2.814828e-10,0.92483,2
104.65600,  10.10000, 6.012656e-02, 93.56867,50.00000,50.00000,2.819977e-10,0.92494,2
106.98600,  10.76000, 2.500103e-02, 93.13233,50.00000,50.00000,2.811623e-10,0.92506,2
108.62300,  11.42000,-2.051146e-02, 92.60984,50.00000,50.00000,2.813263e-10,0.92516,2
109.61800,  12.08000,-6.055334e-02, 92.17369,50.00000,50.00000,2.817077e-10,0.92527,2
110.08900,  12.74000,-9.042697e-02, 91.74659,50.00000,50.00000,2.822704e-10,0.92538,2
110.15100,  13.40000,     -0.11379, 91.34900,50.00000,50.00000,2.821655e-10,0.92548,2
109.95800,  14.06000,     -0.12879, 90.97430,50.00000,50.00000,2.827358e-10,0.92558,2
109.50400,  14.72000,     -0.14095, 90.65161,50.00000,50.00000,2.822474e-10,0.92568,2
108.89000,  15.38000,     -0.14760, 90.35863,50.00000,50.00000,2.822819e-10,0.92577,2
108.14600,  16.04000,     -0.15290, 90.10643,50.00000,50.00000,2.824383e-10,0.92586,2
107.34600,  16.70000,     -0.15452, 89.85643,50.00000,50.00000,2.827034e-10,0.92594,2
106.27800,  17.72000,     -0.13448, 89.77470,50.00000,50.00000,2.831573e-10,0.92604,3
107.29300,  19.04000,-4.017218e-02, 90.55622,50.00000,50.00000,2.821731e-10,0.92614,3
110.52100,  20.36000, 2.619754e-02, 91.10141,50.00000,50.00000,2.820549e-10,0.92620,3
115.48500,  21.68000,      0.10063, 91.66265,50.00000,50.00000,2.829151e-10,0.92619,3
121.94600,  23.00000,      0.16287, 92.16245,50.00000,50.00000,2.829114e-10,0.92611,3
129.25500,  24.32000,      0.20607, 92.52349,50.00000,50.00000,2.831097e-10,0.92595,3
137.02299,  25.64000,      0.22689, 92.76888,50.00000,50.00000,2.828789e-10,0.92571,3
144.91901,  26.96000,      0.22832, 92.90522,50.00000,50.00000,2.829990e-10,0.92538,3
152.69400,  28.28000,      0.21705, 92.98695,50.00000,50.00000,2.829762e-10,0.92489,3
160.25200,  29.60000,      0.19941, 93.05522,50.00000,50.00000,2.834645e-10,0.92453,3
167.53400,  30.92000,      0.18042, 93.11647,50.00000,50.00000,2.835294e-10,0.92424,3
174.59700,  32.24000,      0.15799, 93.15743,50.00000,50.00000,2.832012e-10,0.92394,3
181.49001,  33.56000,      0.13311, 93.18474,50.00000,50.00000,2.829894e-10,0.92363,3
188.24500,  34.88000,      0.10905, 93.26647,50.00000,50.00000,2.834377e-10,0.92332,3
194.92799,  36.20000, 8.107214e-02, 93.30723,50.00000,50.00000,2.835484e-10,0.92300,3
201.54700,  37.52000, 5.245952e-02, 93.32771,50.00000,50.00000,2.835616e-10,0.92270,3
208.14101,  38.84000, 1.894035e-02, 93.40964,50.00000,50.00000,2.832947e-10,0.92240,3
214.69501,  40.16000,-1.299550e-02, 93.41406,50.00000,50.00000,2.831974e-10,0.92212,3
221.27499,  41.48000,-4.888669e-02, 93.49578,50.00000,50.00000,2.836551e-10,0.92186,3
227.82300,  42.80000,-8.989877e-02, 93.48233,50.00000,50.00000,2.833366e-10,0.92161,3
234.37399,  44.12000,     -0.13143, 93.48233,50.00000,50.00000,2.835998e-10,0.92137,3
240.93100,  45.44000,     -0.17570, 93.52992,50.00000,50.00000,2.831879e-10,0.92114,3
247.49899,  46.76000,     -0.21946, 93.58454,50.00000,50.00000,2.840672e-10,0.92093,3
254.07800,  48.08000,     -0.26958, 93.61165,50.00000,50.00000,2.837353e-10,0.92072,3
260.65302,  49.40000,     -0.32172, 93.63896,50.00000,50.00000,2.844200e-10,0.92052,3
267.23099,  50.72000,     -0.37800, 93.71406,50.00000,50.00000,2.842045e-10,0.92032,3
273.79300,  52.04000,     -0.43851, 93.71406,50.00000,50.00000,2.837906e-10,0.92013,3
280.36200,  53.36000,     -0.50129, 93.74116,50.00000,50.00000,2.840691e-10,0.91995,3
286.92801,  54.68000,     -0.56523, 93.76847,50.00000,50.00000,2.844848e-10,0.91975,3
293.50201,  56.00000,     -0.63232, 93.77530,50.00000,50.00000,2.841167e-10,0.91959,3
301.54800,  57.80000,     -0.93996, 96.15382,50.00000,24.00000,2.846145e-10,0.91937,4
303.31100,  61.10000,     -1.54233, 94.86124,50.00000,23.00000,2.842178e-10,0.91902,4
302.08099,  64.40000,     -1.59821, 94.40241,50.00000,23.00000,2.843456e-10,0.91873,4
301.04099,  67.70000,     -1.57792, 93.95924,50.00000,23.00000,2.848720e-10,0.91852,4
300.48199,  71.00000,     -1.56091, 93.63896,50.00000,23.00000,2.844124e-10,0.91838,4
300.21600,  74.30000,     -1.55244, 93.31867,50.00000,23.00000,2.847595e-10,0.91828,4
300.08499,  77.60000,     -1.54714, 93.00281,50.00000,23.00000,2.858257e-10,0.91823,4
300.05899,  80.90000,     -1.54592, 92.76446,50.00000,23.00000,2.860280e-10,0.91823,4
300.02200,  84.20000,     -1.54644, 92.47129,50.00000,23.00000,2.850228e-10,0.91825,4
300.01001,  87.50000,     -1.54486, 92.24639,50.00000,23.00000,2.849941e-10,0.91831,4
300.00699,  90.80000,     -1.54427, 92.03514,50.00000,23.00000,2.853470e-10,0.91838,4
300.00900,  94.10000,     -1.54233, 91.82390,50.00000,23.00000,2.865811e-10,0.91849,4
300.01801,  97.40000,     -1.54234, 91.63293,50.00000,23.00000,2.851066e-10,0.91861,4
300.01599, 100.70000,     -1.54117, 91.44217,50.00000,23.00000,2.856427e-10,0.91873,4
300.01901, 104.00000,     -1.53981, 91.28554,50.00000,23.00000,2.866440e-10,0.91887,4
300.00201, 107.30000,     -1.53725, 91.12189,50.00000,23.00000,2.868558e-10,0.91901,4
300.01700, 110.60000,     -1.53767, 90.95823,50.00000,23.00000,2.864304e-10,0.91916,4
300.01401, 113.90000,     -1.53844, 90.83333,50.00000,23.00000,2.865371e-10,0.91937,4
300.01300, 117.20000,     -1.53611, 90.68333,50.00000,23.00000,2.867450e-10,0.91929,4
300.01700, 120.50000,     -1.53514, 90.53353,50.00000,23.00000,2.867584e-10,0.91890,4
300.01401, 123.80000,     -1.53533, 90.39036,50.00000,23.00000,2.865467e-10,0.91830,4
300.01599, 127.10000,     -1.53494, 90.25181,50.00000,23.00000,2.873821e-10,0.91749,4
300.01999, 130.40000,     -1.53573, 90.08815,50.00000,23.00000,2.873382e-10,0.91642,4
300.00900, 133.70000,     -1.53435, 89.97912,50.00000,23.00000,2.871875e-10,0.91511,4
300.01801, 137.00000,     -1.53203, 89.85643,50.00000,23.00000,2.874183e-10,0.91357,4
300.02701, 140.30000,     -1.53263, 89.72028,50.00000,23.00000,2.878151e-10,0.91183,4
300.02899, 143.60000,     -1.53224, 89.61807,50.00000,23.00000,2.872656e-10,0.90991,4
300.02802, 146.90000,     -1.53146, 89.45221,50.00000,23.00000,2.879391e-10,0.90785,4
300.01801, 150.20000,     -1.53106, 89.31586,50.00000,23.00000,2.879448e-10,0.90565,4
300.02802, 153.50000,     -1.53010, 89.21365,50.00000,23.00000,2.885704e-10,0.90335,4
300.04001, 156.80000,     -1.52993, 89.04317,50.00000,23.00000,2.875957e-10,0.90086,4
300.04901, 160.10000,     -1.52975, 88.92731,50.00000,22.00000,2.884693e-10,0.89843,4
300.01599, 163.40000,     -1.52774, 88.75703,50.00000,22.00000,2.884540e-10,0.89596,4
300.01401, 166.70000,     -1.52813, 88.64799,50.00000,22.00000,2.886619e-10,0.89346,4
300.00800, 170.00000,     -1.52559, 88.47068,50.00000,22.00000,2.891751e-10,0.89091,4
300.03201, 173.30000,     -1.52524, 88.36165,50.00000,22.00000,2.880345e-10,0.88834,4
300.02301, 176.60000,     -1.52600, 88.22771,50.00000,22.00000,2.890434e-10,0.88574,4
300.02301, 179.90000,     -1.52484, 88.01185,50.00000,22.00000,2.878227e-10,0.88309,4
300.01199, 183.20000,     -1.52560, 87.90964,50.00000,22.00000,2.892818e-10,0.88028,4
300.01801, 186.50000,     -1.52366, 87.73916,50.00000,22.00000,2.883778e-10,0.87755,4
300.02802, 189.80000,     -1.52329, 87.60301,50.00000,22.00000,2.891579e-10,0.87478,4
300.01099, 193.10000,     -1.52306, 87.47349,50.00000,22.00000,2.894535e-10,0.87197,4
300.01599, 196.40000,     -1.52366, 87.35080,50.00000,22.00000,2.893181e-10,0.86912,4
300.02301, 199.70000,     -1.52328, 87.19398,50.00000,22.00000,2.894879e-10,0.86621,4
300.01801, 203.00000,     -1.52444, 87.05080,50.00000,22.00000,2.896730e-10,0.86327,4
300.01999, 206.30000,     -1.52230, 86.88735,50.00000,22.00000,2.895355e-10,0.86027,4
300.01700, 209.60000,     -1.52230, 86.77149,50.00000,22.00000,2.895985e-10,0.85722,4
300.01199, 212.90000,     -1.52190, 86.62610,50.00000,22.00000,2.899799e-10,0.85414,4
300.01001, 216.20000,     -1.52150, 86.46928,50.00000,22.00000,2.901039e-10,0.85083,4
300.01801, 219.50000,     -1.52016, 86.35341,50.00000,22.00000,2.895812e-10,0.84765,4
300.00500, 222.80000,     -1.52052, 86.20341,50.00000,22.00000,2.898597e-10,0.84442,4
300.01999, 226.10000,     -1.52113, 86.05361,50.00000,22.00000,2.897053e-10,0.84116,4
300.01401, 229.40000,     -1.51995, 85.91044,50.00000,22.00000,2.906056e-10,0.83787,4
300.01801, 232.70000,     -1.51918, 85.77410,50.00000,22.00000,2.900180e-10,0.83452,4
300.02899, 236.00000,     -1.51920, 85.63112,50.00000,22.00000,2.901402e-10,0.83114,4
300.02200, 239.30000,     -1.51802, 85.48554,50.00000,22.00000,2.909718e-10,0.82754,4
300.01401, 242.60000,     -1.51859, 85.34940,50.00000,22.00000,2.911204e-10,0.82410,4
300.02399, 245.90000,     -1.51744, 85.18574,50.00000,22.00000,2.910863e-10,0.82059,4
300.02399, 249.20000,     -1.51803, 85.04257,50.00000,22.00000,2.912160e-10,0.81708,4
300.01099, 252.50000,     -1.51878, 84.92450,50.00000,22.00000,2.914925e-10,0.81354,4
300.00500, 255.80000,     -1.51819, 84.78815,50.00000,22.00000,2.917366e-10,0.80997,4
300.00400, 259.10000,     -1.51935, 84.64518,50.00000,22.00000,2.911702e-10,0.80636,4
300.01300, 262.40000,     -1.51820, 84.50201,50.00000,22.00000,2.912827e-10,0.80274,4
300.01099, 265.70000,     -1.51800, 84.35884,50.00000,22.00000,2.918606e-10,0.79910,4
300.02899, 269.00000,     -1.51453, 84.22249,50.00000,22.00000,2.917748e-10,0.79544,4
300.01999, 272.30000,     -1.51491, 84.05663,50.00000,22.00000,2.918357e-10,0.79176,4
300.02200, 275.60000,     -1.51199, 83.89317,50.00000,22.00000,2.922325e-10,0.78729,4
300.00601, 278.90000,     -1.51371, 83.78855,50.00000,22.00000,2.919979e-10,0.78445,4
300.00400, 282.20000,     -1.51118, 83.66586,50.00000,22.00000,2.927608e-10,0.78421,4
300.00400, 285.50000,     -1.51157, 83.51606,50.00000,22.00000,2.923241e-10,0.78487,4
300.01099, 288.80000,     -1.51255, 83.36386,50.00000,22.00000,2.927323e-10,0.78561,4
300.01501, 292.10000,     -1.51256, 83.24799,50.00000,22.00000,2.929134e-10,0.78616,4
300.01901, 295.40000,     -1.51335, 83.09116,50.00000,22.00000,2.937565e-10,0.78655,4
300.01099, 298.70000,     -1.51080, 82.97530,50.00000,23.00000,2.918319e-10,0.78680,4
300.00699, 302.00000,     -1.51177, 82.83896,50.00000,23.00000,2.935161e-10,0.78697,4
300.01300, 305.30000,     -1.51081, 82.68916,50.00000,23.00000,2.929001e-10,0.78706,4
300.02499, 308.60000,     -1.50947, 82.55281,50.00000,23.00000,2.939377e-10,0.78711,4
300.02301, 311.90000,     -1.51024, 82.43012,50.00000,23.00000,2.929191e-10,0.78714,4
300.01001, 315.20000,     -1.50983, 82.28695,50.00000,23.00000,2.937564e-10,0.78716,4
300.02100, 318.50000,     -1.50965, 82.15743,50.00000,23.00000,2.934780e-10,0.78719,4
300.01300, 321.80000,     -1.51022, 82.02791,50.00000,23.00000,2.941303e-10,0.78719,4
300.00900, 325.10000,     -1.50807, 81.88494,50.00000,23.00000,2.936497e-10,0.78719,4
300.00299, 328.40000,     -1.50787, 81.75542,50.00000,23.00000,2.938709e-10,0.78719,4
300.02100, 331.70000,     -1.50712, 81.57811,50.00000,23.00000,2.933636e-10,0.78719,4
300.01801, 335.00000,     -1.50614, 81.45562,50.00000,23.00000,2.937069e-10,0.78720,4
300.02200, 338.30000,     -1.50829, 81.31928,50.00000,23.00000,2.936916e-10,0.78719,4
300.02200, 341.60000,     -1.50596, 81.17610,50.00000,23.00000,2.946625e-10,0.78719,4
300.00800, 344.90000,     -1.50437, 81.03293,50.00000,23.00000,2.936667e-10,0.78719,4
300.01901, 348.20000,     -1.50362, 80.91707,50.00000,23.00000,2.944660e-10,0.78720,4
300.00699, 351.50000,     -1.50359, 80.75361,50.00000,23.00000,2.931289e-10,0.78719,4
300.02600, 354.80000,     -1.50110, 80.62410,50.00000,23.00000,2.950363e-10,0.78720,4
300.03101, 358.10000,     -1.50150, 80.49458,50.00000,23.00000,2.945442e-10,0.78720,4
300.01001, 361.40000,     -1.50107, 80.33092,50.00000,23.00000,2.941685e-10,0.78720,4
300.01401, 364.70000,     -1.49777, 80.21064,50.00000,23.00000,2.944394e-10,0.78720,4
300.01801, 368.00000,     -1.49817, 80.06064,50.00000,23.00000,2.949027e-10,0.78719,4
300.01901, 371.30000,     -1.49817, 79.95161,50.00000,23.00000,2.944049e-10,0.78719,4
300.01801, 374.60000,     -1.49641, 79.81084,50.00000,23.00000,2.949962e-10,0.78719,4
300.01199, 377.90000,     -1.49524, 79.66084,50.00000,23.00000,2.951222e-10,0.78719,4
300.00800, 381.20000,     -1.49542, 79.51767,50.00000,23.00000,2.947025e-10,0.78719,4
300.01401, 384.50000,     -1.49524, 79.38815,50.00000,23.00000,2.950993e-10,0.78720,4
300.00601, 387.80000,     -1.49386, 79.22470,50.00000,23.00000,2.958050e-10,0.78720,4
300.00699, 391.10000,     -1.49406, 79.06787,50.00000,23.00000,2.950440e-10,0.78720,4
300.01300, 394.40000,     -1.49018, 78.97249,50.00000,23.00000,2.950953e-10,0.78719,4
300.03201, 397.70000,     -1.49041, 78.80884,50.00000,23.00000,2.959099e-10,0.78719,4
300.01199, 401.00000,     -1.48784, 78.69538,50.00000,23.00000,2.958012e-10,0.78720,4
300.02600, 404.30000,     -1.48748, 78.53173,50.00000,23.00000,2.958259e-10,0.78720,4
300.01801, 407.60000,     -1.48629, 78.41586,50.00000,23.00000,2.965087e-10,0.78718,4
300.01599, 410.90000,     -1.48434, 78.26606,50.00000,23.00000,2.958259e-10,0.78719,4
300.02899, 414.20000,     -1.48417, 78.12731,50.00000,23.00000,2.963906e-10,0.78718,4
300.02100, 417.50000,     -1.48182, 78.00462,50.00000,23.00000,2.963886e-10,0.78718,4
300.01300, 420.80000,     -1.47967, 77.88213,50.00000,23.00000,2.967721e-10,0.78718,4
300.01401, 424.10000,     -1.47947, 77.73896,50.00000,23.00000,2.955341e-10,0.78715,4
300.02301, 427.40000,     -1.47949, 77.56847,50.00000,23.00000,2.970620e-10,0.78719,4
300.00299, 430.70000,     -1.47848, 77.45944,50.00000,23.00000,2.967528e-10,0.78719,4
300.00601, 434.00000,     -1.47790, 77.32309,50.00000,23.00000,2.970771e-10,0.78718,4
300.01599, 437.30000,     -1.47656, 77.20060,50.00000,23.00000,2.967300e-10,0.78718,4
300.01401, 440.60000,     -1.47578, 77.05743,50.00000,23.00000,2.965545e-10,0.78718,4
300.00699, 443.90000,     -1.47401, 76.94839,50.00000,23.00000,2.964477e-10,0.78718,4
300.02200, 447.20000,     -1.47346, 76.78474,50.00000,23.00000,2.971936e-10,0.78720,4
300.01401, 450.50000,     -1.47266, 76.66888,50.00000,23.00000,2.970046e-10,0.78719,4
300.00000, 453.80000,     -1.47167, 76.55301,50.00000,23.00000,2.973729e-10,0.78720,4
300.01999, 457.10000,     -1.47170, 76.39639,50.00000,23.00000,2.970619e-10,0.78718,4
300.01199, 460.40000,     -1.47130, 76.26004,50.00000,23.00000,2.973004e-10,0.78719,4
300.00299, 463.70000,     -1.47050, 76.11687,50.00000,23.00000,2.970715e-10,0.78719,4
300.02802, 467.00000,     -1.46977, 75.98735,50.00000,23.00000,2.974967e-10,0.78719,4
300.01801, 470.30000,     -1.46956, 75.81024,50.00000,23.00000,2.967491e-10,0.78719,4
300.01801, 473.60000,     -1.46761, 75.71486,50.00000,23.00000,2.976876e-10,0.78718,4
300.01199, 476.90000,     -1.46702, 75.61928,50.00000,23.00000,2.972583e-10,0.78719,4
300.01401, 480.20000,     -1.46527, 75.47631,50.00000,23.00000,2.985228e-10,0.78720,4
300.01700, 483.50000,     -1.48979, 75.32631,50.00000,23.00000,2.980060e-10,0.78720,4
300.01599, 486.80000,     -1.49388, 75.18996,50.00000,23.00000,2.983341e-10,0.78719,4
300.02100, 490.10000,     -1.49700, 75.06044,50.00000,23.00000,2.976875e-10,0.78718,4
300.00699, 493.40000,     -1.49406, 74.91747,50.00000,23.00000,2.990170e-10,0.78719,4
300.01401, 496.70000,     -1.49485, 74.80843,50.00000,23.00000,2.991963e-10,0.78719,4
300.02499, 500.00000,     -1.49429, 74.64478,50.00000,23.00000,2.987958e-10,0.78718,4
300.01001, 503.30000,     -1.49329, 74.52209,50.00000,23.00000,2.991142e-10,0.78719,4
300.00900, 506.60000,     -1.49367, 74.39036,50.00000,23.00000,2.980098e-10,0.78720,4
300.02100, 509.90000,     -1.49369, 74.24719,50.00000,23.00000,2.988415e-10,0.78720,4
300.01700, 513.20000,     -1.49466, 74.09719,50.00000,23.00000,2.995567e-10,0.78719,4
300.02499, 516.50000,     -1.49098, 74.00181,50.00000,23.00000,2.987899e-10,0.78719,4
300.01700, 519.80000,     -1.49174, 73.82470,50.00000,23.00000,2.992248e-10,0.78719,4
300.02100, 523.10000,     -1.48902, 73.71566,50.00000,23.00000,2.991371e-10,0.78718,4
300.02899, 526.40000,     -1.48982, 73.56566,50.00000,23.00000,2.994099e-10,0.78719,4
300.01401, 529.70000,     -1.49018, 73.45663,50.00000,23.00000,2.985993e-10,0.78719,4
300.01001, 533.00000,     -1.48667, 73.33394,50.00000,23.00000,2.988586e-10,0.78717,4
300.02499, 536.30000,     -1.48397, 73.21124,50.00000,23.00000,2.998103e-10,0.78720,4
300.01700, 539.60000,     -1.48804, 73.05462,50.00000,23.00000,2.996750e-10,0.78719,4
300.02899, 542.90000,     -1.48729, 72.92510,50.00000,23.00000,2.991885e-10,0.78719,4
300.02100, 546.20000,     -1.48552, 72.82972,50.00000,23.00000,2.987462e-10,0.78719,4
300.04300, 549.50000,     -1.48614, 72.68655,50.00000,23.00000,2.995987e-10,0.78719,4
299.99899, 552.80000,     -1.48587, 72.57068,50.00000,23.00000,2.994804e-10,0.78720,4
300.02701, 556.10000,     -1.48611, 72.42751,50.00000,23.00000,3.000678e-10,0.78719,4
300.01300, 559.40000,     -1.48492, 72.31165,50.00000,23.00000,2.993565e-10,0.78719,4
300.02100, 562.70000,     -1.48377, 72.17530,50.00000,23.00000,3.007297e-10,0.78719,4
300.01901, 566.00000,     -1.48454, 72.05261,50.00000,23.00000,3.003942e-10,0.78719,4
300.01300, 569.30000,     -1.48317, 71.95723,50.00000,23.00000,2.995128e-10,0.78719,4
300.01501, 572.60000,     -1.48142, 71.82771,50.00000,23.00000,3.000259e-10,0.78719,4
300.01700, 575.90000,     -1.48220, 71.67791,50.00000,23.00000,3.003693e-10,0.78719,4
300.01801, 579.20000,     -1.48337, 71.56205,50.00000,23.00000,3.007736e-10,0.78719,4
300.02899, 582.50000,     -1.48028, 71.41888,50.00000,23.00000,3.000259e-10,0.78719,4
300.01300, 585.80000,     -1.48006, 71.27570,50.00000,23.00000,3.007222e-10,0.78719,4
300.01901, 589.10000,     -1.47948, 71.18715,50.00000,23.00000,3.000679e-10,0.78719,4
300.00601, 592.40000,     -1.47888, 71.03032,50.00000,23.00000,3.006229e-10,0.78717,4
300.01401, 595.70000,     -1.47928, 70.90763,50.00000,23.00000,3.006896e-10,0.78720,4
300.02899, 599.00000,     -1.47950, 70.78514,50.00000,23.00000,3.006744e-10,0.78720,4
300.01801, 602.30000,     -1.48240, 70.64197,50.00000,23.00000,3.008251e-10,0.78720,4
300.01099, 605.60000,     -1.48122, 70.53293,50.00000,23.00000,3.006841e-10,0.78719,4
300.01599, 608.90000,     -1.48123, 70.39659,50.00000,23.00000,3.009053e-10,0.78720,4
300.01700, 612.20000,     -1.47929, 70.30120,50.00000,23.00000,3.011436e-10,0.78719,4
300.01001, 615.50000,     -1.47869, 70.15120,50.00000,23.00000,3.004132e-10,0.78719,4
300.01901, 618.80000,     -1.48124, 70.05582,50.00000,23.00000,3.015271e-10,0.78720,4
300.00601, 622.10000,     -1.47946, 69.92631,50.00000,23.00000,3.020192e-10,0.78719,4
300.01901, 625.40000,     -1.47929, 69.81044,50.00000,23.00000,3.018284e-10,0.78718,4
300.02301, 628.70000,     -1.48007, 69.68775,50.00000,23.00000,3.022614e-10,0.78718,4
300.00699, 632.00000,     -1.47888, 69.56506,50.00000,23.00000,3.017331e-10,0.78720,4
300.01199, 635.30000,     -1.47733, 69.43554,50.00000,23.00000,3.015785e-10,0.78720,4
300.04001, 638.60000,     -1.47563, 69.29257,50.00000,23.00000,3.015594e-10,0.78720,4
300.00900, 641.90000,     -1.47791, 69.19036,50.00000,23.00000,3.021297e-10,0.78719,4
300.02100, 645.20000,     -1.47696, 69.08353,50.00000,23.00000,3.018151e-10,0.78719,4
300.01599, 648.50000,     -1.47695, 68.94036,50.00000,23.00000,3.025226e-10,0.78720,4
300.01199, 651.80000,     -1.47772, 68.82450,50.00000,23.00000,3.028222e-10,0.78720,4
300.01401, 655.10000,     -1.47772, 68.72912,50.00000,23.00000,3.019505e-10,0.78720,4
300.02100, 658.40000,     -1.47637, 68.60643,50.00000,23.00000,3.030014e-10,0.78719,4
300.02399, 661.70000,     -1.47502, 68.47008,50.00000,23.00000,3.025685e-10,0.78720,4
300.01599, 665.00000,     -1.47559, 68.34739,50.00000,23.00000,3.020934e-10,0.78720,4
300.00900, 668.30000,     -1.47441, 68.22470,50.00000,23.00000,3.024311e-10,0.78719,4
300.00101, 671.60000,     -1.47556, 68.10201,50.00000,23.00000,3.031559e-10,0.78720,4
300.02200, 674.90000,     -1.47560, 68.00663,50.00000,23.00000,3.023872e-10,0.78719,4
300.01599, 678.20000,     -1.47500, 67.91124,50.00000,23.00000,3.032036e-10,0.78719,4
300.01300, 681.50000,     -1.47558, 67.76807,50.00000,23.00000,3.033791e-10,0.78720,4
300.01501, 684.80000,     -1.47461, 67.64538,50.00000,23.00000,3.030797e-10,0.78719,4
300.01999, 688.10000,     -1.47345, 67.54317,50.00000,23.00000,3.032170e-10,0.78718,4
300.02701, 691.40000,     -1.47288, 67.41365,50.00000,23.00000,3.032456e-10,0.78719,4
300.00900, 694.70000,     -1.47402, 67.30462,50.00000,23.00000,3.032570e-10,0.78719,4
300.01401, 698.00000,     -1.47305, 67.17530,50.00000,23.00000,3.038883e-10,0.78720,4
300.01199, 701.30000,     -1.47363, 67.07289,50.00000,23.00000,3.037776e-10,0.78720,4
300.04401, 704.60000,     -1.47447, 66.93675,50.00000,23.00000,3.044891e-10,0.78719,4
300.02899, 707.90000,     -1.47211, 66.83454,50.00000,23.00000,3.031694e-10,0.78719,4
300.01401, 711.20000,     -1.47227, 66.71185,50.00000,23.00000,3.043823e-10,0.78719,4
300.02499, 714.50000,     -1.47171, 66.60964,50.00000,23.00000,3.041421e-10,0.78720,4
300.01901, 717.80000,     -1.47423, 66.48012,50.00000,23.00000,3.039359e-10,0.78720,4
300.01999, 721.10000,     -1.47345, 66.36426,50.00000,23.00000,3.036289e-10,0.78720,4
300.01901, 724.40000,     -1.47423, 66.23474,50.00000,23.00000,3.039436e-10,0.78719,4
300.01501, 727.70000,     -1.47228, 66.11205,50.00000,23.00000,3.043805e-10,0.78719,4
300.02100, 731.00000,     -1.47443, 66.01667,50.00000,23.00000,3.052673e-10,0.78720,4
300.00699, 734.30000,     -1.47421, 65.88032,50.00000,23.00000,3.045750e-10,0.78718,4
300.00500, 737.60000,     -1.47498, 65.75080,50.00000,23.00000,3.043842e-10,0.78718,4
300.02499, 740.90000,     -1.47366, 65.62129,50.00000,23.00000,3.045101e-10,0.78718,4
300.02802, 744.20000,     -1.47580, 65.49639,50.00000,23.00000,3.049202e-10,0.78716,4
300.00900, 747.50000,     -1.47402, 65.38735,50.00000,23.00000,3.050804e-10,0.78720,4
300.01700, 750.80000,     -1.47500, 65.34639,50.00000,23.00000,3.049583e-10,0.78720,4
300.01001, 754.10000,     -1.47207, 65.16928,50.00000,23.00000,3.052482e-10,0.78719,4
300.02301, 757.40000,     -1.47210, 65.05562,50.00000,23.00000,3.055744e-10,0.78718,4
300.01801, 760.70000,     -1.47423, 64.97390,50.00000,23.00000,3.053532e-10,0.78719,4
300.00601, 764.00000,     -1.47343, 64.85120,50.00000,23.00000,3.048782e-10,0.78718,4
300.02701, 767.30000,     -1.47444, 64.72169,50.00000,23.00000,3.062534e-10,0.78718,4
300.00101, 770.60000,     -1.47381, 64.61948,50.00000,23.00000,3.058089e-10,0.78719,4
300.01300, 773.90000,     -1.47402, 64.50361,50.00000,23.00000,3.064403e-10,0.78720,4
300.00699, 777.20000,     -1.47187, 64.36727,50.00000,23.00000,3.059558e-10,0.78720,4
300.01199, 780.50000,     -1.47363, 64.27189,50.00000,23.00000,3.059520e-10,0.78719,4
300.01501, 783.80000,     -1.47442, 64.17651,50.00000,23.00000,3.060130e-10,0.78720,4
300.01700, 787.10000,     -1.47267, 64.02651,50.00000,23.00000,3.063145e-10,0.78718,4
300.02301, 790.40000,     -1.47540, 63.91747,50.00000,23.00000,3.049259e-10,0.78718,4
300.00699, 793.70000,     -1.47382, 63.82209,50.00000,23.00000,3.064823e-10,0.78719,4
300.00601, 797.00000,     -1.47284, 63.71305,50.00000,23.00000,3.062553e-10,0.78719,4
300.01801, 800.30000,     -1.47501, 63.59719,50.00000,23.00000,3.057155e-10,0.78720,4
300.01999, 803.60000,     -1.47404, 63.48133,50.00000,23.00000,3.065719e-10,0.78721,4
300.01401, 806.90000,     -1.47403, 63.38594,50.00000,23.00000,3.067360e-10,0.78720,4
300.00699, 810.20000,     -1.47421, 63.25643,50.00000,23.00000,3.068600e-10,0.78719,4
300.02100, 813.50000,     -1.47423, 63.18153,50.00000,23.00000,3.067474e-10,0.78719,4
300.01599, 816.80000,     -1.47442, 63.04518,50.00000,23.00000,3.063813e-10,0.78718,4
300.01099, 820.10000,     -1.47383, 62.92932,50.00000,23.00000,3.064612e-10,0.78719,4
300.01001, 823.40000,     -1.47480, 62.82711,50.00000,23.00000,3.069058e-10,0.78719,4
300.00601, 826.70000,     -1.47479, 62.69759,50.00000,23.00000,3.065166e-10,0.78720,4
300.02301, 830.00000,     -1.47443, 62.62269,50.00000,23.00000,3.065700e-10,0.78719,4
300.02499, 833.30000,     -1.47560, 62.52028,50.00000,23.00000,3.072929e-10,0.78717,4
300.01501, 836.60000,     -1.47656, 62.41807,50.00000,23.00000,3.066921e-10,0.78719,4
300.01501, 839.90000,     -1.47597, 62.30904,50.00000,23.00000,3.065166e-10,0.78719,4
300.01501, 843.20000,     -1.47578, 62.19779,50.00000,23.00000,3.062954e-10,0.78719,4
300.01801, 846.50000,     -1.47578, 62.05462,50.00000,23.00000,3.072891e-10,0.78719,4
300.01801, 849.80000,     -1.47462, 61.98655,50.00000,23.00000,3.069992e-10,0.78718,4
300.00601, 853.10000,     -1.47576, 61.89799,50.00000,23.00000,3.068427e-10,0.78718,4
300.00900, 856.40000,     -1.47480, 61.77530,50.00000,23.00000,3.079032e-10,0.78719,4
300.01001, 859.70000,     -1.47635, 61.63896,50.00000,23.00000,3.061562e-10,0.78718,4
300.01001, 863.00000,     -1.47596, 61.57068,50.00000,23.00000,3.068943e-10,0.78719,4
300.01801, 866.30000,     -1.47890, 61.46165,50.00000,23.00000,3.084145e-10,0.78719,4
300.02701, 869.60000,     -1.47911, 61.33213,50.00000,23.00000,3.074207e-10,0.78719,4
300.00500, 872.90000,     -1.47907, 61.22992,50.00000,23.00000,3.077202e-10,0.78720,4
300.01300, 876.20000,     -1.48045, 61.10281,50.00000,23.00000,3.076057e-10,0.78719,4
299.99899, 879.50000,     -1.47964, 61.00743,50.00000,23.00000,3.070678e-10,0.78719,4
300.00101, 882.80000,     -1.47828, 60.90522,50.00000,22.00000,3.076439e-10,0.78718,4
300.01401, 886.10000,     -1.47850, 60.83695,50.00000,22.00000,3.074437e-10,0.78720,4
300.01901, 889.40000,     -1.47851, 60.74157,50.00000,22.00000,3.076362e-10,0.78719,4
300.00900, 892.70000,     -1.47810, 60.65301,50.00000,22.00000,3.080635e-10,0.78719,4
300.01099, 896.00000,     -1.47869, 60.56446,50.00000,22.00000,3.092861e-10,0.78719,4
300.00800, 899.30000,     -1.47830, 60.45542,50.00000,22.00000,3.076763e-10,0.78718,4
300.01700, 902.60000,     -1.47909, 60.35301,50.00000,22.00000,3.086033e-10,0.78719,4
300.02399, 905.90000,     -1.47813, 60.26446,50.00000,22.00000,2.897567e-10,0.78720,4
300.01599, 909.20000,     -1.47753, 60.13494,50.00000,22.00000,2.891616e-10,0.78719,4
300.01901, 912.50000,     -1.47637, 60.08273,50.00000,22.00000,2.892665e-10,0.78719,4
300.02399, 915.80000,     -1.47677, 59.94639,50.00000,22.00000,2.899913e-10,0.78719,4
300.01501, 919.10000,     -1.47617, 59.83735,50.00000,21.00000,2.895260e-10,0.78719,4
300.01401, 922.40000,     -1.47500, 59.73514,50.00000,21.00000,2.895926e-10,0.78720,4
300.03101, 925.70000,     -1.47464, 59.62610,50.00000,21.00000,2.892074e-10,0.78720,4
300.01401, 929.00000,     -1.47636, 59.52390,50.00000,21.00000,2.898654e-10,0.78719,4
300.02301, 932.30000,     -1.47540, 59.43534,50.00000,21.00000,2.889423e-10,0.78718,4
300.01700, 935.60000,     -1.47500, 59.31265,50.00000,21.00000,2.897320e-10,0.78719,4
300.02200, 938.90000,     -1.47540, 59.20361,50.00000,21.00000,2.894345e-10,0.78719,4
300.01901, 942.20000,     -1.47442, 59.08775,50.00000,21.00000,2.890644e-10,0.78720,4
300.01901, 945.50000,     -1.47306, 58.99237,50.00000,21.00000,2.890987e-10,0.78719,4
300.01001, 948.80000,     -1.47421, 58.90141,50.00000,21.00000,2.893201e-10,0.78718,4
300.01300, 952.10000,     -1.47363, 58.80602,50.00000,21.00000,2.894058e-10,0.78719,4
300.01501, 955.40000,     -1.47266, 58.69699,50.00000,21.00000,2.895756e-10,0.78719,4
300.01099, 958.70000,     -1.47344, 58.56747,50.00000,21.00000,2.897700e-10,0.78718,4
300.01801, 962.00000,     -1.47248, 58.48112,50.00000,21.00000,2.894286e-10,0.78719,4
300.01099, 965.30000,     -1.47305, 58.35161,50.00000,21.00000,2.898045e-10,0.78720,4
300.00699, 968.60000,     -1.47187, 58.26988,50.00000,21.00000,2.899971e-10,0.78719,4
300.01001, 971.90000,     -1.47188, 58.20181,50.00000,21.00000,2.891617e-10,0.78720,4
300.00500, 975.20000,     -1.47206, 58.06546,50.00000,21.00000,2.897568e-10,0.78720,4
300.01700, 978.50000,     -1.47150, 57.94277,50.00000,21.00000,2.898236e-10,0.78719,4
300.01300, 981.80000,     -1.47188, 57.86104,50.00000,21.00000,2.899304e-10,0.78719,4
300.01801, 985.10000,     -1.47131, 57.73835,50.00000,21.00000,2.892380e-10,0.78719,4
300.01501, 988.40000,     -1.47013, 57.65884,50.00000,21.00000,2.893295e-10,0.78719,4
300.02200, 991.70000,     -1.47268, 57.54980,50.00000,21.00000,2.896385e-10,0.78718,4
300.03201, 995.00000,     -1.47172, 57.46566,50.00000,21.00000,2.888832e-10,0.78720,4
300.01599, 998.30000,     -1.47189, 57.34980,50.00000,21.00000,2.890683e-10,0.78719,4
300.00800,1001.60000,     -1.47110, 57.26807,50.00000,21.00000,2.891026e-10,0.78719,4
300.00201,1004.90000,     -1.47186, 57.17952,50.00000,21.00000,2.902013e-10,0.78719,4
300.01999,1008.20000,     -1.47248, 57.04317,50.00000,21.00000,2.899647e-10,0.78719,4
300.00101,1011.50000,     -1.47420, 56.96145,50.00000,21.00000,2.901250e-10,0.78720,4
300.01901,1014.80000,     -1.47442, 56.85462,50.00000,21.00000,2.895450e-10,0.78718,4
300.01801,1018.10000,     -1.47345, 56.74558,50.00000,21.00000,2.897968e-10,0.78719,4
300.01001,1021.40000,     -1.47480, 56.65020,50.00000,21.00000,2.891903e-10,0.78719,4
300.00400,1024.70000,     -1.47615, 56.56145,50.00000,21.00000,2.899666e-10,0.78719,4
300.00400,1028.00000,     -1.47537, 56.43655,50.00000,21.00000,2.897338e-10,0.78719,4
299.99600,1031.30000,     -1.47575, 56.31386,50.00000,21.00000,2.899456e-10,0.78719,4
300.02802,1034.60000,     -1.47677, 56.22530,50.00000,21.00000,2.894573e-10,0.78720,4
300.01999,1037.90000,     -1.47734, 56.11627,50.00000,21.00000,2.900714e-10,0.78720,4
300.02600,1041.20000,     -1.47697, 56.03454,50.00000,21.00000,2.893028e-10,0.78718,4
300.01801,1044.50000,     -1.47715, 55.91867,50.00000,21.00000,2.896557e-10,0.78718,4
300.00800,1047.80000,     -1.47771, 55.84357,50.00000,21.00000,2.896614e-10,0.78719,4
300.01300,1051.10000,     -1.47578, 55.72088,50.00000,21.00000,2.892265e-10,0.78719,4
300.00800,1054.40000,     -1.47693, 55.63916,50.00000,21.00000,2.892208e-10,0.78720,4
300.01501,1057.70000,     -1.47772, 55.55060,50.00000,21.00000,2.894192e-10,0.78720,4
300.01001,1061.00000,     -1.47908, 55.45522,50.00000,21.00000,2.892647e-10,0.78718,4
300.01999,1064.30000,     -1.47910, 55.33936,50.00000,21.00000,2.895107e-10,0.78718,4
300.01599,1067.60000,     -1.47773, 55.26426,50.00000,21.00000,2.891960e-10,0.78719,4
300.01599,1070.90000,     -1.47967, 55.18474,50.00000,21.00000,2.894211e-10,0.78719,4
300.00601,1074.20000,     -1.47985, 55.08936,50.00000,21.00000,2.892208e-10,0.78719,4
300.01901,1077.50000,     -1.47871, 54.99398,50.00000,21.00000,2.892647e-10,0.78719,4
300.02200,1080.80000,     -1.47968, 54.85763,50.00000,21.00000,2.894688e-10,0.78719,4
300.01199,1084.10000,     -1.48044, 54.79639,50.00000,21.00000,2.901249e-10,0.78719,4
300.01801,1087.40000,     -1.48143, 54.68273,50.00000,21.00000,2.893371e-10,0.78720,4
300.02200,1090.70000,     -1.48105, 54.57369,50.00000,21.00000,2.897910e-10,0.78719,4
300.01700,1094.00000,     -1.48240, 54.49197,50.00000,21.00000,2.902203e-10,0.78720,4
300.01700,1097.30000,     -1.48123, 54.45100,50.00000,21.00000,2.896309e-10,0.78719,4
300.00400,1100.60000,     -1.48432, 54.31466,50.00000,21.00000,2.893219e-10,0.78719,4
300.01401,1103.90000,     -1.48239, 54.22610,50.00000,21.00000,2.899379e-10,0.78719,4
300.01001,1107.20000,     -1.48375, 54.11707,50.00000,21.00000,2.898235e-10,0.78719,4
300.02100,1110.50000,     -1.48610, 54.04900,50.00000,21.00000,2.896079e-10,0.78719,4
300.01401,1113.80000,     -1.48162, 53.93996,50.00000,21.00000,2.905617e-10,0.78719,4
300.01901,1117.10000,     -1.48571, 53.92631,50.00000,21.00000,2.902317e-10,0.78719,4
300.01599,1120.40000,     -1.48493, 53.81044,50.00000,21.00000,2.903309e-10,0.78719,4
300.00900,1123.70000,     -1.48453, 53.74900,50.00000,21.00000,2.907276e-10,0.78718,4
300.04700,1127.00000,     -1.48498, 53.65361,50.00000,21.00000,2.906285e-10,0.78719,4
300.01700,1130.30000,     -1.48454, 53.56044,50.00000,21.00000,2.917138e-10,0.78717,4
300.01401,1133.60000,     -1.48726, 53.47189,50.00000,21.00000,2.909659e-10,0.78718,4
300.01901,1136.90000,     -1.48668, 53.39699,50.00000,21.00000,2.896709e-10,0.78718,4
300.02600,1140.20000,     -1.48864, 53.30161,50.00000,21.00000,2.906609e-10,0.78720,4
300.00699,1143.50000,     -1.48666, 53.20602,50.00000,21.00000,2.908249e-10,0.78718,4
300.02399,1146.80000,     -1.48825, 53.10382,50.00000,21.00000,2.902316e-10,0.78719,4
300.02100,1150.10000,     -1.48844, 53.04719,50.00000,21.00000,2.903843e-10,0.78719,4
300.00900,1153.40000,     -1.48959, 52.93353,50.00000,21.00000,2.911987e-10,0.78720,4
300.01599,1156.70000,     -1.48921, 52.82450,50.00000,21.00000,2.908249e-10,0.78719,4
300.02600,1160.00000,     -1.49001, 52.70863,50.00000,21.00000,2.912330e-10,0.78719,4
300.01700,1163.30000,     -1.49038, 52.64036,50.00000,21.00000,2.919463e-10,0.78718,4
300.00400,1166.60000,     -1.49016, 52.55422,50.00000,21.00000,2.910748e-10,0.78718,4
300.00800,1169.90000,     -1.48997, 52.44277,50.00000,21.00000,2.907066e-10,0.78719,4
300.02399,1173.20000,     -1.49039, 52.34056,50.00000,22.00000,2.912235e-10,0.78720,4
300.01199,1176.50000,     -1.49076, 52.24980,50.00000,22.00000,2.916717e-10,0.78719,4
300.01700,1179.80000,     -1.49388, 52.14980,50.00000,22.00000,2.910653e-10,0.78719,4
300.01001,1183.10000,     -1.49309, 52.06787,50.00000,22.00000,2.910423e-10,0.78718,4
300.00699,1186.40000,     -1.49289, 51.96807,50.00000,22.00000,2.917632e-10,0.78719,4
300.00299,1189.70000,     -1.49249, 51.92028,50.00000,22.00000,2.902908e-10,0.78720,4
300.00299,1193.00000,     -1.49308, 51.80442,50.00000,22.00000,2.908535e-10,0.78719,4
300.01599,1196.30000,     -1.49349, 51.69538,50.00000,22.00000,2.910004e-10,0.78719,4
300.01300,1199.60000,     -1.49368, 51.62731,50.00000,22.00000,2.901631e-10,0.78719,4
300.02701,1202.90000,     -1.49507, 51.56586,50.00000,22.00000,2.903348e-10,0.78720,4
300.02301,1206.20000,     -1.49701, 51.49096,50.00000,22.00000,2.895031e-10,0.78720,4
300.00400,1209.50000,     -1.49697, 51.42952,50.00000,22.00000,2.904567e-10,0.78719,4
300.01401,1212.80000,     -1.49718, 51.28655,50.00000,22.00000,2.906418e-10,0.78718,4
300.01300,1216.10000,     -1.49816, 51.21386,50.00000,22.00000,2.903213e-10,0.78719,4
300.00900,1219.40000,     -1.49990, 51.15482,50.00000,22.00000,2.898730e-10,0.78719,4
300.01999,1222.70000,     -1.50070, 51.07289,50.00000,22.00000,2.907790e-10,0.78718,4
300.01501,1226.00000,     -1.50011, 50.97068,50.00000,22.00000,2.909051e-10,0.78718,4
300.00800,1229.30000,     -1.50165, 50.90944,50.00000,22.00000,2.905083e-10,0.78718,4
300.01999,1232.60000,     -1.50148, 50.82068,50.00000,22.00000,2.901154e-10,0.78718,4
300.01401,1235.90000,     -1.50283, 50.73675,50.00000,22.00000,2.904243e-10,0.78719,4
300.01401,1239.20000,     -1.50186, 50.69137,50.00000,22.00000,2.907257e-10,0.78718,4
300.01401,1242.50000,     -1.50244, 50.56867,50.00000,22.00000,2.915974e-10,0.78719,4
300.02200,1245.80000,     -1.50557, 50.51406,50.00000,22.00000,2.915534e-10,0.78719,4
300.01901,1249.10000,     -1.50478, 50.40502,50.00000,22.00000,2.908191e-10,0.78718,4
300.01801,1252.40000,     -1.50673, 50.28916,50.00000,22.00000,2.916164e-10,0.78719,4
300.01999,1255.70000,     -1.50732, 50.23474,50.00000,22.00000,2.914066e-10,0.78719,4
300.03101,1257.10000,     -1.50909, 50.10743,50.00000,50.00000,2.919368e-10,0.78720,5
300.23700,1257.26500,     -1.45183, 49.78715,50.00000,50.00000,2.913016e-10,0.78719,5
300.82999,1257.43000,     -1.28727, 48.86707,50.00000,50.00000,2.913589e-10,0.78719,5
301.95700,1257.59500,     -1.01883, 47.68112,50.00000,50.00000,2.919464e-10,0.78719,5
303.64301,1257.76000,     -0.67589, 47.62430,50.00000,50.00000,2.907619e-10,0.78720,5
305.83899,1257.92500,     -0.31062, 48.16506,50.00000,50.00000,2.911872e-10,0.78721,5
308.43799,1258.09000, 3.086398e-02, 48.85341,50.00000,50.00000,2.909661e-10,0.78720,5
311.31299,1258.25500,      0.31524, 49.43273,50.00000,50.00000,2.912674e-10,0.78720,5
314.31799,1258.42000,      0.51557, 49.87108,50.00000,50.00000,2.909545e-10,0.78719,5
317.35901,1258.58500,      0.63693, 50.14598,50.00000,50.00000,2.905426e-10,0.78719,5
320.35199,1258.75000,      0.68875, 50.25743,50.00000,50.00000,2.909050e-10,0.78720,5
323.26501,1258.91500,      0.68744, 50.31867,50.00000,50.00000,2.916794e-10,0.78719,5
326.10800,1259.08000,      0.65913, 50.34598,50.00000,50.00000,2.917919e-10,0.78720,5
328.91000,1259.24500,      0.62213, 50.34598,50.00000,50.00000,2.912197e-10,0.78719,5
331.72198,1259.41000,      0.59945, 50.34598,50.00000,50.00000,2.913418e-10,0.78719,5
334.59100,1259.57500,      0.60020, 50.34598,50.00000,50.00000,2.913264e-10,0.78719,5
337.54800,1259.74000,      0.62752, 50.38695,50.00000,50.00000,2.909737e-10,0.78719,5
340.62799,1259.90500,      0.67991, 50.42771,50.00000,50.00000,2.931003e-10,0.78719,5
343.82599,1260.07000,      0.74905, 50.50281,50.00000,50.00000,2.918644e-10,0.78719,5
347.12799,1260.23500,      0.82918, 50.56406,50.00000,50.00000,2.919121e-10,0.78720,5
350.56601,1260.40000,      0.90685, 50.61867,50.00000,50.00000,2.914009e-10,0.78719,5
354.06299,1260.56500,      0.97320, 50.64578,50.00000,50.00000,2.912464e-10,0.78719,5
357.60400,1260.73000,      1.02683, 50.70040,50.00000,50.00000,2.912808e-10,0.78720,5
361.18500,1260.89500,      1.06526, 50.70040,50.00000,50.00000,2.911854e-10,0.78720,5
364.77600,1261.06000,      1.08231, 50.70040,50.00000,50.00000,2.911243e-10,0.78720,5
368.36600,1261.22500,      1.08530, 50.67309,50.00000,50.00000,2.920208e-10,0.78719,5
371.95001,1261.39000,      1.08532, 50.59137,50.00000,50.00000,2.910214e-10,0.78719,5
375.52499,1261.55500,      1.09324, 50.49137,50.00000,50.00000,2.917307e-10,0.78720,5
379.09100,1261.72000,      1.09089, 50.32771,50.00000,50.00000,2.912960e-10,0.78719,5
382.67200,1261.88500,      1.08701, 50.12791,50.00000,50.00000,2.916890e-10,0.78719,5
386.26300,1262.05000,      1.09439, 49.85301,50.00000,50.00000,2.915325e-10,0.78719,5
389.84201,1262.21500,      1.09351, 49.51908,50.00000,50.00000,2.917976e-10,0.78719,5
393.43500,1262.38000,      1.10601, 49.13976,50.00000,50.00000,2.912197e-10,0.78719,5
397.05600,1262.54500,      1.11447, 48.57390,50.00000,50.00000,2.912426e-10,0.78720,5
400.66000,1262.71000,      1.13204, 48.00602,50.00000,50.00000,2.910176e-10,0.78719,5
404.28500,1262.87500,      1.14668, 47.32450,50.00000,50.00000,2.906761e-10,0.78719,5
407.89401,1263.04000,      1.16230, 46.57711,50.00000,50.00000,2.915592e-10,0.78719,5
411.49200,1263.20500,      1.16973, 45.60703,50.00000,50.00000,2.912388e-10,0.78719,5
415.09000,1263.37000,      1.17021, 44.54839,50.00000,50.00000,2.914962e-10,0.78718,5
418.67300,1263.53500,      1.16996, 43.31024,50.00000,50.00000,2.909718e-10,0.78719,5
422.23300,1263.70000,      1.14754, 41.89056,50.00000,50.00000,2.916374e-10,0.78719,5
425.80301,1263.86500,      1.10016, 40.39337,50.00000,50.00000,2.918416e-10,0.78718,5
429.35199,1264.03000,      1.03179, 38.78494,50.00000,50.00000,2.912292e-10,0.78718,5
432.89001,1264.19500,      0.96850, 37.07430,50.00000,50.00000,2.913094e-10,0.78720,5
436.43100,1264.36000,      0.86347, 35.42510,50.00000,50.00000,2.912044e-10,0.78720,5
439.93900,1264.52500,      0.74804, 33.74839,50.00000,50.00000,2.908134e-10,0.78719,5
443.45801,1264.69000,      0.62002, 32.28092,50.00000,50.00000,2.918930e-10,0.78720,5
446.96100,1264.85500,      0.49029, 30.89739,50.00000,50.00000,2.917632e-10,0.78720,5
450.46500,1265.02000,      0.34607, 29.77510,50.00000,50.00000,2.921084e-10,0.78719,5
453.95499,1265.18500,      0.18573, 28.86426,50.00000,50.00000,2.917481e-10,0.78719,5
457.45499,1265.35000, 2.341466e-02, 28.16667,50.00000,50.00000,2.913265e-10,0.78719,5
460.92801,1265.51500,     -0.14810, 27.65783,50.00000,50.00000,2.918797e-10,0.78719,5
464.40100,1265.68000,     -0.30914, 27.35120,50.00000,50.00000,2.920647e-10,0.78719,5
467.84799,1265.84500,     -0.47019, 27.12631,50.00000,50.00000,2.919465e-10,0.78719,5
471.32101,1266.01000,     -0.61082, 27.06486,50.00000,50.00000,2.920952e-10,0.78719,5
474.75900,1266.17500,     -0.73876, 27.01044,50.00000,50.00000,2.912616e-10,0.78720,5
478.19800,1266.34000,     -0.85015, 27.01044,50.00000,50.00000,2.912598e-10,0.78719,5
481.63000,1266.50500,     -0.94870, 27.01044,50.00000,50.00000,2.915020e-10,0.78719,5
485.05399,1266.67000,     -1.03744, 27.06486,50.00000,50.00000,2.916623e-10,0.78719,5
488.45700,1266.83500,     -1.12468, 27.05803,50.00000,50.00000,2.913494e-10,0.78719,5
491.86801,1267.00000,     -1.20616, 27.06486,50.00000,50.00000,2.915191e-10,0.78720,5
495.27301,1267.16500,     -1.28279, 27.11948,50.00000,50.00000,2.914067e-10,0.78718,5
498.66101,1267.33000,     -1.36733, 27.11948,50.00000,50.00000,2.915402e-10,0.78719,5
502.05399,1267.49500,     -1.44827, 27.14679,50.00000,50.00000,2.918052e-10,0.78719,5
505.44601,1267.66000,     -1.52782, 27.20120,50.00000,50.00000,2.919616e-10,0.78718,5
508.82199,1267.82500,     -1.60747, 27.20120,50.00000,50.00000,2.912273e-10,0.78719,5
512.21100,1267.99000,     -1.68778, 27.25803,50.00000,50.00000,2.921200e-10,0.78720,5
515.57800,1268.15500,     -1.77150, 27.28534,50.00000,50.00000,2.910824e-10,0.78719,5
518.94202,1268.32000,     -1.84810, 27.31245,50.00000,50.00000,2.914658e-10,0.78719,5
522.30499,1268.48500,     -1.92943, 27.36707,50.00000,50.00000,2.911491e-10,0.78719,5
525.65997,1268.65000,     -2.01189, 27.36707,50.00000,50.00000,2.911776e-10,0.78719,5
529.02197,1268.81500,     -2.09995, 27.42169,50.00000,50.00000,2.911091e-10,0.78719,5
532.36298,1268.98000,     -2.17230, 27.42169,50.00000,50.00000,2.919731e-10,0.78720,5
535.72998,1269.14500,     -2.24472, 27.46928,50.00000,50.00000,2.914162e-10,0.78719,5
539.06799,1269.31000,     -2.32552, 27.50341,50.00000,50.00000,2.914429e-10,0.78720,5
542.43402,1269.47500,     -2.40272, 27.53072,50.00000,50.00000,2.920570e-10,0.78719,5
545.78400,1269.64000,     -2.48442, 27.57831,50.00000,50.00000,2.920075e-10,0.78719,5
549.11902,1269.80500,     -2.56906, 27.61245,50.00000,50.00000,2.910385e-10,0.78720,5
552.46100,1269.97000,     -2.65323, 27.61245,50.00000,50.00000,2.914047e-10,0.78720,5
555.80902,1270.13500,     -2.73366, 27.66687,50.00000,50.00000,2.914906e-10,0.78720,5
559.13702,1270.30000,     -2.81511, 27.68052,50.00000,50.00000,2.910214e-10,0.78719,5
562.47302,1270.46500,     -2.89412, 27.69418,50.00000,50.00000,2.909394e-10,0.78719,5
565.81097,1270.63000,     -2.97447, 27.72149,50.00000,50.00000,2.916240e-10,0.78719,5
569.13702,1270.79500,     -3.05282, 27.74880,50.00000,50.00000,2.915573e-10,0.78719,5
572.47601,1270.96000,     -3.13364, 27.77590,50.00000,50.00000,2.917423e-10,0.78720,5
575.80200,1271.12500,     -3.21603, 27.82369,50.00000,50.00000,2.918128e-10,0.78720,5
579.14301,1271.29000,     -3.27478, 27.83052,50.00000,50.00000,2.920226e-10,0.78719,5
582.47101,1271.45500,     -3.37430, 27.87831,50.00000,50.00000,2.915001e-10,0.78719,5
585.79999,1271.62000,     -3.46464, 27.88494,50.00000,50.00000,2.921906e-10,0.78719,5
589.13501,1271.78500,     -3.53727, 27.91225,50.00000,50.00000,2.920418e-10,0.78719,5
592.46002,1271.95000,     -3.62835, 27.93956,50.00000,50.00000,2.918891e-10,0.78719,5
595.78497,1272.11500,     -3.71402, 27.96687,50.00000,50.00000,2.914067e-10,0.78719,5
599.11700,1272.28000,     -3.79481, 27.99398,50.00000,50.00000,2.916298e-10,0.78720,5
602.43903,1272.44500,     -3.87887, 28.04177,50.00000,50.00000,2.926789e-10,0.78720,5
605.75897,1272.61000,     -3.95136, 28.05542,50.00000,50.00000,2.914944e-10,0.78719,5
609.09998,1272.77500,     -4.03525, 28.07590,50.00000,50.00000,2.909908e-10,0.78720,5
612.41498,1272.94000,     -4.11516, 28.13032,50.00000,50.00000,2.912063e-10,0.78719,5
615.73999,1273.10500,     -4.19004, 28.15763,50.00000,50.00000,2.912330e-10,0.78719,5
619.06403,1273.27000,     -4.27111, 28.15763,50.00000,50.00000,2.912998e-10,0.78719,5
622.38501,1273.43500,     -4.35056, 28.21225,50.00000,50.00000,2.912063e-10,0.78719,5
625.70203,1273.60000,     -4.42249, 28.21225,50.00000,50.00000,2.915095e-10,0.78719,5
629.01898,1273.76500,     -4.49830, 28.26667,50.00000,50.00000,2.919273e-10,0.78720,5
632.34003,1273.93000,     -4.57656, 28.29398,50.00000,50.00000,2.919389e-10,0.78720,5
635.66699,1274.09500,     -4.65022, 28.29398,50.00000,50.00000,2.923641e-10,0.78720,5
638.97900,1274.26000,     -4.71763, 28.34839,50.00000,50.00000,2.915707e-10,0.78719,5
642.30200,1274.42500,     -4.77944, 28.39618,50.00000,50.00000,2.913379e-10,0.78719,5
645.62299,1274.59000,     -4.84868, 28.43032,50.00000,50.00000,2.917080e-10,0.78720,5
648.93103,1274.75500,     -4.90648, 28.45743,50.00000,50.00000,2.915211e-10,0.78719,5
652.24597,1274.92000,     -4.96305, 28.49157,50.00000,50.00000,2.912770e-10,0.78720,5
655.57098,1275.08500,     -5.02533, 28.51205,50.00000,50.00000,2.912979e-10,0.78720,5
658.89203,1275.25000,     -5.08330, 28.51205,50.00000,50.00000,2.911338e-10,0.78716,5
662.19897,1275.41500,     -5.14539, 28.52570,50.00000,50.00000,2.914982e-10,0.78720,5
665.52002,1275.58000,     -5.20627, 28.59378,50.00000,50.00000,2.916526e-10,0.78719,5
668.84003,1275.74500,     -5.24815, 28.59378,50.00000,50.00000,2.914084e-10,0.78719,5
672.16199,1275.91000,     -5.32052, 28.60743,50.00000,50.00000,2.908973e-10,0.78720,5
675.46399,1276.07500,     -5.37988, 28.64839,50.00000,50.00000,2.911052e-10,0.78719,5
678.79199,1276.24000,     -5.43683, 28.64839,50.00000,50.00000,2.911892e-10,0.78720,5
682.10699,1276.40500,     -5.49486, 28.68233,50.00000,50.00000,2.915039e-10,0.78719,5
685.43402,1276.57000,     -5.54139, 28.73012,50.00000,50.00000,2.912789e-10,0.78720,5
688.75000,1276.73500,     -5.60047, 28.73012,50.00000,50.00000,2.924194e-10,0.78719,5
692.07397,1276.90000,     -5.67170, 28.75060,50.00000,50.00000,2.912083e-10,0.78719,5
695.39502,1277.06500,     -5.73351, 28.77791,50.00000,50.00000,2.916966e-10,0.78719,5
698.71399,1277.23000,     -5.79714, 28.77791,50.00000,50.00000,2.911701e-10,0.78720,5
702.02802,1277.39500,     -5.86163, 28.80502,50.00000,50.00000,2.910671e-10,0.78719,5
705.34998,1277.56000,     -5.92232, 28.83233,50.00000,50.00000,2.924080e-10,0.78719,5
708.67102,1277.72500,     -6.01086, 28.84598,50.00000,50.00000,2.922554e-10,0.78719,5
711.99402,1277.89000,     -6.07755, 28.87329,50.00000,50.00000,2.926255e-10,0.78719,5
715.32397,1278.05500,     -6.14712, 28.88695,50.00000,50.00000,2.914066e-10,0.78720,5
718.64697,1278.22000,     -6.22080, 28.91406,50.00000,50.00000,2.922401e-10,0.78720,5
721.96698,1278.38500,     -6.30411, 28.96867,50.00000,50.00000,2.916012e-10,0.78720,5
725.28601,1278.55000,     -6.40907, 28.94137,50.00000,50.00000,2.913628e-10,0.78720,5
728.59302,1278.71500,     -6.49380, 28.96867,50.00000,50.00000,2.918758e-10,0.78720,5
731.93701,1278.88000,     -6.58012, 28.99598,50.00000,50.00000,2.913589e-10,0.78718,5
735.26099,1279.04500,     -6.66966, 28.99598,50.00000,50.00000,2.921581e-10,0.78719,5
738.58197,1279.21000,     -6.75245, 29.02309,50.00000,50.00000,2.911244e-10,0.78720,5
741.90503,1279.37500,     -6.83500, 29.05040,50.00000,50.00000,2.914905e-10,0.78721,5
745.21997,1279.54000,     -6.93823, 29.07771,50.00000,50.00000,2.917099e-10,0.78720,5
748.53900,1279.70500,     -7.03937, 29.10502,50.00000,50.00000,2.921753e-10,0.78721,5
751.86603,1279.87000,     -7.12261, 29.13233,50.00000,50.00000,2.919198e-10,0.78719,5
755.19299,1280.03500,     -7.21784, 29.15944,50.00000,50.00000,2.916298e-10,0.78720,5
758.51202,1280.20000,     -7.29957, 29.15944,50.00000,50.00000,2.928600e-10,0.78719,5
761.84601,1280.36500,     -7.38081, 29.18675,50.00000,50.00000,2.925243e-10,0.78720,5
765.16199,1280.53000,     -7.46402, 29.21406,50.00000,50.00000,2.914810e-10,0.78719,5
768.47900,1280.69500,     -7.53829, 29.21406,50.00000,50.00000,2.918681e-10,0.78720,5
771.81000,1280.86000,     -7.62210, 29.25482,50.00000,50.00000,2.914562e-10,0.78719,5
775.12500,1281.02500,     -7.69546, 29.29578,50.00000,50.00000,2.910309e-10,0.78719,5
778.44702,1281.19000,     -7.76149, 29.30261,50.00000,50.00000,2.915077e-10,0.78719,5
781.76099,1281.35500,     -7.82476, 29.32309,50.00000,50.00000,2.917823e-10,0.78719,5
785.06702,1281.52000,     -7.88526, 29.35040,50.00000,50.00000,2.916375e-10,0.78719,5
788.38800,1281.68500,     -7.94482, 29.37068,50.00000,50.00000,            ,0.44955,5
791.70300,1281.85000,     -8.01561, 29.40703,50.00000,50.00000,            ,0.44821,5
794.72498,1282.00000,     -8.06376, 29.40703,50.00000,50.00000,            ,0.44700,5