File: data/TGA/005d-L_M/ExpDat_2025_02_26_PS-F4-isothermal-1K.csv
#EXPORTTYPE:                 ,DATA ALL
#FILE:                       ,2025_02_26_PS-F4-isothermal-1K.ngb-ss5
#FORMAT:                     ,NETZSCH5
#FTYPE:                      ,ASCII
#IDENTITY:                   ,PS-F4
#DECIMAL:                    ,POINT
#SEPARATOR:                  ,COMMA
#MTYPE:                      ,DSC
#INSTRUMENT:                 ,NETZSCH STA 449F5
#PROJECT:                    ,PS
#DATE/TIME:                  ,2/26/2025 5:36:53 PM (UTC-5)
#CORR. FILE:                 ,
#TEMPCAL:                    ,13-11-2024 10:37
#SENSITIVITY:                ,28-06-2023 13:53
#LABORATORY:                 ,Tran/Aspuru
#OPERATOR:                   ,Stanley
#REMARK:                     ,
#SAMPLE:                     ,PS-F4
#SAMPLE MASS /mg:            ,5.24
#MATERIAL:                   ,
#REFERENCE:                  ,
#REFERENCE MASS /mg:         ,0
#TYPE OF CRUCIBLE:           ,Al2O3 85 ‘l, open
#SAMPLE CRUCIBLE MASS /mg:   ,0
#REFERENCE CRUCIBLE MASS /mg:,0
#DSC RANGE /‘V:              ,5000
#TG RANGE /mg:               ,35000
#TAU-R:                      ,---
#CORR. CODE:                 ,000
#EXO:                        ,-1
#RANGE:                      ,30›C....800›C/0.0....20.0K/min
#SEGMENT:                    ,S1-5/5
#SEG. 1:                     ,30›C/10.0(K/min)/100›C
#SEG. 2:                     ,100›C/00:10/100›C
#SEG. 3:                     ,100›C/5.0(K/min)/300›C
#SEG. 4:                     ,300›C/20:00/300›C
#SEG. 5:                     ,300›C/20.0(K/min)/800›C

##Temp./›C,Time/min,DSC/(mW/mg),Mass/%,Gas Flow(purge2)/(ml/min),Gas Flow(protective)/(ml/min),TIC(scan:1)/A,Sensit./(uV/mW),Segment
 28.70400,   0.00000,      0.37641,    100.00000,50.00000,50.00000,            ,0.92331,1
 32.37000,   1.36000,      0.51907,     93.41489,50.00000,50.00000,2.062244e-10,0.92343,1
 39.72500,   2.72000,      1.06117,     94.37347,50.00000,50.00000,2.062912e-10,0.92356,1
 50.15000,   4.08000,      1.61580,     95.40344,50.00000,50.00000,2.068691e-10,0.92374,1
 63.88900,   5.44000,      2.23637,     96.43550,50.00000,50.00000,2.061691e-10,0.92395,1
 79.78300,   6.80000,      2.74184,     97.13073,50.00000,50.00000,2.063827e-10,0.92418,1
 89.07900,   7.58000,      2.79551,     97.15649,50.00000,50.00000,2.056999e-10,0.92434,2
 95.41700,   8.26000,      2.28133,     96.41813,50.00000,50.00000,2.069206e-10,0.92447,2
 99.81300,   8.94000,      1.64130,     95.57405,50.00000,50.00000,2.069988e-10,0.92460,2
103.10300,   9.62000,      1.23000,     95.03416,50.00000,50.00000,2.066784e-10,0.92473,2
105.77900,  10.30000,      0.98950,     94.62176,50.00000,50.00000,2.072010e-10,0.92489,2
107.78000,  10.98000,      0.73201,     94.18359,50.00000,50.00000,2.070293e-10,0.92502,2
109.04800,  11.66000,      0.44889,     93.68702,50.00000,50.00000,2.072658e-10,0.92514,2
109.70300,  12.34000,      0.20373,     93.23359,50.00000,50.00000,2.066803e-10,0.92526,2
109.90400,  13.02000, 1.522094e-02,     92.83416,50.00000,50.00000,2.075042e-10,0.92538,2
109.76400,  13.70000,     -0.12652,     92.48225,50.00000,50.00000,2.079106e-10,0.92550,2
109.36500,  14.38000,     -0.23541,     92.15630,50.00000,50.00000,2.073174e-10,0.92561,2
108.78500,  15.06000,     -0.31778,     91.84752,50.00000,50.00000,2.077446e-10,0.92574,2
108.09100,  15.74000,     -0.37475,     91.58626,50.00000,50.00000,2.074223e-10,0.92584,2
107.29800,  16.42000,     -0.40840,     91.32290,50.00000,50.00000,2.074471e-10,0.92592,2
106.35800,  17.20000,     -0.42412,     91.08969,50.00000,50.00000,2.077217e-10,0.92602,3
106.52700,  18.56000, 9.677078e-02,     91.60782,50.00000,50.00000,2.080555e-10,0.92614,3
109.49800,  19.92000,      0.59655,     92.16698,50.00000,50.00000,2.083702e-10,0.92620,3
114.19700,  21.28000,      1.00495,     92.66584,50.00000,50.00000,2.082653e-10,0.92619,3
120.56100,  22.64000,      1.36402,     93.13206,50.00000,50.00000,2.085152e-10,0.92609,3
127.90500,  24.00000,      1.59169,     93.42366,50.00000,50.00000,2.086791e-10,0.92591,3
135.78400,  25.36000,      1.72868,     93.65019,50.00000,50.00000,2.093373e-10,0.92565,3
143.82600,  26.72000,      1.79056,     93.78206,50.00000,50.00000,2.092437e-10,0.92524,3
151.79601,  28.08000,      1.81068,     93.87920,50.00000,50.00000,2.086163e-10,0.92477,3
159.52400,  29.44000,      1.80015,     93.91794,50.00000,50.00000,2.088623e-10,0.92436,3
167.00900,  30.80000,      1.77819,     93.96985,50.00000,50.00000,2.090530e-10,0.92406,3
174.28200,  32.16000,      1.75476,     94.02805,50.00000,50.00000,2.098312e-10,0.92370,3
181.36099,  33.52000,      1.73342,     94.09294,50.00000,50.00000,2.086678e-10,0.92338,3
188.34801,  34.88000,      1.72322,     94.16412,50.00000,50.00000,2.095642e-10,0.92307,3
195.25301,  36.24000,      1.71999,     94.19008,50.00000,50.00000,2.099457e-10,0.92275,3
202.08000,  37.60000,      1.71896,     94.31317,50.00000,50.00000,2.093029e-10,0.92242,3
208.86900,  38.96000,      1.71785,     94.34542,50.00000,50.00000,2.096347e-10,0.92213,3
215.64600,  40.32000,      1.71243,     94.41889,50.00000,50.00000,2.097283e-10,0.92186,3
222.40300,  41.68000,      1.68914,     94.54847,50.00000,50.00000,2.096519e-10,0.92162,3
229.17300,  43.04000,      1.66636,     94.60019,50.00000,50.00000,2.101460e-10,0.92135,3
235.93600,  44.40000,      1.64680,     94.65859,50.00000,50.00000,2.101784e-10,0.92112,3
242.69099,  45.76000,      1.63102,     94.73626,50.00000,50.00000,2.101497e-10,0.92091,3
249.45300,  47.12000,      1.61194,     94.83989,50.00000,50.00000,2.095489e-10,0.92069,3
256.22800,  48.48000,      1.59439,     94.89179,50.00000,50.00000,2.102757e-10,0.92050,3
263.00000,  49.84000,      1.57429,     94.91107,50.00000,50.00000,2.100659e-10,0.92030,3
269.76999,  51.20000,      1.55352,     94.87882,50.00000,50.00000,2.111550e-10,0.92010,3
276.55499,  52.56000,      1.53388,     94.88531,50.00000,50.00000,2.101021e-10,0.91992,3
283.31900,  53.92000,      1.50824,     94.79676,50.00000,50.00000,2.103806e-10,0.91975,3
290.08899,  55.28000,      1.48434,     94.69313,50.00000,50.00000,2.100982e-10,0.91959,3
296.85101,  56.64000,      1.45961,     94.51164,50.00000,50.00000,2.105999e-10,0.91941,3
302.88199,  59.50000,     -0.24721,     93.96985,50.00000,43.00000,2.104683e-10,0.91912,4
302.55499,  62.90000,     -0.70534,     92.91183,50.00000,43.00000,2.114372e-10,0.91882,4
301.36099,  66.30000,     -0.70582,     92.10229,50.00000,43.00000,2.115936e-10,0.91860,4
300.63699,  69.70000,     -0.65506,     91.36813,50.00000,43.00000,2.107392e-10,0.91845,4
300.29300,  73.10000,     -0.62593,     90.76794,50.00000,43.00000,2.107639e-10,0.91836,4
300.13501,  76.50000,     -0.61379,     90.27137,50.00000,43.00000,2.116356e-10,0.91831,4
300.05200,  79.90000,     -0.61077,     89.70134,50.00000,43.00000,2.128639e-10,0.91831,4
300.03201,  83.30000,     -0.60964,     89.26088,50.00000,43.00000,2.122574e-10,0.91834,4
300.01801,  86.70000,     -0.61204,     88.85725,50.00000,43.00000,2.120610e-10,0.91841,4
300.02100,  90.10000,     -0.61111,     88.47080,50.00000,43.00000,2.115765e-10,0.91849,4
300.01501,  93.50000,     -0.61000,     88.10592,50.00000,43.00000,2.124252e-10,0.91859,4
300.01099,  96.90000,     -0.61018,     87.78206,50.00000,43.00000,2.122078e-10,0.91871,4
300.01801, 100.30000,     -0.61241,     87.44523,50.00000,43.00000,2.124767e-10,0.91885,4
300.02100, 103.70000,     -0.61278,     87.18607,50.00000,43.00000,2.129345e-10,0.91898,4
300.01001, 107.10000,     -0.61554,     86.87080,50.00000,43.00000,2.124500e-10,0.91913,4
300.00699, 110.50000,     -0.61295,     86.60324,50.00000,43.00000,2.122593e-10,0.91927,4
300.01300, 113.90000,     -0.61518,     86.34408,50.00000,43.00000,2.128582e-10,0.91945,4
300.01599, 117.30000,     -0.61610,     86.08492,50.00000,43.00000,2.131463e-10,0.91928,4
300.01401, 120.70000,     -0.61629,     85.82595,50.00000,43.00000,2.130585e-10,0.91880,4
300.01401, 124.10000,     -0.61592,     85.59924,50.00000,43.00000,2.128162e-10,0.91812,4
300.01901, 127.50000,     -0.61740,     85.35954,50.00000,43.00000,2.131901e-10,0.91717,4
300.02301, 130.90000,     -0.61666,     85.10267,50.00000,43.00000,2.131367e-10,0.91595,4
300.00800, 134.30000,     -0.61850,     84.89542,50.00000,43.00000,2.130318e-10,0.91456,4
300.01300, 137.70000,     -0.61647,     84.66870,50.00000,42.00000,2.129650e-10,0.91287,4
300.01300, 141.10000,     -0.61721,     84.43340,50.00000,42.00000,2.135162e-10,0.91099,4
300.01801, 144.50000,     -0.61740,     84.23893,50.00000,42.00000,2.132321e-10,0.90902,4
300.03000, 147.90000,     -0.61593,     84.02309,50.00000,42.00000,2.142716e-10,0.90680,4
300.02499, 151.30000,     -0.61907,     83.81584,50.00000,42.00000,2.135372e-10,0.90447,4
300.01901, 154.70000,     -0.61777,     83.59561,50.00000,42.00000,2.140732e-10,0.90203,4
300.02701, 158.10000,     -0.61944,     83.38187,50.00000,42.00000,2.146950e-10,0.89966,4
300.01401, 161.50000,     -0.61999,     83.17462,50.00000,42.00000,2.144528e-10,0.89710,4
300.01401, 164.90000,     -0.61925,     82.96088,50.00000,42.00000,2.143211e-10,0.89450,4
300.00800, 168.30000,     -0.62054,     82.76011,50.00000,42.00000,2.141152e-10,0.89186,4
300.02802, 171.70000,     -0.61796,     82.55935,50.00000,42.00000,2.150477e-10,0.88931,4
300.02301, 175.10000,     -0.62036,     82.37786,50.00000,42.00000,2.149582e-10,0.88659,4
300.02399, 178.50000,     -0.61444,     82.20095,50.00000,42.00000,2.145863e-10,0.88382,4
300.01901, 181.90000,     -0.61037,     81.98721,50.00000,42.00000,2.156238e-10,0.88101,4
300.02399, 185.30000,     -0.61075,     81.77977,50.00000,42.00000,2.151203e-10,0.87816,4
300.01300, 188.70000,     -0.61222,     81.58550,50.00000,42.00000,2.146835e-10,0.87541,4
300.02301, 192.10000,     -0.61352,     81.39122,50.00000,42.00000,2.158412e-10,0.87246,4
300.01001, 195.50000,     -0.61129,     81.20344,50.00000,42.00000,2.159690e-10,0.86946,4
300.01599, 198.90000,     -0.60907,     81.02195,50.00000,42.00000,2.156735e-10,0.86656,4
300.01999, 202.30000,     -0.61241,     80.80821,50.00000,42.00000,2.161541e-10,0.86346,4
300.03000, 205.70000,     -0.61112,     80.66584,50.00000,42.00000,2.165433e-10,0.86030,4
300.01599, 209.10000,     -0.61351,     80.48874,50.00000,42.00000,2.166061e-10,0.85711,4
300.01599, 212.50000,     -0.61314,     80.28798,50.00000,42.00000,2.159309e-10,0.85402,4
300.01199, 215.90000,     -0.61185,     80.11947,50.00000,42.00000,2.160492e-10,0.85073,4
300.01801, 219.30000,     -0.60982,     79.94466,50.00000,42.00000,2.166501e-10,0.84738,4
300.01099, 222.70000,     -0.61333,     79.77634,50.00000,42.00000,2.168217e-10,0.84398,4
300.01999, 226.10000,     -0.61148,     79.60782,50.00000,42.00000,2.169323e-10,0.84070,4
300.01901, 229.50000,     -0.61167,     79.42653,50.00000,42.00000,2.171020e-10,0.83724,4
300.00601, 232.90000,     -0.61184,     79.25802,50.00000,42.00000,2.169093e-10,0.83372,4
300.01401, 236.30000,     -0.61111,     79.07672,50.00000,42.00000,2.170715e-10,0.83016,4
300.02301, 239.70000,     -0.61130,     78.90840,50.00000,42.00000,2.177467e-10,0.82672,4
300.00800, 243.10000,     -0.61314,     78.76584,50.00000,42.00000,2.182331e-10,0.82308,4
300.01801, 246.50000,     -0.61037,     78.57156,50.00000,42.00000,2.189578e-10,0.81940,4
300.03201, 249.90000,     -0.61168,     78.42252,50.00000,42.00000,2.181339e-10,0.81569,4
300.01700, 253.30000,     -0.61111,     78.25420,50.00000,42.00000,2.180023e-10,0.81197,4
300.01999, 256.70000,     -0.61167,     78.05763,50.00000,42.00000,2.182445e-10,0.80838,4
300.01001, 260.10000,     -0.61092,     77.90229,50.00000,42.00000,2.188129e-10,0.80459,4
300.01099, 263.50000,     -0.61111,     77.73378,50.00000,42.00000,2.189999e-10,0.80079,4
300.01099, 266.90000,     -0.61092,     77.55897,50.00000,42.00000,2.188568e-10,0.79695,4
300.00500, 270.30000,     -0.61092,     77.40134,50.00000,42.00000,2.186985e-10,0.79309,4
300.01001, 273.70000,     -0.61073,     77.23931,50.00000,42.00000,2.198391e-10,0.78921,4
300.01501, 277.10000,     -0.60907,     77.05363,50.00000,42.00000,2.194023e-10,0.78511,4
300.01999, 280.50000,     -0.60982,     76.87233,50.00000,42.00000,2.200394e-10,0.78422,4
300.01801, 283.90000,     -0.60982,     76.70401,50.00000,42.00000,2.191944e-10,0.78478,4
300.01300, 287.30000,     -0.61055,     76.56145,50.00000,42.00000,2.195854e-10,0.78551,4
300.01999, 290.70000,     -0.60963,     76.39943,50.00000,42.00000,2.196064e-10,0.78609,4
300.01199, 294.10000,     -0.61111,     76.21164,50.00000,42.00000,2.195320e-10,0.78650,4
300.02899, 297.50000,     -0.60945,     76.07557,50.00000,42.00000,2.202701e-10,0.78678,4
300.01401, 300.90000,     -0.61333,     75.90725,50.00000,42.00000,2.191124e-10,0.78695,4
300.02100, 304.30000,     -0.61259,     75.77767,50.00000,42.00000,2.198162e-10,0.78704,4
300.02200, 307.70000,     -0.60945,     75.60286,50.00000,42.00000,2.202225e-10,0.78711,4
300.00800, 311.10000,     -0.61221,     75.45382,50.00000,42.00000,2.196503e-10,0.78715,4
300.02200, 314.50000,     -0.61019,     75.29847,50.00000,42.00000,2.209377e-10,0.78716,4
300.00800, 317.90000,     -0.61073,     75.12996,50.00000,42.00000,2.074528e-10,0.78717,4
300.00900, 321.30000,     -0.61055,     74.96164,50.00000,42.00000,2.066078e-10,0.78718,4
300.00000, 324.70000,     -0.60851,     74.81260,50.00000,42.00000,2.068080e-10,0.78718,4
300.01401, 328.10000,     -0.60944,     74.64847,50.00000,42.00000,2.067299e-10,0.78719,4
300.00101, 331.50000,     -0.61054,     74.51260,50.00000,42.00000,2.062817e-10,0.78719,4
300.01901, 334.90000,     -0.61241,     74.37004,50.00000,42.00000,2.064819e-10,0.78719,4
300.03101, 338.30000,     -0.61186,     74.21450,50.00000,42.00000,2.064628e-10,0.78720,4
300.01501, 341.70000,     -0.61296,     74.04408,50.00000,42.00000,2.062607e-10,0.78719,4
300.01300, 345.10000,     -0.61185,     73.90802,50.00000,42.00000,2.065773e-10,0.78720,4
300.01999, 348.50000,     -0.61000,     73.75248,50.00000,42.00000,2.068558e-10,0.78720,4
300.01599, 351.90000,     -0.61129,     73.59714,50.00000,42.00000,2.066956e-10,0.78720,4
300.01401, 355.30000,     -0.61111,     73.45458,50.00000,42.00000,2.057438e-10,0.78719,4
300.01501, 358.70000,     -0.60963,     73.29905,50.00000,42.00000,2.062874e-10,0.78720,4
300.00500, 362.10000,     -0.61240,     73.16527,50.00000,42.00000,2.066269e-10,0.78719,4
300.01901, 365.50000,     -0.61352,     72.99046,50.00000,42.00000,2.068615e-10,0.78719,4
300.02100, 368.90000,     -0.61204,     72.86737,50.00000,42.00000,2.070732e-10,0.78720,4
300.02200, 372.30000,     -0.61259,     72.71183,50.00000,42.00000,2.071247e-10,0.78720,4
300.02399, 375.70000,     -0.61148,     72.58225,50.00000,42.00000,2.074165e-10,0.78719,4
300.00699, 379.10000,     -0.61129,     72.42691,50.00000,42.00000,2.071533e-10,0.78721,4
300.00900, 382.50000,     -0.60944,     72.28435,50.00000,42.00000,2.070236e-10,0.78720,4
300.01599, 385.90000,     -0.61240,     72.14179,50.00000,42.00000,2.073002e-10,0.78719,4
300.01599, 389.30000,     -0.61166,     71.98645,50.00000,42.00000,2.068958e-10,0.78720,4
300.01901, 392.70000,     -0.61074,     71.85038,50.00000,42.00000,2.077369e-10,0.78720,4
300.01700, 396.10000,     -0.61314,     71.69504,50.00000,42.00000,2.075271e-10,0.78719,4
300.01001, 399.50000,     -0.61110,     71.59141,50.00000,42.00000,2.075023e-10,0.78720,4
300.00601, 402.90000,     -0.61073,     71.42939,50.00000,42.00000,2.076015e-10,0.78720,4
300.01300, 406.30000,     -0.61055,     71.24809,50.00000,42.00000,2.078133e-10,0.78720,4
300.01801, 409.70000,     -0.61148,     71.11851,50.00000,42.00000,2.083148e-10,0.78720,4
300.01700, 413.10000,     -0.61037,     70.98244,50.00000,42.00000,2.077694e-10,0.78719,4
300.02399, 416.50000,     -0.60945,     70.83989,50.00000,42.00000,2.078208e-10,0.78720,4
300.02100, 419.90000,     -0.61093,     70.69752,50.00000,42.00000,2.083111e-10,0.78718,4
300.00800, 423.30000,     -0.61258,     70.52252,50.00000,42.00000,2.085304e-10,0.78718,4
300.01199, 426.70000,     -0.61296,     70.39313,50.00000,42.00000,2.087345e-10,0.78717,4
300.01001, 430.10000,     -0.61443,     70.21164,50.00000,42.00000,2.098675e-10,0.78719,4
300.01099, 433.50000,     -0.61203,     70.08855,50.00000,42.00000,2.096558e-10,0.78719,4
300.02200, 436.90000,     -0.61315,     69.95916,50.00000,42.00000,2.084713e-10,0.78719,4
300.01199, 440.30000,     -0.61222,     69.77118,50.00000,42.00000,2.086773e-10,0.78719,4
300.01801, 443.70000,     -0.61222,     69.63092,50.00000,42.00000,2.087078e-10,0.78719,4
300.00900, 447.10000,     -0.61332,     69.51431,50.00000,42.00000,2.090301e-10,0.78720,4
300.01300, 450.50000,     -0.61277,     69.37176,50.00000,42.00000,2.088451e-10,0.78719,4
300.01401, 453.90000,     -0.61518,     69.21641,50.00000,42.00000,2.088756e-10,0.78719,4
300.00800, 457.30000,     -0.61554,     69.10630,50.00000,42.00000,2.094173e-10,0.78719,4
300.01401, 460.70000,     -0.61462,     68.96164,50.00000,42.00000,2.096596e-10,0.78719,4
300.00400, 464.10000,     -0.61240,     68.81908,50.00000,42.00000,2.095127e-10,0.78719,4
300.01199, 467.50000,     -0.61481,     68.68302,50.00000,42.00000,2.097911e-10,0.78718,4
300.01401, 470.90000,     -0.61296,     68.53416,50.00000,42.00000,2.093181e-10,0.78720,4
300.01599, 474.30000,     -0.61277,     68.39160,50.00000,42.00000,2.092590e-10,0.78718,4
300.02600, 477.70000,     -0.61278,     68.26202,50.00000,42.00000,2.093983e-10,0.78718,4
300.01999, 481.10000,     -0.61500,     68.11966,50.00000,42.00000,2.102852e-10,0.78720,4
300.01401, 484.50000,     -0.61444,     67.99656,50.00000,42.00000,2.095833e-10,0.78719,4
300.01901, 487.90000,     -0.61758,     67.84103,50.00000,42.00000,2.097893e-10,0.78719,4
300.01001, 491.30000,     -0.61462,     67.73092,50.00000,42.00000,2.099343e-10,0.78719,4
300.00699, 494.70000,     -0.61517,     67.60134,50.00000,42.00000,2.093086e-10,0.78718,4
300.01700, 498.10000,     -0.61351,     67.46546,50.00000,42.00000,2.094002e-10,0.78719,4
300.01501, 501.50000,     -0.61351,     67.34237,50.00000,42.00000,2.097740e-10,0.78720,4
300.00900, 504.90000,     -0.61369,     67.20420,50.00000,42.00000,2.094670e-10,0.78720,4
300.00900, 508.30000,     -0.61092,     67.05515,50.00000,42.00000,2.102794e-10,0.78719,4
300.02600, 511.70000,     -0.61426,     66.95153,50.00000,42.00000,2.103138e-10,0.78719,4
300.00900, 515.10000,     -0.61462,     66.79618,50.00000,42.00000,2.099266e-10,0.78719,4
300.02200, 518.50000,     -0.61333,     66.67958,50.00000,41.00000,2.100715e-10,0.78718,4
300.01401, 521.90000,     -0.61166,     66.52405,50.00000,41.00000,2.093201e-10,0.78719,4
300.01599, 525.30000,     -0.60981,     66.43340,50.00000,41.00000,2.104454e-10,0.78720,4
300.00699, 528.70000,     -0.61240,     66.27137,50.00000,41.00000,2.109089e-10,0.78719,4
300.01401, 532.10000,     -0.61148,     66.13550,50.00000,41.00000,2.104092e-10,0.78718,4
300.01199, 535.50000,     -0.61000,     65.99294,50.00000,41.00000,2.109203e-10,0.78719,4
300.01599, 538.90000,     -0.61129,     65.86336,50.00000,41.00000,2.105484e-10,0.78720,4
300.01700, 542.30000,     -0.61166,     65.73378,50.00000,41.00000,2.106647e-10,0.78719,4
300.01501, 545.70000,     -0.61166,     65.59141,50.00000,41.00000,2.114888e-10,0.78719,4
300.00400, 549.10000,     -0.61184,     65.41641,50.00000,41.00000,2.105332e-10,0.78719,4
300.01001, 552.50000,     -0.61129,     65.28683,50.00000,41.00000,2.111321e-10,0.78720,4
300.01099, 555.90000,     -0.60981,     65.13798,50.00000,41.00000,2.116756e-10,0.78719,4
300.01300, 559.30000,     -0.61370,     65.03435,50.00000,41.00000,2.113819e-10,0.78720,4
300.01099, 562.70000,     -0.61166,     64.85286,50.00000,41.00000,2.111626e-10,0.78720,4
300.01700, 566.10000,     -0.61092,     64.72996,50.00000,41.00000,2.117958e-10,0.78720,4
300.01999, 569.50000,     -0.61315,     64.57443,50.00000,41.00000,2.115135e-10,0.78719,4
300.01501, 572.90000,     -0.61277,     64.45134,50.00000,42.00000,2.116928e-10,0.78719,4
300.00800, 576.30000,     -0.61351,     64.32176,50.00000,42.00000,2.111035e-10,0.78719,4
300.01999, 579.70000,     -0.61611,     64.17939,50.00000,42.00000,2.122021e-10,0.78720,4
300.00800, 583.10000,     -0.61647,     64.03034,50.00000,42.00000,2.123737e-10,0.78720,4
300.01199, 586.50000,     -0.61666,     63.89427,50.00000,42.00000,2.121964e-10,0.78720,4
300.01801, 589.90000,     -0.61407,     63.77767,50.00000,42.00000,2.127228e-10,0.78718,4
300.01999, 593.30000,     -0.61444,     63.62233,50.00000,42.00000,2.127838e-10,0.78719,4
300.01501, 596.70000,     -0.61388,     63.49924,50.00000,42.00000,2.134743e-10,0.78719,4
300.01901, 600.10000,     -0.61537,     63.35668,50.00000,42.00000,2.125568e-10,0.78718,4
300.01099, 603.50000,     -0.61665,     63.22710,50.00000,42.00000,2.129974e-10,0.78718,4
300.00900, 606.90000,     -0.61480,     63.09122,50.00000,42.00000,2.145481e-10,0.78719,4
300.01300, 610.30000,     -0.61481,     62.94866,50.00000,42.00000,2.130490e-10,0.78719,4
300.02399, 613.70000,     -0.61740,     62.84504,50.00000,42.00000,2.133751e-10,0.78719,4
300.01801, 617.10000,     -0.61573,     62.70248,50.00000,42.00000,2.128811e-10,0.78719,4
300.01599, 620.50000,     -0.61277,     62.57939,50.00000,41.00000,2.137985e-10,0.78720,4
300.01700, 623.90000,     -0.61296,     62.46298,50.00000,41.00000,2.137126e-10,0.78719,4
300.02499, 627.30000,     -0.61334,     62.34637,50.00000,41.00000,2.142124e-10,0.78719,4
300.01401, 630.70000,     -0.61536,     62.24275,50.00000,41.00000,2.143078e-10,0.78719,4
300.01300, 634.10000,     -0.61629,     62.08282,50.00000,41.00000,2.142506e-10,0.78720,4
300.02100, 637.50000,     -0.61611,     61.96622,50.00000,41.00000,2.148990e-10,0.78720,4
300.01599, 640.90000,     -0.61647,     61.84981,50.00000,41.00000,2.143649e-10,0.78719,4
300.01401, 644.30000,     -0.61573,     61.72672,50.00000,41.00000,2.146339e-10,0.78720,4
300.01199, 647.70000,     -0.61314,     61.59065,50.00000,41.00000,2.147617e-10,0.78720,4
300.02301, 651.10000,     -0.61537,     61.45458,50.00000,41.00000,2.142696e-10,0.78718,4
300.03000, 654.50000,     -0.61648,     61.31221,50.00000,41.00000,2.147275e-10,0.78717,4
300.01999, 657.90000,     -0.61352,     61.19561,50.00000,41.00000,2.158108e-10,0.78719,4
300.00900, 661.30000,     -0.61499,     61.05305,50.00000,41.00000,2.154884e-10,0.78719,4
300.00500, 664.70000,     -0.61425,     60.94943,50.00000,41.00000,2.151509e-10,0.78720,4
300.01599, 668.10000,     -0.61333,     60.82634,50.00000,41.00000,2.155266e-10,0.78718,4
299.99899, 671.50000,     -0.61591,     60.70973,50.00000,41.00000,2.153301e-10,0.78718,4
300.01401, 674.90000,     -0.61277,     60.57366,50.00000,41.00000,2.151050e-10,0.78719,4
300.00201, 678.30000,     -0.61480,     60.41832,50.00000,41.00000,2.152691e-10,0.78719,4
300.00900, 681.70000,     -0.61573,     60.28874,50.00000,41.00000,2.158012e-10,0.78717,4
300.02301, 685.10000,     -0.61777,     60.16565,50.00000,41.00000,2.157269e-10,0.78719,4
300.02399, 688.50000,     -0.61611,     60.02958,50.00000,41.00000,2.165203e-10,0.78720,4
300.01199, 691.90000,     -0.61832,     59.90019,50.00000,41.00000,2.159385e-10,0.78720,4
300.01099, 695.30000,     -0.61665,     59.75115,50.00000,41.00000,2.157154e-10,0.78718,4
300.01999, 698.70000,     -0.61999,     59.62156,50.00000,41.00000,2.156105e-10,0.78719,4
300.00699, 702.10000,     -0.61702,     59.48550,50.00000,41.00000,2.150936e-10,0.78720,4
300.04901, 705.50000,     -0.61668,     59.33664,50.00000,41.00000,2.156334e-10,0.78719,4
300.03299, 708.90000,     -0.61741,     59.20706,50.00000,41.00000,2.162609e-10,0.78720,4
300.01801, 712.30000,     -0.61721,     59.08397,50.00000,41.00000,2.158489e-10,0.78721,4
300.01501, 715.70000,     -0.61832,     58.97385,50.00000,42.00000,2.155990e-10,0.78720,4
300.02200, 719.10000,     -0.62147,     58.82481,50.00000,42.00000,2.157230e-10,0.78718,4
300.01700, 722.50000,     -0.62073,     58.69542,50.00000,42.00000,2.155666e-10,0.78719,4
300.01599, 725.90000,     -0.61740,     58.56584,50.00000,41.00000,2.152253e-10,0.78719,4
300.01801, 729.30000,     -0.61703,     58.45573,50.00000,41.00000,2.153816e-10,0.78719,4
300.00900, 732.70000,     -0.61943,     58.31966,50.00000,41.00000,2.158336e-10,0.78719,4
300.01801, 736.10000,     -0.61758,     58.25496,50.00000,41.00000,2.157268e-10,0.78719,4
300.03299, 739.50000,     -0.61852,     58.11889,50.00000,41.00000,2.157898e-10,0.78719,4
300.02301, 742.90000,     -0.61777,     57.99580,50.00000,41.00000,2.163220e-10,0.78720,4
300.02200, 746.30000,     -0.61740,     57.85973,50.00000,41.00000,2.160302e-10,0.78719,4
300.00699, 749.70000,     -0.61647,     57.76908,50.00000,41.00000,2.154922e-10,0.78719,4
300.02200, 753.10000,     -0.61629,     57.62672,50.00000,41.00000,2.161064e-10,0.78719,4
300.00000, 756.50000,     -0.61813,     57.53588,50.00000,41.00000,2.159157e-10,0.78719,4
300.02200, 759.90000,     -0.61444,     57.38053,50.00000,41.00000,2.162495e-10,0.78719,4
300.01099, 763.30000,     -0.61684,     57.27691,50.00000,41.00000,2.163315e-10,0.78719,4
300.01999, 766.70000,     -0.61592,     57.17328,50.00000,41.00000,2.163753e-10,0.78719,4
300.01801, 770.10000,     -0.61647,     57.01775,50.00000,41.00000,2.169685e-10,0.78720,4
300.01599, 773.50000,     -0.61721,     56.90973,50.00000,41.00000,2.173519e-10,0.78720,4
300.02499, 776.90000,     -0.61722,     56.78454,50.00000,41.00000,2.174454e-10,0.78720,4
300.01300, 780.30000,     -0.62035,     56.64218,50.00000,41.00000,2.174073e-10,0.78718,4
300.01099, 783.70000,     -0.61850,     56.50611,50.00000,41.00000,2.175732e-10,0.78718,4
300.01599, 787.10000,     -0.61721,     56.40668,50.00000,41.00000,2.179718e-10,0.78719,4
300.01001, 790.50000,     -0.61758,     56.29027,50.00000,41.00000,2.182732e-10,0.78718,4
300.01999, 793.90000,     -0.61740,     56.14771,50.00000,41.00000,2.182368e-10,0.78718,4
300.01001, 797.30000,     -0.61813,     56.04408,50.00000,41.00000,2.184486e-10,0.78719,4
300.01801, 800.70000,     -0.61851,     55.90802,50.00000,41.00000,2.182617e-10,0.78720,4
300.01999, 804.10000,     -0.61796,     55.75267,50.00000,41.00000,2.185211e-10,0.78719,4
300.01801, 807.50000,     -0.61925,     55.65534,50.00000,41.00000,2.183857e-10,0.78719,4
300.02399, 810.90000,     -0.61907,     55.55821,50.00000,41.00000,2.186928e-10,0.78719,4
300.01801, 814.30000,     -0.61814,     55.41584,50.00000,41.00000,2.176724e-10,0.78718,4
300.00900, 817.70000,     -0.62183,     55.27977,50.00000,41.00000,2.191792e-10,0.78718,4
300.01401, 821.10000,     -0.61869,     55.15668,50.00000,41.00000,2.188702e-10,0.78719,4
300.00699, 824.50000,     -0.61961,     55.03569,50.00000,41.00000,2.192192e-10,0.78719,4
300.01700, 827.90000,     -0.62091,     54.93206,50.00000,41.00000,2.199286e-10,0.78718,4
300.01199, 831.30000,     -0.62035,     54.82634,50.00000,41.00000,2.185154e-10,0.78719,4
300.01099, 834.70000,     -0.62239,     54.66221,50.00000,41.00000,2.192268e-10,0.78720,4
300.01300, 838.10000,     -0.62035,     54.55210,50.00000,41.00000,2.191734e-10,0.78719,4
300.01999, 841.50000,     -0.62036,     54.42252,50.00000,41.00000,2.191562e-10,0.78719,4
300.01300, 844.90000,     -0.62146,     54.29313,50.00000,41.00000,2.189979e-10,0.78719,4
300.01999, 848.30000,     -0.62147,     54.17653,50.00000,41.00000,2.200814e-10,0.78721,4
300.01401, 851.70000,     -0.62202,     54.06641,50.00000,41.00000,2.196827e-10,0.78719,4
300.02200, 855.10000,     -0.62406,     53.95630,50.00000,41.00000,2.195492e-10,0.78719,4
300.01599, 858.50000,     -0.62276,     53.81374,50.00000,41.00000,2.199802e-10,0.78720,4
300.00800, 861.90000,     -0.62442,     53.66908,50.00000,41.00000,2.200985e-10,0.78720,4
300.00900, 865.30000,     -0.62294,     53.59141,50.00000,41.00000,2.201824e-10,0.78720,4
300.01901, 868.70000,     -0.62110,     53.46832,50.00000,41.00000,2.204304e-10,0.78719,4
300.00800, 872.10000,     -0.62220,     53.33874,50.00000,41.00000,2.197513e-10,0.78719,4
300.02600, 875.50000,     -0.62240,     53.24160,50.00000,41.00000,2.196636e-10,0.78719,4
300.02200, 878.90000,     -0.62406,     53.14447,50.00000,41.00000,2.201423e-10,0.78720,4
300.01300, 882.30000,     -0.62294,     53.01927,50.00000,41.00000,2.161827e-10,0.78718,4
300.01001, 885.70000,     -0.62146,     52.89618,50.00000,41.00000,2.157974e-10,0.78720,4
300.02200, 889.10000,     -0.62277,     52.76660,50.00000,41.00000,2.166271e-10,0.78720,4
300.01901, 892.50000,     -0.62369,     52.66947,50.00000,41.00000,2.166386e-10,0.78719,4
300.01401, 895.90000,     -0.62017,     52.54847,50.00000,41.00000,2.169132e-10,0.78719,4
300.00201, 899.30000,     -0.62442,     52.43836,50.00000,41.00000,2.168693e-10,0.78719,4
300.00699, 902.70000,     -0.61943,     52.33473,50.00000,41.00000,2.173080e-10,0.78719,4
300.00400, 906.10000,     -0.62053,     52.20954,50.00000,41.00000,2.177352e-10,0.78719,4
300.01599, 909.50000,     -0.61925,     52.14485,50.00000,41.00000,2.173347e-10,0.78719,4
299.99899, 912.90000,     -0.61794,     52.02824,50.00000,41.00000,2.187900e-10,0.78720,4
300.01700, 916.30000,     -0.61869,     51.88569,50.00000,41.00000,2.177086e-10,0.78719,4
300.00699, 919.70000,     -0.61721,     51.80802,50.00000,41.00000,2.174187e-10,0.78719,4
300.02100, 923.10000,     -0.61703,     51.70439,50.00000,40.00000,2.185021e-10,0.78719,4
300.00800, 926.50000,     -0.61869,     51.56832,50.00000,40.00000,2.185383e-10,0.78719,4
300.01199, 929.90000,     -0.61832,     51.47118,50.00000,40.00000,2.176857e-10,0.78720,4
300.02499, 933.30000,     -0.61648,     51.35458,50.00000,40.00000,2.190457e-10,0.78720,4
300.01199, 936.70000,     -0.61776,     51.21202,50.00000,40.00000,2.188568e-10,0.78720,4
300.02301, 940.10000,     -0.61777,     51.10840,50.00000,40.00000,2.183857e-10,0.78720,4
300.00500, 943.50000,     -0.61776,     50.97252,50.00000,40.00000,2.184448e-10,0.78719,4
300.02100, 946.90000,     -0.62018,     50.85592,50.00000,40.00000,2.177906e-10,0.78720,4
300.00900, 950.30000,     -0.61573,     50.72634,50.00000,40.00000,2.172489e-10,0.78719,4
300.00500, 953.70000,     -0.61850,     50.62481,50.00000,40.00000,2.170792e-10,0.78719,4
300.01999, 957.10000,     -0.61870,     50.51469,50.00000,40.00000,2.167359e-10,0.78719,4
300.01700, 960.50000,     -0.61869,     50.39160,50.00000,40.00000,2.174339e-10,0.78718,4
300.01901, 963.90000,     -0.61463,     50.26870,50.00000,40.00000,2.165966e-10,0.78718,4
300.02600, 967.30000,     -0.61556,     50.17576,50.00000,40.00000,2.168464e-10,0.78719,4
300.00201, 970.70000,     -0.61609,     50.06126,50.00000,40.00000,2.168751e-10,0.78719,4
300.00699, 974.10000,     -0.61388,     49.92538,50.00000,40.00000,2.164555e-10,0.78718,4
300.03000, 977.50000,     -0.61759,     49.78721,50.00000,40.00000,2.170754e-10,0.78719,4
300.02600, 980.90000,     -0.61870,     49.70286,50.00000,40.00000,2.110290e-10,0.78720,4
300.01999, 984.30000,     -0.61777,     49.57767,50.00000,40.00000,2.102222e-10,0.78719,4
300.01501, 987.70000,     -0.61647,     49.46336,50.00000,40.00000,2.096653e-10,0.78719,4
300.01501, 991.10000,     -0.61536,     49.31431,50.00000,40.00000,2.099304e-10,0.78720,4
300.00800, 994.50000,     -0.61850,     49.19561,50.00000,40.00000,2.099018e-10,0.78719,4
300.01001, 997.90000,     -0.61573,     49.06393,50.00000,40.00000,2.104034e-10,0.78719,4
300.01401,1001.30000,     -0.61555,     48.95802,50.00000,40.00000,2.109871e-10,0.78719,4
300.01700,1004.70000,     -0.61592,     48.82634,50.00000,40.00000,2.091313e-10,0.78719,4
300.01700,1008.10000,     -0.61703,     48.66450,50.00000,40.00000,2.102546e-10,0.78720,4
300.01099,1011.50000,     -0.61813,     48.58454,50.00000,40.00000,2.098599e-10,0.78720,4
300.01099,1014.90000,     -0.61702,     48.47004,50.00000,40.00000,2.099628e-10,0.78719,4
300.01401,1018.30000,     -0.61740,     48.36870,50.00000,40.00000,2.093047e-10,0.78718,4
300.00299,1021.70000,     -0.61794,     48.23053,50.00000,40.00000,2.100391e-10,0.78719,4
300.01199,1025.10000,     -0.61887,     48.12462,50.00000,40.00000,2.103958e-10,0.78720,4
300.01199,1028.50000,     -0.61887,     48.01031,50.00000,40.00000,2.099933e-10,0.78718,4
300.01801,1031.90000,     -0.61832,     47.89580,50.00000,40.00000,2.099247e-10,0.78719,4
300.01901,1035.30000,     -0.61980,     47.77920,50.00000,40.00000,2.102337e-10,0.78720,4
300.01501,1038.70000,     -0.61851,     47.65611,50.00000,41.00000,2.107258e-10,0.78718,4
300.01099,1042.10000,     -0.61721,     47.57634,50.00000,41.00000,2.107620e-10,0.78719,4
300.02200,1045.50000,     -0.61888,     47.45115,50.00000,41.00000,2.109871e-10,0.78719,4
300.03201,1048.90000,     -0.61722,     47.35172,50.00000,41.00000,2.108726e-10,0.78718,4
300.02899,1052.30000,     -0.61963,     47.22214,50.00000,40.00000,2.108001e-10,0.78719,4
300.01401,1055.70000,     -0.61795,     47.11202,50.00000,40.00000,2.105503e-10,0.78718,4
300.02802,1059.10000,     -0.61630,     47.00420,50.00000,40.00000,2.106495e-10,0.78719,4
300.01999,1062.50000,     -0.61777,     46.87672,50.00000,40.00000,2.109642e-10,0.78719,4
300.00699,1065.90000,     -0.61702,     46.74504,50.00000,40.00000,2.104511e-10,0.78719,4
300.01199,1069.30000,     -0.61536,     46.67385,50.00000,40.00000,2.103710e-10,0.78719,4
300.02399,1072.70000,     -0.61759,     46.51412,50.00000,40.00000,2.106858e-10,0.78718,4
300.03601,1076.10000,     -0.61612,     46.41260,50.00000,40.00000,2.099858e-10,0.78720,4
300.01599,1079.50000,     -0.61925,     46.30019,50.00000,40.00000,2.108860e-10,0.78720,4
300.01401,1082.90000,     -0.61536,     46.19656,50.00000,40.00000,2.107506e-10,0.78720,4
300.01099,1086.30000,     -0.61665,     46.08645,50.00000,40.00000,2.111454e-10,0.78719,4
300.01599,1089.70000,     -0.61851,     45.95706,50.00000,40.00000,2.108650e-10,0.78720,4
300.01501,1093.10000,     -0.61814,     45.84046,50.00000,40.00000,2.105713e-10,0.78718,4
300.01801,1096.50000,     -0.61906,     45.73034,50.00000,40.00000,2.114029e-10,0.78719,4
300.00299,1099.90000,     -0.61517,     45.61164,50.00000,40.00000,2.109031e-10,0.78719,4
300.03400,1103.30000,     -0.61649,     45.52080,50.00000,40.00000,2.115039e-10,0.78719,4
300.02200,1106.70000,     -0.62073,     45.41718,50.00000,40.00000,2.109585e-10,0.78719,4
300.01700,1110.10000,     -0.61795,     45.26832,50.00000,40.00000,2.117691e-10,0.78719,4
300.01001,1113.50000,     -0.61628,     45.19046,50.00000,40.00000,2.118416e-10,0.78718,4
300.03000,1116.90000,     -0.62148,     45.09771,50.00000,40.00000,2.118244e-10,0.78718,4
300.02100,1120.30000,     -0.61981,     44.92710,50.00000,40.00000,2.113495e-10,0.78719,4
300.02802,1123.70000,     -0.62148,     44.82137,50.00000,40.00000,2.118435e-10,0.78719,4
300.00800,1127.10000,     -0.61702,     44.74580,50.00000,40.00000,2.118645e-10,0.78719,4
300.00699,1130.50000,     -0.62072,     44.59466,50.00000,40.00000,2.125205e-10,0.78720,4
300.01099,1133.90000,     -0.61684,     44.48454,50.00000,40.00000,2.120895e-10,0.78719,4
300.02200,1137.30000,     -0.61703,     44.36794,50.00000,40.00000,2.125053e-10,0.78719,4
300.01300,1140.70000,     -0.61536,     44.24695,50.00000,40.00000,2.127514e-10,0.78718,4
300.00800,1144.10000,     -0.61980,     44.14981,50.00000,40.00000,2.121964e-10,0.78720,4
300.01199,1147.50000,     -0.61795,     44.04618,50.00000,40.00000,2.129325e-10,0.78719,4
300.01999,1150.90000,     -0.61907,     43.93397,50.00000,40.00000,2.133751e-10,0.78719,4
300.01999,1154.30000,     -0.61444,     43.81527,50.00000,41.00000,2.132892e-10,0.78719,4
300.01801,1157.70000,     -0.61647,     43.69218,50.00000,41.00000,2.126102e-10,0.78719,4
300.01300,1161.10000,     -0.61518,     43.58645,50.00000,41.00000,2.118721e-10,0.78719,4
300.01199,1164.50000,     -0.61536,     43.48053,50.00000,41.00000,2.128429e-10,0.78720,4
300.01300,1167.90000,     -0.61573,     43.39847,50.00000,41.00000,2.126732e-10,0.78719,4
300.01801,1171.30000,     -0.61610,     43.26260,50.00000,41.00000,2.135925e-10,0.78719,4
300.01401,1174.70000,     -0.61851,     43.15897,50.00000,41.00000,2.131844e-10,0.78720,4
300.01300,1178.10000,     -0.61647,     43.05095,50.00000,41.00000,2.136364e-10,0.78720,4
300.01401,1181.50000,     -0.61684,     42.93225,50.00000,41.00000,2.139435e-10,0.78720,4
300.02301,1184.90000,     -0.61518,     42.81985,50.00000,41.00000,2.125492e-10,0.78718,4
300.03900,1188.30000,     -0.61501,     42.72271,50.00000,41.00000,2.129001e-10,0.78718,4
300.01199,1191.70000,     -0.61684,     42.60840,50.00000,41.00000,2.136860e-10,0.78720,4
300.01199,1195.10000,     -0.61739,     42.58034,50.00000,41.00000,2.130585e-10,0.78719,4
300.01901,1198.50000,     -0.61758,     42.40973,50.00000,41.00000,2.133846e-10,0.78719,4
300.01501,1201.90000,     -0.61925,     42.31260,50.00000,41.00000,2.131138e-10,0.78720,4
300.01300,1205.30000,     -0.61980,     42.19599,50.00000,41.00000,2.127800e-10,0.78719,4
300.02301,1208.70000,     -0.61722,     42.08588,50.00000,41.00000,2.130718e-10,0.78718,4
300.01099,1212.10000,     -0.61795,     41.97576,50.00000,41.00000,2.133255e-10,0.78719,4
300.02499,1215.50000,     -0.61814,     41.87214,50.00000,41.00000,2.138634e-10,0.78719,4
300.00800,1218.90000,     -0.61924,     41.76851,50.00000,41.00000,2.136726e-10,0.78719,4
300.02100,1222.30000,     -0.61537,     41.66698,50.00000,41.00000,2.133484e-10,0.78720,4
299.99799,1225.70000,     -0.61701,     41.54828,50.00000,41.00000,2.138424e-10,0.78719,4
300.01801,1229.10000,     -0.61684,     41.45324,50.00000,41.00000,2.139148e-10,0.78720,4
300.01099,1232.50000,     -0.61573,     41.33664,50.00000,41.00000,2.136574e-10,0.78719,4
300.01901,1235.90000,     -0.61500,     41.22214,50.00000,41.00000,2.143154e-10,0.78719,4
300.03000,1239.30000,     -0.61722,     41.14237,50.00000,41.00000,2.136421e-10,0.78719,4
300.01199,1242.70000,     -0.61887,     41.03874,50.00000,41.00000,2.138614e-10,0.78719,4
300.01801,1246.10000,     -0.61832,     40.93511,50.00000,41.00000,2.143059e-10,0.78719,4
300.01700,1249.50000,     -0.61962,     40.85095,50.00000,41.00000,2.141456e-10,0.78718,4
300.01099,1252.90000,     -0.62017,     40.71050,50.00000,41.00000,2.142429e-10,0.78719,4
300.01300,1256.30000,     -0.62091,     40.62195,50.00000,41.00000,2.147655e-10,0.78719,4
300.05200,1257.13500,     -0.60059,     40.53130,50.00000,50.00000,2.143574e-10,0.78719,5
300.43500,1257.30500,     -0.33124,     40.38664,50.00000,50.00000,2.147808e-10,0.78719,5
301.40399,1257.47500,      0.30735,     40.30458,50.00000,50.00000,2.143211e-10,0.78718,5
303.01401,1257.64500,      1.26222,     40.39313,50.00000,50.00000,2.142963e-10,0.78718,5
305.24701,1257.81500,      2.39141,     40.64141,50.00000,50.00000,2.140999e-10,0.78719,5
307.92801,1257.98500,      3.52167,     40.95878,50.00000,50.00000,2.144432e-10,0.78719,5
310.91800,1258.15500,      4.50379,     41.23511,50.00000,50.00000,2.140674e-10,0.78718,5
314.01801,1258.32500,      5.24931,     41.39924,50.00000,50.00000,2.144909e-10,0.78720,5
317.12799,1258.49500,      5.72607,     41.58053,50.00000,50.00000,2.145653e-10,0.78719,5
320.14999,1258.66500,      5.96629,     41.69294,50.00000,50.00000,2.144260e-10,0.78719,5
323.09201,1258.83500,      6.03426,     41.74466,50.00000,50.00000,2.147026e-10,0.78719,5
325.95001,1259.00500,      6.00630,     41.79008,50.00000,50.00000,2.139396e-10,0.78719,5
328.76801,1259.17500,      5.95756,     41.82252,50.00000,50.00000,2.144699e-10,0.78719,5
331.61700,1259.34500,      5.94276,     41.87424,50.00000,50.00000,2.147293e-10,0.78718,5
334.54599,1259.51500,      5.99774,     41.89370,50.00000,50.00000,2.149048e-10,0.78719,5
337.57700,1259.68500,      6.13102,     41.97347,50.00000,50.00000,2.141037e-10,0.78718,5
340.74799,1259.85500,      6.33647,     42.02538,50.00000,50.00000,2.145462e-10,0.78718,5
344.06400,1260.02500,      6.58935,     42.07729,50.00000,50.00000,2.143860e-10,0.78719,5
347.49301,1260.19500,      6.86010,     42.12901,50.00000,50.00000,2.149200e-10,0.78720,5
351.01700,1260.36500,      7.11914,     42.15496,50.00000,50.00000,2.142353e-10,0.78719,5
354.60501,1260.53500,      7.34452,     42.15496,50.00000,50.00000,2.148933e-10,0.78719,5
358.22198,1260.70500,      7.52514,     42.22195,50.00000,50.00000,2.154313e-10,0.78719,5
361.86099,1260.87500,      7.66108,     42.13989,50.00000,50.00000,2.146225e-10,0.78718,5
365.52802,1261.04500,      7.75038,     42.04695,50.00000,50.00000,2.140064e-10,0.78719,5
369.16501,1261.21500,      7.81515,     41.85267,50.00000,50.00000,2.151185e-10,0.78719,5
372.80701,1261.38500,      7.85883,     41.64752,50.00000,50.00000,2.142925e-10,0.78719,5
376.45499,1261.55500,      7.89804,     41.43588,50.00000,50.00000,2.149239e-10,0.78719,5
380.11700,1261.72500,      7.94302,     41.10782,50.00000,50.00000,2.154522e-10,0.78719,5
383.76999,1261.89500,      7.99442,     40.71698,50.00000,50.00000,2.152806e-10,0.78719,5
387.44199,1262.06500,      8.05862,     40.23340,50.00000,50.00000,2.150974e-10,0.78719,5
391.13199,1262.23500,      8.13225,     39.62443,50.00000,50.00000,2.147274e-10,0.78719,5
394.83200,1262.40500,      8.22309,     38.85153,50.00000,50.00000,2.152844e-10,0.78719,5
398.52701,1262.57500,      8.32933,     37.89294,50.00000,50.00000,2.140541e-10,0.78720,5
402.21701,1262.74500,      8.45117,     36.73359,50.00000,50.00000,2.147788e-10,0.78719,5
405.91199,1262.91500,      8.59277,     35.21584,50.00000,50.00000,2.147503e-10,0.78720,5
409.60901,1263.08500,      8.75820,     33.41947,50.00000,50.00000,2.141685e-10,0.78719,5
413.28699,1263.25500,      8.93899,     31.21298,50.00000,50.00000,2.144966e-10,0.78719,5
416.96201,1263.42500,      9.13381,     28.65019,50.00000,50.00000,2.147007e-10,0.78720,5
420.62299,1263.59500,      9.34228,     25.60153,50.00000,50.00000,2.149944e-10,0.78720,5
424.27600,1263.76500,      9.54923,     22.23130,50.00000,50.00000,2.147884e-10,0.78719,5
427.90399,1263.93500,      9.74062,     18.45725,50.00000,50.00000,2.146206e-10,0.78719,5
431.53500,1264.10500,      9.87665,     14.48683,50.00000,50.00000,2.144870e-10,0.78716,5
435.14499,1264.27500,      9.92596,     10.48168,50.00000,50.00000,2.148590e-10,0.78719,5
438.74399,1264.44500,      9.85265,      6.84809,50.00000,50.00000,2.148476e-10,0.78719,5
442.35400,1264.61500,      9.65008,      3.69580,50.00000,50.00000,2.149449e-10,0.78719,5
445.94501,1264.78500,      9.33411,      1.27557,50.00000,50.00000,2.149182e-10,0.78719,5
449.53201,1264.95500,      8.93680,     -0.44294,50.00000,50.00000,2.145023e-10,0.78719,5
453.10400,1265.12500,      8.52190,     -1.50095,50.00000,50.00000,2.153054e-10,0.78719,5
456.68799,1265.29500,      8.16505,     -2.20038,50.00000,50.00000,2.153644e-10,0.78716,5
460.25800,1265.46500,      7.88026,     -2.58053,50.00000,50.00000,2.145977e-10,0.78719,5
463.82501,1265.63500,      7.65544,     -2.81355,50.00000,50.00000,2.146052e-10,0.78719,5
467.39999,1265.80500,      7.47847,     -2.98645,50.00000,50.00000,2.146187e-10,0.78720,5
470.94501,1265.97500,      7.32309,     -3.08359,50.00000,50.00000,2.154599e-10,0.78719,5
474.49100,1266.14500,      7.19318,     -3.13531,50.00000,50.00000,2.154712e-10,0.78720,5
478.02399,1266.31500,      7.07567,     -3.18721,50.00000,50.00000,2.149792e-10,0.78719,5
481.53699,1266.48500,      6.96321,     -3.18721,50.00000,50.00000,2.156296e-10,0.78720,5
485.06201,1266.65500,      6.86581,     -3.18721,50.00000,50.00000,2.149333e-10,0.78719,5
488.56100,1266.82500,      6.77296,     -3.16126,50.00000,50.00000,2.148514e-10,0.78720,5
492.07001,1266.99500,      6.69026,     -3.13531,50.00000,50.00000,2.144337e-10,0.78719,5
495.55899,1267.16500,      6.61021,     -3.10935,50.00000,50.00000,2.147350e-10,0.78719,5
499.04901,1267.33500,      6.52968,     -3.05763,50.00000,50.00000,2.145615e-10,0.78720,5
502.53400,1267.50500,      6.44645,     -3.00573,50.00000,50.00000,2.145042e-10,0.78719,5
506.00800,1267.67500,      6.36650,     -2.97347,50.00000,50.00000,2.145385e-10,0.78719,5
509.48099,1267.84500,      6.28535,     -2.92805,50.00000,50.00000,2.149829e-10,0.78719,5
512.94397,1268.01500,      6.20340,     -2.87634,50.00000,50.00000,2.158928e-10,0.78719,5
516.39600,1268.18500,      6.12089,     -2.85038,50.00000,50.00000,2.150574e-10,0.78719,5
519.85797,1268.35500,      6.04366,     -2.80496,50.00000,50.00000,2.143307e-10,0.78719,5
523.31299,1268.52500,      5.96424,     -2.77901,50.00000,50.00000,2.154846e-10,0.78720,5
526.75500,1268.69500,      5.88380,     -2.72080,50.00000,50.00000,2.148743e-10,0.78719,5
530.20300,1268.86500,      5.80672,     -2.69485,50.00000,50.00000,2.144241e-10,0.78720,5
533.64502,1269.03500,      5.73372,     -2.64313,50.00000,50.00000,2.149582e-10,0.78720,5
537.08301,1269.20500,      5.65406,     -2.63664,50.00000,50.00000,2.148705e-10,0.78719,5
540.52399,1269.37500,      5.57327,     -2.58912,50.00000,50.00000,2.145233e-10,0.78720,5
543.96198,1269.54500,      5.49511,     -2.56317,50.00000,50.00000,2.153339e-10,0.78719,5
547.39600,1269.71500,      5.41784,     -2.51145,50.00000,50.00000,2.147674e-10,0.78720,5
550.81799,1269.88500,      5.33426,     -2.48550,50.00000,50.00000,2.147122e-10,0.78719,5
554.25098,1270.05500,      5.25422,     -2.43359,50.00000,50.00000,2.145748e-10,0.78718,5
557.69000,1270.22500,      5.17722,     -2.40782,50.00000,50.00000,2.146435e-10,0.78720,5
561.11200,1270.39500,      5.09177,     -2.37538,50.00000,50.00000,2.146435e-10,0.78719,5
564.53497,1270.56500,      5.00543,     -2.32996,50.00000,50.00000,2.148571e-10,0.78719,5
567.96399,1270.73500,      4.92136,     -2.27595,50.00000,50.00000,2.151470e-10,0.78720,5
571.38599,1270.90500,      4.83822,     -2.25019,50.00000,50.00000,2.145023e-10,0.78720,5
574.81598,1271.07500,      4.76769,     -2.22424,50.00000,50.00000,2.147179e-10,0.78720,5
578.25500,1271.24500,      4.69171,     -2.17233,50.00000,50.00000,2.155075e-10,0.78718,5
581.68500,1271.41500,      4.61356,     -2.14656,50.00000,50.00000,2.153225e-10,0.78719,5
585.11102,1271.58500,      4.52236,     -2.12061,50.00000,50.00000,2.143993e-10,0.78718,5
588.56403,1271.75500,      4.42854,     -2.09466,50.00000,50.00000,2.153854e-10,0.78719,5
591.95203,1271.92500,      4.32063,     -2.04294,50.00000,50.00000,2.147521e-10,0.78718,5
595.36902,1272.09500,      4.22183,     -1.99103,50.00000,50.00000,2.144890e-10,0.78719,5
598.77600,1272.26500,      4.12262,     -1.99103,50.00000,50.00000,2.157478e-10,0.78719,5
602.21002,1272.43500,      4.02588,     -1.93931,50.00000,50.00000,2.143384e-10,0.78718,5
605.60303,1272.60500,      3.92998,     -1.91336,50.00000,50.00000,2.155705e-10,0.78718,5
609.01300,1272.77500,      3.83931,     -1.88740,50.00000,50.00000,2.154636e-10,0.78719,5
612.44098,1272.94500,      3.75695,     -1.83569,50.00000,50.00000,2.149582e-10,0.78719,5
615.84802,1273.11500,      3.66220,     -1.80973,50.00000,50.00000,2.152386e-10,0.78719,5
619.25800,1273.28500,      3.56719,     -1.78378,50.00000,50.00000,2.144757e-10,0.78718,5
622.67902,1273.45500,      3.46919,     -1.73187,50.00000,50.00000,2.149162e-10,0.78719,5
626.09399,1273.62500,      3.37172,     -1.70382,50.00000,50.00000,2.149238e-10,0.78719,5
629.52100,1273.79500,      3.26650,     -1.67805,50.00000,50.00000,2.153264e-10,0.78718,5
632.92200,1273.96500,      3.16340,     -1.65210,50.00000,50.00000,2.148820e-10,0.78719,5
636.32599,1274.13500,      3.05526,     -1.62615,50.00000,50.00000,2.155285e-10,0.78719,5
639.74701,1274.30500,      2.94406,     -1.60019,50.00000,50.00000,2.152691e-10,0.78719,5
643.15997,1274.47500,      2.83365,     -1.55496,50.00000,50.00000,2.152557e-10,0.78719,5
646.56500,1274.64500,      2.72009,     -1.52252,50.00000,50.00000,2.150802e-10,0.78719,5
649.97302,1274.81500,      2.60966,     -1.49656,50.00000,50.00000,2.152996e-10,0.78719,5
653.38300,1274.98500,      2.49724,     -1.47080,50.00000,50.00000,2.149295e-10,0.78718,5
656.78802,1275.15500,      2.38656,     -1.44485,50.00000,50.00000,2.161140e-10,0.78720,5
660.19800,1275.32500,      2.26902,     -1.41889,50.00000,50.00000,2.146644e-10,0.78719,5
663.60602,1275.49500,      2.14714,     -1.39294,50.00000,50.00000,2.152100e-10,0.78719,5
667.02002,1275.66500,      2.02788,     -1.33893,50.00000,50.00000,2.153797e-10,0.78719,5
670.42401,1275.83500,      1.90251,     -1.33893,50.00000,50.00000,2.152863e-10,0.78719,5
673.83600,1276.00500,      1.78182,     -1.31317,50.00000,50.00000,2.149353e-10,0.78720,5
677.24902,1276.17500,      1.66028,     -1.26126,50.00000,50.00000,2.154369e-10,0.78719,5
680.67401,1276.34500,      1.51941,     -1.23531,50.00000,50.00000,2.155952e-10,0.78719,5
684.08197,1276.51500,      1.38316,     -1.20954,50.00000,50.00000,2.153416e-10,0.78720,5
687.50000,1276.68500,      1.25013,     -1.18359,50.00000,50.00000,2.157325e-10,0.78719,5
690.91602,1276.85500,      1.11296,     -1.15763,50.00000,50.00000,2.155494e-10,0.78718,5
694.33002,1277.02500,      0.97070,     -1.15763,50.00000,50.00000,2.156067e-10,0.78720,5
697.75201,1277.19500,      0.82394,     -1.10592,50.00000,50.00000,2.157536e-10,0.78719,5
701.17200,1277.36500,      0.68191,     -1.07996,50.00000,50.00000,2.158718e-10,0.78719,5
704.57098,1277.53500,      0.53204,     -1.05401,50.00000,50.00000,2.159042e-10,0.78718,5
707.98999,1277.70500,      0.38514,     -1.02805,50.00000,50.00000,2.151527e-10,0.78719,5
711.41199,1277.87500,      0.23852,     -1.02805,50.00000,50.00000,2.158547e-10,0.78719,5
714.82800,1278.04500, 9.006668e-02,     -0.97634,50.00000,50.00000,2.150554e-10,0.78719,5
718.25299,1278.21500,-7.057471e-02,     -0.93740,50.00000,50.00000,2.152557e-10,0.78719,5
721.66400,1278.38500,     -0.21116,     -0.92233,50.00000,50.00000,2.159748e-10,0.78719,5
725.09601,1278.55500,     -0.37129,     -0.89637,50.00000,50.00000,2.155227e-10,0.78719,5
728.51202,1278.72500,     -0.53916,     -0.87691,50.00000,50.00000,2.162342e-10,0.78719,5
731.92798,1278.89500,     -0.71852,     -0.85763,50.00000,50.00000,2.153130e-10,0.78719,5
735.33301,1279.06500,     -0.89650,     -0.84466,50.00000,50.00000,2.158051e-10,0.78719,5
738.75000,1279.23500,     -1.06286,     -0.79275,50.00000,50.00000,2.160931e-10,0.78720,5
742.17102,1279.40500,     -1.22153,     -0.74752,50.00000,50.00000,2.153243e-10,0.78719,5
745.58899,1279.57500,     -1.38676,     -0.71508,50.00000,50.00000,2.158107e-10,0.78719,5
749.01801,1279.74500,     -1.55831,     -0.68912,50.00000,50.00000,2.161274e-10,0.78720,5
752.43201,1279.91500,     -1.72962,     -0.63740,50.00000,50.00000,2.159595e-10,0.78719,5
755.85498,1280.08500,     -1.90196,     -0.63740,50.00000,50.00000,2.165584e-10,0.78721,5
759.27899,1280.25500,     -2.07597,     -0.61145,50.00000,50.00000,2.160931e-10,0.78721,5
762.69598,1280.42500,     -2.25038,     -0.50992,50.00000,50.00000,2.159996e-10,0.78720,5
766.09302,1280.59500,     -2.42419,     -0.50553,50.00000,50.00000,2.154541e-10,0.78719,5
769.49902,1280.76500,     -2.59938,     -0.50553,50.00000,50.00000,2.159309e-10,0.78720,5
772.90900,1280.93500,     -2.76380,     -0.45382,50.00000,50.00000,2.161026e-10,0.78721,5
776.33002,1281.10500,     -2.92442,     -0.42366,50.00000,50.00000,2.156258e-10,0.78720,5
779.75098,1281.27500,     -3.09662,     -0.41927,50.00000,50.00000,2.156067e-10,0.78721,5
783.15997,1281.44500,     -3.25304,     -0.39332,50.00000,50.00000,2.157249e-10,0.78719,5
786.56897,1281.61500,     -3.41688,     -0.36737,50.00000,50.00000,2.157059e-10,0.78720,5
789.97998,1281.78500,     -3.57133,     -0.34160,50.00000,50.00000,            ,0.44891,5
793.39899,1281.95500,     -3.72218,     -0.31565,50.00000,50.00000,            ,0.44753,5
794.30103,1282.00000,     -3.76297,     -0.28969,50.00000,50.00000,            ,0.44717,5