File: data/TGA/005d-L_M/ExpDat_2025_03_14_SL_005D_L1_isothermal.csv
#EXPORTTYPE:                 ,DATA ALL
#FILE:                       ,2025_03_14_SL_005D_L1_isothermal.ngb-ss5
#FORMAT:                     ,NETZSCH5
#FTYPE:                      ,ASCII
#IDENTITY:                   ,2025_03_14_SL_005D_L1
#DECIMAL:                    ,POINT
#SEPARATOR:                  ,COMMA
#MTYPE:                      ,DSC
#INSTRUMENT:                 ,NETZSCH STA 449F5
#PROJECT:                    ,PS
#DATE/TIME:                  ,3/14/2025 2:00:32 PM (UTC-4)
#CORR. FILE:                 ,
#TEMPCAL:                    ,13-11-2024 10:37
#SENSITIVITY:                ,28-06-2023 13:53
#LABORATORY:                 ,Tran/Aspuru
#OPERATOR:                   ,Stanley
#REMARK:                     ,2025_03_14_SL_005D_L1_isothermal
#SAMPLE:                     ,2025_03_14_SL_005D_L1
#SAMPLE MASS /mg:            ,5.01
#MATERIAL:                   ,Polystyrene
#REFERENCE:                  ,
#REFERENCE MASS /mg:         ,0
#TYPE OF CRUCIBLE:           ,Al2O3 85 ‘l, open
#SAMPLE CRUCIBLE MASS /mg:   ,0
#REFERENCE CRUCIBLE MASS /mg:,0
#DSC RANGE /‘V:              ,5000
#TG RANGE /mg:               ,35000
#TAU-R:                      ,---
#CORR. CODE:                 ,000
#EXO:                        ,-1
#RANGE:                      ,30›C....800›C/0.0....20.0K/min
#SEGMENT:                    ,S1-5/5
#SEG. 1:                     ,30›C/10.0(K/min)/100›C
#SEG. 2:                     ,100›C/00:10/100›C
#SEG. 3:                     ,100›C/5.0(K/min)/300›C
#SEG. 4:                     ,300›C/20:00/300›C
#SEG. 5:                     ,300›C/20.0(K/min)/800›C

##Temp./›C,Time/min,DSC/(mW/mg),Mass/%,Gas Flow(purge2)/(ml/min),Gas Flow(protective)/(ml/min),TIC(scan:1)/A,Sensit./(uV/mW),Segment
 32.49700,   0.00000,-9.262295e-02,100.00000,50.00000,52.00000,            ,0.92400,1
 34.56200,   1.32000,-8.122166e-02,100.61417,50.00000,52.00000,2.294255e-10,0.92404,1
 40.34900,   2.64000,-5.827161e-02,101.85828,50.00000,52.00000,2.296829e-10,0.92409,1
 49.27700,   3.96000,-8.058927e-03,103.16128,50.00000,52.00000,2.301940e-10,0.92418,1
 61.62200,   5.28000, 6.955035e-02,104.37405,50.00000,52.00000,2.297916e-10,0.92431,1
 76.48500,   6.60000,      0.15159,105.13493,50.00000,52.00000,2.297554e-10,0.92447,1
 86.87000,   7.46000,      0.18611,105.22076,50.00000,52.00000,2.297954e-10,0.92459,2
 93.69300,   8.12000,      0.13735,104.45529,50.00000,52.00000,2.299766e-10,0.92471,2
 98.71700,   8.78000, 7.338640e-02,103.35549,50.00000,52.00000,2.300053e-10,0.92478,2
102.37900,   9.44000, 2.134293e-02,102.68723,50.00000,52.00000,2.299461e-10,0.92491,2
105.26600,  10.10000,-1.208795e-02,102.17904,50.00000,52.00000,2.298069e-10,0.92502,2
107.56000,  10.76000,-4.076350e-02,101.65289,50.00000,52.00000,2.297478e-10,0.92512,2
109.16400,  11.42000,-6.996346e-02,101.09741,50.00000,52.00000,2.298107e-10,0.92523,2
110.11300,  12.08000,-9.535897e-02,100.62096,50.00000,52.00000,2.294350e-10,0.92533,2
110.53800,  12.74000,     -0.11362,100.17385,50.00000,52.00000,2.294808e-10,0.92543,2
110.55300,  13.40000,     -0.12689, 99.76287,50.00000,52.00000,2.298069e-10,0.92553,2
110.30000,  14.06000,     -0.13467, 99.52794,50.00000,52.00000,2.300148e-10,0.92563,2
109.80600,  14.72000,     -0.13979, 99.08084,50.00000,52.00000,2.298775e-10,0.92572,2
109.14200,  15.38000,     -0.14241, 98.75349,50.00000,52.00000,2.295590e-10,0.92581,2
108.36500,  16.04000,     -0.14321, 98.48922,50.00000,52.00000,2.297840e-10,0.92590,2
107.51600,  16.70000,     -0.14201, 98.29960,50.00000,52.00000,2.294502e-10,0.92597,2
106.38900,  17.72000,     -0.12821, 98.15050,50.00000,52.00000,2.296658e-10,0.92607,3
107.29800,  19.04000,-6.611097e-02, 98.93852,50.00000,52.00000,2.294007e-10,0.92616,3
110.44000,  20.36000,-2.471309e-02, 99.50998,50.00000,52.00000,2.303581e-10,0.92620,3
115.36900,  21.68000, 2.841056e-02,100.09242,50.00000,52.00000,2.298260e-10,0.92618,3
121.78600,  23.00000, 7.927796e-02,100.58922,50.00000,52.00000,2.306004e-10,0.92608,3
129.10800,  24.32000,      0.12246,100.88743,50.00000,53.00000,2.302188e-10,0.92590,3
136.89999,  25.64000,      0.15577,101.11098,50.00000,53.00000,2.295704e-10,0.92564,3
144.83400,  26.96000,      0.17323,101.22156,50.00000,53.00000,2.302799e-10,0.92528,3
152.64101,  28.28000,      0.17804,101.31637,50.00000,53.00000,2.292538e-10,0.92483,3
160.19901,  29.60000,      0.16967,101.36826,50.00000,53.00000,2.302399e-10,0.92446,3
167.52100,  30.92000,      0.15579,101.39102,50.00000,53.00000,2.302075e-10,0.92412,3
174.59399,  32.24000,      0.13493,101.39102,50.00000,53.00000,2.298546e-10,0.92381,3
181.47301,  33.56000,      0.11612,101.43832,50.00000,53.00000,2.302456e-10,0.92350,3
188.25200,  34.88000, 8.657774e-02,101.45409,50.00000,53.00000,2.313614e-10,0.92318,3
194.94099,  36.20000, 4.786515e-02,101.43393,50.00000,53.00000,2.300338e-10,0.92286,3
201.57201,  37.52000, 1.434903e-02,101.46766,50.00000,53.00000,2.305889e-10,0.92255,3
208.16499,  38.84000,-1.724371e-02,101.48124,50.00000,53.00000,2.299652e-10,0.92225,3
214.71800,  40.16000,-4.760173e-02,101.48124,50.00000,53.00000,2.304001e-10,0.92197,3
221.28600,  41.48000,-8.134675e-02,101.53553,50.00000,53.00000,2.303276e-10,0.92169,3
227.85001,  42.80000,     -0.11246,101.56248,50.00000,53.00000,2.301331e-10,0.92143,3
234.38800,  44.12000,     -0.14668,101.61677,50.00000,53.00000,2.307815e-10,0.92119,3
240.95300,  45.44000,     -0.18118,101.65070,50.00000,53.00000,2.311191e-10,0.92096,3
247.50800,  46.76000,     -0.21687,101.63713,50.00000,53.00000,2.307281e-10,0.92074,3
254.07600,  48.08000,     -0.25657,101.65749,50.00000,53.00000,2.310581e-10,0.92053,3
260.65100,  49.40000,     -0.29869,101.67764,50.00000,53.00000,2.314777e-10,0.92032,3
267.21301,  50.72000,     -0.34311,101.67764,50.00000,53.00000,2.309952e-10,0.92012,3
273.80899,  52.04000,     -0.38972,101.67764,50.00000,53.00000,2.313308e-10,0.91994,3
280.37201,  53.36000,     -0.43759,101.67086,50.00000,53.00000,2.313175e-10,0.91976,3
286.94901,  54.68000,     -0.48527,101.61457,50.00000,53.00000,2.307491e-10,0.91958,3
293.51901,  56.00000,     -0.53812,101.56028,50.00000,53.00000,2.313881e-10,0.91942,3
301.56400,  57.80000,     -0.79674,101.13353,50.00000,53.00000,2.309723e-10,0.91920,4
303.32199,  61.10000,     -1.34784, 99.98403,50.00000,53.00000,2.315292e-10,0.91885,4
302.08701,  64.40000,     -1.40016, 99.19601,50.00000,53.00000,2.314721e-10,0.91857,4
301.04401,  67.70000,     -1.38235, 98.54571,50.00000,54.00000,2.323646e-10,0.91836,4
300.46799,  71.00000,     -1.36437, 97.97884,50.00000,54.00000,2.325553e-10,0.91822,4
300.20700,  74.30000,     -1.35466, 97.45489,50.00000,54.00000,2.323094e-10,0.91814,4
300.08600,  77.60000,     -1.34750, 96.96727,50.00000,54.00000,2.322693e-10,0.91810,4
300.03699,  80.90000,     -1.34220, 96.58563,50.00000,54.00000,2.328567e-10,0.91811,4
300.03799,  84.20000,     -1.33620, 96.17006,50.00000,54.00000,2.331581e-10,0.91814,4
300.02600,  87.50000,     -1.33232, 95.81776,50.00000,55.00000,2.322540e-10,0.91821,4
300.01199,  90.80000,     -1.32552, 95.47904,50.00000,55.00000,2.333432e-10,0.91830,4
300.01700,  94.10000,     -1.31992, 95.12675,50.00000,55.00000,2.340603e-10,0.91841,4
300.00000,  97.40000,     -1.31525, 94.83333,50.00000,55.00000,2.336711e-10,0.91854,4
300.01199, 100.70000,     -1.32843, 94.51477,50.00000,55.00000,2.340431e-10,0.91868,4
300.01599, 104.00000,     -1.32379, 94.27764,50.00000,55.00000,2.346516e-10,0.91882,4
300.01599, 107.30000,     -1.27581, 93.94351,50.00000,55.00000,2.343139e-10,0.91897,4
300.00101, 110.60000,     -1.26921, 93.66128,50.00000,55.00000,2.343273e-10,0.91911,4
300.01199, 113.90000,     -1.26343, 93.38343,50.00000,55.00000,2.341099e-10,0.91935,4
300.02399, 117.20000,     -1.25706, 93.11257,50.00000,55.00000,2.348385e-10,0.91926,4
300.02200, 120.50000,     -1.25183, 92.90479,50.00000,55.00000,2.348575e-10,0.91887,4
300.01901, 123.80000,     -1.24661, 92.63613,50.00000,55.00000,2.354660e-10,0.91829,4
300.00500, 127.10000,     -1.24330, 92.41697,50.00000,55.00000,2.343540e-10,0.91747,4
300.00500, 130.40000,     -1.23846, 92.11896,50.00000,55.00000,2.350349e-10,0.91634,4
300.01700, 133.70000,     -1.23461, 91.89541,50.00000,55.00000,2.350998e-10,0.91501,4
300.00400, 137.00000,     -1.22840, 91.61756,50.00000,55.00000,2.352715e-10,0.91346,4
300.00900, 140.30000,     -1.22686, 91.40080,50.00000,55.00000,2.357578e-10,0.91170,4
300.01501, 143.60000,     -1.22261, 91.21118,50.00000,55.00000,2.355213e-10,0.90977,4
300.02399, 146.90000,     -1.21721, 90.96048,50.00000,55.00000,2.350730e-10,0.90768,4
300.01801, 150.20000,     -1.21411, 90.73693,50.00000,55.00000,2.353192e-10,0.90548,4
300.02499, 153.50000,     -1.21121, 90.52016,50.00000,55.00000,2.355919e-10,0.90316,4
300.01501, 156.80000,     -1.20926, 90.32375,50.00000,55.00000,2.363928e-10,0.90078,4
300.01901, 160.10000,     -1.20385, 90.05269,50.00000,55.00000,2.354279e-10,0.89834,4
300.01501, 163.40000,     -1.20133, 89.84271,50.00000,55.00000,2.353191e-10,0.89573,4
300.01599, 166.70000,     -1.19979, 89.65309,50.00000,55.00000,2.364712e-10,0.89320,4
300.00900, 170.00000,     -1.19494, 89.41357,50.00000,55.00000,2.362423e-10,0.89066,4
300.01001, 173.30000,     -1.19281, 89.22176,50.00000,55.00000,2.356758e-10,0.88808,4
300.02200, 176.60000,     -1.18858, 89.00719,50.00000,55.00000,2.358952e-10,0.88547,4
300.01501, 179.90000,     -1.18857, 88.79042,50.00000,55.00000,2.370091e-10,0.88283,4
300.02100, 183.20000,     -1.18606, 88.60080,50.00000,55.00000,2.371025e-10,0.88013,4
300.00299, 186.50000,     -1.18352, 88.41557,50.00000,55.00000,2.366409e-10,0.87727,4
300.01501, 189.80000,     -1.17986, 88.16707,50.00000,55.00000,2.369557e-10,0.87451,4
300.02499, 193.10000,     -1.17949, 87.93673,50.00000,55.00000,2.365245e-10,0.87168,4
300.02802, 196.40000,     -1.17698, 87.71996,50.00000,55.00000,2.369328e-10,0.86881,4
300.01501, 199.70000,     -1.17657, 87.50319,50.00000,55.00000,2.367611e-10,0.86591,4
300.02301, 203.00000,     -1.17349, 87.29321,50.00000,55.00000,2.374135e-10,0.86295,4
300.02301, 206.30000,     -1.17329, 87.06287,50.00000,55.00000,2.368794e-10,0.85996,4
300.02200, 209.60000,     -1.17039, 86.88683,50.00000,55.00000,2.366658e-10,0.85691,4
300.01700, 212.90000,     -1.16980, 86.66327,50.00000,55.00000,2.373390e-10,0.85365,4
300.02100, 216.20000,     -1.16691, 86.44651,50.00000,55.00000,2.376861e-10,0.85052,4
300.01199, 219.50000,     -1.16535, 86.22974,50.00000,55.00000,2.374534e-10,0.84732,4
300.01801, 222.80000,     -1.16419, 86.05130,50.00000,55.00000,2.377376e-10,0.84410,4
300.01001, 226.10000,     -1.16322, 85.81856,50.00000,55.00000,2.372056e-10,0.84084,4
300.00601, 229.40000,     -1.16031, 85.63573,50.00000,55.00000,2.375946e-10,0.83753,4
299.99200, 232.70000,     -1.15797, 85.43034,50.00000,55.00000,2.371407e-10,0.83418,4
299.99899, 236.00000,     -1.15740, 85.23373,50.00000,55.00000,2.372437e-10,0.83079,4
300.00900, 239.30000,     -1.15296, 85.01936,50.00000,55.00000,2.376270e-10,0.82721,4
299.99600, 242.60000,     -1.15140, 84.82275,50.00000,55.00000,2.383957e-10,0.82375,4
300.01801, 245.90000,     -1.15027, 84.63094,50.00000,55.00000,2.383804e-10,0.82025,4
299.99899, 249.20000,     -1.14792, 84.44790,50.00000,55.00000,2.384968e-10,0.81673,4
300.01801, 252.50000,     -1.14504, 84.25609,50.00000,55.00000,2.381287e-10,0.81318,4
300.01001, 255.80000,     -1.14271, 84.03932,50.00000,55.00000,2.381305e-10,0.80960,4
300.01099, 259.10000,     -1.14039, 83.84950,50.00000,55.00000,2.390957e-10,0.80582,4
300.00500, 262.40000,     -1.13883, 83.63273,50.00000,55.00000,2.398262e-10,0.80219,4
300.00900, 265.70000,     -1.13536, 83.44311,50.00000,55.00000,2.393627e-10,0.79856,4
300.01700, 269.00000,     -1.13498, 83.24431,50.00000,55.00000,2.391013e-10,0.79488,4
300.01801, 272.30000,     -1.13266, 83.05469,50.00000,55.00000,2.401503e-10,0.79119,4
300.00800, 275.60000,     -1.13168, 82.85828,50.00000,55.00000,2.396774e-10,0.78623,4
300.00900, 278.90000,     -1.12917, 82.66846,50.00000,55.00000,2.401561e-10,0.78425,4
300.01501, 282.20000,     -1.13150, 82.44950,50.00000,55.00000,2.400265e-10,0.78428,4
300.00500, 285.50000,     -1.12723, 82.28004,50.00000,55.00000,2.401409e-10,0.78499,4
300.01901, 288.80000,     -1.12531, 82.05649,50.00000,54.00000,2.409707e-10,0.78570,4
300.02301, 292.10000,     -1.12454, 81.87365,50.00000,55.00000,2.406807e-10,0.78623,4
300.02100, 295.40000,     -1.12357, 81.68842,50.00000,54.00000,2.404327e-10,0.78660,4
300.00800, 298.70000,     -1.12162, 81.50559,50.00000,55.00000,2.405567e-10,0.78684,4
300.01901, 302.00000,     -1.11757, 81.30240,50.00000,54.00000,2.408866e-10,0.78699,4
300.01501, 305.30000,     -1.11505, 81.11257,50.00000,54.00000,2.413902e-10,0.78707,4
300.00201, 308.60000,     -1.11039, 80.95010,50.00000,54.00000,2.421589e-10,0.78712,4
300.03299, 311.90000,     -1.10695, 80.76267,50.00000,54.00000,2.415581e-10,0.78716,4
300.02301, 315.20000,     -1.10655, 80.55269,50.00000,54.00000,2.418099e-10,0.78718,4
300.02701, 318.50000,     -1.10095, 80.38543,50.00000,54.00000,2.420654e-10,0.78718,4
300.01801, 321.80000,     -1.10074, 80.21617,50.00000,54.00000,2.422008e-10,0.78718,4
300.02899, 325.10000,     -1.09708, 80.02655,50.00000,54.00000,2.420902e-10,0.78718,4
300.02200, 328.40000,     -1.09417, 79.81417,50.00000,54.00000,2.424679e-10,0.78720,4
300.01199, 331.70000,     -1.09145, 79.66068,50.00000,54.00000,2.429009e-10,0.78720,4
300.01501, 335.00000,     -1.08991, 79.45968,50.00000,54.00000,2.418232e-10,0.78719,4
300.01001, 338.30000,     -1.09377, 79.26327,50.00000,54.00000,2.429773e-10,0.78720,4
300.02499, 341.60000,     -1.09533, 79.07345,50.00000,54.00000,2.423038e-10,0.78721,4
300.00900, 344.90000,     -1.09067, 78.92455,50.00000,54.00000,2.431678e-10,0.78720,4
300.02301, 348.20000,     -1.08953, 78.73473,50.00000,54.00000,2.421283e-10,0.78718,4
300.01999, 351.50000,     -1.08566, 78.55190,50.00000,54.00000,2.425289e-10,0.78719,4
300.01901, 354.80000,     -1.08372, 78.36906,50.00000,54.00000,2.430401e-10,0.78719,4
300.01001, 358.10000,     -1.08119, 78.21996,50.00000,54.00000,2.433834e-10,0.78719,4
300.02100, 361.40000,     -1.08411, 78.02355,50.00000,54.00000,2.431507e-10,0.78719,4
300.01501, 364.70000,     -1.07946, 77.83373,50.00000,54.00000,2.438336e-10,0.78719,4
300.03201, 368.00000,     -1.07793, 77.66228,50.00000,54.00000,2.430687e-10,0.78720,4
300.02701, 371.30000,     -1.07367, 77.45888,50.00000,54.00000,2.438030e-10,0.78719,4
300.01401, 374.60000,     -1.07230, 77.28962,50.00000,54.00000,2.437878e-10,0.78718,4
300.00400, 377.90000,     -1.07113, 77.12016,50.00000,54.00000,2.439575e-10,0.78718,4
300.00900, 381.20000,     -1.06842, 76.95529,50.00000,54.00000,2.440700e-10,0.78719,4
300.01300, 384.50000,     -1.07694, 76.76347,50.00000,54.00000,2.437096e-10,0.78720,4
300.00500, 387.80000,     -1.07306, 76.59401,50.00000,54.00000,2.434978e-10,0.78719,4
300.02100, 391.10000,     -1.06941, 76.41118,50.00000,54.00000,2.443161e-10,0.78721,4
300.01300, 394.40000,     -1.06804, 76.22834,50.00000,54.00000,2.435760e-10,0.78721,4
300.02899, 397.70000,     -1.06458, 76.04531,50.00000,54.00000,2.443657e-10,0.78719,4
300.01999, 401.00000,     -1.06476, 75.88962,50.00000,54.00000,2.436275e-10,0.78719,4
300.01401, 404.30000,     -1.06437, 75.72016,50.00000,53.00000,2.441673e-10,0.78720,4
300.01801, 407.60000,     -1.06244, 75.53733,50.00000,53.00000,2.438221e-10,0.78719,4
300.02200, 410.90000,     -1.06148, 75.36327,50.00000,53.00000,2.451304e-10,0.78719,4
300.01801, 414.20000,     -1.05992, 75.20758,50.00000,53.00000,2.442970e-10,0.78720,4
300.01599, 417.50000,     -1.06205, 75.02455,50.00000,53.00000,2.442131e-10,0.78720,4
300.02301, 420.80000,     -1.05780, 74.81916,50.00000,53.00000,2.445202e-10,0.78718,4
300.01901, 424.10000,     -1.05760, 74.67685,50.00000,53.00000,2.445812e-10,0.78719,4
300.03101, 427.40000,     -1.05452, 74.48503,50.00000,53.00000,2.446289e-10,0.78719,4
300.00699, 430.70000,     -1.05372, 74.32016,50.00000,53.00000,2.442647e-10,0.78720,4
300.01700, 434.00000,     -1.05160, 74.14391,50.00000,53.00000,2.266865e-10,0.78720,4
300.04199, 437.30000,     -1.05067, 73.95429,50.00000,53.00000,2.270108e-10,0.78719,4
300.01599, 440.60000,     -1.05141, 73.81657,50.00000,53.00000,2.257766e-10,0.78719,4
300.02301, 443.90000,     -1.04987, 73.62016,50.00000,53.00000,2.262688e-10,0.78720,4
300.01901, 447.20000,     -1.04909, 73.45529,50.00000,53.00000,2.266598e-10,0.78719,4
300.01001, 450.50000,     -1.04773, 73.28802,50.00000,53.00000,2.262554e-10,0.78720,4
300.00900, 453.80000,     -1.04811, 73.10519,50.00000,53.00000,2.261448e-10,0.78721,4
300.01401, 457.10000,     -1.04792, 72.92675,50.00000,53.00000,2.259274e-10,0.78719,4
300.01999, 460.40000,     -1.04793, 72.75070,50.00000,53.00000,2.266255e-10,0.78721,4
300.01801, 463.70000,     -1.04483, 72.58124,50.00000,53.00000,2.271041e-10,0.78719,4
300.02301, 467.00000,     -1.04329, 72.42555,50.00000,53.00000,2.272740e-10,0.78720,4
300.02399, 470.30000,     -1.04368, 72.23353,50.00000,53.00000,2.270299e-10,0.78719,4
300.00699, 473.60000,     -1.04327, 72.06427,50.00000,53.00000,2.265377e-10,0.78719,4
300.00900, 476.90000,     -1.04192, 71.92874,50.00000,53.00000,2.274474e-10,0.78718,4
300.01001, 480.20000,     -1.04096, 71.73892,50.00000,53.00000,2.271938e-10,0.78719,4
300.01901, 483.50000,     -1.04097, 71.55609,50.00000,53.00000,2.272034e-10,0.78719,4
300.01001, 486.80000,     -1.04173, 71.40020,50.00000,53.00000,2.267475e-10,0.78720,4
300.01300, 490.10000,     -1.04019, 71.23094,50.00000,53.00000,2.270851e-10,0.78719,4
300.02701, 493.40000,     -1.04001, 71.05489,50.00000,53.00000,2.266197e-10,0.78718,4
300.01501, 496.70000,     -1.03787, 70.86287,50.00000,53.00000,2.268962e-10,0.78719,4
300.01501, 500.00000,     -1.03941, 70.71158,50.00000,53.00000,2.268314e-10,0.78718,4
300.01001, 503.30000,     -1.03825, 70.56248,50.00000,53.00000,2.272606e-10,0.78718,4
300.02399, 506.60000,     -1.03652, 70.39321,50.00000,53.00000,2.277279e-10,0.78718,4
300.02301, 509.90000,     -1.03652, 70.25090,50.00000,53.00000,2.269229e-10,0.78719,4
300.01199, 513.20000,     -1.03593, 70.08144,50.00000,53.00000,2.266883e-10,0.78719,4
300.01599, 516.50000,     -1.03477, 69.91677,50.00000,53.00000,2.275505e-10,0.78718,4
300.01401, 519.80000,     -1.03380, 69.70000,50.00000,53.00000,2.272301e-10,0.78719,4
300.01901, 523.10000,     -1.03400, 69.56447,50.00000,53.00000,2.278442e-10,0.78719,4
300.01801, 526.40000,     -1.03284, 69.40180,50.00000,53.00000,2.281112e-10,0.78719,4
300.01001, 529.70000,     -1.03360, 69.22575,50.00000,53.00000,2.276001e-10,0.78719,4
300.02600, 533.00000,     -1.03188, 69.06986,50.00000,53.00000,2.283764e-10,0.78719,4
300.02100, 536.30000,     -1.03284, 68.89381,50.00000,53.00000,2.276592e-10,0.78719,4
300.01099, 539.60000,     -1.03109, 68.78543,50.00000,53.00000,2.281361e-10,0.78719,4
300.01501, 542.90000,     -1.03013, 68.54371,50.00000,53.00000,2.278862e-10,0.78719,4
300.06100, 546.20000,     -1.03057, 68.44890,50.00000,53.00000,2.289563e-10,0.78719,4
300.02499, 549.50000,     -1.03053, 68.20499,50.00000,53.00000,2.282658e-10,0.78719,4
300.02399, 552.80000,     -1.03053, 68.08303,50.00000,53.00000,2.290917e-10,0.78719,4
300.02301, 556.10000,     -1.03053, 67.92715,50.00000,53.00000,2.286930e-10,0.78721,4
300.01801, 559.40000,     -1.03033, 67.77365,50.00000,53.00000,2.279873e-10,0.78720,4
300.01801, 562.70000,     -1.02878, 67.61557,50.00000,53.00000,2.287922e-10,0.78720,4
300.01801, 566.00000,     -1.02781, 67.42595,50.00000,53.00000,2.285805e-10,0.78721,4
300.02301, 569.30000,     -1.02956, 67.26108,50.00000,53.00000,2.289333e-10,0.78720,4
300.01401, 572.60000,     -1.02684, 67.12555,50.00000,52.00000,2.286969e-10,0.78720,4
300.01300, 575.90000,     -1.02684, 66.94271,50.00000,53.00000,2.293796e-10,0.78720,4
300.02100, 579.20000,     -1.02627, 66.79361,50.00000,53.00000,2.299519e-10,0.78719,4
300.02600, 582.50000,     -1.02627, 66.65808,50.00000,52.00000,2.297249e-10,0.78719,4
300.01401, 585.80000,     -1.02568, 66.44810,50.00000,52.00000,2.295018e-10,0.78720,4
300.02802, 589.10000,     -1.02492, 66.31257,50.00000,52.00000,2.290859e-10,0.78721,4
300.02200, 592.40000,     -1.02549, 66.14331,50.00000,52.00000,2.299614e-10,0.78720,4
300.01300, 595.70000,     -1.02452, 65.97385,50.00000,52.00000,2.295895e-10,0.78719,4
300.01801, 599.00000,     -1.02278, 65.81816,50.00000,52.00000,2.298412e-10,0.78719,4
300.01999, 602.30000,     -1.02356, 65.71198,50.00000,52.00000,2.299690e-10,0.78720,4
300.01599, 605.60000,     -1.02491, 65.50878,50.00000,52.00000,2.307911e-10,0.78719,4
300.00299, 608.90000,     -1.02373, 65.37325,50.00000,52.00000,2.299901e-10,0.78720,4
300.01901, 612.20000,     -1.02182, 65.18363,50.00000,52.00000,2.300568e-10,0.78720,4
300.01999, 615.50000,     -1.02298, 65.06846,50.00000,52.00000,2.307262e-10,0.78720,4
300.02100, 618.80000,     -1.02395, 64.89900,50.00000,52.00000,2.300682e-10,0.78719,4
300.00699, 622.10000,     -1.02335, 64.75669,50.00000,52.00000,2.297249e-10,0.78719,4
300.02100, 625.40000,     -1.02395, 64.58064,50.00000,52.00000,2.305622e-10,0.78719,4
300.02899, 628.70000,     -1.02454, 64.42475,50.00000,52.00000,2.308350e-10,0.78719,4
300.01001, 632.00000,     -1.02451, 64.26228,50.00000,52.00000,2.304612e-10,0.78719,4
300.00601, 635.30000,     -1.02393, 64.11317,50.00000,52.00000,2.302189e-10,0.78721,4
300.01700, 638.60000,     -1.02317, 63.93713,50.00000,52.00000,2.300529e-10,0.78720,4
300.00500, 641.90000,     -1.02102, 63.76088,50.00000,52.00000,2.304611e-10,0.78719,4
300.01401, 645.20000,     -1.02123, 63.63453,50.00000,52.00000,2.307568e-10,0.78719,4
300.00699, 648.50000,     -1.02199, 63.46287,50.00000,52.00000,2.309093e-10,0.78720,4
300.02399, 651.80000,     -1.02027, 63.31836,50.00000,52.00000,2.309475e-10,0.78719,4
300.02200, 655.10000,     -1.02066, 63.14212,50.00000,52.00000,2.313557e-10,0.78719,4
300.02399, 658.40000,     -1.02027, 62.99321,50.00000,52.00000,2.314663e-10,0.78720,4
300.02301, 661.70000,     -1.02143, 62.84411,50.00000,52.00000,2.310734e-10,0.78719,4
300.01099, 665.00000,     -1.01948, 62.68822,50.00000,52.00000,2.309551e-10,0.78719,4
300.01801, 668.30000,     -1.02007, 62.53693,50.00000,52.00000,2.315750e-10,0.78719,4
300.01001, 671.60000,     -1.01890, 62.41277,50.00000,52.00000,2.312355e-10,0.78720,4
300.02301, 674.90000,     -1.02008, 62.25030,50.00000,52.00000,2.309266e-10,0.78719,4
300.01999, 678.20000,     -1.01930, 62.08084,50.00000,52.00000,2.317085e-10,0.78720,4
300.01700, 681.50000,     -1.01910, 61.91836,50.00000,52.00000,2.320901e-10,0.78720,4
300.00699, 684.80000,     -1.02006, 61.77605,50.00000,52.00000,2.320384e-10,0.78719,4
300.02600, 688.10000,     -1.01757, 61.62016,50.00000,52.00000,2.318154e-10,0.78719,4
300.01401, 691.40000,     -1.01775, 61.47126,50.00000,52.00000,2.323036e-10,0.78719,4
300.02100, 694.70000,     -1.01872, 61.32894,50.00000,52.00000,2.319679e-10,0.78719,4
300.01099, 698.00000,     -1.01871, 61.19341,50.00000,52.00000,2.324295e-10,0.78719,4
300.01801, 701.30000,     -1.01620, 61.05110,50.00000,52.00000,2.324772e-10,0.78719,4
300.01300, 704.60000,     -1.01542, 60.90220,50.00000,52.00000,2.326469e-10,0.78719,4
300.01199, 707.90000,     -1.01523, 60.70559,50.00000,52.00000,2.324238e-10,0.78719,4
300.00900, 711.20000,     -1.01523, 60.57006,50.00000,52.00000,2.328415e-10,0.78718,4
300.00400, 714.50000,     -1.01503, 60.44830,50.00000,52.00000,2.325706e-10,0.78718,4
300.01199, 717.80000,     -1.01504, 60.30599,50.00000,52.00000,2.332420e-10,0.78719,4
300.01501, 721.10000,     -1.01504, 60.13653,50.00000,52.00000,2.328663e-10,0.78719,4
300.01901, 724.40000,     -1.01330, 59.96048,50.00000,52.00000,2.324065e-10,0.78718,4
300.01599, 727.70000,     -1.01349, 59.85888,50.00000,52.00000,2.333984e-10,0.78718,4
300.01901, 731.00000,     -1.01369, 59.71657,50.00000,52.00000,2.327805e-10,0.78719,4
300.02100, 734.30000,     -1.01350, 59.56747,50.00000,52.00000,2.328090e-10,0.78719,4
300.01901, 737.60000,     -1.01214, 59.41178,50.00000,52.00000,2.341289e-10,0.78719,4
300.01401, 740.90000,     -1.01388, 59.26048,50.00000,52.00000,2.331504e-10,0.78719,4
300.01901, 744.20000,     -1.01292, 59.11816,50.00000,52.00000,2.330761e-10,0.78719,4
300.01099, 747.50000,     -1.01097, 58.98263,50.00000,52.00000,2.340603e-10,0.78720,4
300.00800, 750.80000,     -1.01368, 58.82016,50.00000,52.00000,2.337456e-10,0.78719,4
300.01599, 754.10000,     -1.01349, 58.65749,50.00000,52.00000,2.338676e-10,0.78719,4
300.02100, 757.40000,     -1.01214, 58.54910,50.00000,52.00000,2.347374e-10,0.78719,4
300.00699, 760.70000,     -1.01039, 58.42715,50.00000,52.00000,2.343120e-10,0.78720,4
300.01401, 764.00000,     -1.01252, 58.27804,50.00000,52.00000,2.340431e-10,0.78719,4
300.00299, 767.30000,     -1.01193, 58.13593,50.00000,52.00000,2.341785e-10,0.78719,4
300.02301, 770.60000,     -1.01157, 57.95968,50.00000,52.00000,2.344857e-10,0.78718,4
300.04800, 773.90000,     -1.01276, 57.84451,50.00000,52.00000,2.339478e-10,0.78719,4
300.01300, 777.20000,     -1.01349, 57.67525,50.00000,52.00000,2.350197e-10,0.78720,4
300.02100, 780.50000,     -1.01079, 57.53293,50.00000,52.00000,2.350178e-10,0.78718,4
300.00900, 783.80000,     -1.01194, 57.39741,50.00000,52.00000,2.348575e-10,0.78719,4
300.01901, 787.10000,     -1.01350, 57.25509,50.00000,52.00000,2.346459e-10,0.78718,4
300.01099, 790.40000,     -1.01426, 57.09940,50.00000,52.00000,2.349281e-10,0.78718,4
300.01099, 793.70000,     -1.01175, 56.95709,50.00000,52.00000,2.348862e-10,0.78719,4
300.01599, 797.00000,     -1.01059, 56.83513,50.00000,52.00000,2.349167e-10,0.78719,4
300.01700, 800.30000,     -1.01195, 56.69960,50.00000,51.00000,2.354203e-10,0.78720,4
300.01501, 803.60000,     -1.01136, 56.52355,50.00000,51.00000,2.348461e-10,0.78719,4
300.02600, 806.90000,     -1.01254, 56.38124,50.00000,51.00000,2.354393e-10,0.78720,4
300.02301, 810.20000,     -1.01369, 56.26607,50.00000,51.00000,2.351475e-10,0.78720,4
300.01300, 813.50000,     -1.01291, 56.12375,50.00000,51.00000,2.348156e-10,0.78719,4
300.04999, 816.80000,     -1.01295, 55.96128,50.00000,51.00000,2.354393e-10,0.78719,4
300.01599, 820.10000,     -1.01407, 55.85289,50.00000,51.00000,2.359199e-10,0.78719,4
300.01700, 823.40000,     -1.01446, 55.71058,50.00000,51.00000,2.363377e-10,0.78719,4
300.01401, 826.70000,     -1.01349, 55.54132,50.00000,51.00000,2.348232e-10,0.78718,4
300.01401, 830.00000,     -1.01330, 55.42615,50.00000,51.00000,2.358989e-10,0.78719,4
300.04099, 833.30000,     -1.01372, 55.25669,50.00000,51.00000,2.354717e-10,0.78720,4
300.01599, 836.60000,     -1.01330, 55.16188,50.00000,51.00000,2.359581e-10,0.78720,4
300.01099, 839.90000,     -1.01387, 55.02635,50.00000,51.00000,2.364712e-10,0.78719,4
300.00800, 843.20000,     -1.01580, 54.88403,50.00000,51.00000,2.359352e-10,0.78718,4
300.01199, 846.50000,     -1.01426, 54.75529,50.00000,51.00000,2.367992e-10,0.78719,4
300.03101, 849.80000,     -1.01448, 54.61996,50.00000,51.00000,2.368660e-10,0.78719,4
300.01401, 853.10000,     -1.01581, 54.49800,50.00000,51.00000,2.365169e-10,0.78719,4
300.01599, 856.40000,     -1.01485, 54.33533,50.00000,51.00000,2.365818e-10,0.78718,4
300.01599, 859.70000,     -1.01407, 54.19980,50.00000,51.00000,2.371693e-10,0.78719,4
300.00601, 863.00000,     -1.01503, 54.06447,50.00000,51.00000,2.366771e-10,0.78720,4
300.01300, 866.30000,     -1.01639, 53.92894,50.00000,51.00000,2.367573e-10,0.78719,4
300.02600, 869.60000,     -1.01331, 53.80020,50.00000,51.00000,2.372264e-10,0.78718,4
300.01901, 872.90000,     -1.01698, 53.70539,50.00000,51.00000,2.378158e-10,0.78719,4
300.01901, 876.20000,     -1.01659, 53.53593,50.00000,51.00000,2.378750e-10,0.78719,4
300.02301, 879.50000,     -1.01544, 53.38703,50.00000,51.00000,2.380390e-10,0.78719,4
300.01901, 882.80000,     -1.01620, 53.27186,50.00000,51.00000,2.378731e-10,0.78718,4
300.03101, 886.10000,     -1.01815, 53.15669,50.00000,51.00000,2.380028e-10,0.78720,4
300.00900, 889.40000,     -1.01561, 52.99401,50.00000,51.00000,2.372590e-10,0.78718,4
300.02100, 892.70000,     -1.01640, 52.85170,50.00000,51.00000,2.385311e-10,0.78719,4
300.01099, 896.00000,     -1.01755, 52.72974,50.00000,51.00000,2.385311e-10,0.78719,4
300.01599, 899.30000,     -1.01659, 52.60120,50.00000,51.00000,2.382584e-10,0.78719,4
300.02701, 902.60000,     -1.01718, 52.47924,50.00000,51.00000,2.376195e-10,0.78719,4
300.01099, 905.90000,     -1.01871, 52.34371,50.00000,51.00000,2.381725e-10,0.78720,4
300.01300, 909.20000,     -1.01949, 52.20818,50.00000,51.00000,2.383823e-10,0.78720,4
300.01801, 912.50000,     -1.01717, 52.08623,50.00000,51.00000,2.383137e-10,0.78720,4
300.00299, 915.80000,     -1.01870, 51.95070,50.00000,51.00000,2.388439e-10,0.78720,4
300.01099, 919.10000,     -1.01987, 51.82196,50.00000,51.00000,2.385884e-10,0.78720,4
300.02301, 922.40000,     -1.01969, 51.68663,50.00000,51.00000,2.389259e-10,0.78720,4
300.01199, 925.70000,     -1.02007, 51.57146,50.00000,51.00000,2.388268e-10,0.78719,4
300.02399, 929.00000,     -1.02085, 51.42914,50.00000,51.00000,2.392768e-10,0.78719,4
300.02200, 932.30000,     -1.02046, 51.29361,50.00000,51.00000,2.390975e-10,0.78720,4
300.03000, 935.60000,     -1.02125, 51.17166,50.00000,51.00000,2.396030e-10,0.78719,4
300.01001, 938.90000,     -1.02277, 51.05649,50.00000,51.00000,2.389813e-10,0.78718,4
300.01001, 942.20000,     -1.02161, 50.95489,50.00000,51.00000,2.390804e-10,0.78719,4
300.02200, 945.50000,     -1.02279, 50.80579,50.00000,51.00000,2.392215e-10,0.78719,4
300.02100, 948.80000,     -1.02588, 50.67046,50.00000,51.00000,2.391014e-10,0.78719,4
300.01599, 952.10000,     -1.02297, 50.53493,50.00000,51.00000,2.394085e-10,0.78718,4
300.00500, 955.40000,     -1.02393, 50.43333,50.00000,51.00000,2.403298e-10,0.78720,4
300.01300, 958.70000,     -1.02626, 50.31138,50.00000,51.00000,2.394122e-10,0.78720,4
300.02301, 962.00000,     -1.02569, 50.17585,50.00000,51.00000,2.404422e-10,0.78719,4
300.01300, 965.30000,     -1.02394, 50.04032,50.00000,51.00000,2.399483e-10,0.78719,4
300.01901, 968.60000,     -1.02665, 49.92515,50.00000,51.00000,2.407398e-10,0.78718,4
300.01901, 971.90000,     -1.02704, 49.79421,50.00000,51.00000,2.390041e-10,0.78718,4
300.01700, 975.20000,     -1.02355, 49.66547,50.00000,51.00000,2.408753e-10,0.78720,4
300.01999, 978.50000,     -1.02530, 49.55709,50.00000,51.00000,2.405338e-10,0.78719,4
300.02701, 981.80000,     -1.02705, 49.42156,50.00000,51.00000,2.404422e-10,0.78718,4
300.01199, 985.10000,     -1.02529, 49.29281,50.00000,51.00000,2.403813e-10,0.78718,4
300.00699, 988.40000,     -1.02528, 49.19800,50.00000,51.00000,2.406826e-10,0.78719,4
300.02899, 991.70000,     -1.02647, 49.06248,50.00000,51.00000,2.409974e-10,0.78718,4
300.01700, 995.00000,     -1.02704, 48.92036,50.00000,51.00000,2.408715e-10,0.78719,4
300.01901, 998.30000,     -1.02704, 48.81198,50.00000,51.00000,2.408294e-10,0.78719,4
300.01401,1001.60000,     -1.02742, 48.68323,50.00000,51.00000,2.409324e-10,0.78720,4
300.00500,1004.90000,     -1.02644, 48.55449,50.00000,51.00000,2.407951e-10,0.78720,4
300.01401,1008.20000,     -1.02974, 48.41677,50.00000,51.00000,2.409229e-10,0.78720,4
300.02399,1011.50000,     -1.02956, 48.32196,50.00000,51.00000,2.412147e-10,0.78718,4
300.02499,1014.80000,     -1.02840, 48.17285,50.00000,51.00000,2.406025e-10,0.78719,4
299.99799,1018.10000,     -1.02914, 48.05090,50.00000,51.00000,2.407246e-10,0.78719,4
300.01401,1021.40000,     -1.03206, 47.93573,50.00000,51.00000,2.416572e-10,0.78720,4
300.00400,1024.70000,     -1.03089, 47.82735,50.00000,51.00000,2.417145e-10,0.78719,4
300.02399,1028.00000,     -1.03111, 47.68503,50.00000,51.00000,2.412395e-10,0.78719,4
300.01300,1031.30000,     -1.03303, 47.56307,50.00000,51.00000,2.415371e-10,0.78720,4
300.02200,1034.60000,     -1.03343, 47.44790,50.00000,51.00000,2.419109e-10,0.78719,4
300.01501,1037.90000,     -1.03496, 47.33273,50.00000,51.00000,2.415504e-10,0.78719,4
300.01999,1041.20000,     -1.03555, 47.24251,50.00000,51.00000,2.415409e-10,0.78720,4
300.00500,1044.50000,     -1.03457, 47.10020,50.00000,51.00000,2.422733e-10,0.78720,4
300.01700,1047.80000,     -1.03632, 46.99182,50.00000,51.00000,2.419948e-10,0.78719,4
300.01801,1051.10000,     -1.03613, 46.85629,50.00000,51.00000,2.419605e-10,0.78718,4
300.01099,1054.40000,     -1.03612, 46.72076,50.00000,51.00000,2.422428e-10,0.78719,4
300.03000,1057.70000,     -1.03866, 46.56507,50.00000,51.00000,2.425365e-10,0.78719,4
300.01501,1061.00000,     -1.03922, 46.49721,50.00000,51.00000,2.421703e-10,0.78718,4
300.01099,1064.30000,     -1.03786, 46.37525,50.00000,51.00000,2.420655e-10,0.78718,4
300.01599,1067.60000,     -1.03884, 46.24671,50.00000,51.00000,2.423725e-10,0.78720,4
300.01901,1070.90000,     -1.03923, 46.13832,50.00000,51.00000,2.428226e-10,0.78720,4
300.01501,1074.20000,     -1.03883, 45.99820,50.00000,51.00000,2.424908e-10,0.78719,4
300.01901,1077.50000,     -1.03903, 45.92156,50.00000,51.00000,2.429256e-10,0.78719,4
300.01099,1080.80000,     -1.04096, 45.80639,50.00000,51.00000,2.430706e-10,0.78719,4
300.01001,1084.10000,     -1.04018, 45.66407,50.00000,51.00000,2.435131e-10,0.78718,4
300.01199,1087.40000,     -1.04173, 45.54890,50.00000,51.00000,2.433758e-10,0.78719,4
300.02499,1090.70000,     -1.04291, 45.41337,50.00000,51.00000,2.431946e-10,0.78719,4
300.02499,1094.00000,     -1.04446, 45.29820,50.00000,51.00000,2.427730e-10,0.78719,4
300.01199,1097.30000,     -1.04251, 45.18303,50.00000,51.00000,2.432500e-10,0.78720,4
300.02701,1100.60000,     -1.04465, 45.06786,50.00000,51.00000,2.433204e-10,0.78720,4
300.02802,1103.90000,     -1.04504, 44.96407,50.00000,51.00000,2.424145e-10,0.78718,4
300.02701,1107.20000,     -1.04504, 44.84890,50.00000,51.00000,2.433529e-10,0.78719,4
300.01901,1110.50000,     -1.04522, 44.74731,50.00000,51.00000,2.440072e-10,0.78719,4
300.01599,1113.80000,     -1.04677, 44.61617,50.00000,51.00000,2.434844e-10,0.78720,4
300.02499,1117.10000,     -1.04639, 44.48762,50.00000,51.00000,2.444534e-10,0.78720,4
300.01199,1120.40000,     -1.04773, 44.39940,50.00000,51.00000,2.435074e-10,0.78720,4
300.01801,1123.70000,     -1.04812, 44.33174,50.00000,51.00000,2.438450e-10,0.78719,4
300.02200,1127.00000,     -1.04852, 44.20299,50.00000,51.00000,2.449322e-10,0.78719,4
300.01099,1130.30000,     -1.04792, 44.06747,50.00000,51.00000,2.444897e-10,0.78719,4
300.01001,1133.60000,     -1.05024, 43.99301,50.00000,51.00000,2.443867e-10,0.78719,4
300.01801,1136.90000,     -1.05161, 43.85529,50.00000,51.00000,2.439041e-10,0.78719,4
300.01501,1140.20000,     -1.04967, 43.76048,50.00000,51.00000,2.446251e-10,0.78720,4
300.01300,1143.50000,     -1.05063, 43.66547,50.00000,51.00000,2.446308e-10,0.78719,4
300.01099,1146.80000,     -1.05237, 43.57745,50.00000,51.00000,2.452621e-10,0.78718,4
300.01700,1150.10000,     -1.05122, 43.43513,50.00000,51.00000,2.449169e-10,0.78718,4
300.02200,1153.40000,     -1.05200, 43.33353,50.00000,51.00000,2.453727e-10,0.78720,4
300.03000,1156.70000,     -1.05278, 43.22515,50.00000,51.00000,2.456989e-10,0.78719,4
300.01700,1160.00000,     -1.05335, 43.13713,50.00000,51.00000,2.457351e-10,0.78720,4
300.02399,1163.30000,     -1.05529, 43.02196,50.00000,51.00000,2.461052e-10,0.78719,4
300.01801,1166.60000,     -1.05431, 42.90679,50.00000,51.00000,2.458267e-10,0.78721,4
300.01901,1169.90000,     -1.05586, 42.80739,50.00000,51.00000,2.459545e-10,0.78720,4
300.02399,1173.20000,     -1.05587, 42.70579,50.00000,51.00000,2.462233e-10,0.78719,4
300.01401,1176.50000,     -1.05818, 42.58164,50.00000,51.00000,2.461281e-10,0.78719,4
300.01801,1179.80000,     -1.05722, 42.51397,50.00000,51.00000,2.457714e-10,0.78719,4
300.01300,1183.10000,     -1.05740, 42.36487,50.00000,51.00000,2.465725e-10,0.78720,4
300.01300,1186.40000,     -1.05721, 42.27006,50.00000,51.00000,2.464047e-10,0.78719,4
300.01801,1189.70000,     -1.05818, 42.16387,50.00000,51.00000,2.457047e-10,0.78719,4
300.00699,1193.00000,     -1.05875, 42.03513,50.00000,50.00000,2.464752e-10,0.78720,4
300.01401,1196.30000,     -1.05934, 41.94032,50.00000,50.00000,2.464829e-10,0.78719,4
300.01901,1199.60000,     -1.06051, 41.84770,50.00000,50.00000,2.462368e-10,0.78719,4
300.01099,1202.90000,     -1.06069, 41.73034,50.00000,50.00000,2.458133e-10,0.78719,4
300.01501,1206.20000,     -1.06243, 41.64451,50.00000,50.00000,2.466964e-10,0.78719,4
300.01401,1209.50000,     -1.06437, 41.52934,50.00000,50.00000,2.467136e-10,0.78719,4
300.02701,1212.80000,     -1.06303, 41.43673,50.00000,50.00000,2.469902e-10,0.78718,4
300.02100,1216.10000,     -1.06438, 41.33733,50.00000,50.00000,2.476310e-10,0.78719,4
300.01099,1219.40000,     -1.06514, 41.22216,50.00000,50.00000,2.473926e-10,0.78719,4
300.01801,1222.70000,     -1.06457, 41.12056,50.00000,50.00000,2.479191e-10,0.78720,4
300.02200,1226.00000,     -1.06670, 41.03253,50.00000,50.00000,2.472878e-10,0.78720,4
300.02600,1229.30000,     -1.06632, 40.91737,50.00000,50.00000,2.473087e-10,0.78720,4
300.01801,1232.60000,     -1.06611, 40.78862,50.00000,50.00000,2.477436e-10,0.78719,4
300.00900,1235.90000,     -1.06804, 40.70739,50.00000,50.00000,2.482624e-10,0.78719,4
300.01401,1239.20000,     -1.06727, 40.60579,50.00000,50.00000,2.479896e-10,0.78719,4
300.01199,1242.50000,     -1.06823, 40.51098,50.00000,50.00000,2.482013e-10,0.78719,4
300.00800,1245.80000,     -1.06920, 40.38902,50.00000,50.00000,2.476788e-10,0.78719,4
300.00900,1249.10000,     -1.07055, 40.28064,50.00000,50.00000,2.479706e-10,0.78719,4
300.01501,1252.40000,     -1.06998, 40.18563,50.00000,50.00000,2.481270e-10,0.78718,4
300.01501,1255.70000,     -1.07230, 40.07505,50.00000,50.00000,2.477054e-10,0.78719,4
300.01901,1257.10000,     -1.07211, 40.02096,50.00000,50.00000,2.483902e-10,0.78719,5
300.22198,1257.26500,     -0.99594, 40.07725,50.00000,50.00000,2.485027e-10,0.78720,5
300.82101,1257.43000,     -0.79933, 40.24671,50.00000,50.00000,2.483921e-10,0.78719,5
301.92599,1257.59500,     -0.50353, 40.56507,50.00000,50.00000,2.472763e-10,0.78719,5
303.61200,1257.76000,     -0.14862, 40.91058,50.00000,50.00000,2.480583e-10,0.78719,5
305.78299,1257.92500,      0.21816, 41.23134,50.00000,50.00000,2.476120e-10,0.78719,5
308.35800,1258.09000,      0.54885, 41.54291,50.00000,50.00000,2.480221e-10,0.78719,5
311.20901,1258.25500,      0.81230, 41.79361,50.00000,50.00000,2.475014e-10,0.78719,5
314.19199,1258.42000,      0.99373, 41.99222,50.00000,50.00000,2.482299e-10,0.78719,5
317.22101,1258.58500,      1.09755, 42.10060,50.00000,50.00000,2.479858e-10,0.78719,5
320.19901,1258.75000,      1.13726, 42.15489,50.00000,50.00000,2.481861e-10,0.78719,5
323.10400,1258.91500,      1.13479, 42.19541,50.00000,50.00000,2.476826e-10,0.78719,5
325.95499,1259.08000,      1.11386, 42.24970,50.00000,50.00000,2.479591e-10,0.78720,5
328.76300,1259.24500,      1.09714, 42.24970,50.00000,50.00000,2.471066e-10,0.78719,5
331.61200,1259.41000,      1.09423, 42.27685,50.00000,50.00000,2.472000e-10,0.78719,5
334.47501,1259.57500,      1.12180, 42.33094,50.00000,50.00000,2.470989e-10,0.78718,5
337.44400,1259.74000,      1.17606, 42.39202,50.00000,50.00000,2.471657e-10,0.78718,5
340.51199,1259.90500,      1.24979, 42.46647,50.00000,50.00000,2.470798e-10,0.78719,5
343.71301,1260.07000,      1.35027, 42.54770,50.00000,50.00000,2.474460e-10,0.78719,5
347.02701,1260.23500,      1.45629, 42.60419,50.00000,50.00000,2.480144e-10,0.78718,5
350.44299,1260.40000,      1.56034, 42.66747,50.00000,50.00000,2.475948e-10,0.78719,5
353.94800,1260.56500,      1.65288, 42.74870,50.00000,50.00000,2.470646e-10,0.78719,5
357.50299,1260.73000,      1.72538, 42.77585,50.00000,50.00000,2.474385e-10,0.78718,5
361.07901,1260.89500,      1.77875, 42.79621,50.00000,50.00000,2.469959e-10,0.78719,5
364.67001,1261.06000,      1.82804, 42.76906,50.00000,50.00000,2.471466e-10,0.78719,5
368.25201,1261.22500,      1.85205, 42.74192,50.00000,50.00000,2.465058e-10,0.78719,5
371.85599,1261.39000,      1.88268, 42.62914,50.00000,50.00000,2.472572e-10,0.78719,5
375.43201,1261.55500,      1.88946, 42.47784,50.00000,50.00000,2.472229e-10,0.78718,5
379.00101,1261.72000,      1.89948, 42.27445,50.00000,50.00000,2.470264e-10,0.78719,5
382.58701,1261.88500,      1.47373, 41.98543,50.00000,50.00000,2.469330e-10,0.78719,5
386.17499,1262.05000,      2.16462, 41.59261,50.00000,50.00000,2.472114e-10,0.78719,5
389.75800,1262.21500,      2.34720, 41.20200,50.00000,50.00000,2.474957e-10,0.78718,5
393.36301,1262.38000,      2.42239, 40.68244,50.00000,50.00000,2.474689e-10,0.78719,5
396.96500,1262.54500,      2.42708, 40.13373,50.00000,50.00000,2.468796e-10,0.78719,5
400.58600,1262.71000,      2.59028, 39.42934,50.00000,50.00000,2.474136e-10,0.78718,5
404.19800,1262.87500,      2.44033, 38.57784,50.00000,50.00000,2.468432e-10,0.78720,5
407.80899,1263.04000,      2.60950, 37.55729,50.00000,50.00000,2.465934e-10,0.78719,5
411.42200,1263.20500,      2.53691, 36.41238,50.00000,50.00000,2.467919e-10,0.78720,5
415.00800,1263.37000,      2.38628, 35.01457,50.00000,50.00000,2.467976e-10,0.78719,5
418.60001,1263.53500,      2.40324, 33.51517,50.00000,50.00000,2.476234e-10,0.78719,5
422.16800,1263.70000,      2.72673, 31.78982,50.00000,50.00000,2.477855e-10,0.78719,5
425.73001,1263.86500,      2.78625, 29.85469,50.00000,50.00000,2.474479e-10,0.78719,5
429.30099,1264.03000,      3.26463, 27.69142,50.00000,50.00000,2.473983e-10,0.78720,5
432.83301,1264.19500,      2.73300, 25.32475,50.00000,50.00000,2.472152e-10,0.78719,5
436.35999,1264.36000,      2.62730, 22.81377,50.00000,50.00000,2.477378e-10,0.78719,5
439.89301,1264.52500,      2.46950, 20.32295,50.00000,50.00000,2.475548e-10,0.78719,5
443.41501,1264.69000,      2.31126, 17.75549,50.00000,50.00000,2.472152e-10,0.78720,5
446.92899,1264.85500,      2.07556, 15.33473,50.00000,50.00000,2.471504e-10,0.78720,5
450.43500,1265.02000,      1.79567, 12.97046,50.00000,50.00000,2.469731e-10,0.78720,5
453.92401,1265.18500,      1.52087, 10.83633,50.00000,50.00000,2.466508e-10,0.78720,5
457.41599,1265.35000,      1.21876,  9.03214,50.00000,50.00000,2.464123e-10,0.78719,5
460.88800,1265.51500,      1.34011,  7.51916,50.00000,50.00000,2.475090e-10,0.78720,5
464.35800,1265.68000,      1.07281,  6.33812,50.00000,50.00000,2.475433e-10,0.78718,5
467.81799,1265.84500,      0.81745,  5.49142,50.00000,50.00000,2.471447e-10,0.78721,5
471.27301,1266.01000,      0.57762,  4.93134,50.00000,50.00000,2.475662e-10,0.78719,5
474.72400,1266.17500,      0.37687,  4.64910,50.00000,50.00000,2.474460e-10,0.78720,5
478.16699,1266.34000,      0.20528,  4.49541,50.00000,50.00000,2.469596e-10,0.78719,5
481.61099,1266.50500, 5.909052e-02,  4.43912,50.00000,50.00000,2.473202e-10,0.78719,5
485.02899,1266.67000,-6.206396e-02,  4.41198,50.00000,50.00000,2.472343e-10,0.78720,5
488.45999,1266.83500,     -0.17045,  4.38483,50.00000,50.00000,2.473964e-10,0.78720,5
491.87399,1267.00000,     -0.27110,  4.38483,50.00000,50.00000,2.472038e-10,0.78719,5
495.26901,1267.16500,     -0.36264,  4.41198,50.00000,50.00000,2.478790e-10,0.78719,5
498.66199,1267.33000,     -0.45221,  4.46607,50.00000,50.00000,2.473469e-10,0.78719,5
502.05301,1267.49500,     -0.53903,  4.46607,50.00000,50.00000,2.475643e-10,0.78720,5
505.44601,1267.66000,     -0.62153,  4.49321,50.00000,50.00000,2.467632e-10,0.78719,5
508.82300,1267.82500,     -0.70649,  4.53613,50.00000,50.00000,2.471027e-10,0.78719,5
512.20099,1267.99000,     -0.78909,  4.57685,50.00000,50.00000,2.468910e-10,0.78720,5
515.57397,1268.15500,     -0.86981,  4.65808,50.00000,50.00000,2.464943e-10,0.78719,5
518.94299,1268.32000,     -0.95015,  4.65808,50.00000,50.00000,2.475719e-10,0.78720,5
522.30298,1268.48500,     -1.03552,  4.68523,50.00000,50.00000,2.471599e-10,0.78719,5
525.65698,1268.65000,     -1.11716,  4.73253,50.00000,50.00000,2.469139e-10,0.78720,5
529.01898,1268.81500,     -1.20595,  4.76647,50.00000,50.00000,2.467060e-10,0.78720,5
532.37299,1268.98000,     -1.29177,  4.79361,50.00000,50.00000,2.467117e-10,0.78720,5
535.72498,1269.14500,     -1.37694,  4.84770,50.00000,50.00000,2.472132e-10,0.78720,5
539.07397,1269.31000,     -1.46302,  4.84770,50.00000,50.00000,2.485752e-10,0.78720,5
542.41302,1269.47500,     -1.55026,  4.87485,50.00000,50.00000,2.463187e-10,0.78719,5
545.75500,1269.64000,     -1.63496,  4.90200,50.00000,50.00000,2.467841e-10,0.78719,5
549.09900,1269.80500,     -1.72457,  4.92914,50.00000,50.00000,2.464657e-10,0.78720,5
552.44000,1269.97000,     -1.81000,  4.95609,50.00000,50.00000,2.465858e-10,0.78719,5
555.78003,1270.13500,     -1.89523,  5.01038,50.00000,50.00000,2.472440e-10,0.78719,5
559.10999,1270.30000,     -1.98321,  5.06687,50.00000,50.00000,2.473678e-10,0.78718,5
562.44702,1270.46500,     -2.07319,  5.12096,50.00000,50.00000,2.479553e-10,0.78719,5
565.79602,1270.63000,     -2.15947,  5.21816,50.00000,50.00000,2.464905e-10,0.78720,5
569.12701,1270.79500,     -2.24629,  5.27904,50.00000,50.00000,2.477169e-10,0.78719,5
572.45599,1270.96000,     -2.33507,  5.37385,50.00000,50.00000,2.477512e-10,0.78718,5
575.79901,1271.12500,     -2.42063,  5.45968,50.00000,50.00000,2.473316e-10,0.78720,5
579.12201,1271.29000,     -2.51030,  5.51617,50.00000,50.00000,2.478161e-10,0.78719,5
582.46301,1271.45500,     -2.59423,  5.59521,50.00000,50.00000,2.479839e-10,0.78719,5
585.79102,1271.62000,     -2.68534,  5.60200,50.00000,50.00000,2.467136e-10,0.78719,5
589.12000,1271.78500,     -2.77648,  5.62914,50.00000,50.00000,2.476558e-10,0.78719,5
592.45300,1271.95000,     -2.86877,  5.65609,50.00000,50.00000,2.471428e-10,0.78719,5
595.77600,1272.11500,     -2.96303,  5.65609,50.00000,50.00000,2.469692e-10,0.78718,5
599.10199,1272.28000,     -3.05307,  5.65609,50.00000,50.00000,2.477399e-10,0.78719,5
602.41998,1272.44500,     -3.14648,  5.66287,50.00000,50.00000,2.471104e-10,0.78720,5
605.75403,1272.61000,     -3.23765,  5.66287,50.00000,50.00000,2.474747e-10,0.78719,5
609.07300,1272.77500,     -3.33018,  5.66287,50.00000,50.00000,2.476997e-10,0.78719,5
612.40399,1272.94000,     -3.41757,  5.66287,50.00000,50.00000,2.477950e-10,0.78719,5
615.72302,1273.10500,     -3.50916,  5.69002,50.00000,50.00000,2.476825e-10,0.78719,5
619.03998,1273.27000,     -3.59404,  5.69002,50.00000,50.00000,2.477417e-10,0.78719,5
622.35699,1273.43500,     -3.68578,  5.74431,50.00000,50.00000,2.477970e-10,0.78719,5
625.67999,1273.60000,     -3.77370,  5.74431,50.00000,50.00000,2.472019e-10,0.78719,5
628.99902,1273.76500,     -3.86354,  5.79840,50.00000,50.00000,2.476234e-10,0.78719,5
632.32202,1273.93000,     -3.95858,  5.79840,50.00000,50.00000,2.478389e-10,0.78719,5
635.63800,1274.09500,     -4.04883,  5.85269,50.00000,50.00000,2.477893e-10,0.78719,5
638.95099,1274.26000,     -4.14308,  5.83912,50.00000,50.00000,2.478733e-10,0.78719,5
642.26898,1274.42500,     -4.23402,  5.89321,50.00000,50.00000,2.475738e-10,0.78719,5
645.58502,1274.59000,     -4.32365,  5.89321,50.00000,50.00000,2.478694e-10,0.78718,5
648.90601,1274.75500,     -4.40632,  5.92036,50.00000,50.00000,2.474212e-10,0.78718,5
652.22101,1274.92000,     -4.48879,  5.92715,50.00000,50.00000,2.474556e-10,0.78719,5
655.53497,1275.08500,     -4.58005,  5.95429,50.00000,50.00000,2.476615e-10,0.78718,5
658.84399,1275.25000,     -4.66574,  5.92715,50.00000,50.00000,2.480660e-10,0.78719,5
662.16302,1275.41500,     -4.75432,  5.98144,50.00000,50.00000,2.473506e-10,0.78718,5
665.47198,1275.58000,     -4.83845,  5.98144,50.00000,50.00000,2.472591e-10,0.78717,5
668.80103,1275.74500,     -4.92520,  5.99481,50.00000,50.00000,2.474232e-10,0.78719,5
672.10699,1275.91000,     -5.00770,  6.01517,50.00000,50.00000,2.475032e-10,0.78719,5
675.42401,1276.07500,     -5.10838,  6.04910,50.00000,50.00000,2.475585e-10,0.78719,5
678.75702,1276.24000,     -5.19676,  6.08303,50.00000,50.00000,2.477017e-10,0.78719,5
682.04999,1276.40500,     -5.28629,  6.11677,50.00000,50.00000,2.476101e-10,0.78718,5
685.38098,1276.57000,     -5.38077,  6.14391,50.00000,50.00000,2.480411e-10,0.78719,5
688.69000,1276.73500,     -5.48705,  6.17106,50.00000,50.00000,2.472591e-10,0.78718,5
692.00897,1276.90000,     -5.58988,  6.19820,50.00000,50.00000,2.483845e-10,0.78721,5
695.33600,1277.06500,     -5.69045,  6.25689,50.00000,50.00000,2.472896e-10,0.78719,5
698.65997,1277.23000,     -5.78432,  6.25689,50.00000,50.00000,2.471714e-10,0.78720,5
701.97699,1277.39500,     -5.87954,  6.28403,50.00000,50.00000,2.475700e-10,0.78719,5
705.31000,1277.56000,     -5.98537,  6.31098,50.00000,50.00000,2.482128e-10,0.78719,5
708.62903,1277.72500,     -6.08849,  6.33812,50.00000,50.00000,2.477990e-10,0.78720,5
711.94202,1277.89000,     -6.19367,  6.33812,50.00000,50.00000,2.481117e-10,0.78720,5
715.26898,1278.05500,     -6.31245,  6.39242,50.00000,50.00000,2.472762e-10,0.78719,5
718.58301,1278.22000,     -6.42380,  6.41936,50.00000,50.00000,2.473298e-10,0.78719,5
721.90302,1278.38500,     -6.53511,  6.44651,50.00000,50.00000,2.467060e-10,0.78719,5
725.23297,1278.55000,     -6.65759,  6.47365,50.00000,50.00000,2.474633e-10,0.78717,5
728.54797,1278.71500,     -6.78703,  6.50080,50.00000,50.00000,2.471770e-10,0.78720,5
731.86902,1278.88000,     -6.90848,  6.52774,50.00000,50.00000,2.467709e-10,0.78721,5
735.18298,1279.04500,     -7.03180,  6.56168,50.00000,50.00000,2.483311e-10,0.78719,5
738.50403,1279.21000,     -7.15935,  6.58204,50.00000,50.00000,2.476196e-10,0.78720,5
741.83698,1279.37500,     -7.29220,  6.58204,50.00000,50.00000,2.483577e-10,0.78718,5
745.14801,1279.54000,     -7.42494,  6.66327,50.00000,50.00000,2.474213e-10,0.78720,5
748.46301,1279.70500,     -7.58062,  6.66327,50.00000,50.00000,2.474957e-10,0.78719,5
751.77399,1279.87000,     -7.71843,  6.69042,50.00000,50.00000,2.478008e-10,0.78720,5
755.09601,1280.03500,     -7.86230,  6.71756,50.00000,50.00000,2.479839e-10,0.78719,5
758.41199,1280.20000,     -8.00425,  6.74471,50.00000,50.00000,2.476768e-10,0.78720,5
761.73401,1280.36500,     -8.14172,  6.77166,50.00000,50.00000,2.475034e-10,0.78720,5
765.04999,1280.53000,     -8.27955,  6.82595,50.00000,50.00000,2.470321e-10,0.78720,5
768.37097,1280.69500,     -8.41916,  6.85309,50.00000,50.00000,2.474136e-10,0.78720,5
771.69501,1280.86000,     -8.56390,  6.85309,50.00000,50.00000,2.478370e-10,0.78720,5
775.01398,1281.02500,     -8.68328,  6.88004,50.00000,50.00000,2.477588e-10,0.78719,5
778.32501,1281.19000,     -8.81735,  6.93433,50.00000,50.00000,2.480660e-10,0.78720,5
781.64600,1281.35500,     -8.94215,  6.96148,50.00000,50.00000,2.481957e-10,0.78721,5
784.94897,1281.52000,     -9.06715,  6.96148,50.00000,50.00000,2.473583e-10,0.78720,5
788.25897,1281.68500,     -9.18885,  7.01557,50.00000,50.00000,2.472133e-10,0.78719,5
791.58099,1281.85000,     -9.30421,  7.01557,50.00000,50.00000,            ,0.44826,5
794.58002,1282.00000,     -9.42329,  7.06307,50.00000,50.00000,            ,0.44706,5