File: data/TGA/005d-L_M/ExpDat_2025_07_10_SL_PS_005d-L2_isothermal.csv
#EXPORTTYPE:                 ,DATA ALL
#FILE:                       ,2025_07_10_SL_PS_005d-L2_isothermal.ngb-ss5
#FORMAT:                     ,NETZSCH5
#FTYPE:                      ,ASCII
#IDENTITY:                   ,PS-005d-L2
#DECIMAL:                    ,POINT
#SEPARATOR:                  ,COMMA
#MTYPE:                      ,DSC
#INSTRUMENT:                 ,NETZSCH STA 449F5
#PROJECT:                    ,
#DATE/TIME:                  ,7/10/2025 10:57:38 AM (UTC-4)
#CORR. FILE:                 ,
#TEMPCAL:                    ,05-05-2025 14:38
#SENSITIVITY:                ,28-06-2023 13:53
#LABORATORY:                 ,Tran/AAG
#OPERATOR:                   ,Stanley
#REMARK:                     ,2025_03_29_SL_005d_M1_isothermal
#SAMPLE:                     ,PS-005d-L2
#SAMPLE MASS /mg:            ,5.10
#MATERIAL:                   ,Polystyrene
#REFERENCE:                  ,
#REFERENCE MASS /mg:         ,0
#TYPE OF CRUCIBLE:           ,Al2O3 85 ‘l, open
#SAMPLE CRUCIBLE MASS /mg:   ,0
#REFERENCE CRUCIBLE MASS /mg:,0
#DSC RANGE /‘V:              ,5000
#TG RANGE /mg:               ,35000
#TAU-R:                      ,---
#CORR. CODE:                 ,000
#EXO:                        ,-1
#RANGE:                      ,30›C....800›C/0.0....20.0K/min
#SEGMENT:                    ,S1-5/5
#SEG. 1:                     ,30›C/10.0(K/min)/100›C
#SEG. 2:                     ,100›C/00:10/100›C
#SEG. 3:                     ,100›C/5.0(K/min)/300›C
#SEG. 4:                     ,300›C/20:00/300›C
#SEG. 5:                     ,300›C/20.0(K/min)/800›C

##Temp./›C,Time/min,DSC/(mW/mg),Mass/%,Gas Flow(purge2)/(ml/min),Gas Flow(protective)/(ml/min),TIC(scan:1)/A,Sensit./(uV/mW),Segment
 30.56100,   0.00000,      0.29704,100.00000,50.00000,51.00000,            ,0.92366,1
 33.31500,   1.32000,      0.55233,101.49961,50.00000,52.00000,2.871662e-09,0.92372,1
 40.01200,   2.64000,      1.27994,102.60667,50.00000,52.00000,2.877444e-09,0.92381,1
 49.64700,   3.96000,      1.96637,103.65373,50.00000,52.00000,2.878503e-09,0.92394,1
 62.46700,   5.28000,      2.75962,104.66961,50.00000,52.00000,2.876480e-09,0.92411,1
 77.47900,   6.60000,      3.43946,105.35725,50.00000,52.00000,2.876740e-09,0.92431,1
 87.78700,   7.46000,      3.70648,105.46824,50.00000,52.00000,2.875330e-09,0.92448,2
 94.35000,   8.12000,      3.28652,104.74510,50.00000,52.00000,2.878641e-09,0.92460,2
 99.02800,   8.78000,      2.56351,103.87765,50.00000,52.00000,2.870525e-09,0.92472,2
102.42100,   9.44000,      1.96517,103.17000,50.00000,52.00000,2.872020e-09,0.92484,2
105.17600,  10.10000,      1.58953,102.66647,50.00000,52.00000,2.874538e-09,0.92496,2
107.33000,  10.76000,      1.26976,102.22510,50.00000,52.00000,2.874889e-09,0.92508,2
108.83200,  11.42000,      0.92351,101.65275,50.00000,52.00000,2.869833e-09,0.92520,2
109.70700,  12.08000,      0.58886,101.18471,50.00000,52.00000,2.874127e-09,0.92531,2
110.09700,  12.74000,      0.30840,100.75216,50.00000,52.00000,2.869895e-09,0.92543,2
110.09500,  13.40000, 8.813653e-02,100.36157,50.00000,52.00000,2.871781e-09,0.92553,2
109.82800,  14.06000,-8.193860e-02,100.00451,50.00000,52.00000,2.873247e-09,0.92564,2
109.33400,  14.72000,     -0.21418, 99.67392,50.00000,52.00000,2.871707e-09,0.92574,2
108.71700,  15.38000,     -0.31493, 99.37235,50.00000,52.00000,2.870737e-09,0.92583,2
107.99200,  16.04000,     -0.38210, 99.13059,50.00000,52.00000,2.866140e-09,0.92592,2
107.19200,  16.70000,     -0.42514, 98.86216,50.00000,52.00000,2.861699e-09,0.92599,2
106.12700,  17.72000,     -0.33567, 98.78451,50.00000,52.00000,2.860775e-09,0.92609,3
107.35800,  19.04000,      0.43492, 99.58529,50.00000,52.00000,2.864397e-09,0.92617,3
110.65600,  20.36000,      0.98793,100.15529,50.00000,52.00000,2.868305e-09,0.92620,3
115.65900,  21.68000,      1.52456,100.76529,50.00000,52.00000,2.864682e-09,0.92616,3
122.08600,  23.00000,      1.95850,101.19804,50.00000,52.00000,2.866232e-09,0.92604,3
129.35001,  24.32000,      2.25045,101.54843,50.00000,52.00000,2.871266e-09,0.92584,3
137.06599,  25.64000,      2.44009,101.76137,50.00000,52.00000,2.865717e-09,0.92551,3
144.88699,  26.96000,      2.54892,101.92333,50.00000,52.00000,2.865224e-09,0.92512,3
152.61501,  28.28000,      2.59191,102.00980,50.00000,52.00000,2.861557e-09,0.92463,3
160.13000,  29.60000,      2.59086,102.06314,50.00000,52.00000,2.860217e-09,0.92428,3
167.42500,  30.92000,      2.57455,102.13627,50.00000,52.00000,2.855876e-09,0.92397,3
174.50400,  32.24000,      2.55399,102.14961,50.00000,52.00000,2.857892e-09,0.92366,3
181.39799,  33.56000,      2.53686,102.22275,50.00000,52.00000,2.855189e-09,0.92334,3
188.18300,  34.88000,      2.52500,102.25392,50.00000,52.00000,2.857339e-09,0.92302,3
194.86400,  36.20000,      2.50117,102.28706,50.00000,52.00000,2.856736e-09,0.92271,3
201.50900,  37.52000,      2.47695,102.32706,50.00000,52.00000,2.855978e-09,0.92241,3
208.10201,  38.84000,      2.46870,102.37804,50.00000,52.00000,2.854971e-09,0.92212,3
214.66701,  40.16000,      2.47026,102.43569,50.00000,52.00000,2.856128e-09,0.92185,3
221.24200,  41.48000,      2.47348,102.47569,50.00000,52.00000,2.851847e-09,0.92159,3
227.81000,  42.80000,      2.48289,102.54216,50.00000,52.00000,2.855607e-09,0.92135,3
234.36000,  44.12000,      2.48865,102.58216,50.00000,52.00000,2.851056e-09,0.92113,3
240.94299,  45.44000,      2.49473,102.66196,50.00000,52.00000,2.844761e-09,0.92091,3
247.49600,  46.76000,      2.49628,102.70196,50.00000,52.00000,2.853904e-09,0.92071,3
254.07600,  48.08000,      2.49623,102.76196,50.00000,52.00000,2.845087e-09,0.92051,3
260.65701,  49.40000,      2.48919,102.79510,50.00000,52.00000,2.852445e-09,0.92030,3
267.23300,  50.72000,      2.48578,102.86608,50.00000,52.00000,2.857427e-09,0.92011,3
273.80399,  52.04000,      2.47793,102.86176,50.00000,52.00000,2.850923e-09,0.91993,3
280.39099,  53.36000,      2.46428,102.88608,50.00000,52.00000,2.856536e-09,0.91976,3
286.97101,  54.68000,      2.44667,102.88608,50.00000,52.00000,2.851962e-09,0.91959,3
293.53500,  56.00000,      2.43062,102.85941,50.00000,52.00000,2.850567e-09,0.91944,3
301.52301,  57.80000,      1.63972,102.58667,50.00000,52.00000,2.851404e-09,0.91923,4
303.25900,  61.10000,     -0.42790,101.71490,50.00000,52.00000,2.845758e-09,0.91891,4
302.08301,  64.40000,     -0.66334,101.14922,50.00000,52.00000,2.844561e-09,0.91866,4
301.04199,  67.70000,     -0.60829,100.63902,50.00000,52.00000,2.840618e-09,0.91847,4
300.49301,  71.00000,     -0.55161,100.23745,50.00000,52.00000,2.843835e-09,0.91834,4
300.22501,  74.30000,     -0.51114, 99.86471,50.00000,52.00000,2.842841e-09,0.91827,4
300.10199,  77.60000,     -0.50498, 99.47647,50.00000,52.00000,2.840642e-09,0.91824,4
300.04901,  80.90000,     -0.50134, 99.13059,50.00000,52.00000,2.840974e-09,0.91825,4
300.02600,  84.20000,     -0.49505, 98.83098,50.00000,52.00000,2.839643e-09,0.91829,4
300.02899,  87.50000,     -0.49677, 98.51824,50.00000,52.00000,2.840760e-09,0.91835,4
300.00601,  90.80000,     -0.50131, 98.25863,50.00000,52.00000,2.829638e-09,0.91844,4
300.00900,  94.10000,     -0.49865, 97.98588,50.00000,52.00000,2.833604e-09,0.91854,4
300.00500,  97.40000,     -0.50245, 97.71961,50.00000,52.00000,2.836988e-09,0.91866,4
300.00500, 100.70000,     -0.49770, 97.50000,50.00000,52.00000,2.833746e-09,0.91879,4
300.01300, 104.00000,     -0.50037, 97.21824,50.00000,53.00000,2.836750e-09,0.91893,4
299.99899, 107.30000,     -0.49903, 97.00529,50.00000,53.00000,2.844218e-09,0.91908,4
300.01199, 110.60000,     -0.49904, 96.80353,50.00000,53.00000,2.838497e-09,0.91922,4
300.01401, 113.90000,     -0.50303, 96.57059,50.00000,53.00000,2.834475e-09,0.91942,4
300.01801, 117.20000,     -0.49961, 96.38196,50.00000,53.00000,2.835502e-09,0.91926,4
300.01999, 120.50000,     -0.50132, 96.15569,50.00000,53.00000,2.836239e-09,0.91884,4
300.01199, 123.80000,     -0.49942, 95.96490,50.00000,53.00000,2.839381e-09,0.91823,4
300.02100, 127.10000,     -0.50379, 95.76078,50.00000,53.00000,2.837464e-09,0.91740,4
300.00500, 130.40000,     -0.50245, 95.56569,50.00000,53.00000,2.842360e-09,0.91624,4
300.01801, 133.70000,     -0.50037, 95.33275,50.00000,53.00000,2.836272e-09,0.91490,4
300.01199, 137.00000,     -0.50284, 95.16412,50.00000,53.00000,2.847225e-09,0.91335,4
300.00299, 140.30000,     -0.50492, 94.99784,50.00000,53.00000,2.838174e-09,0.91161,4
300.02301, 143.60000,     -0.50341, 94.80471,50.00000,53.00000,2.843071e-09,0.90969,4
300.01901, 146.90000,     -0.50303, 94.62510,50.00000,53.00000,2.835133e-09,0.90763,4
300.01599, 150.20000,     -0.50512, 94.44549,50.00000,53.00000,2.835707e-09,0.90543,4
300.01700, 153.50000,     -0.50398, 94.27235,50.00000,53.00000,2.841769e-09,0.90315,4
300.01199, 156.80000,     -0.50531, 94.04608,50.00000,53.00000,2.836457e-09,0.90066,4
300.00699, 160.10000,     -0.50511, 93.89980,50.00000,53.00000,2.826656e-09,0.89824,4
300.01099, 163.40000,     -0.50645, 93.72216,50.00000,53.00000,2.821516e-09,0.89577,4
300.02100, 166.70000,     -0.50702, 93.52490,50.00000,53.00000,2.839878e-09,0.89326,4
299.98300, 170.00000,     -0.50339, 93.38941,50.00000,52.00000,2.838768e-09,0.89072,4
299.98999, 173.30000,     -0.50282, 93.22314,50.00000,52.00000,2.846082e-09,0.88814,4
299.98700, 176.60000,     -0.50054, 93.09000,50.00000,52.00000,2.847006e-09,0.88553,4
300.00101, 179.90000,     -0.49846, 92.92373,50.00000,52.00000,2.845591e-09,0.88288,4
300.00800, 183.20000,     -0.50036, 92.74627,50.00000,52.00000,2.851633e-09,0.88019,4
300.00900, 186.50000,     -0.50246, 92.58431,50.00000,52.00000,2.848920e-09,0.87732,4
300.01901, 189.80000,     -0.49885, 92.42235,50.00000,52.00000,2.854554e-09,0.87454,4
300.02100, 193.10000,     -0.49733, 92.26039,50.00000,52.00000,2.849005e-09,0.87172,4
300.01401, 196.40000,     -0.50018, 92.07176,50.00000,52.00000,2.852897e-09,0.86886,4
300.01801, 199.70000,     -0.49980, 91.89431,50.00000,52.00000,2.853688e-09,0.86595,4
300.00299, 203.00000,     -0.50245, 91.72804,50.00000,52.00000,2.843854e-09,0.86299,4
299.99399, 206.30000,     -0.50226, 91.54157,50.00000,52.00000,2.855355e-09,0.85999,4
300.00500, 209.60000,     -0.49941, 91.39529,50.00000,52.00000,2.855230e-09,0.85694,4
300.00800, 212.90000,     -0.50303, 91.20216,50.00000,52.00000,2.844415e-09,0.85368,4
300.01801, 216.20000,     -0.50512, 91.01137,50.00000,52.00000,2.850622e-09,0.85054,4
300.00900, 219.50000,     -0.50379, 90.86510,50.00000,52.00000,2.852532e-09,0.84735,4
300.01401, 222.80000,     -0.50474, 90.69196,50.00000,52.00000,2.849258e-09,0.84412,4
300.01199, 226.10000,     -0.50132, 90.49902,50.00000,52.00000,2.853865e-09,0.84084,4
300.00201, 229.40000,     -0.50207, 90.35255,50.00000,52.00000,2.844660e-09,0.83754,4
300.02200, 232.70000,     -0.50474, 90.15294,50.00000,52.00000,2.838921e-09,0.83401,4
300.01001, 236.00000,     -0.50911, 90.00667,50.00000,52.00000,2.848561e-09,0.83063,4
300.01401, 239.30000,     -0.50664, 89.82020,50.00000,52.00000,2.843372e-09,0.82720,4
300.02600, 242.60000,     -0.50532, 89.69157,50.00000,52.00000,2.842550e-09,0.82374,4
300.01801, 245.90000,     -0.50740, 89.50294,50.00000,52.00000,2.844721e-09,0.82025,4
300.01099, 249.20000,     -0.50360, 89.34333,50.00000,52.00000,2.842492e-09,0.81673,4
300.01700, 252.50000,     -0.50132, 89.27235,50.00000,52.00000,2.839981e-09,0.81318,4
300.02802, 255.80000,     -0.51007, 89.04392,50.00000,52.00000,2.834377e-09,0.80959,4
300.04401, 259.10000,     -0.51217, 88.85078,50.00000,52.00000,2.837190e-09,0.80581,4
300.03299, 262.40000,     -0.51444, 88.67118,50.00000,52.00000,2.825833e-09,0.80218,4
300.03000, 265.70000,     -0.51653, 88.46490,50.00000,53.00000,2.827994e-09,0.79854,4
300.01999, 269.00000,     -0.51082, 88.18529,50.00000,53.00000,2.833624e-09,0.79487,4
300.01801, 272.30000,     -0.51405, 88.10098,50.00000,52.00000,2.846824e-09,0.79118,4
299.99500, 275.60000,     -0.51195, 87.93471,50.00000,52.00000,2.840236e-09,0.78625,4
299.99301, 278.90000,     -0.50587, 87.79941,50.00000,52.00000,2.839853e-09,0.78430,4
300.00601, 282.20000,     -0.50911, 87.67078,50.00000,52.00000,2.844789e-09,0.78432,4
300.02399, 285.50000,     -0.51007, 87.53765,50.00000,52.00000,2.840006e-09,0.78500,4
300.00500, 288.80000,     -0.51005, 87.37569,50.00000,52.00000,2.842864e-09,0.78570,4
300.01700, 292.10000,     -0.50930, 87.20706,50.00000,52.00000,2.838407e-09,0.78623,4
300.01199, 295.40000,     -0.50626, 87.08275,50.00000,52.00000,2.844711e-09,0.78659,4
300.01099, 298.70000,     -0.50797, 86.90980,50.00000,52.00000,2.839552e-09,0.78683,4
300.01300, 302.00000,     -0.50759, 86.76569,50.00000,52.00000,2.839620e-09,0.78696,4
300.01199, 305.30000,     -0.50987, 86.61039,50.00000,52.00000,2.846605e-09,0.78706,4
300.00500, 308.60000,     -0.50625, 86.48392,50.00000,52.00000,2.839814e-09,0.78712,4
300.01599, 311.90000,     -0.50683, 86.31529,50.00000,52.00000,2.846523e-09,0.78715,4
300.02200, 315.20000,     -0.51064, 86.22216,50.00000,52.00000,2.829984e-09,0.78717,4
300.01999, 318.50000,     -0.51082, 86.03137,50.00000,52.00000,2.837817e-09,0.78718,4
300.01401, 321.80000,     -0.51234, 85.87157,50.00000,52.00000,2.834859e-09,0.78720,4
300.02200, 325.10000,     -0.51045, 85.70961,50.00000,52.00000,2.835388e-09,0.78719,4
300.00900, 328.40000,     -0.51120, 85.53451,50.00000,52.00000,2.836508e-09,0.78719,4
300.01501, 331.70000,     -0.51329, 85.39255,50.00000,52.00000,2.836388e-09,0.78719,4
300.01501, 335.00000,     -0.50911, 85.23941,50.00000,52.00000,2.835165e-09,0.78720,4
300.01099, 338.30000,     -0.51139, 85.06412,50.00000,52.00000,2.834826e-09,0.78719,4
300.01300, 341.60000,     -0.51310, 84.90451,50.00000,52.00000,2.833416e-09,0.78720,4
300.02701, 344.90000,     -0.50988, 84.75804,50.00000,52.00000,2.830184e-09,0.78720,4
300.01599, 348.20000,     -0.51272, 84.59824,50.00000,52.00000,2.838040e-09,0.78721,4
300.01300, 351.50000,     -0.51101, 84.43412,50.00000,52.00000,2.837868e-09,0.78720,4
300.01401, 354.80000,     -0.51253, 84.26118,50.00000,52.00000,2.830461e-09,0.78720,4
300.01300, 358.10000,     -0.51329, 84.11922,50.00000,52.00000,2.839862e-09,0.78720,4
300.01199, 361.40000,     -0.51348, 83.95941,50.00000,52.00000,2.827274e-09,0.78719,4
300.01599, 364.70000,     -0.51614, 83.80863,50.00000,52.00000,2.835663e-09,0.78719,4
300.01801, 368.00000,     -0.51842, 83.62235,50.00000,52.00000,2.840880e-09,0.78719,4
300.00000, 371.30000,     -0.51537, 83.49137,50.00000,52.00000,2.837729e-09,0.78720,4
300.01300, 374.60000,     -0.50892, 83.36941,50.00000,52.00000,2.834978e-09,0.78720,4
300.01999, 377.90000,     -0.51576, 83.22961,50.00000,52.00000,2.839288e-09,0.78719,4
300.01999, 381.20000,     -0.51291, 83.05000,50.00000,52.00000,2.833863e-09,0.78720,4
300.01300, 384.50000,     -0.51405, 82.89471,50.00000,52.00000,2.836666e-09,0.78719,4
300.01300, 387.80000,     -0.51424, 82.75490,50.00000,52.00000,2.837007e-09,0.78719,4
300.01300, 391.10000,     -0.51747, 82.61510,50.00000,52.00000,2.835020e-09,0.78719,4
300.01199, 394.40000,     -0.51386, 82.41549,50.00000,52.00000,2.839323e-09,0.78720,4
300.01801, 397.70000,     -0.51633, 82.27353,50.00000,52.00000,2.841628e-09,0.78719,4
300.01199, 401.00000,     -0.51690, 82.14706,50.00000,52.00000,2.837670e-09,0.78719,4
300.01001, 404.30000,     -0.51842, 82.00078,50.00000,52.00000,2.839086e-09,0.78719,4
300.01501, 407.60000,     -0.51899, 81.84549,50.00000,52.00000,2.841417e-09,0.78720,4
300.01099, 410.90000,     -0.51956, 81.68569,50.00000,52.00000,2.836562e-09,0.78719,4
300.01901, 414.20000,     -0.52166, 81.54373,50.00000,52.00000,2.834867e-09,0.78719,4
300.00699, 417.50000,     -0.51975, 81.35745,50.00000,52.00000,2.832175e-09,0.78719,4
300.01001, 420.80000,     -0.51823, 81.25098,50.00000,52.00000,2.836258e-09,0.78719,4
300.01501, 424.10000,     -0.51785, 81.09118,50.00000,52.00000,2.833643e-09,0.78719,4
300.01001, 427.40000,     -0.51880, 80.93137,50.00000,52.00000,2.846317e-09,0.78719,4
300.01700, 430.70000,     -0.52146, 80.79608,50.00000,52.00000,2.842512e-09,0.78720,4
300.02200, 434.00000,     -0.52147, 80.61863,50.00000,52.00000,2.835485e-09,0.78720,4
300.00800, 437.30000,     -0.51975, 80.48118,50.00000,52.00000,2.840774e-09,0.78719,4
300.01099, 440.60000,     -0.52678, 80.32137,50.00000,52.00000,2.838053e-09,0.78721,4
300.00900, 443.90000,     -0.52393, 80.18824,50.00000,52.00000,2.838663e-09,0.78720,4
300.02301, 447.20000,     -0.52451, 80.05529,50.00000,52.00000,2.837119e-09,0.78719,4
300.00500, 450.50000,     -0.52602, 79.88667,50.00000,52.00000,2.836287e-09,0.78720,4
300.00900, 453.80000,     -0.52336, 79.72686,50.00000,52.00000,2.830633e-09,0.78719,4
300.00900, 457.10000,     -0.52051, 79.61373,50.00000,52.00000,2.830583e-09,0.78720,4
300.01501, 460.40000,     -0.51918, 79.45843,50.00000,52.00000,2.833627e-09,0.78721,4
300.01700, 463.70000,     -0.52603, 79.32549,50.00000,52.00000,2.831221e-09,0.78721,4
300.03000, 467.00000,     -0.52299, 79.19000,50.00000,52.00000,2.831788e-09,0.78721,4
300.02200, 470.30000,     -0.52793, 79.00373,50.00000,52.00000,2.833344e-09,0.78721,4
300.03000, 473.60000,     -0.52451, 78.86392,50.00000,52.00000,2.833022e-09,0.78722,4
300.01801, 476.90000,     -0.52451, 78.73098,50.00000,52.00000,2.833349e-09,0.78719,4
300.01401, 480.20000,     -0.52184, 78.61784,50.00000,52.00000,2.834925e-09,0.78719,4
300.00800, 483.50000,     -0.52982, 78.45137,50.00000,52.00000,2.836622e-09,0.78719,4
300.02200, 486.80000,     -0.52698, 78.29176,50.00000,52.00000,2.835122e-09,0.78720,4
300.00800, 490.10000,     -0.52678, 78.13863,50.00000,52.00000,2.826917e-09,0.78719,4
300.02701, 493.40000,     -0.53097, 78.02098,50.00000,52.00000,2.834106e-09,0.78719,4
300.00800, 496.70000,     -0.52906, 77.85020,50.00000,52.00000,2.838202e-09,0.78720,4
300.01801, 500.00000,     -0.52869, 77.69059,50.00000,52.00000,2.826370e-09,0.78720,4
300.00400, 503.30000,     -0.53058, 77.57078,50.00000,52.00000,2.823401e-09,0.78719,4
300.01300, 506.60000,     -0.52925, 77.43314,50.00000,52.00000,2.825225e-09,0.78719,4
300.01801, 509.90000,     -0.52926, 77.27353,50.00000,53.00000,2.821552e-09,0.78719,4
300.02200, 513.20000,     -0.53268, 77.11373,50.00000,53.00000,2.824404e-09,0.78719,4
300.01300, 516.50000,     -0.52754, 76.97392,50.00000,53.00000,2.824366e-09,0.78720,4
300.01300, 519.80000,     -0.52811, 76.83431,50.00000,53.00000,2.828331e-09,0.78720,4
300.02899, 523.10000,     -0.53059, 76.65020,50.00000,53.00000,2.826030e-09,0.78721,4
300.01501, 526.40000,     -0.53306, 76.51471,50.00000,53.00000,2.822615e-09,0.78720,4
300.01801, 529.70000,     -0.53135, 76.38392,50.00000,53.00000,2.821924e-09,0.78719,4
300.01700, 533.00000,     -0.53382, 76.21098,50.00000,53.00000,2.839695e-09,0.78719,4
300.01999, 536.30000,     -0.53211, 76.07118,50.00000,53.00000,2.834873e-09,0.78719,4
300.03299, 539.60000,     -0.53269, 75.95804,50.00000,53.00000,2.832445e-09,0.78719,4
300.01901, 542.90000,     -0.53743, 75.77176,50.00000,53.00000,2.838530e-09,0.78719,4
300.01801, 546.20000,     -0.53059, 75.65196,50.00000,53.00000,2.837395e-09,0.78720,4
300.01501, 549.50000,     -0.53401, 75.54549,50.00000,53.00000,2.832907e-09,0.78720,4
300.01099, 552.80000,     -0.53609, 75.38569,50.00000,53.00000,2.837273e-09,0.78719,4
300.00000, 556.10000,     -0.53457, 75.22588,50.00000,53.00000,2.831966e-09,0.78719,4
300.01599, 559.40000,     -0.53762, 75.10608,50.00000,53.00000,2.829138e-09,0.78719,4
300.01501, 562.70000,     -0.53667, 74.93980,50.00000,53.00000,2.824421e-09,0.78719,4
300.01901, 566.00000,     -0.53648, 74.79569,50.00000,53.00000,2.839269e-09,0.78717,4
300.02100, 569.30000,     -0.53686, 74.65373,50.00000,53.00000,2.829860e-09,0.78719,4
300.01901, 572.60000,     -0.53572, 74.53392,50.00000,53.00000,2.827790e-09,0.78719,4
300.01099, 575.90000,     -0.53666, 74.38294,50.00000,53.00000,2.830165e-09,0.78719,4
300.01999, 579.20000,     -0.53724, 74.26980,50.00000,53.00000,2.833360e-09,0.78719,4
300.02100, 582.50000,     -0.53648, 74.11235,50.00000,53.00000,2.834774e-09,0.78718,4
300.02499, 585.80000,     -0.53781, 73.99039,50.00000,53.00000,2.828812e-09,0.78719,4
300.01901, 589.10000,     -0.53762, 73.83725,50.00000,53.00000,2.835552e-09,0.78719,4
300.01700, 592.40000,     -0.54237, 73.71078,50.00000,54.00000,2.824154e-09,0.78719,4
300.01300, 595.70000,     -0.53857, 73.57118,50.00000,53.00000,2.826665e-09,0.78719,4
300.01901, 599.00000,     -0.53971, 73.40686,50.00000,54.00000,2.828167e-09,0.78717,4
300.01099, 602.30000,     -0.54008, 73.28725,50.00000,54.00000,2.825818e-09,0.78717,4
300.00601, 605.60000,     -0.53932, 73.12745,50.00000,54.00000,2.829062e-09,0.78718,4
300.01300, 608.90000,     -0.54484, 72.99647,50.00000,54.00000,2.816126e-09,0.78716,4
300.01501, 612.20000,     -0.53876, 72.85235,50.00000,54.00000,2.826157e-09,0.78717,4
300.01901, 615.50000,     -0.53876, 72.71255,50.00000,54.00000,2.830824e-09,0.78718,4
300.02499, 618.80000,     -0.54009, 72.60843,50.00000,54.00000,2.818262e-09,0.78719,4
300.01801, 622.10000,     -0.54161, 72.47529,50.00000,54.00000,2.820575e-09,0.78719,4
300.01001, 625.40000,     -0.54293, 72.31784,50.00000,54.00000,2.820261e-09,0.78718,4
300.02399, 628.70000,     -0.53933, 72.19137,50.00000,54.00000,2.818973e-09,0.78719,4
300.02701, 632.00000,     -0.54199, 72.01608,50.00000,54.00000,2.819907e-09,0.78721,4
300.01099, 635.30000,     -0.53932, 71.89627,50.00000,54.00000,2.816203e-09,0.78721,4
300.02301, 638.60000,     -0.54294, 71.78314,50.00000,54.00000,2.820792e-09,0.78720,4
300.00101, 641.90000,     -0.54217, 71.64118,50.00000,54.00000,2.821184e-09,0.78719,4
300.00699, 645.20000,     -0.54236, 71.48804,50.00000,54.00000,2.819040e-09,0.78721,4
300.01999, 648.50000,     -0.54484, 71.37490,50.00000,54.00000,2.814612e-09,0.78718,4
300.00800, 651.80000,     -0.54502, 71.23529,50.00000,54.00000,2.816903e-09,0.78720,4
300.03101, 655.10000,     -0.54352, 71.08216,50.00000,54.00000,2.813569e-09,0.78719,4
300.01001, 658.40000,     -0.54787, 70.95569,50.00000,54.00000,2.822367e-09,0.78719,4
300.00800, 661.70000,     -0.54749, 70.82255,50.00000,54.00000,2.823839e-09,0.78720,4
300.02301, 665.00000,     -0.54465, 70.70941,50.00000,54.00000,2.829708e-09,0.78719,4
299.99701, 668.30000,     -0.54939, 70.56078,50.00000,54.00000,2.814710e-09,0.78720,4
299.99500, 671.60000,     -0.54825, 70.45000,50.00000,54.00000,2.823056e-09,0.78720,4
300.01501, 674.90000,     -0.54788, 70.29020,50.00000,54.00000,2.820005e-09,0.78719,4
300.02100, 678.20000,     -0.54769, 70.15706,50.00000,54.00000,2.822415e-09,0.78720,4
300.02100, 681.50000,     -0.54731, 70.03725,50.00000,54.00000,2.822406e-09,0.78719,4
300.01099, 684.80000,     -0.55244, 69.91098,50.00000,54.00000,2.815915e-09,0.78720,4
300.01599, 688.10000,     -0.54864, 69.77784,50.00000,54.00000,2.822336e-09,0.78720,4
300.01501, 691.40000,     -0.54902, 69.64471,50.00000,54.00000,2.819139e-09,0.78720,4
300.01999, 694.70000,     -0.55016, 69.51373,50.00000,54.00000,2.820477e-09,0.78719,4
300.01001, 698.00000,     -0.55035, 69.38745,50.00000,54.00000,2.821734e-09,0.78719,4
300.01501, 701.30000,     -0.54921, 69.25431,50.00000,54.00000,2.818355e-09,0.78719,4
300.01501, 704.60000,     -0.54883, 69.12118,50.00000,54.00000,2.823620e-09,0.78719,4
300.01001, 707.90000,     -0.55206, 69.00137,50.00000,54.00000,2.816111e-09,0.78719,4
300.01801, 711.20000,     -0.55016, 68.86157,50.00000,54.00000,2.813022e-09,0.78719,4
300.01401, 714.50000,     -0.55149, 68.73961,50.00000,54.00000,2.816410e-09,0.78719,4
300.01801, 717.80000,     -0.55073, 68.58431,50.00000,54.00000,2.813652e-09,0.78720,4
300.01501, 721.10000,     -0.55054, 68.47784,50.00000,54.00000,2.817985e-09,0.78720,4
300.01501, 724.40000,     -0.55225, 68.33804,50.00000,54.00000,2.816594e-09,0.78720,4
300.01801, 727.70000,     -0.55339, 68.19176,50.00000,54.00000,2.814153e-09,0.78719,4
300.01401, 731.00000,     -0.55168, 68.04314,50.00000,54.00000,2.814055e-09,0.78720,4
300.01300, 734.30000,     -0.55491, 67.93667,50.00000,54.00000,2.812847e-09,0.78718,4
300.02399, 737.60000,     -0.55073, 67.77020,50.00000,54.00000,2.811160e-09,0.78719,4
300.01700, 740.90000,     -0.55605, 67.66373,50.00000,54.00000,2.809292e-09,0.78719,4
300.02899, 744.20000,     -0.55587, 67.51725,50.00000,54.00000,2.804371e-09,0.78719,4
300.01901, 747.50000,     -0.55510, 67.41745,50.00000,54.00000,2.810982e-09,0.78719,4
300.01199, 750.80000,     -0.55396, 67.27118,50.00000,54.00000,2.807423e-09,0.78719,4
300.02399, 754.10000,     -0.55397, 67.13137,50.00000,54.00000,2.806965e-09,0.78719,4
300.01501, 757.40000,     -0.55415, 66.99157,50.00000,54.00000,2.805864e-09,0.78719,4
300.01999, 760.70000,     -0.55491, 66.87412,50.00000,54.00000,2.804124e-09,0.78719,4
300.02100, 764.00000,     -0.55472, 66.74765,50.00000,54.00000,2.801272e-09,0.78719,4
300.00699, 767.30000,     -0.55319, 66.63451,50.00000,54.00000,2.807290e-09,0.78718,4
300.00000, 770.60000,     -0.55566, 66.48137,50.00000,54.00000,2.801918e-09,0.78719,4
300.02100, 773.90000,     -0.55605, 66.34824,50.00000,54.00000,2.802075e-09,0.78719,4
300.02301, 777.20000,     -0.55815, 66.23510,50.00000,54.00000,2.804712e-09,0.78719,4
300.01099, 780.50000,     -0.56004, 66.12196,50.00000,54.00000,2.799057e-09,0.78719,4
300.01099, 783.80000,     -0.55757, 65.96235,50.00000,54.00000,2.796868e-09,0.78720,4
300.01099, 787.10000,     -0.55928, 65.84020,50.00000,54.00000,2.798301e-09,0.78719,4
300.01300, 790.40000,     -0.55909, 65.72275,50.00000,54.00000,2.796317e-09,0.78720,4
300.01599, 793.70000,     -0.56023, 65.57627,50.00000,54.00000,2.795313e-09,0.78721,4
300.02399, 797.00000,     -0.55910, 65.47647,50.00000,54.00000,2.802119e-09,0.78719,4
300.01300, 800.30000,     -0.55928, 65.35667,50.00000,54.00000,2.789243e-09,0.78719,4
300.00400, 803.60000,     -0.56117, 65.21020,50.00000,54.00000,2.787910e-09,0.78719,4
300.01199, 806.90000,     -0.56023, 65.05059,50.00000,54.00000,2.788356e-09,0.78719,4
300.01401, 810.20000,     -0.56137, 64.94412,50.00000,54.00000,2.793751e-09,0.78718,4
300.02301, 813.50000,     -0.56100, 64.82431,50.00000,54.00000,2.793623e-09,0.78718,4
300.02802, 816.80000,     -0.56461, 64.69784,50.00000,54.00000,2.799837e-09,0.78719,4
300.02301, 820.10000,     -0.56290, 64.53157,50.00000,54.00000,2.792944e-09,0.78720,4
300.01700, 823.40000,     -0.56099, 64.41843,50.00000,54.00000,2.793748e-09,0.78719,4
300.01401, 826.70000,     -0.56555, 64.27863,50.00000,54.00000,2.795809e-09,0.78719,4
300.00800, 830.00000,     -0.56441, 64.15882,50.00000,54.00000,2.795918e-09,0.78719,4
300.01999, 833.30000,     -0.56308, 64.04353,50.00000,54.00000,2.797646e-09,0.78719,4
300.01901, 836.60000,     -0.56232, 63.89922,50.00000,54.00000,2.791908e-09,0.78719,4
300.02399, 839.90000,     -0.56537, 63.79275,50.00000,54.00000,2.799356e-09,0.78720,4
300.01300, 843.20000,     -0.56308, 63.66627,50.00000,54.00000,2.794440e-09,0.78719,4
300.00299, 846.50000,     -0.56459, 63.55980,50.00000,54.00000,2.787496e-09,0.78719,4
300.03000, 849.80000,     -0.56784, 63.39784,50.00000,54.00000,2.791434e-09,0.78719,4
300.01901, 853.10000,     -0.56688, 63.29137,50.00000,54.00000,2.787249e-09,0.78718,4
300.01999, 856.40000,     -0.56803, 63.18490,50.00000,54.00000,2.788575e-09,0.78719,4
300.02301, 859.70000,     -0.56803, 63.05627,50.00000,54.00000,2.783761e-09,0.78718,4
300.01700, 863.00000,     -0.56669, 62.91431,50.00000,54.00000,2.791408e-09,0.78719,4
300.02200, 866.30000,     -0.56385, 62.76784,50.00000,54.00000,2.792300e-09,0.78719,4
300.01199, 869.60000,     -0.56802, 62.66137,50.00000,54.00000,2.793023e-09,0.78719,4
300.01300, 872.90000,     -0.56878, 62.54824,50.00000,54.00000,2.783685e-09,0.78719,4
300.00800, 876.20000,     -0.56859, 62.41529,50.00000,54.00000,2.786832e-09,0.78720,4
300.00699, 879.50000,     -0.56973, 62.30431,50.00000,54.00000,2.780636e-09,0.78720,4
300.01599, 882.80000,     -0.56954, 62.17784,50.00000,54.00000,2.784484e-09,0.78719,4
300.02899, 886.10000,     -0.56784, 62.05804,50.00000,54.00000,2.785099e-09,0.78718,4
300.01901, 889.40000,     -0.57012, 61.93157,50.00000,54.00000,2.782579e-09,0.78719,4
300.01501, 892.70000,     -0.57087, 61.78961,50.00000,54.00000,2.780774e-09,0.78719,4
300.01501, 896.00000,     -0.56992, 61.68098,50.00000,54.00000,2.786110e-09,0.78720,4
300.01599, 899.30000,     -0.57049, 61.56118,50.00000,54.00000,2.782556e-09,0.78720,4
300.00699, 902.60000,     -0.56973, 61.42137,50.00000,54.00000,2.774172e-09,0.78718,4
300.01001, 905.90000,     -0.56840, 61.29490,50.00000,54.00000,2.776767e-09,0.78720,4
300.00400, 909.20000,     -0.56915, 61.17510,50.00000,54.00000,2.783711e-09,0.78718,4
300.01901, 912.50000,     -0.56821, 61.06863,50.00000,54.00000,2.784633e-09,0.78718,4
300.02200, 915.80000,     -0.57392, 60.93784,50.00000,54.00000,2.780264e-09,0.78718,4
300.01099, 919.10000,     -0.57277, 60.82471,50.00000,54.00000,2.780980e-09,0.78718,4
300.00500, 922.40000,     -0.57163, 60.69157,50.00000,54.00000,2.772318e-09,0.78719,4
300.01501, 925.70000,     -0.57011, 60.59176,50.00000,54.00000,2.776080e-09,0.78720,4
300.02200, 929.00000,     -0.57164, 60.45863,50.00000,54.00000,2.776950e-09,0.78720,4
300.01901, 932.30000,     -0.57468, 60.32549,50.00000,54.00000,2.782441e-09,0.78720,4
300.01401, 935.60000,     -0.56878, 60.19922,50.00000,54.00000,2.782982e-09,0.78720,4
300.00400, 938.90000,     -0.57562, 60.07275,50.00000,54.00000,2.784513e-09,0.78719,4
300.01501, 942.20000,     -0.57258, 59.98608,50.00000,54.00000,2.785032e-09,0.78718,4
300.02399, 945.50000,     -0.57297, 59.83314,50.00000,54.00000,2.779953e-09,0.78718,4
300.01999, 948.80000,     -0.57487, 59.74667,50.00000,54.00000,2.783840e-09,0.78718,4
300.00500, 952.10000,     -0.57182, 59.61353,50.00000,54.00000,2.777420e-09,0.78719,4
300.02100, 955.40000,     -0.57373, 59.48706,50.00000,54.00000,2.781974e-09,0.78719,4
300.01700, 958.70000,     -0.57696, 59.35176,50.00000,54.00000,2.781734e-09,0.78719,4
300.01401, 962.00000,     -0.57695, 59.23863,50.00000,54.00000,2.784158e-09,0.78719,4
300.01099, 965.30000,     -0.57657, 59.11216,50.00000,54.00000,2.784571e-09,0.78719,4
300.02802, 968.60000,     -0.57582, 59.00569,50.00000,54.00000,2.782731e-09,0.78719,4
300.02499, 971.90000,     -0.57639, 58.87922,50.00000,54.00000,2.778102e-09,0.78718,4
300.02701, 975.20000,     -0.57563, 58.75941,50.00000,54.00000,2.777289e-09,0.78720,4
300.02499, 978.50000,     -0.58019, 58.61078,50.00000,54.00000,2.778575e-09,0.78719,4
300.01099, 981.80000,     -0.57809, 58.49765,50.00000,54.00000,2.779067e-09,0.78719,4
300.02301, 985.10000,     -0.57468, 58.38451,50.00000,54.00000,2.778767e-09,0.78720,4
300.02899, 988.40000,     -0.57525, 58.27804,50.00000,54.00000,2.776293e-09,0.78719,4
300.02200, 991.70000,     -0.57905, 58.15157,50.00000,54.00000,2.781950e-09,0.78719,4
300.01001, 995.00000,     -0.57828, 58.04510,50.00000,54.00000,2.778675e-09,0.78720,4
300.00900, 998.30000,     -0.58094, 57.91863,50.00000,54.00000,2.776821e-09,0.78719,4
300.01599,1001.60000,     -0.57809, 57.80549,50.00000,54.00000,2.778877e-09,0.78718,4
300.02301,1004.90000,     -0.57810, 57.66588,50.00000,54.00000,2.774315e-09,0.78720,4
300.01501,1008.20000,     -0.57980, 57.55941,50.00000,54.00000,2.775224e-09,0.78720,4
300.01099,1011.50000,     -0.58303, 57.45941,50.00000,54.00000,2.771991e-09,0.78718,4
300.01801,1014.80000,     -0.58000, 57.31980,50.00000,54.00000,2.768142e-09,0.78719,4
300.01999,1018.10000,     -0.58019, 57.20000,50.00000,54.00000,2.777122e-09,0.78720,4
300.01401,1021.40000,     -0.58550, 57.08020,50.00000,54.00000,2.776385e-09,0.78719,4
300.02301,1024.70000,     -0.58399, 56.99373,50.00000,54.00000,2.774676e-09,0.78719,4
300.01599,1028.00000,     -0.58475, 56.86059,50.00000,54.00000,2.772919e-09,0.78719,4
300.02100,1031.30000,     -0.58494, 56.73412,50.00000,54.00000,2.769162e-09,0.78720,4
300.02600,1034.60000,     -0.58038, 56.62098,50.00000,54.00000,2.772796e-09,0.78719,4
300.01700,1037.90000,     -0.58475, 56.50784,50.00000,54.00000,2.774196e-09,0.78720,4
300.01099,1041.20000,     -0.58417, 56.40137,50.00000,54.00000,2.774711e-09,0.78719,4
300.02100,1044.50000,     -0.58589, 56.28157,50.00000,54.00000,2.773443e-09,0.78719,4
300.01401,1047.80000,     -0.58341, 56.16843,50.00000,55.00000,2.767955e-09,0.78718,4
300.03601,1051.10000,     -0.58248, 56.06196,50.00000,55.00000,2.773158e-09,0.78720,4
300.01099,1054.40000,     -0.58493, 55.95549,50.00000,55.00000,2.768015e-09,0.78719,4
300.02301,1057.70000,     -0.58209, 55.81569,50.00000,55.00000,2.768374e-09,0.78720,4
300.01099,1061.00000,     -0.58664, 55.68922,50.00000,55.00000,2.770548e-09,0.78719,4
300.01099,1064.30000,     -0.58284, 55.57608,50.00000,55.00000,2.769397e-09,0.78718,4
300.02100,1067.60000,     -0.58722, 55.46961,50.00000,55.00000,2.773038e-09,0.78717,4
300.00900,1070.90000,     -0.58626, 55.37647,50.00000,55.00000,2.768420e-09,0.78719,4
300.01300,1074.20000,     -0.58683, 55.25000,50.00000,55.00000,2.755864e-09,0.78718,4
300.01999,1077.50000,     -0.58551, 55.14353,50.00000,55.00000,2.762750e-09,0.78719,4
300.01300,1080.80000,     -0.58835, 55.03039,50.00000,55.00000,2.763177e-09,0.78719,4
300.02899,1084.10000,     -0.58818, 54.90392,50.00000,55.00000,2.763750e-09,0.78718,4
300.02200,1087.40000,     -0.58817, 54.79745,50.00000,55.00000,2.758746e-09,0.78719,4
300.01901,1090.70000,     -0.59045, 54.69098,50.00000,55.00000,2.762169e-09,0.78719,4
300.00601,1094.00000,     -0.58911, 54.55137,50.00000,55.00000,2.762189e-09,0.78719,4
300.01401,1097.30000,     -0.58779, 54.47804,50.00000,55.00000,2.752426e-09,0.78718,4
300.00201,1100.60000,     -0.59006, 54.34490,50.00000,55.00000,2.749037e-09,0.78718,4
300.01300,1103.90000,     -0.59045, 54.23843,50.00000,55.00000,2.750581e-09,0.78719,4
300.01199,1107.20000,     -0.58987, 54.12529,50.00000,55.00000,2.753747e-09,0.78718,4
300.01801,1110.50000,     -0.58817, 54.04549,50.00000,55.00000,2.754025e-09,0.78719,4
300.01901,1113.80000,     -0.58874, 53.91902,50.00000,55.00000,2.750100e-09,0.78719,4
300.01300,1117.10000,     -0.58988, 53.79922,50.00000,55.00000,2.752915e-09,0.78719,4
300.02399,1120.40000,     -0.59026, 53.71275,50.00000,55.00000,2.761712e-09,0.78719,4
300.01501,1123.70000,     -0.59159, 53.56627,50.00000,55.00000,2.749781e-09,0.78719,4
300.03000,1127.00000,     -0.58837, 53.45314,50.00000,55.00000,2.751788e-09,0.78719,4
300.01401,1130.30000,     -0.59197, 53.37569,50.00000,55.00000,2.744514e-09,0.78718,4
300.02399,1133.60000,     -0.59406, 53.23588,50.00000,55.00000,2.762785e-09,0.78720,4
300.01599,1136.90000,     -0.59577, 53.14706,50.00000,55.00000,2.756846e-09,0.78718,4
300.02899,1140.20000,     -0.59483, 53.03392,50.00000,55.00000,2.758058e-09,0.78719,4
300.01199,1143.50000,     -0.59444, 52.92745,50.00000,55.00000,2.762837e-09,0.78719,4
300.00601,1146.80000,     -0.59177, 52.81216,50.00000,55.00000,2.755549e-09,0.78719,4
300.01001,1150.10000,     -0.59120, 52.70569,50.00000,55.00000,2.756760e-09,0.78719,4
300.00500,1153.40000,     -0.59139, 52.59922,50.00000,55.00000,2.758724e-09,0.78720,4
300.02100,1156.70000,     -0.59083, 52.51941,50.00000,55.00000,2.758345e-09,0.78720,4
300.01801,1160.00000,     -0.59330, 52.40627,50.00000,55.00000,2.760439e-09,0.78719,4
300.01501,1163.30000,     -0.59311, 52.30627,50.00000,55.00000,2.761254e-09,0.78719,4
300.01599,1166.60000,     -0.59254, 52.15765,50.00000,55.00000,2.752538e-09,0.78719,4
300.00900,1169.90000,     -0.59386, 52.05784,50.00000,55.00000,2.752821e-09,0.78720,4
300.02499,1173.20000,     -0.59463, 51.94471,50.00000,55.00000,2.750899e-09,0.78718,4
300.02802,1176.50000,     -0.59559, 51.85824,50.00000,55.00000,2.755631e-09,0.78719,4
300.00900,1179.80000,     -0.59291, 51.71627,50.00000,55.00000,2.754805e-09,0.78719,4
300.02200,1183.10000,     -0.59368, 51.60765,50.00000,55.00000,2.757350e-09,0.78720,4
300.03000,1186.40000,     -0.59597, 51.51882,50.00000,55.00000,2.751684e-09,0.78720,4
300.01901,1189.70000,     -0.59634, 51.40804,50.00000,55.00000,2.750585e-09,0.78719,4
300.01599,1193.00000,     -0.59824, 51.28824,50.00000,55.00000,2.751748e-09,0.78719,4
300.01501,1196.30000,     -0.59273, 51.20824,50.00000,55.00000,2.746259e-09,0.78719,4
300.03000,1199.60000,     -0.59806, 51.10843,50.00000,55.00000,2.748751e-09,0.78718,4
300.01199,1202.90000,     -0.59615, 51.00196,50.00000,55.00000,2.748067e-09,0.78719,4
300.02100,1206.20000,     -0.59596, 50.89549,50.00000,55.00000,2.750908e-09,0.78720,4
300.00500,1209.50000,     -0.59766, 50.77353,50.00000,55.00000,2.745419e-09,0.78719,4
300.02200,1212.80000,     -0.59767, 50.66706,50.00000,55.00000,2.748607e-09,0.78719,4
300.02100,1216.10000,     -0.59767, 50.58059,50.00000,55.00000,2.745813e-09,0.78719,4
300.00500,1219.40000,     -0.59861, 50.47412,50.00000,55.00000,2.748873e-09,0.78719,4
300.01199,1222.70000,     -0.60052, 50.35196,50.00000,55.00000,2.741011e-09,0.78719,4
300.00601,1226.00000,     -0.59823, 50.27216,50.00000,55.00000,2.739413e-09,0.78718,4
300.01501,1229.30000,     -0.60185, 50.16118,50.00000,55.00000,2.741152e-09,0.78719,4
300.01300,1232.60000,     -0.60109, 50.06137,50.00000,55.00000,2.736363e-09,0.78719,4
300.02200,1235.90000,     -0.59995, 49.96157,50.00000,55.00000,2.734704e-09,0.78719,4
300.02200,1239.20000,     -0.60413, 49.85725,50.00000,55.00000,2.731071e-09,0.78719,4
300.01401,1242.50000,     -0.60242, 49.75314,50.00000,55.00000,2.734776e-09,0.78720,4
300.01501,1245.80000,     -0.60280, 49.66000,50.00000,55.00000,2.728173e-09,0.78719,4
300.01901,1249.10000,     -0.60242, 49.55353,50.00000,55.00000,2.732857e-09,0.78720,4
300.01801,1252.40000,     -0.60489, 49.44706,50.00000,55.00000,2.736670e-09,0.78720,4
300.01401,1255.70000,     -0.60546, 49.34039,50.00000,55.00000,2.729808e-09,0.78718,4
300.03799,1257.10000,     -0.58970, 49.29176,50.00000,55.00000,2.737393e-09,0.78719,5
300.23099,1257.26500,     -0.36421, 49.34490,50.00000,55.00000,2.741807e-09,0.78720,5
300.86200,1257.43000,      0.24254, 49.52902,50.00000,55.00000,2.729448e-09,0.78719,5
302.04001,1257.59500,      1.23822, 49.87510,50.00000,55.00000,2.731691e-09,0.78719,5
303.79700,1257.76000,      2.52801, 50.19902,50.00000,55.00000,2.734334e-09,0.78721,5
306.08600,1257.92500,      3.95508, 50.51392,50.00000,55.00000,2.732302e-09,0.78720,5
308.75201,1258.09000,      5.34793, 50.79118,50.00000,55.00000,2.727403e-09,0.78720,5
311.66800,1258.25500,      6.56628, 51.04863,50.00000,55.00000,2.735497e-09,0.78721,5
314.68900,1258.42000,      7.52277, 51.15725,50.00000,55.00000,2.730268e-09,0.78720,5
317.70700,1258.58500,      8.18565, 51.32588,50.00000,55.00000,2.731556e-09,0.78719,5
320.66501,1258.75000,      8.58631, 51.37902,50.00000,55.00000,2.728122e-09,0.78719,5
323.52600,1258.91500,      8.77907, 51.40569,50.00000,55.00000,2.736398e-09,0.78719,5
326.33499,1259.08000,      8.84905, 51.40569,50.00000,55.00000,2.735651e-09,0.78719,5
329.09900,1259.24500,      8.87022, 51.43235,50.00000,55.00000,2.733645e-09,0.78718,5
331.87701,1259.41000,      8.91327, 51.45667,50.00000,55.00000,2.735711e-09,0.78719,5
334.71600,1259.57500,      9.02634, 51.49216,50.00000,55.00000,2.736016e-09,0.78719,5
337.67099,1259.74000,      9.22957, 51.54549,50.00000,55.00000,2.735845e-09,0.78719,5
340.73700,1259.90500,      9.52520, 51.63196,50.00000,55.00000,2.736090e-09,0.78719,5
343.95901,1260.07000,      9.88392, 51.67863,50.00000,55.00000,2.732975e-09,0.78719,5
347.28101,1260.23500,     10.27474, 51.71176,50.00000,55.00000,2.736241e-09,0.78720,5
350.71500,1260.40000,     10.66843, 51.76725,50.00000,55.00000,2.735170e-09,0.78719,5
354.22501,1260.56500,     11.02787, 51.79392,50.00000,55.00000,2.737217e-09,0.78719,5
357.78900,1260.73000,     11.33519, 51.78059,50.00000,55.00000,2.733494e-09,0.78720,5
361.35101,1260.89500,     11.58313, 51.76725,50.00000,55.00000,2.735935e-09,0.78719,5
364.93399,1261.06000,     11.76705, 51.70961,50.00000,55.00000,2.736716e-09,0.78720,5
368.50601,1261.22500,     11.90130, 51.60765,50.00000,55.00000,2.737264e-09,0.78719,5
372.06799,1261.39000,     11.99557, 51.46118,50.00000,55.00000,2.735038e-09,0.78720,5
375.62601,1261.55500,     12.07279, 51.29255,50.00000,55.00000,2.726643e-09,0.78720,5
379.19699,1261.72000,     12.14536, 51.09294,50.00000,55.00000,2.735776e-09,0.78720,5
382.76199,1261.88500,     12.22368, 50.74020,50.00000,55.00000,2.734350e-09,0.78720,5
386.33200,1262.05000,     12.31561, 50.37863,50.00000,55.00000,2.734021e-09,0.78720,5
389.92999,1262.21500,     12.42534, 49.94157,50.00000,55.00000,2.730800e-09,0.78720,5
393.52899,1262.38000,     12.54989, 49.31608,50.00000,55.00000,2.726337e-09,0.78719,5
397.14099,1262.54500,     12.69438, 48.52196,50.00000,55.00000,2.732104e-09,0.78719,5
400.74799,1262.71000,     12.85231, 47.51922,50.00000,55.00000,2.728595e-09,0.78720,5
404.35901,1262.87500,     13.00617, 46.43667,50.00000,55.00000,2.729682e-09,0.78719,5
407.96799,1263.04000,     13.14968, 45.08569,50.00000,55.00000,2.739142e-09,0.78719,5
411.56100,1263.20500,     13.29820, 43.59510,50.00000,55.00000,2.734356e-09,0.78719,5
415.14001,1263.37000,     13.46814, 41.78941,50.00000,55.00000,2.732142e-09,0.78719,5
418.72198,1263.53500,     13.65033, 39.62647,50.00000,55.00000,2.735815e-09,0.78719,5
422.28601,1263.70000,     13.84810, 37.14196,50.00000,55.00000,2.731263e-09,0.78719,5
425.83801,1263.86500,     14.04589, 34.49118,50.00000,55.00000,2.737227e-09,0.78719,5
429.37900,1264.03000,     14.23535, 31.35667,50.00000,55.00000,2.736584e-09,0.78719,5
432.91699,1264.19500,     14.40206, 28.19784,50.00000,55.00000,2.734644e-09,0.78720,5
436.44501,1264.36000,     14.52578, 24.79490,50.00000,55.00000,2.729557e-09,0.78719,5
439.96399,1264.52500,     14.58356, 21.44529,50.00000,55.00000,2.724832e-09,0.78718,5
443.47101,1264.69000,     14.55859, 18.24196,50.00000,55.00000,2.735339e-09,0.78719,5
446.98401,1264.85500,     14.44061, 15.33373,50.00000,55.00000,2.733481e-09,0.78719,5
450.48001,1265.02000,     14.22600, 12.78941,50.00000,55.00000,2.728727e-09,0.78719,5
453.98700,1265.18500,     13.94159, 10.76176,50.00000,55.00000,2.735134e-09,0.78719,5
457.47699,1265.35000,     13.61248,  9.09137,50.00000,55.00000,2.731083e-09,0.78718,5
460.95999,1265.51500,     13.27765,  7.90471,50.00000,55.00000,2.730535e-09,0.78718,5
464.44101,1265.68000,     12.96022,  6.95529,50.00000,55.00000,2.731351e-09,0.78719,5
467.91400,1265.84500,     12.66957,  6.38961,50.00000,55.00000,2.731755e-09,0.78719,5
471.37399,1266.01000,     12.40343,  5.89706,50.00000,55.00000,2.732038e-09,0.78718,5
474.82101,1266.17500,     12.15883,  5.64863,50.00000,55.00000,2.731383e-09,0.78720,5
478.26401,1266.34000,     11.93791,  5.46000,50.00000,55.00000,2.730713e-09,0.78718,5
481.69901,1266.50500,     11.73952,  5.39353,50.00000,55.00000,2.736104e-09,0.78720,5
485.12799,1266.67000,     11.56111,  5.38020,50.00000,55.00000,2.731535e-09,0.78720,5
488.55600,1266.83500,     11.40378,  5.38020,50.00000,55.00000,2.729415e-09,0.78719,5
491.94800,1267.00000,     11.26340,  5.40902,50.00000,55.00000,2.730118e-09,0.78719,5
495.34799,1267.16500,     11.13328,  5.40902,50.00000,55.00000,2.731985e-09,0.78719,5
498.74200,1267.33000,     11.01656,  5.46235,50.00000,55.00000,2.732524e-09,0.78718,5
502.13199,1267.49500,     10.90802,  5.48882,50.00000,55.00000,2.733648e-09,0.78718,5
505.51099,1267.66000,     10.79774,  5.51549,50.00000,55.00000,2.737851e-09,0.78719,5
508.88599,1267.82500,     10.69779,  5.56216,50.00000,55.00000,2.734739e-09,0.78718,5
512.26501,1267.99000,     10.59715,  5.57098,50.00000,55.00000,2.731958e-09,0.78720,5
515.63501,1268.15500,     10.49841,  5.62412,50.00000,55.00000,2.735198e-09,0.78720,5
518.99103,1268.32000,     10.39953,  5.65078,50.00000,55.00000,2.735269e-09,0.78720,5
522.35901,1268.48500,     10.30110,  5.67745,50.00000,55.00000,2.732391e-09,0.78720,5
525.71399,1268.65000,     10.19977,  5.73294,50.00000,55.00000,2.735982e-09,0.78719,5
529.07501,1268.81500,     10.09651,  5.73294,50.00000,55.00000,2.727746e-09,0.78719,5
532.42798,1268.98000,      9.99141,  5.75961,50.00000,55.00000,2.732216e-09,0.78719,5
535.77698,1269.14500,      9.88811,  5.81275,50.00000,55.00000,2.732938e-09,0.78719,5
539.12097,1269.31000,      9.78689,  5.83941,50.00000,55.00000,2.734059e-09,0.78719,5
542.45300,1269.47500,      9.68356,  5.83941,50.00000,55.00000,2.734761e-09,0.78719,5
545.80298,1269.64000,      9.57610,  5.86824,50.00000,55.00000,2.731427e-09,0.78718,5
549.14600,1269.80500,      9.47231,  5.92137,50.00000,55.00000,2.733940e-09,0.78719,5
552.47803,1269.97000,      9.36720,  5.94804,50.00000,55.00000,2.740005e-09,0.78719,5
555.80798,1270.13500,      9.26458,  5.97471,50.00000,55.00000,2.730070e-09,0.78719,5
559.14899,1270.30000,      9.16064,  6.00804,50.00000,55.00000,2.734953e-09,0.78719,5
562.47900,1270.46500,      9.05356,  6.02804,50.00000,55.00000,2.729808e-09,0.78718,5
565.81299,1270.63000,      8.95096,  6.08118,50.00000,55.00000,2.731223e-09,0.78719,5
569.13898,1270.79500,      8.84686,  6.10784,50.00000,55.00000,2.728820e-09,0.78719,5
572.48102,1270.96000,      8.73829,  6.13451,50.00000,55.00000,2.732495e-09,0.78718,5
575.81000,1271.12500,      8.62977,  6.16098,50.00000,55.00000,2.728937e-09,0.78719,5
579.14600,1271.29000,      8.51907,  6.16098,50.00000,55.00000,2.733495e-09,0.78719,5
582.47198,1271.45500,      8.40739,  6.20765,50.00000,55.00000,2.731210e-09,0.78718,5
585.79303,1271.62000,      8.29369,  6.24098,50.00000,55.00000,2.731957e-09,0.78718,5
589.11902,1271.78500,      8.18216,  6.24314,50.00000,55.00000,2.725070e-09,0.78718,5
592.44598,1271.95000,      8.06097,  6.28980,50.00000,55.00000,2.726133e-09,0.78719,5
595.77698,1272.11500,      7.94691,  6.28980,50.00000,55.00000,2.727779e-09,0.78719,5
599.09198,1272.28000,      7.82992,  6.32294,50.00000,55.00000,2.730636e-09,0.78719,5
602.40997,1272.44500,      7.70847,  6.33176,50.00000,55.00000,2.731156e-09,0.78719,5
605.73401,1272.61000,      7.58759,  6.38510,50.00000,55.00000,2.734989e-09,0.78718,5
609.05103,1272.77500,      7.47141,  6.38510,50.00000,55.00000,2.739300e-09,0.78719,5
612.38599,1272.94000,      7.36131,  6.41176,50.00000,55.00000,2.734576e-09,0.78719,5
615.69299,1273.10500,      7.24627,  6.43843,50.00000,55.00000,2.727481e-09,0.78720,5
619.01099,1273.27000,      7.13423,  6.45824,50.00000,55.00000,2.731171e-09,0.78719,5
622.34399,1273.43500,      7.01727,  6.49157,50.00000,55.00000,2.732297e-09,0.78719,5
625.66400,1273.60000,      6.89630,  6.49157,50.00000,55.00000,2.731720e-09,0.78719,5
628.96997,1273.76500,      6.76756,  6.51824,50.00000,55.00000,2.733279e-09,0.78718,5
632.28802,1273.93000,      6.63721,  6.54490,50.00000,55.00000,2.725670e-09,0.78719,5
635.59198,1274.09500,      6.51086,  6.57137,50.00000,55.00000,2.734343e-09,0.78719,5
638.91901,1274.26000,      6.38242,  6.59804,50.00000,55.00000,2.728752e-09,0.78719,5
642.22498,1274.42500,      6.25481,  6.59804,50.00000,55.00000,2.730178e-09,0.78719,5
645.54401,1274.59000,      6.13002,  6.62471,50.00000,55.00000,2.727288e-09,0.78720,5
648.84601,1274.75500,      6.00263,  6.62471,50.00000,55.00000,2.731632e-09,0.78719,5
652.15601,1274.92000,      5.87660,  6.65804,50.00000,55.00000,2.732100e-09,0.78721,5
655.47198,1275.08500,      5.75019,  6.65137,50.00000,55.00000,2.729533e-09,0.78720,5
658.78497,1275.25000,      5.61803,  6.67784,50.00000,55.00000,2.729599e-09,0.78719,5
662.09497,1275.41500,      5.48927,  6.73118,50.00000,55.00000,2.729386e-09,0.78719,5
665.42102,1275.58000,      5.35931,  6.73118,50.00000,55.00000,2.735442e-09,0.78719,5
668.72302,1275.74500,      5.22524,  6.72451,50.00000,55.00000,2.730170e-09,0.78719,5
672.03003,1275.91000,      5.08481,  6.77118,50.00000,55.00000,2.734233e-09,0.78719,5
675.34302,1276.07500,      4.94306,  6.77118,50.00000,55.00000,2.733314e-09,0.78720,5
678.65802,1276.24000,      4.80211,  6.77765,50.00000,55.00000,2.730032e-09,0.78720,5
681.97601,1276.40500,      4.66528,  6.80431,50.00000,55.00000,2.728195e-09,0.78719,5
685.28003,1276.57000,      4.52741,  6.82431,50.00000,55.00000,2.732791e-09,0.78720,5
688.60999,1276.73500,      4.38441,  6.83098,50.00000,55.00000,2.726160e-09,0.78720,5
691.92902,1276.90000,      4.23976,  6.85765,50.00000,55.00000,2.730686e-09,0.78720,5
695.23798,1277.06500,      4.08978,  6.87765,50.00000,55.00000,2.728932e-09,0.78721,5
698.55902,1277.23000,      3.93821,  6.87765,50.00000,55.00000,2.732928e-09,0.78720,5
701.87000,1277.39500,      3.78374,  6.91078,50.00000,55.00000,2.729958e-09,0.78719,5
705.19202,1277.56000,      3.63105,  6.88412,50.00000,55.00000,2.730079e-09,0.78720,5
708.51501,1277.72500,      3.47735,  6.93745,50.00000,55.00000,2.729354e-09,0.78720,5
711.82800,1277.89000,      3.32820,  6.94412,50.00000,55.00000,2.729551e-09,0.78720,5
715.14697,1278.05500,      3.17529,  6.96412,50.00000,55.00000,2.729025e-09,0.78720,5
718.46301,1278.22000,      3.01858,  6.99078,50.00000,55.00000,2.730024e-09,0.78720,5
721.78802,1278.38500,      2.86621,  6.99078,50.00000,55.00000,2.733481e-09,0.78719,5
725.09698,1278.55000,      2.71409,  7.01725,50.00000,55.00000,2.726275e-09,0.78719,5
728.41199,1278.71500,      2.56608,  7.03059,50.00000,55.00000,2.735467e-09,0.78720,5
731.74597,1278.88000,      2.41686,  7.01725,50.00000,55.00000,2.731190e-09,0.78721,5
735.05298,1279.04500,      2.26729,  7.07059,50.00000,55.00000,2.727658e-09,0.78720,5
738.38098,1279.21000,      2.11651,  7.07059,50.00000,55.00000,2.723444e-09,0.78720,5
741.68500,1279.37500,      1.96381,  7.09725,50.00000,55.00000,2.734375e-09,0.78721,5
745.01001,1279.54000,      1.81245,  7.08392,50.00000,55.00000,2.726873e-09,0.78720,5
748.33398,1279.70500,      1.66466,  7.11275,50.00000,55.00000,2.730486e-09,0.78721,5
751.64801,1279.87000,      1.51885,  7.11275,50.00000,55.00000,2.728186e-09,0.78720,5
754.96899,1280.03500,      1.38057,  7.13941,50.00000,55.00000,2.728794e-09,0.78720,5
758.29401,1280.20000,      1.24794,  7.16588,50.00000,55.00000,2.729521e-09,0.78720,5
761.60400,1280.36500,      1.12457,  7.16588,50.00000,55.00000,2.731014e-09,0.78719,5
764.91302,1280.53000,      0.98971,  7.16588,50.00000,55.00000,2.726871e-09,0.78719,5
768.22900,1280.69500,      0.86059,  7.19255,50.00000,55.00000,2.730521e-09,0.78720,5
771.54602,1280.86000,      0.73758,  7.19255,50.00000,55.00000,2.728648e-09,0.78719,5
774.86902,1281.02500,      0.61811,  7.23255,50.00000,55.00000,2.733241e-09,0.78719,5
778.17700,1281.19000,      0.50155,  7.24588,50.00000,55.00000,2.737216e-09,0.78719,5
781.49701,1281.35500,      0.38761,  7.21922,50.00000,55.00000,2.735076e-09,0.78719,5
784.81897,1281.52000,      0.27399,  7.24588,50.00000,55.00000,2.731701e-09,0.78720,5
788.12799,1281.68500,      0.15869,  7.27235,50.00000,55.00000,2.729402e-09,0.78720,5
791.45001,1281.85000, 4.471371e-02,  7.29902,50.00000,55.00000,            ,0.44832,5
794.46802,1282.00000,-6.056058e-02,  7.29902,50.00000,55.00000,            ,0.44710,5