File: data/TGA/005d-L_M/ExpDat_2025_02_22_005d-L3-dynamic-1K.csv
#EXPORTTYPE:                 ,DATA ALL
#FILE:                       ,2025_02_22_005d-L3-dynamic-1K.ngb-ss5
#FORMAT:                     ,NETZSCH5
#FTYPE:                      ,ASCII
#IDENTITY:                   ,005d-L3
#DECIMAL:                    ,POINT
#SEPARATOR:                  ,COMMA
#MTYPE:                      ,DSC
#INSTRUMENT:                 ,NETZSCH STA 449F5
#PROJECT:                    ,PS
#DATE/TIME:                  ,2/24/2025 1:51:03 PM (UTC-5)
#CORR. FILE:                 ,
#TEMPCAL:                    ,13-11-2024 10:37
#SENSITIVITY:                ,28-06-2023 13:53
#LABORATORY:                 ,Tran/Aspuru
#OPERATOR:                   ,Stanley
#REMARK:                     ,
#SAMPLE:                     ,005d-L3
#SAMPLE MASS /mg:            ,5.03
#MATERIAL:                   ,
#REFERENCE:                  ,
#REFERENCE MASS /mg:         ,0
#TYPE OF CRUCIBLE:           ,Al2O3 85 ‘l, open
#SAMPLE CRUCIBLE MASS /mg:   ,0
#REFERENCE CRUCIBLE MASS /mg:,0
#DSC RANGE /‘V:              ,5000
#TG RANGE /mg:               ,35000
#TAU-R:                      ,---
#CORR. CODE:                 ,000
#EXO:                        ,-1
#RANGE:                      ,20›C....800›C/0.0....20.0K/min
#SEGMENT:                    ,S1-4/4
#SEG. 1:                     ,20›C/5.0(K/min)/100›C
#SEG. 2:                     ,100›C/00:05/100›C
#SEG. 3:                     ,100›C/1.0(K/min)/400›C
#SEG. 4:                     ,400›C/20.0(K/min)/800›C

##Temp./›C,Time/min,DSC/(mW/mg),Mass/%,Gas Flow(purge2)/(ml/min),Gas Flow(protective)/(ml/min),TIC(scan:1)/A,Sensit./(uV/mW),Segment
 30.00700,  0.00000,      0.51076,    100.00000,50.00000,38.00000,            ,0.92356,1
 31.38300,  1.06667,      0.21246,     99.68509,50.00000,38.00000,1.997586e-10,0.92363,1
 32.48400,  2.13333,      0.12985,     92.83857,50.00000,37.00000,2.000008e-10,0.92374,1
 33.51500,  3.20000,      0.13442,     92.55527,50.00000,37.00000,1.997051e-10,0.92383,1
 35.28300,  4.26667,      0.28106,     92.55527,50.00000,37.00000,1.995658e-10,0.92392,1
 38.08100,  5.33333,      0.50185,     92.96680,50.00000,37.00000,1.996574e-10,0.92398,1
 41.98900,  6.40000,      0.72699,     93.41670,50.00000,37.00000,2.000007e-10,0.92406,1
 46.79700,  7.46667,      0.94227,     93.84394,50.00000,37.00000,1.995144e-10,0.92412,1
 52.37800,  8.53333,      1.12882,     94.19702,50.00000,37.00000,2.001400e-10,0.92421,1
 58.52500,  9.60000,      1.28030,     94.55249,50.00000,37.00000,2.002086e-10,0.92432,1
 64.98600, 10.66667,      1.39397,     94.73022,50.00000,37.00000,1.999721e-10,0.92444,1
 71.58100, 11.73333,      1.47173,     94.86501,50.00000,37.00000,2.015190e-10,0.92458,1
 78.16700, 12.80000,      1.52590,     94.89881,50.00000,37.00000,2.006340e-10,0.92476,1
 84.68900, 13.86667,      1.56202,     94.79304,50.00000,37.00000,2.002678e-10,0.92495,1
 91.10200, 14.93333,      1.57874,     94.71889,50.00000,37.00000,2.007179e-10,0.92513,1
 97.27500, 15.98333,      1.58248,     94.54115,50.00000,37.00000,2.004834e-10,0.92531,2
101.36400, 16.78333,      1.37973,     94.07793,50.00000,37.00000,2.002583e-10,0.92545,2
104.02000, 17.58333,      0.94289,     93.20080,50.00000,37.00000,2.004413e-10,0.92559,2
105.77400, 18.38333,      0.63145,     92.42704,50.00000,37.00000,2.005291e-10,0.92572,2
106.98300, 19.18333,      0.42393,     91.79503,50.00000,37.00000,2.011280e-10,0.92584,2
107.66800, 19.98333,      0.22497,     91.21014,50.00000,37.00000,2.002430e-10,0.92595,2
107.84200, 20.78333, 4.275082e-02,     90.65686,50.00000,37.00000,2.004166e-10,0.92604,2
107.61600, 21.80000,-9.407810e-02,     90.07654,50.00000,37.00000,2.004165e-10,0.92613,3
107.37900, 22.86667,     -0.10414,     89.69205,50.00000,37.00000,2.006874e-10,0.92618,3
107.16100, 23.93333,     -0.10628,     89.31193,50.00000,37.00000,2.006951e-10,0.92620,3
106.97700, 25.00000,-8.102301e-02,     89.07117,50.00000,37.00000,2.007065e-10,0.92618,3
107.03700, 26.06667,-3.036357e-02,     88.84175,50.00000,37.00000,2.016544e-10,0.92611,3
107.24400, 27.13333, 2.293918e-02,     88.70676,50.00000,37.00000,2.006874e-10,0.92601,3
107.65600, 28.20000, 7.542849e-02,     88.59662,50.00000,37.00000,2.015763e-10,0.92584,3
108.22900, 29.26667,      0.12348,     88.48867,50.00000,37.00000,2.024403e-10,0.92566,3
108.95600, 30.33333,      0.16611,     88.35368,50.00000,37.00000,2.018204e-10,0.92540,3
109.81500, 31.40000,      0.20183,     88.25249,50.00000,37.00000,2.012539e-10,0.92513,3
110.76000, 32.46667,      0.22998,     88.14453,50.00000,37.00000,2.022190e-10,0.92478,3
111.78400, 33.53333,      0.25171,     87.99602,50.00000,37.00000,2.015190e-10,0.92444,3
112.85200, 34.60000,      0.26702,     87.93539,50.00000,37.00000,2.014789e-10,0.92400,3
113.95100, 35.66667,      0.27671,     87.81392,50.00000,37.00000,2.019310e-10,0.92359,3
115.07700, 36.73333,      0.28361,     87.73976,50.00000,37.00000,2.012271e-10,0.92307,3
116.20300, 37.80000,      0.28737,     87.60477,50.00000,37.00000,2.021350e-10,0.92260,3
117.34200, 38.86667,      0.28782,     87.54175,50.00000,37.00000,2.016049e-10,0.92201,3
118.46100, 39.93333,      0.28695,     87.45845,50.00000,37.00000,2.017497e-10,0.92154,3
119.59400, 41.00000,      0.28657,     87.32366,50.00000,37.00000,2.023544e-10,0.92109,3
120.68500, 42.06667,      0.28305,     87.26958,50.00000,37.00000,2.016239e-10,0.92074,3
121.78500, 43.13333,      0.28168,     87.21789,50.00000,37.00000,2.025871e-10,0.92039,3
122.87800, 44.20000,      0.28064,     87.15706,50.00000,37.00000,2.025909e-10,0.92014,3
123.96700, 45.26667,      0.27911,     87.07614,50.00000,37.00000,2.022037e-10,0.91989,3
125.03700, 46.33333,      0.27790,     86.99523,50.00000,37.00000,2.025299e-10,0.91970,3
126.10500, 47.40000,      0.27686,     86.99523,50.00000,37.00000,2.030716e-10,0.91951,3
127.17400, 48.46667,      0.27583,     86.96819,50.00000,37.00000,2.033691e-10,0.91937,3
128.23500, 49.53333,      0.27612,     86.92107,50.00000,37.00000,2.022476e-10,0.91922,3
129.30600, 50.60000,      0.27608,     86.92107,50.00000,37.00000,2.035808e-10,0.91912,3
130.38000, 51.66667,      0.27572,     86.83996,50.00000,37.00000,2.031879e-10,0.91902,3
131.43500, 52.73333,      0.27635,     86.88270,50.00000,37.00000,2.020454e-10,0.91897,3
132.48100, 53.80000,      0.27631,     86.83320,50.00000,37.00000,2.022363e-10,0.91893,3
133.54100, 54.86667,      0.27878,     86.86481,50.00000,37.00000,2.022591e-10,0.91892,3
134.62000, 55.93333,      0.28009,     86.83777,50.00000,37.00000,1.872941e-10,0.91893,3
135.70000, 57.00000,      0.28057,     86.84672,50.00000,37.00000,1.876773e-10,0.91896,3
136.76300, 58.06667,      0.28222,     86.79960,50.00000,37.00000,1.870232e-10,0.91899,3
137.83099, 59.13333,      0.28203,     86.83320,50.00000,37.00000,1.868877e-10,0.91901,3
138.90300, 60.20000,      0.28235,     86.86024,50.00000,37.00000,1.873665e-10,0.91904,3
139.98399, 61.26667,      0.28384,     86.88946,50.00000,37.00000,1.869011e-10,0.91907,3
141.05299, 62.33333,      0.28366,     86.94573,50.00000,37.00000,1.866665e-10,0.91909,3
142.14400, 63.40000,      0.28298,     86.93221,50.00000,37.00000,1.866950e-10,0.91912,3
143.20300, 64.46667,      0.28079,     86.91869,50.00000,37.00000,1.868267e-10,0.91914,3
144.26700, 65.53333,      0.28129,     86.91869,50.00000,37.00000,1.868973e-10,0.91916,3
145.34900, 66.60000,      0.28162,     86.98628,50.00000,37.00000,1.868668e-10,0.91917,3
146.39900, 67.66667,      0.28144,     86.98628,50.00000,37.00000,1.866531e-10,0.91916,3
147.48100, 68.73333,      0.27909,     87.01093,50.00000,37.00000,1.863480e-10,0.91915,3
148.56599, 69.80000,      0.27774,     87.01093,50.00000,37.00000,1.870269e-10,0.91913,3
149.59900, 70.86667,      0.27521,     87.03121,50.00000,37.00000,1.867352e-10,0.91910,3
150.69299, 71.93333,      0.27538,     87.07177,50.00000,37.00000,1.863822e-10,0.91906,3
151.76100, 73.00000,      0.27471,     87.07853,50.00000,37.00000,1.869831e-10,0.91902,3
152.81300, 74.06667,      0.27285,     87.11670,50.00000,37.00000,1.867180e-10,0.91895,3
153.89200, 75.13333,      0.27251,     87.13022,50.00000,37.00000,1.871013e-10,0.91890,3
154.95700, 76.20000,      0.27235,     87.14374,50.00000,38.00000,1.874847e-10,0.91881,3
156.03700, 77.26667,      0.27083,     87.17296,50.00000,38.00000,1.865311e-10,0.91874,3
157.10699, 78.33333,      0.26746,     87.19980,50.00000,38.00000,1.870670e-10,0.91865,3
158.17700, 79.40000,      0.26797,     87.22684,50.00000,38.00000,1.868687e-10,0.91856,3
159.24300, 80.46667,      0.26578,     87.22684,50.00000,38.00000,1.866456e-10,0.91845,3
160.31100, 81.53333,      0.26629,     87.23817,50.00000,38.00000,1.870956e-10,0.91836,3
161.36501, 82.60000,      0.26342,     87.25845,50.00000,38.00000,1.866359e-10,0.91824,3
162.42400, 83.66667,      0.26088,     87.31690,50.00000,38.00000,1.867218e-10,0.91812,3
163.49400, 84.73333,      0.25834,     87.31014,50.00000,38.00000,1.874675e-10,0.91799,3
164.56599, 85.80000,      0.25564,     87.38887,50.00000,37.00000,1.876011e-10,0.91788,3
165.60800, 86.86667,      0.25496,     87.41809,50.00000,37.00000,1.867160e-10,0.91773,3
166.67400, 87.93333,      0.25446,     87.42247,50.00000,37.00000,1.869354e-10,0.91761,3
167.73801, 89.00000,      0.25225,     87.44950,50.00000,37.00000,1.878185e-10,0.91746,3
168.80400, 90.06667,      0.25056,     87.46978,50.00000,37.00000,1.867275e-10,0.91733,3
169.87801, 91.13333,      0.25040,     87.49682,50.00000,37.00000,1.874351e-10,0.91718,3
170.94099, 92.20000,      0.24751,     87.52386,50.00000,37.00000,1.864452e-10,0.91704,3
172.00900, 93.26667,      0.24598,     87.52386,50.00000,37.00000,1.874904e-10,0.91688,3
173.07401, 94.33333,      0.24155,     87.55070,50.00000,37.00000,1.871605e-10,0.91674,3
174.13800, 95.40000,      0.24156,     87.55070,50.00000,37.00000,1.867848e-10,0.91658,3
175.22000, 96.46667,      0.24123,     87.57992,50.00000,37.00000,1.866589e-10,0.91644,3
176.28300, 97.53333,      0.23901,     87.63181,50.00000,37.00000,1.864644e-10,0.91627,3
177.35500, 98.60000,      0.23611,     87.65865,50.00000,38.00000,1.869851e-10,0.91613,3
178.42400, 99.66667,      0.23458,     87.64533,50.00000,38.00000,1.875687e-10,0.91596,3
179.48801,100.73333,      0.23459,     87.67217,50.00000,37.00000,1.866150e-10,0.91581,3
180.57001,101.80000,      0.22722,     87.71054,50.00000,37.00000,1.868019e-10,0.91564,3
181.63100,102.86667,      0.22397,     87.71054,50.00000,37.00000,1.867409e-10,0.91550,3
182.69299,103.93333,      0.22053,     87.73738,50.00000,37.00000,1.874026e-10,0.91533,3
183.75301,105.00000,      0.21727,     87.73062,50.00000,37.00000,1.871109e-10,0.91516,3
184.81400,106.06667,      0.21451,     87.75765,50.00000,37.00000,1.866989e-10,0.91501,3
185.89101,107.13333,      0.21124,     87.79821,50.00000,37.00000,1.881675e-10,0.91486,3
186.95900,108.20000,      0.20693,     87.79821,50.00000,37.00000,1.871720e-10,0.91469,3
188.01401,109.26667,      0.20382,     87.79821,50.00000,37.00000,1.881122e-10,0.91454,3
189.10100,110.33333,      0.20123,     87.85209,50.00000,38.00000,1.876888e-10,0.91436,3
190.15199,111.40000,      0.19724,     87.81392,50.00000,38.00000,1.878319e-10,0.91421,3
191.23000,112.46667,      0.19360,     87.83638,50.00000,38.00000,1.871529e-10,0.91404,3
192.29500,113.53333,      0.19048,     87.88588,50.00000,38.00000,1.876355e-10,0.91386,3
193.37601,114.60000,      0.18510,     87.91292,50.00000,38.00000,1.875839e-10,0.91371,3
194.42200,115.66667,      0.18040,     87.93320,50.00000,38.00000,1.874542e-10,0.91353,3
195.52499,116.73333,      0.17622,     87.90616,50.00000,38.00000,1.878262e-10,0.91337,3
196.57001,117.80000,      0.16960,     87.93996,50.00000,38.00000,1.877632e-10,0.91320,3
197.63499,118.86667,      0.16505,     87.96461,50.00000,38.00000,1.875763e-10,0.91305,3
198.69800,119.93333,      0.15980,     88.02306,50.00000,38.00000,1.878681e-10,0.91286,3
199.77299,121.00000,      0.15594,     87.97356,50.00000,38.00000,1.871834e-10,0.91271,3
200.81700,122.06667,      0.15102,     88.01869,50.00000,38.00000,1.877117e-10,0.91253,3
201.89200,123.13333,      0.14679,     88.02763,50.00000,38.00000,1.877746e-10,0.91236,3
202.96201,124.20000,      0.14239,     88.07475,50.00000,38.00000,1.874962e-10,0.91218,3
204.02699,125.26667,      0.13675,     88.06799,50.00000,38.00000,1.874924e-10,0.91203,3
205.08701,126.33333,      0.12988,     88.02525,50.00000,38.00000,1.870994e-10,0.91184,3
206.14600,127.40000,      0.12509,     88.09960,50.00000,38.00000,1.872596e-10,0.91169,3
207.23199,128.46667,      0.12101,     88.18728,50.00000,38.00000,1.873684e-10,0.91149,3
208.29500,129.53333,      0.11673,     88.08390,50.00000,38.00000,1.877651e-10,0.91133,3
209.37500,130.60000,      0.11158,     88.13101,50.00000,38.00000,1.884461e-10,0.91114,3
210.42799,131.66667,      0.10571,     88.13101,50.00000,38.00000,1.883297e-10,0.91098,3
211.49800,132.73333,      0.10124,     88.16700,50.00000,38.00000,1.880207e-10,0.91078,3
212.57201,133.80000, 9.447085e-02,     88.18728,50.00000,38.00000,1.874676e-10,0.91063,3
213.62700,134.86667, 8.681022e-02,     88.21650,50.00000,38.00000,1.882877e-10,0.91043,3
214.68600,135.93333, 8.354227e-02,     88.23459,50.00000,38.00000,1.882896e-10,0.91026,3
215.75900,137.00000, 7.744689e-02,     88.24791,50.00000,38.00000,1.886082e-10,0.91007,3
216.83501,138.06667, 7.222336e-02,     88.28847,50.00000,38.00000,1.883545e-10,0.90991,3
217.89799,139.13333, 6.663582e-02,     88.27495,50.00000,38.00000,1.882210e-10,0.90971,3
218.94501,140.20000, 6.068319e-02,     88.27495,50.00000,38.00000,1.881695e-10,0.90954,3
220.01900,141.26667, 5.401255e-02,     88.34254,50.00000,38.00000,1.880589e-10,0.90933,3
221.07401,142.33333, 4.927820e-02,     88.36938,50.00000,38.00000,1.875782e-10,0.90916,3
222.13699,143.40000, 4.613216e-02,     88.35825,50.00000,38.00000,1.877994e-10,0.90896,3
223.21201,144.46667, 3.978376e-02,     88.35825,50.00000,38.00000,1.875248e-10,0.90878,3
224.27901,145.53333, 3.395606e-02,     88.38966,50.00000,38.00000,1.882000e-10,0.90861,3
225.34300,146.60000, 2.687126e-02,     88.36262,50.00000,38.00000,1.877575e-10,0.90840,3
226.42599,147.66667, 2.101987e-02,     88.41670,50.00000,38.00000,1.881085e-10,0.90822,3
227.48199,148.73333, 1.444312e-02,     88.43241,50.00000,38.00000,1.872368e-10,0.90801,3
228.53900,149.80000, 9.638291e-03,     88.46163,50.00000,38.00000,1.874656e-10,0.90784,3
229.60800,150.86667, 2.858667e-03,     88.44135,50.00000,38.00000,1.879006e-10,0.90763,3
230.67300,151.93333,-3.040397e-03,     88.48191,50.00000,38.00000,1.881751e-10,0.90744,3
231.75200,153.00000,-1.127892e-02,     88.49543,50.00000,38.00000,1.880894e-10,0.90723,3
232.80901,154.06667,-1.487454e-02,     88.53598,50.00000,38.00000,1.869621e-10,0.90704,3
233.88400,155.13333,-1.991298e-02,     88.52247,50.00000,38.00000,1.882649e-10,0.90683,3
234.95200,156.20000,-2.873295e-02,     88.54493,50.00000,38.00000,1.881046e-10,0.90665,3
236.02200,157.26667,-3.541411e-02,     88.59205,50.00000,38.00000,1.879139e-10,0.90643,3
237.09399,158.33333,-4.390891e-02,     88.58986,50.00000,38.00000,1.877784e-10,0.90624,3
238.16299,159.40000,-4.827819e-02,     88.58986,50.00000,38.00000,1.882992e-10,0.90602,3
239.22200,160.46667,-5.680385e-02,     88.60795,50.00000,38.00000,1.875763e-10,0.90583,3
240.28900,161.53333,-6.300124e-02,     88.64831,50.00000,38.00000,1.882992e-10,0.90562,3
241.35201,162.60000,-7.481360e-02,     88.64831,50.00000,38.00000,1.879349e-10,0.90543,3
242.41701,163.66667,-7.941529e-02,     88.66859,50.00000,38.00000,1.884861e-10,0.90521,3
243.48100,164.73333,-8.819205e-02,     88.67316,50.00000,38.00000,1.876564e-10,0.90501,3
244.55099,165.80000,-9.136847e-02,     88.67316,50.00000,38.00000,1.884232e-10,0.90478,3
245.61200,166.86667,-9.908816e-02,     88.68668,50.00000,38.00000,1.896019e-10,0.90460,3
246.66901,167.93333,     -0.10846,     88.72704,50.00000,38.00000,1.884633e-10,0.90437,3
247.74300,169.00000,     -0.11603,     88.73380,50.00000,38.00000,1.885146e-10,0.90418,3
248.80901,170.06667,     -0.12253,     88.76083,50.00000,38.00000,1.882457e-10,0.90395,3
249.87100,171.13333,     -0.13160,     88.73380,50.00000,38.00000,1.883354e-10,0.90375,3
250.95300,172.20000,     -0.13758,     88.76083,50.00000,38.00000,1.885624e-10,0.90352,3
252.00700,173.26667,     -0.14778,     88.75408,50.00000,38.00000,1.886482e-10,0.90332,3
253.07700,174.33333,     -0.15361,     88.75408,50.00000,38.00000,1.884879e-10,0.90309,3
254.15401,175.40000,     -0.15946,     88.80815,50.00000,38.00000,1.892643e-10,0.90289,3
255.20900,176.46667,     -0.17081,     88.77435,50.00000,38.00000,1.884059e-10,0.90266,3
256.27200,177.53333,     -0.17797,     88.80139,50.00000,38.00000,1.894093e-10,0.90246,3
257.35001,178.60000,     -0.18773,     88.80139,50.00000,38.00000,1.894054e-10,0.90222,3
258.40100,179.66667,     -0.19400,     88.80815,50.00000,38.00000,1.892738e-10,0.90203,3
259.46399,180.73333,     -0.20011,     88.84851,50.00000,38.00000,1.903858e-10,0.90177,3
260.53799,181.80000,     -0.21250,     88.82823,50.00000,38.00000,1.891574e-10,0.90159,3
261.60800,182.86667,     -0.22013,     88.85527,50.00000,38.00000,1.901150e-10,0.90138,3
262.67001,183.93333,     -0.22851,     88.87097,50.00000,38.00000,1.901303e-10,0.90114,3
263.74500,185.00000,     -0.23728,     88.90477,50.00000,38.00000,1.898041e-10,0.90093,3
264.79901,186.06667,     -0.24588,     88.87773,50.00000,38.00000,1.893310e-10,0.90069,3
265.86401,187.13333,     -0.25617,     88.88449,50.00000,38.00000,1.900158e-10,0.90048,3
266.93600,188.20000,     -0.26055,     88.90477,50.00000,38.00000,1.896229e-10,0.90024,3
267.98999,189.26667,     -0.27106,     88.94751,50.00000,38.00000,1.900139e-10,0.90004,3
269.07001,190.33333,     -0.27845,     88.90696,50.00000,38.00000,1.903038e-10,0.89979,3
270.13501,191.40000,     -0.29014,     88.93400,50.00000,38.00000,1.899623e-10,0.89958,3
271.18600,192.46667,     -0.29867,     88.94533,50.00000,38.00000,1.906986e-10,0.89933,3
272.26801,193.53333,     -0.30500,     88.91153,50.00000,38.00000,1.898823e-10,0.89912,3
273.33499,194.60000,     -0.31377,     88.91372,50.00000,38.00000,1.896763e-10,0.89887,3
274.39999,195.66667,     -0.32331,     88.92724,50.00000,38.00000,1.901283e-10,0.89866,3
275.46500,196.73333,     -0.33175,     88.91372,50.00000,38.00000,1.902904e-10,0.89840,3
276.53400,197.80000,     -0.34077,     88.91372,50.00000,38.00000,1.901436e-10,0.89819,3
277.59201,198.86667,     -0.35169,     88.93400,50.00000,38.00000,1.903973e-10,0.89793,3
278.65601,199.93333,     -0.36075,     88.94076,50.00000,38.00000,1.904086e-10,0.89771,3
279.73801,201.00000,     -0.36872,     88.93181,50.00000,38.00000,1.901760e-10,0.89747,3
280.79901,202.06667,     -0.37802,     88.95209,50.00000,38.00000,1.901951e-10,0.89725,3
281.87000,203.13333,     -0.38640,     88.92505,50.00000,38.00000,1.900978e-10,0.89699,3
282.92801,204.20000,     -0.39915,     88.90477,50.00000,38.00000,1.894646e-10,0.89676,3
283.98999,205.26667,     -0.40776,     88.87097,50.00000,38.00000,1.899166e-10,0.89652,3
285.06100,206.33333,     -0.41489,     88.87097,50.00000,38.00000,1.896859e-10,0.89629,3
286.12201,207.40000,     -0.42430,     88.88449,50.00000,38.00000,1.896744e-10,0.89603,3
287.19299,208.46667,     -0.43336,     88.86421,50.00000,38.00000,1.905708e-10,0.89581,3
288.27200,209.53333,     -0.44530,     88.85527,50.00000,38.00000,1.903496e-10,0.89554,3
289.30301,210.60000,     -0.45839,     88.82823,50.00000,38.00000,1.900291e-10,0.89532,3
290.37900,211.66667,     -0.46163,     88.81471,50.00000,38.00000,1.902523e-10,0.89506,3
291.44501,212.73333,     -0.47937,     88.80139,50.00000,38.00000,1.905708e-10,0.89485,3
292.55301,213.80000,     -0.48744,     88.78787,50.00000,38.00000,1.905556e-10,0.89458,3
293.56500,214.86667,     -0.50235,     88.74732,50.00000,38.00000,1.909332e-10,0.89435,3
294.64099,215.93333,     -0.50203,     88.74732,50.00000,38.00000,1.904430e-10,0.89409,3
295.73599,217.00000,     -0.51954,     88.69344,50.00000,38.00000,1.905880e-10,0.89385,3
296.78601,218.06667,     -0.53285,     88.66640,50.00000,38.00000,1.904983e-10,0.89359,3
297.84299,219.13333,     -0.54024,     88.66640,50.00000,38.00000,1.915798e-10,0.89337,3
298.92401,220.20000,     -0.54921,     88.63260,50.00000,38.00000,1.907062e-10,0.89308,3
299.99200,221.26667,     -0.55838,     88.62147,50.00000,38.00000,1.913433e-10,0.89286,3
301.04599,222.33333,     -0.57200,     88.53360,50.00000,38.00000,1.904334e-10,0.89259,3
302.10800,223.40000,     -0.58122,     88.50676,50.00000,38.00000,1.911430e-10,0.89236,3
303.17499,224.46667,     -0.59163,     88.45268,50.00000,38.00000,1.917419e-10,0.89208,3
304.23300,225.53333,     -0.60109,     88.42127,50.00000,38.00000,1.914807e-10,0.89185,3
305.30499,226.60000,     -0.61214,     88.38748,50.00000,38.00000,1.910362e-10,0.89157,3
306.36899,227.66667,     -0.62127,     88.33340,50.00000,38.00000,1.915226e-10,0.89134,3
307.44400,228.73333,     -0.63277,     88.22545,50.00000,39.00000,1.918850e-10,0.89106,3
308.51401,229.80000,     -0.64546,     88.17157,50.00000,39.00000,1.916656e-10,0.89082,3
309.58099,230.86667,     -0.65740,     88.11750,50.00000,39.00000,1.919842e-10,0.89054,3
310.63901,231.93333,     -0.66468,     88.00954,50.00000,39.00000,1.920986e-10,0.89030,3
311.72000,233.00000,     -0.67728,     87.92863,50.00000,39.00000,1.918869e-10,0.89002,3
312.78500,234.06667,     -0.68774,     87.87455,50.00000,39.00000,1.922685e-10,0.88978,3
313.85001,235.13333,     -0.69921,     87.78012,50.00000,39.00000,1.926460e-10,0.88949,3
314.92899,236.20000,     -0.71112,     87.67217,50.00000,39.00000,1.926670e-10,0.88926,3
315.98300,237.26667,     -0.72166,     87.57097,50.00000,39.00000,1.919402e-10,0.88898,3
317.05899,238.33333,     -0.73029,     87.49006,50.00000,39.00000,1.923542e-10,0.88873,3
318.13000,239.40000,     -0.74602,     87.34831,50.00000,39.00000,1.926193e-10,0.88845,3
319.19101,240.46667,     -0.75942,     87.21332,50.00000,39.00000,1.929913e-10,0.88820,3
320.25299,241.53333,     -0.76791,     87.07853,50.00000,39.00000,1.930084e-10,0.88791,3
321.32101,242.60000,     -0.78119,     86.93002,50.00000,39.00000,1.927968e-10,0.88767,3
322.39301,243.66667,     -0.79390,     86.82207,50.00000,39.00000,1.928291e-10,0.88738,3
323.46399,244.73333,     -0.80566,     86.60616,50.00000,39.00000,1.927395e-10,0.88713,3
324.52200,245.80000,     -0.81566,     86.41491,50.00000,39.00000,1.930218e-10,0.88683,3
325.58600,246.86667,     -0.82548,     86.22604,50.00000,39.00000,1.933173e-10,0.88658,3
326.65201,247.93333,     -0.83832,     86.03698,50.00000,39.00000,1.924896e-10,0.88630,3
327.72198,249.00000,     -0.85120,     85.80099,50.00000,39.00000,1.931896e-10,0.88604,3
328.79199,250.06667,     -0.86072,     85.56243,50.00000,39.00000,1.933060e-10,0.88576,3
329.85501,251.13333,     -0.87406,     85.31730,50.00000,39.00000,1.929226e-10,0.88549,3
330.92401,252.20000,     -0.88244,     85.04513,50.00000,39.00000,1.927604e-10,0.88520,3
331.98801,253.26667,     -0.89384,     84.77296,50.00000,39.00000,1.932449e-10,0.88492,3
333.04999,254.33333,     -0.90426,     84.55944,50.00000,39.00000,1.933975e-10,0.88464,3
334.13800,255.40000,     -0.91314,     84.17932,50.00000,39.00000,1.930923e-10,0.88439,3
335.17700,256.46667,     -0.92400,     83.79245,50.00000,39.00000,1.929817e-10,0.88409,3
336.24899,257.53333,     -0.93512,     83.40557,50.00000,39.00000,1.937160e-10,0.88383,3
337.30200,258.60000,     -0.93718,     83.02545,50.00000,39.00000,1.937294e-10,0.88354,3
338.37701,259.66667,     -0.95240,     82.61153,50.00000,39.00000,1.939945e-10,0.88328,3
339.44199,260.73333,     -0.96198,     82.12346,50.00000,39.00000,1.934243e-10,0.88298,3
340.52301,261.80000,     -0.96938,     81.62187,50.00000,39.00000,1.936588e-10,0.88273,3
341.59698,262.86667,     -0.98187,     81.06183,50.00000,39.00000,1.934662e-10,0.88242,3
342.66101,263.93333,     -0.99072,     80.52664,50.00000,39.00000,1.939030e-10,0.88217,3
343.71799,265.00000,     -1.00182,     79.93738,50.00000,39.00000,1.942024e-10,0.88190,3
344.79099,266.06667,     -1.00747,     79.26481,50.00000,39.00000,1.936950e-10,0.88160,3
345.84698,267.13333,     -1.01557,     78.55169,50.00000,39.00000,1.942253e-10,0.88134,3
346.90201,268.20000,     -1.02634,     77.79165,50.00000,39.00000,1.944656e-10,0.88102,3
347.97198,269.26667,     -1.03143,     77.01332,50.00000,39.00000,1.937294e-10,0.88077,3
349.04199,270.33333,     -1.03511,     76.18569,50.00000,39.00000,1.935024e-10,0.88046,3
350.11499,271.40000,     -1.05089,     75.27694,50.00000,39.00000,1.942939e-10,0.88019,3
351.18301,272.46667,     -1.05481,     74.28728,50.00000,39.00000,1.944294e-10,0.87988,3
352.23499,273.53333,     -1.06406,     73.29761,50.00000,39.00000,1.944866e-10,0.87962,3
353.29999,274.60000,     -1.07005,     72.20915,50.00000,39.00000,1.942520e-10,0.87930,3
354.35800,275.66667,     -1.07255,     71.08231,50.00000,39.00000,1.943779e-10,0.87904,3
355.43799,276.73333,     -1.08067,     69.82505,50.00000,39.00000,1.947632e-10,0.87872,3
356.49899,277.80000,     -1.08505,     68.50696,50.00000,39.00000,1.944161e-10,0.87845,3
357.56799,278.86667,     -1.09070,     67.10338,50.00000,39.00000,1.949024e-10,0.87814,3
358.63599,279.93333,     -1.09802,     65.62127,50.00000,39.00000,1.946507e-10,0.87787,3
359.71301,281.00000,     -1.10808,     64.08270,50.00000,39.00000,1.957149e-10,0.87755,3
360.75699,282.06667,     -1.12269,     62.43181,50.00000,39.00000,1.948471e-10,0.87729,3
361.82199,283.13333,     -1.12925,     60.71571,50.00000,39.00000,1.951523e-10,0.87696,3
362.89099,284.20000,     -1.14042,     58.92982,50.00000,39.00000,1.953048e-10,0.87669,3
363.95099,285.26667,     -1.15181,     57.02942,50.00000,39.00000,1.945495e-10,0.87637,3
365.01901,286.33333,     -1.16200,     55.03658,50.00000,39.00000,1.948852e-10,0.87609,3
366.09601,287.40000,     -1.17641,     52.95388,50.00000,39.00000,1.953392e-10,0.87578,3
367.14999,288.46667,     -1.19335,     50.83738,50.00000,39.00000,1.950206e-10,0.87549,3
368.21301,289.53333,     -1.21118,     48.60616,50.00000,39.00000,1.952668e-10,0.87517,3
369.28799,290.60000,     -1.22173,     46.32107,50.00000,39.00000,1.947784e-10,0.87485,3
370.34799,291.66667,     -1.24575,     43.89404,50.00000,39.00000,1.952514e-10,0.87456,3
371.43301,292.73333,     -1.25597,     41.46044,50.00000,39.00000,1.952820e-10,0.87429,3
372.49500,293.80000,     -1.28327,     38.97972,50.00000,39.00000,1.948128e-10,0.87397,3
373.56500,294.86667,     -1.30433,     36.48529,50.00000,39.00000,1.958198e-10,0.87369,3
374.62900,295.93333,     -1.34491,     33.95507,50.00000,39.00000,1.955318e-10,0.87336,3
375.69601,297.00000,     -1.36907,     31.40437,50.00000,39.00000,1.956806e-10,0.87307,3
376.76700,298.06667,     -1.40138,     28.88310,50.00000,39.00000,1.957283e-10,0.87276,3
377.82901,299.13333,     -1.43780,     26.35050,50.00000,39.00000,1.964836e-10,0.87244,3
378.88699,300.20000,     -1.47942,     23.90119,50.00000,39.00000,1.965427e-10,0.87216,3
379.96399,301.26667,     -1.52077,     21.47873,50.00000,39.00000,1.964321e-10,0.87182,3
381.02701,302.33333,     -1.56541,     19.12167,50.00000,39.00000,1.965866e-10,0.87153,3
382.10901,303.40000,     -1.61021,     16.91750,50.00000,39.00000,1.968079e-10,0.87121,3
383.17099,304.46667,     -1.65831,     14.79642,50.00000,39.00000,1.965866e-10,0.87091,3
384.23001,305.53333,     -1.71105,     12.81948,50.00000,39.00000,1.964302e-10,0.87059,3
385.28601,306.60000,     -1.75597,     10.92326,50.00000,39.00000,1.969757e-10,0.87031,3
386.36200,307.66667,     -1.81440,      9.19145,50.00000,39.00000,1.960907e-10,0.86997,3
387.43500,308.73333,     -1.86912,      7.59463,50.00000,39.00000,1.967793e-10,0.86968,3
388.50500,309.80000,     -1.91470,      6.13936,50.00000,39.00000,1.961231e-10,0.86935,3
389.56400,310.86667,     -1.96406,      4.81690,50.00000,39.00000,1.968288e-10,0.86906,3
390.63699,311.93333,     -2.02419,      3.67197,50.00000,39.00000,1.967811e-10,0.86872,3
391.70001,313.00000,     -2.08728,      2.62604,50.00000,39.00000,1.970025e-10,0.86844,3
392.77301,314.06667,     -2.15599,      1.68370,50.00000,39.00000,1.966304e-10,0.86809,3
393.83401,315.13333,     -2.21336,      0.86282,50.00000,39.00000,1.972542e-10,0.86781,3
394.90399,316.20000,     -2.26699,      0.15427,50.00000,39.00000,1.966132e-10,0.86747,3
395.95401,317.26667,     -2.31962,     -0.44851,50.00000,39.00000,1.974965e-10,0.86718,3
397.03601,318.33333,     -2.37098,     -1.02207,50.00000,39.00000,1.964511e-10,0.86689,3
398.09399,319.40000,     -2.42196,     -1.45169,50.00000,40.00000,1.961270e-10,0.86654,3
399.15900,320.46667,     -2.47026,     -1.81829,50.00000,39.00000,1.978588e-10,0.86625,3
399.67300,320.97833,     -2.49429,     -2.00716,50.00000,40.00000,1.970730e-10,0.86606,4
399.81000,321.05833,     -2.46957,     -2.00716,50.00000,40.00000,1.970730e-10,0.86606,4
400.05099,321.13833,     -2.31771,     -2.00716,50.00000,40.00000,1.970730e-10,0.86606,4
400.47198,321.21833,     -2.00827,     -2.00716,50.00000,39.00000,1.970062e-10,0.86600,4
401.05600,321.29833,     -1.54752,     -1.94652,50.00000,40.00000,1.970062e-10,0.86600,4
401.83499,321.37833,     -0.95438,     -1.91948,50.00000,39.00000,1.974792e-10,0.86595,4
402.79700,321.45833,     -0.24951,     -1.84970,50.00000,39.00000,1.974792e-10,0.86595,4
403.91901,321.53833,      0.52597,     -1.73956,50.00000,40.00000,1.971836e-10,0.86591,4
405.20999,321.61833,      1.33319,     -1.63618,50.00000,40.00000,1.971836e-10,0.86591,4
406.61301,321.69833,      2.13912,     -1.54155,50.00000,40.00000,1.972237e-10,0.86585,4
408.10599,321.77833,      2.91057,     -1.47416,50.00000,40.00000,1.972237e-10,0.86585,4
409.67099,321.85833,      3.61315,     -1.41113,50.00000,40.00000,1.971454e-10,0.86581,4
411.28201,321.93833,      4.23044,     -1.35944,50.00000,40.00000,1.971454e-10,0.86581,4
412.90701,322.01833,      4.74397,     -1.30318,50.00000,40.00000,1.968593e-10,0.86574,4
414.53000,322.09833,      5.15028,     -1.27614,50.00000,40.00000,1.968593e-10,0.86574,4
416.12799,322.17833,      5.44648,     -1.27614,50.00000,39.00000,1.973705e-10,0.86571,4
417.69501,322.25833,      5.63694,     -1.24930,50.00000,39.00000,1.973705e-10,0.86571,4
419.22299,322.33833,      5.73932,     -1.24930,50.00000,40.00000,1.975403e-10,0.86566,4
420.71500,322.41833,      5.76053,     -1.24930,50.00000,39.00000,1.975403e-10,0.86566,4
422.15201,322.49833,      5.71797,     -1.27614,50.00000,40.00000,1.968632e-10,0.86560,4
423.55801,322.57833,      5.62933,     -1.27614,50.00000,40.00000,1.968632e-10,0.86560,4
424.92001,322.65833,      5.50988,     -1.30318,50.00000,40.00000,1.971340e-10,0.86556,4
426.27301,322.73833,      5.37539,     -1.33022,50.00000,40.00000,1.971340e-10,0.86556,4
427.59799,322.81833,      5.23952,     -1.38648,50.00000,40.00000,1.969719e-10,0.86551,4
428.90701,322.89833,      5.11418,     -1.38648,50.00000,40.00000,1.969719e-10,0.86551,4
430.22299,322.97833,      5.01147,     -1.41332,50.00000,40.00000,1.972294e-10,0.86546,4
431.56201,323.05833,      4.93344,     -1.44036,50.00000,40.00000,1.972294e-10,0.86546,4
432.89401,323.13833,      4.88573,     -1.46064,50.00000,40.00000,1.971950e-10,0.86542,4
434.26700,323.21833,      4.87021,     -1.46740,50.00000,40.00000,1.971950e-10,0.86542,4
435.64301,323.29833,      4.88381,     -1.49443,50.00000,40.00000,1.972999e-10,0.86537,4
437.06000,323.37833,      4.93132,     -1.49443,50.00000,40.00000,1.972999e-10,0.86537,4
438.50800,323.45833,      5.00179,     -1.49443,50.00000,40.00000,1.975631e-10,0.86531,4
439.99100,323.53833,      5.09587,     -1.52147,50.00000,40.00000,1.975631e-10,0.86531,4
441.48099,323.61833,      5.20539,     -1.52147,50.00000,40.00000,1.963958e-10,0.86526,4
443.02600,323.69833,      5.32430,     -1.52147,50.00000,40.00000,1.963958e-10,0.86526,4
444.57700,323.77833,      5.44768,     -1.49443,50.00000,40.00000,1.975517e-10,0.86522,4
446.15201,323.85833,      5.56869,     -1.49443,50.00000,40.00000,1.975517e-10,0.86522,4
447.75299,323.93833,      5.68593,     -1.48767,50.00000,40.00000,1.971264e-10,0.86516,4
449.37100,324.01833,      5.79278,     -1.46740,50.00000,40.00000,1.971264e-10,0.86516,4
450.99301,324.09833,      5.88508,     -1.46740,50.00000,40.00000,1.974946e-10,0.86511,4
452.61700,324.17833,      5.96883,     -1.46740,50.00000,40.00000,1.974946e-10,0.86511,4
454.25800,324.25833,      6.03537,     -1.44036,50.00000,40.00000,1.975174e-10,0.86508,4
455.89600,324.33833,      6.08633,     -1.41332,50.00000,40.00000,1.975174e-10,0.86508,4
457.54300,324.41833,      6.12358,     -1.41332,50.00000,40.00000,1.972141e-10,0.86502,4
459.17999,324.49833,      6.14854,     -1.40676,50.00000,40.00000,1.972141e-10,0.86502,4
460.82101,324.57833,      6.16006,     -1.35944,50.00000,40.00000,1.976089e-10,0.86497,4
462.45099,324.65833,      6.15840,     -1.35944,50.00000,40.00000,1.976089e-10,0.86497,4
464.09299,324.73833,      6.14892,     -1.35944,50.00000,40.00000,1.976261e-10,0.86493,4
465.72900,324.81833,      6.13619,     -1.33022,50.00000,40.00000,1.976261e-10,0.86493,4
467.36600,324.89833,      6.11833,     -1.30318,50.00000,40.00000,1.975136e-10,0.86487,4
469.01300,324.97833,      6.09780,     -1.27614,50.00000,40.00000,1.975136e-10,0.86487,4
470.64999,325.05833,      6.07657,     -1.27614,50.00000,40.00000,1.975136e-10,0.86487,4
472.28601,325.13833,      6.05688,     -1.24930,50.00000,40.00000,1.970902e-10,0.86482,4
473.92599,325.21833,      6.03540,     -1.24930,50.00000,40.00000,1.970902e-10,0.86482,4
475.56299,325.29833,      6.01643,     -1.19523,50.00000,40.00000,1.971779e-10,0.86478,4
477.22299,325.37833,      5.99678,     -1.19523,50.00000,40.00000,1.971779e-10,0.86478,4
478.87799,325.45833,      5.97915,     -1.16819,50.00000,40.00000,1.972714e-10,0.86473,4
480.53000,325.53833,      5.96308,     -1.14135,50.00000,40.00000,1.972714e-10,0.86473,4
482.19699,325.61833,      5.94701,     -1.14135,50.00000,40.00000,1.970424e-10,0.86468,4
483.84601,325.69833,      5.92922,     -1.13459,50.00000,40.00000,1.970424e-10,0.86468,4
485.51001,325.77833,      5.91191,     -1.08509,50.00000,40.00000,1.984501e-10,0.86463,4
487.18399,325.85833,      5.89504,     -1.05805,50.00000,40.00000,1.984501e-10,0.86463,4
488.84698,325.93833,      5.87550,     -1.05805,50.00000,40.00000,1.979237e-10,0.86457,4
490.52899,326.01833,      5.85400,     -1.03101,50.00000,40.00000,1.979237e-10,0.86457,4
492.18500,326.09833,      5.83117,     -1.03101,50.00000,40.00000,1.973705e-10,0.86453,4
493.85901,326.17833,      5.80609,     -1.00398,50.00000,40.00000,1.973705e-10,0.86453,4
495.53299,326.25833,      5.77564,     -0.97714,50.00000,40.00000,1.973591e-10,0.86448,4
497.20499,326.33833,      5.74473,     -0.95010,50.00000,40.00000,1.973591e-10,0.86448,4
498.87500,326.41833,      5.70714,     -0.92306,50.00000,40.00000,1.978626e-10,0.86442,4
500.54099,326.49833,      5.67332,     -0.92306,50.00000,39.00000,1.978626e-10,0.86442,4
502.21100,326.57833,      5.63932,     -0.89602,50.00000,40.00000,1.980896e-10,0.86437,4
503.87601,326.65833,      5.60284,     -0.86918,50.00000,40.00000,1.980896e-10,0.86437,4
505.53400,326.73833,      5.56258,     -0.86918,50.00000,40.00000,1.977482e-10,0.86433,4
507.21399,326.81833,      5.52452,     -0.84215,50.00000,40.00000,1.977482e-10,0.86433,4
508.88199,326.89833,      5.48212,     -0.81511,50.00000,40.00000,1.974086e-10,0.86428,4
510.55099,326.97833,      5.43696,     -0.78807,50.00000,40.00000,1.974086e-10,0.86428,4
512.21399,327.05833,      5.39305,     -0.78807,50.00000,40.00000,1.970234e-10,0.86424,4
513.88000,327.13833,      5.34994,     -0.73419,50.00000,40.00000,1.970234e-10,0.86424,4
515.55103,327.21833,      5.30715,     -0.73419,50.00000,40.00000,1.970768e-10,0.86419,4
517.21399,327.29833,      5.25948,     -0.70716,50.00000,40.00000,1.970768e-10,0.86419,4
518.86798,327.37833,      5.21329,     -0.68012,50.00000,40.00000,1.971969e-10,0.86414,4
520.53198,327.45833,      5.16898,     -0.69364,50.00000,40.00000,1.971969e-10,0.86414,4
522.20300,327.53833,      5.12217,     -0.69364,50.00000,40.00000,1.972999e-10,0.86408,4
523.87201,327.61833,      5.07485,     -0.66660,50.00000,39.00000,1.972999e-10,0.86408,4
525.53003,327.69833,      5.02722,     -0.63976,50.00000,40.00000,1.977558e-10,0.86403,4
527.18597,327.77833,      4.97933,     -0.61272,50.00000,40.00000,1.977558e-10,0.86403,4
528.84998,327.85833,      4.93280,     -0.61272,50.00000,40.00000,1.980056e-10,0.86399,4
530.50201,327.93833,      4.88051,     -0.58569,50.00000,40.00000,1.980056e-10,0.86399,4
532.16602,328.01833,      4.83376,     -0.55865,50.00000,40.00000,1.980056e-10,0.86399,4
533.82703,328.09833,      4.78101,     -0.53181,50.00000,40.00000,1.972046e-10,0.86393,4
535.48798,328.17833,      4.73585,     -0.53181,50.00000,40.00000,1.972046e-10,0.86393,4
537.12402,328.25833,      4.68717,     -0.50258,50.00000,40.00000,1.971874e-10,0.86389,4
538.78699,328.33833,      4.63526,     -0.50258,50.00000,40.00000,1.971874e-10,0.86389,4
540.44299,328.41833,      4.58095,     -0.47555,50.00000,40.00000,1.973687e-10,0.86384,4
542.09698,328.49833,      4.52874,     -0.47555,50.00000,40.00000,1.973687e-10,0.86384,4
543.75800,328.57833,      4.47474,     -0.44851,50.00000,40.00000,1.976795e-10,0.86379,4
545.39301,328.65833,      4.41557,     -0.42147,50.00000,40.00000,1.976795e-10,0.86379,4
547.05499,328.73833,      4.35971,     -0.42147,50.00000,40.00000,1.975575e-10,0.86374,4
548.70203,328.81833,      4.30378,     -0.39463,50.00000,40.00000,1.975575e-10,0.86374,4
550.34900,328.89833,      4.24759,     -0.37435,50.00000,40.00000,1.973724e-10,0.86369,4
551.99298,328.97833,      4.19219,     -0.36759,50.00000,40.00000,1.973724e-10,0.86369,4
553.65100,329.05833,      4.13447,     -0.34056,50.00000,40.00000,1.973610e-10,0.86362,4
555.29999,329.13833,      4.08447,     -0.32704,50.00000,40.00000,1.973610e-10,0.86362,4
556.95599,329.21833,      4.03400,     -0.30676,50.00000,40.00000,1.973934e-10,0.86359,4
558.59998,329.29833,      3.97974,     -0.28648,50.00000,40.00000,1.973934e-10,0.86359,4
560.23700,329.37833,      3.92655,     -0.25964,50.00000,40.00000,1.978588e-10,0.86353,4
561.89099,329.45833,      3.87832,     -0.25964,50.00000,40.00000,1.978588e-10,0.86353,4
563.53302,329.53833,      3.82035,     -0.23260,50.00000,40.00000,1.981201e-10,0.86349,4
565.17499,329.61833,      3.76565,     -0.20557,50.00000,40.00000,1.981201e-10,0.86349,4
566.82098,329.69833,      3.71017,     -0.20557,50.00000,40.00000,1.970043e-10,0.86344,4
568.46399,329.77833,      3.65416,     -0.17853,50.00000,40.00000,1.970043e-10,0.86344,4
570.10303,329.85833,      3.59789,     -0.17853,50.00000,40.00000,1.986179e-10,0.86339,4
571.75897,329.93833,      3.53898,     -0.15169,50.00000,40.00000,1.986179e-10,0.86339,4
573.39099,330.01833,      3.47836,     -0.15169,50.00000,40.00000,1.977844e-10,0.86334,4
575.03198,330.09833,      3.41531,     -0.12465,50.00000,40.00000,1.977844e-10,0.86334,4
576.67798,330.17833,      3.35558,     -0.12465,50.00000,40.00000,1.984424e-10,0.86329,4
578.31201,330.25833,      3.29336,-9.761431e-02,50.00000,40.00000,1.984424e-10,0.86329,4
579.94800,330.33833,      3.23446,-7.057654e-02,50.00000,40.00000,1.974296e-10,0.86324,4
581.58502,330.41833,      3.17365,-7.057654e-02,50.00000,40.00000,1.974296e-10,0.86324,4
583.21503,330.49833,      3.11562,-4.373757e-02,50.00000,40.00000,1.983776e-10,0.86319,4
584.84900,330.57833,      3.05236,-1.669980e-02,50.00000,40.00000,1.983776e-10,0.86319,4
586.48999,330.65833,      2.98915,-1.669980e-02,50.00000,40.00000,1.971569e-10,0.86314,4
588.13000,330.73833,      2.92928,-1.669980e-02,50.00000,40.00000,1.971569e-10,0.86314,4
589.76099,330.81833,      2.86942, 1.033797e-02,50.00000,40.00000,1.971569e-10,0.86314,4
591.39600,330.89833,      2.80905, 3.737575e-02,50.00000,40.00000,1.980247e-10,0.86309,4
593.03302,330.97833,      2.75236, 4.413519e-02,50.00000,40.00000,1.980247e-10,0.86309,4
594.66602,331.05833,      2.69038, 6.421471e-02,50.00000,40.00000,1.974391e-10,0.86304,4
596.30298,331.13833,      2.62873, 9.125249e-02,50.00000,39.00000,1.974391e-10,0.86304,4
597.92700,331.21833,      2.56932, 9.125249e-02,50.00000,40.00000,1.981163e-10,0.86299,4
599.56500,331.29833,      2.50492, 9.125249e-02,50.00000,40.00000,1.981163e-10,0.86299,4
601.19000,331.37833,      2.44673, 9.125249e-02,50.00000,40.00000,1.975765e-10,0.86294,4
602.82202,331.45833,      2.38550,      0.11829,50.00000,40.00000,1.975765e-10,0.86294,4
604.46198,331.53833,      2.32434,      0.14533,50.00000,40.00000,1.973495e-10,0.86289,4
606.08899,331.61833,      2.27000,      0.14533,50.00000,40.00000,1.973495e-10,0.86289,4
607.71198,331.69833,      2.20378,      0.19920,50.00000,40.00000,1.973857e-10,0.86284,4
609.34100,331.77833,      2.13904,      0.22624,50.00000,40.00000,1.973857e-10,0.86284,4
610.97900,331.85833,      2.07435,      0.22624,50.00000,40.00000,1.981049e-10,0.86278,4
612.60498,331.93833,      2.00968,      0.24652,50.00000,40.00000,1.981049e-10,0.86278,4
614.22900,332.01833,      1.94190,      0.25328,50.00000,40.00000,1.975460e-10,0.86273,4
615.85400,332.09833,      1.87473,      0.25328,50.00000,40.00000,1.975460e-10,0.86273,4
617.46997,332.17833,      1.80758,      0.28012,50.00000,40.00000,1.976490e-10,0.86268,4
619.11499,332.25833,      1.74197,      0.30040,50.00000,40.00000,1.976490e-10,0.86268,4
620.71698,332.33833,      1.67257,      0.30716,50.00000,40.00000,1.974926e-10,0.86263,4
622.36102,332.41833,      1.60704,      0.33419,50.00000,40.00000,1.974926e-10,0.86263,4
623.97302,332.49833,      1.54007,      0.33419,50.00000,40.00000,1.975670e-10,0.86258,4
625.60999,332.57833,      1.47521,      0.36123,50.00000,40.00000,1.975670e-10,0.86258,4
627.24200,332.65833,      1.40488,      0.38827,50.00000,40.00000,1.973705e-10,0.86253,4
628.84802,332.73833,      1.33601,      0.38827,50.00000,40.00000,1.973705e-10,0.86253,4
630.47900,332.81833,      1.26548,      0.41511,50.00000,40.00000,1.979332e-10,0.86248,4
632.09698,332.89833,      1.19352,      0.44215,50.00000,40.00000,1.979332e-10,0.86248,4
633.72998,332.97833,      1.12482,      0.44215,50.00000,40.00000,1.977138e-10,0.86243,4
635.35101,333.05833,      1.04973,      0.44215,50.00000,40.00000,1.977138e-10,0.86243,4
636.96997,333.13833,      0.98288,      0.44215,50.00000,40.00000,1.978283e-10,0.86240,4
638.58801,333.21833,      0.91169,      0.46918,50.00000,40.00000,1.978283e-10,0.86240,4
640.20898,333.29833,      0.84320,      0.49622,50.00000,40.00000,1.967430e-10,0.86233,4
641.82397,333.37833,      0.77065,      0.49622,50.00000,40.00000,1.967430e-10,0.86233,4
643.45398,333.45833,      0.69373,      0.50954,50.00000,40.00000,1.975879e-10,0.86229,4
645.06500,333.53833,      0.62304,      0.52306,50.00000,40.00000,1.975879e-10,0.86229,4
646.67499,333.61833,      0.54648,      0.52982,50.00000,40.00000,1.978263e-10,0.86224,4
648.30499,333.69833,      0.47117,      0.55010,50.00000,40.00000,1.978263e-10,0.86224,4
649.92200,333.77833,      0.39680,      0.57714,50.00000,40.00000,1.980820e-10,0.86218,4
651.53998,333.85833,      0.32366,      0.57714,50.00000,40.00000,1.980820e-10,0.86218,4
653.14600,333.93833,      0.24909,      0.60417,50.00000,40.00000,1.982250e-10,0.86213,4
654.77301,334.01833,      0.17698,      0.62425,50.00000,40.00000,1.982250e-10,0.86213,4
656.39899,334.09833,      0.10074,      0.65129,50.00000,40.00000,1.979256e-10,0.86209,4
658.00299,334.17833, 2.305353e-02,      0.65805,50.00000,40.00000,1.979256e-10,0.86209,4
659.62299,334.25833,-5.277793e-02,      0.65805,50.00000,40.00000,1.977787e-10,0.86203,4
661.23798,334.33833,     -0.12735,      0.68509,50.00000,40.00000,1.977787e-10,0.86203,4
662.84601,334.41833,     -0.20426,      0.71213,50.00000,40.00000,1.969032e-10,0.86198,4
664.46198,334.49833,     -0.28021,      0.71213,50.00000,40.00000,1.969032e-10,0.86198,4
666.09302,334.57833,     -0.35731,      0.71889,50.00000,40.00000,1.976680e-10,0.86193,4
667.70502,334.65833,     -0.43373,      0.73897,50.00000,40.00000,1.976680e-10,0.86193,4
669.32599,334.73833,     -0.50798,      0.73897,50.00000,40.00000,1.972828e-10,0.86189,4
670.94702,334.81833,     -0.58639,      0.76600,50.00000,40.00000,1.972828e-10,0.86189,4
672.56598,334.89833,     -0.66353,      0.79304,50.00000,40.00000,1.975956e-10,0.86184,4
674.17499,334.97833,     -0.73877,      0.79304,50.00000,40.00000,1.975956e-10,0.86184,4
675.79602,335.05833,     -0.82460,      0.79304,50.00000,40.00000,1.975956e-10,0.86184,4
677.40399,335.13833,     -0.91435,      0.79304,50.00000,40.00000,1.981850e-10,0.86179,4
679.02600,335.21833,     -0.99399,      0.82008,50.00000,40.00000,1.981850e-10,0.86179,4
680.62701,335.29833,     -1.07599,      0.84692,50.00000,40.00000,1.980686e-10,0.86173,4
682.24701,335.37833,     -1.15673,      0.84692,50.00000,40.00000,1.980686e-10,0.86173,4
683.86499,335.45833,     -1.23923,      0.87396,50.00000,40.00000,1.984959e-10,0.86169,4
685.50000,335.53833,     -1.31801,      0.87396,50.00000,40.00000,1.984959e-10,0.86169,4
687.08801,335.61833,     -1.40097,      0.90099,50.00000,40.00000,1.973571e-10,0.86164,4
688.70398,335.69833,     -1.47742,      0.92803,50.00000,40.00000,1.973571e-10,0.86164,4
690.31500,335.77833,     -1.57015,      0.92803,50.00000,40.00000,1.977730e-10,0.86159,4
691.93500,335.85833,     -1.64893,      0.95507,50.00000,40.00000,1.977730e-10,0.86159,4
693.54602,335.93833,     -1.72483,      0.95507,50.00000,40.00000,1.975041e-10,0.86154,4
695.16901,336.01833,     -1.80439,      0.98191,50.00000,40.00000,1.975041e-10,0.86154,4
696.78198,336.09833,     -1.88509,      1.00895,50.00000,40.00000,1.981106e-10,0.86149,4
698.39203,336.17833,     -1.95979,      1.00895,50.00000,40.00000,1.981106e-10,0.86149,4
700.01001,336.25833,     -2.04345,      1.00895,50.00000,40.00000,1.971283e-10,0.86144,4
701.62201,336.33833,     -2.12047,      1.01571,50.00000,40.00000,1.971283e-10,0.86144,4
703.23999,336.41833,     -2.19710,      1.03598,50.00000,40.00000,1.976795e-10,0.86139,4
704.86102,336.49833,     -2.27270,      1.06302,50.00000,40.00000,1.976795e-10,0.86139,4
706.47101,336.57833,     -2.35413,      1.06958,50.00000,40.00000,1.974735e-10,0.86134,4
708.09003,336.65833,     -2.43487,      1.08986,50.00000,40.00000,1.974735e-10,0.86134,4
709.70300,336.73833,     -2.51489,      1.08986,50.00000,40.00000,1.982231e-10,0.86129,4
711.31299,336.81833,     -2.59134,      1.11690,50.00000,40.00000,1.982231e-10,0.86129,4
712.93201,336.89833,     -2.66519,      1.11690,50.00000,40.00000,1.973381e-10,0.86124,4
714.54303,336.97833,     -2.74080,      1.11690,50.00000,40.00000,1.973381e-10,0.86124,4
716.16699,337.05833,     -2.82299,      1.14394,50.00000,40.00000,1.974735e-10,0.86118,4
717.76898,337.13833,     -2.90376,      1.14394,50.00000,40.00000,1.974735e-10,0.86118,4
719.39203,337.21833,     -2.98354,      1.17097,50.00000,40.00000,1.968002e-10,0.86114,4
720.99799,337.29833,     -3.06001,      1.17097,50.00000,40.00000,1.968002e-10,0.86114,4
722.61700,337.37833,     -3.13895,      1.17097,50.00000,40.00000,1.980171e-10,0.86109,4
724.23700,337.45833,     -3.22225,      1.19781,50.00000,40.00000,1.980171e-10,0.86109,4
725.84802,337.53833,     -3.30224,      1.22485,50.00000,40.00000,1.979542e-10,0.86103,4
727.45502,337.61833,     -3.38564,      1.22485,50.00000,40.00000,1.979542e-10,0.86103,4
729.06702,337.69833,     -3.46929,      1.22485,50.00000,40.00000,1.972618e-10,0.86098,4
730.67798,337.77833,     -3.55380,      1.25189,50.00000,40.00000,1.972618e-10,0.86098,4
732.29303,337.85833,     -3.63984,      1.27893,50.00000,40.00000,1.975097e-10,0.86093,4
733.90802,337.93833,     -3.71969,      1.30577,50.00000,40.00000,1.975097e-10,0.86093,4
735.53198,338.01833,     -3.81202,      1.27893,50.00000,40.00000,1.977253e-10,0.86089,4
737.14301,338.09833,     -3.88683,      1.27893,50.00000,40.00000,1.977253e-10,0.86089,4
738.75598,338.17833,     -3.96411,      1.31928,50.00000,40.00000,1.977253e-10,0.86089,4
740.36902,338.25833,     -4.04484,      1.33280,50.00000,40.00000,1.976108e-10,0.86084,4
741.97198,338.33833,     -4.12768,      1.33280,50.00000,40.00000,1.976108e-10,0.86084,4
743.59399,338.41833,     -4.20370,      1.35984,50.00000,40.00000,1.980305e-10,0.86079,4
745.20398,338.49833,     -4.27046,      1.35984,50.00000,40.00000,1.980305e-10,0.86079,4
746.81799,338.57833,     -4.35367,      1.38688,50.00000,40.00000,1.975021e-10,0.86070,4
748.42902,338.65833,     -4.42830,      1.40040,50.00000,40.00000,1.975021e-10,0.86070,4
750.03802,338.73833,     -4.50574,      1.41372,50.00000,40.00000,1.975117e-10,0.86069,4
751.64600,338.81833,     -4.58208,      1.41372,50.00000,40.00000,1.975117e-10,0.86069,4
753.27002,338.89833,     -4.66130,      1.44076,50.00000,40.00000,1.972980e-10,0.86063,4
754.87799,338.97833,     -4.73937,      1.44076,50.00000,40.00000,1.972980e-10,0.86063,4
756.48199,339.05833,     -4.81664,      1.44076,50.00000,40.00000,1.977635e-10,0.86059,4
758.09497,339.13833,     -4.89811,      1.46779,50.00000,40.00000,1.977635e-10,0.86059,4
759.71002,339.21833,     -4.97421,      1.49483,50.00000,40.00000,1.972008e-10,0.86053,4
761.32703,339.29833,     -5.05218,      1.49483,50.00000,40.00000,1.972008e-10,0.86053,4
762.93799,339.37833,     -5.13067,      1.50835,50.00000,40.00000,1.978397e-10,0.86049,4
764.54999,339.45833,     -5.20739,      1.52167,50.00000,39.00000,1.978397e-10,0.86049,4
766.16998,339.53833,     -5.28634,      1.54871,50.00000,40.00000,1.973247e-10,0.86043,4
767.77502,339.61833,     -5.36213,      1.57575,50.00000,40.00000,1.973247e-10,0.86043,4
769.38702,339.69833,     -5.43650,      1.57575,50.00000,40.00000,1.977749e-10,0.86037,4
770.99597,339.77833,     -5.51371,      1.59602,50.00000,40.00000,1.977749e-10,0.86037,4
772.61499,339.85833,     -5.59186,      1.60278,50.00000,40.00000,1.973000e-10,0.86033,4
774.22400,339.93833,     -5.64318,      1.62982,50.00000,40.00000,1.973000e-10,0.86033,4
775.83398,340.01833,     -5.71933,      1.62982,50.00000,40.00000,1.975708e-10,0.86027,4
777.44800,340.09833,     -5.79271,      1.62982,50.00000,40.00000,1.975708e-10,0.86027,4
779.04901,340.17833,     -5.86957,      1.65666,50.00000,40.00000,1.984272e-10,0.86023,4
780.66602,340.25833,     -5.93567,      1.68370,50.00000,40.00000,1.984272e-10,0.86023,4
782.28003,340.33833,     -6.00798,      1.68370,50.00000,40.00000,1.975383e-10,0.86018,4
783.89398,340.41833,     -6.07679,      1.68370,50.00000,40.00000,1.975383e-10,0.86018,4
785.50702,340.49833,     -6.13905,      1.71074,50.00000,40.00000,1.977977e-10,0.86012,4
787.11603,340.57833,     -6.16305,      1.73777,50.00000,40.00000,1.977977e-10,0.86012,4
788.71698,340.65833,     -6.23533,      1.76461,50.00000,40.00000,1.975842e-10,0.86007,4
790.32300,340.73833,     -6.30616,      1.76461,50.00000,40.00000,            ,0.44877,4
791.93799,340.81833,     -6.37317,      1.76461,50.00000,40.00000,            ,0.44812,4
793.54602,340.89833,     -6.44100,      1.79384,50.00000,40.00000,            ,0.44747,4
794.26099,340.93333,     -6.47261,      1.79384,50.00000,40.00000,            ,0.44719,4