File: data/TGA/005d-L_M/ExpDat_2025_02_27_005d-L4-dynamic-1K.csv
#EXPORTTYPE:                 ,DATA ALL
#FILE:                       ,2025_02_27_005d-L4-isothermal-1K.ngb-ss5
#FORMAT:                     ,NETZSCH5
#FTYPE:                      ,ASCII
#IDENTITY:                   ,005d-L4
#DECIMAL:                    ,POINT
#SEPARATOR:                  ,COMMA
#MTYPE:                      ,DSC
#INSTRUMENT:                 ,NETZSCH STA 449F5
#PROJECT:                    ,PS
#DATE/TIME:                  ,2/27/2025 4:02:02 PM (UTC-5)
#CORR. FILE:                 ,
#TEMPCAL:                    ,13-11-2024 10:37
#SENSITIVITY:                ,28-06-2023 13:53
#LABORATORY:                 ,Tran/Aspuru
#OPERATOR:                   ,Stanley
#REMARK:                     ,
#SAMPLE:                     ,005d-L4
#SAMPLE MASS /mg:            ,5.06
#MATERIAL:                   ,
#REFERENCE:                  ,
#REFERENCE MASS /mg:         ,0
#TYPE OF CRUCIBLE:           ,Al2O3 85 ‘l, open
#SAMPLE CRUCIBLE MASS /mg:   ,0
#REFERENCE CRUCIBLE MASS /mg:,0
#DSC RANGE /‘V:              ,5000
#TG RANGE /mg:               ,35000
#TAU-R:                      ,---
#CORR. CODE:                 ,000
#EXO:                        ,-1
#RANGE:                      ,20›C....800›C/0.0....20.0K/min
#SEGMENT:                    ,S1-4/4
#SEG. 1:                     ,20›C/5.0(K/min)/100›C
#SEG. 2:                     ,100›C/00:05/100›C
#SEG. 3:                     ,100›C/1.0(K/min)/400›C
#SEG. 4:                     ,400›C/20.0(K/min)/800›C

##Temp./›C,Time/min,DSC/(mW/mg),Mass/%,Gas Flow(purge2)/(ml/min),Gas Flow(protective)/(ml/min),TIC(scan:1)/A,Sensit./(uV/mW),Segment
 29.25900,  0.00000,      0.99113,    100.00000,50.00000,43.00000,            ,0.92341,1
 34.67600,  1.06667,      0.45526,     97.94763,50.00000,42.00000,2.157058e-10,0.92388,1
 37.43900,  2.13333,      0.16663,     85.19209,50.00000,41.00000,2.150974e-10,0.92423,1
 38.80900,  3.20000, 2.021396e-02,     89.35968,50.00000,41.00000,2.161522e-10,0.92445,1
 39.47800,  4.26667,-5.884337e-02,     88.66206,50.00000,41.00000,2.156944e-10,0.92464,1
 40.26400,  5.33333, 0.000000e+00,     88.58162,50.00000,41.00000,2.161694e-10,0.92477,1
 42.18600,  6.40000,      0.18657,     89.05553,50.00000,41.00000,2.169418e-10,0.92485,1
 45.44000,  7.46667,      0.38524,     89.69289,50.00000,41.00000,2.163449e-10,0.92492,1
 49.83600,  8.53333,      0.56651,     90.30988,50.00000,41.00000,2.160911e-10,0.92496,1
 55.25400,  9.60000,      0.73113,     90.92925,50.00000,41.00000,2.165851e-10,0.92500,1
 61.41200, 10.66667,      0.86331,     91.44802,50.00000,41.00000,2.174205e-10,0.92502,1
 68.05900, 11.73333,      0.96238,     91.82806,50.00000,41.00000,2.164574e-10,0.92505,1
 74.91900, 12.80000,      1.02812,     92.15000,50.00000,41.00000,2.175960e-10,0.92509,1
 81.81600, 13.86667,      1.07063,     92.34012,50.00000,41.00000,2.180385e-10,0.92517,1
 88.66800, 14.93333,      1.09264,     92.44743,50.00000,41.00000,2.172336e-10,0.92525,1
 95.38200, 16.00000,      1.10553,     92.58142,50.00000,42.00000,2.171574e-10,0.92536,1
 99.83200, 16.80000,      0.95846,     92.32668,50.00000,42.00000,2.175292e-10,0.92545,2
102.80700, 17.60000,      0.61897,     91.72964,50.00000,42.00000,2.175922e-10,0.92556,2
104.83100, 18.40000,      0.40229,     91.33834,50.00000,42.00000,2.183494e-10,0.92566,2
106.28600, 19.20000,      0.26126,     91.00968,50.00000,42.00000,2.172452e-10,0.92576,2
107.18600, 20.00000,      0.11287,     90.63636,50.00000,42.00000,2.172966e-10,0.92586,2
107.50800, 20.80000,-2.575823e-02,     90.25178,50.00000,42.00000,2.185879e-10,0.92593,2
107.47300, 21.80000,     -0.12534,     89.95889,50.00000,42.00000,2.182712e-10,0.92605,3
107.34800, 22.86667,     -0.12747,     89.76443,50.00000,42.00000,2.172775e-10,0.92612,3
107.19200, 23.93333,     -0.13419,     89.60119,50.00000,42.00000,2.183838e-10,0.92618,3
107.07900, 25.00000,     -0.11942,     89.49150,50.00000,42.00000,2.185116e-10,0.92620,3
107.11900, 26.06667,-8.481137e-02,     89.41107,50.00000,42.00000,2.183590e-10,0.92618,3
107.34200, 27.13333,-4.872482e-02,     89.40435,50.00000,42.00000,2.181968e-10,0.92612,3
107.73500, 28.20000,-1.132131e-02,     89.37075,50.00000,42.00000,2.185421e-10,0.92600,3
108.31400, 29.26667, 2.231856e-02,     89.40217,50.00000,42.00000,2.180100e-10,0.92585,3
109.02600, 30.33333, 5.285457e-02,     89.37530,50.00000,42.00000,2.186737e-10,0.92563,3
109.86300, 31.40000, 7.700484e-02,     89.32609,50.00000,42.00000,2.177277e-10,0.92539,3
110.78300, 32.46667, 9.772250e-02,     89.32609,50.00000,42.00000,2.184848e-10,0.92507,3
111.78200, 33.53333,      0.11172,     89.32609,50.00000,42.00000,2.185058e-10,0.92468,3
112.83100, 34.60000,      0.12409,     89.29704,50.00000,42.00000,2.188530e-10,0.92431,3
113.92300, 35.66667,      0.13137,     89.25000,50.00000,42.00000,2.200031e-10,0.92383,3
115.04400, 36.73333,      0.13800,     89.25000,50.00000,42.00000,2.188454e-10,0.92338,3
116.14100, 37.80000,      0.14201,     89.22332,50.00000,42.00000,2.183991e-10,0.92281,3
117.27300, 38.86667,      0.14322,     89.23676,50.00000,42.00000,2.195549e-10,0.92229,3
118.38000, 39.93333,      0.14328,     89.20988,50.00000,42.00000,2.190533e-10,0.92176,3
119.50300, 41.00000,      0.14317,     89.20988,50.00000,42.00000,2.195434e-10,0.92137,3
120.59200, 42.06667,      0.14323,     89.18972,50.00000,42.00000,2.191086e-10,0.92096,3
121.69000, 43.13333,      0.14363,     89.15613,50.00000,42.00000,2.189007e-10,0.92066,3
122.79500, 44.20000,      0.14419,     89.18972,50.00000,42.00000,2.196903e-10,0.92035,3
123.88000, 45.26667,      0.14540,     89.16285,50.00000,42.00000,2.201519e-10,0.92012,3
124.96500, 46.33333,      0.14382,     89.16285,50.00000,42.00000,2.202301e-10,0.91990,3
126.03600, 47.40000,      0.14521,     89.18300,50.00000,42.00000,2.192421e-10,0.91972,3
127.12000, 48.46667,      0.14544,     89.15613,50.00000,42.00000,2.199001e-10,0.91952,3
128.18900, 49.53333,      0.14600,     89.15613,50.00000,42.00000,2.207413e-10,0.91937,3
129.25500, 50.60000,      0.14640,     89.18300,50.00000,42.00000,2.202282e-10,0.91925,3
130.31900, 51.66667,      0.14647,     89.18083,50.00000,42.00000,2.206592e-10,0.91914,3
131.39900, 52.73333,      0.14936,     89.21423,50.00000,42.00000,2.198620e-10,0.91908,3
132.45700, 53.80000,      0.14926,     89.23439,50.00000,42.00000,2.202034e-10,0.91904,3
133.52000, 54.86667,      0.15033,     89.23439,50.00000,42.00000,2.200394e-10,0.91902,3
134.59599, 55.93333,      0.15223,     89.26126,50.00000,42.00000,2.207622e-10,0.91901,3
135.65900, 57.00000,      0.15364,     89.26798,50.00000,42.00000,2.208310e-10,0.91903,3
136.72301, 58.06667,      0.15538,     89.29486,50.00000,42.00000,2.208901e-10,0.91904,3
137.77901, 59.13333,      0.15861,     89.29486,50.00000,42.00000,2.211723e-10,0.91905,3
138.86000, 60.20000,      0.16003,     89.34842,50.00000,42.00000,2.217350e-10,0.91906,3
139.92300, 61.26667,      0.16244,     89.34842,50.00000,42.00000,2.220363e-10,0.91908,3
140.98700, 62.33333,      0.16486,     89.35514,50.00000,42.00000,2.214260e-10,0.91910,3
142.07300, 63.40000,      0.16628,     89.38202,50.00000,42.00000,2.215290e-10,0.91912,3
143.14700, 64.46667,      0.16721,     89.39545,50.00000,42.00000,2.219467e-10,0.91913,3
144.21600, 65.53333,      0.16963,     89.42233,50.00000,42.00000,2.214051e-10,0.91914,3
145.27299, 66.60000,      0.17106,     89.44901,50.00000,42.00000,2.217254e-10,0.91914,3
146.34500, 67.66667,      0.17316,     89.47589,50.00000,42.00000,2.220459e-10,0.91913,3
147.41800, 68.73333,      0.17577,     89.47589,50.00000,42.00000,2.220878e-10,0.91912,3
148.49400, 69.80000,      0.17704,     89.50949,50.00000,42.00000,2.214565e-10,0.91909,3
149.55701, 70.86667,      0.17898,     89.52964,50.00000,42.00000,2.215767e-10,0.91906,3
150.62700, 71.93333,      0.18093,     89.61897,50.00000,42.00000,2.215958e-10,0.91902,3
151.67999, 73.00000,      0.18288,     89.56087,50.00000,42.00000,2.216644e-10,0.91896,3
152.75000, 74.06667,      0.18500,     89.58775,50.00000,42.00000,2.218419e-10,0.91890,3
153.81500, 75.13333,      0.18645,     89.64130,50.00000,42.00000,2.216568e-10,0.91883,3
154.88600, 76.20000,      0.18875,     89.66818,50.00000,42.00000,2.216739e-10,0.91876,3
155.95500, 77.26667,      0.19004,     89.70178,50.00000,42.00000,2.213535e-10,0.91867,3
157.00900, 78.33333,      0.19117,     89.73518,50.00000,42.00000,2.224694e-10,0.91859,3
158.08400, 79.40000,      0.19365,     89.78893,50.00000,42.00000,2.217312e-10,0.91848,3
159.15900, 80.46667,      0.19360,     89.78893,50.00000,42.00000,2.217521e-10,0.91839,3
160.22200, 81.53333,      0.19423,     89.83597,50.00000,42.00000,2.214393e-10,0.91827,3
161.32300, 82.60000,      0.19588,     89.86265,50.00000,42.00000,2.221851e-10,0.91817,3
162.35600, 83.66667,      0.19685,     89.88281,50.00000,42.00000,2.221584e-10,0.91804,3
163.44299, 84.73333,      0.19715,     89.90968,50.00000,42.00000,2.211972e-10,0.91793,3
164.51199, 85.80000,      0.19847,     89.93656,50.00000,42.00000,2.212429e-10,0.91779,3
165.55299, 86.86667,      0.19911,     89.97668,50.00000,42.00000,2.214241e-10,0.91767,3
166.63100, 87.93333,      0.19925,     89.96996,50.00000,42.00000,2.217541e-10,0.91753,3
167.69800, 89.00000,      0.19938,     90.01700,50.00000,42.00000,2.211876e-10,0.91740,3
168.76601, 90.06667,      0.19986,     90.02372,50.00000,42.00000,2.227287e-10,0.91725,3
169.83600, 91.13333,      0.20102,     90.09071,50.00000,42.00000,2.226028e-10,0.91712,3
170.88901, 92.20000,      0.20201,     90.07075,50.00000,42.00000,2.219639e-10,0.91695,3
171.95599, 93.26667,      0.20266,     90.12431,50.00000,42.00000,2.219582e-10,0.91683,3
173.03101, 94.33333,      0.20196,     90.13775,50.00000,42.00000,2.220860e-10,0.91667,3
174.08800, 95.40000,      0.20143,     90.16462,50.00000,42.00000,2.214603e-10,0.91653,3
175.15800, 96.46667,      0.20294,     90.20474,50.00000,42.00000,2.216530e-10,0.91636,3
176.23000, 97.53333,      0.20394,     90.20474,50.00000,42.00000,2.222004e-10,0.91622,3
177.30200, 98.60000,      0.20443,     90.23162,50.00000,42.00000,2.214394e-10,0.91606,3
178.34599, 99.66667,      0.20458,     90.28538,50.00000,42.00000,2.221756e-10,0.91591,3
179.42999,100.73333,      0.20508,     90.31206,50.00000,42.00000,2.223854e-10,0.91575,3
180.48801,101.80000,      0.20609,     90.32549,50.00000,42.00000,2.222214e-10,0.91558,3
181.56500,102.86667,      0.20625,     90.34565,50.00000,42.00000,2.223530e-10,0.91543,3
182.63800,103.93333,      0.20607,     90.33893,50.00000,42.00000,2.219753e-10,0.91526,3
183.69099,105.00000,      0.20572,     90.36581,50.00000,42.00000,2.225075e-10,0.91511,3
184.75000,106.06667,      0.20742,     90.40613,50.00000,42.00000,2.229767e-10,0.91494,3
185.81799,107.13333,      0.20638,     90.41937,50.00000,42.00000,2.223320e-10,0.91480,3
186.89799,108.20000,      0.20467,     90.44625,50.00000,42.00000,2.229328e-10,0.91462,3
187.95799,109.26667,      0.20586,     90.43281,50.00000,42.00000,2.232132e-10,0.91447,3
189.03101,110.33333,      0.20551,     90.45968,50.00000,42.00000,2.227555e-10,0.91430,3
190.09500,111.40000,      0.20534,     90.49545,50.00000,41.00000,2.227020e-10,0.91414,3
191.16400,112.46667,      0.20619,     90.50217,50.00000,41.00000,2.224865e-10,0.91397,3
192.22000,113.53333,      0.20567,     90.50217,50.00000,41.00000,2.228833e-10,0.91382,3
193.29700,114.60000,      0.20481,     90.54249,50.00000,41.00000,2.222500e-10,0.91364,3
194.35699,115.66667,      0.20602,     90.56245,50.00000,41.00000,2.227058e-10,0.91348,3
195.43401,116.73333,      0.20412,     90.56245,50.00000,41.00000,2.229805e-10,0.91331,3
196.50101,117.80000,      0.20413,     90.56245,50.00000,41.00000,2.225704e-10,0.91313,3
197.56799,118.86667,      0.20516,     90.58933,50.00000,41.00000,2.232705e-10,0.91297,3
198.62801,119.93333,      0.20534,     90.61621,50.00000,41.00000,2.234688e-10,0.91279,3
199.70399,121.00000,      0.20396,     90.60277,50.00000,41.00000,2.225189e-10,0.91263,3
200.78000,122.06667,      0.20449,     90.64308,50.00000,41.00000,2.231064e-10,0.91245,3
201.83501,123.13333,      0.20466,     90.68992,50.00000,41.00000,2.228203e-10,0.91229,3
202.91499,124.20000,      0.20641,     90.66324,50.00000,41.00000,2.231426e-10,0.91211,3
203.97800,125.26667,      0.20433,     90.66976,50.00000,41.00000,2.231235e-10,0.91194,3
205.05499,126.33333,      0.20469,     90.67648,50.00000,41.00000,2.234726e-10,0.91176,3
206.09700,127.40000,      0.20556,     90.71008,50.00000,41.00000,2.228489e-10,0.91160,3
207.16701,128.46667,      0.20349,     90.71008,50.00000,41.00000,2.229958e-10,0.91141,3
208.22000,129.53333,      0.20367,     90.72352,50.00000,41.00000,2.239666e-10,0.91125,3
209.29401,130.60000,      0.20403,     90.71897,50.00000,41.00000,2.227326e-10,0.91106,3
210.35001,131.66667,      0.20369,     90.74585,50.00000,41.00000,2.231808e-10,0.91089,3
211.41100,132.73333,      0.20213,     90.74585,50.00000,41.00000,2.241211e-10,0.91069,3
212.48399,133.80000,      0.20092,     90.74585,50.00000,41.00000,2.234230e-10,0.91053,3
213.54401,134.86667,      0.19901,     90.77273,50.00000,41.00000,2.234592e-10,0.91033,3
214.60201,135.93333,      0.20392,     90.79289,50.00000,41.00000,2.241135e-10,0.91017,3
215.67101,137.00000,      0.20026,     90.80632,50.00000,41.00000,2.241268e-10,0.90997,3
216.74200,138.06667,      0.19992,     90.83083,50.00000,42.00000,2.237548e-10,0.90980,3
217.81400,139.13333,      0.20082,     90.85771,50.00000,42.00000,2.234707e-10,0.90960,3
218.88499,140.20000,      0.20101,     90.88458,50.00000,42.00000,2.239723e-10,0.90943,3
219.93900,141.26667,      0.19909,     90.88458,50.00000,42.00000,2.238426e-10,0.90923,3
221.02200,142.33333,      0.19946,     90.89783,50.00000,42.00000,2.239666e-10,0.90906,3
222.08099,143.40000,      0.19683,     90.91798,50.00000,42.00000,2.237167e-10,0.90885,3
223.15199,144.46667,      0.19685,     90.94486,50.00000,42.00000,2.227688e-10,0.90865,3
224.23000,145.53333,      0.19651,     90.94486,50.00000,42.00000,2.239895e-10,0.90848,3
225.28700,146.60000,      0.19600,     90.96502,50.00000,42.00000,2.240086e-10,0.90827,3
226.35800,147.66667,      0.19619,     90.99190,50.00000,42.00000,2.236786e-10,0.90809,3
227.43201,148.73333,      0.19639,     90.99862,50.00000,42.00000,2.241306e-10,0.90789,3
228.47701,149.80000,      0.19356,     91.01186,50.00000,42.00000,2.236271e-10,0.90770,3
229.55099,150.86667,      0.19145,     91.01186,50.00000,42.00000,2.103615e-10,0.90749,3
230.61501,151.93333,      0.19058,     91.03874,50.00000,42.00000,2.096367e-10,0.90731,3
231.67700,153.00000,      0.18952,     91.05889,50.00000,42.00000,2.097415e-10,0.90710,3
232.76500,154.06667,      0.18919,     91.07905,50.00000,42.00000,2.093468e-10,0.90692,3
233.82001,155.13333,      0.18617,     91.05889,50.00000,42.00000,2.091160e-10,0.90670,3
234.87500,156.20000,      0.18511,     91.08577,50.00000,42.00000,2.093830e-10,0.90652,3
235.94600,157.26667,      0.18494,     91.13261,50.00000,42.00000,2.097092e-10,0.90630,3
237.01199,158.33333,      0.18245,     91.13261,50.00000,42.00000,2.096558e-10,0.90611,3
238.07300,159.40000,      0.18067,     91.15949,50.00000,42.00000,2.098446e-10,0.90590,3
239.14700,160.46667,      0.17889,     91.15949,50.00000,42.00000,2.096863e-10,0.90571,3
240.20799,161.53333,      0.17746,     91.15277,50.00000,42.00000,2.098084e-10,0.90549,3
241.28700,162.60000,      0.17567,     91.17964,50.00000,42.00000,2.096366e-10,0.90527,3
242.34200,163.66667,      0.17352,     91.20652,50.00000,42.00000,2.095928e-10,0.90508,3
243.41200,164.73333,      0.17245,     91.19980,50.00000,42.00000,2.100734e-10,0.90485,3
244.47301,165.80000,      0.17155,     91.23992,50.00000,42.00000,2.100182e-10,0.90466,3
245.54900,166.86667,      0.16975,     91.25336,50.00000,42.00000,2.098980e-10,0.90443,3
246.61900,167.93333,      0.16740,     91.24664,50.00000,42.00000,2.104435e-10,0.90424,3
247.67300,169.00000,      0.16361,     91.29368,50.00000,42.00000,2.102204e-10,0.90401,3
248.74200,170.06667,      0.16415,     91.29368,50.00000,42.00000,2.110062e-10,0.90382,3
249.81599,171.13333,      0.16215,     91.34723,50.00000,42.00000,2.105389e-10,0.90359,3
250.88100,172.20000,      0.15798,     91.34723,50.00000,42.00000,2.103652e-10,0.90340,3
251.94701,173.26667,      0.15579,     91.36067,50.00000,42.00000,2.108764e-10,0.90316,3
253.00900,174.33333,      0.15396,     91.36739,50.00000,42.00000,2.107029e-10,0.90296,3
254.08000,175.40000,      0.15231,     91.38083,50.00000,42.00000,2.104206e-10,0.90273,3
255.14500,176.46667,      0.14938,     91.39427,50.00000,42.00000,2.112465e-10,0.90253,3
256.20700,177.53333,      0.14663,     91.42115,50.00000,42.00000,2.102890e-10,0.90230,3
257.27499,178.60000,      0.14205,     91.43458,50.00000,42.00000,2.108421e-10,0.90209,3
258.34201,179.66667,      0.14257,     91.44130,50.00000,42.00000,2.107334e-10,0.90186,3
259.39700,180.73333,      0.13852,     91.44130,50.00000,42.00000,2.110901e-10,0.90165,3
260.46701,181.80000,      0.13685,     91.46798,50.00000,42.00000,2.105655e-10,0.90142,3
261.53101,182.86667,      0.13407,     91.49486,50.00000,42.00000,2.102471e-10,0.90121,3
262.60300,183.93333,      0.13441,     91.49486,50.00000,42.00000,2.109814e-10,0.90097,3
263.67700,185.00000,      0.12721,     91.49486,50.00000,42.00000,2.104091e-10,0.90077,3
264.73700,186.06667,      0.12625,     91.52174,50.00000,42.00000,2.113342e-10,0.90052,3
265.80499,187.13333,      0.12216,     91.52391,50.00000,42.00000,2.112045e-10,0.90028,3
266.85800,188.20000,      0.12322,     91.51719,50.00000,42.00000,2.107582e-10,0.90007,3
267.92999,189.26667,      0.11875,     91.57095,50.00000,42.00000,2.115917e-10,0.89987,3
269.00601,190.33333,      0.11630,     91.55751,50.00000,42.00000,2.114163e-10,0.89962,3
270.07700,191.40000,      0.11143,     91.55751,50.00000,42.00000,2.115726e-10,0.89937,3
271.14301,192.46667,      0.10841,     91.61107,50.00000,42.00000,2.116374e-10,0.89916,3
272.18399,193.53333,      0.10687,     91.61107,50.00000,42.00000,2.122002e-10,0.89891,3
273.26199,194.60000,      0.10421,     91.58439,50.00000,42.00000,2.111778e-10,0.89870,3
274.34201,195.66667,      0.10043,     91.61107,50.00000,42.00000,2.115822e-10,0.89845,3
275.41000,196.73333, 9.849982e-02,     91.59111,50.00000,42.00000,2.119903e-10,0.89824,3
276.47299,197.80000, 9.526091e-02,     91.59783,50.00000,42.00000,2.105732e-10,0.89799,3
277.53799,198.86667, 9.052160e-02,     91.62451,50.00000,42.00000,2.108268e-10,0.89776,3
278.60400,199.93333, 8.689246e-02,     91.61779,50.00000,42.00000,2.113152e-10,0.89751,3
279.66101,201.00000, 8.531194e-02,     91.59783,50.00000,42.00000,2.101670e-10,0.89728,3
280.73001,202.06667, 8.035732e-02,     91.63123,50.00000,42.00000,2.117958e-10,0.89702,3
281.80399,203.13333, 7.839198e-02,     91.61107,50.00000,42.00000,2.106724e-10,0.89681,3
282.86200,204.20000, 7.435520e-02,     91.61107,50.00000,42.00000,2.109794e-10,0.89656,3
283.92700,205.26667, 7.087341e-02,     91.63123,50.00000,42.00000,2.109699e-10,0.89633,3
284.99500,206.33333, 6.681886e-02,     91.63123,50.00000,42.00000,2.112846e-10,0.89611,3
286.04599,207.40000, 6.313022e-02,     91.62451,50.00000,42.00000,2.118416e-10,0.89585,3
287.11200,208.46667, 6.018855e-02,     91.59783,50.00000,42.00000,2.113380e-10,0.89563,3
288.18100,209.53333, 5.648434e-02,     91.60435,50.00000,42.00000,2.111855e-10,0.89536,3
289.25500,210.60000, 5.485200e-02,     91.58439,50.00000,42.00000,2.112198e-10,0.89510,3
290.32199,211.66667, 5.018522e-02,     91.55751,50.00000,42.00000,2.104512e-10,0.89487,3
291.38800,212.73333, 4.702385e-02,     91.57095,50.00000,42.00000,2.108230e-10,0.89461,3
292.46500,213.80000, 4.195678e-02,     91.55079,50.00000,42.00000,2.110939e-10,0.89438,3
293.51501,214.86667, 3.649575e-02,     91.49704,50.00000,42.00000,2.116508e-10,0.89412,3
294.59000,215.93333, 3.273519e-02,     91.52628,50.00000,42.00000,2.115573e-10,0.89388,3
295.66000,217.00000, 2.934615e-02,     91.47253,50.00000,42.00000,2.114468e-10,0.89362,3
296.72900,218.06667, 2.575782e-02,     91.46581,50.00000,42.00000,2.109947e-10,0.89339,3
297.78500,219.13333, 1.948566e-02,     91.44565,50.00000,42.00000,2.117786e-10,0.89312,3
298.83701,220.20000, 1.683204e-02,     91.43893,50.00000,42.00000,2.114506e-10,0.89288,3
299.92700,221.26667, 1.283183e-02,     91.39881,50.00000,42.00000,2.111511e-10,0.89262,3
300.98999,222.33333, 6.903407e-03,     91.37866,50.00000,42.00000,2.117786e-10,0.89239,3
302.06100,223.40000, 2.880083e-03,     91.33834,50.00000,42.00000,2.114982e-10,0.89211,3
303.12100,224.46667,-1.537984e-03,     91.30474,50.00000,42.00000,2.113323e-10,0.89187,3
304.18500,225.53333,-6.544741e-03,     91.26462,50.00000,42.00000,2.118378e-10,0.89160,3
305.29800,226.60000,-9.444698e-03,     91.20415,50.00000,42.00000,2.113610e-10,0.89136,3
306.32199,227.66667,-1.389498e-02,     91.12372,50.00000,42.00000,2.111377e-10,0.89108,3
307.37399,228.73333,-1.642455e-02,     91.12372,50.00000,42.00000,2.118416e-10,0.89085,3
308.44800,229.80000,-2.302414e-02,     91.04328,50.00000,42.00000,2.118015e-10,0.89057,3
309.49500,230.86667,-2.499051e-02,     90.99625,50.00000,42.00000,2.115307e-10,0.89033,3
310.57599,231.93333,-3.026063e-02,     90.93597,50.00000,42.00000,2.116222e-10,0.89006,3
311.64401,233.00000,-3.321329e-02,     90.85553,50.00000,42.00000,2.117290e-10,0.88981,3
312.72299,234.06667,-3.656310e-02,     90.79960,50.00000,42.00000,2.115364e-10,0.88952,3
313.78299,235.13333,-4.537344e-02,     90.74585,50.00000,42.00000,2.116432e-10,0.88929,3
314.85300,236.20000,-4.699264e-02,     90.63182,50.00000,42.00000,2.112064e-10,0.88900,3
315.90399,237.26667,-5.154360e-02,     90.53794,50.00000,42.00000,2.123642e-10,0.88876,3
316.96701,238.33333,-5.649816e-02,     90.47767,50.00000,42.00000,2.111969e-10,0.88848,3
318.06601,239.40000,-6.401329e-02,     90.34348,50.00000,42.00000,2.123356e-10,0.88824,3
319.11600,240.46667,-6.527211e-02,     90.23617,50.00000,42.00000,2.123356e-10,0.88795,3
320.19101,241.53333,-7.419089e-02,     90.12885,50.00000,42.00000,2.117882e-10,0.88770,3
321.25299,242.60000,-7.743273e-02,     90.02826,50.00000,42.00000,2.115327e-10,0.88741,3
322.31500,243.66667,-8.166709e-02,     89.89407,50.00000,42.00000,2.119866e-10,0.88717,3
323.38699,244.73333,-8.551963e-02,     89.75988,50.00000,42.00000,2.118454e-10,0.88687,3
324.45801,245.80000,-9.076357e-02,     89.59881,50.00000,42.00000,2.120781e-10,0.88662,3
325.52200,246.86667,-9.523042e-02,     89.43794,50.00000,41.00000,2.124882e-10,0.88633,3
326.60101,247.93333,-9.990888e-02,     89.25000,50.00000,41.00000,2.119712e-10,0.88607,3
327.65302,249.00000,     -0.10579,     89.08913,50.00000,41.00000,2.128181e-10,0.88579,3
328.72699,250.06667,     -0.11029,     88.87451,50.00000,41.00000,2.124138e-10,0.88554,3
329.80099,251.13333,     -0.11362,     88.65988,50.00000,41.00000,2.126026e-10,0.88524,3
330.86200,252.20000,     -0.12053,     88.41838,50.00000,41.00000,2.119637e-10,0.88499,3
331.91299,253.26667,     -0.12228,     88.20375,50.00000,41.00000,2.122116e-10,0.88469,3
332.99200,254.33333,     -0.12764,     87.88182,50.00000,41.00000,2.125511e-10,0.88443,3
334.04901,255.40000,     -0.13320,     87.61798,50.00000,41.00000,2.118950e-10,0.88414,3
335.11301,256.46667,     -0.13558,     87.31601,50.00000,41.00000,2.116470e-10,0.88388,3
336.18100,257.53333,     -0.14017,     86.99190,50.00000,41.00000,2.121525e-10,0.88358,3
337.25101,258.60000,     -0.14136,     86.63854,50.00000,41.00000,2.129668e-10,0.88332,3
338.32700,259.66667,     -0.14677,     86.23162,50.00000,41.00000,2.131233e-10,0.88303,3
339.39499,260.73333,     -0.15139,     85.82708,50.00000,41.00000,2.127513e-10,0.88277,3
340.44601,261.80000,     -0.15703,     85.39545,50.00000,41.00000,2.124138e-10,0.88246,3
341.51199,262.86667,     -0.15987,     84.92372,50.00000,41.00000,2.126598e-10,0.88221,3
342.57001,263.93333,     -0.16473,     84.40494,50.00000,41.00000,2.118759e-10,0.88190,3
343.64099,265.00000,     -0.16758,     83.84605,50.00000,41.00000,2.126578e-10,0.88164,3
344.70499,266.06667,     -0.17348,     83.29150,50.00000,42.00000,2.124195e-10,0.88134,3
345.76501,267.13333,     -0.17392,     82.60968,50.00000,42.00000,2.121983e-10,0.88107,3
346.84000,268.20000,     -0.17964,     81.91660,50.00000,42.00000,2.123966e-10,0.88076,3
347.90701,269.26667,     -0.18883,     81.16759,50.00000,42.00000,2.125092e-10,0.88050,3
348.97900,270.33333,     -0.19072,     80.41403,50.00000,42.00000,2.125492e-10,0.88019,3
350.04999,271.40000,     -0.19404,     79.53972,50.00000,42.00000,2.128944e-10,0.87992,3
351.11801,272.46667,     -0.20002,     78.62984,50.00000,42.00000,2.125644e-10,0.87961,3
352.16400,273.53333,     -0.20131,     77.69308,50.00000,42.00000,2.134991e-10,0.87934,3
353.23401,274.60000,     -0.20609,     76.63320,50.00000,42.00000,2.130813e-10,0.87904,3
354.28900,275.66667,     -0.20740,     75.55553,50.00000,42.00000,2.133369e-10,0.87877,3
355.37601,276.73333,     -0.20708,     74.32589,50.00000,42.00000,2.127514e-10,0.87845,3
356.42599,277.80000,     -0.21188,     73.06700,50.00000,42.00000,2.132911e-10,0.87818,3
357.50000,278.86667,     -0.21465,     71.69190,50.00000,42.00000,2.127533e-10,0.87786,3
358.57001,279.93333,     -0.21721,     70.26996,50.00000,42.00000,2.130832e-10,0.87754,3
359.64401,281.00000,     -0.22350,     68.75178,50.00000,42.00000,2.131615e-10,0.87728,3
360.69199,282.06667,     -0.22360,     67.07273,50.00000,42.00000,2.130432e-10,0.87696,3
361.76700,283.13333,     -0.22474,     65.30870,50.00000,42.00000,2.138214e-10,0.87668,3
362.83200,284.20000,     -0.23355,     63.50435,50.00000,42.00000,2.136344e-10,0.87637,3
363.90302,285.26667,     -0.23637,     61.56798,50.00000,42.00000,2.133980e-10,0.87610,3
364.96100,286.33333,     -0.24252,     59.53794,50.00000,42.00000,2.140522e-10,0.87582,3
366.02100,287.40000,     -0.24743,     57.37806,50.00000,42.00000,2.137337e-10,0.87550,3
367.09299,288.46667,     -0.25612,     55.18913,50.00000,42.00000,2.143994e-10,0.87523,3
368.17099,289.53333,     -0.26232,     52.86383,50.00000,42.00000,2.141495e-10,0.87490,3
369.22501,290.60000,     -0.27126,     50.42016,50.00000,42.00000,2.141590e-10,0.87457,3
370.29300,291.66667,     -0.28315,     47.93379,50.00000,42.00000,2.142086e-10,0.87430,3
371.35999,292.73333,     -0.29612,     45.31561,50.00000,42.00000,2.138996e-10,0.87397,3
372.43201,293.80000,     -0.30850,     42.70198,50.00000,42.00000,2.145118e-10,0.87370,3
373.50000,294.86667,     -0.32470,     39.95850,50.00000,42.00000,2.142677e-10,0.87337,3
374.56601,295.93333,     -0.34031,     37.23972,50.00000,42.00000,2.145729e-10,0.87309,3
375.63101,297.00000,     -0.35976,     34.46067,50.00000,42.00000,2.144985e-10,0.87276,3
376.69601,298.06667,     -0.38137,     31.68597,50.00000,42.00000,2.138463e-10,0.87248,3
377.76501,299.13333,     -0.40389,     28.90909,50.00000,42.00000,2.147560e-10,0.87214,3
378.83401,300.20000,     -0.43050,     26.16798,50.00000,42.00000,2.147998e-10,0.87186,3
379.90601,301.26667,     -0.45633,     23.52292,50.00000,42.00000,2.149925e-10,0.87153,3
380.96201,302.33333,     -0.49051,     20.89585,50.00000,42.00000,2.156887e-10,0.87125,3
382.04999,303.40000,     -0.52416,     18.37372,50.00000,42.00000,2.156086e-10,0.87092,3
383.08701,304.46667,     -0.55788,     15.96798,50.00000,42.00000,2.153416e-10,0.87063,3
384.16599,305.53333,     -0.59236,     13.72984,50.00000,42.00000,2.153511e-10,0.87029,3
385.23300,306.60000,     -0.63162,     11.58340,50.00000,42.00000,2.151337e-10,0.87000,3
386.31299,307.66667,     -0.66694,      9.62253,50.00000,42.00000,2.154159e-10,0.86967,3
387.37100,308.73333,     -0.71027,      7.80040,50.00000,42.00000,2.149525e-10,0.86938,3
388.43701,309.80000,     -0.74429,      6.16818,50.00000,42.00000,2.154636e-10,0.86904,3
389.50101,310.86667,     -0.78313,      4.69704,50.00000,42.00000,2.162800e-10,0.86876,3
390.57401,311.93333,     -0.81951,      3.38458,50.00000,42.00000,2.163411e-10,0.86842,3
391.63199,313.00000,     -0.85835,      2.21976,50.00000,42.00000,2.158642e-10,0.86813,3
392.70300,314.06667,     -0.89472,      1.19348,50.00000,42.00000,2.156391e-10,0.86780,3
393.77499,315.13333,     -0.92731,      0.31917,50.00000,42.00000,2.154465e-10,0.86752,3
394.84000,316.20000,     -0.95803,     -0.44763,50.00000,42.00000,2.151775e-10,0.86717,3
395.90701,317.26667,     -0.98733,     -1.09387,50.00000,42.00000,2.158127e-10,0.86688,3
396.97000,318.33333,     -1.01844,     -1.65059,50.00000,42.00000,2.156372e-10,0.86654,3
398.02701,319.40000,     -1.04573,     -2.14249,50.00000,42.00000,2.154369e-10,0.86625,3
399.09698,320.46667,     -1.07832,     -2.54704,50.00000,42.00000,2.155247e-10,0.86591,3
399.67300,321.04000,     -1.09722,     -2.76166,50.00000,42.00000,2.157306e-10,0.86576,4
399.79901,321.12000,     -1.08630,     -2.76166,50.00000,42.00000,2.151452e-10,0.86571,4
400.03201,321.20000,     -0.96842,     -2.76166,50.00000,42.00000,2.151452e-10,0.86571,4
400.45300,321.28000,     -0.72389,     -2.76166,50.00000,42.00000,2.156543e-10,0.86566,4
401.00500,321.36000,     -0.35120,     -2.73498,50.00000,42.00000,2.156543e-10,0.86566,4
401.74899,321.44000,      0.13333,     -2.67688,50.00000,42.00000,2.156677e-10,0.86562,4
402.70099,321.52000,      0.70510,     -2.58281,50.00000,42.00000,2.156677e-10,0.86562,4
403.79099,321.60000,      1.32911,     -2.49565,50.00000,42.00000,2.157517e-10,0.86556,4
405.05701,321.68000,      1.98018,     -2.41976,50.00000,42.00000,2.157517e-10,0.86556,4
406.44101,321.76000,      2.62136,     -2.31008,50.00000,42.00000,2.153626e-10,0.86552,4
407.92599,321.84000,      3.22752,     -2.25870,50.00000,42.00000,2.153626e-10,0.86552,4
409.47601,321.92000,      3.77931,     -2.19605,50.00000,42.00000,2.162666e-10,0.86546,4
411.06900,322.00000,      4.25144,     -2.13794,50.00000,42.00000,2.162666e-10,0.86546,4
412.69501,322.08000,      4.64430,     -2.11107,50.00000,42.00000,2.149677e-10,0.86542,4
414.29999,322.16000,      4.94616,     -2.05751,50.00000,42.00000,2.149677e-10,0.86542,4
415.89600,322.24000,      5.15851,     -2.05751,50.00000,42.00000,2.157994e-10,0.86536,4
417.46600,322.32000,      5.28865,     -2.03063,50.00000,42.00000,2.157994e-10,0.86536,4
418.98901,322.40000,      5.34706,     -2.03063,50.00000,42.00000,2.153759e-10,0.86532,4
420.48300,322.48000,      5.34215,     -2.05751,50.00000,42.00000,2.153759e-10,0.86532,4
421.93701,322.56000,      5.28735,     -2.08419,50.00000,42.00000,2.153263e-10,0.86527,4
423.33899,322.64000,      5.20073,     -2.11107,50.00000,42.00000,2.153263e-10,0.86527,4
424.72101,322.72000,      5.09337,     -2.13794,50.00000,42.00000,2.161827e-10,0.86523,4
426.06299,322.80000,      4.97721,     -2.16482,50.00000,42.00000,2.161827e-10,0.86523,4
427.40399,322.88000,      4.86489,     -2.19170,50.00000,42.00000,2.154961e-10,0.86518,4
428.72800,322.96000,      4.76291,     -2.24526,50.00000,42.00000,2.154961e-10,0.86518,4
430.05701,323.04000,      4.67712,     -2.27213,50.00000,42.00000,2.149582e-10,0.86513,4
431.36899,323.12000,      4.61725,     -2.29901,50.00000,42.00000,2.149582e-10,0.86513,4
432.71799,323.20000,      4.58604,     -2.32569,50.00000,42.00000,2.149582e-10,0.86513,4
434.08200,323.28000,      4.58054,     -2.32569,50.00000,42.00000,2.156068e-10,0.86507,4
435.47101,323.36000,      4.60005,     -2.35257,50.00000,42.00000,2.156068e-10,0.86507,4
436.88300,323.44000,      4.64561,     -2.37945,50.00000,42.00000,2.160435e-10,0.86504,4
438.33301,323.52000,      4.71173,     -2.40632,50.00000,42.00000,2.160435e-10,0.86504,4
439.79401,323.60000,      4.79561,     -2.40632,50.00000,42.00000,2.156773e-10,0.86499,4
441.29599,323.68000,      4.89134,     -2.40632,50.00000,42.00000,2.156773e-10,0.86499,4
442.82101,323.76000,      4.99289,     -2.40632,50.00000,42.00000,2.155133e-10,0.86494,4
444.37100,323.84000,      5.10124,     -2.40632,50.00000,42.00000,2.155133e-10,0.86494,4
445.96301,323.92000,      5.20359,     -2.43300,50.00000,42.00000,2.150344e-10,0.86488,4
447.54599,324.00000,      5.30350,     -2.43300,50.00000,42.00000,2.150344e-10,0.86488,4
449.16299,324.08000,      5.39613,     -2.43300,50.00000,42.00000,2.157040e-10,0.86483,4
450.79001,324.16000,      5.47663,     -2.43300,50.00000,42.00000,2.157040e-10,0.86483,4
452.41000,324.24000,      5.54594,     -2.43300,50.00000,42.00000,2.165203e-10,0.86478,4
454.04901,324.32000,      5.60419,     -2.41976,50.00000,42.00000,2.165203e-10,0.86478,4
455.69501,324.40000,      5.64934,     -2.41976,50.00000,42.00000,2.155763e-10,0.86473,4
457.32800,324.48000,      5.68209,     -2.40632,50.00000,42.00000,2.155763e-10,0.86473,4
458.97299,324.56000,      5.70608,     -2.37945,50.00000,42.00000,2.155285e-10,0.86467,4
460.61801,324.64000,      5.71880,     -2.36601,50.00000,42.00000,2.155285e-10,0.86467,4
462.28601,324.72000,      5.72343,     -2.35257,50.00000,42.00000,2.154598e-10,0.86463,4
463.89301,324.80000,      5.72046,     -2.35257,50.00000,42.00000,2.154598e-10,0.86463,4
465.52701,324.88000,      5.71242,     -2.35257,50.00000,42.00000,2.154674e-10,0.86459,4
467.16699,324.96000,      5.70196,     -2.32569,50.00000,42.00000,2.154674e-10,0.86459,4
468.80099,325.04000,      5.69424,     -2.29901,50.00000,42.00000,2.155457e-10,0.86453,4
470.45200,325.12000,      5.68059,     -2.29901,50.00000,42.00000,2.155457e-10,0.86453,4
472.08701,325.20000,      5.66816,     -2.27213,50.00000,42.00000,2.154369e-10,0.86448,4
473.73099,325.28000,      5.65810,     -2.24526,50.00000,42.00000,2.154369e-10,0.86448,4
475.36801,325.36000,      5.64862,     -2.24526,50.00000,42.00000,2.159328e-10,0.86442,4
477.02802,325.44000,      5.64141,     -2.21838,50.00000,42.00000,2.159328e-10,0.86442,4
478.68399,325.52000,      5.63530,     -2.19170,50.00000,42.00000,2.154159e-10,0.86438,4
480.33401,325.60000,      5.62883,     -2.19170,50.00000,42.00000,2.154159e-10,0.86438,4
481.99100,325.68000,      5.62501,     -2.13794,50.00000,42.00000,2.155990e-10,0.86433,4
483.64899,325.76000,      5.61968,     -2.11107,50.00000,42.00000,2.155990e-10,0.86433,4
485.31699,325.84000,      5.61411,     -2.11107,50.00000,42.00000,2.152767e-10,0.86429,4
486.98199,325.92000,      5.60772,     -2.08419,50.00000,42.00000,2.152767e-10,0.86429,4
488.64600,326.00000,      5.60370,     -2.08419,50.00000,42.00000,2.152767e-10,0.86429,4
490.31500,326.08000,      5.59645,     -2.05751,50.00000,42.00000,2.156505e-10,0.86423,4
491.98999,326.16000,      5.58622,     -2.03063,50.00000,42.00000,2.156505e-10,0.86423,4
493.65900,326.24000,      5.57240,     -2.03063,50.00000,42.00000,2.154235e-10,0.86419,4
495.32999,326.32000,      5.55825,     -2.00375,50.00000,42.00000,2.154235e-10,0.86419,4
497.00601,326.40000,      5.53906,     -1.97688,50.00000,42.00000,2.154865e-10,0.86414,4
498.68301,326.48000,      5.52274,     -1.97688,50.00000,42.00000,2.154865e-10,0.86414,4
500.34500,326.56000,      5.50444,     -1.95020,50.00000,42.00000,2.159405e-10,0.86409,4
502.01501,326.64000,      5.48334,     -1.92332,50.00000,42.00000,2.159405e-10,0.86409,4
503.68900,326.72000,      5.46612,     -1.89644,50.00000,42.00000,2.155437e-10,0.86404,4
505.35501,326.80000,      5.44122,     -1.89644,50.00000,42.00000,2.155437e-10,0.86404,4
507.01801,326.88000,      5.41714,     -1.86957,50.00000,42.00000,2.153683e-10,0.86399,4
508.68701,326.96000,      5.39522,     -1.84289,50.00000,42.00000,2.153683e-10,0.86399,4
510.35001,327.04000,      5.37236,     -1.81601,50.00000,42.00000,2.159252e-10,0.86394,4
512.02100,327.12000,      5.34815,     -1.81601,50.00000,42.00000,2.159252e-10,0.86394,4
513.68903,327.20000,      5.31897,     -1.78913,50.00000,42.00000,2.155399e-10,0.86388,4
515.34900,327.28000,      5.29234,     -1.76225,50.00000,42.00000,2.155399e-10,0.86388,4
517.01599,327.36000,      5.26637,     -1.76225,50.00000,42.00000,2.147217e-10,0.86384,4
518.68298,327.44000,      5.24024,     -1.74229,50.00000,42.00000,2.147217e-10,0.86384,4
520.35901,327.52000,      5.21427,     -1.73557,50.00000,42.00000,2.158603e-10,0.86379,4
521.99902,327.60000,      5.18356,     -1.70870,50.00000,42.00000,2.158603e-10,0.86379,4
523.66901,327.68000,      5.15236,     -1.68182,50.00000,42.00000,2.156162e-10,0.86374,4
525.33502,327.76000,      5.12353,     -1.66166,50.00000,42.00000,2.156162e-10,0.86374,4
526.99500,327.84000,      5.09526,     -1.66166,50.00000,42.00000,2.154732e-10,0.86369,4
528.65698,327.92000,      5.06504,     -1.64822,50.00000,42.00000,2.154732e-10,0.86369,4
530.30499,328.00000,      5.03482,     -1.62826,50.00000,42.00000,2.153778e-10,0.86365,4
531.96503,328.08000,      5.00657,     -1.60138,50.00000,42.00000,2.153778e-10,0.86365,4
533.61798,328.16000,      4.97760,     -1.57451,50.00000,42.00000,2.146988e-10,0.86359,4
535.28400,328.24000,      4.94855,     -1.57451,50.00000,42.00000,2.146988e-10,0.86359,4
536.94501,328.32000,      4.91852,     -1.54763,50.00000,42.00000,2.162151e-10,0.86355,4
538.59003,328.40000,      4.88745,     -1.54763,50.00000,42.00000,2.162151e-10,0.86355,4
540.25403,328.48000,      4.85710,     -1.52095,50.00000,42.00000,2.159729e-10,0.86350,4
541.91302,328.56000,      4.82498,     -1.50079,50.00000,42.00000,2.159729e-10,0.86350,4
543.55798,328.64000,      4.79497,     -1.48735,50.00000,42.00000,2.151508e-10,0.86344,4
545.23199,328.72000,      4.76733,     -1.46719,50.00000,42.00000,2.151508e-10,0.86344,4
546.87500,328.80000,      4.72987,     -1.46047,50.00000,42.00000,2.154389e-10,0.86339,4
548.52600,328.88000,      4.69913,     -1.44032,50.00000,42.00000,2.154389e-10,0.86339,4
550.17902,328.96000,      4.66479,     -1.41344,50.00000,42.00000,2.151222e-10,0.86335,4
551.83002,329.04000,      4.63212,     -1.41344,50.00000,42.00000,2.151222e-10,0.86335,4
553.48199,329.12000,      4.60593,     -1.38676,50.00000,42.00000,2.152576e-10,0.86329,4
555.14001,329.20000,      4.57962,     -1.35988,50.00000,42.00000,2.152576e-10,0.86329,4
556.78900,329.28000,      4.55632,     -1.33300,50.00000,42.00000,2.159347e-10,0.86325,4
558.44397,329.36000,      4.53024,     -1.30613,50.00000,42.00000,2.159347e-10,0.86325,4
560.09998,329.44000,      4.49867,     -1.30613,50.00000,42.00000,2.147808e-10,0.86319,4
561.75800,329.52000,      4.46722,     -1.30613,50.00000,42.00000,2.147808e-10,0.86319,4
563.40503,329.60000,      4.43043,     -1.27945,50.00000,42.00000,2.154827e-10,0.86314,4
565.06097,329.68000,      4.39378,     -1.27945,50.00000,42.00000,2.154827e-10,0.86314,4
566.70300,329.76000,      4.35256,     -1.25257,50.00000,42.00000,2.154827e-10,0.86314,4
568.33600,329.84000,      4.31271,     -1.22569,50.00000,42.00000,2.152958e-10,0.86310,4
569.99298,329.92000,      4.27090,     -1.22569,50.00000,42.00000,2.152958e-10,0.86310,4
571.61798,330.00000,      4.22575,     -1.20553,50.00000,42.00000,2.151299e-10,0.86305,4
573.26099,330.08000,      4.18401,     -1.19881,50.00000,42.00000,2.151299e-10,0.86305,4
574.90503,330.16000,      4.14153,     -1.17213,50.00000,42.00000,2.158375e-10,0.86300,4
576.53302,330.24000,      4.09987,     -1.17213,50.00000,42.00000,2.158375e-10,0.86300,4
578.17401,330.32000,      4.05890,     -1.14526,50.00000,42.00000,2.152729e-10,0.86294,4
579.79999,330.40000,      4.01657,     -1.14526,50.00000,42.00000,2.152729e-10,0.86294,4
581.44098,330.48000,      3.97769,     -1.11838,50.00000,42.00000,2.152938e-10,0.86289,4
583.08197,330.56000,      3.93643,     -1.09150,50.00000,42.00000,2.152938e-10,0.86289,4
584.71100,330.64000,      3.90153,     -1.06482,50.00000,42.00000,2.152863e-10,0.86285,4
586.36102,330.72000,      3.86408,     -1.03794,50.00000,42.00000,2.152863e-10,0.86285,4
587.98297,330.80000,      3.83270,     -1.03794,50.00000,42.00000,2.159519e-10,0.86279,4
589.61298,330.88000,      3.79705,     -1.03794,50.00000,42.00000,2.159519e-10,0.86279,4
591.24500,330.96000,      3.76041,     -1.01107,50.00000,42.00000,2.153721e-10,0.86275,4
592.88202,331.04000,      3.72584,     -1.01107,50.00000,42.00000,2.153721e-10,0.86275,4
594.50897,331.12000,      3.68885,     -0.98202,50.00000,42.00000,2.158986e-10,0.86270,4
596.13300,331.20000,      3.65419,     -0.96186,50.00000,42.00000,2.158986e-10,0.86270,4
597.77399,331.28000,      3.61665,     -0.94170,50.00000,42.00000,2.157593e-10,0.86265,4
599.40399,331.36000,      3.58618,     -0.92826,50.00000,42.00000,2.157593e-10,0.86265,4
601.03900,331.44000,      3.54913,     -0.92826,50.00000,42.00000,2.156239e-10,0.86260,4
602.66998,331.52000,      3.51416,     -0.91502,50.00000,42.00000,2.156239e-10,0.86260,4
604.29102,331.60000,      3.47786,     -0.90158,50.00000,42.00000,2.151050e-10,0.86254,4
605.92603,331.68000,      3.44062,     -0.87470,50.00000,42.00000,2.151050e-10,0.86254,4
607.55902,331.76000,      3.40038,     -0.87470,50.00000,42.00000,2.154694e-10,0.86250,4
609.17999,331.84000,      3.36190,     -0.84783,50.00000,42.00000,2.154694e-10,0.86250,4
610.81598,331.92000,      3.32473,     -0.84111,50.00000,42.00000,2.156010e-10,0.86243,4
612.44598,332.00000,      3.28625,     -0.82095,50.00000,42.00000,2.156010e-10,0.86243,4
614.08197,332.08000,      3.24535,     -0.79427,50.00000,42.00000,2.150307e-10,0.86240,4
615.69800,332.16000,      3.20336,     -0.79427,50.00000,42.00000,2.150307e-10,0.86240,4
617.33002,332.24000,      3.16438,     -0.79427,50.00000,42.00000,2.153721e-10,0.86235,4
618.95502,332.32000,      3.12265,     -0.76739,50.00000,42.00000,2.153721e-10,0.86235,4
620.58698,332.40000,      3.08336,     -0.76739,50.00000,42.00000,2.152137e-10,0.86229,4
622.19897,332.48000,      3.03723,     -0.74051,50.00000,42.00000,2.152137e-10,0.86229,4
623.82703,332.56000,      2.99529,     -0.72036,50.00000,42.00000,2.150593e-10,0.86225,4
625.46100,332.64000,      2.95348,     -0.71364,50.00000,42.00000,2.150593e-10,0.86225,4
627.08698,332.72000,      2.91264,     -0.68696,50.00000,42.00000,2.156239e-10,0.86220,4
628.71100,332.80000,      2.87019,     -0.68696,50.00000,42.00000,2.156239e-10,0.86220,4
630.33197,332.88000,      2.82582,     -0.66008,50.00000,42.00000,2.157955e-10,0.86214,4
631.95398,332.96000,      2.78476,     -0.63320,50.00000,42.00000,2.157955e-10,0.86214,4
633.57300,333.04000,      2.73802,     -0.63320,50.00000,42.00000,2.159023e-10,0.86209,4
635.20099,333.12000,      2.69404,     -0.63320,50.00000,42.00000,2.159023e-10,0.86209,4
636.81702,333.20000,      2.64956,     -0.60632,50.00000,42.00000,2.156582e-10,0.86204,4
638.44800,333.28000,      2.60320,     -0.57964,50.00000,42.00000,2.156582e-10,0.86204,4
640.07098,333.36000,      2.55928,     -0.57964,50.00000,42.00000,2.156162e-10,0.86200,4
641.67603,333.44000,      2.50987,     -0.57964,50.00000,42.00000,2.156162e-10,0.86200,4
643.30103,333.52000,      2.46415,     -0.55277,50.00000,42.00000,2.164554e-10,0.86194,4
644.91998,333.60000,      2.41884,     -0.52589,50.00000,42.00000,2.164554e-10,0.86194,4
646.53998,333.68000,      2.37130,     -0.52589,50.00000,42.00000,2.164554e-10,0.86194,4
648.16101,333.76000,      2.32418,     -0.49684,50.00000,42.00000,2.156582e-10,0.86189,4
649.78198,333.84000,      2.28013,     -0.49684,50.00000,42.00000,2.156582e-10,0.86189,4
651.40698,333.92000,      2.22825,     -0.46996,50.00000,42.00000,2.153377e-10,0.86184,4
653.02100,334.00000,      2.17201,     -0.46996,50.00000,42.00000,2.153377e-10,0.86184,4
654.63098,334.08000,      2.12506,     -0.44308,50.00000,42.00000,2.153663e-10,0.86180,4
656.24500,334.16000,      2.07795,     -0.44308,50.00000,42.00000,2.153663e-10,0.86180,4
657.86902,334.24000,      2.03130,     -0.41640,50.00000,42.00000,2.158547e-10,0.86176,4
659.49500,334.32000,      1.98567,     -0.40296,50.00000,42.00000,2.158547e-10,0.86176,4
661.10797,334.40000,      1.94046,     -0.38953,50.00000,42.00000,2.147808e-10,0.86170,4
662.72900,334.48000,      1.89391,     -0.38953,50.00000,42.00000,2.147808e-10,0.86170,4
664.34900,334.56000,      1.85049,     -0.36265,50.00000,42.00000,2.152671e-10,0.86165,4
665.96503,334.64000,      1.80271,     -0.33577,50.00000,42.00000,2.152671e-10,0.86165,4
667.57599,334.72000,      1.75206,     -0.33577,50.00000,42.00000,2.155896e-10,0.86160,4
669.19897,334.80000,      1.70397,     -0.30909,50.00000,42.00000,2.155896e-10,0.86160,4
670.81702,334.88000,      1.65420,     -0.30909,50.00000,42.00000,2.153148e-10,0.86155,4
672.44098,334.96000,      1.60669,     -0.28893,50.00000,42.00000,2.153148e-10,0.86155,4
674.05701,335.04000,      1.55870,     -0.28893,50.00000,42.00000,2.162094e-10,0.86150,4
675.66400,335.12000,      1.50630,     -0.25534,50.00000,42.00000,2.162094e-10,0.86150,4
677.28699,335.20000,      1.43617,     -0.25534,50.00000,42.00000,2.154674e-10,0.86145,4
678.90900,335.28000,      1.38342,     -0.22846,50.00000,42.00000,2.154674e-10,0.86145,4
680.51801,335.36000,      1.32897,     -0.21502,50.00000,42.00000,2.154618e-10,0.86140,4
682.13800,335.44000,      1.27709,     -0.20178,50.00000,42.00000,2.154618e-10,0.86140,4
683.75000,335.52000,      1.22626,     -0.20178,50.00000,42.00000,2.152595e-10,0.86134,4
685.35699,335.60000,      1.16945,     -0.18834,50.00000,42.00000,2.152595e-10,0.86134,4
686.97498,335.68000,      1.11432,     -0.17490,50.00000,42.00000,2.152309e-10,0.86129,4
688.59601,335.76000,      1.05962,     -0.17490,50.00000,42.00000,2.152309e-10,0.86129,4
690.21002,335.84000,      1.00751,     -0.14802,50.00000,42.00000,2.153168e-10,0.86126,4
691.81403,335.92000,      0.95829,     -0.14802,50.00000,42.00000,2.153168e-10,0.86126,4
693.43799,336.00000,      0.90525,     -0.12115,50.00000,42.00000,2.152386e-10,0.86120,4
695.04102,336.08000,      0.85295,     -0.12115,50.00000,42.00000,2.152386e-10,0.86120,4
696.66602,336.16000,      0.80514,     -0.10119,50.00000,42.00000,2.150631e-10,0.86114,4
698.27100,336.24000,      0.75221,     -0.10119,50.00000,42.00000,2.150631e-10,0.86114,4
699.89203,336.32000,      0.70285,-6.758893e-02,50.00000,42.00000,2.155266e-10,0.86110,4
701.51202,336.40000,      0.65148,-6.758893e-02,50.00000,42.00000,2.155266e-10,0.86110,4
703.13599,336.48000,      0.59871,-6.758893e-02,50.00000,42.00000,2.152443e-10,0.86104,4
704.74701,336.56000,      0.55106,-4.743083e-02,50.00000,42.00000,2.152443e-10,0.86104,4
706.36102,336.64000,      0.49391,-3.399209e-02,50.00000,42.00000,2.156639e-10,0.86100,4
707.96399,336.72000,      0.43972,-1.383399e-02,50.00000,42.00000,2.156639e-10,0.86100,4
709.59601,336.80000,      0.39224, 1.284585e-02,50.00000,42.00000,2.154179e-10,0.86096,4
711.21301,336.88000,      0.33836, 1.284585e-02,50.00000,42.00000,2.154179e-10,0.86096,4
712.83197,336.96000,      0.28557, 1.284585e-02,50.00000,42.00000,2.154179e-10,0.86096,4
714.43298,337.04000,      0.23607, 3.972332e-02,50.00000,42.00000,2.150536e-10,0.86090,4
716.04797,337.12000,      0.18769, 3.972332e-02,50.00000,42.00000,2.150536e-10,0.86090,4
717.65503,337.20000,      0.13476, 6.660079e-02,50.00000,42.00000,2.150955e-10,0.86085,4
719.27802,337.28000, 8.891912e-02, 6.660079e-02,50.00000,42.00000,2.150955e-10,0.86085,4
720.88300,337.36000, 3.726149e-02, 6.660079e-02,50.00000,42.00000,2.158318e-10,0.86081,4
722.48999,337.44000,-1.423059e-02,      0.12036,50.00000,42.00000,2.158318e-10,0.86081,4
724.10999,337.52000,-6.682347e-02,      0.12036,50.00000,42.00000,2.148724e-10,0.86075,4
725.72601,337.60000,     -0.11418,      0.12036,50.00000,42.00000,2.148724e-10,0.86075,4
727.33801,337.68000,     -0.16580,      0.14704,50.00000,42.00000,2.150364e-10,0.86070,4
728.95898,337.76000,     -0.22584,      0.14704,50.00000,42.00000,2.150364e-10,0.86070,4
730.56799,337.84000,     -0.27746,      0.14704,50.00000,42.00000,2.150097e-10,0.86065,4
732.17499,337.92000,     -0.32603,      0.17391,50.00000,42.00000,2.150097e-10,0.86065,4
733.78497,338.00000,     -0.37985,      0.20079,50.00000,42.00000,2.153740e-10,0.86059,4
735.40198,338.08000,     -0.43223,      0.20079,50.00000,42.00000,2.153740e-10,0.86059,4
737.02399,338.16000,     -0.48156,      0.22767,50.00000,42.00000,2.152882e-10,0.86055,4
738.63098,338.24000,     -0.52782,      0.22767,50.00000,42.00000,2.152882e-10,0.86055,4
740.24200,338.32000,     -0.58095,      0.22767,50.00000,42.00000,2.150155e-10,0.86050,4
741.85199,338.40000,     -0.62877,      0.25435,50.00000,42.00000,2.150155e-10,0.86050,4
743.45801,338.48000,     -0.67414,      0.28123,50.00000,42.00000,2.158700e-10,0.86044,4
745.08502,338.56000,     -0.72353,      0.28123,50.00000,42.00000,2.158700e-10,0.86044,4
746.70203,338.64000,     -0.77208,      0.28123,50.00000,42.00000,2.150860e-10,0.86039,4
748.30902,338.72000,     -0.82530,      0.28123,50.00000,42.00000,2.150860e-10,0.86039,4
749.92401,338.80000,     -0.86797,      0.31028,50.00000,42.00000,2.152138e-10,0.86035,4
751.54999,338.88000,     -0.91337,      0.32372,50.00000,42.00000,2.152138e-10,0.86035,4
753.15198,338.96000,     -0.96311,      0.33043,50.00000,42.00000,2.154064e-10,0.86029,4
754.76501,339.04000,     -1.01006,      0.33715,50.00000,42.00000,2.154064e-10,0.86029,4
756.38599,339.12000,     -1.05455,      0.36403,50.00000,42.00000,2.149066e-10,0.86025,4
757.99799,339.20000,     -1.10568,      0.36403,50.00000,42.00000,2.149066e-10,0.86025,4
759.60498,339.28000,     -1.15041,      0.39071,50.00000,42.00000,2.153130e-10,0.86020,4
761.22400,339.36000,     -1.19856,      0.39071,50.00000,42.00000,2.153130e-10,0.86020,4
762.82599,339.44000,     -1.25076,      0.41759,50.00000,42.00000,2.146969e-10,0.86015,4
764.44702,339.52000,     -1.29754,      0.44447,50.00000,42.00000,2.146969e-10,0.86015,4
766.05798,339.60000,     -1.34412,      0.44447,50.00000,42.00000,2.150097e-10,0.86008,4
767.66302,339.68000,     -1.39180,      0.47134,50.00000,42.00000,2.150097e-10,0.86008,4
769.28400,339.76000,     -1.44228,      0.47134,50.00000,42.00000,2.149295e-10,0.86004,4
770.88599,339.84000,     -1.48991,      0.49802,50.00000,42.00000,2.149295e-10,0.86004,4
772.48901,339.92000,     -1.53634,      0.49802,50.00000,42.00000,2.154407e-10,0.85999,4
774.10602,340.00000,     -1.58227,      0.52490,50.00000,42.00000,2.154407e-10,0.85999,4
775.71100,340.08000,     -1.63129,      0.52490,50.00000,42.00000,2.154445e-10,0.85993,4
777.32300,340.16000,     -1.67680,      0.54506,50.00000,42.00000,2.154445e-10,0.85993,4
778.92401,340.24000,     -1.72842,      0.57866,50.00000,42.00000,2.146244e-10,0.85989,4
780.53198,340.32000,     -1.77253,      0.57866,50.00000,42.00000,2.146244e-10,0.85989,4
782.14398,340.40000,     -1.81844,      0.57866,50.00000,42.00000,2.151394e-10,0.85984,4
783.75000,340.48000,     -1.86647,      0.60553,50.00000,42.00000,2.151394e-10,0.85984,4
785.36902,340.56000,     -1.91065,      0.60553,50.00000,42.00000,2.148800e-10,0.85979,4
786.96997,340.64000,     -1.95492,      0.61206,50.00000,42.00000,2.148800e-10,0.85979,4
788.58099,340.72000,     -2.00169,      0.65909,50.00000,42.00000,2.148800e-10,0.85979,4
790.18597,340.80000,     -2.04723,      0.65909,50.00000,42.00000,2.152309e-10,0.85974,4
791.80402,340.88000,     -2.09461,      0.68597,50.00000,42.00000,            ,0.44817,4
793.41302,340.96000,     -2.13941,      0.68597,50.00000,42.00000,            ,0.44753,4
794.21503,341.00000,     -2.16556,      0.68597,50.00000,42.00000,            ,0.44721,4