File: data/TGA/005d-L_M/ExpDat_2025_02_25_005d-L3-isothermal-1K.csv
#EXPORTTYPE:                 ,DATA ALL
#FILE:                       ,2025_02_25_005d-L3-isothermal-1K.ngb-ss5
#FORMAT:                     ,NETZSCH5
#FTYPE:                      ,ASCII
#IDENTITY:                   ,005d-L3
#DECIMAL:                    ,POINT
#SEPARATOR:                  ,COMMA
#MTYPE:                      ,DSC
#INSTRUMENT:                 ,NETZSCH STA 449F5
#PROJECT:                    ,PS
#DATE/TIME:                  ,2/25/2025 4:41:59 PM (UTC-5)
#CORR. FILE:                 ,
#TEMPCAL:                    ,13-11-2024 10:37
#SENSITIVITY:                ,28-06-2023 13:53
#LABORATORY:                 ,Tran/Aspuru
#OPERATOR:                   ,Stanley
#REMARK:                     ,
#SAMPLE:                     ,005d-L3
#SAMPLE MASS /mg:            ,5.17
#MATERIAL:                   ,
#REFERENCE:                  ,
#REFERENCE MASS /mg:         ,0
#TYPE OF CRUCIBLE:           ,Al2O3 85 ‘l, open
#SAMPLE CRUCIBLE MASS /mg:   ,0
#REFERENCE CRUCIBLE MASS /mg:,0
#DSC RANGE /‘V:              ,5000
#TG RANGE /mg:               ,35000
#TAU-R:                      ,---
#CORR. CODE:                 ,000
#EXO:                        ,-1
#RANGE:                      ,30›C....800›C/0.0....20.0K/min
#SEGMENT:                    ,S1-5/5
#SEG. 1:                     ,30›C/10.0(K/min)/100›C
#SEG. 2:                     ,100›C/00:10/100›C
#SEG. 3:                     ,100›C/5.0(K/min)/300›C
#SEG. 4:                     ,300›C/20:00/300›C
#SEG. 5:                     ,300›C/20.0(K/min)/800›C

##Temp./›C,Time/min,DSC/(mW/mg),Mass/%,Gas Flow(purge2)/(ml/min),Gas Flow(protective)/(ml/min),TIC(scan:1)/A,Sensit./(uV/mW),Segment
 30.46600,   0.00000,      0.74533,    100.00000,50.00000,50.00000,            ,0.92364,1
 35.33800,   1.36000,      0.62799,     86.00600,50.00000,50.00000,1.982365e-10,0.92381,1
 42.16300,   2.72000,      0.93950,     93.19226,50.00000,50.00000,1.980743e-10,0.92401,1
 51.65700,   4.08000,      1.43692,     94.21199,50.00000,50.00000,1.984615e-10,0.92419,1
 64.53700,   5.44000,      2.04776,     95.27756,50.00000,50.00000,1.987800e-10,0.92440,1
 79.80700,   6.80000,      2.57840,     95.98008,50.00000,50.00000,1.995640e-10,0.92461,1
 88.62300,   7.56000,      2.64327,     95.92766,50.00000,50.00000,1.993637e-10,0.92474,2
 94.78200,   8.24000,      2.16738,     95.12456,50.00000,50.00000,1.992359e-10,0.92484,2
 99.09100,   8.92000,      1.57590,     94.23830,50.00000,50.00000,1.999855e-10,0.92495,2
102.32700,   9.60000,      1.19074,     93.51838,50.00000,50.00000,1.998711e-10,0.92505,2
105.02300,  10.28000,      0.95806,     93.02379,50.00000,50.00000,2.008171e-10,0.92518,2
107.05400,  10.96000,      0.72264,     92.38472,50.00000,50.00000,1.995258e-10,0.92528,2
108.37900,  11.64000,      0.46579,     91.73926,50.00000,50.00000,1.995506e-10,0.92537,2
109.05200,  12.32000,      0.23777,     91.12650,50.00000,50.00000,1.996422e-10,0.92547,2
109.35500,  13.00000, 6.185769e-02,     90.71954,50.00000,50.00000,1.998825e-10,0.92556,2
109.28800,  13.68000,-7.519161e-02,     90.13075,50.00000,50.00000,2.009029e-10,0.92566,2
108.95800,  14.36000,     -0.17832,     89.66692,50.00000,50.00000,2.007427e-10,0.92576,2
108.44400,  15.04000,     -0.25957,     89.29052,50.00000,50.00000,2.001305e-10,0.92585,2
107.80000,  15.72000,     -0.31604,     88.96228,50.00000,50.00000,1.999816e-10,0.92592,2
107.06900,  16.40000,     -0.35129,     88.66692,50.00000,50.00000,1.997909e-10,0.92599,2
106.16800,  17.20000,     -0.36516,     88.37795,50.00000,50.00000,1.999855e-10,0.92607,3
106.51400,  18.56000,      0.12714,     88.88356,50.00000,50.00000,2.004699e-10,0.92616,3
109.56800,  19.92000,      0.58970,     89.35184,50.00000,50.00000,2.013664e-10,0.92620,3
114.35800,  21.28000,      0.97773,     89.78956,50.00000,50.00000,2.011623e-10,0.92618,3
120.78600,  22.64000,      1.31469,     90.08046,50.00000,50.00000,2.012520e-10,0.92608,3
128.16000,  24.00000,      1.53348,     90.16151,50.00000,50.00000,2.018242e-10,0.92591,3
136.05000,  25.36000,      1.66282,     90.18781,50.00000,50.00000,2.012043e-10,0.92566,3
144.08400,  26.72000,      1.71573,     90.16809,50.00000,50.00000,2.010974e-10,0.92528,3
152.03500,  28.08000,      1.72243,     90.18124,50.00000,50.00000,2.012864e-10,0.92483,3
159.76601,  29.44000,      1.70303,     90.21180,50.00000,50.00000,2.013741e-10,0.92444,3
167.24300,  30.80000,      1.66631,     90.26441,50.00000,50.00000,2.012997e-10,0.92415,3
174.50700,  32.16000,      1.62529,     90.29052,50.00000,50.00000,2.020359e-10,0.92381,3
181.59900,  33.52000,      1.58755,     90.34313,50.00000,50.00000,2.020130e-10,0.92350,3
188.55800,  34.88000,      1.55231,     90.38897,50.00000,50.00000,2.021980e-10,0.92320,3
195.45200,  36.24000,      1.52774,     90.40870,50.00000,50.00000,2.026615e-10,0.92286,3
202.28300,  37.60000,      1.50058,     90.47215,50.00000,50.00000,2.018794e-10,0.92258,3
209.08400,  38.96000,      1.48120,     90.47660,50.00000,50.00000,2.016944e-10,0.92230,3
215.83400,  40.32000,      1.45920,     90.53559,50.00000,50.00000,2.017689e-10,0.92201,3
222.60201,  41.68000,      1.43807,     90.56847,50.00000,50.00000,2.024555e-10,0.92177,3
229.34801,  43.04000,      1.40940,     90.61451,50.00000,50.00000,2.030220e-10,0.92155,3
236.12601,  44.40000,      1.38831,     90.67350,50.00000,50.00000,2.030659e-10,0.92130,3
242.89500,  45.76000,      1.35780,     90.71296,50.00000,50.00000,2.028751e-10,0.92110,3
249.66600,  47.12000,      1.32793,     90.76538,50.00000,50.00000,2.022324e-10,0.92090,3
256.42899,  48.48000,      1.29066,     90.78511,50.00000,50.00000,2.033519e-10,0.92071,3
263.18500,  49.84000,      1.25498,     90.80484,50.00000,50.00000,2.032528e-10,0.92051,3
269.95999,  51.20000,      1.21350,     90.84429,50.00000,50.00000,2.025852e-10,0.92032,3
276.72699,  52.56000,      1.16859,     90.89671,50.00000,50.00000,2.035370e-10,0.92015,3
283.50201,  53.92000,      1.12329,     90.89671,50.00000,50.00000,2.035065e-10,0.91996,3
290.25201,  55.28000,      1.07364,     90.89671,50.00000,50.00000,2.040214e-10,0.91979,3
297.04001,  56.64000,      1.02370,     90.88356,50.00000,50.00000,2.035789e-10,0.91964,3
302.93500,  59.56000,     -0.77635,     90.83772,50.00000,41.00000,2.031917e-10,0.91932,4
302.51099,  62.96000,     -1.25955,     90.13075,50.00000,41.00000,2.037926e-10,0.91902,4
301.31400,  66.36000,     -1.25438,     89.63191,50.00000,41.00000,2.037831e-10,0.91881,4
300.60300,  69.76000,     -1.20793,     89.18549,50.00000,41.00000,2.036305e-10,0.91865,4
300.26199,  73.16000,     -1.17893,     88.77408,50.00000,41.00000,2.035523e-10,0.91855,4
300.11099,  76.56000,     -1.16710,     88.41083,50.00000,41.00000,2.044734e-10,0.91849,4
300.05200,  79.96000,     -1.16346,     88.11760,50.00000,41.00000,2.043266e-10,0.91847,4
300.02200,  83.36000,     -1.16360,     87.81354,50.00000,41.00000,2.043590e-10,0.91849,4
300.00699,  86.76000,     -1.16002,     87.51141,50.00000,41.00000,2.046890e-10,0.91853,4
300.00299,  90.16000,     -1.16151,     87.25764,50.00000,41.00000,2.048130e-10,0.91861,4
300.01700,  93.56000,     -1.16322,     87.00387,50.00000,41.00000,2.057247e-10,0.91870,4
300.00900,  96.96000,     -1.16171,     86.79362,50.00000,41.00000,2.061176e-10,0.91881,4
300.02200, 100.36000,     -1.16679,     86.55745,50.00000,41.00000,2.063980e-10,0.91893,4
300.02200, 103.76000,     -1.16679,     86.33424,50.00000,41.00000,2.063389e-10,0.91905,4
300.01199, 107.16000,     -1.16977,     86.11103,50.00000,41.00000,2.059555e-10,0.91918,4
300.00699, 110.56000,     -1.17258,     85.93810,50.00000,41.00000,2.055206e-10,0.91931,4
300.00699, 113.96000,     -1.17202,     85.74778,50.00000,41.00000,2.053967e-10,0.91949,4
300.01501, 117.36000,     -1.17147,     85.53114,50.00000,41.00000,2.058773e-10,0.91930,4
300.01999, 120.76000,     -1.17466,     85.34952,50.00000,41.00000,2.060318e-10,0.91882,4
300.01401, 124.16000,     -1.17390,     85.15899,50.00000,41.00000,2.065086e-10,0.91812,4
300.00800, 127.56000,     -1.17427,     84.91625,50.00000,41.00000,2.059707e-10,0.91722,4
300.01599, 130.96000,     -1.17653,     84.75203,50.00000,41.00000,2.052173e-10,0.91602,4
300.02499, 134.36000,     -1.17523,     84.57041,50.00000,41.00000,2.056560e-10,0.91455,4
300.01901, 137.76000,     -1.17578,     84.41934,50.00000,41.00000,2.060299e-10,0.91287,4
300.01199, 141.16000,     -1.17521,     84.23559,50.00000,41.00000,2.072467e-10,0.91107,4
300.01401, 144.56000,     -1.17671,     84.05184,50.00000,41.00000,2.072143e-10,0.90901,4
300.01401, 147.96000,     -1.17634,     83.88337,50.00000,41.00000,2.071419e-10,0.90679,4
300.01801, 151.36000,     -1.17747,     83.70174,50.00000,41.00000,2.070618e-10,0.90445,4
300.01501, 154.76000,     -1.17878,     83.54623,50.00000,41.00000,2.080460e-10,0.90215,4
300.00699, 158.16000,     -1.18064,     83.37563,50.00000,41.00000,2.082139e-10,0.89965,4
300.01300, 161.56000,     -1.18027,     83.21141,50.00000,41.00000,2.080765e-10,0.89709,4
300.01901, 164.96000,     -1.18159,     83.02766,50.00000,41.00000,2.075958e-10,0.89461,4
300.01001, 168.36000,     -1.18121,     82.84159,50.00000,41.00000,2.074547e-10,0.89197,4
300.01599, 171.76000,     -1.18140,     82.68859,50.00000,41.00000,2.077446e-10,0.88930,4
300.00699, 175.16000,     -1.18345,     82.52437,50.00000,41.00000,2.070713e-10,0.88658,4
300.01401, 178.56000,     -1.18309,     82.32089,50.00000,41.00000,2.037563e-10,0.88395,4
300.02701, 181.96000,     -1.18104,     82.15010,50.00000,41.00000,2.023716e-10,0.88115,4
300.01501, 185.36000,     -1.18421,     81.99923,50.00000,41.00000,1.952534e-10,0.87830,4
300.02701, 188.76000,     -1.18217,     81.78472,50.00000,41.00000,1.949253e-10,0.87554,4
300.01599, 192.16000,     -1.18815,     81.61838,50.00000,41.00000,1.947422e-10,0.87259,4
300.01599, 195.56000,     -1.18496,     81.46093,50.00000,41.00000,1.948242e-10,0.86960,4
300.01001, 198.96000,     -1.18514,     81.29014,50.00000,41.00000,1.944446e-10,0.86656,4
300.01300, 202.36000,     -1.18646,     81.11083,50.00000,41.00000,1.942005e-10,0.86361,4
300.01999, 205.76000,     -1.18516,     80.90077,50.00000,41.00000,1.945915e-10,0.86047,4
300.01801, 209.16000,     -1.18853,     80.72785,50.00000,41.00000,1.948948e-10,0.85727,4
300.02399, 212.56000,     -1.18854,     80.57021,50.00000,41.00000,1.949481e-10,0.85402,4
300.02499, 215.96000,     -1.18798,     80.38646,50.00000,41.00000,1.947670e-10,0.85074,4
300.01501, 219.36000,     -1.18721,     80.19613,50.00000,41.00000,1.945687e-10,0.84755,4
300.01801, 222.76000,     -1.17991,     80.03849,50.00000,41.00000,1.952324e-10,0.84415,4
300.02200, 226.16000,     -1.17485,     79.87660,50.00000,41.00000,1.951885e-10,0.84072,4
300.02802, 229.56000,     -1.17598,     79.68627,50.00000,41.00000,1.950111e-10,0.83723,4
300.02600, 232.96000,     -1.17523,     79.50890,50.00000,41.00000,1.950035e-10,0.83387,4
300.01599, 236.36000,     -1.17503,     79.33830,50.00000,41.00000,1.953125e-10,0.83032,4
300.00400, 239.76000,     -1.17276,     79.18066,50.00000,41.00000,1.958408e-10,0.82689,4
300.01501, 243.16000,     -1.17353,     78.98375,50.00000,41.00000,1.956940e-10,0.82326,4
300.01501, 246.56000,     -1.17315,     78.82186,50.00000,41.00000,1.959152e-10,0.81959,4
300.01199, 249.96000,     -1.17671,     78.65338,50.00000,41.00000,1.961784e-10,0.81606,4
300.00900, 253.36000,     -1.17296,     78.47389,50.00000,41.00000,1.970844e-10,0.81233,4
300.03699, 256.76000,     -1.17787,     78.33385,50.00000,41.00000,1.966304e-10,0.80858,4
300.01700, 260.16000,     -1.17765,     78.12379,50.00000,41.00000,1.974697e-10,0.80479,4
300.02100, 263.56000,     -1.17972,     77.95957,50.00000,41.00000,1.974697e-10,0.80116,4
300.01001, 266.96000,     -1.17802,     77.77369,50.00000,41.00000,1.970100e-10,0.79733,4
300.01099, 270.36000,     -1.18027,     77.59420,50.00000,41.00000,1.975650e-10,0.79347,4
300.00500, 273.76000,     -1.17876,     77.41702,50.00000,41.00000,1.973705e-10,0.78978,4
300.01501, 277.16000,     -1.17915,     77.22650,50.00000,41.00000,1.982173e-10,0.78523,4
300.03101, 280.56000,     -1.17711,     77.01644,50.00000,41.00000,1.983757e-10,0.78422,4
300.02399, 283.96000,     -1.17766,     76.85242,50.00000,41.00000,1.978053e-10,0.78469,4
300.02899, 287.36000,     -1.18067,     76.65319,50.00000,41.00000,1.985683e-10,0.78544,4
300.01001, 290.76000,     -1.18177,     76.48472,50.00000,41.00000,1.985798e-10,0.78606,4
300.01901, 294.16000,     -1.18253,     76.27679,50.00000,41.00000,1.987610e-10,0.78650,4
300.03101, 297.56000,     -1.18311,     76.11277,50.00000,41.00000,1.982460e-10,0.78677,4
300.01199, 300.96000,     -1.18458,     75.88956,50.00000,41.00000,1.987400e-10,0.78693,4
300.01901, 304.36000,     -1.18234,     75.71219,50.00000,41.00000,1.995734e-10,0.78704,4
300.01700, 307.76000,     -1.18122,     75.53501,50.00000,41.00000,1.993827e-10,0.78711,4
300.01999, 311.16000,     -1.18141,     75.36441,50.00000,41.00000,1.990337e-10,0.78715,4
300.00699, 314.56000,     -1.18420,     75.17389,50.00000,41.00000,1.992683e-10,0.78716,4
300.01700, 317.96000,     -1.18103,     74.99671,50.00000,41.00000,1.997375e-10,0.78718,4
300.01700, 321.36000,     -1.18572,     74.79981,50.00000,41.00000,2.003765e-10,0.78719,4
300.01901, 324.76000,     -1.18441,     74.61586,50.00000,41.00000,1.995240e-10,0.78719,4
300.02200, 328.16000,     -1.18422,     74.45841,50.00000,41.00000,1.997661e-10,0.78719,4
300.01300, 331.56000,     -1.18721,     74.24836,50.00000,41.00000,2.002811e-10,0.78719,4
300.01700, 334.96000,     -1.18478,     74.09072,50.00000,41.00000,2.000904e-10,0.78719,4
300.01801, 338.36000,     -1.18684,     73.89381,50.00000,41.00000,2.011165e-10,0.78720,4
300.01001, 341.76000,     -1.18833,     73.68375,50.00000,41.00000,2.012138e-10,0.78718,4
300.01999, 345.16000,     -1.18891,     73.50658,50.00000,41.00000,2.010918e-10,0.78719,4
300.01199, 348.56000,     -1.18608,     73.32263,50.00000,41.00000,2.008819e-10,0.78718,4
300.01099, 351.96000,     -1.18571,     73.13675,50.00000,41.00000,2.013950e-10,0.78719,4
300.00400, 355.36000,     -1.18720,     72.95280,50.00000,41.00000,2.014008e-10,0.78717,4
300.01099, 358.76000,     -1.18702,     72.76905,50.00000,41.00000,2.014943e-10,0.78719,4
300.00699, 362.16000,     -1.18926,     72.57872,50.00000,41.00000,2.017098e-10,0.78719,4
300.01300, 365.56000,     -1.19302,     72.42108,50.00000,41.00000,2.015590e-10,0.78720,4
300.01401, 368.96000,     -1.18946,     72.21103,50.00000,41.00000,2.014084e-10,0.78720,4
300.00201, 372.36000,     -1.18944,     72.02070,50.00000,41.00000,2.024669e-10,0.78719,4
300.01700, 375.76000,     -1.18984,     71.86306,50.00000,41.00000,2.016029e-10,0.78721,4
300.02600, 379.16000,     -1.19248,     71.65087,50.00000,41.00000,2.020760e-10,0.78719,4
300.01501, 382.56000,     -1.19509,     71.46480,50.00000,41.00000,2.013129e-10,0.78721,4
299.99200, 385.96000,     -1.19299,     71.28104,50.00000,41.00000,2.022132e-10,0.78720,4
300.01801, 389.36000,     -1.19134,     71.09072,50.00000,41.00000,2.028637e-10,0.78719,4
300.01999, 392.76000,     -1.19116,     70.91335,50.00000,41.00000,2.031689e-10,0.78720,4
300.01801, 396.16000,     -1.19584,     70.73404,50.00000,41.00000,2.030563e-10,0.78719,4
300.01801, 399.56000,     -1.19490,     70.55455,50.00000,41.00000,2.024384e-10,0.78718,4
300.01599, 402.96000,     -1.19471,     70.35764,50.00000,41.00000,2.024822e-10,0.78718,4
300.01901, 406.36000,     -1.19640,     70.16054,50.00000,41.00000,2.034740e-10,0.78719,4
300.01700, 409.76000,     -1.19378,     70.00309,50.00000,41.00000,2.030010e-10,0.78720,4
300.02399, 413.16000,     -1.19660,     69.79961,50.00000,41.00000,2.027989e-10,0.78719,4
300.00101, 416.56000,     -1.19675,     69.60696,50.00000,41.00000,2.033902e-10,0.78719,4
300.01599, 419.96000,     -1.19790,     69.44952,50.00000,41.00000,2.035218e-10,0.78719,4
300.01401, 423.36000,     -1.19602,     69.28530,50.00000,41.00000,2.032394e-10,0.78719,4
300.00900, 426.76000,     -1.19358,     69.10155,50.00000,41.00000,2.036438e-10,0.78718,4
300.01099, 430.16000,     -1.19489,     68.87834,50.00000,41.00000,2.041951e-10,0.78719,4
300.01099, 433.56000,     -1.19471,     68.69439,50.00000,41.00000,2.044201e-10,0.78718,4
300.00699, 436.96000,     -1.19545,     68.49749,50.00000,41.00000,2.037640e-10,0.78719,4
300.00900, 440.36000,     -1.19733,     68.33346,50.00000,41.00000,2.036724e-10,0.78719,4
300.02499, 443.76000,     -1.19922,     68.14952,50.00000,41.00000,2.043342e-10,0.78720,4
300.02200, 447.16000,     -1.19678,     67.97234,50.00000,41.00000,2.045841e-10,0.78720,4
300.02600, 450.56000,     -1.19623,     67.80812,50.00000,41.00000,2.046814e-10,0.78720,4
300.01099, 453.96000,     -1.19789,     67.59807,50.00000,41.00000,2.045803e-10,0.78720,4
300.01801, 457.36000,     -1.19715,     67.43404,50.00000,41.00000,2.040405e-10,0.78719,4
300.00900, 460.76000,     -1.20033,     67.27640,50.00000,41.00000,2.047157e-10,0.78719,4
300.01401, 464.16000,     -1.19846,     67.07950,50.00000,41.00000,2.049999e-10,0.78719,4
300.01300, 467.56000,     -1.20371,     66.89574,50.00000,41.00000,2.053013e-10,0.78720,4
300.00400, 470.96000,     -1.19882,     66.69226,50.00000,41.00000,2.058620e-10,0.78720,4
300.01199, 474.36000,     -1.20164,     66.52147,50.00000,41.00000,2.050495e-10,0.78720,4
300.00601, 477.76000,     -1.20145,     66.33772,50.00000,41.00000,2.060470e-10,0.78719,4
300.02100, 481.16000,     -1.20259,     66.15397,50.00000,41.00000,2.061195e-10,0.78719,4
300.01599, 484.56000,     -1.20165,     65.98762,50.00000,41.00000,2.062492e-10,0.78716,4
300.02100, 487.96000,     -1.19997,     65.80368,50.00000,41.00000,2.060318e-10,0.78720,4
300.01801, 491.36000,     -1.20203,     65.63965,50.00000,41.00000,2.062149e-10,0.78718,4
300.01501, 494.76000,     -1.20521,     65.44932,50.00000,41.00000,2.064018e-10,0.78719,4
300.00000, 498.16000,     -1.20856,     65.29826,50.00000,41.00000,2.065467e-10,0.78719,4
300.01099, 501.56000,     -1.20183,     65.13424,50.00000,41.00000,2.074757e-10,0.78718,4
300.02802, 504.96000,     -1.20579,     64.94371,50.00000,41.00000,2.068863e-10,0.78719,4
300.01199, 508.36000,     -1.20333,     64.78627,50.00000,41.00000,2.077999e-10,0.78719,4
300.00900, 511.76000,     -1.20464,     64.58279,50.00000,41.00000,2.075577e-10,0.78719,4
300.01599, 515.16000,     -1.20727,     64.41857,50.00000,41.00000,2.077637e-10,0.78721,4
300.02499, 518.56000,     -1.20654,     64.23482,50.00000,41.00000,2.081642e-10,0.78719,4
300.01501, 521.96000,     -1.20840,     64.05087,50.00000,41.00000,2.076950e-10,0.78719,4
300.01199, 525.36000,     -1.21120,     63.89342,50.00000,41.00000,2.077351e-10,0.78719,4
300.00201, 528.76000,     -1.21213,     63.67021,50.00000,41.00000,2.085686e-10,0.78719,4
300.00800, 532.16000,     -1.21326,     63.49284,50.00000,41.00000,2.079315e-10,0.78719,4
300.01099, 535.56000,     -1.21120,     63.34855,50.00000,41.00000,2.085476e-10,0.78719,4
300.02499, 538.96000,     -1.20691,     63.15822,50.00000,41.00000,2.090149e-10,0.78719,4
300.01801, 542.36000,     -1.21121,     62.97427,50.00000,41.00000,2.083015e-10,0.78719,4
300.01599, 545.76000,     -1.21046,     62.84294,50.00000,41.00000,2.088413e-10,0.78719,4
300.01599, 549.16000,     -1.20990,     62.66132,50.00000,41.00000,2.088794e-10,0.78719,4
300.01300, 552.56000,     -1.20971,     62.48414,50.00000,41.00000,2.093201e-10,0.78719,4
300.01099, 555.96000,     -1.21120,     62.30696,50.00000,41.00000,2.095680e-10,0.78718,4
300.01401, 559.36000,     -1.20746,     62.14932,50.00000,41.00000,2.092418e-10,0.78719,4
300.01599, 562.76000,     -1.21158,     61.97215,50.00000,41.00000,2.094803e-10,0.78719,4
300.02399, 566.16000,     -1.21028,     61.80793,50.00000,41.00000,2.093334e-10,0.78719,4
300.02100, 569.56000,     -1.20466,     61.65048,50.00000,41.00000,2.098294e-10,0.78719,4
300.02100, 572.96000,     -1.21459,     61.47311,50.00000,40.00000,2.104797e-10,0.78720,4
300.02100, 576.36000,     -1.21047,     61.27621,50.00000,40.00000,2.105618e-10,0.78720,4
300.01700, 579.76000,     -1.21177,     61.11219,50.00000,40.00000,2.104206e-10,0.78719,4
300.01501, 583.16000,     -1.21514,     60.92824,50.00000,40.00000,2.110118e-10,0.78719,4
300.00699, 586.56000,     -1.21157,     60.74449,50.00000,40.00000,2.109851e-10,0.78720,4
300.00400, 589.96000,     -1.21082,     60.56074,50.00000,40.00000,2.110824e-10,0.78719,4
300.00201, 593.36000,     -1.21400,     60.41625,50.00000,40.00000,2.113609e-10,0.78720,4
300.01801, 596.76000,     -1.21402,     60.20619,50.00000,40.00000,2.115917e-10,0.78720,4
300.01300, 600.16000,     -1.21458,     60.02224,50.00000,40.00000,2.118473e-10,0.78717,4
299.99899, 603.56000,     -1.21250,     59.85822,50.00000,41.00000,2.111454e-10,0.78717,4
300.00699, 606.96000,     -1.21663,     59.68104,50.00000,41.00000,2.116547e-10,0.78718,4
300.00500, 610.36000,     -1.21775,     59.50368,50.00000,41.00000,2.118263e-10,0.78720,4
300.00800, 613.76000,     -1.21438,     59.31335,50.00000,41.00000,2.118263e-10,0.78718,4
300.03000, 617.16000,     -1.21835,     59.12959,50.00000,41.00000,2.119998e-10,0.78719,4
300.01599, 620.56000,     -1.21571,     58.95010,50.00000,41.00000,2.129631e-10,0.78719,4
300.01901, 623.96000,     -1.21646,     58.79903,50.00000,41.00000,2.125797e-10,0.78720,4
300.01401, 627.36000,     -1.21608,     58.61528,50.00000,41.00000,2.128220e-10,0.78719,4
300.01099, 630.76000,     -1.21870,     58.45106,50.00000,41.00000,2.131748e-10,0.78720,4
300.02899, 634.16000,     -1.21741,     58.28046,50.00000,41.00000,2.122135e-10,0.78720,4
300.01199, 637.56000,     -1.21983,     58.10986,50.00000,41.00000,2.129555e-10,0.78717,4
300.01401, 640.96000,     -1.22377,     57.94565,50.00000,41.00000,2.129746e-10,0.78719,4
300.01700, 644.36000,     -1.22171,     57.76847,50.00000,41.00000,2.124195e-10,0.78718,4
300.02802, 647.76000,     -1.21985,     57.59768,50.00000,41.00000,2.135525e-10,0.78718,4
300.01599, 651.16000,     -1.22189,     57.44681,50.00000,41.00000,2.134991e-10,0.78718,4
300.01599, 654.56000,     -1.22096,     57.29574,50.00000,41.00000,2.133808e-10,0.78719,4
300.02802, 657.96000,     -1.22172,     57.15783,50.00000,41.00000,2.140331e-10,0.78719,4
300.01199, 661.36000,     -1.21983,     56.99381,50.00000,41.00000,2.145462e-10,0.78719,4
300.00601, 664.76000,     -1.22019,     56.82302,50.00000,41.00000,2.140560e-10,0.78719,4
300.01501, 668.16000,     -1.22114,     56.67215,50.00000,41.00000,2.147789e-10,0.78719,4
300.01901, 671.56000,     -1.22021,     56.49478,50.00000,41.00000,2.148342e-10,0.78719,4
300.02899, 674.96000,     -1.22098,     56.33733,50.00000,40.00000,2.147713e-10,0.78719,4
300.02301, 678.36000,     -1.22265,     56.15338,50.00000,40.00000,2.153855e-10,0.78718,4
300.01801, 681.76000,     -1.22171,     56.00019,50.00000,40.00000,2.147465e-10,0.78719,4
300.02899, 685.16000,     -1.22210,     55.81644,50.00000,40.00000,2.151052e-10,0.78719,4
300.02200, 688.56000,     -1.22134,     55.65899,50.00000,40.00000,2.148323e-10,0.78718,4
300.01099, 691.96000,     -1.22208,     55.51451,50.00000,40.00000,2.145920e-10,0.78719,4
300.01801, 695.36000,     -1.22433,     55.32418,50.00000,40.00000,2.155094e-10,0.78720,4
300.01999, 698.76000,     -1.22584,     55.17311,50.00000,40.00000,2.150669e-10,0.78720,4
300.02701, 702.16000,     -1.22510,     54.97621,50.00000,40.00000,2.156315e-10,0.78720,4
300.01001, 705.56000,     -1.22489,     54.83830,50.00000,40.00000,2.146454e-10,0.78719,4
300.01999, 708.96000,     -1.22303,     54.65222,50.00000,40.00000,1.989593e-10,0.78720,4
300.01801, 712.36000,     -1.22490,     54.48162,50.00000,40.00000,1.987190e-10,0.78718,4
300.01099, 715.76000,     -1.22939,     54.35029,50.00000,40.00000,1.991863e-10,0.78719,4
300.01700, 719.16000,     -1.22752,     54.17311,50.00000,40.00000,1.992874e-10,0.78719,4
300.01001, 722.56000,     -1.22620,     54.00232,50.00000,40.00000,1.988792e-10,0.78719,4
300.01801, 725.96000,     -1.22733,     53.84487,50.00000,40.00000,1.993542e-10,0.78718,4
300.01401, 729.36000,     -1.22527,     53.64797,50.00000,40.00000,1.985226e-10,0.78719,4
300.01401, 732.76000,     -1.23145,     53.46402,50.00000,40.00000,1.991748e-10,0.78719,4
300.01501, 736.16000,     -1.22920,     53.31315,50.00000,40.00000,1.991252e-10,0.78719,4
300.00699, 739.56000,     -1.23144,     53.15551,50.00000,40.00000,1.989669e-10,0.78719,4
300.01001, 742.96000,     -1.22920,     52.95861,50.00000,40.00000,1.997128e-10,0.78719,4
300.02802, 746.36000,     -1.23204,     52.82070,50.00000,40.00000,1.997814e-10,0.78719,4
300.02200, 749.76000,     -1.23634,     52.63694,50.00000,41.00000,1.990928e-10,0.78719,4
300.01700, 753.16000,     -1.23446,     52.48588,50.00000,41.00000,1.994705e-10,0.78720,4
300.00900, 756.56000,     -1.23332,     52.32843,50.00000,41.00000,1.999778e-10,0.78721,4
300.01300, 759.96000,     -1.23520,     52.14449,50.00000,41.00000,2.002505e-10,0.78721,4
300.01501, 763.36000,     -1.23670,     52.00677,50.00000,41.00000,1.993828e-10,0.78721,4
300.02100, 766.76000,     -1.23521,     51.84913,50.00000,41.00000,2.002219e-10,0.78720,4
300.00400, 770.16000,     -1.23462,     51.68491,50.00000,41.00000,1.996783e-10,0.78718,4
300.01999, 773.56000,     -1.23484,     51.56692,50.00000,41.00000,2.004375e-10,0.78720,4
300.02399, 776.96000,     -1.23447,     51.38956,50.00000,41.00000,2.001552e-10,0.78719,4
300.01001, 780.36000,     -1.23482,     51.25164,50.00000,41.00000,2.006283e-10,0.78718,4
300.01199, 783.76000,     -1.23670,     51.10735,50.00000,40.00000,2.008934e-10,0.78720,4
300.02200, 787.16000,     -1.23578,     50.96944,50.00000,40.00000,2.003498e-10,0.78719,4
300.01999, 790.56000,     -1.23427,     50.80522,50.00000,40.00000,2.008285e-10,0.78720,4
300.01300, 793.96000,     -1.23464,     50.62805,50.00000,40.00000,2.005577e-10,0.78720,4
300.01300, 797.36000,     -1.23633,     50.49014,50.00000,40.00000,2.013702e-10,0.78719,4
300.01901, 800.76000,     -1.23427,     50.35010,50.00000,40.00000,2.015361e-10,0.78718,4
300.01700, 804.16000,     -1.23914,     50.20580,50.00000,40.00000,2.019444e-10,0.78718,4
300.01700, 807.56000,     -1.23671,     50.06132,50.00000,40.00000,2.014255e-10,0.78719,4
300.03299, 810.96000,     -1.23729,     49.90368,50.00000,40.00000,2.014810e-10,0.78719,4
300.01401, 814.36000,     -1.23820,     49.71992,50.00000,40.00000,2.011967e-10,0.78720,4
300.01999, 817.76000,     -1.24027,     49.56228,50.00000,40.00000,2.014503e-10,0.78721,4
300.02200, 821.16000,     -1.24121,     49.41141,50.00000,40.00000,2.022018e-10,0.78719,4
300.01001, 824.56000,     -1.24026,     49.25164,50.00000,40.00000,2.020893e-10,0.78720,4
300.01401, 827.96000,     -1.24101,     49.06789,50.00000,40.00000,2.028274e-10,0.78719,4
300.01501, 831.36000,     -1.23989,     48.93656,50.00000,40.00000,2.024613e-10,0.78719,4
300.02200, 834.76000,     -1.24009,     48.79207,50.00000,40.00000,2.030525e-10,0.78718,4
300.01801, 838.16000,     -1.24364,     48.63462,50.00000,40.00000,2.031517e-10,0.78719,4
300.01801, 841.56000,     -1.24308,     48.47698,50.00000,40.00000,2.035446e-10,0.78720,4
300.02200, 844.96000,     -1.24065,     48.31934,50.00000,40.00000,2.034054e-10,0.78720,4
300.00500, 848.36000,     -1.24269,     48.16190,50.00000,40.00000,2.034607e-10,0.78719,4
300.02100, 851.76000,     -1.24084,     48.02186,50.00000,40.00000,2.039031e-10,0.78718,4
300.02802, 855.16000,     -1.24141,     47.86422,50.00000,40.00000,2.045288e-10,0.78719,4
300.02399, 858.56000,     -1.24253,     47.74603,50.00000,40.00000,2.038994e-10,0.78718,4
300.00900, 861.96000,     -1.24382,     47.59729,50.00000,40.00000,2.035865e-10,0.78719,4
300.01001, 865.36000,     -1.24401,     47.47253,50.00000,40.00000,2.042961e-10,0.78722,4
300.00900, 868.76000,     -1.24288,     47.29536,50.00000,40.00000,2.041092e-10,0.78721,4
300.01901, 872.16000,     -1.24346,     47.16402,50.00000,40.00000,2.039470e-10,0.78719,4
300.00201, 875.56000,     -1.24531,     47.00870,50.00000,40.00000,2.050228e-10,0.78720,4
300.01999, 878.96000,     -1.24440,     46.86209,50.00000,40.00000,2.046947e-10,0.78721,4
300.02899, 882.36000,     -1.24441,     46.67814,50.00000,40.00000,2.050724e-10,0.78721,4
300.01300, 885.76000,     -1.24645,     46.54043,50.00000,40.00000,2.050095e-10,0.78717,4
300.00900, 889.16000,     -1.24494,     46.40251,50.00000,40.00000,2.055855e-10,0.78719,4
300.01300, 892.56000,     -1.24532,     46.27118,50.00000,40.00000,2.049369e-10,0.78719,4
300.01501, 895.96000,     -1.24476,     46.09400,50.00000,40.00000,2.046928e-10,0.78720,4
300.01501, 899.36000,     -1.24645,     45.96925,50.00000,40.00000,2.050266e-10,0.78720,4
300.04001, 902.76000,     -1.24461,     45.79845,50.00000,40.00000,2.051868e-10,0.78719,4
300.01099, 906.16000,     -1.24495,     45.66074,50.00000,40.00000,2.052860e-10,0.78720,4
300.00400, 909.56000,     -1.24306,     45.52940,50.00000,40.00000,2.046374e-10,0.78718,4
300.01401, 912.96000,     -1.24476,     45.39807,50.00000,40.00000,2.050552e-10,0.78720,4
300.00400, 916.36000,     -1.24362,     45.23404,50.00000,40.00000,2.047158e-10,0.78719,4
300.01300, 919.76000,     -1.24307,     45.09613,50.00000,40.00000,2.048512e-10,0.78719,4
300.02301, 923.16000,     -1.24440,     44.94739,50.00000,40.00000,2.056732e-10,0.78719,4
300.03000, 926.56000,     -1.24385,     44.83578,50.00000,40.00000,2.052688e-10,0.78720,4
300.03299, 929.96000,     -1.24592,     44.66499,50.00000,40.00000,2.053223e-10,0.78718,4
300.02499, 933.36000,     -1.25003,     44.51393,50.00000,40.00000,2.052002e-10,0.78719,4
300.03101, 936.76000,     -1.24835,     44.38279,50.00000,40.00000,2.062721e-10,0.78719,4
300.01999, 940.16000,     -1.24946,     44.22515,50.00000,40.00000,2.051773e-10,0.78719,4
300.02100, 943.56000,     -1.25002,     44.06112,50.00000,40.00000,2.052422e-10,0.78719,4
300.01300, 946.96000,     -1.24420,     43.91663,50.00000,40.00000,2.054004e-10,0.78719,4
300.02301, 950.36000,     -1.24946,     43.77215,50.00000,40.00000,2.056961e-10,0.78720,4
300.01599, 953.76000,     -1.24908,     43.63211,50.00000,40.00000,2.053089e-10,0.78720,4
300.02200, 957.16000,     -1.24852,     43.46151,50.00000,40.00000,2.056942e-10,0.78720,4
300.01700, 960.56000,     -1.24870,     43.33017,50.00000,40.00000,2.043438e-10,0.78720,4
300.03500, 963.96000,     -1.24779,     43.15938,50.00000,40.00000,2.045116e-10,0.78719,4
300.01099, 967.36000,     -1.24813,     43.03250,50.00000,39.00000,2.049923e-10,0.78719,4
300.02399, 970.76000,     -1.24684,     42.86847,50.00000,39.00000,2.037143e-10,0.78718,4
300.00699, 974.16000,     -1.24944,     42.73056,50.00000,39.00000,2.048645e-10,0.78719,4
300.00900, 977.56000,     -1.24888,     42.62553,50.00000,39.00000,2.052345e-10,0.78719,4
300.01401, 980.96000,     -1.25076,     42.47447,50.00000,39.00000,2.038536e-10,0.78720,4
300.01999, 984.36000,     -1.24702,     42.33675,50.00000,39.00000,2.050781e-10,0.78719,4
300.01001, 987.76000,     -1.24794,     42.17911,50.00000,39.00000,2.049351e-10,0.78718,4
300.02701, 991.16000,     -1.24534,     42.03462,50.00000,39.00000,2.050819e-10,0.78718,4
300.01300, 994.56000,     -1.24701,     41.89458,50.00000,39.00000,2.049618e-10,0.78719,4
300.00900, 997.96000,     -1.24813,     41.72398,50.00000,39.00000,2.054481e-10,0.78719,4
300.01999,1001.36000,     -1.24758,     41.61238,50.00000,39.00000,2.056351e-10,0.78720,4
300.01501,1004.76000,     -1.24701,     41.47447,50.00000,39.00000,2.054710e-10,0.78719,4
300.00900,1008.16000,     -1.24850,     41.34101,50.00000,39.00000,2.056255e-10,0.78719,4
300.01300,1011.56000,     -1.24776,     41.18337,50.00000,39.00000,2.056103e-10,0.78718,4
300.01199,1014.96000,     -1.24870,     41.04990,50.00000,39.00000,2.064514e-10,0.78720,4
300.01199,1018.36000,     -1.24476,     40.92959,50.00000,39.00000,2.061329e-10,0.78719,4
300.02100,1021.76000,     -1.24702,     40.77215,50.00000,39.00000,2.063141e-10,0.78719,4
300.00601,1025.16000,     -1.25150,     40.58820,50.00000,39.00000,2.070846e-10,0.78719,4
300.01801,1028.56000,     -1.25039,     40.48975,50.00000,39.00000,2.066745e-10,0.78718,4
300.01099,1031.96000,     -1.25094,     40.32573,50.00000,40.00000,2.065238e-10,0.78718,4
300.00900,1035.36000,     -1.24907,     40.18124,50.00000,40.00000,2.067967e-10,0.78718,4
300.00500,1038.76000,     -1.25187,     40.02360,50.00000,40.00000,2.077198e-10,0.78719,4
300.00000,1042.16000,     -1.24812,     39.89014,50.00000,40.00000,2.077159e-10,0.78720,4
300.02301,1045.56000,     -1.25227,     39.71954,50.00000,40.00000,2.065639e-10,0.78720,4
300.02301,1048.96000,     -1.24871,     39.59265,50.00000,40.00000,2.069015e-10,0.78720,4
300.01501,1052.36000,     -1.25320,     39.45919,50.00000,40.00000,2.070102e-10,0.78720,4
300.01801,1055.76000,     -1.25133,     39.31257,50.00000,40.00000,2.077312e-10,0.78720,4
300.00601,1059.16000,     -1.25225,     39.18124,50.00000,40.00000,2.079468e-10,0.78719,4
300.01401,1062.56000,     -1.25132,     39.03675,50.00000,40.00000,2.085380e-10,0.78720,4
300.02600,1065.96000,     -1.25303,     38.88569,50.00000,40.00000,2.088528e-10,0.78718,4
300.02200,1069.36000,     -1.25209,     38.73482,50.00000,41.00000,2.086830e-10,0.78718,4
300.03101,1072.76000,     -1.24947,     38.57505,50.00000,41.00000,2.090245e-10,0.78719,4
300.02802,1076.16000,     -1.25153,     38.49632,50.00000,41.00000,2.085819e-10,0.78718,4
300.00601,1079.56000,     -1.25675,     38.33868,50.00000,41.00000,2.084294e-10,0.78718,4
300.01300,1082.96000,     -1.25282,     38.17466,50.00000,41.00000,2.088604e-10,0.78719,4
300.01801,1086.36000,     -1.25620,     38.06963,50.00000,41.00000,2.085819e-10,0.78719,4
300.02200,1089.76000,     -1.25246,     37.90329,50.00000,41.00000,2.086429e-10,0.78719,4
300.02701,1093.16000,     -1.25828,     37.79826,50.00000,41.00000,2.086125e-10,0.78719,4
300.01501,1096.56000,     -1.25582,     37.65822,50.00000,41.00000,2.079639e-10,0.78720,4
300.00800,1099.96000,     -1.25750,     37.51373,50.00000,41.00000,2.093373e-10,0.78720,4
300.01300,1103.36000,     -1.25620,     37.38897,50.00000,41.00000,2.085800e-10,0.78719,4
300.01501,1106.76000,     -1.25901,     37.25996,50.00000,41.00000,2.084523e-10,0.78719,4
300.01801,1110.16000,     -1.25789,     37.10677,50.00000,41.00000,2.089596e-10,0.78718,4
300.00800,1113.56000,     -1.25863,     36.97969,50.00000,41.00000,2.094593e-10,0.78719,4
300.00500,1116.96000,     -1.25525,     36.87911,50.00000,41.00000,2.091446e-10,0.78719,4
300.01999,1120.36000,     -1.25696,     36.72805,50.00000,41.00000,2.094841e-10,0.78719,4
300.01700,1123.76000,     -1.25320,     36.60986,50.00000,41.00000,2.094403e-10,0.78720,4
300.01801,1127.16000,     -1.25414,     36.49400,50.00000,41.00000,2.093620e-10,0.78719,4
300.01001,1130.56000,     -1.25582,     36.36267,50.00000,41.00000,2.098408e-10,0.78719,4
300.01501,1133.96000,     -1.25301,     36.25106,50.00000,41.00000,2.096882e-10,0.78719,4
300.02200,1137.36000,     -1.25209,     36.10658,50.00000,41.00000,2.095184e-10,0.78719,4
300.02802,1140.76000,     -1.25491,     35.97969,50.00000,41.00000,2.103500e-10,0.78720,4
300.01199,1144.16000,     -1.25413,     35.84178,50.00000,41.00000,2.107983e-10,0.78719,4
300.01999,1147.56000,     -1.25902,     35.73462,50.00000,41.00000,2.094345e-10,0.78720,4
300.01001,1150.96000,     -1.25563,     35.59014,50.00000,41.00000,2.109584e-10,0.78721,4
300.00601,1154.36000,     -1.25525,     35.50716,50.00000,41.00000,2.094823e-10,0.78719,4
300.00900,1157.76000,     -1.25282,     35.32321,50.00000,41.00000,2.108898e-10,0.78719,4
300.01199,1161.16000,     -1.25320,     35.21161,50.00000,41.00000,2.104625e-10,0.78719,4
300.01401,1164.56000,     -1.25489,     35.04101,50.00000,41.00000,2.110920e-10,0.78719,4
300.01700,1167.96000,     -1.25414,     34.92282,50.00000,41.00000,2.114124e-10,0.78720,4
300.03201,1171.36000,     -1.25585,     34.79807,50.00000,41.00000,2.112523e-10,0.78720,4
300.01599,1174.76000,     -1.25714,     34.65803,50.00000,42.00000,2.122631e-10,0.78719,4
300.01999,1178.16000,     -1.25827,     34.51586,50.00000,42.00000,2.126255e-10,0.78719,4
299.99899,1181.56000,     -1.25786,     34.41721,50.00000,42.00000,2.126694e-10,0.78720,4
299.99600,1184.96000,     -1.25430,     34.29033,50.00000,42.00000,2.133789e-10,0.78719,4
300.01001,1188.36000,     -1.25900,     34.14603,50.00000,42.00000,2.134914e-10,0.78719,4
300.01999,1191.76000,     -1.25996,     34.00812,50.00000,42.00000,2.134342e-10,0.78719,4
300.01599,1195.16000,     -1.25770,     33.90967,50.00000,42.00000,2.143573e-10,0.78718,4
300.00699,1198.56000,     -1.25994,     33.77834,50.00000,42.00000,2.135715e-10,0.78720,4
300.01099,1201.96000,     -1.26013,     33.63385,50.00000,42.00000,2.139739e-10,0.78719,4
300.01901,1205.36000,     -1.25789,     33.48956,50.00000,42.00000,2.148495e-10,0.78719,4
300.00400,1208.76000,     -1.26087,     33.38878,50.00000,42.00000,2.150383e-10,0.78719,4
300.01501,1212.16000,     -1.25545,     33.26190,50.00000,42.00000,2.155285e-10,0.78719,4
300.01501,1215.56000,     -1.26107,     33.15687,50.00000,42.00000,2.150936e-10,0.78719,4
300.01300,1218.96000,     -1.25901,     32.99923,50.00000,42.00000,2.149715e-10,0.78718,4
300.01801,1222.36000,     -1.26014,     32.90735,50.00000,43.00000,2.154255e-10,0.78718,4
300.00800,1225.76000,     -1.26200,     32.78259,50.00000,43.00000,2.154789e-10,0.78719,4
300.01599,1229.16000,     -1.25939,     32.68414,50.00000,43.00000,2.157402e-10,0.78720,4
300.02100,1232.56000,     -1.26127,     32.55938,50.00000,43.00000,2.164098e-10,0.78718,4
300.01401,1235.96000,     -1.26445,     32.42824,50.00000,43.00000,2.168389e-10,0.78720,4
300.01901,1239.36000,     -1.26127,     32.32321,50.00000,43.00000,2.160283e-10,0.78719,4
300.02600,1242.76000,     -1.25903,     32.23114,50.00000,43.00000,2.165451e-10,0.78721,4
300.01501,1246.16000,     -1.26089,     32.12611,50.00000,42.00000,2.162132e-10,0.78719,4
300.01999,1249.56000,     -1.26183,     32.02108,50.00000,42.00000,2.162724e-10,0.78720,4
300.02899,1252.96000,     -1.26184,     31.92921,50.00000,42.00000,2.161941e-10,0.78720,4
300.02899,1256.36000,     -1.26372,     31.78472,50.00000,42.00000,2.164116e-10,0.78720,4
300.08600,1257.10000,     -1.24337,     31.71702,50.00000,50.00000,2.158470e-10,0.78718,5
300.47699,1257.27000,     -0.96034,     31.69729,50.00000,50.00000,2.155494e-10,0.78720,5
301.46100,1257.44000,     -0.29558,     31.65571,50.00000,50.00000,2.152099e-10,0.78718,5
303.09299,1257.61000,      0.69785,     31.77176,50.00000,50.00000,2.154922e-10,0.78719,5
305.33099,1257.78000,      1.86184,     32.01025,50.00000,50.00000,2.149143e-10,0.78718,5
308.04199,1257.95000,      3.02814,     32.28588,50.00000,50.00000,2.149372e-10,0.78718,5
311.02600,1258.12000,      4.04414,     32.58356,50.00000,50.00000,2.144890e-10,0.78718,5
314.15201,1258.29000,      4.81100,     32.78046,50.00000,50.00000,2.150459e-10,0.78719,5
317.24899,1258.46000,      5.30433,     32.93153,50.00000,50.00000,2.159786e-10,0.78720,5
320.30600,1258.63000,      5.54929,     33.02128,50.00000,50.00000,2.158910e-10,0.78719,5
323.23199,1258.80000,      5.61627,     33.10000,50.00000,50.00000,2.162514e-10,0.78719,5
326.08801,1258.97000,      5.58033,     33.15242,50.00000,50.00000,2.161675e-10,0.78718,5
328.90701,1259.14000,      5.52099,     33.15242,50.00000,50.00000,2.156677e-10,0.78719,5
331.73999,1259.31000,      5.49505,     33.20503,50.00000,50.00000,2.153873e-10,0.78719,5
334.66901,1259.48000,      5.54492,     33.23133,50.00000,50.00000,2.152253e-10,0.78719,5
337.71100,1259.65000,      5.67609,     33.31006,50.00000,50.00000,2.152215e-10,0.78719,5
340.88000,1259.82000,      5.88138,     33.34294,50.00000,50.00000,2.155399e-10,0.78719,5
344.18799,1259.99000,      6.13081,     33.38878,50.00000,50.00000,2.158661e-10,0.78718,5
347.63901,1260.16000,      6.40701,     33.45455,50.00000,50.00000,2.159042e-10,0.78720,5
351.16101,1260.33000,      6.66431,     33.49381,50.00000,50.00000,2.157326e-10,0.78718,5
354.74899,1260.50000,      6.89102,     33.53327,50.00000,50.00000,2.159348e-10,0.78719,5
358.37900,1260.67000,      7.06155,     33.49381,50.00000,50.00000,2.152519e-10,0.78719,5
362.03000,1260.84000,      7.18604,     33.46750,50.00000,50.00000,2.161522e-10,0.78719,5
365.66901,1261.01000,      7.26414,     33.41296,50.00000,50.00000,2.151890e-10,0.78719,5
369.32800,1261.18000,      7.31245,     33.33404,50.00000,50.00000,2.153625e-10,0.78719,5
372.96799,1261.35000,      7.33365,     33.18085,50.00000,50.00000,2.156601e-10,0.78719,5
376.60400,1261.52000,      7.35639,     32.99710,50.00000,50.00000,2.152557e-10,0.78719,5
380.26001,1261.69000,      7.37220,     32.75416,50.00000,50.00000,2.156563e-10,0.78719,5
383.92001,1261.86000,      7.39458,     32.44352,50.00000,50.00000,2.146950e-10,0.78719,5
387.58899,1262.03000,      7.43059,     32.06267,50.00000,50.00000,2.161179e-10,0.78720,5
391.26700,1262.20000,      7.46820,     31.60542,50.00000,50.00000,2.159195e-10,0.78720,5
394.97000,1262.37000,      7.51837,     31.05822,50.00000,50.00000,2.153130e-10,0.78718,5
398.65100,1262.54000,      7.57146,     30.35803,50.00000,50.00000,2.157783e-10,0.78718,5
402.38699,1262.71000,      7.63512,     29.50464,50.00000,50.00000,2.153339e-10,0.78718,5
406.05899,1262.88000,      7.70270,     28.44545,50.00000,50.00000,2.159729e-10,0.78719,5
409.73099,1263.05000,      7.76560,     27.24197,50.00000,50.00000,2.157821e-10,0.78719,5
413.41400,1263.22000,      7.83081,     25.88530,50.00000,50.00000,2.158184e-10,0.78719,5
417.08899,1263.39000,      7.91080,     24.24836,50.00000,50.00000,2.154999e-10,0.78719,5
420.74500,1263.56000,      7.99119,     22.34681,50.00000,50.00000,2.159061e-10,0.78718,5
424.40500,1263.73000,      8.06408,     20.22843,50.00000,50.00000,2.156238e-10,0.78719,5
428.03201,1263.90000,      8.12340,     17.98337,50.00000,50.00000,2.153453e-10,0.78719,5
431.65701,1264.07000,      8.16307,     15.55222,50.00000,50.00000,2.146702e-10,0.78718,5
435.28000,1264.24000,      8.17405,     13.07060,50.00000,50.00000,2.160091e-10,0.78719,5
438.88901,1264.41000,      8.13807,     10.57602,50.00000,50.00000,2.147045e-10,0.78718,5
442.49399,1264.58000,      8.06063,      8.23675,50.00000,50.00000,2.147998e-10,0.78718,5
446.07501,1264.75000,      7.92686,      6.08124,50.00000,50.00000,2.151203e-10,0.78719,5
449.65799,1264.92000,      7.74057,      4.27157,50.00000,50.00000,2.152939e-10,0.78718,5
453.24100,1265.09000,      7.51655,      2.69381,50.00000,50.00000,2.149601e-10,0.78719,5
456.81799,1265.26000,      7.26479,      1.46402,50.00000,50.00000,2.158299e-10,0.78718,5
460.37900,1265.43000,      7.00308,      0.54720,50.00000,50.00000,2.156239e-10,0.78719,5
463.93701,1265.60000,      6.74118,     -0.15300,50.00000,50.00000,2.158127e-10,0.78718,5
467.49500,1265.77000,      6.49406,     -0.57544,50.00000,50.00000,2.149219e-10,0.78719,5
471.04199,1265.94000,      6.26328,     -0.87311,50.00000,50.00000,2.157478e-10,0.78719,5
474.57300,1266.11000,      6.05753,     -0.95609,50.00000,50.00000,2.150859e-10,0.78719,5
478.12399,1266.28000,      5.87772,     -0.98240,50.00000,50.00000,2.150707e-10,0.78719,5
481.63501,1266.45000,      5.72422,     -0.95609,50.00000,50.00000,2.157593e-10,0.78719,5
485.14801,1266.62000,      5.59013,     -0.95609,50.00000,50.00000,2.157574e-10,0.78720,5
488.66199,1266.79000,      5.47307,     -0.90368,50.00000,50.00000,2.152653e-10,0.78719,5
492.17200,1266.96000,      5.36242,     -0.85106,50.00000,50.00000,2.151565e-10,0.78719,5
495.67001,1267.13000,      5.26549,     -0.82495,50.00000,50.00000,2.156086e-10,0.78720,5
499.15201,1267.30000,      5.15473,     -0.79865,50.00000,50.00000,2.147369e-10,0.78720,5
502.62399,1267.47000,      5.05297,     -0.74603,50.00000,50.00000,2.156391e-10,0.78720,5
506.10800,1267.64000,      4.95314,     -0.71992,50.00000,50.00000,2.156448e-10,0.78719,5
509.57401,1267.81000,      4.84866,     -0.66731,50.00000,50.00000,2.155209e-10,0.78719,5
513.03497,1267.98000,      4.74973,     -0.64101,50.00000,50.00000,2.152767e-10,0.78719,5
516.50800,1268.15000,      4.66224,     -0.58414,50.00000,50.00000,2.154770e-10,0.78719,5
519.96899,1268.32000,      4.58072,     -0.55783,50.00000,50.00000,2.155800e-10,0.78719,5
523.45599,1268.49000,      4.49595,     -0.50542,50.00000,50.00000,2.150288e-10,0.78719,5
526.91901,1268.66000,      4.40358,     -0.47911,50.00000,50.00000,2.157402e-10,0.78719,5
530.36798,1268.83000,      4.29905,     -0.42669,50.00000,50.00000,2.152920e-10,0.78718,5
533.81299,1269.00000,      4.18784,     -0.40039,50.00000,50.00000,2.156734e-10,0.78719,5
537.23901,1269.17000,      4.07670,     -0.34778,50.00000,50.00000,2.156525e-10,0.78718,5
540.67297,1269.34000,      3.96528,     -0.32166,50.00000,50.00000,2.159938e-10,0.78717,5
544.09698,1269.51000,      3.85271,     -0.27563,50.00000,50.00000,2.152099e-10,0.78719,5
547.52100,1269.68000,      3.75506,     -0.24275,50.00000,50.00000,2.152252e-10,0.78719,5
550.94501,1269.85000,      3.65879,     -0.21663,50.00000,50.00000,2.153015e-10,0.78719,5
554.37097,1270.02000,      3.56133,     -0.16402,50.00000,50.00000,2.148380e-10,0.78719,5
557.79901,1270.19000,      3.46817,-8.529981e-02,50.00000,50.00000,2.150746e-10,0.78720,5
561.22498,1270.36000,      3.37305,-8.529981e-02,50.00000,50.00000,2.156907e-10,0.78720,5
564.64899,1270.53000,      3.27439,-5.241779e-02,50.00000,50.00000,2.151394e-10,0.78719,5
568.07202,1270.70000,      3.17347,-2.398453e-02,50.00000,50.00000,2.161121e-10,0.78719,5
571.49701,1270.87000,      3.07721, 4.158607e-02,50.00000,50.00000,2.159500e-10,0.78720,5
574.91101,1271.04000,      2.98296, 1.547389e-02,50.00000,50.00000,2.155266e-10,0.78719,5
578.33301,1271.21000,      2.87823, 6.789168e-02,50.00000,50.00000,2.151718e-10,0.78720,5
581.75201,1271.38000,      2.76907,      0.12263,50.00000,50.00000,2.149029e-10,0.78720,5
585.17902,1271.55000,      2.66680,      0.14894,50.00000,50.00000,2.157326e-10,0.78720,5
588.60303,1271.72000,      2.56443,      0.17524,50.00000,50.00000,2.160034e-10,0.78719,5
592.01300,1271.89000,      2.44646,      0.22766,50.00000,50.00000,2.154655e-10,0.78720,5
595.42499,1272.06000,      2.33923,      0.33056,50.00000,50.00000,2.153626e-10,0.78719,5
598.85400,1272.23000,      2.23141,      0.30426,50.00000,50.00000,2.152729e-10,0.78719,5
602.27197,1272.40000,      2.12212,      0.30426,50.00000,50.00000,2.158584e-10,0.78720,5
605.68597,1272.57000,      2.01026,      0.31083,50.00000,50.00000,2.157192e-10,0.78720,5
609.11200,1272.74000,      1.90611,      0.36344,50.00000,50.00000,2.152768e-10,0.78720,5
612.52002,1272.91000,      1.79274,      0.40928,50.00000,50.00000,2.155132e-10,0.78720,5
615.92798,1273.08000,      1.67819,      0.44217,50.00000,50.00000,2.154694e-10,0.78719,5
619.35999,1273.25000,      1.56138,      0.46847,50.00000,50.00000,2.155456e-10,0.78720,5
622.77197,1273.42000,      1.44252,      0.49458,50.00000,50.00000,2.150059e-10,0.78720,5
626.17999,1273.59000,      1.31907,      0.52089,50.00000,50.00000,2.157822e-10,0.78720,5
629.60199,1273.76000,      1.19952,      0.54720,50.00000,50.00000,2.157155e-10,0.78720,5
633.01398,1273.93000,      1.07055,      0.59961,50.00000,50.00000,2.154618e-10,0.78720,5
636.41901,1274.10000,      0.93321,      0.62592,50.00000,50.00000,2.158470e-10,0.78720,5
639.83698,1274.27000,      0.81949,      0.65222,50.00000,50.00000,2.153587e-10,0.78719,5
643.24402,1274.44000,      0.69891,      0.67853,50.00000,50.00000,2.158986e-10,0.78719,5
646.65002,1274.61000,      0.56883,      0.70464,50.00000,50.00000,2.152557e-10,0.78719,5
650.06500,1274.78000,      0.43610,      0.75725,50.00000,50.00000,2.147522e-10,0.78718,5
653.47498,1274.95000,      0.29753,      0.78356,50.00000,50.00000,2.154465e-10,0.78719,5
656.88800,1275.12000,      0.18127,      0.80967,50.00000,50.00000,2.150478e-10,0.78718,5
660.29498,1275.29000, 3.999674e-02,      0.83598,50.00000,50.00000,2.153722e-10,0.78719,5
663.70801,1275.46000,-9.285716e-02,      0.86228,50.00000,50.00000,2.158795e-10,0.78719,5
667.13202,1275.63000,     -0.24188,      1.07447,50.00000,50.00000,2.161789e-10,0.78719,5
670.53400,1275.80000,     -0.37832,      0.93230,50.00000,50.00000,2.159901e-10,0.78718,5
673.94098,1275.97000,     -0.52956,      0.93230,50.00000,50.00000,2.147236e-10,0.78719,5
677.34399,1276.14000,     -0.66693,      0.98704,50.00000,50.00000,2.154312e-10,0.78718,5
680.76099,1276.31000,     -0.83259,      0.97176,50.00000,50.00000,2.153073e-10,0.78719,5
684.16901,1276.48000,     -0.98376,      0.99787,50.00000,50.00000,2.164268e-10,0.78719,5
687.58801,1276.65000,     -1.13559,      1.02418,50.00000,50.00000,2.158375e-10,0.78718,5
691.00299,1276.82000,     -1.28146,      1.05048,50.00000,50.00000,2.161427e-10,0.78719,5
694.41498,1276.99000,     -1.42612,      1.07679,50.00000,50.00000,2.154579e-10,0.78718,5
697.84802,1277.16000,     -1.57381,      1.12921,50.00000,50.00000,2.161941e-10,0.78719,5
701.26599,1277.33000,     -1.71814,      1.15551,50.00000,50.00000,2.157994e-10,0.78719,5
704.68103,1277.50000,     -1.86851,      1.18182,50.00000,50.00000,2.157630e-10,0.78719,5
708.10797,1277.67000,     -2.02348,      1.18839,50.00000,50.00000,2.150269e-10,0.78719,5
711.52899,1277.84000,     -2.18121,      1.21451,50.00000,50.00000,2.149907e-10,0.78720,5
714.94897,1278.01000,     -2.33405,      1.26712,50.00000,50.00000,2.150536e-10,0.78718,5
718.36298,1278.18000,     -2.48808,      1.26712,50.00000,50.00000,2.149658e-10,0.78718,5
721.78198,1278.35000,     -2.65108,      1.31954,50.00000,50.00000,2.159652e-10,0.78719,5
725.19897,1278.52000,     -2.81318,      1.34584,50.00000,50.00000,2.150249e-10,0.78719,5
728.61102,1278.69000,     -2.97622,      1.39845,50.00000,50.00000,2.149715e-10,0.78718,5
732.02502,1278.86000,     -3.15082,      1.39845,50.00000,50.00000,2.152881e-10,0.78718,5
735.43701,1279.03000,     -3.31800,      1.45087,50.00000,50.00000,2.154579e-10,0.78718,5
738.85999,1279.20000,     -3.46010,      1.45087,50.00000,50.00000,2.147274e-10,0.78719,5
742.28497,1279.37000,     -3.62667,      1.47718,50.00000,50.00000,2.155705e-10,0.78719,5
745.70099,1279.54000,     -3.78312,      1.52979,50.00000,50.00000,2.153911e-10,0.78718,5
749.12097,1279.71000,     -3.94682,      1.52979,50.00000,50.00000,2.156524e-10,0.78719,5
752.54199,1279.88000,     -4.10703,      1.55590,50.00000,50.00000,2.156983e-10,0.78719,5
755.95502,1280.05000,     -4.26910,      1.60851,50.00000,50.00000,2.160683e-10,0.78719,5
759.37299,1280.22000,     -4.42796,      1.63482,50.00000,50.00000,2.151375e-10,0.78719,5
762.77698,1280.39000,     -4.58866,      1.66093,50.00000,50.00000,2.149772e-10,0.78720,5
766.20398,1280.56000,     -4.74909,      1.68723,50.00000,50.00000,2.151756e-10,0.78719,5
769.60999,1280.73000,     -4.91263,      1.71354,50.00000,50.00000,2.155724e-10,0.78719,5
773.02301,1280.90000,     -5.07716,      1.73985,50.00000,50.00000,2.151700e-10,0.78719,5
776.44800,1281.07000,     -5.23654,      1.76596,50.00000,50.00000,2.159291e-10,0.78718,5
779.86499,1281.24000,     -5.40366,      1.81199,50.00000,50.00000,2.161636e-10,0.78719,5
783.27802,1281.41000,     -5.55640,      1.84487,50.00000,50.00000,2.157363e-10,0.78719,5
786.68903,1281.58000,     -5.70544,      1.87099,50.00000,50.00000,2.161121e-10,0.78719,5
790.10498,1281.75000,     -5.86986,      1.89729,50.00000,50.00000,            ,0.44886,5
793.51300,1281.92000,     -6.03589,      1.92360,50.00000,50.00000,            ,0.44749,5
794.32898,1281.96000,     -6.05813,      1.92360,50.00000,50.00000,            ,0.44716,5