File: data/TGA/005d-L_M/ExpDat_2025_02_20_PS-F1-dynamic-1K.csv
#EXPORTTYPE:                 ,DATA ALL
#FILE:                       ,2025_02_20_PS-F1-dynamic-1K.ngb-ss5
#FORMAT:                     ,NETZSCH5
#FTYPE:                      ,ASCII
#IDENTITY:                   ,PS-F1
#DECIMAL:                    ,POINT
#SEPARATOR:                  ,COMMA
#MTYPE:                      ,DSC
#INSTRUMENT:                 ,NETZSCH STA 449F5
#PROJECT:                    ,PS
#DATE/TIME:                  ,2/20/2025 7:12:46 PM (UTC-5)
#CORR. FILE:                 ,
#TEMPCAL:                    ,13-11-2024 10:37
#SENSITIVITY:                ,28-06-2023 13:53
#LABORATORY:                 ,Tran/Aspuru
#OPERATOR:                   ,Stanley
#REMARK:                     ,
#SAMPLE:                     ,PS-F1
#SAMPLE MASS /mg:            ,4.97
#MATERIAL:                   ,
#REFERENCE:                  ,
#REFERENCE MASS /mg:         ,0
#TYPE OF CRUCIBLE:           ,Al2O3 85 ‘l, open
#SAMPLE CRUCIBLE MASS /mg:   ,0
#REFERENCE CRUCIBLE MASS /mg:,0
#DSC RANGE /‘V:              ,5000
#TG RANGE /mg:               ,35000
#TAU-R:                      ,---
#CORR. CODE:                 ,000
#EXO:                        ,-1
#RANGE:                      ,20›C....800›C/0.0....20.0K/min
#SEGMENT:                    ,S1-4/4
#SEG. 1:                     ,20›C/5.0(K/min)/100›C
#SEG. 2:                     ,100›C/00:05/100›C
#SEG. 3:                     ,100›C/1.0(K/min)/400›C
#SEG. 4:                     ,400›C/20.0(K/min)/800›C

##Temp./›C,Time/min,DSC/(mW/mg),Mass/%,Gas Flow(purge2)/(ml/min),Gas Flow(protective)/(ml/min),TIC(scan:1)/A,Sensit./(uV/mW),Segment
 29.32700,  0.00000, 9.010112e-02,100.00000,50.00000,35.00000,            ,0.92343,1
 30.25700,  1.06667, 5.584555e-02, 92.79779,50.00000,35.00000,1.838474e-10,0.92349,1
 31.31300,  2.13333, 6.098540e-02, 93.42153,50.00000,35.00000,1.837978e-10,0.92356,1
 32.53800,  3.20000,      0.10035, 93.15513,50.00000,35.00000,1.839390e-10,0.92363,1
 34.56600,  4.26667,      0.23433, 93.43058,50.00000,35.00000,1.841335e-10,0.92371,1
 37.72200,  5.33333,      0.40619, 93.90181,50.00000,35.00000,1.838951e-10,0.92378,1
 41.86100,  6.40000,      0.57701, 94.34346,50.00000,35.00000,1.840610e-10,0.92386,1
 46.92200,  7.46667,      0.73210, 94.86459,50.00000,35.00000,1.841717e-10,0.92394,1
 52.63300,  8.53333,      0.86843, 95.30624,50.00000,35.00000,1.843796e-10,0.92406,1
 58.88300,  9.60000,      0.97837, 95.63400,50.00000,35.00000,1.845893e-10,0.92417,1
 65.37900, 10.66667,      1.05741, 95.85252,50.00000,35.00000,1.846675e-10,0.92433,1
 71.98400, 11.73333,      1.11426, 96.04386,50.00000,35.00000,1.843185e-10,0.92449,1
 78.56100, 12.80000,      1.15274, 96.12575,50.00000,35.00000,1.854248e-10,0.92470,1
 85.07500, 13.86667,      1.17631, 96.20765,50.00000,35.00000,1.847381e-10,0.92488,1
 91.43300, 14.93333,      1.19440, 96.26237,50.00000,35.00000,1.847858e-10,0.92510,1
 97.53900, 15.98333,      1.24440, 96.28974,50.00000,35.00000,1.848488e-10,0.92529,2
101.57700, 16.78333,      1.06582, 95.91187,50.00000,35.00000,1.851520e-10,0.92545,2
104.19200, 17.58333,      0.69584, 95.29718,50.00000,35.00000,1.854611e-10,0.92559,2
105.90500, 18.38333,      0.45378, 94.83280,50.00000,35.00000,1.849784e-10,0.92573,2
107.09200, 19.18333,      0.29946, 94.47304,50.00000,35.00000,1.853294e-10,0.92585,2
107.73800, 19.98333,      0.14617, 94.07485,50.00000,35.00000,1.851578e-10,0.92596,2
107.89700, 20.78333, 5.846984e-03, 93.66056,50.00000,35.00000,1.854133e-10,0.92605,2
107.64000, 21.80000,-9.321006e-02, 93.29859,50.00000,35.00000,1.865997e-10,0.92613,3
107.38700, 22.86667,-9.353671e-02, 93.09376,50.00000,35.00000,1.854477e-10,0.92618,3
107.14700, 23.93333,-8.952127e-02, 92.87505,50.00000,35.00000,1.856250e-10,0.92620,3
106.97500, 25.00000,-6.847342e-02, 92.76579,50.00000,35.00000,1.862259e-10,0.92617,3
106.99800, 26.06667,-2.705555e-02, 92.67706,50.00000,35.00000,1.862105e-10,0.92610,3
107.21400, 27.13333, 1.620102e-02, 92.60885,50.00000,35.00000,1.853294e-10,0.92599,3
107.63800, 28.20000, 5.696167e-02, 92.57465,50.00000,35.00000,1.862755e-10,0.92581,3
108.20700, 29.26667, 9.589997e-02, 92.52012,50.00000,35.00000,1.855984e-10,0.92562,3
108.95900, 30.33333,      0.12884, 92.52676,50.00000,35.00000,1.866646e-10,0.92536,3
109.80500, 31.40000,      0.15629, 92.49276,50.00000,35.00000,1.865559e-10,0.92509,3
110.76700, 32.46667,      0.17825, 92.43803,50.00000,35.00000,1.870899e-10,0.92473,3
111.79300, 33.53333,      0.19487, 92.42435,50.00000,35.00000,1.861686e-10,0.92439,3
112.86400, 34.60000,      0.20682, 92.39034,50.00000,34.00000,1.864624e-10,0.92394,3
113.97300, 35.66667,      0.21695, 92.38350,50.00000,34.00000,1.865063e-10,0.92353,3
115.08900, 36.73333,      0.22072, 92.30141,50.00000,34.00000,1.867752e-10,0.92301,3
116.23000, 37.80000,      0.22332, 92.31509,50.00000,34.00000,1.863518e-10,0.92254,3
117.34800, 38.86667,      0.22425, 92.26056,50.00000,34.00000,1.869602e-10,0.92195,3
118.46400, 39.93333,      0.22485, 92.27425,50.00000,34.00000,1.869964e-10,0.92148,3
119.57700, 41.00000,      0.22545, 92.20584,50.00000,34.00000,1.868553e-10,0.92103,3
120.68100, 42.06667,      0.22521, 92.20584,50.00000,34.00000,1.868286e-10,0.92069,3
121.78100, 43.13333,      0.22380, 92.17867,50.00000,34.00000,1.866284e-10,0.92034,3
122.87700, 44.20000,      0.22423, 92.15815,50.00000,34.00000,1.874256e-10,0.92009,3
123.95300, 45.26667,      0.22366, 92.15131,50.00000,34.00000,1.867103e-10,0.91985,3
125.03700, 46.33333,      0.22275, 92.15131,50.00000,34.00000,1.870385e-10,0.91966,3
126.12000, 47.40000,      0.22369, 92.15131,50.00000,34.00000,1.870479e-10,0.91947,3
127.20200, 48.46667,      0.22329, 92.15131,50.00000,34.00000,1.867981e-10,0.91931,3
128.26801, 49.53333,      0.22306, 92.15131,50.00000,34.00000,1.867028e-10,0.91919,3
129.32800, 50.60000,      0.22316, 92.13763,50.00000,34.00000,1.873970e-10,0.91907,3
130.40601, 51.66667,      0.22310, 92.16499,50.00000,34.00000,1.874466e-10,0.91900,3
131.46201, 52.73333,      0.22203, 92.17183,50.00000,34.00000,1.865692e-10,0.91894,3
132.54300, 53.80000,      0.22231, 92.17183,50.00000,34.00000,1.871223e-10,0.91891,3
133.60800, 54.86667,      0.22293, 92.19899,50.00000,34.00000,1.860409e-10,0.91890,3
134.67400, 55.93333,      0.22304, 92.20584,50.00000,34.00000,1.874905e-10,0.91892,3
135.74100, 57.00000,      0.22383, 92.21952,50.00000,34.00000,1.873588e-10,0.91895,3
136.80600, 58.06667,      0.22377, 92.22636,50.00000,34.00000,1.870708e-10,0.91899,3
137.87700, 59.13333,      0.22423, 92.26056,50.00000,34.00000,1.868954e-10,0.91902,3
138.95300, 60.20000,      0.22469, 92.25372,50.00000,34.00000,1.875172e-10,0.91904,3
140.01100, 61.26667,      0.22532, 92.27425,50.00000,34.00000,1.870555e-10,0.91908,3
141.10300, 62.33333,      0.22476, 92.30141,50.00000,34.00000,1.871510e-10,0.91910,3
142.16299, 63.40000,      0.22421, 92.32193,50.00000,34.00000,1.873417e-10,0.91913,3
143.22600, 64.46667,      0.22416, 92.32877,50.00000,34.00000,1.868629e-10,0.91915,3
144.30400, 65.53333,      0.22446, 92.34930,50.00000,34.00000,1.870289e-10,0.91917,3
145.37300, 66.60000,      0.22340, 92.36982,50.00000,34.00000,1.871033e-10,0.91917,3
146.42400, 67.66667,      0.22302, 92.39718,50.00000,34.00000,1.871872e-10,0.91917,3
147.49500, 68.73333,      0.22501, 92.40402,50.00000,34.00000,1.866588e-10,0.91916,3
148.57201, 69.80000,      0.22668, 92.41751,50.00000,34.00000,1.869182e-10,0.91914,3
149.65300, 70.86667,      0.22409, 92.47223,50.00000,34.00000,1.866798e-10,0.91911,3
150.71001, 71.93333,      0.22150, 92.50644,50.00000,34.00000,1.862965e-10,0.91906,3
151.76500, 73.00000,      0.21959, 92.50644,50.00000,34.00000,1.858292e-10,0.91902,3
152.83701, 74.06667,      0.21921, 92.54728,50.00000,34.00000,1.861553e-10,0.91895,3
153.89500, 75.13333,      0.21747, 92.58833,50.00000,34.00000,1.864662e-10,0.91889,3
154.97701, 76.20000,      0.21659, 92.62254,50.00000,34.00000,1.862163e-10,0.91881,3
156.04401, 77.26667,      0.21467, 92.64286,50.00000,34.00000,1.863423e-10,0.91873,3
157.10800, 78.33333,      0.21276, 92.67022,50.00000,34.00000,1.857128e-10,0.91864,3
158.19000, 79.40000,      0.21255, 92.69759,50.00000,34.00000,1.859360e-10,0.91855,3
159.25000, 80.46667,      0.20841, 92.71811,50.00000,34.00000,1.863918e-10,0.91843,3
160.31799, 81.53333,      0.20684, 92.77948,50.00000,34.00000,1.864872e-10,0.91834,3
161.39000, 82.60000,      0.20389, 92.77948,50.00000,34.00000,1.858902e-10,0.91821,3
162.44299, 83.66667,      0.20437, 92.80684,50.00000,34.00000,1.862984e-10,0.91810,3
163.50900, 84.73333,      0.20125, 92.82736,50.00000,34.00000,1.859970e-10,0.91797,3
164.57500, 85.80000,      0.20001, 92.85473,50.00000,34.00000,1.862201e-10,0.91785,3
165.64799, 86.86667,      0.19809, 92.90926,50.00000,34.00000,1.865921e-10,0.91771,3
166.71400, 87.93333,      0.19375, 92.92294,50.00000,34.00000,1.860046e-10,0.91758,3
167.77600, 89.00000,      0.19148, 92.96398,50.00000,33.00000,1.865788e-10,0.91743,3
168.84500, 90.06667,      0.19041, 92.99115,50.00000,33.00000,1.863461e-10,0.91730,3
169.90199, 91.13333,      0.18675, 93.01167,50.00000,33.00000,1.863861e-10,0.91715,3
170.96100, 92.20000,      0.18447, 93.05272,50.00000,33.00000,1.864605e-10,0.91701,3
172.04800, 93.26667,      0.18409, 93.08692,50.00000,33.00000,1.856212e-10,0.91686,3
173.10500, 94.33333,      0.17990, 93.10040,50.00000,33.00000,1.857243e-10,0.91672,3
174.16901, 95.40000,      0.17623, 93.14829,50.00000,33.00000,1.863556e-10,0.91656,3
175.22900, 96.46667,      0.17429, 93.15513,50.00000,33.00000,1.863747e-10,0.91641,3
176.30000, 97.53333,      0.17182, 93.18249,50.00000,33.00000,1.860294e-10,0.91625,3
177.42599, 98.60000,      0.16832, 93.23018,50.00000,33.00000,1.864281e-10,0.91610,3
178.43900, 99.66667,      0.16480, 93.23702,50.00000,33.00000,1.858253e-10,0.91593,3
179.49500,100.73333,      0.16285, 93.27123,50.00000,33.00000,1.865844e-10,0.91579,3
180.57201,101.80000,      0.16002, 93.29175,50.00000,33.00000,1.862106e-10,0.91563,3
181.63000,102.86667,      0.15667, 93.33944,50.00000,33.00000,1.864147e-10,0.91548,3
182.69701,103.93333,      0.15297, 93.38048,50.00000,33.00000,1.862602e-10,0.91530,3
183.77600,105.00000,      0.15187, 93.41469,50.00000,33.00000,1.863670e-10,0.91516,3
184.83000,106.06667,      0.14799, 93.41469,50.00000,33.00000,1.863536e-10,0.91499,3
185.91901,107.13333,      0.14532, 93.45553,50.00000,33.00000,1.861134e-10,0.91483,3
186.98300,108.20000,      0.14212, 93.50342,50.00000,33.00000,1.865177e-10,0.91467,3
188.03799,109.26667,      0.13909, 93.47606,50.00000,33.00000,1.868458e-10,0.91451,3
189.10800,110.33333,      0.13484, 93.55795,50.00000,33.00000,1.865463e-10,0.91434,3
190.17799,111.40000,      0.13128, 93.58531,50.00000,33.00000,1.862315e-10,0.91419,3
191.24200,112.46667,      0.12859, 93.59215,50.00000,33.00000,1.866626e-10,0.91401,3
192.31100,113.53333,      0.12677, 93.64004,50.00000,33.00000,1.864109e-10,0.91386,3
193.37500,114.60000,      0.12057, 93.66740,50.00000,33.00000,1.868344e-10,0.91368,3
194.43201,115.66667,      0.11628, 93.66740,50.00000,33.00000,1.870022e-10,0.91353,3
195.50999,116.73333,      0.11445, 93.72193,50.00000,33.00000,1.871033e-10,0.91335,3
196.57700,117.80000,      0.11015, 93.74245,50.00000,33.00000,1.871853e-10,0.91320,3
197.61900,118.86667,      0.10585, 93.77666,50.00000,33.00000,1.859970e-10,0.91302,3
198.71300,119.93333,      0.10207, 93.80382,50.00000,33.00000,1.868782e-10,0.91285,3
199.77200,121.00000, 9.828449e-02, 93.81751,50.00000,33.00000,1.863327e-10,0.91268,3
200.84801,122.06667, 9.537385e-02, 93.85855,50.00000,33.00000,1.867523e-10,0.91251,3
201.90800,123.13333, 9.086930e-02, 93.88592,50.00000,33.00000,1.864795e-10,0.91233,3
202.97600,124.20000, 8.741745e-02, 93.89940,50.00000,33.00000,1.861992e-10,0.91218,3
204.03500,125.26667, 8.077764e-02, 93.95412,50.00000,33.00000,1.865940e-10,0.91199,3
205.08200,126.33333, 7.854848e-02, 93.92676,50.00000,33.00000,1.874618e-10,0.91183,3
206.15401,127.40000, 7.684856e-02, 94.00885,50.00000,33.00000,1.861324e-10,0.91165,3
207.22701,128.46667, 7.124689e-02, 94.03602,50.00000,33.00000,1.867752e-10,0.91149,3
208.29700,129.53333, 6.723169e-02, 94.04970,50.00000,33.00000,1.877212e-10,0.91129,3
209.35600,130.60000, 6.285375e-02, 94.05654,50.00000,33.00000,1.878318e-10,0.91113,3
210.41600,131.66667, 5.829046e-02, 94.11127,50.00000,33.00000,1.877117e-10,0.91094,3
211.49899,132.73333, 5.460954e-02, 94.11811,50.00000,33.00000,1.877365e-10,0.91077,3
212.56300,133.80000, 4.789432e-02, 94.15211,50.00000,33.00000,1.878567e-10,0.91058,3
213.62500,134.86667, 4.508741e-02, 94.15211,50.00000,33.00000,1.879272e-10,0.91041,3
214.69000,135.93333, 4.191881e-02, 94.17948,50.00000,33.00000,1.883602e-10,0.91022,3
215.75400,137.00000, 3.463785e-02, 94.20684,50.00000,33.00000,1.875228e-10,0.91005,3
216.81100,138.06667, 2.859412e-02, 94.23421,50.00000,33.00000,1.884498e-10,0.90986,3
217.88000,139.13333, 2.504373e-02, 94.25453,50.00000,33.00000,1.885700e-10,0.90968,3
218.95500,140.20000, 2.077054e-02, 94.26137,50.00000,33.00000,1.884708e-10,0.90949,3
220.03400,141.26667, 1.666845e-02, 94.28873,50.00000,33.00000,1.889573e-10,0.90931,3
221.09300,142.33333, 1.166118e-02, 94.32978,50.00000,33.00000,1.890049e-10,0.90911,3
222.15300,143.40000, 2.873217e-03, 94.35030,50.00000,33.00000,1.884822e-10,0.90894,3
223.22000,144.46667, 2.516521e-03, 94.36378,50.00000,33.00000,1.893101e-10,0.90873,3
224.28600,145.53333,-3.958413e-03, 94.39115,50.00000,33.00000,1.887588e-10,0.90855,3
225.35001,146.60000,-8.825139e-03, 94.40483,50.00000,33.00000,1.896267e-10,0.90835,3
226.40900,147.66667,-1.478313e-02, 94.41851,50.00000,34.00000,1.903038e-10,0.90817,3
227.47600,148.73333,-1.948986e-02, 94.47082,50.00000,34.00000,1.893825e-10,0.90797,3
228.54201,149.80000,-2.239963e-02, 94.48451,50.00000,34.00000,1.897755e-10,0.90779,3
229.62601,150.86667,-2.838980e-02, 94.50503,50.00000,34.00000,1.898251e-10,0.90757,3
230.68201,151.93333,-3.602050e-02, 94.53924,50.00000,34.00000,1.903725e-10,0.90740,3
231.75900,153.00000,-3.823172e-02, 94.55272,50.00000,34.00000,1.898479e-10,0.90719,3
232.83299,154.06667,-4.334957e-02, 94.56640,50.00000,34.00000,1.897774e-10,0.90700,3
233.89600,155.13333,-5.083793e-02, 94.58913,50.00000,34.00000,1.894608e-10,0.90678,3
234.98199,156.20000,-5.652556e-02, 94.61650,50.00000,34.00000,1.904984e-10,0.90660,3
236.03999,157.26667,-6.240558e-02, 94.65070,50.00000,34.00000,1.897545e-10,0.90639,3
237.12000,158.33333,-6.866363e-02, 94.68491,50.00000,34.00000,1.897068e-10,0.90620,3
238.18900,159.40000,-7.438733e-02, 94.68491,50.00000,34.00000,1.894569e-10,0.90598,3
239.25600,160.46667,-8.103568e-02, 94.70523,50.00000,34.00000,1.894359e-10,0.90579,3
240.31799,161.53333,-8.769784e-02, 94.73260,50.00000,34.00000,1.896515e-10,0.90557,3
241.37300,162.60000,-9.437361e-02, 94.73260,50.00000,34.00000,1.891423e-10,0.90538,3
242.43401,163.66667,     -0.10033, 94.75996,50.00000,34.00000,1.896457e-10,0.90516,3
243.50500,164.73333,     -0.10594, 94.80785,50.00000,34.00000,1.891594e-10,0.90497,3
244.57001,165.80000,     -0.11119, 94.81449,50.00000,34.00000,1.891366e-10,0.90475,3
245.63100,166.86667,     -0.12049, 94.83501,50.00000,34.00000,1.892357e-10,0.90455,3
246.69901,167.93333,     -0.12595, 94.85553,50.00000,33.00000,1.895562e-10,0.90433,3
247.77200,169.00000,     -0.13198, 94.87143,50.00000,33.00000,1.894150e-10,0.90413,3
248.82700,170.06667,     -0.13931, 94.89879,50.00000,33.00000,1.886272e-10,0.90391,3
249.89700,171.13333,     -0.14536, 94.91247,50.00000,33.00000,1.894264e-10,0.90371,3
250.96400,172.20000,     -0.15143, 94.96700,50.00000,33.00000,1.898116e-10,0.90348,3
252.02901,173.26667,     -0.16010, 94.98753,50.00000,33.00000,1.894283e-10,0.90329,3
253.09399,174.33333,     -0.16657, 94.98753,50.00000,33.00000,1.893005e-10,0.90305,3
254.15800,175.40000,     -0.17324, 95.01489,50.00000,33.00000,1.894989e-10,0.90285,3
255.22200,176.46667,     -0.18289, 95.01952,50.00000,33.00000,1.891251e-10,0.90262,3
256.28400,177.53333,     -0.18737, 95.06036,50.00000,33.00000,1.888809e-10,0.90239,3
257.35400,178.60000,     -0.19576, 95.08089,50.00000,33.00000,1.896820e-10,0.90218,3
258.41901,179.66667,     -0.20212, 95.08089,50.00000,33.00000,1.886520e-10,0.90194,3
259.48499,180.73333,     -0.21017, 95.10825,50.00000,33.00000,1.893158e-10,0.90174,3
260.56900,181.80000,     -0.21750, 95.13561,50.00000,33.00000,1.898823e-10,0.90153,3
261.61099,182.86667,     -0.22764, 95.15594,50.00000,33.00000,1.897049e-10,0.90131,3
262.68701,183.93333,     -0.23183, 95.18330,50.00000,33.00000,1.897164e-10,0.90110,3
263.75299,185.00000,     -0.23864, 95.19014,50.00000,33.00000,1.890774e-10,0.90086,3
264.81601,186.06667,     -0.24885, 95.21751,50.00000,33.00000,1.886386e-10,0.90061,3
265.88300,187.13333,     -0.25401, 95.24487,50.00000,33.00000,1.895847e-10,0.90041,3
266.94000,188.20000,     -0.26013, 95.25855,50.00000,33.00000,1.887264e-10,0.90017,3
268.02399,189.26667,     -0.26965, 95.26539,50.00000,33.00000,1.887149e-10,0.89996,3
269.08401,190.33333,     -0.27636, 95.29256,50.00000,33.00000,1.893139e-10,0.89971,3
270.15701,191.40000,     -0.28328, 95.31308,50.00000,33.00000,1.889057e-10,0.89950,3
271.22000,192.46667,     -0.29210, 95.32676,50.00000,33.00000,1.899738e-10,0.89926,3
272.27600,193.53333,     -0.29868, 95.34044,50.00000,33.00000,1.902561e-10,0.89904,3
273.33899,194.60000,     -0.30640, 95.34044,50.00000,33.00000,1.896057e-10,0.89879,3
274.41699,195.66667,     -0.31586, 95.36781,50.00000,33.00000,1.896439e-10,0.89857,3
275.46701,196.73333,     -0.32248, 95.39497,50.00000,33.00000,1.900596e-10,0.89833,3
276.54599,197.80000,     -0.33084, 95.38129,50.00000,33.00000,1.898460e-10,0.89811,3
277.59299,198.86667,     -0.33978, 95.39497,50.00000,33.00000,1.899605e-10,0.89786,3
278.66400,199.93333,     -0.34399, 95.40181,50.00000,33.00000,1.902980e-10,0.89763,3
279.72601,201.00000,     -0.35355, 95.42918,50.00000,33.00000,1.900672e-10,0.89742,3
280.79199,202.06667,     -0.35722, 95.42918,50.00000,33.00000,1.902504e-10,0.89717,3
281.86401,203.13333,     -0.36815, 95.44286,50.00000,33.00000,1.903496e-10,0.89691,3
282.93399,204.20000,     -0.37586, 95.45654,50.00000,33.00000,1.903419e-10,0.89669,3
284.01199,205.26667,     -0.38283, 95.47706,50.00000,33.00000,1.908760e-10,0.89643,3
285.07999,206.33333,     -0.39269, 95.47022,50.00000,33.00000,1.906223e-10,0.89622,3
286.13599,207.40000,     -0.39892, 95.47243,50.00000,33.00000,1.911773e-10,0.89595,3
287.17801,208.46667,     -0.40209, 95.49980,50.00000,33.00000,1.913795e-10,0.89573,3
288.26501,209.53333,     -0.40855, 95.49296,50.00000,33.00000,1.913815e-10,0.89547,3
289.30801,210.60000,     -0.41790, 95.49980,50.00000,33.00000,1.914291e-10,0.89524,3
290.38901,211.66667,     -0.42209, 95.48612,50.00000,33.00000,1.911487e-10,0.89499,3
291.44699,212.73333,     -0.43014, 95.51348,50.00000,33.00000,1.910190e-10,0.89475,3
292.57001,213.80000,     -0.43456, 95.51348,50.00000,33.00000,1.914826e-10,0.89447,3
293.60999,214.86667,     -0.44322, 95.53380,50.00000,33.00000,1.908722e-10,0.89427,3
294.66101,215.93333,     -0.44783, 95.54064,50.00000,33.00000,1.911201e-10,0.89400,3
295.74799,217.00000,     -0.45287, 95.51348,50.00000,33.00000,1.913890e-10,0.89376,3
296.81201,218.06667,     -0.45032, 95.52032,50.00000,33.00000,1.919422e-10,0.89350,3
297.88000,219.13333,     -0.45731, 95.52032,50.00000,33.00000,1.913891e-10,0.89326,3
298.93201,220.20000,     -0.46314, 95.54748,50.00000,33.00000,1.911602e-10,0.89299,3
300.01001,221.26667,     -0.47172, 95.52032,50.00000,33.00000,1.915283e-10,0.89276,3
301.06100,222.33333,     -0.47778, 95.49980,50.00000,33.00000,1.913662e-10,0.89249,3
302.14801,223.40000,     -0.48622, 95.48612,50.00000,33.00000,1.911659e-10,0.89226,3
303.19901,224.46667,     -0.49172, 95.49296,50.00000,33.00000,1.916084e-10,0.89199,3
304.26501,225.53333,     -0.48784, 95.48612,50.00000,33.00000,1.905975e-10,0.89175,3
305.32800,226.60000,     -0.49807, 95.49296,50.00000,33.00000,1.909657e-10,0.89147,3
306.40100,227.66667,     -0.50422, 95.48612,50.00000,33.00000,1.915531e-10,0.89124,3
307.45499,228.73333,     -0.50368, 95.48612,50.00000,33.00000,1.903667e-10,0.89097,3
308.52600,229.80000,     -0.51142, 95.45875,50.00000,33.00000,1.917591e-10,0.89073,3
309.59900,230.86667,     -0.51780, 95.44507,50.00000,33.00000,1.918526e-10,0.89045,3
310.67801,231.93333,     -0.52361, 95.43139,50.00000,33.00000,1.908970e-10,0.89021,3
311.74500,233.00000,     -0.52884, 95.41791,50.00000,33.00000,1.914005e-10,0.88993,3
312.80600,234.06667,     -0.53428, 95.39054,50.00000,33.00000,1.912174e-10,0.88969,3
313.86700,235.13333,     -0.54171, 95.37002,50.00000,33.00000,1.919498e-10,0.88941,3
314.92899,236.20000,     -0.54499, 95.36318,50.00000,33.00000,1.915550e-10,0.88916,3
316.00101,237.26667,     -0.55127, 95.33581,50.00000,33.00000,1.914597e-10,0.88887,3
317.07501,238.33333,     -0.55916, 95.28813,50.00000,33.00000,1.913624e-10,0.88863,3
318.13000,239.40000,     -0.56467, 95.28813,50.00000,33.00000,1.909408e-10,0.88835,3
319.19199,240.46667,     -0.56900, 95.25392,50.00000,33.00000,1.911087e-10,0.88811,3
320.27200,241.53333,     -0.57476, 95.19920,50.00000,33.00000,1.916695e-10,0.88782,3
321.32901,242.60000,     -0.58351, 95.14467,50.00000,33.00000,1.912670e-10,0.88757,3
322.39899,243.66667,     -0.58769, 95.08994,50.00000,33.00000,1.909275e-10,0.88728,3
323.47601,244.73333,     -0.59470, 95.02636,50.00000,33.00000,1.919002e-10,0.88698,3
324.53400,245.80000,     -0.59930, 94.97163,50.00000,33.00000,1.920910e-10,0.88673,3
325.61401,246.86667,     -0.60574, 94.91710,50.00000,33.00000,1.910477e-10,0.88645,3
326.66000,247.93333,     -0.61176, 94.83501,50.00000,33.00000,1.915646e-10,0.88619,3
327.72400,249.00000,     -0.61419, 94.75312,50.00000,33.00000,1.918889e-10,0.88591,3
328.78500,250.06667,     -0.61905, 94.63702,50.00000,33.00000,1.921292e-10,0.88565,3
329.86099,251.13333,     -0.62676, 94.56881,50.00000,33.00000,1.917629e-10,0.88536,3
330.91199,252.20000,     -0.63164, 94.45956,50.00000,33.00000,1.915188e-10,0.88510,3
332.00201,253.26667,     -0.63676, 94.32294,50.00000,33.00000,1.923199e-10,0.88480,3
333.04800,254.33333,     -0.64247, 94.18632,50.00000,33.00000,1.915626e-10,0.88456,3
334.12299,255.40000,     -0.64883, 94.04970,50.00000,33.00000,1.925049e-10,0.88429,3
335.17899,256.46667,     -0.65357, 93.88350,50.00000,33.00000,1.924782e-10,0.88400,3
336.24301,257.53333,     -0.65894, 93.71972,50.00000,33.00000,1.927394e-10,0.88370,3
337.30701,258.60000,     -0.66330, 93.50121,50.00000,33.00000,1.918124e-10,0.88345,3
338.37201,259.66667,     -0.66562, 93.30986,50.00000,33.00000,1.925945e-10,0.88315,3
339.44400,260.73333,     -0.67001, 93.07545,50.00000,33.00000,1.927662e-10,0.88289,3
340.52399,261.80000,     -0.67278, 92.82958,50.00000,33.00000,1.929932e-10,0.88259,3
341.58301,262.86667,     -0.68128, 92.55654,50.00000,33.00000,1.929264e-10,0.88233,3
342.63901,263.93333,     -0.68159, 92.22636,50.00000,33.00000,1.931076e-10,0.88201,3
343.69901,265.00000,     -0.68333, 91.92354,50.00000,33.00000,1.926708e-10,0.88176,3
344.76599,266.06667,     -0.68983, 91.53883,50.00000,33.00000,1.930789e-10,0.88145,3
345.84201,267.13333,     -0.68439, 91.15433,50.00000,33.00000,1.936779e-10,0.88119,3
346.92700,268.20000,     -0.68844, 90.74225,50.00000,33.00000,1.933098e-10,0.88089,3
347.99100,269.26667,     -0.69642, 90.24829,50.00000,33.00000,1.930733e-10,0.88062,3
349.05499,270.33333,     -0.70380, 89.71791,50.00000,34.00000,1.935521e-10,0.88030,3
350.11401,271.40000,     -0.70373, 89.15795,50.00000,34.00000,1.929970e-10,0.88004,3
351.19901,272.46667,     -0.70409, 88.53421,50.00000,34.00000,1.933689e-10,0.87973,3
352.25500,273.53333,     -0.71504, 87.88994,50.00000,34.00000,1.932659e-10,0.87946,3
353.33099,274.60000,     -0.71562, 87.15473,50.00000,34.00000,1.943149e-10,0.87916,3
354.39999,275.66667,     -0.71098, 86.35111,50.00000,33.00000,1.929550e-10,0.87889,3
355.47198,276.73333,     -0.71343, 85.50885,50.00000,34.00000,1.933498e-10,0.87857,3
356.53500,277.80000,     -0.70939, 84.55976,50.00000,33.00000,1.935387e-10,0.87830,3
357.60699,278.86667,     -0.70808, 83.54889,50.00000,33.00000,1.934795e-10,0.87799,3
358.66000,279.93333,     -0.70590, 82.44266,50.00000,33.00000,1.933079e-10,0.87772,3
359.71399,281.00000,     -0.70162, 81.27042,50.00000,33.00000,1.932888e-10,0.87740,3
360.77499,282.06667,     -0.70070, 79.96157,50.00000,33.00000,1.930446e-10,0.87713,3
361.85001,283.13333,     -0.69726, 78.60926,50.00000,33.00000,1.933250e-10,0.87682,3
362.91400,284.20000,     -0.69654, 77.11610,50.00000,33.00000,1.931801e-10,0.87654,3
363.98099,285.26667,     -0.68780, 75.51590,50.00000,33.00000,1.934815e-10,0.87622,3
365.04700,286.33333,     -0.68918, 73.80181,50.00000,33.00000,1.935577e-10,0.87594,3
366.10599,287.40000,     -0.68781, 72.00563,50.00000,33.00000,1.934262e-10,0.87563,3
367.17899,288.46667,     -0.68517, 70.04567,50.00000,33.00000,1.934357e-10,0.87535,3
368.24600,289.53333,     -0.67827, 67.97666,50.00000,33.00000,1.933402e-10,0.87503,3
369.31100,290.60000,     -0.68731, 65.82777,50.00000,33.00000,1.938610e-10,0.87476,3
370.36899,291.66667,     -0.68635, 63.54004,50.00000,33.00000,1.934376e-10,0.87444,3
371.45401,292.73333,     -0.70717, 61.10423,50.00000,33.00000,1.937961e-10,0.87416,3
372.51099,293.80000,     -0.72248, 58.59799,50.00000,33.00000,1.936416e-10,0.87382,3
373.57001,294.86667,     -0.74061, 56.01670,50.00000,33.00000,1.941013e-10,0.87355,3
374.63199,295.93333,     -0.76565, 53.34648,50.00000,33.00000,1.939620e-10,0.87324,3
375.70901,297.00000,     -0.78584, 50.56479,50.00000,33.00000,1.935749e-10,0.87295,3
376.78299,298.06667,     -0.81210, 47.77183,50.00000,33.00000,1.939602e-10,0.87261,3
377.83499,299.13333,     -0.84788, 44.90362,50.00000,33.00000,1.937217e-10,0.87233,3
378.90201,300.20000,     -0.87968, 42.01268,50.00000,33.00000,1.944027e-10,0.87199,3
379.97000,301.26667,     -0.92193, 39.10584,50.00000,33.00000,1.945228e-10,0.87171,3
381.04199,302.33333,     -0.96517, 36.26036,50.00000,33.00000,1.944637e-10,0.87139,3
382.10300,303.40000,     -1.01219, 33.38531,50.00000,33.00000,1.930886e-10,0.87110,3
383.15900,304.46667,     -1.06281, 30.59457,50.00000,33.00000,1.938839e-10,0.87077,3
384.24100,305.53333,     -1.11665, 27.92676,50.00000,33.00000,1.935253e-10,0.87048,3
385.29300,306.60000,     -1.18233, 25.33179,50.00000,33.00000,1.936989e-10,0.87015,3
386.37799,307.66667,     -1.23823, 22.90060,50.00000,33.00000,1.944198e-10,0.86988,3
387.44299,308.73333,     -1.30429, 20.59014,50.00000,33.00000,1.944122e-10,0.86953,3
388.50800,309.80000,     -1.37206, 18.46177,50.00000,33.00000,1.943531e-10,0.86924,3
389.56601,310.86667,     -1.44460, 16.47002,50.00000,33.00000,1.946697e-10,0.86891,3
390.63599,311.93333,     -1.51474, 14.67847,50.00000,33.00000,1.950588e-10,0.86862,3
391.69699,313.00000,     -1.59186, 13.03501,50.00000,33.00000,1.940384e-10,0.86829,3
392.76300,314.06667,     -1.68215, 11.49376,50.00000,33.00000,1.946964e-10,0.86800,3
393.83200,315.13333,     -1.78678, 10.01650,50.00000,33.00000,1.950416e-10,0.86767,3
394.90399,316.20000,     -1.89369,  8.65976,50.00000,33.00000,1.949959e-10,0.86738,3
395.98099,317.26667,     -1.99431,  7.33964,50.00000,33.00000,1.945038e-10,0.86704,3
397.04300,318.33333,     -2.09451,  6.22636,50.00000,33.00000,1.950550e-10,0.86674,3
398.10101,319.40000,     -2.19034,  5.14507,50.00000,34.00000,1.956062e-10,0.86640,3
399.16501,320.46667,     -2.25789,  4.18229,50.00000,34.00000,1.952190e-10,0.86611,3
399.68500,320.97833,     -2.28583,  3.77928,50.00000,34.00000,1.946163e-10,0.86596,4
399.81100,321.05833,     -2.26162,  3.73380,50.00000,34.00000,1.951466e-10,0.86591,4
400.07700,321.13833,     -2.12964,  3.67243,50.00000,34.00000,1.951466e-10,0.86591,4
400.50500,321.21833,     -1.88022,  3.67243,50.00000,34.00000,1.955700e-10,0.86586,4
401.10800,321.29833,     -1.51547,  3.67243,50.00000,34.00000,1.955700e-10,0.86586,4
401.89700,321.37833,     -1.05175,  3.67243,50.00000,34.00000,1.949139e-10,0.86582,4
402.87799,321.45833,     -0.51600,  3.69960,50.00000,34.00000,1.949139e-10,0.86582,4
404.00000,321.53833, 6.239659e-02,  3.75654,50.00000,34.00000,1.953353e-10,0.86576,4
405.30099,321.61833,      0.65720,  3.78390,50.00000,34.00000,1.953353e-10,0.86576,4
406.71399,321.69833,      1.23817,  3.83863,50.00000,34.00000,1.947784e-10,0.86571,4
408.22400,321.77833,      1.78035,  3.87264,50.00000,34.00000,1.947784e-10,0.86571,4
409.79599,321.85833,      2.26675,  3.89316,50.00000,34.00000,1.950683e-10,0.86566,4
411.41800,321.93833,      2.67840,  3.89316,50.00000,34.00000,1.950683e-10,0.86566,4
413.06000,322.01833,      3.00937,  3.89316,50.00000,34.00000,1.953583e-10,0.86561,4
414.67499,322.09833,      3.25915,  3.89316,50.00000,34.00000,1.953583e-10,0.86561,4
416.28000,322.17833,      3.42342,  3.83179,50.00000,34.00000,1.951027e-10,0.86557,4
417.85599,322.25833,      3.51536,  3.77243,50.00000,34.00000,1.951027e-10,0.86557,4
419.39700,322.33833,      3.54177,  3.67928,50.00000,34.00000,1.953679e-10,0.86552,4
420.88699,322.41833,      3.51331,  3.57907,50.00000,34.00000,1.953679e-10,0.86552,4
422.33801,322.49833,      3.44091,  3.47425,50.00000,34.00000,1.951313e-10,0.86547,4
423.74600,322.57833,      3.34285,  3.36499,50.00000,34.00000,1.951313e-10,0.86547,4
425.13199,322.65833,      3.22712,  3.25131,50.00000,34.00000,1.948070e-10,0.86541,4
426.47501,322.73833,      3.10387,  3.13521,50.00000,34.00000,1.948070e-10,0.86541,4
427.80499,322.81833,      2.98794,  2.98491,50.00000,34.00000,1.948433e-10,0.86536,4
429.13599,322.89833,      2.88334,  2.85050,50.00000,34.00000,1.948433e-10,0.86536,4
430.45401,322.97833,      2.79816,  2.71630,50.00000,34.00000,1.952534e-10,0.86532,4
431.77301,323.05833,      2.73466,  2.57746,50.00000,34.00000,1.952534e-10,0.86532,4
433.15399,323.13833,      2.69732,  2.43179,50.00000,34.00000,1.951485e-10,0.86528,4
434.49500,323.21833,      2.68152,  2.30885,50.00000,34.00000,1.951485e-10,0.86528,4
435.88901,323.29833,      2.69468,  2.18129,50.00000,34.00000,1.952896e-10,0.86522,4
437.30399,323.37833,      2.72777,  2.05392,50.00000,34.00000,1.952896e-10,0.86522,4
438.75201,323.45833,      2.78071,  1.92414,50.00000,34.00000,1.952896e-10,0.86522,4
440.22400,323.53833,      2.84352,  1.79437,50.00000,34.00000,1.955586e-10,0.86517,4
441.73099,323.61833,      2.92100,  1.68974,50.00000,34.00000,1.955586e-10,0.86517,4
443.26999,323.69833,      3.00079,  1.56439,50.00000,34.00000,1.948433e-10,0.86512,4
444.82800,323.77833,      3.08474,  1.47344,50.00000,34.00000,1.948433e-10,0.86512,4
446.41101,323.85833,      3.16394,  1.35956,50.00000,34.00000,1.955204e-10,0.86508,4
448.00500,323.93833,      3.23901,  1.26398,50.00000,34.00000,1.955204e-10,0.86508,4
449.62100,324.01833,      3.30217,  1.14789,50.00000,34.00000,1.949272e-10,0.86502,4
451.25299,324.09833,      3.35496,  1.04326,50.00000,34.00000,1.949272e-10,0.86502,4
452.89001,324.17833,      3.39704,  0.95211,50.00000,34.00000,1.948967e-10,0.86497,4
454.51901,324.25833,      3.42779,  0.86338,50.00000,34.00000,1.948967e-10,0.86497,4
456.16800,324.33833,      3.44369,  0.76318,50.00000,34.00000,1.942615e-10,0.86492,4
457.81699,324.41833,      3.44791,  0.70181,50.00000,34.00000,1.942615e-10,0.86492,4
459.45901,324.49833,      3.44320,  0.59940,50.00000,34.00000,1.952247e-10,0.86487,4
461.10400,324.57833,      3.42860,  0.54004,50.00000,34.00000,1.952247e-10,0.86487,4
462.73801,324.65833,      3.40422,  0.48330,50.00000,34.00000,1.953868e-10,0.86483,4
464.38000,324.73833,      3.37685,  0.42857,50.00000,34.00000,1.953868e-10,0.86483,4
466.01401,324.81833,      3.34832,  0.37404,50.00000,34.00000,1.957035e-10,0.86477,4
467.64801,324.89833,      3.31019,  0.31932,50.00000,34.00000,1.957035e-10,0.86477,4
469.29300,324.97833,      3.27094,  0.29195,50.00000,34.00000,1.947708e-10,0.86473,4
470.92700,325.05833,      3.23852,  0.29195,50.00000,34.00000,1.947708e-10,0.86473,4
472.57199,325.13833,      3.20232,  0.26459,50.00000,34.00000,1.953506e-10,0.86468,4
474.20599,325.21833,      3.16467,  0.26459,50.00000,34.00000,1.953506e-10,0.86468,4
475.85901,325.29833,      3.12838,  0.23742,50.00000,34.00000,1.955948e-10,0.86462,4
477.51199,325.37833,      3.09339,  0.23742,50.00000,34.00000,1.955948e-10,0.86462,4
479.15201,325.45833,      3.05964,  0.23742,50.00000,34.00000,1.952896e-10,0.86458,4
480.80701,325.53833,      3.02530,  0.23742,50.00000,34.00000,1.952896e-10,0.86458,4
482.46100,325.61833,      2.99300,  0.23742,50.00000,34.00000,1.952114e-10,0.86454,4
484.12201,325.69833,      2.96428,  0.26459,50.00000,34.00000,1.952114e-10,0.86454,4
485.79401,325.77833,      2.93521,  0.29195,50.00000,34.00000,1.953983e-10,0.86449,4
487.44601,325.85833,      2.90193,  0.29879,50.00000,34.00000,1.953983e-10,0.86449,4
489.11499,325.93833,      2.87130,  0.31932,50.00000,34.00000,1.956062e-10,0.86443,4
490.79001,326.01833,      2.83752,  0.36036,50.00000,34.00000,1.956062e-10,0.86443,4
492.45599,326.09833,      2.80555,  0.37404,50.00000,34.00000,1.949215e-10,0.86438,4
494.11899,326.17833,      2.76712,  0.37404,50.00000,34.00000,1.949215e-10,0.86438,4
495.78299,326.25833,      2.73330,  0.42857,50.00000,34.00000,1.950359e-10,0.86434,4
497.45099,326.33833,      2.69351,  0.45594,50.00000,34.00000,1.950359e-10,0.86434,4
499.12399,326.41833,      2.65330,  0.45594,50.00000,34.00000,1.950359e-10,0.86434,4
500.80200,326.49833,      2.60758,  0.48330,50.00000,34.00000,1.948567e-10,0.86428,4
502.46701,326.57833,      2.56085,  0.48330,50.00000,34.00000,1.948567e-10,0.86428,4
504.13901,326.65833,      2.51569,  0.51046,50.00000,34.00000,1.950607e-10,0.86424,4
505.81100,326.73833,      2.47057,  0.53783,50.00000,34.00000,1.950607e-10,0.86424,4
507.47501,326.81833,      2.42189,  0.53783,50.00000,34.00000,1.952400e-10,0.86418,4
509.14200,326.89833,      2.37556,  0.56519,50.00000,34.00000,1.952400e-10,0.86418,4
510.79999,326.97833,      2.32769,  0.59256,50.00000,34.00000,1.950970e-10,0.86414,4
512.46503,327.05833,      2.27834,  0.61972,50.00000,34.00000,1.950970e-10,0.86414,4
514.13300,327.13833,      2.23238,  0.61972,50.00000,34.00000,1.958447e-10,0.86409,4
515.79602,327.21833,      2.18748,  0.64708,50.00000,34.00000,1.958447e-10,0.86409,4
517.45599,327.29833,      2.13770,  0.67445,50.00000,34.00000,1.952267e-10,0.86403,4
519.11298,327.37833,      2.08692,  0.67445,50.00000,34.00000,1.952267e-10,0.86403,4
520.76703,327.45833,      2.03953,  0.67445,50.00000,34.00000,1.957302e-10,0.86399,4
522.43298,327.53833,      1.98779,  0.70865,50.00000,34.00000,1.957302e-10,0.86399,4
524.08600,327.61833,      1.94231,  0.74950,50.00000,34.00000,1.958770e-10,0.86394,4
525.74200,327.69833,      1.89350,  0.75634,50.00000,34.00000,1.958770e-10,0.86394,4
527.41101,327.77833,      1.84633,  0.77002,50.00000,34.00000,1.953716e-10,0.86389,4
529.06403,327.85833,      1.79655,  0.77002,50.00000,34.00000,1.953716e-10,0.86389,4
530.71997,327.93833,      1.74997,  0.79738,50.00000,34.00000,1.948319e-10,0.86385,4
532.38202,328.01833,      1.70215,  0.81107,50.00000,34.00000,1.948319e-10,0.86385,4
534.04303,328.09833,      1.65411,  0.83159,50.00000,34.00000,1.952285e-10,0.86379,4
535.69702,328.17833,      1.60241,  0.86559,50.00000,34.00000,1.952285e-10,0.86379,4
537.34802,328.25833,      1.55153,  0.89296,50.00000,34.00000,1.939544e-10,0.86373,4
538.99799,328.33833,      1.49911,  0.89296,50.00000,34.00000,1.939544e-10,0.86373,4
540.66400,328.41833,      1.44969,  0.92032,50.00000,34.00000,1.947879e-10,0.86369,4
542.31702,328.49833,      1.39789,  0.92032,50.00000,34.00000,1.947879e-10,0.86369,4
543.95898,328.57833,      1.34719,  0.94769,50.00000,34.00000,1.950264e-10,0.86363,4
545.61200,328.65833,      1.29335,  0.94769,50.00000,34.00000,1.950264e-10,0.86363,4
547.26703,328.73833,      1.24304,  0.97485,50.00000,34.00000,1.953258e-10,0.86359,4
548.90900,328.81833,      1.18955,  1.00221,50.00000,34.00000,1.953258e-10,0.86359,4
550.54901,328.89833,      1.13825,  1.02958,50.00000,34.00000,1.949958e-10,0.86353,4
552.19800,328.97833,      1.08432,  1.02958,50.00000,34.00000,1.949958e-10,0.86353,4
553.84302,329.05833,      1.03017,  1.05694,50.00000,34.00000,1.951026e-10,0.86349,4
555.49103,329.13833,      0.97769,  1.05694,50.00000,34.00000,1.951026e-10,0.86349,4
557.13202,329.21833,      0.91521,  1.08410,50.00000,34.00000,1.948719e-10,0.86344,4
558.77899,329.29833,      0.86229,  1.11147,50.00000,34.00000,1.948719e-10,0.86344,4
560.42297,329.37833,      0.81133,  1.12515,50.00000,34.00000,1.952019e-10,0.86339,4
562.05603,329.45833,      0.75988,  1.14105,50.00000,34.00000,1.952019e-10,0.86339,4
563.70099,329.53833,      0.71590,  1.16841,50.00000,34.00000,1.953735e-10,0.86334,4
565.33197,329.61833,      0.67475,  1.18893,50.00000,34.00000,1.953735e-10,0.86334,4
566.97998,329.69833,      0.62493,  1.19577,50.00000,34.00000,1.949634e-10,0.86328,4
568.62598,329.77833,      0.57299,  1.22294,50.00000,34.00000,1.949634e-10,0.86328,4
570.25897,329.85833,      0.52332,  1.22294,50.00000,34.00000,1.945820e-10,0.86324,4
571.89398,329.93833,      0.47207,  1.25030,50.00000,34.00000,1.945820e-10,0.86324,4
573.54498,330.01833,      0.42451,  1.25030,50.00000,34.00000,1.953125e-10,0.86319,4
575.17297,330.09833,      0.37176,  1.27767,50.00000,34.00000,1.953125e-10,0.86319,4
576.81799,330.17833,      0.32021,  1.29135,50.00000,34.00000,1.946220e-10,0.86314,4
578.45599,330.25833,      0.26845,  1.30503,50.00000,34.00000,1.946220e-10,0.86314,4
580.09003,330.33833,      0.21594,  1.30503,50.00000,34.00000,1.959342e-10,0.86309,4
581.72998,330.41833,      0.16631,  1.33219,50.00000,34.00000,1.959342e-10,0.86309,4
583.36700,330.49833,      0.11650,  1.35956,50.00000,34.00000,1.959342e-10,0.86309,4
584.99402,330.57833, 6.368524e-02,  1.35956,50.00000,34.00000,1.953144e-10,0.86304,4
586.62903,330.65833, 9.556339e-03,  1.38692,50.00000,34.00000,1.953144e-10,0.86304,4
588.27100,330.73833,-4.561717e-02,  1.40060,50.00000,34.00000,1.948376e-10,0.86299,4
589.89801,330.81833,     -0.10071,  1.43481,50.00000,34.00000,1.948376e-10,0.86299,4
591.52502,330.89833,     -0.15318,  1.44165,50.00000,34.00000,1.951027e-10,0.86294,4
593.16602,330.97833,     -0.20272,  1.46197,50.00000,34.00000,1.951027e-10,0.86294,4
594.79303,331.05833,     -0.25953,  1.46197,50.00000,34.00000,1.949215e-10,0.86289,4
596.40900,331.13833,     -0.31484,  1.46881,50.00000,34.00000,1.949215e-10,0.86289,4
598.04401,331.21833,     -0.36750,  1.49618,50.00000,34.00000,1.946564e-10,0.86284,4
599.67798,331.29833,     -0.42206,  1.52354,50.00000,34.00000,1.946564e-10,0.86284,4
601.30798,331.37833,     -0.47538,  1.52354,50.00000,34.00000,1.945190e-10,0.86279,4
602.94000,331.45833,     -0.53289,  1.55091,50.00000,34.00000,1.945190e-10,0.86279,4
604.57098,331.53833,     -0.58315,  1.55755,50.00000,34.00000,1.950474e-10,0.86274,4
606.19202,331.61833,     -0.64306,  1.57807,50.00000,34.00000,1.950474e-10,0.86274,4
607.82703,331.69833,     -0.69829,  1.60543,50.00000,34.00000,1.949463e-10,0.86268,4
609.45599,331.77833,     -0.75774,  1.60543,50.00000,34.00000,1.949463e-10,0.86268,4
611.07703,331.85833,     -0.81767,  1.63280,50.00000,34.00000,1.949215e-10,0.86264,4
612.70502,331.93833,     -0.87955,  1.63280,50.00000,34.00000,1.949215e-10,0.86264,4
614.32898,332.01833,     -0.93961,  1.66016,50.00000,34.00000,1.946735e-10,0.86259,4
615.95300,332.09833,     -1.00044,  1.66016,50.00000,34.00000,1.946735e-10,0.86259,4
617.58099,332.17833,     -1.05800,  1.68732,50.00000,34.00000,1.950799e-10,0.86254,4
619.19702,332.25833,     -1.12359,  1.68732,50.00000,34.00000,1.950799e-10,0.86254,4
620.82703,332.33833,     -1.18767,  1.71469,50.00000,34.00000,1.952209e-10,0.86249,4
622.44098,332.41833,     -1.24960,  1.74205,50.00000,34.00000,1.952209e-10,0.86249,4
624.06500,332.49833,     -1.31496,  1.76942,50.00000,34.00000,1.944237e-10,0.86244,4
625.69299,332.57833,     -1.37908,  1.76942,50.00000,34.00000,1.944237e-10,0.86244,4
627.32202,332.65833,     -1.44164,  1.76942,50.00000,34.00000,1.954308e-10,0.86239,4
628.93799,332.73833,     -1.50821,  1.78974,50.00000,34.00000,1.954308e-10,0.86239,4
630.55499,332.81833,     -1.56526,  1.78974,50.00000,34.00000,1.954555e-10,0.86234,4
632.17798,332.89833,     -1.63520,  1.79658,50.00000,34.00000,1.954555e-10,0.86234,4
633.81403,332.97833,     -1.69740,  1.82394,50.00000,34.00000,1.946563e-10,0.86229,4
635.41998,333.05833,     -1.76685,  1.85131,50.00000,34.00000,1.946563e-10,0.86229,4
637.04797,333.13833,     -1.83389,  1.87867,50.00000,34.00000,1.949538e-10,0.86224,4
638.65997,333.21833,     -1.90141,  1.87867,50.00000,34.00000,1.949538e-10,0.86224,4
640.28003,333.29833,     -1.97063,  1.87867,50.00000,34.00000,1.946811e-10,0.86219,4
641.89502,333.37833,     -2.04275,  1.90584,50.00000,34.00000,1.946811e-10,0.86219,4
643.51703,333.45833,     -2.11301,  1.93320,50.00000,34.00000,1.949138e-10,0.86215,4
645.12598,333.53833,     -2.18315,  1.93320,50.00000,34.00000,1.949138e-10,0.86215,4
646.74500,333.61833,     -2.25024,  1.96056,50.00000,34.00000,1.941738e-10,0.86210,4
648.36401,333.69833,     -2.32113,  1.96056,50.00000,34.00000,1.941738e-10,0.86210,4
649.97900,333.77833,     -2.38741,  1.98793,50.00000,34.00000,1.950722e-10,0.86204,4
651.60498,333.85833,     -2.45512,  1.98793,50.00000,34.00000,1.950722e-10,0.86204,4
653.20398,333.93833,     -2.52206,  2.01509,50.00000,34.00000,1.949462e-10,0.86199,4
654.83099,334.01833,     -2.58867,  2.04245,50.00000,34.00000,1.949462e-10,0.86199,4
656.44000,334.09833,     -2.65694,  2.05614,50.00000,34.00000,1.949462e-10,0.86199,4
658.05701,334.17833,     -2.71997,  2.05614,50.00000,34.00000,1.954193e-10,0.86194,4
659.66101,334.25833,     -2.78619,  2.06982,50.00000,34.00000,1.954193e-10,0.86194,4
661.28198,334.33833,     -2.85720,  2.09718,50.00000,34.00000,1.951237e-10,0.86189,4
662.89203,334.41833,     -2.92199,  2.09718,50.00000,34.00000,1.951237e-10,0.86189,4
664.51202,334.49833,     -2.98914,  2.12455,50.00000,34.00000,1.953716e-10,0.86184,4
666.12903,334.57833,     -3.05860,  2.15171,50.00000,34.00000,1.953716e-10,0.86184,4
667.74103,334.65833,     -3.12703,  2.15171,50.00000,34.00000,1.953468e-10,0.86179,4
669.36298,334.73833,     -3.19568,  2.15171,50.00000,34.00000,1.953468e-10,0.86179,4
670.96503,334.81833,     -3.26077,  2.15171,50.00000,34.00000,1.952743e-10,0.86175,4
672.59003,334.89833,     -3.33012,  2.17907,50.00000,34.00000,1.952743e-10,0.86175,4
674.20697,334.97833,     -3.39318,  2.20644,50.00000,34.00000,1.954116e-10,0.86169,4
675.82098,335.05833,     -3.45486,  2.23380,50.00000,34.00000,1.954116e-10,0.86169,4
677.43799,335.13833,     -3.52227,  2.23380,50.00000,34.00000,1.946774e-10,0.86164,4
679.05402,335.21833,     -3.59172,  2.23380,50.00000,34.00000,1.946774e-10,0.86164,4
680.66901,335.29833,     -3.66075,  2.26097,50.00000,34.00000,1.948871e-10,0.86158,4
682.28400,335.37833,     -3.72779,  2.28833,50.00000,34.00000,1.948871e-10,0.86158,4
683.89697,335.45833,     -3.79532,  2.28833,50.00000,34.00000,1.955834e-10,0.86154,4
685.51599,335.53833,     -3.86461,  2.31569,50.00000,34.00000,1.955834e-10,0.86154,4
687.13000,335.61833,     -3.93438,  2.34306,50.00000,34.00000,1.954136e-10,0.86149,4
688.74200,335.69833,     -4.00060,  2.34306,50.00000,34.00000,1.954136e-10,0.86149,4
690.36102,335.77833,     -4.06889,  2.34306,50.00000,34.00000,1.946735e-10,0.86144,4
691.96802,335.85833,     -4.13794,  2.37022,50.00000,34.00000,1.946735e-10,0.86144,4
693.58099,335.93833,     -4.21348,  2.37022,50.00000,34.00000,1.954593e-10,0.86139,4
695.18597,336.01833,     -4.28008,  2.39759,50.00000,34.00000,1.954593e-10,0.86139,4
696.79999,336.09833,     -4.34406,  2.39759,50.00000,34.00000,1.959209e-10,0.86135,4
698.41803,336.17833,     -4.41390,  2.41811,50.00000,34.00000,1.959209e-10,0.86135,4
700.03101,336.25833,     -4.47918,  2.42495,50.00000,34.00000,1.952381e-10,0.86129,4
701.64899,336.33833,     -4.54654,  2.45231,50.00000,34.00000,1.952381e-10,0.86129,4
703.25800,336.41833,     -4.61088,  2.47948,50.00000,34.00000,1.949902e-10,0.86124,4
704.87000,336.49833,     -4.67603,  2.47948,50.00000,34.00000,1.949902e-10,0.86124,4
706.49298,336.57833,     -4.74299,  2.47948,50.00000,34.00000,1.955699e-10,0.86120,4
708.09998,336.65833,     -4.80751,  2.50684,50.00000,34.00000,1.955699e-10,0.86120,4
709.72900,336.73833,     -4.87549,  2.51368,50.00000,34.00000,1.953697e-10,0.86114,4
711.32898,336.81833,     -4.94096,  2.53421,50.00000,34.00000,1.953697e-10,0.86114,4
712.94598,336.89833,     -5.00412,  2.54789,50.00000,34.00000,1.953201e-10,0.86109,4
714.55798,336.97833,     -5.06934,  2.56157,50.00000,34.00000,1.953201e-10,0.86109,4
716.17200,337.05833,     -5.13314,  2.56157,50.00000,34.00000,1.959134e-10,0.86104,4
717.78497,337.13833,     -5.20319,  2.56841,50.00000,34.00000,1.959134e-10,0.86104,4
719.38800,337.21833,     -5.26439,  2.58873,50.00000,34.00000,1.959018e-10,0.86099,4
721.00702,337.29833,     -5.32807,  2.61610,50.00000,33.00000,1.959018e-10,0.86099,4
722.62701,337.37833,     -5.39160,  2.61610,50.00000,33.00000,1.952266e-10,0.86094,4
724.22900,337.45833,     -5.45520,  2.64346,50.00000,33.00000,1.952266e-10,0.86094,4
725.84998,337.53833,     -5.51809,  2.68672,50.00000,33.00000,1.951180e-10,0.86088,4
727.46198,337.61833,     -5.58628,  2.67304,50.00000,33.00000,1.951180e-10,0.86088,4
729.07800,337.69833,     -5.64883,  2.70040,50.00000,33.00000,1.951180e-10,0.86088,4
730.69397,337.77833,     -5.71543,  2.70040,50.00000,33.00000,1.951312e-10,0.86083,4
732.30298,337.85833,     -5.78055,  2.70040,50.00000,34.00000,1.951312e-10,0.86083,4
733.91901,337.93833,     -5.84684,  2.72777,50.00000,33.00000,1.956729e-10,0.86078,4
735.53400,338.01833,     -5.91135,  2.75493,50.00000,33.00000,1.956729e-10,0.86078,4
737.14600,338.09833,     -5.97535,  2.75493,50.00000,33.00000,1.951695e-10,0.86073,4
738.75299,338.17833,     -6.03917,  2.78229,50.00000,33.00000,1.951695e-10,0.86073,4
740.37701,338.25833,     -6.10913,  2.80966,50.00000,33.00000,1.955413e-10,0.86068,4
741.98102,338.33833,     -6.17622,  2.80966,50.00000,33.00000,1.955413e-10,0.86068,4
743.59998,338.41833,     -6.24258,  2.80966,50.00000,33.00000,1.950607e-10,0.86063,4
745.20599,338.49833,     -6.30477,  2.83702,50.00000,33.00000,1.950607e-10,0.86063,4
746.82397,338.57833,     -6.36915,  2.83702,50.00000,33.00000,1.952744e-10,0.86058,4
748.42603,338.65833,     -6.43757,  2.86419,50.00000,33.00000,1.952744e-10,0.86058,4
750.04602,338.73833,     -6.50495,  2.86419,50.00000,33.00000,1.953106e-10,0.86053,4
751.66199,338.81833,     -6.56720,  2.89155,50.00000,33.00000,1.953106e-10,0.86053,4
753.26898,338.89833,     -6.63352,  2.89155,50.00000,33.00000,1.961994e-10,0.86048,4
754.88599,338.97833,     -6.69776,  2.91891,50.00000,33.00000,1.961994e-10,0.86048,4
756.49799,339.05833,     -6.76513,  2.91891,50.00000,33.00000,1.951026e-10,0.86044,4
758.10699,339.13833,     -6.82766,  2.94628,50.00000,33.00000,1.951026e-10,0.86044,4
759.71600,339.21833,     -6.89569,  2.94628,50.00000,33.00000,1.957837e-10,0.86038,4
761.32202,339.29833,     -6.96187,  2.97344,50.00000,33.00000,1.957837e-10,0.86038,4
762.93103,339.37833,     -7.02692,  3.00080,50.00000,33.00000,1.951484e-10,0.86033,4
764.53998,339.45833,     -7.09247,  3.00080,50.00000,33.00000,1.951484e-10,0.86033,4
766.14899,339.53833,     -7.15317,  3.00080,50.00000,33.00000,1.951542e-10,0.86028,4
767.75500,339.61833,     -7.22440,  3.02817,50.00000,33.00000,1.951542e-10,0.86028,4
769.36603,339.69833,     -7.28344,  3.05553,50.00000,33.00000,1.954003e-10,0.86023,4
770.97803,339.77833,     -7.35037,  3.05553,50.00000,33.00000,1.954003e-10,0.86023,4
772.58801,339.85833,     -7.41141,  3.08270,50.00000,33.00000,1.951733e-10,0.86017,4
774.20502,339.93833,     -7.47400,  3.11006,50.00000,33.00000,1.951733e-10,0.86017,4
775.81097,340.01833,     -7.54615,  3.11006,50.00000,33.00000,1.950111e-10,0.86013,4
777.41998,340.09833,     -7.61276,  3.13742,50.00000,33.00000,1.950111e-10,0.86013,4
779.03198,340.17833,     -7.67720,  3.16479,50.00000,33.00000,1.953068e-10,0.86008,4
780.63397,340.25833,     -7.73768,  3.16479,50.00000,33.00000,1.953068e-10,0.86008,4
782.25299,340.33833,     -7.79912,  3.16479,50.00000,33.00000,1.954956e-10,0.86003,4
783.86603,340.41833,     -7.86409,  3.19215,50.00000,33.00000,1.954956e-10,0.86003,4
785.47302,340.49833,     -7.92272,  3.21247,50.00000,33.00000,1.957245e-10,0.85996,4
787.09802,340.57833,     -7.98608,  3.24668,50.00000,33.00000,1.957245e-10,0.85996,4
788.69299,340.65833,     -8.04940,  3.24668,50.00000,33.00000,1.953621e-10,0.85991,4
790.30200,340.73833,     -8.10684,  3.24668,50.00000,33.00000,            ,0.44878,4
791.90503,340.81833,     -8.16713,  3.27404,50.00000,33.00000,            ,0.44813,4
793.51501,340.89833,     -8.22284,  3.27404,50.00000,33.00000,            ,0.44749,4
794.22198,340.93333,     -8.24694,  3.27404,50.00000,33.00000,            ,0.44720,4