File: data/TGA/005d-L_M/ExpDat_2025_07_20_SL_PS_Tosoh_F4_isothermal.csv
#EXPORTTYPE:                 ,DATA ALL
#FILE:                       ,2025_07_20_SL_PS_Tosoh_F4_isothermal.ngb-ss5
#FORMAT:                     ,NETZSCH5
#FTYPE:                      ,ASCII
#IDENTITY:                   ,PS-Tosoh-F4
#DECIMAL:                    ,POINT
#SEPARATOR:                  ,COMMA
#MTYPE:                      ,DSC
#INSTRUMENT:                 ,NETZSCH STA 449F5
#PROJECT:                    ,
#DATE/TIME:                  ,7/20/2025 11:49:11 AM (UTC-4)
#CORR. FILE:                 ,
#TEMPCAL:                    ,05-05-2025 14:38
#SENSITIVITY:                ,28-06-2023 13:53
#LABORATORY:                 ,Tran/AAG
#OPERATOR:                   ,Stan
#REMARK:                     ,2025_03_29_SL_005d_M1_isothermal
#SAMPLE:                     ,PS-Tosoh-F4
#SAMPLE MASS /mg:            ,5.13
#MATERIAL:                   ,Polystyrene
#REFERENCE:                  ,
#REFERENCE MASS /mg:         ,0
#TYPE OF CRUCIBLE:           ,Al2O3 85 ‘l, open
#SAMPLE CRUCIBLE MASS /mg:   ,0
#REFERENCE CRUCIBLE MASS /mg:,0
#DSC RANGE /‘V:              ,5000
#TG RANGE /mg:               ,35000
#TAU-R:                      ,---
#CORR. CODE:                 ,000
#EXO:                        ,-1
#RANGE:                      ,30›C....800›C/0.0....20.0K/min
#SEGMENT:                    ,S1-5/5
#SEG. 1:                     ,30›C/10.0(K/min)/100›C
#SEG. 2:                     ,100›C/00:10/100›C
#SEG. 3:                     ,100›C/5.0(K/min)/300›C
#SEG. 4:                     ,300›C/20:00/300›C
#SEG. 5:                     ,300›C/20.0(K/min)/800›C

##Temp./›C,Time/min,DSC/(mW/mg),Mass/%,Gas Flow(purge2)/(ml/min),Gas Flow(protective)/(ml/min),TIC(scan:1)/A,Sensit./(uV/mW),Segment
 33.22900,   0.00000,      0.64953,    100.00000,50.00000,50.00000,            ,0.92412,1
 37.98000,   1.36000,      0.52151,     91.37037,50.00000,50.00000,1.804985e-08,0.92428,1
 44.22000,   2.72000,      0.75105,     92.57895,50.00000,50.00000,1.810268e-08,0.92444,1
 52.86400,   4.08000,      1.18211,     93.64639,50.00000,50.00000,1.805544e-08,0.92461,1
 64.93600,   5.44000,      1.73728,     94.79747,50.00000,50.00000,1.807668e-08,0.92478,1
 79.51500,   6.80000,      2.24287,     95.67096,50.00000,50.00000,1.806573e-08,0.92495,1
 88.13000,   7.56083,      2.35686,     95.77446,50.00000,50.00000,1.806773e-08,0.92506,2
 94.26300,   8.24083,      1.99375,     95.10624,50.00000,50.00000,1.807365e-08,0.92514,2
 98.57400,   8.92083,      1.48935,     94.36082,50.00000,50.00000,1.807976e-08,0.92523,2
101.85300,   9.60083,      1.15625,     93.86472,50.00000,50.00000,1.805765e-08,0.92531,2
104.57700,  10.28083,      0.96508,     93.50078,50.00000,50.00000,1.806648e-08,0.92539,2
106.68900,  10.96083,      0.76314,     93.11715,50.00000,50.00000,1.809881e-08,0.92547,2
108.09900,  11.64083,      0.51341,     92.68480,50.00000,50.00000,1.801759e-08,0.92555,2
108.88000,  12.32083,      0.28802,     92.27466,50.00000,50.00000,1.804835e-08,0.92563,2
109.23400,  13.00083,      0.11221,     91.88207,50.00000,50.00000,1.806966e-08,0.92570,2
109.23000,  13.68083,-2.477308e-02,     91.55789,50.00000,50.00000,1.801556e-08,0.92577,2
108.96800,  14.36083,     -0.13341,     91.23821,50.00000,50.00000,1.807464e-08,0.92584,2
108.48300,  15.04083,     -0.21902,     90.94269,50.00000,50.00000,1.805234e-08,0.92591,2
107.87100,  15.72083,     -0.27951,     90.71988,50.00000,50.00000,1.806899e-08,0.92597,2
107.15000,  16.40083,     -0.31795,     90.47953,50.00000,50.00000,1.804597e-08,0.92603,2
106.26800,  17.20083,     -0.33954,     90.28538,50.00000,50.00000,1.805057e-08,0.92609,3
106.50000,  18.56083,      0.11680,     90.93606,50.00000,50.00000,1.802920e-08,0.92617,3
109.39600,  19.92083,      0.56933,     91.57778,50.00000,50.00000,1.802722e-08,0.92620,3
114.05600,  21.28083,      0.94714,     92.23060,50.00000,50.00000,1.801205e-08,0.92618,3
120.36300,  22.64083,      1.28506,     92.78402,50.00000,50.00000,1.803946e-08,0.92611,3
127.68900,  24.00083,      1.51511,     93.15458,50.00000,50.00000,1.805129e-08,0.92597,3
135.58600,  25.36083,      1.66264,     93.42593,50.00000,50.00000,1.806116e-08,0.92576,3
143.63800,  26.72083,      1.74316,     93.61111,50.00000,50.00000,1.800342e-08,0.92547,3
151.64799,  28.08083,      1.79143,     93.74347,50.00000,50.00000,1.800912e-08,0.92509,3
159.42999,  29.44083,      1.81195,     93.83606,50.00000,50.00000,1.804998e-08,0.92463,3
166.96899,  30.80083,      1.81827,     93.92865,50.00000,50.00000,1.803876e-08,0.92436,3
174.26900,  32.16083,      1.82501,     93.95517,50.00000,50.00000,1.802338e-08,0.92407,3
181.38400,  33.52083,      1.83422,     94.04113,50.00000,50.00000,1.797959e-08,0.92378,3
188.36400,  34.88083,      1.85034,     94.12710,50.00000,50.00000,1.802760e-08,0.92348,3
195.27100,  36.24083,      1.87303,     94.20643,50.00000,50.00000,1.800839e-08,0.92315,3
202.10201,  37.60083,      1.90494,     94.31228,50.00000,50.00000,1.798957e-08,0.92286,3
208.89700,  38.96083,      1.94077,     94.40507,50.00000,50.00000,1.799770e-08,0.92258,3
215.67900,  40.32083,      1.97215,     94.52417,50.00000,50.00000,1.801409e-08,0.92232,3
222.42700,  41.68083,      1.98677,     94.60351,50.00000,50.00000,1.800130e-08,0.92207,3
229.18300,  43.04083,      2.00488,     94.70487,50.00000,50.00000,1.798360e-08,0.92183,3
235.96100,  44.40083,      2.03113,     94.81072,50.00000,50.00000,1.797626e-08,0.92161,3
242.72600,  45.76083,      2.05782,     94.90331,50.00000,50.00000,1.795849e-08,0.92140,3
249.48900,  47.12083,      2.08746,     94.98285,50.00000,50.00000,1.798156e-08,0.92120,3
256.25201,  48.48083,      2.12136,     95.03567,50.00000,50.00000,1.794394e-08,0.92100,3
263.03000,  49.84083,      2.15458,     95.10858,50.00000,50.00000,1.797557e-08,0.92081,3
269.81201,  51.20083,      2.18688,     95.12827,50.00000,50.00000,1.794304e-08,0.92063,3
276.60501,  52.56083,      2.22174,     95.14386,50.00000,50.00000,1.794787e-08,0.92045,3
283.38599,  53.92083,      2.25545,     95.16355,50.00000,50.00000,1.800064e-08,0.92027,3
290.14700,  55.28083,      2.28945,     95.13723,50.00000,50.00000,1.798064e-08,0.92011,3
296.91501,  56.64083,      2.32397,     95.10858,50.00000,50.00000,1.797839e-08,0.91992,3
303.17700,  59.56083,      0.72536,     95.71930,50.00000,32.00000,1.795975e-08,0.91959,4
302.76001,  62.96083,      0.25626,     95.02476,50.00000,32.00000,1.790521e-08,0.91927,4
301.45001,  66.36083,      0.24716,     94.51520,50.00000,32.00000,1.795980e-08,0.91900,4
300.67099,  69.76083,      0.29193,     94.12281,50.00000,32.00000,1.794426e-08,0.91881,4
300.29800,  73.16083,      0.32166,     93.71910,50.00000,32.00000,1.793306e-08,0.91866,4
300.11899,  76.56083,      0.33255,     93.36628,50.00000,32.00000,1.794029e-08,0.91856,4
300.05801,  79.96083,      0.33857,     93.02222,50.00000,32.00000,1.790548e-08,0.91852,4
300.02899,  83.36083,      0.33932,     92.71131,50.00000,32.00000,1.795520e-08,0.91850,4
300.01801,  86.76083,      0.33893,     92.46433,50.00000,32.00000,1.788989e-08,0.91851,4
300.01001,  90.16083,      0.33723,     92.19084,50.00000,32.00000,1.788272e-08,0.91856,4
300.00500,  93.56083,      0.33685,     91.93060,50.00000,32.00000,1.791244e-08,0.91863,4
300.00900,  96.96083,      0.34025,     91.68811,50.00000,32.00000,1.789511e-08,0.91871,4
300.02399, 100.36083,      0.34007,     91.49610,50.00000,32.00000,1.790083e-08,0.91881,4
300.01599, 103.76083,      0.33950,     91.29766,50.00000,32.00000,1.788589e-08,0.91893,4
300.01099, 107.16083,      0.33931,     91.05945,50.00000,32.00000,1.788645e-08,0.91905,4
300.01199, 110.56083,      0.34120,     90.92066,50.00000,32.00000,1.788579e-08,0.91917,4
300.02701, 113.96083,      0.34045,     90.67349,50.00000,31.00000,1.787473e-08,0.91931,4
300.01300, 117.36083,      0.34252,     90.49493,50.00000,31.00000,1.785629e-08,0.91947,4
300.02600, 120.76083,      0.34366,     90.32300,50.00000,31.00000,1.787804e-08,0.91929,4
300.00800, 124.16083,      0.34403,     90.11774,50.00000,31.00000,1.785611e-08,0.91882,4
300.02200, 127.56083,      0.34668,     89.95029,50.00000,31.00000,1.787355e-08,0.91818,4
300.01401, 130.96083,      0.34649,     89.78265,50.00000,31.00000,1.786314e-08,0.91732,4
300.01700, 134.36083,      0.34951,     89.61715,50.00000,31.00000,1.782920e-08,0.91620,4
300.00601, 137.76083,      0.35178,     89.46277,50.00000,31.00000,1.788010e-08,0.91485,4
300.01801, 141.16083,      0.35499,     89.27973,50.00000,31.00000,1.784186e-08,0.91330,4
300.01700, 144.56083,      0.35896,     89.10994,50.00000,31.00000,1.787497e-08,0.91155,4
300.01001, 147.96083,      0.36160,     88.94678,50.00000,31.00000,1.784352e-08,0.90952,4
300.01501, 151.36083,      0.36727,     88.79454,50.00000,32.00000,1.785392e-08,0.90744,4
300.02100, 154.76083,      0.36841,     88.61813,50.00000,31.00000,1.786536e-08,0.90523,4
300.03000, 158.16083,      0.38032,     88.44620,50.00000,32.00000,1.781105e-08,0.90293,4
300.01199, 161.56083,      0.38239,     88.26745,50.00000,32.00000,1.779410e-08,0.90056,4
300.01099, 164.96083,      0.38560,     88.14854,50.00000,32.00000,1.780304e-08,0.89801,4
300.01901, 168.36083,      0.38843,     87.98304,50.00000,32.00000,1.783791e-08,0.89553,4
300.02802, 171.76083,      0.39354,     87.81111,50.00000,32.00000,1.781677e-08,0.89302,4
300.01501, 175.16083,      0.39221,     87.64561,50.00000,32.00000,1.785781e-08,0.89048,4
300.01401, 178.56083,      0.39788,     87.50000,50.00000,32.00000,1.787016e-08,0.88790,4
300.01700, 181.96083,      0.39920,     87.35010,50.00000,31.00000,1.781383e-08,0.88527,4
300.01700, 185.36083,      0.40204,     87.22437,50.00000,31.00000,1.780283e-08,0.88262,4
300.01599, 188.76083,      0.40204,     87.06784,50.00000,31.00000,1.772210e-08,0.87993,4
300.00699, 192.16083,      0.40279,     86.90253,50.00000,31.00000,1.779402e-08,0.87705,4
300.00900, 195.56083,      0.40014,     86.73704,50.00000,31.00000,1.781978e-08,0.87427,4
300.00699, 198.96083,      0.27583,     86.57388,50.00000,31.00000,1.780911e-08,0.87145,4
300.02701, 202.36083,      0.26374,     86.42164,50.00000,31.00000,1.780094e-08,0.86858,4
300.00299, 205.76083,      0.26317,     86.28265,50.00000,31.00000,1.779125e-08,0.86565,4
300.00800, 209.16083,      0.26468,     86.08421,50.00000,31.00000,1.784810e-08,0.86270,4
300.00201, 212.56083,      0.26487,     85.95848,50.00000,31.00000,1.781278e-08,0.85953,4
300.02600, 215.96083,      0.26715,     85.82183,50.00000,31.00000,1.777201e-08,0.85648,4
300.03201, 219.36083,      0.26904,     85.66959,50.00000,31.00000,1.777680e-08,0.85338,4
300.03201, 222.76083,      0.26979,     85.47329,50.00000,31.00000,1.781604e-08,0.85023,4
300.01801, 226.16083,      0.27394,     85.33450,50.00000,31.00000,1.774940e-08,0.84704,4
300.00000, 229.56083,      0.27299,     85.16238,50.00000,31.00000,1.776836e-08,0.84380,4
300.00500, 232.96083,      0.27507,     85.03236,50.00000,31.00000,1.779150e-08,0.84052,4
300.02301, 236.36083,      0.27546,     84.90000,50.00000,31.00000,1.780663e-08,0.83720,4
300.01801, 239.76083,      0.27999,     84.73021,50.00000,31.00000,1.776699e-08,0.83369,4
300.01199, 243.16083,      0.27791,     84.59786,50.00000,32.00000,1.773780e-08,0.83030,4
300.01199, 246.56083,      0.28282,     84.45887,50.00000,32.00000,1.778093e-08,0.82686,4
300.02301, 249.96083,      0.28188,     84.29123,50.00000,32.00000,1.776675e-08,0.82340,4
300.00601, 253.36083,      0.28320,     84.18538,50.00000,32.00000,1.778242e-08,0.81990,4
300.01099, 256.76083,      0.28509,     83.99357,50.00000,32.00000,1.770441e-08,0.81638,4
300.01801, 260.16083,      0.28944,     83.88558,50.00000,32.00000,1.775241e-08,0.81281,4
300.01700, 263.56083,      0.28792,     83.72671,50.00000,32.00000,1.773504e-08,0.80924,4
300.02100, 266.96083,      0.29000,     83.58772,50.00000,32.00000,1.774876e-08,0.80563,4
300.02301, 270.36083,      0.29114,     83.46218,50.00000,32.00000,1.774321e-08,0.80181,4
300.02200, 273.76083,      0.29567,     83.28791,50.00000,32.00000,1.774956e-08,0.79818,4
300.01501, 277.16083,      0.29454,     83.14444,50.00000,32.00000,1.775414e-08,0.79450,4
300.01801, 280.56083,      0.29775,     83.04308,50.00000,32.00000,1.774321e-08,0.79081,4
300.02701, 283.96083,      0.29643,     82.90409,50.00000,32.00000,1.767602e-08,0.78573,4
300.00699, 287.36083,      0.29831,     82.75867,50.00000,32.00000,1.770282e-08,0.78411,4
300.01901, 290.76083,      0.30134,     82.60858,50.00000,32.00000,1.770255e-08,0.78424,4
300.01001, 294.16083,      0.30266,     82.45653,50.00000,32.00000,1.770936e-08,0.78495,4
300.02301, 297.56083,      0.30644,     82.33743,50.00000,32.00000,1.772469e-08,0.78566,4
300.00400, 300.96083,      0.31267,     82.22047,50.00000,32.00000,1.768357e-08,0.78624,4
300.00601, 304.36083,      0.31966,     82.09259,50.00000,32.00000,1.773418e-08,0.78660,4
300.01801, 307.76083,      0.32193,     81.93158,50.00000,32.00000,1.771253e-08,0.78683,4
300.00400, 311.16083,      0.32835,     81.80585,50.00000,32.00000,1.769835e-08,0.78697,4
300.01501, 314.56083,      0.33478,     81.66706,50.00000,32.00000,1.773314e-08,0.78707,4
300.01700, 317.96083,      0.33969,     81.50819,50.00000,32.00000,1.772519e-08,0.78713,4
300.00699, 321.36083,      0.35008,     81.39571,50.00000,32.00000,1.765891e-08,0.78715,4
300.01700, 324.76083,      0.40015,     81.26335,50.00000,32.00000,1.773551e-08,0.78717,4
300.01999, 328.16083,      0.41470,     81.12671,50.00000,32.00000,1.768495e-08,0.78719,4
300.01599, 331.56083,      0.41450,     81.00760,50.00000,32.00000,1.766872e-08,0.78718,4
300.01199, 334.96083,      0.41564,     80.83333,50.00000,32.00000,1.769900e-08,0.78719,4
300.01199, 338.36083,      0.42168,     80.70097,50.00000,32.00000,1.772990e-08,0.78720,4
300.02200, 341.76083,      0.42584,     80.56862,50.00000,32.00000,1.767211e-08,0.78719,4
300.02301, 345.16083,      0.42509,     80.41657,50.00000,33.00000,1.774659e-08,0.78720,4
300.00800, 348.56083,      0.42716,     80.29747,50.00000,33.00000,1.766785e-08,0.78719,4
300.01801, 351.96083,      0.43056,     80.15848,50.00000,33.00000,1.767970e-08,0.78719,4
300.02100, 355.36083,      0.43264,     80.01949,50.00000,33.00000,1.765914e-08,0.78720,4
300.01401, 358.76083,      0.43529,     79.92261,50.00000,33.00000,1.770950e-08,0.78718,4
300.00601, 362.16083,      0.43509,     79.77700,50.00000,33.00000,1.766233e-08,0.78719,4
300.02802, 365.56083,      0.43832,     79.60487,50.00000,33.00000,1.774302e-08,0.78719,4
300.01999, 368.96083,      0.44058,     79.47700,50.00000,33.00000,1.768697e-08,0.78719,4
300.01001, 372.36083,      0.43944,     79.36452,50.00000,33.00000,1.766356e-08,0.78719,4
300.02600, 375.76083,      0.44455,     79.25205,50.00000,33.00000,1.767949e-08,0.78719,4
300.02200, 379.16083,      0.44436,     79.14620,50.00000,33.00000,1.767676e-08,0.78719,4
300.01199, 382.56083,      0.44662,     78.99630,50.00000,33.00000,1.768084e-08,0.78719,4
300.01999, 385.96083,      0.44738,     78.85068,50.00000,33.00000,1.768047e-08,0.78718,4
300.03000, 389.36083,      0.44871,     78.73158,50.00000,33.00000,1.767470e-08,0.78719,4
300.01300, 392.76083,      0.44662,     78.62359,50.00000,33.00000,1.765806e-08,0.78719,4
300.02200, 396.16083,      0.44814,     78.49571,50.00000,33.00000,1.764857e-08,0.78720,4
300.01401, 399.56083,      0.44851,     78.35673,50.00000,33.00000,1.764612e-08,0.78719,4
300.03101, 402.96083,      0.45135,     78.23333,50.00000,33.00000,1.768960e-08,0.78718,4
300.00900, 406.36083,      0.45550,     78.10097,50.00000,33.00000,1.767614e-08,0.78719,4
300.01999, 409.76083,      0.45418,     78.00838,50.00000,33.00000,1.764273e-08,0.78719,4
300.01599, 413.16083,      0.45607,     77.86277,50.00000,33.00000,1.764569e-08,0.78720,4
300.01999, 416.56083,      0.45531,     77.74581,50.00000,33.00000,1.766112e-08,0.78719,4
300.02600, 419.96083,      0.48158,     77.61579,50.00000,33.00000,1.765970e-08,0.78721,4
300.01801, 423.36083,      0.48592,     77.50117,50.00000,33.00000,1.761355e-08,0.78719,4
300.01501, 426.76083,      0.48932,     77.40175,50.00000,33.00000,1.758040e-08,0.78719,4
300.02499, 430.16083,      0.49273,     77.29591,50.00000,33.00000,1.762369e-08,0.78718,4
300.01199, 433.56083,      0.49064,     77.14386,50.00000,33.00000,1.758137e-08,0.78719,4
300.01099, 436.96083,      0.49026,     77.03567,50.00000,33.00000,1.758397e-08,0.78720,4
300.03500, 440.36083,      0.49179,     76.91014,50.00000,33.00000,1.757492e-08,0.78719,4
300.02200, 443.76083,      0.48781,     76.77778,50.00000,33.00000,1.759603e-08,0.78719,4
300.02200, 447.16083,      0.49027,     76.67193,50.00000,34.00000,1.758480e-08,0.78719,4
300.00699, 450.56083,      0.48742,     76.56374,50.00000,34.00000,1.756397e-08,0.78719,4
300.01999, 453.96083,      0.48951,     76.46023,50.00000,34.00000,1.762391e-08,0.78719,4
300.01401, 457.36083,      0.49177,     76.34113,50.00000,34.00000,1.758339e-08,0.78718,4
300.01401, 460.76083,      0.48611,     76.20000,50.00000,34.00000,1.756650e-08,0.78719,4
300.00500, 464.16083,      0.48365,     76.08967,50.00000,34.00000,1.755219e-08,0.78718,4
300.01501, 467.56083,      0.48460,     75.97505,50.00000,34.00000,1.758650e-08,0.78719,4
300.02399, 470.96083,      0.48403,     75.84932,50.00000,34.00000,1.753703e-08,0.78718,4
300.01401, 474.36083,      0.48497,     75.74347,50.00000,34.00000,1.758172e-08,0.78719,4
300.01199, 477.76083,      0.48233,     75.63762,50.00000,34.00000,1.754519e-08,0.78718,4
300.01901, 481.16083,      0.47950,     75.52066,50.00000,34.00000,1.756810e-08,0.78719,4
300.03101, 484.56083,      0.47818,     75.42807,50.00000,34.00000,1.752968e-08,0.78720,4
300.02399, 487.96083,      0.47912,     75.30897,50.00000,34.00000,1.753568e-08,0.78719,4
300.02200, 491.36083,      0.47610,     75.19649,50.00000,34.00000,1.754318e-08,0.78719,4
300.00699, 494.76083,      0.47137,     75.09064,50.00000,34.00000,1.752149e-08,0.78719,4
300.01599, 498.16083,      0.47628,     74.98480,50.00000,34.00000,1.753501e-08,0.78720,4
300.02200, 501.56083,      0.47610,     74.83918,50.00000,34.00000,1.756221e-08,0.78719,4
300.00699, 504.96083,      0.47212,     74.72671,50.00000,34.00000,1.752039e-08,0.78719,4
300.01001, 508.36083,      0.47704,     74.62534,50.00000,34.00000,1.753654e-08,0.78719,4
300.01001, 511.76083,      0.47571,     74.51949,50.00000,34.00000,1.755246e-08,0.78719,4
300.01099, 515.16083,      0.47005,     74.41365,50.00000,34.00000,1.752700e-08,0.78719,4
300.01599, 518.56083,      0.47326,     74.30546,50.00000,34.00000,1.747854e-08,0.78720,4
300.02100, 521.96083,      0.47232,     74.24815,50.00000,34.00000,1.751858e-08,0.78720,4
300.01099, 525.36083,      0.47401,     74.06082,50.00000,34.00000,1.753631e-08,0.78719,4
300.03299, 528.76083,      0.47289,     73.90643,50.00000,34.00000,1.751436e-08,0.78719,4
300.01801, 532.16083,      0.47099,     73.82027,50.00000,34.00000,1.752939e-08,0.78719,4
300.03201, 535.56083,      0.46760,     73.70780,50.00000,34.00000,1.748983e-08,0.78720,4
300.02701, 538.96083,      0.47251,     73.59552,50.00000,34.00000,1.751526e-08,0.78719,4
300.01999, 542.36083,      0.47081,     73.46316,50.00000,34.00000,1.748844e-08,0.78719,4
300.02399, 545.76083,      0.46760,     73.39688,50.00000,34.00000,1.751861e-08,0.78720,4
300.02600, 549.16083,      0.47194,     73.26472,50.00000,34.00000,1.752927e-08,0.78718,4
300.02802, 552.56083,      0.46930,     73.14561,50.00000,34.00000,1.751298e-08,0.78719,4
300.01801, 555.96083,      0.46911,     73.01988,50.00000,34.00000,1.748974e-08,0.78718,4
300.01901, 559.36083,      0.46967,     72.91618,50.00000,34.00000,1.748829e-08,0.78719,4
300.00400, 562.76083,      0.46872,     72.81033,50.00000,34.00000,1.749885e-08,0.78718,4
300.01199, 566.16083,      0.47005,     72.69337,50.00000,34.00000,1.748472e-08,0.78720,4
300.02200, 569.56083,      0.47137,     72.57427,50.00000,34.00000,1.749664e-08,0.78718,4
300.01901, 572.96083,      0.47005,     72.46179,50.00000,34.00000,1.752247e-08,0.78719,4
300.02301, 576.36083,      0.46760,     72.36257,50.00000,34.00000,1.753404e-08,0.78720,4
300.00601, 579.76083,      0.47061,     72.24347,50.00000,34.00000,1.753202e-08,0.78719,4
300.01700, 583.16083,      0.47081,     72.13099,50.00000,34.00000,1.750098e-08,0.78719,4
300.01199, 586.56083,      0.46854,     72.05166,50.00000,34.00000,1.752154e-08,0.78719,4
300.01099, 589.96083,      0.46891,     71.93255,50.00000,34.00000,1.747187e-08,0.78719,4
300.03400, 593.36083,      0.47063,     71.80916,50.00000,34.00000,1.748293e-08,0.78719,4
300.02802, 596.76083,      0.46968,     71.69669,50.00000,34.00000,1.749844e-08,0.78719,4
300.00101, 600.16083,      0.46456,     71.60409,50.00000,34.00000,1.748857e-08,0.78719,4
300.00900, 603.56083,      0.46702,     71.49162,50.00000,35.00000,1.748361e-08,0.78719,4
300.02100, 606.96083,      0.46627,     71.36589,50.00000,35.00000,1.750511e-08,0.78719,4
300.00601, 610.36083,      0.46211,     71.27329,50.00000,35.00000,1.752902e-08,0.78718,4
300.01099, 613.76083,      0.46249,     71.14094,50.00000,35.00000,1.751380e-08,0.78720,4
300.01700, 617.16083,      0.45739,     71.04834,50.00000,35.00000,1.748646e-08,0.78719,4
300.01599, 620.56083,      0.45418,     70.91598,50.00000,35.00000,1.746549e-08,0.78720,4
300.02600, 623.96083,      0.45532,     70.81014,50.00000,35.00000,1.747407e-08,0.78719,4
300.02600, 627.36083,      0.45456,     70.67563,50.00000,35.00000,1.750846e-08,0.78719,4
300.02399, 630.76083,      0.44776,     70.60507,50.00000,35.00000,1.751145e-08,0.78720,4
299.99899, 634.16083,      0.45493,     70.46823,50.00000,35.00000,1.749997e-08,0.78719,4
300.01300, 637.56083,      0.45267,     70.39552,50.00000,35.00000,1.749712e-08,0.78719,4
300.01999, 640.96083,      0.45531,     70.30292,50.00000,35.00000,1.746927e-08,0.78719,4
300.01001, 644.36083,      0.45266,     70.16842,50.00000,35.00000,1.747810e-08,0.78719,4
300.00201, 647.76083,      0.45455,     70.07349,50.00000,35.00000,1.749946e-08,0.78719,4
300.01199, 651.16083,      0.45285,     69.97427,50.00000,35.00000,1.747055e-08,0.78719,4
300.02100, 654.56083,      0.45380,     69.82203,50.00000,35.00000,1.749030e-08,0.78719,4
300.01999, 657.96083,      0.45531,     69.72515,50.00000,35.00000,1.748547e-08,0.78720,4
300.01599, 661.36083,      0.45569,     69.60370,50.00000,35.00000,1.752617e-08,0.78720,4
300.01901, 664.76083,      0.45550,     69.51111,50.00000,35.00000,1.749806e-08,0.78719,4
300.02301, 668.16083,      0.45210,     69.39864,50.00000,35.00000,1.749762e-08,0.78718,4
300.01199, 671.56083,      0.45607,     69.27524,50.00000,35.00000,1.752331e-08,0.78718,4
300.01999, 674.96083,      0.45154,     69.15828,50.00000,35.00000,1.753321e-08,0.78719,4
300.01700, 678.36083,      0.45305,     69.08324,50.00000,35.00000,1.748259e-08,0.78718,4
300.00900, 681.76083,      0.44907,     68.94873,50.00000,35.00000,1.751985e-08,0.78718,4
300.00601, 685.16083,      0.44983,     68.83626,50.00000,35.00000,1.752922e-08,0.78719,4
300.02100, 688.56083,      0.45135,     68.73041,50.00000,35.00000,1.753454e-08,0.78719,4
300.02100, 691.96083,      0.45607,     68.61793,50.00000,35.00000,1.749048e-08,0.78719,4
299.99600, 695.36083,      0.45398,     68.51423,50.00000,35.00000,1.748537e-08,0.78720,4
300.02701, 698.76083,      0.45437,     68.41287,50.00000,35.00000,1.750284e-08,0.78720,4
300.02899, 702.16083,      0.45154,     68.28499,50.00000,35.00000,1.749396e-08,0.78720,4
300.02100, 705.56083,      0.45135,     68.22768,50.00000,35.00000,1.748048e-08,0.78719,4
300.01901, 708.96083,      0.44984,     68.08869,50.00000,35.00000,1.750639e-08,0.78718,4
299.99399, 712.36083,      0.45114,     67.97622,50.00000,35.00000,1.748814e-08,0.78720,4
300.01700, 715.76083,      0.45418,     67.87700,50.00000,35.00000,1.749528e-08,0.78718,4
300.02200, 719.16083,      0.45324,     67.77115,50.00000,35.00000,1.751298e-08,0.78719,4
300.01401, 722.56083,      0.45248,     67.66530,50.00000,35.00000,1.753931e-08,0.78719,4
300.01300, 725.96083,      0.45134,     67.53743,50.00000,35.00000,1.748260e-08,0.78719,4
300.00201, 729.36083,      0.45304,     67.43587,50.00000,35.00000,1.751054e-08,0.78719,4
300.02399, 732.76083,      0.45305,     67.34776,50.00000,35.00000,1.750590e-08,0.78719,4
300.01300, 736.16083,      0.45512,     67.20877,50.00000,35.00000,1.751317e-08,0.78719,4
300.01801, 739.56083,      0.45172,     67.14269,50.00000,35.00000,1.751913e-08,0.78720,4
300.01501, 742.96083,      0.45267,     67.01033,50.00000,35.00000,1.750951e-08,0.78719,4
300.01199, 746.36083,      0.44908,     66.92437,50.00000,35.00000,1.751799e-08,0.78720,4
300.02600, 749.76083,      0.45437,     66.84932,50.00000,35.00000,1.747882e-08,0.78720,4
300.01599, 753.16083,      0.45191,     66.67719,50.00000,35.00000,1.750895e-08,0.78719,4
300.00500, 756.56083,      0.45285,     66.59786,50.00000,35.00000,1.749726e-08,0.78720,4
300.02200, 759.96083,      0.45418,     66.50526,50.00000,35.00000,1.749969e-08,0.78719,4
300.01199, 763.36083,      0.45323,     66.37739,50.00000,35.00000,1.749437e-08,0.78719,4
300.01199, 766.76083,      0.45285,     66.30234,50.00000,35.00000,1.749703e-08,0.78719,4
300.02399, 770.16083,      0.45022,     66.18324,50.00000,35.00000,1.749199e-08,0.78720,4
300.02100, 773.56083,      0.45003,     66.09942,50.00000,35.00000,1.749357e-08,0.78719,4
300.01300, 776.96083,      0.45531,     65.96062,50.00000,35.00000,1.747421e-08,0.78719,4
300.01999, 780.36083,      0.45229,     65.85478,50.00000,35.00000,1.746451e-08,0.78718,4
300.02301, 783.76083,      0.45154,     65.75536,50.00000,35.00000,1.745539e-08,0.78719,4
300.01599, 787.16083,      0.44832,     65.66511,50.00000,35.00000,1.750218e-08,0.78718,4
300.01901, 790.56083,      0.45172,     65.58343,50.00000,35.00000,1.750571e-08,0.78720,4
300.02399, 793.96083,      0.44965,     65.45107,50.00000,35.00000,1.746553e-08,0.78720,4
300.00900, 797.36083,      0.45191,     65.35185,50.00000,35.00000,1.747451e-08,0.78720,4
300.03000, 800.76083,      0.45079,     65.27914,50.00000,35.00000,1.748517e-08,0.78720,4
300.01099, 804.16083,      0.45002,     65.15127,50.00000,35.00000,1.748115e-08,0.78720,4
300.01700, 807.56083,      0.45097,     65.03879,50.00000,35.00000,1.741926e-08,0.78718,4
300.02701, 810.96083,      0.44965,     64.93060,50.00000,35.00000,1.748691e-08,0.78720,4
300.02100, 814.36083,      0.45513,     64.85789,50.00000,35.00000,1.747205e-08,0.78720,4
300.02399, 817.76083,      0.44852,     64.71891,50.00000,34.00000,1.750276e-08,0.78720,4
300.01300, 821.16083,      0.44870,     64.62632,50.00000,34.00000,1.745780e-08,0.78720,4
300.01599, 824.56083,      0.44927,     64.52710,50.00000,34.00000,1.746425e-08,0.78718,4
300.02301, 827.96083,      0.45003,     64.42788,50.00000,34.00000,1.742621e-08,0.78719,4
300.01801, 831.36083,      0.44719,     64.33528,50.00000,34.00000,1.746994e-08,0.78719,4
300.00601, 834.76083,      0.45021,     64.23158,50.00000,34.00000,1.745596e-08,0.78720,4
300.01401, 838.16083,      0.44927,     64.11910,50.00000,34.00000,1.748687e-08,0.78719,4
300.02100, 841.56083,      0.44984,     64.00877,50.00000,34.00000,1.746540e-08,0.78719,4
300.02200, 844.96083,      0.45003,     63.89415,50.00000,34.00000,1.742931e-08,0.78719,4
300.02301, 848.36083,      0.44889,     63.80585,50.00000,34.00000,1.744151e-08,0.78719,4
300.01599, 851.76083,      0.45191,     63.68246,50.00000,34.00000,1.742920e-08,0.78719,4
300.01001, 855.16083,      0.45021,     63.60955,50.00000,34.00000,1.740339e-08,0.78720,4
300.00900, 858.56083,      0.45021,     63.49064,50.00000,34.00000,1.747807e-08,0.78719,4
300.01401, 861.96083,      0.45153,     63.39123,50.00000,34.00000,1.743825e-08,0.78719,4
300.02701, 865.36083,      0.44890,     63.28772,50.00000,34.00000,1.742890e-08,0.78719,4
300.01401, 868.76083,      0.44775,     63.19513,50.00000,34.00000,1.742958e-08,0.78719,4
300.01901, 872.16083,      0.44946,     63.10234,50.00000,34.00000,1.744865e-08,0.78720,4
300.01001, 875.56083,      0.45078,     63.00312,50.00000,34.00000,1.742719e-08,0.78719,4
300.01801, 878.96083,      0.44908,     62.88402,50.00000,34.00000,1.744526e-08,0.78719,4
300.01001, 882.36083,      0.44794,     62.77817,50.00000,34.00000,1.744079e-08,0.78719,4
300.01599, 885.76083,      0.44643,     62.67232,50.00000,34.00000,1.743776e-08,0.78719,4
300.01801, 889.16083,      0.45040,     62.57973,50.00000,34.00000,1.746154e-08,0.78719,4
300.01801, 892.56083,      0.45267,     62.47388,50.00000,34.00000,1.738980e-08,0.78719,4
300.01501, 895.96083,      0.45191,     62.36803,50.00000,34.00000,1.741088e-08,0.78718,4
300.01401, 899.36083,      0.44851,     62.27544,50.00000,34.00000,1.744858e-08,0.78718,4
300.01300, 902.76083,      0.44927,     62.20273,50.00000,34.00000,1.739791e-08,0.78719,4
300.01599, 906.16083,      0.45248,     62.10994,50.00000,34.00000,1.744760e-08,0.78719,4
300.01999, 909.56083,      0.44795,     61.99084,50.00000,34.00000,1.743782e-08,0.78719,4
300.01999, 912.96083,      0.44984,     61.87836,50.00000,34.00000,1.744951e-08,0.78718,4
300.01001, 916.36083,      0.44964,     61.77251,50.00000,34.00000,1.742951e-08,0.78719,4
300.00900, 919.76083,      0.45210,     61.67992,50.00000,34.00000,1.742509e-08,0.78719,4
300.00800, 923.16083,      0.44718,     61.56082,50.00000,34.00000,1.738575e-08,0.78719,4
300.01801, 926.56083,      0.44983,     61.47485,50.00000,34.00000,1.741891e-08,0.78719,4
300.01001, 929.96083,      0.44681,     61.38889,50.00000,34.00000,1.742998e-08,0.78718,4
300.02802, 933.36083,      0.45230,     61.26316,50.00000,34.00000,1.743268e-08,0.78718,4
300.01099, 936.76083,      0.44794,     61.17719,50.00000,34.00000,1.741217e-08,0.78719,4
300.01501, 940.16083,      0.44568,     61.07563,50.00000,34.00000,1.742621e-08,0.78721,4
300.03201, 943.56083,      0.44871,     60.98304,50.00000,34.00000,1.743943e-08,0.78719,4
300.01599, 946.96083,      0.44908,     60.86394,50.00000,34.00000,1.741526e-08,0.78720,4
300.02100, 950.36083,      0.44700,     60.78460,50.00000,34.00000,1.742153e-08,0.78719,4
300.01300, 953.76083,      0.44568,     60.69201,50.00000,34.00000,1.739298e-08,0.78720,4
300.00699, 957.16083,      0.44737,     60.59279,50.00000,34.00000,1.739602e-08,0.78719,4
300.01999, 960.56083,      0.44757,     60.48031,50.00000,34.00000,1.741799e-08,0.78719,4
300.01099, 963.96083,      0.44851,     60.37446,50.00000,34.00000,1.740595e-08,0.78719,4
300.01901, 967.36083,      0.44568,     60.29279,50.00000,34.00000,1.744050e-08,0.78719,4
300.02499, 970.76083,      0.44757,     60.20019,50.00000,34.00000,1.739920e-08,0.78719,4
300.02701, 974.16083,      0.44738,     60.09435,50.00000,34.00000,1.741064e-08,0.78719,4
300.01801, 977.56083,      0.44813,     59.98850,50.00000,34.00000,1.734488e-08,0.78719,4
300.01501, 980.96083,      0.44832,     59.87602,50.00000,34.00000,1.737596e-08,0.78720,4
300.00699, 984.36083,      0.44700,     59.79669,50.00000,34.00000,1.743109e-08,0.78719,4
300.02802, 987.76083,      0.44795,     59.69084,50.00000,34.00000,1.737747e-08,0.78718,4
300.01300, 991.16083,      0.44775,     59.58499,50.00000,34.00000,1.736520e-08,0.78719,4
300.02899, 994.56083,      0.44738,     59.49883,50.00000,34.00000,1.739242e-08,0.78719,4
300.01700, 997.96083,      0.44738,     59.43938,50.00000,34.00000,1.735848e-08,0.78719,4
300.02200,1001.36083,      0.44606,     59.32027,50.00000,34.00000,1.743471e-08,0.78720,4
300.02802,1004.76083,      0.44549,     59.20780,50.00000,34.00000,1.735663e-08,0.78718,4
300.01999,1008.16083,      0.44455,     59.10195,50.00000,34.00000,1.734590e-08,0.78717,4
300.01999,1011.56083,      0.44568,     59.02924,50.00000,34.00000,1.737573e-08,0.78718,4
300.01700,1014.96083,      0.44398,     58.91676,50.00000,34.00000,1.734950e-08,0.78719,4
300.00900,1018.36083,      0.44567,     58.83723,50.00000,34.00000,1.733497e-08,0.78718,4
300.01501,1021.76083,      0.44530,     58.72476,50.00000,34.00000,1.731814e-08,0.78720,4
300.02200,1025.16083,      0.44417,     58.65867,50.00000,34.00000,1.733164e-08,0.78719,4
300.02499,1028.56083,      0.44568,     58.54620,50.00000,34.00000,1.734254e-08,0.78719,4
300.01999,1031.96083,      0.44719,     58.46023,50.00000,34.00000,1.729070e-08,0.78719,4
300.01001,1035.36083,      0.44737,     58.36979,50.00000,34.00000,1.725245e-08,0.78720,4
300.01999,1038.76083,      0.44549,     58.25731,50.00000,34.00000,1.730406e-08,0.78720,4
300.03201,1042.16083,      0.44569,     58.17797,50.00000,34.00000,1.729767e-08,0.78719,4
300.01901,1045.56083,      0.44417,     58.06550,50.00000,34.00000,1.730020e-08,0.78719,4
300.01801,1048.96083,      0.44417,     57.99259,50.00000,34.00000,1.732068e-08,0.78719,4
300.02200,1052.36083,      0.44455,     57.87349,50.00000,34.00000,1.730281e-08,0.78718,4
300.02399,1055.76083,      0.44323,     57.81404,50.00000,34.00000,1.725963e-08,0.78719,4
300.03601,1059.16083,      0.44248,     57.70819,50.00000,33.00000,1.729055e-08,0.78720,4
300.02200,1062.56083,      0.44795,     57.59571,50.00000,34.00000,1.725230e-08,0.78719,4
300.02701,1065.96083,      0.44455,     57.51637,50.00000,34.00000,1.726257e-08,0.78720,4
300.02499,1069.36083,      0.44455,     57.41696,50.00000,34.00000,1.726581e-08,0.78720,4
300.01700,1072.76083,      0.44492,     57.31774,50.00000,34.00000,1.730713e-08,0.78718,4
300.01501,1076.16083,      0.44284,     57.20312,50.00000,34.00000,1.725715e-08,0.78718,4
300.01801,1079.56083,      0.44946,     57.13041,50.00000,34.00000,1.721815e-08,0.78718,4
300.01801,1082.96083,      0.44454,     57.03119,50.00000,34.00000,1.722615e-08,0.78719,4
300.02301,1086.36083,      0.44171,     56.93840,50.00000,34.00000,1.724505e-08,0.78719,4
300.02100,1089.76083,      0.44530,     56.80390,50.00000,34.00000,1.721503e-08,0.78718,4
300.01199,1093.16083,      0.44530,     56.71793,50.00000,34.00000,1.721891e-08,0.78719,4
300.01999,1096.56083,      0.45002,     56.63197,50.00000,34.00000,1.722830e-08,0.78719,4
300.02100,1099.96083,      0.44587,     56.52398,50.00000,34.00000,1.722279e-08,0.78719,4
300.00699,1103.36083,      0.44548,     56.45984,50.00000,34.00000,1.723513e-08,0.78718,4
300.02899,1106.76083,      0.44455,     56.34737,50.00000,34.00000,1.716426e-08,0.78719,4
300.03000,1110.16083,      0.44474,     56.28791,50.00000,34.00000,1.718861e-08,0.78718,4
300.02802,1113.56083,      0.45022,     56.16667,50.00000,34.00000,1.719637e-08,0.78718,4
300.01401,1116.96083,      0.44265,     56.07173,50.00000,34.00000,1.721651e-08,0.78718,4
300.00900,1120.36083,      0.44681,     55.97914,50.00000,34.00000,1.718561e-08,0.78718,4
300.02399,1123.76083,      0.44795,     55.87329,50.00000,34.00000,1.720230e-08,0.78719,4
300.01901,1127.16083,      0.44360,     55.76530,50.00000,34.00000,1.715117e-08,0.78719,4
300.01700,1130.56083,      0.44190,     55.69688,50.00000,34.00000,1.714534e-08,0.78720,4
300.01599,1133.96083,      0.44341,     55.58441,50.00000,34.00000,1.714938e-08,0.78720,4
300.00699,1137.36083,      0.44359,     55.48967,50.00000,34.00000,1.713776e-08,0.78719,4
300.01199,1140.76083,      0.44756,     55.40136,50.00000,34.00000,1.717368e-08,0.78719,4
300.01801,1144.16083,      0.44247,     55.30429,50.00000,34.00000,1.718848e-08,0.78719,4
300.01501,1147.56083,      0.44379,     55.20955,50.00000,34.00000,1.716883e-08,0.78718,4
300.03000,1150.96083,      0.44153,     55.11033,50.00000,34.00000,1.717595e-08,0.78719,4
300.01700,1154.36083,      0.44379,     55.01111,50.00000,34.00000,1.716062e-08,0.78718,4
300.01700,1157.76083,      0.44284,     54.93158,50.00000,34.00000,1.717914e-08,0.78719,4
300.02499,1161.16083,      0.44398,     54.79922,50.00000,34.00000,1.714216e-08,0.78719,4
300.01801,1164.56083,      0.44738,     54.71559,50.00000,34.00000,1.714858e-08,0.78719,4
300.01901,1167.96083,      0.44587,     54.63606,50.00000,34.00000,1.715800e-08,0.78719,4
300.02200,1171.36083,      0.44417,     54.54347,50.00000,34.00000,1.712578e-08,0.78719,4
300.01700,1174.76083,      0.44473,     54.45536,50.00000,34.00000,1.712598e-08,0.78719,4
300.01001,1178.16083,      0.44397,     54.36920,50.00000,34.00000,1.714419e-08,0.78719,4
300.02100,1181.56083,      0.44266,     54.25906,50.00000,34.00000,1.715754e-08,0.78720,4
300.00900,1184.96083,      0.44284,     54.16199,50.00000,34.00000,1.716851e-08,0.78718,4
300.01801,1188.36083,      0.44436,     54.07602,50.00000,34.00000,1.711517e-08,0.78719,4
300.02499,1191.76083,      0.44417,     54.00312,50.00000,34.00000,1.710975e-08,0.78720,4
300.01199,1195.16083,      0.44246,     53.87310,50.00000,34.00000,1.711435e-08,0.78719,4
300.01901,1198.56083,      0.44417,     53.81793,50.00000,34.00000,1.713645e-08,0.78720,4
300.00900,1201.96083,      0.44190,     53.72534,50.00000,34.00000,1.711421e-08,0.78720,4
300.01501,1205.36083,      0.44379,     53.61949,50.00000,34.00000,1.711410e-08,0.78719,4
300.02301,1208.76083,      0.44247,     53.50702,50.00000,34.00000,1.708146e-08,0.78718,4
300.01300,1212.16083,      0.44454,     53.41209,50.00000,34.00000,1.712325e-08,0.78720,4
300.01599,1215.56083,      0.44265,     53.32183,50.00000,34.00000,1.711548e-08,0.78719,4
300.00400,1218.96083,      0.44303,     53.19610,50.00000,34.00000,1.706890e-08,0.78719,4
300.02301,1222.36083,      0.44341,     53.12105,50.00000,34.00000,1.711573e-08,0.78719,4
300.02399,1225.76083,      0.44530,     53.06803,50.00000,34.00000,1.712046e-08,0.78719,4
300.01599,1229.16083,      0.44152,     52.94912,50.00000,34.00000,1.711585e-08,0.78719,4
300.01300,1232.56083,      0.44190,     52.85634,50.00000,34.00000,1.708638e-08,0.78719,4
300.01001,1235.96083,      0.44473,     52.76608,50.00000,34.00000,1.707095e-08,0.78718,4
300.01001,1239.36083,      0.44322,     52.66452,50.00000,34.00000,1.707903e-08,0.78718,4
300.01599,1242.76083,      0.44171,     52.58733,50.00000,34.00000,1.709264e-08,0.78718,4
300.00500,1246.16083,      0.44492,     52.47700,50.00000,34.00000,1.709595e-08,0.78719,4
300.00299,1249.56083,      0.44359,     52.41092,50.00000,34.00000,1.703802e-08,0.78718,4
300.01901,1252.96083,      0.44436,     52.31832,50.00000,34.00000,1.710914e-08,0.78719,4
300.01001,1256.36083,      0.44303,     52.26316,50.00000,34.00000,1.707459e-08,0.78721,4
300.04401,1257.10083,      0.46175,     52.09786,50.00000,50.00000,1.700247e-08,0.78720,5
300.30701,1257.27083,      0.65845,     52.08460,50.00000,50.00000,1.704314e-08,0.78719,5
301.04199,1257.44083,      1.12567,     52.11092,50.00000,50.00000,1.702207e-08,0.78720,5
302.35101,1257.61083,      1.85889,     52.21462,50.00000,50.00000,1.701111e-08,0.78720,5
304.27200,1257.78083,      2.76758,     52.36238,50.00000,50.00000,1.708181e-08,0.78720,5
306.70901,1257.95083,      3.73398,     52.53216,50.00000,50.00000,1.704338e-08,0.78719,5
309.53000,1258.12083,      4.63488,     52.66004,50.00000,50.00000,1.704036e-08,0.78719,5
312.59201,1258.29083,      5.38479,     52.80780,50.00000,50.00000,1.704017e-08,0.78720,5
315.69400,1258.46083,      5.92946,     52.94464,50.00000,50.00000,1.703303e-08,0.78721,5
318.79901,1258.63083,      6.27368,     52.96452,50.00000,50.00000,1.703097e-08,0.78719,5
321.81400,1258.80083,      6.45186,     53.00643,50.00000,50.00000,1.707178e-08,0.78719,5
324.72299,1258.97083,      6.51763,     53.01306,50.00000,50.00000,1.705589e-08,0.78719,5
327.59799,1259.14083,      6.53360,     53.03938,50.00000,50.00000,1.702889e-08,0.78720,5
330.44601,1259.31083,      6.55323,     53.08577,50.00000,50.00000,1.702240e-08,0.78720,5
333.34299,1259.48083,      6.61888,     53.11228,50.00000,50.00000,1.697933e-08,0.78719,5
336.34000,1259.65083,      6.75423,     53.20487,50.00000,50.00000,1.704013e-08,0.78719,5
339.44800,1259.82083,      6.95725,     53.23353,50.00000,50.00000,1.702814e-08,0.78719,5
342.71899,1259.99083,      7.21596,     53.31520,50.00000,50.00000,1.702554e-08,0.78719,5
346.11499,1260.16083,      7.50745,     53.38791,50.00000,50.00000,1.704478e-08,0.78720,5
349.63901,1260.33083,      7.80219,     53.44737,50.00000,50.00000,1.702849e-08,0.78719,5
353.23901,1260.50083,      8.07759,     53.47388,50.00000,50.00000,1.698836e-08,0.78720,5
356.90701,1260.67083,      8.31978,     53.47388,50.00000,50.00000,1.700702e-08,0.78719,5
360.58899,1260.84083,      8.53180,     53.41657,50.00000,50.00000,1.701329e-08,0.78719,5
364.30099,1261.01083,      8.82155,     53.42982,50.00000,50.00000,1.701133e-08,0.78719,5
367.97699,1261.18083,      8.91401,     53.31949,50.00000,50.00000,1.700731e-08,0.78719,5
371.67200,1261.35083,      9.26871,     53.20936,50.00000,50.00000,1.700005e-08,0.78720,5
375.34799,1261.52083,      9.30406,     52.97778,50.00000,50.00000,1.704784e-08,0.78720,5
379.04401,1261.69083,      9.47083,     52.74620,50.00000,50.00000,1.700931e-08,0.78720,5
382.72501,1261.86083,      9.45490,     52.33821,50.00000,50.00000,1.702510e-08,0.78719,5
386.43201,1262.03083,      9.82852,     51.89708,50.00000,50.00000,1.703785e-08,0.78720,5
390.14999,1262.20083,      9.72436,     51.30390,50.00000,50.00000,1.700520e-08,0.78720,5
393.87299,1262.37083,     10.19733,     50.54737,50.00000,50.00000,1.699704e-08,0.78719,5
397.61200,1262.54083,     10.41008,     49.63879,50.00000,50.00000,1.704802e-08,0.78719,5
401.34000,1262.71083,      9.89987,     48.48538,50.00000,50.00000,1.699221e-08,0.78719,5
405.07800,1262.88083,     10.36973,     47.04542,50.00000,50.00000,1.700584e-08,0.78720,5
408.79300,1263.05083,     11.37808,     45.26121,50.00000,50.00000,1.700979e-08,0.78719,5
412.53601,1263.22083,     11.13626,     43.08226,50.00000,50.00000,1.704849e-08,0.78719,5
416.23901,1263.39083,     11.31342,     40.53509,50.00000,50.00000,1.700280e-08,0.78720,5
419.92099,1263.56083,     11.72776,     37.30877,50.00000,50.00000,1.701783e-08,0.78720,5
423.62900,1263.73083,     12.27337,     33.71404,50.00000,50.00000,1.699260e-08,0.78720,5
427.28799,1263.90083,     12.87274,     29.62534,50.00000,50.00000,1.702320e-08,0.78720,5
430.94400,1264.07083,     13.49734,     25.01832,50.00000,50.00000,1.699691e-08,0.78719,5
434.58301,1264.24083,     14.46890,     20.14678,50.00000,50.00000,1.699977e-08,0.78720,5
438.22501,1264.41083,     14.42359,     15.32378,50.00000,50.00000,1.699882e-08,0.78720,5
441.86401,1264.58083,     14.14907,     10.80273,50.00000,50.00000,1.705902e-08,0.78720,5
445.49200,1264.75083,     13.71145,      6.85750,50.00000,50.00000,1.699590e-08,0.78721,5
449.11200,1264.92083,     13.21142,      3.67739,50.00000,50.00000,1.701758e-08,0.78720,5
452.73300,1265.09083,     12.70177,      1.42359,50.00000,50.00000,1.701753e-08,0.78719,5
456.34799,1265.26083,     12.23993,     -0.17544,50.00000,50.00000,1.701007e-08,0.78720,5
459.95801,1265.43083,     11.85575,     -1.11267,50.00000,50.00000,1.701177e-08,0.78719,5
463.57199,1265.60083,     11.55126,     -1.65731,50.00000,50.00000,1.702140e-08,0.78720,5
467.16699,1265.77083,     11.32420,     -1.95283,50.00000,50.00000,1.703133e-08,0.78719,5
470.75400,1265.94083,     11.15066,     -2.09844,50.00000,50.00000,1.701186e-08,0.78720,5
474.31900,1266.11083,     11.02575,     -2.18674,50.00000,50.00000,1.701780e-08,0.78719,5
477.87701,1266.28083,     10.92371,     -2.24834,50.00000,50.00000,1.699883e-08,0.78719,5
481.41901,1266.45083,     10.84643,     -2.26823,50.00000,50.00000,1.699196e-08,0.78720,5
484.95200,1266.62083,     10.78067,     -2.27037,50.00000,50.00000,1.699175e-08,0.78719,5
488.47900,1266.79083,     10.73145,     -2.24405,50.00000,50.00000,1.699175e-08,0.78719,5
492.00800,1266.96083,     10.69477,     -2.22417,50.00000,50.00000,1.701743e-08,0.78719,5
495.51199,1267.13083,     10.66212,     -2.19103,50.00000,50.00000,1.700048e-08,0.78719,5
499.01700,1267.30083,     10.63737,     -2.16452,50.00000,50.00000,1.699818e-08,0.78720,5
502.51099,1267.47083,     10.61504,     -2.13587,50.00000,50.00000,1.701415e-08,0.78719,5
505.99701,1267.64083,     10.59372,     -2.10955,50.00000,50.00000,1.701073e-08,0.78718,5
509.47400,1267.81083,     10.57765,     -2.04113,50.00000,50.00000,1.698182e-08,0.78718,5
512.94702,1267.98083,     10.56197,     -2.02339,50.00000,50.00000,1.697295e-08,0.78719,5
516.42700,1268.15083,     10.54910,     -1.99708,50.00000,50.00000,1.701343e-08,0.78719,5
519.89899,1268.32083,     10.53785,     -1.94405,50.00000,50.00000,1.700862e-08,0.78719,5
523.36401,1268.49083,     10.52500,     -1.91754,50.00000,50.00000,1.699296e-08,0.78720,5
526.83398,1268.66083,     10.51472,     -1.86238,50.00000,50.00000,1.698560e-08,0.78719,5
530.28400,1268.83083,     10.50139,     -1.86238,50.00000,50.00000,1.701322e-08,0.78719,5
533.72803,1269.00083,     10.48745,     -1.80955,50.00000,50.00000,1.705072e-08,0.78719,5
537.18103,1269.17083,     10.47720,     -1.78304,50.00000,50.00000,1.699496e-08,0.78719,5
540.61700,1269.34083,     10.46598,     -1.73684,50.00000,50.00000,1.701301e-08,0.78719,5
544.05200,1269.51083,     10.45837,     -1.70370,50.00000,50.00000,1.699815e-08,0.78720,5
547.49799,1269.68083,     10.45199,     -1.67719,50.00000,50.00000,1.703076e-08,0.78719,5
550.93701,1269.85083,     10.44531,     -1.67271,50.00000,50.00000,1.698666e-08,0.78719,5
554.38098,1270.02083,     10.43690,     -1.56472,50.00000,50.00000,1.697991e-08,0.78720,5
557.81598,1270.19083,     10.42869,     -1.57797,50.00000,50.00000,1.702625e-08,0.78720,5
561.24701,1270.36083,     10.42153,     -1.55146,50.00000,50.00000,1.699306e-08,0.78720,5
564.67401,1270.53083,     10.41252,     -1.52495,50.00000,50.00000,1.698298e-08,0.78719,5
568.10498,1270.70083,     10.39907,     -1.46998,50.00000,50.00000,1.699859e-08,0.78720,5
571.54602,1270.87083,     10.39245,     -1.41481,50.00000,50.00000,1.700545e-08,0.78720,5
574.96100,1271.04083,     10.37886,     -1.41481,50.00000,50.00000,1.703623e-08,0.78719,5
578.39502,1271.21083,     10.37011,     -1.36179,50.00000,50.00000,1.699827e-08,0.78719,5
581.81299,1271.38083,     10.36340,     -1.36179,50.00000,50.00000,1.700869e-08,0.78719,5
585.25299,1271.55083,     10.35866,     -1.33548,50.00000,50.00000,1.698941e-08,0.78720,5
588.66998,1271.72083,     10.34967,     -1.28246,50.00000,50.00000,1.698700e-08,0.78718,5
592.08801,1271.89083,     10.34158,     -1.27583,50.00000,50.00000,1.695917e-08,0.78720,5
595.51898,1272.06083,     10.33208,     -1.22300,50.00000,50.00000,1.696227e-08,0.78720,5
598.93799,1272.23083,     10.32362,     -1.19649,50.00000,50.00000,1.700569e-08,0.78719,5
602.37201,1272.40083,     10.31571,     -1.16784,50.00000,50.00000,1.700675e-08,0.78720,5
605.78101,1272.57083,     10.30651,     -1.13918,50.00000,50.00000,1.699032e-08,0.78719,5
609.20203,1272.74083,     10.29726,     -1.08616,50.00000,50.00000,1.701182e-08,0.78719,5
612.62299,1272.91083,     10.29317,     -1.05965,50.00000,50.00000,1.699102e-08,0.78719,5
616.04901,1273.08083,     10.28928,     -1.03333,50.00000,50.00000,1.701845e-08,0.78719,5
619.46997,1273.25083,     10.28436,     -1.00468,50.00000,50.00000,1.700409e-08,0.78720,5
622.89697,1273.42083,     10.27796,     -0.98480,50.00000,50.00000,1.697920e-08,0.78719,5
626.30798,1273.59083,     10.27098,     -0.95166,50.00000,50.00000,1.699695e-08,0.78718,5
629.72498,1273.76083,     10.26507,     -0.93177,50.00000,50.00000,1.697887e-08,0.78720,5
633.13397,1273.93083,     10.26153,     -0.89649,50.00000,50.00000,1.700403e-08,0.78719,5
636.55701,1274.10083,     10.26236,     -0.86784,50.00000,50.00000,1.702771e-08,0.78720,5
639.96802,1274.27083,     10.26704,     -0.84133,50.00000,50.00000,1.700031e-08,0.78719,5
643.38300,1274.44083,     10.27174,     -0.84133,50.00000,50.00000,1.700140e-08,0.78719,5
646.79498,1274.61083,     10.28161,     -0.78850,50.00000,50.00000,1.698007e-08,0.78719,5
650.21002,1274.78083,     10.29532,     -0.78850,50.00000,50.00000,1.699071e-08,0.78719,5
653.62000,1274.95083,     10.30699,     -0.73548,50.00000,50.00000,1.703046e-08,0.78719,5
657.02502,1275.12083,     10.32540,     -0.73548,50.00000,50.00000,1.699286e-08,0.78719,5
660.43402,1275.29083,     10.34601,     -0.68928,50.00000,50.00000,1.700680e-08,0.78719,5
663.84302,1275.46083,     10.36556,     -0.68265,50.00000,50.00000,1.698495e-08,0.78720,5
667.26001,1275.63083,     10.38560,     -0.62963,50.00000,50.00000,1.698175e-08,0.78720,5
670.67102,1275.80083,     10.40183,     -0.60312,50.00000,50.00000,1.701390e-08,0.78720,5
674.08099,1275.97083,     10.41727,     -0.60312,50.00000,50.00000,1.696297e-08,0.78719,5
677.49799,1276.14083,     10.43289,     -0.57680,50.00000,50.00000,1.698664e-08,0.78719,5
680.91602,1276.31083,     10.44562,     -0.55029,50.00000,50.00000,1.701520e-08,0.78720,5
684.32800,1276.48083,     10.44907,     -0.51053,50.00000,50.00000,1.696766e-08,0.78719,5
687.73901,1276.65083,     10.44802,     -0.47096,50.00000,50.00000,1.698654e-08,0.78719,5
691.15802,1276.82083,     10.44162,     -0.47096,50.00000,50.00000,1.696844e-08,0.78719,5
694.57599,1276.99083,     10.42700,     -0.47096,50.00000,50.00000,1.698134e-08,0.78719,5
697.99200,1277.16083,     10.40897,     -0.41579,50.00000,50.00000,1.697664e-08,0.78719,5
701.41602,1277.33083,     10.38331,     -0.38928,50.00000,50.00000,1.695812e-08,0.78720,5
704.82599,1277.50083,     10.35435,     -0.36277,50.00000,50.00000,1.700360e-08,0.78720,5
708.25000,1277.67083,     10.32295,     -0.34308,50.00000,50.00000,1.703227e-08,0.78721,5
711.66498,1277.84083,     10.28827,     -0.33645,50.00000,50.00000,1.698332e-08,0.78721,5
715.08600,1278.01083,     10.24794,     -0.30994,50.00000,50.00000,1.700234e-08,0.78720,5
718.50403,1278.18083,     10.19812,     -0.25692,50.00000,50.00000,1.696810e-08,0.78720,5
721.93903,1278.35083,     10.14077,     -0.25692,50.00000,50.00000,1.697048e-08,0.78719,5
725.35999,1278.52083,     10.07836,     -0.23060,50.00000,50.00000,1.701986e-08,0.78719,5
728.76898,1278.69083,     10.00556,     -0.21735,50.00000,50.00000,1.701070e-08,0.78718,5
732.19598,1278.86083,      9.93009,     -0.17758,50.00000,50.00000,1.698357e-08,0.78718,5
735.60999,1279.03083,      9.84788,     -0.15107,50.00000,50.00000,1.698858e-08,0.78720,5
739.03400,1279.20083,      9.75972,     -0.12456,50.00000,50.00000,1.694284e-08,0.78719,5
742.44299,1279.37083,      9.66217,     -0.12456,50.00000,50.00000,1.697803e-08,0.78719,5
745.86603,1279.54083,      9.56878,-6.959064e-02,50.00000,50.00000,1.694854e-08,0.78721,5
749.29401,1279.71083,      9.46866,-6.959064e-02,50.00000,50.00000,1.696889e-08,0.78719,5
752.70801,1279.88083,      9.36417,-2.982456e-02,50.00000,50.00000,1.697041e-08,0.78719,5
756.12701,1280.05083,      9.25479,-1.656920e-02,50.00000,50.00000,1.694383e-08,0.78718,5
759.54199,1280.22083,      9.14396,-1.656920e-02,50.00000,50.00000,1.696632e-08,0.78718,5
762.95502,1280.39083,      9.02459, 4.074074e-02,50.00000,50.00000,1.697465e-08,0.78719,5
766.36499,1280.56083,      8.90179, 6.725146e-02,50.00000,50.00000,1.701575e-08,0.78719,5
769.78601,1280.73083,      8.77727, 9.376218e-02,50.00000,50.00000,1.697815e-08,0.78719,5
773.20099,1280.90083,      8.65383, 7.387914e-02,50.00000,50.00000,1.699930e-08,0.78718,5
776.63702,1281.07083,      8.52778,      0.12904,50.00000,50.00000,1.700785e-08,0.78718,5
780.04401,1281.24083,      8.40134,      0.15536,50.00000,50.00000,1.701433e-08,0.78720,5
783.46600,1281.41083,      8.27418,      0.15536,50.00000,50.00000,1.697125e-08,0.78719,5
786.88202,1281.58083,      8.14551,      0.18187,50.00000,50.00000,1.695812e-08,0.78719,5
790.29303,1281.75083,      8.01233,      0.20838,50.00000,50.00000,            ,0.44878,5
793.71802,1281.92083,      7.88506,      0.20838,50.00000,50.00000,            ,0.44741,5
794.52698,1281.96083,      7.85586,      0.20838,50.00000,50.00000,            ,0.44708,5