File: data/TGA/005d-L_M/ExpDat_2025_03_08_SL_005F_J3_isothermal.csv
#EXPORTTYPE:                 ,DATA ALL
#FILE:                       ,2025_03_08_SL_005F_J3_isothermal.ngb-ss5
#FORMAT:                     ,NETZSCH5
#FTYPE:                      ,ASCII
#IDENTITY:                   ,2025_03_08_SL_005F_J3_i
#DECIMAL:                    ,POINT
#SEPARATOR:                  ,COMMA
#MTYPE:                      ,DSC
#INSTRUMENT:                 ,NETZSCH STA 449F5
#PROJECT:                    ,PS
#DATE/TIME:                  ,3/8/2025 5:04:34 PM (UTC-5)
#CORR. FILE:                 ,
#TEMPCAL:                    ,13-11-2024 10:37
#SENSITIVITY:                ,28-06-2023 13:53
#LABORATORY:                 ,Tran/Aspuru
#OPERATOR:                   ,Stanley
#REMARK:                     ,2025_03_08_SL_005F_J3_isothermal
#SAMPLE:                     ,2025_03_08_SL_005F_J3_i
#SAMPLE MASS /mg:            ,5.02
#MATERIAL:                   ,Polystyrene
#REFERENCE:                  ,
#REFERENCE MASS /mg:         ,0
#TYPE OF CRUCIBLE:           ,Al2O3 85 ‘l, open
#SAMPLE CRUCIBLE MASS /mg:   ,0
#REFERENCE CRUCIBLE MASS /mg:,0
#DSC RANGE /‘V:              ,5000
#TG RANGE /mg:               ,35000
#TAU-R:                      ,---
#CORR. CODE:                 ,000
#EXO:                        ,-1
#RANGE:                      ,30›C....800›C/0.0....20.0K/min
#SEGMENT:                    ,S1-5/5
#SEG. 1:                     ,30›C/10.0(K/min)/100›C
#SEG. 2:                     ,100›C/00:10/100›C
#SEG. 3:                     ,100›C/5.0(K/min)/300›C
#SEG. 4:                     ,300›C/20:00/300›C
#SEG. 5:                     ,300›C/20.0(K/min)/800›C

##Temp./›C,Time/min,DSC/(mW/mg),Mass/%,Gas Flow(purge2)/(ml/min),Gas Flow(protective)/(ml/min),TIC(scan:1)/A,Sensit./(uV/mW),Segment
 32.74000,   0.00000,      0.13273,100.00000,50.00000,50.00000,            ,0.92404,1
 35.43800,   1.32000,      0.30726,100.49143,50.00000,50.00000,2.045230e-10,0.92410,1
 41.40600,   2.64000,      0.70500,101.59801,50.00000,50.00000,2.053128e-10,0.92418,1
 50.28400,   3.96000,      1.11247,102.82849,50.00000,50.00000,2.047863e-10,0.92429,1
 62.49500,   5.28000,      1.59191,104.18068,50.00000,50.00000,2.048358e-10,0.92444,1
 77.13200,   6.60000,      1.98575,105.08665,50.00000,50.00000,2.046089e-10,0.92461,1
 87.33900,   7.46000,      2.10786,105.39542,50.00000,50.00000,2.051926e-10,0.92475,2
 93.83400,   8.12000,      1.77708,104.80498,50.00000,50.00000,2.047042e-10,0.92485,2
 98.50400,   8.78000,      1.28939,103.94402,50.00000,50.00000,2.047176e-10,0.92495,2
101.92400,   9.44000,      0.93033,103.42351,50.00000,50.00000,2.051296e-10,0.92504,2
104.72700,  10.10000,      0.72487,103.04701,50.00000,50.00000,2.048911e-10,0.92514,2
106.93300,  10.76000,      0.54993,102.58725,50.00000,50.00000,2.053795e-10,0.92524,2
108.49500,  11.42000,      0.35798,102.14781,50.00000,50.00000,2.052059e-10,0.92534,2
109.39200,  12.08000,      0.16994,101.71056,50.00000,50.00000,2.046452e-10,0.92544,2
109.80700,  12.74000, 2.316925e-02,101.25080,50.00000,50.00000,2.052363e-10,0.92553,2
109.85300,  13.40000,-9.003046e-02,100.90837,50.00000,50.00000,2.055568e-10,0.92562,2
109.61400,  14.06000,     -0.17674,100.57470,50.00000,50.00000,2.061691e-10,0.92571,2
109.14800,  14.72000,     -0.24174,100.26594,50.00000,50.00000,2.057094e-10,0.92580,2
108.53600,  15.38000,     -0.28966, 99.98207,50.00000,50.00000,2.055664e-10,0.92588,2
107.82600,  16.04000,     -0.32168, 99.74323,50.00000,50.00000,2.054119e-10,0.92596,2
107.05300,  16.70000,     -0.33996, 99.49303,50.00000,50.00000,2.061138e-10,0.92602,2
106.06100,  17.72000,     -0.27572, 99.40737,50.00000,50.00000,2.054672e-10,0.92611,3
107.33900,  19.04000,      0.16768,100.18267,50.00000,50.00000,2.058506e-10,0.92619,3
110.69200,  20.36000,      0.45458,100.74163,50.00000,50.00000,2.063313e-10,0.92620,3
115.76700,  21.68000,      0.74378,101.27112,50.00000,50.00000,2.064400e-10,0.92615,3
122.22400,  23.00000,      0.96374,101.73765,50.00000,50.00000,2.070790e-10,0.92602,3
129.52699,  24.32000,      1.10097,102.09382,50.00000,50.00000,2.062911e-10,0.92582,3
137.24500,  25.64000,      1.16956,102.23805,50.00000,50.00000,2.066555e-10,0.92553,3
145.05600,  26.96000,      1.18029,102.37311,50.00000,50.00000,2.070504e-10,0.92516,3
152.77100,  28.28000,      1.15447,102.45438,50.00000,50.00000,2.063312e-10,0.92469,3
160.27100,  29.60000,      1.11184,102.53546,50.00000,50.00000,2.074031e-10,0.92434,3
167.52499,  30.92000,      1.05635,102.53546,50.00000,50.00000,2.067986e-10,0.92404,3
174.58000,  32.24000,      1.00131,102.54223,50.00000,50.00000,2.069549e-10,0.92373,3
181.47900,  33.56000,      0.94896,102.52869,50.00000,50.00000,2.075290e-10,0.92342,3
188.26401,  34.88000,      0.90398,102.48147,50.00000,50.00000,2.068767e-10,0.92311,3
194.94200,  36.20000,      0.85951,102.46793,50.00000,50.00000,2.076797e-10,0.92281,3
201.57700,  37.52000,      0.82011,102.36653,50.00000,50.00000,2.082901e-10,0.92251,3
208.15601,  38.84000,      0.78829,102.28526,50.00000,50.00000,2.078610e-10,0.92223,3
214.73199,  40.16000,      0.76012,102.14104,50.00000,50.00000,2.072125e-10,0.92196,3
221.28200,  41.48000,      0.73137,101.99004,50.00000,50.00000,2.077236e-10,0.92171,3
227.85100,  42.80000,      0.68220,101.78725,50.00000,50.00000,2.077579e-10,0.92148,3
234.40800,  44.12000,      0.64654,101.56873,50.00000,50.00000,2.073136e-10,0.92122,3
240.95900,  45.44000,      0.61431,101.29821,50.00000,50.00000,2.083606e-10,0.92101,3
247.53900,  46.76000,      0.58048,100.98048,50.00000,50.00000,2.080402e-10,0.92081,3
254.10500,  48.08000,      0.54460,100.67171,50.00000,50.00000,2.076912e-10,0.92061,3
260.67599,  49.40000,      0.50774,100.32012,50.00000,50.00000,2.080059e-10,0.92042,3
267.25101,  50.72000,      0.47023, 99.88068,50.00000,50.00000,2.075653e-10,0.92024,3
273.81201,  52.04000,      0.42791, 99.41873,50.00000,50.00000,2.074814e-10,0.92006,3
280.39600,  53.36000,      0.38653, 98.89582,50.00000,50.00000,2.077141e-10,0.91988,3
286.96301,  54.68000,      0.34892, 98.22430,50.00000,50.00000,2.088699e-10,0.91971,3
293.52600,  56.00000,      0.31058, 97.42410,50.00000,50.00000,2.088833e-10,0.91956,3
301.44901,  57.80000,     -0.24387, 96.03147,50.00000,47.00000,2.086697e-10,0.91935,4
303.14499,  61.10000,     -1.28596, 92.80857,50.00000,47.00000,2.087364e-10,0.91902,4
302.01901,  64.40000,     -1.35681, 90.56175,50.00000,47.00000,2.087116e-10,0.91876,4
301.02100,  67.70000,     -1.30552, 88.85797,50.00000,47.00000,2.089844e-10,0.91856,4
300.47699,  71.00000,     -1.24422, 87.48327,50.00000,47.00000,2.089843e-10,0.91844,4
300.22000,  74.30000,     -1.20927, 86.20996,50.00000,47.00000,2.086506e-10,0.91836,4
300.09000,  77.60000,     -1.19113, 85.08307,50.00000,47.00000,2.086639e-10,0.91832,4
300.03500,  80.90000,     -1.18140, 84.02171,50.00000,47.00000,2.085953e-10,0.91833,4
300.01401,  84.20000,     -1.16998, 83.04124,50.00000,47.00000,2.092781e-10,0.91836,4
300.01999,  87.50000,     -1.16188, 82.13765,50.00000,47.00000,2.093067e-10,0.91842,4
300.01999,  90.80000,     -1.15531, 81.26534,50.00000,47.00000,2.094803e-10,0.91851,4
300.01300,  94.10000,     -1.16052, 80.40896,50.00000,47.00000,2.090072e-10,0.91861,4
300.00601,  97.40000,     -1.15587, 79.60219,50.00000,47.00000,2.094345e-10,0.91872,4
299.99701, 100.70000,     -1.15335, 78.84044,50.00000,47.00000,2.090435e-10,0.91885,4
300.00800, 104.00000,     -1.15568, 78.09900,50.00000,47.00000,2.093067e-10,0.91898,4
300.00299, 107.30000,     -1.15143, 77.37550,50.00000,47.00000,2.091217e-10,0.91911,4
299.99899, 110.60000,     -1.15393, 76.66793,50.00000,47.00000,2.092075e-10,0.91925,4
300.00601, 113.90000,     -1.15124, 76.03008,50.00000,47.00000,2.094517e-10,0.91944,4
300.00500, 117.20000,     -1.15201, 75.34721,50.00000,47.00000,2.094173e-10,0.91926,4
300.01700, 120.50000,     -1.14604, 74.72072,50.00000,47.00000,1.982078e-10,0.91882,4
300.01599, 123.80000,     -1.15357, 74.09641,50.00000,47.00000,1.973476e-10,0.91818,4
300.01199, 127.10000,     -1.14835, 73.52849,50.00000,47.00000,1.970120e-10,0.91732,4
300.01401, 130.40000,     -1.14951, 72.93367,50.00000,47.00000,1.975994e-10,0.91620,4
300.00101, 133.70000,     -1.14293, 72.33645,50.00000,47.00000,1.976833e-10,0.91485,4
300.00699, 137.00000,     -1.14970, 71.77749,50.00000,47.00000,1.976585e-10,0.91321,4
300.02200, 140.30000,     -1.14914, 71.21633,50.00000,47.00000,1.978435e-10,0.91144,4
300.00500, 143.60000,     -1.14661, 70.68446,50.00000,47.00000,1.971874e-10,0.90951,4
300.00900, 146.90000,     -1.15337, 70.15478,50.00000,47.00000,1.977196e-10,0.90744,4
300.02399, 150.20000,     -1.15184, 69.64104,50.00000,47.00000,1.974011e-10,0.90524,4
300.01599, 153.50000,     -1.15280, 69.09781,50.00000,47.00000,1.965351e-10,0.90294,4
300.02899, 156.80000,     -1.14838, 68.59761,50.00000,47.00000,1.975556e-10,0.90047,4
300.01999, 160.10000,     -1.15338, 68.11295,50.00000,47.00000,1.971378e-10,0.89804,4
300.02499, 163.40000,     -1.15764, 67.63068,50.00000,46.00000,1.972714e-10,0.89557,4
300.02200, 166.70000,     -1.15454, 67.14402,50.00000,46.00000,1.974583e-10,0.89307,4
300.01801, 170.00000,     -1.15396, 66.71116,50.00000,46.00000,1.976471e-10,0.89052,4
300.01300, 173.30000,     -1.15608, 66.19960,50.00000,46.00000,1.975212e-10,0.88796,4
300.00900, 176.60000,     -1.15588, 65.79402,50.00000,46.00000,1.986026e-10,0.88534,4
300.02200, 179.90000,     -1.15937, 65.30717,50.00000,46.00000,1.991806e-10,0.88256,4
300.00699, 183.20000,     -1.16012, 64.85418,50.00000,46.00000,1.987686e-10,0.87987,4
300.00500, 186.50000,     -1.15993, 64.41693,50.00000,46.00000,1.999511e-10,0.87713,4
300.01001, 189.80000,     -1.15916, 63.95717,50.00000,46.00000,1.995354e-10,0.87436,4
300.01300, 193.10000,     -1.16361, 63.52450,50.00000,46.00000,1.991920e-10,0.87153,4
300.01700, 196.40000,     -1.16091, 63.11892,50.00000,46.00000,1.993542e-10,0.86854,4
300.00000, 199.70000,     -1.16359, 62.68625,50.00000,46.00000,1.995773e-10,0.86562,4
300.00601, 203.00000,     -1.16167, 62.25120,50.00000,47.00000,1.998215e-10,0.86266,4
300.01401, 206.30000,     -1.16785, 61.84781,50.00000,47.00000,1.994267e-10,0.85964,4
300.00900, 209.60000,     -1.16592, 61.41056,50.00000,47.00000,1.995068e-10,0.85658,4
300.02600, 212.90000,     -1.16633, 61.02530,50.00000,47.00000,1.992378e-10,0.85349,4
300.01099, 216.20000,     -1.16689, 60.59263,50.00000,47.00000,1.999207e-10,0.85035,4
300.00900, 219.50000,     -1.16727, 60.21394,50.00000,47.00000,1.994800e-10,0.84700,4
300.01801, 222.80000,     -1.17288, 59.80817,50.00000,47.00000,1.997356e-10,0.84377,4
300.03201, 226.10000,     -1.17193, 59.44084,50.00000,47.00000,1.999321e-10,0.84049,4
300.03101, 229.40000,     -1.17483, 59.06912,50.00000,46.00000,2.000770e-10,0.83717,4
300.03201, 232.70000,     -1.17271, 58.70857,50.00000,46.00000,1.995678e-10,0.83383,4
300.03299, 236.00000,     -1.17850, 58.35697,50.00000,46.00000,1.994648e-10,0.83028,4
300.02399, 239.30000,     -1.17501, 58.00538,50.00000,46.00000,1.994667e-10,0.82683,4
300.02200, 242.60000,     -1.17636, 57.67171,50.00000,46.00000,1.995868e-10,0.82337,4
299.99899, 245.90000,     -1.18019, 57.29323,50.00000,46.00000,2.001400e-10,0.81985,4
300.01700, 249.20000,     -1.17809, 56.96873,50.00000,46.00000,2.003612e-10,0.81636,4
300.00000, 252.50000,     -1.18232, 56.63068,50.00000,46.00000,2.009258e-10,0.81262,4
299.98300, 255.80000,     -1.18268, 56.26554,50.00000,46.00000,2.015953e-10,0.80906,4
300.01099, 259.10000,     -1.17808, 55.92749,50.00000,46.00000,2.015553e-10,0.80544,4
300.00400, 262.40000,     -1.18136, 55.58267,50.00000,46.00000,2.011872e-10,0.80182,4
300.01501, 265.70000,     -1.18465, 55.25578,50.00000,46.00000,2.012958e-10,0.79817,4
300.01599, 269.00000,     -1.18504, 54.92908,50.00000,46.00000,2.014484e-10,0.79451,4
300.01700, 272.30000,     -1.18736, 54.60239,50.00000,46.00000,2.022381e-10,0.79063,4
300.03201, 275.60000,     -1.19008, 54.30259,50.00000,46.00000,2.019615e-10,0.78569,4
300.02200, 278.90000,     -1.19277, 54.00279,50.00000,46.00000,2.016926e-10,0.78430,4
300.01901, 282.20000,     -1.19528, 53.66474,50.00000,46.00000,2.017326e-10,0.78448,4
300.01801, 285.50000,     -1.19547, 53.36056,50.00000,46.00000,2.016296e-10,0.78515,4
300.01700, 288.80000,     -1.19643, 53.06753,50.00000,46.00000,2.022343e-10,0.78580,4
300.03299, 292.10000,     -1.19993, 52.76335,50.00000,46.00000,2.019024e-10,0.78630,4
300.03101, 295.40000,     -1.20012, 52.47928,50.00000,46.00000,2.021504e-10,0.78665,4
300.05899, 298.70000,     -1.20171, 52.18865,50.00000,46.00000,2.020187e-10,0.78686,4
300.02301, 302.00000,     -1.20339, 51.90458,50.00000,46.00000,2.024002e-10,0.78698,4
300.01099, 305.30000,     -1.20280, 51.60717,50.00000,46.00000,2.027759e-10,0.78707,4
300.01001, 308.60000,     -1.20434, 51.33665,50.00000,46.00000,2.014712e-10,0.78713,4
300.01300, 311.90000,     -1.20705, 51.05279,50.00000,46.00000,2.024402e-10,0.78717,4
300.01901, 315.20000,     -1.20744, 50.79143,50.00000,46.00000,2.030697e-10,0.78719,4
299.98901, 318.50000,     -1.20778, 50.50737,50.00000,46.00000,2.031879e-10,0.78720,4
300.00800, 321.80000,     -1.20511, 50.20757,50.00000,46.00000,2.034607e-10,0.78719,4
300.00900, 325.10000,     -1.20801, 49.97550,50.00000,46.00000,2.035808e-10,0.78719,4
300.00601, 328.40000,     -1.21012, 49.69163,50.00000,46.00000,2.035847e-10,0.78720,4
300.01300, 331.70000,     -1.21207, 49.42112,50.00000,46.00000,2.039375e-10,0.78719,4
300.03101, 335.00000,     -1.21228, 49.15737,50.00000,46.00000,2.035866e-10,0.78720,4
300.01401, 338.30000,     -1.21323, 48.87351,50.00000,46.00000,2.044678e-10,0.78720,4
300.00699, 341.60000,     -1.21495, 48.62789,50.00000,46.00000,2.040901e-10,0.78719,4
300.01300, 344.90000,     -1.21554, 48.38904,50.00000,46.00000,2.040062e-10,0.78721,4
300.03500, 348.20000,     -1.21943, 48.09143,50.00000,46.00000,2.028675e-10,0.78721,4
300.02100, 351.50000,     -1.22308, 47.84801,50.00000,46.00000,2.039432e-10,0.78720,4
300.03400, 354.80000,     -1.22194, 47.61813,50.00000,46.00000,2.033558e-10,0.78721,4
300.02802, 358.10000,     -1.22329, 47.37490,50.00000,46.00000,2.024135e-10,0.78721,4
300.02399, 361.40000,     -1.22482, 47.10896,50.00000,46.00000,2.030792e-10,0.78720,4
300.00800, 364.70000,     -1.22731, 46.86096,50.00000,46.00000,2.041263e-10,0.78720,4
300.00800, 368.00000,     -1.22885, 46.66255,50.00000,46.00000,2.030716e-10,0.78720,4
300.01599, 371.30000,     -1.22906, 46.41693,50.00000,46.00000,2.034836e-10,0.78721,4
300.01401, 374.60000,     -1.23234, 46.16016,50.00000,46.00000,2.043857e-10,0.78721,4
300.00400, 377.90000,     -1.23368, 45.91673,50.00000,46.00000,2.046204e-10,0.78719,4
300.01599, 381.20000,     -1.23447, 45.72510,50.00000,46.00000,2.047634e-10,0.78719,4
300.01001, 384.50000,     -1.23658, 45.47490,50.00000,46.00000,2.050438e-10,0.78719,4
300.00400, 387.80000,     -1.23715, 45.25857,50.00000,46.00000,2.054500e-10,0.78719,4
300.01099, 391.10000,     -1.23813, 45.02869,50.00000,46.00000,2.051697e-10,0.78719,4
300.01099, 394.40000,     -1.24064, 44.78526,50.00000,46.00000,2.053738e-10,0.78719,4
300.01901, 397.70000,     -1.24219, 44.56215,50.00000,46.00000,2.049427e-10,0.78719,4
300.02200, 401.00000,     -1.24278, 44.37072,50.00000,46.00000,2.053127e-10,0.78718,4
300.06601, 404.30000,     -1.24574, 44.15876,50.00000,46.00000,2.052154e-10,0.78719,4
300.05301, 407.60000,     -1.24746, 43.91534,50.00000,46.00000,2.043381e-10,0.78720,4
300.03299, 410.90000,     -1.25380, 43.72610,50.00000,46.00000,2.047119e-10,0.78719,4
300.03101, 414.20000,     -1.25573, 43.53685,50.00000,46.00000,2.052211e-10,0.78718,4
300.03400, 417.50000,     -1.25438, 43.31375,50.00000,46.00000,2.045632e-10,0.78719,4
300.02301, 420.80000,     -1.25900, 43.10418,50.00000,46.00000,2.045497e-10,0.78720,4
300.01801, 424.10000,     -1.26015, 42.93068,50.00000,46.00000,2.048340e-10,0.78719,4
300.00900, 427.40000,     -1.26245, 42.76155,50.00000,46.00000,2.053222e-10,0.78718,4
300.00699, 430.70000,     -1.26631, 42.52490,50.00000,46.00000,2.047653e-10,0.78719,4
300.00101, 434.00000,     -1.26919, 42.32211,50.00000,46.00000,2.055206e-10,0.78718,4
300.00201, 437.30000,     -1.26784, 42.13964,50.00000,46.00000,2.062092e-10,0.78718,4
299.99799, 440.60000,     -1.27324, 41.92988,50.00000,46.00000,2.055549e-10,0.78718,4
299.99899, 443.90000,     -1.27460, 41.72709,50.00000,46.00000,2.064495e-10,0.78719,4
300.00201, 447.20000,     -1.27595, 41.55817,50.00000,46.00000,2.065124e-10,0.78718,4
300.01199, 450.50000,     -1.27906, 41.38904,50.00000,46.00000,2.068901e-10,0.78719,4
300.01300, 453.80000,     -1.28002, 41.18625,50.00000,46.00000,2.066326e-10,0.78719,4
300.01401, 457.10000,     -1.28176, 41.00139,50.00000,46.00000,2.070884e-10,0.78719,4
300.03299, 460.40000,     -1.28469, 40.81892,50.00000,46.00000,2.070789e-10,0.78719,4
300.04401, 463.70000,     -1.28779, 40.64303,50.00000,46.00000,2.066536e-10,0.78719,4
300.04300, 467.00000,     -1.29165, 40.48088,50.00000,46.00000,2.077007e-10,0.78720,4
300.03400, 470.30000,     -1.29415, 40.30060,50.00000,46.00000,2.063827e-10,0.78720,4
300.01901, 473.60000,     -1.29393, 40.13825,50.00000,46.00000,2.057285e-10,0.78719,4
300.02399, 476.90000,     -1.29587, 39.95578,50.00000,46.00000,2.060699e-10,0.78720,4
300.01700, 480.20000,     -1.29857, 39.79343,50.00000,46.00000,2.065926e-10,0.78720,4
300.01401, 483.50000,     -1.29953, 39.64482,50.00000,45.00000,2.068901e-10,0.78720,4
300.01599, 486.80000,     -1.29876, 39.45100,50.00000,45.00000,2.072849e-10,0.78720,4
300.00101, 490.10000,     -1.30279, 39.32689,50.00000,46.00000,2.076359e-10,0.78720,4
300.00299, 493.40000,     -1.30298, 39.13088,50.00000,46.00000,2.074489e-10,0.78720,4
300.00699, 496.70000,     -1.30376, 38.98884,50.00000,46.00000,2.087498e-10,0.78720,4
300.00800, 500.00000,     -1.30608, 38.81315,50.00000,46.00000,2.076740e-10,0.78719,4
300.00800, 503.30000,     -1.30666, 38.65757,50.00000,46.00000,2.083797e-10,0.78719,4
300.01401, 506.60000,     -1.30821, 38.48187,50.00000,46.00000,2.086411e-10,0.78720,4
300.01099, 509.90000,     -1.31110, 38.35339,50.00000,46.00000,2.087594e-10,0.78720,4
300.02301, 513.20000,     -1.31383, 38.18446,50.00000,46.00000,2.083816e-10,0.78720,4
300.00500, 516.50000,     -1.31554, 38.02888,50.00000,46.00000,2.087192e-10,0.78719,4
300.02499, 519.80000,     -1.31924, 37.85976,50.00000,46.00000,2.085724e-10,0.78719,4
300.03500, 523.10000,     -1.32215, 37.71793,50.00000,46.00000,2.082538e-10,0.78720,4
300.04800, 526.40000,     -1.32642, 37.55558,50.00000,46.00000,2.079868e-10,0.78719,4
300.04001, 529.70000,     -1.32872, 37.41355,50.00000,46.00000,2.078266e-10,0.78718,4
300.02701, 533.00000,     -1.33121, 37.28506,50.00000,46.00000,2.076702e-10,0.78719,4
300.01001, 536.30000,     -1.33369, 37.16116,50.00000,46.00000,2.077389e-10,0.78720,4
300.00699, 539.60000,     -1.33697, 36.99900,50.00000,46.00000,2.076149e-10,0.78720,4
300.02399, 542.90000,     -1.33642, 36.87052,50.00000,46.00000,2.082729e-10,0.78718,4
300.01199, 546.20000,     -1.34045, 36.73526,50.00000,46.00000,2.075634e-10,0.78719,4
300.00101, 549.50000,     -1.34179, 36.61355,50.00000,46.00000,2.077160e-10,0.78718,4
300.00699, 552.80000,     -1.34527, 36.45139,50.00000,46.00000,2.081127e-10,0.78717,4
300.00601, 556.10000,     -1.34585, 36.31614,50.00000,46.00000,2.091045e-10,0.78717,4
300.00201, 559.40000,     -1.34565, 36.18088,50.00000,46.00000,2.093086e-10,0.78718,4
300.00900, 562.70000,     -1.34875, 36.00498,50.00000,46.00000,2.096691e-10,0.78718,4
300.01001, 566.00000,     -1.35068, 35.91036,50.00000,46.00000,2.100144e-10,0.78717,4
299.99899, 569.30000,     -1.35298, 35.74821,50.00000,46.00000,2.099685e-10,0.78718,4
300.01801, 572.60000,     -1.35340, 35.64004,50.00000,46.00000,2.096252e-10,0.78717,4
300.02701, 575.90000,     -1.35631, 35.47769,50.00000,46.00000,2.097320e-10,0.78718,4
300.03500, 579.20000,     -1.35980, 35.34920,50.00000,46.00000,2.085113e-10,0.78720,4
300.04401, 582.50000,     -1.36174, 35.20737,50.00000,46.00000,2.093564e-10,0.78720,4
300.03601, 585.80000,     -1.36733, 35.10359,50.00000,46.00000,2.099494e-10,0.78721,4
300.01599, 589.10000,     -1.36710, 34.98865,50.00000,46.00000,2.092877e-10,0.78720,4
300.02399, 592.40000,     -1.36827, 34.85339,50.00000,46.00000,2.081451e-10,0.78720,4
300.01401, 595.70000,     -1.37347, 34.74522,50.00000,46.00000,2.084332e-10,0.78721,4
300.02399, 599.00000,     -1.37271, 34.63028,50.00000,46.00000,2.080250e-10,0.78721,4
300.00800, 602.30000,     -1.37404, 34.51534,50.00000,46.00000,2.083798e-10,0.78721,4
300.02600, 605.60000,     -1.37542, 34.40040,50.00000,46.00000,2.089309e-10,0.78721,4
300.01401, 608.90000,     -1.38139, 34.27191,50.00000,45.00000,2.086620e-10,0.78719,4
300.00900, 612.20000,     -1.38176, 34.17729,50.00000,45.00000,2.089825e-10,0.78720,4
299.99399, 615.50000,     -1.38464, 34.05558,50.00000,45.00000,2.092456e-10,0.78719,4
299.99701, 618.80000,     -1.38638, 33.94741,50.00000,45.00000,2.095890e-10,0.78721,4
299.99600, 622.10000,     -1.38657, 33.83247,50.00000,46.00000,2.104987e-10,0.78719,4
300.01099, 625.40000,     -1.39065, 33.69741,50.00000,46.00000,2.103882e-10,0.78719,4
300.01501, 628.70000,     -1.39355, 33.57570,50.00000,46.00000,2.107067e-10,0.78718,4
300.01599, 632.00000,     -1.39297, 33.45398,50.00000,46.00000,2.103328e-10,0.78719,4
300.00601, 635.30000,     -1.39411, 33.33904,50.00000,46.00000,2.101611e-10,0.78719,4
300.02600, 638.60000,     -1.39646, 33.24442,50.00000,46.00000,1.885815e-10,0.78719,4
300.03799, 641.90000,     -1.40073, 33.12948,50.00000,46.00000,1.872139e-10,0.78718,4
300.04001, 645.20000,     -1.40363, 33.01454,50.00000,46.00000,1.869945e-10,0.78720,4
300.03000, 648.50000,     -1.40728, 32.90637,50.00000,46.00000,1.870575e-10,0.78719,4
300.02200, 651.80000,     -1.40708, 32.83865,50.00000,46.00000,1.862640e-10,0.78719,4
300.01001, 655.10000,     -1.40899, 32.71016,50.00000,46.00000,1.862831e-10,0.78719,4
300.02399, 658.40000,     -1.40959, 32.55916,50.00000,46.00000,1.868171e-10,0.78718,4
300.00699, 661.70000,     -1.41149, 32.51195,50.00000,45.00000,1.859017e-10,0.78717,4
300.01599, 665.00000,     -1.41267, 32.43745,50.00000,45.00000,1.867256e-10,0.78719,4
300.02301, 668.30000,     -1.41538, 32.31574,50.00000,45.00000,1.860600e-10,0.78717,4
300.01199, 671.60000,     -1.41826, 32.22789,50.00000,45.00000,1.881027e-10,0.78719,4
299.99899, 674.90000,     -1.41959, 32.11295,50.00000,45.00000,1.865768e-10,0.78718,4
299.99899, 678.20000,     -1.42055, 32.00478,50.00000,45.00000,1.877651e-10,0.78719,4
300.00000, 681.50000,     -1.42229, 31.91693,50.00000,46.00000,1.873112e-10,0.78719,4
300.01599, 684.80000,     -1.42000, 31.80876,50.00000,46.00000,1.881504e-10,0.78719,4
300.00000, 688.10000,     -1.42306, 31.65996,50.00000,46.00000,1.886635e-10,0.78719,4
300.01501, 691.40000,     -1.42270, 31.57888,50.00000,46.00000,1.883220e-10,0.78720,4
299.99899, 694.70000,     -1.42557, 31.49781,50.00000,46.00000,1.878033e-10,0.78719,4
300.01501, 698.00000,     -1.42676, 31.37610,50.00000,46.00000,1.880245e-10,0.78719,4
300.02301, 701.30000,     -1.42967, 31.30159,50.00000,46.00000,1.874065e-10,0.78720,4
300.03699, 704.60000,     -1.43162, 31.20020,50.00000,46.00000,1.874447e-10,0.78719,4
300.03201, 707.90000,     -1.43432, 31.12590,50.00000,46.00000,1.878585e-10,0.78720,4
300.04099, 711.20000,     -1.43800, 30.95020,50.00000,46.00000,1.872387e-10,0.78722,4
300.01901, 714.50000,     -1.43854, 30.93665,50.00000,46.00000,1.873093e-10,0.78720,4
300.01999, 717.80000,     -1.44105, 30.82849,50.00000,46.00000,1.871472e-10,0.78720,4
300.00900, 721.10000,     -1.44084, 30.73367,50.00000,45.00000,1.868896e-10,0.78719,4
300.01700, 724.40000,     -1.44240, 30.65259,50.00000,45.00000,1.871624e-10,0.78719,4
300.02301, 727.70000,     -1.44434, 30.57151,50.00000,45.00000,1.877803e-10,0.78719,4
299.99701, 731.00000,     -1.44603, 30.47689,50.00000,45.00000,1.872558e-10,0.78719,4
299.99701, 734.30000,     -1.44970, 30.38227,50.00000,45.00000,1.882572e-10,0.78720,4
300.00299, 737.60000,     -1.44971, 30.30100,50.00000,46.00000,1.886845e-10,0.78720,4
300.00201, 740.90000,     -1.45068, 30.22669,50.00000,46.00000,1.889820e-10,0.78720,4
300.00800, 744.20000,     -1.45184, 30.10498,50.00000,46.00000,1.885948e-10,0.78720,4
300.01401, 747.50000,     -1.45185, 30.01713,50.00000,46.00000,1.890602e-10,0.78719,4
300.00900, 750.80000,     -1.45513, 29.91335,50.00000,46.00000,1.894951e-10,0.78718,4
300.03000, 754.10000,     -1.45710, 29.85936,50.00000,46.00000,1.893539e-10,0.78717,4
300.03500, 757.40000,     -1.46097, 29.74442,50.00000,46.00000,1.888618e-10,0.78717,4
300.02899, 760.70000,     -1.46289, 29.63625,50.00000,46.00000,1.890735e-10,0.78718,4
300.02802, 764.00000,     -1.46810, 29.56853,50.00000,46.00000,1.884574e-10,0.78717,4
300.01999, 767.30000,     -1.46885, 29.48068,50.00000,46.00000,1.881808e-10,0.78717,4
300.02399, 770.60000,     -1.47137, 29.39960,50.00000,46.00000,1.882954e-10,0.78718,4
300.01700, 773.90000,     -1.47271, 29.33207,50.00000,46.00000,1.886577e-10,0.78719,4
300.02600, 777.20000,     -1.47601, 29.24402,50.00000,46.00000,1.882038e-10,0.78719,4
300.01300, 780.50000,     -1.47734, 29.19004,50.00000,45.00000,1.880512e-10,0.78720,4
300.00800, 783.80000,     -1.47945, 29.08187,50.00000,45.00000,1.883335e-10,0.78719,4
300.01999, 787.10000,     -1.47986, 29.00737,50.00000,45.00000,1.885433e-10,0.78720,4
300.00601, 790.40000,     -1.48370, 28.92629,50.00000,45.00000,1.890622e-10,0.78719,4
300.01300, 793.70000,     -1.48622, 28.85199,50.00000,45.00000,1.896000e-10,0.78719,4
300.00500, 797.00000,     -1.48852, 28.75060,50.00000,45.00000,1.891251e-10,0.78721,4
300.00900, 800.30000,     -1.48872, 28.66932,50.00000,46.00000,1.897182e-10,0.78720,4
300.00900, 803.60000,     -1.49007, 28.59721,50.00000,46.00000,1.902618e-10,0.78720,4
300.01001, 806.90000,     -1.49394, 28.52072,50.00000,46.00000,1.909294e-10,0.78720,4
299.99301, 810.20000,     -1.49140, 28.43944,50.00000,46.00000,1.903991e-10,0.78720,4
300.02701, 813.50000,     -1.49609, 28.35378,50.00000,46.00000,1.903648e-10,0.78721,4
300.03799, 816.80000,     -1.49997, 28.24343,50.00000,46.00000,1.901321e-10,0.78720,4
300.03500, 820.10000,     -1.50228, 28.20060,50.00000,46.00000,1.902104e-10,0.78720,4
300.02499, 823.40000,     -1.50516, 28.13307,50.00000,46.00000,1.902465e-10,0.78720,4
300.03201, 826.70000,     -1.50652, 28.06315,50.00000,46.00000,1.900996e-10,0.78719,4
300.01300, 830.00000,     -1.50900, 28.01135,50.00000,46.00000,1.898422e-10,0.78720,4
300.02802, 833.30000,     -1.51115, 27.92570,50.00000,46.00000,1.902504e-10,0.78720,4
300.02301, 836.60000,     -1.51442, 27.89422,50.00000,46.00000,1.900196e-10,0.78719,4
300.01999, 839.90000,     -1.51596, 27.79044,50.00000,45.00000,1.903801e-10,0.78719,4
300.01700, 843.20000,     -1.51596, 27.71833,50.00000,45.00000,1.904812e-10,0.78718,4
300.02301, 846.50000,     -1.51906, 27.64402,50.00000,45.00000,1.910648e-10,0.78718,4
300.01199, 849.80000,     -1.52058, 27.58307,50.00000,45.00000,1.906319e-10,0.78717,4
300.00201, 853.10000,     -1.52365, 27.51554,50.00000,45.00000,1.908245e-10,0.78717,4
300.01001, 856.40000,     -1.52502, 27.44343,50.00000,45.00000,1.912041e-10,0.78718,4
299.99600, 859.70000,     -1.52557, 27.34203,50.00000,45.00000,1.924572e-10,0.78719,4
300.00400, 863.00000,     -1.52733, 27.29462,50.00000,46.00000,1.920605e-10,0.78718,4
300.01001, 866.30000,     -1.52849, 27.20677,50.00000,46.00000,1.926117e-10,0.78718,4
299.99799, 869.60000,     -1.52886, 27.15259,50.00000,46.00000,1.920776e-10,0.78720,4
300.02499, 872.90000,     -1.53122, 27.07151,50.00000,46.00000,1.925202e-10,0.78719,4
300.03900, 876.20000,     -1.53627, 27.01076,50.00000,46.00000,1.926689e-10,0.78720,4
300.02600, 879.50000,     -1.53914, 26.95219,50.00000,46.00000,1.923523e-10,0.78719,4
300.03299, 882.80000,     -1.54051, 26.87092,50.00000,45.00000,1.923084e-10,0.78720,4
300.02399, 886.10000,     -1.54281, 26.79661,50.00000,45.00000,1.922226e-10,0.78719,4
300.01401, 889.40000,     -1.54356, 26.73566,50.00000,45.00000,1.921673e-10,0.78718,4
300.02899, 892.70000,     -1.54378, 26.70876,50.00000,45.00000,1.922283e-10,0.78721,4
300.02499, 896.00000,     -1.54744, 26.60956,50.00000,45.00000,1.928101e-10,0.78720,4
300.02600, 899.30000,     -1.54899, 26.57131,50.00000,45.00000,1.922646e-10,0.78721,4
300.01099, 902.60000,     -1.55147, 26.51036,50.00000,45.00000,1.922950e-10,0.78720,4
300.00900, 905.90000,     -1.55224, 26.44502,50.00000,45.00000,1.925717e-10,0.78721,4
300.01801, 909.20000,     -1.55689, 26.34821,50.00000,45.00000,1.927776e-10,0.78720,4
300.01599, 912.50000,     -1.55785, 26.31653,50.00000,45.00000,1.925544e-10,0.78720,4
300.00601, 915.80000,     -1.56266, 26.22869,50.00000,45.00000,1.926574e-10,0.78720,4
300.02701, 919.10000,     -1.56251, 26.14522,50.00000,45.00000,1.925603e-10,0.78719,4
300.02100, 922.40000,     -1.56249, 26.09343,50.00000,45.00000,1.929607e-10,0.78720,4
300.00800, 925.70000,     -1.56730, 25.99880,50.00000,45.00000,1.924839e-10,0.78721,4
300.02499, 929.00000,     -1.57003, 25.93805,50.00000,45.00000,1.931782e-10,0.78719,4
300.00900, 932.30000,     -1.57367, 25.88845,50.00000,45.00000,1.927909e-10,0.78719,4
300.02701, 935.60000,     -1.57467, 25.86594,50.00000,45.00000,1.923866e-10,0.78718,4
300.02600, 938.90000,     -1.57911, 25.75538,50.00000,45.00000,1.926060e-10,0.78717,4
300.02200, 942.20000,     -1.58103, 25.68785,50.00000,45.00000,1.925583e-10,0.78716,4
300.01199, 945.50000,     -1.57927, 25.60657,50.00000,45.00000,1.923676e-10,0.78715,4
300.01001, 948.80000,     -1.58332, 25.55259,50.00000,45.00000,1.922817e-10,0.78718,4
300.02899, 952.10000,     -1.58645, 25.52112,50.00000,45.00000,1.926022e-10,0.78718,4
300.01099, 955.40000,     -1.58835, 25.46016,50.00000,45.00000,1.926251e-10,0.78720,4
300.01599, 958.70000,     -1.59106, 25.38586,50.00000,45.00000,1.926060e-10,0.78719,4
300.02100, 962.00000,     -1.59493, 25.33845,50.00000,45.00000,1.930065e-10,0.78718,4
300.00500, 965.30000,     -1.59586, 25.26633,50.00000,45.00000,1.925907e-10,0.78718,4
300.02499, 968.60000,     -1.59822, 25.20319,50.00000,45.00000,1.930084e-10,0.78719,4
300.01999, 971.90000,     -1.59918, 25.15598,50.00000,45.00000,1.925011e-10,0.78719,4
300.02600, 975.20000,     -1.59957, 25.07928,50.00000,45.00000,1.934433e-10,0.78719,4
300.00601, 978.50000,     -1.60127, 25.02291,50.00000,45.00000,1.929340e-10,0.78720,4
300.01300, 981.80000,     -1.60592, 24.91932,50.00000,44.00000,1.936283e-10,0.78719,4
300.02600, 985.10000,     -1.60652, 24.87649,50.00000,44.00000,1.933651e-10,0.78721,4
300.01999, 988.40000,     -1.60613, 24.78187,50.00000,44.00000,1.941071e-10,0.78720,4
300.00601, 991.70000,     -1.60398, 24.70060,50.00000,44.00000,1.938095e-10,0.78721,4
300.01801, 995.00000,     -1.60631, 24.70060,50.00000,44.00000,1.941109e-10,0.78721,4
300.01099, 998.30000,     -1.60727, 24.60598,50.00000,44.00000,1.949825e-10,0.78719,4
300.01801,1001.60000,     -1.60882, 24.54960,50.00000,44.00000,1.941681e-10,0.78720,4
300.00699,1004.90000,     -1.60765, 24.49343,50.00000,44.00000,1.943455e-10,0.78720,4
300.00699,1008.20000,     -1.60996, 24.43924,50.00000,45.00000,1.950073e-10,0.78719,4
300.01099,1011.50000,     -1.61036, 24.34243,50.00000,44.00000,1.952133e-10,0.78721,4
300.02200,1014.80000,     -1.60980, 24.28147,50.00000,44.00000,1.948986e-10,0.78720,4
300.00101,1018.10000,     -1.61169, 24.20259,50.00000,45.00000,1.949272e-10,0.78720,4
300.01401,1021.40000,     -1.61055, 24.19363,50.00000,45.00000,1.956653e-10,0.78719,4
300.01300,1024.70000,     -1.61403, 24.11474,50.00000,45.00000,1.964016e-10,0.78719,4
300.02899,1028.00000,     -1.61522, 24.05398,50.00000,45.00000,1.946811e-10,0.78719,4
300.02200,1031.30000,     -1.61520, 24.00876,50.00000,45.00000,1.955967e-10,0.78718,4
300.01999,1034.60000,     -1.61559, 23.95478,50.00000,45.00000,1.958408e-10,0.78717,4
300.02100,1037.90000,     -1.61790, 23.85100,50.00000,45.00000,1.956138e-10,0.78717,4
300.00699,1041.20000,     -1.61904, 23.77669,50.00000,45.00000,1.948738e-10,0.78718,4
300.00900,1044.50000,     -1.62097, 23.72251,50.00000,45.00000,1.956672e-10,0.78718,4
300.01401,1047.80000,     -1.62233, 23.68645,50.00000,45.00000,1.961307e-10,0.78718,4
300.00900,1051.10000,     -1.62116, 23.57151,50.00000,45.00000,1.955242e-10,0.78718,4
300.01099,1054.40000,     -1.62291, 23.54681,50.00000,45.00000,1.959095e-10,0.78718,4
300.01501,1057.70000,     -1.62562, 23.48367,50.00000,45.00000,1.960297e-10,0.78719,4
300.01300,1061.00000,     -1.62445, 23.40936,50.00000,45.00000,1.952591e-10,0.78719,4
300.01801,1064.30000,     -1.62504, 23.34622,50.00000,45.00000,1.964321e-10,0.78719,4
300.01501,1067.60000,     -1.62504, 23.32590,50.00000,45.00000,1.963596e-10,0.78718,4
300.02100,1070.90000,     -1.62679, 23.25618,50.00000,45.00000,1.968956e-10,0.78719,4
300.02399,1074.20000,     -1.62737, 23.17729,50.00000,45.00000,1.969185e-10,0.78719,4
300.01401,1077.50000,     -1.62890, 23.13665,50.00000,45.00000,1.962089e-10,0.78719,4
300.02200,1080.80000,     -1.62872, 23.06912,50.00000,45.00000,1.971378e-10,0.78720,4
299.99799,1084.10000,     -1.62964, 22.99462,50.00000,45.00000,1.970654e-10,0.78720,4
300.00900,1087.40000,     -1.63333, 22.94283,50.00000,45.00000,1.973381e-10,0.78720,4
300.01001,1090.70000,     -1.63333, 22.88426,50.00000,45.00000,1.967812e-10,0.78720,4
300.02200,1094.00000,     -1.63374, 22.83685,50.00000,45.00000,1.967926e-10,0.78721,4
300.00900,1097.30000,     -1.63564, 22.77390,50.00000,45.00000,1.973667e-10,0.78721,4
300.00800,1100.60000,     -1.63448, 22.70618,50.00000,45.00000,1.974754e-10,0.78721,4
300.00299,1103.90000,     -1.63660, 22.63406,50.00000,45.00000,1.977062e-10,0.78720,4
300.01599,1107.20000,     -1.63604, 22.58008,50.00000,45.00000,1.973342e-10,0.78720,4
300.01599,1110.50000,     -1.63682, 22.53486,50.00000,45.00000,1.980114e-10,0.78721,4
300.00400,1113.80000,     -1.63892, 22.46275,50.00000,45.00000,1.975174e-10,0.78721,4
300.01199,1117.10000,     -1.63719, 22.38625,50.00000,45.00000,1.978493e-10,0.78719,4
300.02301,1120.40000,     -1.63895, 22.36594,50.00000,45.00000,1.980629e-10,0.78720,4
300.01401,1123.70000,     -1.64145, 22.29143,50.00000,45.00000,1.976605e-10,0.78718,4
300.01001,1127.00000,     -1.63873, 22.23745,50.00000,45.00000,1.984444e-10,0.78717,4
300.01599,1130.30000,     -1.64203, 22.19004,50.00000,45.00000,1.977806e-10,0.78718,4
299.99799,1133.60000,     -1.64064, 22.12470,50.00000,45.00000,1.975117e-10,0.78718,4
300.01401,1136.90000,     -1.64280, 22.07291,50.00000,46.00000,1.985588e-10,0.78717,4
300.01199,1140.20000,     -1.64260, 22.02789,50.00000,46.00000,1.978112e-10,0.78718,4
300.02200,1143.50000,     -1.64223, 21.94681,50.00000,46.00000,1.985645e-10,0.78719,4
300.01401,1146.80000,     -1.64492, 21.90618,50.00000,46.00000,1.988431e-10,0.78718,4
300.01700,1150.10000,     -1.64647, 21.84084,50.00000,46.00000,1.986256e-10,0.78718,4
300.00601,1153.40000,     -1.64761, 21.77550,50.00000,46.00000,1.986789e-10,0.78719,4
300.00800,1156.70000,     -1.64626, 21.74841,50.00000,46.00000,1.991901e-10,0.78719,4
300.01300,1160.00000,     -1.64975, 21.66733,50.00000,46.00000,1.999417e-10,0.78719,4
300.01300,1163.30000,     -1.64743, 21.63127,50.00000,46.00000,1.991825e-10,0.78719,4
300.00800,1166.60000,     -1.64761, 21.55000,50.00000,46.00000,1.987591e-10,0.78720,4
300.01501,1169.90000,     -1.64743, 21.48705,50.00000,46.00000,1.996441e-10,0.78719,4
300.01099,1173.20000,     -1.64858, 21.45319,50.00000,46.00000,1.999779e-10,0.78719,4
300.01700,1176.50000,     -1.64782, 21.41036,50.00000,46.00000,2.004700e-10,0.78719,4
300.00800,1179.80000,     -1.64916, 21.35618,50.00000,46.00000,1.995067e-10,0.78721,4
300.02600,1183.10000,     -1.65016, 21.27968,50.00000,46.00000,2.001820e-10,0.78721,4
300.01199,1186.40000,     -1.65071, 21.24582,50.00000,46.00000,2.000294e-10,0.78719,4
300.00201,1189.70000,     -1.64895, 21.19183,50.00000,46.00000,2.008687e-10,0.78720,4
300.01599,1193.00000,     -1.65072, 21.14223,50.00000,46.00000,2.003841e-10,0.78720,4
300.02499,1196.30000,     -1.65151, 21.09482,50.00000,46.00000,2.005004e-10,0.78722,4
300.01599,1199.60000,     -1.65168, 21.04084,50.00000,46.00000,2.004299e-10,0.78721,4
300.01199,1202.90000,     -1.65418, 21.01375,50.00000,46.00000,2.009048e-10,0.78719,4
299.99799,1206.20000,     -1.65300, 20.91235,50.00000,47.00000,2.014484e-10,0.78719,4
300.00800,1209.50000,     -1.65321, 20.84920,50.00000,47.00000,2.003536e-10,0.78719,4
300.00601,1212.80000,     -1.65379, 20.82211,50.00000,47.00000,2.015037e-10,0.78720,4
300.01199,1216.10000,     -1.65399, 20.77490,50.00000,47.00000,2.013588e-10,0.78720,4
300.01501,1219.40000,     -1.65322, 20.70717,50.00000,47.00000,2.004357e-10,0.78720,4
300.01700,1222.70000,     -1.65535, 20.65319,50.00000,47.00000,2.009010e-10,0.78718,4
300.01599,1226.00000,     -1.65593, 20.64641,50.00000,47.00000,2.003841e-10,0.78718,4
300.01001,1229.30000,     -1.65534, 20.58546,50.00000,47.00000,2.009964e-10,0.78717,4
300.00699,1232.60000,     -1.65707, 20.52908,50.00000,47.00000,2.020473e-10,0.78718,4
300.02301,1235.90000,     -1.65845, 20.47729,50.00000,47.00000,2.024288e-10,0.78718,4
300.01199,1239.20000,     -1.65824, 20.44343,50.00000,47.00000,2.016926e-10,0.78718,4
300.01199,1242.50000,     -1.65785, 20.38267,50.00000,47.00000,2.017689e-10,0.78718,4
300.01501,1245.80000,     -1.65670, 20.34880,50.00000,47.00000,2.024727e-10,0.78719,4
300.02200,1249.10000,     -1.65961, 20.30159,50.00000,47.00000,2.024097e-10,0.78718,4
300.01999,1252.40000,     -1.65729, 20.22032,50.00000,47.00000,2.017593e-10,0.78719,4
300.02600,1255.70000,     -1.65846, 20.16414,50.00000,47.00000,2.024059e-10,0.78718,4
300.03299,1257.10000,     -1.65886, 20.13705,50.00000,50.00000,2.022819e-10,0.78718,5
300.26300,1257.26500,     -1.53436, 20.13705,50.00000,50.00000,2.021847e-10,0.78720,5
300.98801,1257.43000,     -1.17326, 20.29243,50.00000,50.00000,2.016907e-10,0.78718,5
302.29199,1257.59500,     -0.58135, 20.54940,50.00000,50.00000,2.018204e-10,0.78719,5
304.18301,1257.76000,      0.16415, 20.79283,50.00000,50.00000,2.021408e-10,0.78720,5
306.57401,1257.92500,      0.95248, 21.06773,50.00000,50.00000,2.022018e-10,0.78718,5
309.31699,1258.09000,      1.67856, 21.32689,50.00000,50.00000,2.024364e-10,0.78719,5
312.25400,1258.25500,      2.25859, 21.53645,50.00000,50.00000,2.021389e-10,0.78718,5
315.27802,1258.42000,      2.65551, 21.73028,50.00000,50.00000,2.024040e-10,0.78719,5
318.25900,1258.58500,      2.87582, 21.82052,50.00000,50.00000,2.025413e-10,0.78719,5
321.17099,1258.75000,      2.94499, 21.93327,50.00000,50.00000,2.017632e-10,0.78718,5
323.98099,1258.91500,      2.91710, 21.96016,50.00000,50.00000,2.018451e-10,0.78719,5
326.73199,1259.08000,      2.84354, 22.00757,50.00000,50.00000,2.020034e-10,0.78718,5
329.47299,1259.24500,      2.77265, 22.04143,50.00000,50.00000,2.023525e-10,0.78719,5
332.25000,1259.41000,      2.73514, 22.07510,50.00000,50.00000,2.018623e-10,0.78719,5
335.09299,1259.57500,      2.75243, 22.15398,50.00000,50.00000,2.024956e-10,0.78720,5
338.06900,1259.74000,      2.82554, 22.20817,50.00000,50.00000,2.023601e-10,0.78719,5
341.15302,1259.90500,      2.94776, 22.29143,50.00000,50.00000,2.026729e-10,0.78719,5
344.39099,1260.07000,      3.09704, 22.39980,50.00000,50.00000,2.024250e-10,0.78718,5
347.72800,1260.23500,      3.25208, 22.48984,50.00000,50.00000,2.016373e-10,0.78719,5
351.14899,1260.40000,      3.39443, 22.54402,50.00000,50.00000,2.021027e-10,0.78719,5
354.64401,1260.56500,      3.50944, 22.60478,50.00000,50.00000,2.025013e-10,0.78719,5
358.17099,1260.73000,      3.58764, 22.67231,50.00000,50.00000,2.023258e-10,0.78719,5
361.71600,1260.89500,      3.63222, 22.70618,50.00000,50.00000,2.015057e-10,0.78719,5
365.25800,1261.06000,      3.64429, 22.70618,50.00000,50.00000,2.023544e-10,0.78720,5
368.80499,1261.22500,      3.63057, 22.73327,50.00000,50.00000,2.020168e-10,0.78719,5
372.34299,1261.39000,      3.60417, 22.73327,50.00000,50.00000,2.025356e-10,0.78721,5
375.88501,1261.55500,      3.56732, 22.71295,50.00000,50.00000,2.022019e-10,0.78719,5
379.41400,1261.72000,      3.53536, 22.65219,50.00000,50.00000,2.015609e-10,0.78719,5
382.97198,1261.88500,      3.50812, 22.59343,50.00000,50.00000,2.027988e-10,0.78720,5
386.53000,1262.05000,      3.49094, 22.50120,50.00000,50.00000,2.023696e-10,0.78720,5
390.11099,1262.21500,      3.48989, 22.38386,50.00000,50.00000,2.018452e-10,0.78721,5
393.70300,1262.38000,      3.49079, 22.17649,50.00000,50.00000,2.018318e-10,0.78721,5
397.29001,1262.54500,      3.48987, 21.96016,50.00000,50.00000,2.021026e-10,0.78719,5
400.88300,1262.71000,      3.47112, 21.66733,50.00000,50.00000,2.023315e-10,0.78720,5
404.47601,1262.87500,      3.42983, 21.32928,50.00000,50.00000,2.027092e-10,0.78721,5
408.07300,1263.04000,      3.38587, 20.90319,50.00000,50.00000,2.025147e-10,0.78720,5
411.64899,1263.20500,      3.33931, 20.44343,50.00000,50.00000,2.026157e-10,0.78719,5
415.22000,1263.37000,      3.28707, 19.91614,50.00000,50.00000,2.018223e-10,0.78720,5
418.78601,1263.53500,      3.23265, 19.33028,50.00000,50.00000,2.021885e-10,0.78720,5
422.33200,1263.70000,      3.18048, 18.60219,50.00000,50.00000,2.027321e-10,0.78719,5
425.89200,1263.86500,      3.14121, 17.81116,50.00000,50.00000,2.023068e-10,0.78720,5
429.41800,1264.03000,      3.09883, 16.97291,50.00000,50.00000,2.023372e-10,0.78720,5
432.93900,1264.19500,      3.05274, 16.06235,50.00000,50.00000,2.015609e-10,0.78720,5
436.45499,1264.36000,      2.99459, 15.10677,50.00000,50.00000,2.028313e-10,0.78720,5
439.96899,1264.52500,      2.92700, 14.17829,50.00000,50.00000,2.025566e-10,0.78720,5
443.48300,1264.69000,      2.85008, 13.25876,50.00000,50.00000,2.019653e-10,0.78719,5
446.98099,1264.85500,      2.75851, 12.39801,50.00000,50.00000,2.018585e-10,0.78720,5
450.45901,1265.02000,      2.65958, 11.63167,50.00000,50.00000,2.021980e-10,0.78720,5
453.94101,1265.18500,      2.54269, 10.97131,50.00000,50.00000,2.025280e-10,0.78720,5
457.41199,1265.35000,      2.41487, 10.30876,50.00000,50.00000,2.016850e-10,0.78719,5
460.88000,1265.51500,      2.28055,  9.85578,50.00000,50.00000,2.018089e-10,0.78719,5
464.33200,1265.68000,      2.13889,  9.48845,50.00000,50.00000,2.028904e-10,0.78719,5
467.78900,1265.84500,      1.99779,  9.24960,50.00000,50.00000,2.031078e-10,0.78719,5
471.23001,1266.01000,      1.86640,  9.13008,50.00000,50.00000,2.025032e-10,0.78720,5
474.66901,1266.17500,      1.73884,  9.07610,50.00000,50.00000,2.023354e-10,0.78720,5
478.09100,1266.34000,      1.62050,  9.02191,50.00000,50.00000,2.030487e-10,0.78719,5
481.51901,1266.50500,      1.50864,  8.99482,50.00000,50.00000,2.018204e-10,0.78720,5
484.93701,1266.67000,      1.40897,  8.96793,50.00000,50.00000,2.022209e-10,0.78719,5
488.34698,1266.83500,      1.30786,  8.96793,50.00000,50.00000,2.023182e-10,0.78719,5
491.75800,1267.00000,      1.20431,  8.94084,50.00000,50.00000,2.025776e-10,0.78720,5
495.14899,1267.16500,      1.10799,  8.92729,50.00000,50.00000,2.020341e-10,0.78719,5
498.54300,1267.33000,      1.00729,  8.90697,50.00000,50.00000,2.025051e-10,0.78719,5
501.92801,1267.49500,      0.90868,  8.90697,50.00000,50.00000,2.019233e-10,0.78719,5
505.31601,1267.66000,      0.81169,  8.87988,50.00000,50.00000,2.026978e-10,0.78719,5
508.70001,1267.82500,      0.71207,  8.90697,50.00000,50.00000,2.011947e-10,0.78719,5
512.06799,1267.99000,      0.61332,  8.87988,50.00000,50.00000,2.019310e-10,0.78720,5
515.43903,1268.15500,      0.51422,  8.85299,50.00000,50.00000,2.025891e-10,0.78720,5
518.80402,1268.32000,      0.41425,  8.82590,50.00000,50.00000,2.023182e-10,0.78719,5
522.15802,1268.48500,      0.31856,  8.82590,50.00000,50.00000,2.026157e-10,0.78719,5
525.51599,1268.65000,      0.21741,  8.76952,50.00000,50.00000,2.015610e-10,0.78719,5
528.86499,1268.81500,      0.11721,  8.76952,50.00000,50.00000,2.018718e-10,0.78719,5
532.22101,1268.98000, 1.618050e-02,  8.73347,50.00000,50.00000,2.013111e-10,0.78719,5
535.57300,1269.14500,-8.569127e-02,  8.73347,50.00000,50.00000,2.024383e-10,0.78719,5
538.91400,1269.31000,     -0.18656,  8.70418,50.00000,50.00000,2.022781e-10,0.78719,5
542.26398,1269.47500,     -0.28771,  8.65020,50.00000,50.00000,2.021313e-10,0.78718,5
545.60199,1269.64000,     -0.38915,  8.61853,50.00000,50.00000,2.016868e-10,0.78718,5
548.94702,1269.80500,     -0.48687,  8.59143,50.00000,50.00000,2.020454e-10,0.78719,5
552.28699,1269.97000,     -0.58883,  8.59143,50.00000,50.00000,2.022094e-10,0.78718,5
555.61902,1270.13500,     -0.69077,  8.56454,50.00000,50.00000,2.023945e-10,0.78719,5
558.95697,1270.30000,     -0.79593,  8.53745,50.00000,50.00000,2.028122e-10,0.78718,5
562.27899,1270.46500,     -0.90106,  8.53068,50.00000,50.00000,2.020054e-10,0.78719,5
565.62500,1270.63000,     -1.00049,  8.48327,50.00000,50.00000,2.020836e-10,0.78718,5
568.95697,1270.79500,     -1.09328,  8.45637,50.00000,50.00000,2.026863e-10,0.78718,5
572.29797,1270.96000,     -1.19032,  8.42928,50.00000,50.00000,2.017040e-10,0.78719,5
575.62201,1271.12500,     -1.28969,  8.40219,50.00000,50.00000,2.019653e-10,0.78718,5
578.95300,1271.29000,     -1.39172,  8.37510,50.00000,50.00000,2.021465e-10,0.78718,5
582.27399,1271.45500,     -1.49418,  8.34821,50.00000,50.00000,2.018013e-10,0.78719,5
585.60101,1271.62000,     -1.59320,  8.30080,50.00000,50.00000,2.019329e-10,0.78719,5
588.93402,1271.78500,     -1.69291,  8.29402,50.00000,50.00000,2.019996e-10,0.78719,5
592.25299,1271.95000,     -1.79720,  8.26693,50.00000,50.00000,2.019520e-10,0.78719,5
595.57599,1272.11500,     -1.89463,  8.23984,50.00000,50.00000,2.019576e-10,0.78718,5
598.90002,1272.28000,     -1.99862,  8.21295,50.00000,50.00000,2.020893e-10,0.78719,5
602.22998,1272.44500,     -2.10616,  8.17908,50.00000,50.00000,2.025223e-10,0.78718,5
605.54602,1272.61000,     -2.21408,  8.15876,50.00000,50.00000,2.022305e-10,0.78719,5
608.87598,1272.77500,     -2.31932,  8.13167,50.00000,50.00000,2.026329e-10,0.78719,5
612.20502,1272.94000,     -2.42180,  8.13167,50.00000,50.00000,2.022495e-10,0.78719,5
615.51599,1273.10500,     -2.52545,  8.07769,50.00000,50.00000,2.023659e-10,0.78719,5
618.84003,1273.27000,     -2.63468,  8.07769,50.00000,50.00000,2.024307e-10,0.78719,5
622.16602,1273.43500,     -2.73911,  8.02351,50.00000,50.00000,2.023640e-10,0.78719,5
625.47900,1273.60000,     -2.84936,  7.99661,50.00000,50.00000,2.018928e-10,0.78718,5
628.79199,1273.76500,     -2.95097,  7.94243,50.00000,50.00000,2.018261e-10,0.78719,5
632.12299,1273.93000,     -3.05440,  7.94243,50.00000,50.00000,2.019500e-10,0.78720,5
635.43701,1274.09500,     -3.14813,  7.88845,50.00000,50.00000,2.022877e-10,0.78718,5
638.75299,1274.26000,     -3.27036,  7.86135,50.00000,50.00000,2.015075e-10,0.78719,5
642.07501,1274.42500,     -3.37768,  7.83426,50.00000,50.00000,2.018242e-10,0.78718,5
645.39502,1274.59000,     -3.48473,  7.77789,50.00000,50.00000,2.021656e-10,0.78719,5
648.70599,1274.75500,     -3.59443,  7.77789,50.00000,50.00000,2.025146e-10,0.78719,5
652.02899,1274.92000,     -3.70958,  7.75080,50.00000,50.00000,2.024993e-10,0.78719,5
655.34497,1275.08500,     -3.81667,  7.69681,50.00000,50.00000,2.024573e-10,0.78719,5
658.64502,1275.25000,     -3.93270,  7.66972,50.00000,50.00000,2.026043e-10,0.78719,5
661.96600,1275.41500,     -4.04192,  7.64263,50.00000,50.00000,2.026958e-10,0.78719,5
665.28101,1275.58000,     -4.14779,  7.61574,50.00000,50.00000,2.022724e-10,0.78719,5
668.59998,1275.74500,     -4.26031,  7.58865,50.00000,50.00000,2.016277e-10,0.78719,5
671.92999,1275.91000,     -4.37713,  7.56833,50.00000,50.00000,2.026444e-10,0.78719,5
675.24298,1276.07500,     -4.48933,  7.50299,50.00000,50.00000,2.024421e-10,0.78719,5
678.55298,1276.24000,     -4.60149,  7.48267,50.00000,50.00000,2.024460e-10,0.78719,5
681.87000,1276.40500,     -4.71551,  7.45558,50.00000,50.00000,2.020893e-10,0.78719,5
685.19299,1276.57000,     -4.83847,  7.44880,50.00000,50.00000,2.022152e-10,0.78719,5
688.50500,1276.73500,     -4.96605,  7.41275,50.00000,50.00000,2.024231e-10,0.78719,5
691.83698,1276.90000,     -5.11176,  7.37012,50.00000,50.00000,2.021599e-10,0.78719,5
695.14600,1277.06500,     -5.23328,  7.37012,50.00000,50.00000,2.025375e-10,0.78719,5
698.47198,1277.23000,     -5.36549,  7.31594,50.00000,50.00000,2.032814e-10,0.78719,5
701.78998,1277.39500,     -5.50587,  7.29562,50.00000,50.00000,2.030564e-10,0.78719,5
705.10901,1277.56000,     -5.64542,  7.26853,50.00000,50.00000,2.022629e-10,0.78719,5
708.43799,1277.72500,     -5.79930,  7.23486,50.00000,50.00000,2.020378e-10,0.78720,5
711.74799,1277.89000,     -5.95233,  7.23486,50.00000,50.00000,2.025204e-10,0.78719,5
715.07098,1278.05500,     -6.09705,  7.20777,50.00000,50.00000,2.024136e-10,0.78719,5
718.40002,1278.22000,     -6.24035,  7.18745,50.00000,50.00000,2.016392e-10,0.78719,5
721.72400,1278.38500,     -6.39202,  7.18068,50.00000,50.00000,2.019557e-10,0.78719,5
725.04102,1278.55000,     -6.54254,  7.18068,50.00000,50.00000,2.025222e-10,0.78719,5
728.37299,1278.71500,     -6.68913,  7.14681,50.00000,50.00000,2.020969e-10,0.78719,5
731.69598,1278.88000,     -6.84640,  7.15359,50.00000,50.00000,2.024936e-10,0.78719,5
735.00897,1279.04500,     -7.01863,  7.12669,50.00000,50.00000,2.026501e-10,0.78719,5
738.34302,1279.21000,     -7.17640,  7.12669,50.00000,50.00000,2.017154e-10,0.78719,5
741.65997,1279.37500,     -7.32841,  7.12669,50.00000,50.00000,2.018433e-10,0.78718,5
744.97699,1279.54000,     -7.47829,  7.12669,50.00000,50.00000,2.021065e-10,0.78719,5
748.30701,1279.70500,     -7.62450,  7.15359,50.00000,50.00000,2.021274e-10,0.78720,5
751.63202,1279.87000,     -7.76784,  7.15359,50.00000,50.00000,2.017879e-10,0.78719,5
754.94299,1280.03500,     -7.90628,  7.15359,50.00000,50.00000,2.024441e-10,0.78719,5
758.27197,1280.20000,     -8.04360,  7.16713,50.00000,50.00000,2.022743e-10,0.78720,5
761.58502,1280.36500,     -8.18187,  7.18068,50.00000,50.00000,2.027740e-10,0.78719,5
764.90503,1280.53000,     -8.30570,  7.20777,50.00000,50.00000,2.019424e-10,0.78719,5
768.23602,1280.69500,     -8.42197,  7.18068,50.00000,50.00000,2.019615e-10,0.78720,5
771.55798,1280.86000,     -8.55645,  7.23705,50.00000,50.00000,2.019825e-10,0.78719,5
774.87701,1281.02500,     -8.67361,  7.25060,50.00000,50.00000,2.019920e-10,0.78720,5
778.20697,1281.19000,     -8.78379,  7.27092,50.00000,50.00000,2.017574e-10,0.78720,5
781.53003,1281.35500,     -8.89351,  7.32490,50.00000,50.00000,2.022362e-10,0.78719,5
784.83801,1281.52000,     -8.99090,  7.35199,50.00000,50.00000,2.026825e-10,0.78720,5
788.15698,1281.68500,     -9.08521,  7.37908,50.00000,50.00000,2.026233e-10,0.78720,5
791.47302,1281.85000,     -9.18681,  7.37908,50.00000,50.00000,            ,0.44831,5
794.49500,1282.00000,     -9.27497,  7.43546,50.00000,50.00000,            ,0.44709,5