File: data/TGA/005d-L_M/ExpDat_2025_02_28_Styrofoam_Isothermal.csv
#EXPORTTYPE:                 ,DATA ALL
#FILE:                       ,2025_02_28_Styrofoam_Isothermal.ngb-ss5
#FORMAT:                     ,NETZSCH5
#FTYPE:                      ,ASCII
#IDENTITY:                   ,2025_02_28_Styrofoam_Is
#DECIMAL:                    ,POINT
#SEPARATOR:                  ,COMMA
#MTYPE:                      ,DSC
#INSTRUMENT:                 ,NETZSCH STA 449F5
#PROJECT:                    ,PS
#DATE/TIME:                  ,2/28/2025 1:55:09 PM (UTC-5)
#CORR. FILE:                 ,
#TEMPCAL:                    ,13-11-2024 10:37
#SENSITIVITY:                ,28-06-2023 13:53
#LABORATORY:                 ,Tran/Aspuru
#OPERATOR:                   ,Stanley
#REMARK:                     ,
#SAMPLE:                     ,2025_02_28_Styrofoam_Is
#SAMPLE MASS /mg:            ,5.03
#MATERIAL:                   ,
#REFERENCE:                  ,
#REFERENCE MASS /mg:         ,0
#TYPE OF CRUCIBLE:           ,Al2O3 85 ‘l, open
#SAMPLE CRUCIBLE MASS /mg:   ,0
#REFERENCE CRUCIBLE MASS /mg:,0
#DSC RANGE /‘V:              ,5000
#TG RANGE /mg:               ,35000
#TAU-R:                      ,---
#CORR. CODE:                 ,000
#EXO:                        ,-1
#RANGE:                      ,30›C....800›C/0.0....20.0K/min
#SEGMENT:                    ,S1-5/5
#SEG. 1:                     ,30›C/10.0(K/min)/100›C
#SEG. 2:                     ,100›C/00:10/100›C
#SEG. 3:                     ,100›C/5.0(K/min)/300›C
#SEG. 4:                     ,300›C/20:00/300›C
#SEG. 5:                     ,300›C/20.0(K/min)/800›C

##Temp./›C,Time/min,DSC/(mW/mg),Mass/%,Gas Flow(purge2)/(ml/min),Gas Flow(protective)/(ml/min),TIC(scan:1)/A,Sensit./(uV/mW),Segment
 28.15900,   0.00000,      0.17695,    100.00000,50.00000,50.00000,            ,0.92320,1
 31.54400,   1.36000,      0.32098,     93.16700,50.00000,50.00000,2.215366e-10,0.92331,1
 38.96500,   2.72000,      0.72891,     94.38151,50.00000,50.00000,2.221909e-10,0.92343,1
 49.64000,   4.08000,      1.13586,     95.67256,50.00000,50.00000,2.217273e-10,0.92360,1
 63.63300,   5.44000,      1.58568,     96.75666,50.00000,50.00000,2.225837e-10,0.92380,1
 79.73500,   6.80000,      1.94394,     97.53260,50.00000,50.00000,2.222099e-10,0.92404,1
 89.12100,   7.58000,      1.95015,     97.55964,50.00000,50.00000,2.218437e-10,0.92420,2
 95.56000,   8.26000,      1.54184,     96.87137,50.00000,50.00000,2.218285e-10,0.92434,2
100.03900,   8.94000,      1.08280,     96.01670,50.00000,50.00000,2.228794e-10,0.92448,2
103.33600,   9.62000,      0.79748,     95.49483,50.00000,50.00000,2.223702e-10,0.92461,2
106.00900,  10.30000,      0.62077,     95.10577,50.00000,50.00000,2.223797e-10,0.92478,2
108.01800,  10.98000,      0.44173,     94.67614,50.00000,50.00000,2.220726e-10,0.92492,2
109.27200,  11.66000,      0.24936,     94.20616,50.00000,50.00000,2.222290e-10,0.92505,2
109.92900,  12.34000, 7.928269e-02,     93.80577,50.00000,50.00000,2.227841e-10,0.92518,2
110.11400,  13.02000,-4.542514e-02,     93.34692,50.00000,50.00000,2.232743e-10,0.92531,2
109.95600,  13.70000,     -0.14122,     92.99384,50.00000,50.00000,2.223911e-10,0.92544,2
109.54600,  14.38000,     -0.21040,     92.67674,50.00000,50.00000,2.224082e-10,0.92555,2
108.94700,  15.06000,     -0.26138,     92.36620,50.00000,50.00000,2.220325e-10,0.92569,2
108.21900,  15.74000,     -0.29582,     92.08290,50.00000,50.00000,2.223816e-10,0.92580,2
107.40500,  16.42000,     -0.31638,     91.84453,50.00000,50.00000,2.219600e-10,0.92589,2
106.44200,  17.20000,     -0.32222,     91.59940,50.00000,50.00000,2.215614e-10,0.92600,3
106.52200,  18.56000, 4.636305e-02,     92.10755,50.00000,50.00000,2.224560e-10,0.92612,3
109.44100,  19.92000,      0.38578,     92.66103,50.00000,50.00000,2.223205e-10,0.92619,3
114.14300,  21.28000,      0.67421,     93.23002,50.00000,50.00000,2.233124e-10,0.92619,3
120.48500,  22.64000,      0.92932,     93.68887,50.00000,50.00000,2.228756e-10,0.92610,3
127.85100,  24.00000,      1.09115,     94.01272,50.00000,50.00000,2.236977e-10,0.92592,3
135.73801,  25.36000,      1.18557,     94.22863,50.00000,50.00000,2.229939e-10,0.92566,3
143.77000,  26.72000,      1.22038,     94.35010,50.00000,50.00000,2.236690e-10,0.92525,3
151.74300,  28.08000,      1.21344,     94.59066,50.00000,50.00000,2.238349e-10,0.92478,3
159.48000,  29.44000,      1.18501,     94.44911,50.00000,50.00000,2.237434e-10,0.92436,3
166.98599,  30.80000,      1.14392,     94.47594,50.00000,50.00000,2.223759e-10,0.92406,3
174.23900,  32.16000,      1.10118,     94.53002,50.00000,50.00000,2.233201e-10,0.92370,3
181.31300,  33.52000,      1.06243,     94.57058,50.00000,50.00000,2.231713e-10,0.92337,3
188.29601,  34.88000,      1.02828,     94.62445,50.00000,50.00000,2.235547e-10,0.92305,3
195.18401,  36.24000,      0.99634,     94.66501,50.00000,50.00000,2.235355e-10,0.92274,3
202.01100,  37.60000,      0.96296,     94.69205,50.00000,50.00000,2.229480e-10,0.92239,3
208.80200,  38.96000,      0.93007,     94.70537,50.00000,50.00000,2.223816e-10,0.92210,3
215.57700,  40.32000,      0.89817,     94.75944,50.00000,50.00000,2.234612e-10,0.92183,3
222.34500,  41.68000,      0.86159,     94.82008,50.00000,50.00000,2.224273e-10,0.92154,3
229.10600,  43.04000,      0.82076,     94.84712,50.00000,50.00000,2.229195e-10,0.92130,3
235.87100,  44.40000,      0.77414,     94.84930,50.00000,50.00000,2.240085e-10,0.92108,3
242.63800,  45.76000,      0.72648,     94.82247,50.00000,50.00000,2.228622e-10,0.92086,3
249.39400,  47.12000,      0.67424,     94.86282,50.00000,50.00000,2.229900e-10,0.92063,3
256.16800,  48.48000,      0.61605,     94.84712,50.00000,50.00000,2.226581e-10,0.92043,3
262.93301,  49.84000,      0.55636,     94.74135,50.00000,50.00000,2.229461e-10,0.92024,3
269.71201,  51.20000,      0.49177,     94.73459,50.00000,50.00000,2.229194e-10,0.92006,3
276.47699,  52.56000,      0.42476,     94.69423,50.00000,50.00000,2.228108e-10,0.91988,3
283.27100,  53.92000,      0.35735,     94.61988,50.00000,50.00000,2.223663e-10,0.91969,3
290.01999,  55.28000,      0.28281,     94.50298,50.00000,50.00000,2.229595e-10,0.91952,3
296.78900,  56.64000,      0.20827,     94.34553,50.00000,50.00000,2.236252e-10,0.91937,3
302.86499,  59.50000,     -1.32938,     94.20835,50.00000,40.00000,2.229576e-10,0.91905,4
302.55801,  62.90000,     -1.73049,     93.43698,50.00000,40.00000,2.234726e-10,0.91877,4
301.34500,  66.30000,     -1.72646,     92.89026,50.00000,40.00000,2.235356e-10,0.91854,4
300.63101,  69.70000,     -1.68277,     92.42704,50.00000,40.00000,2.240067e-10,0.91838,4
300.27600,  73.10000,     -1.65816,     92.00199,50.00000,40.00000,2.236156e-10,0.91829,4
300.12100,  76.50000,     -1.64436,     91.61511,50.00000,40.00000,2.235183e-10,0.91825,4
300.05701,  79.90000,     -1.64077,     91.28668,50.00000,40.00000,2.227249e-10,0.91825,4
300.02600,  83.30000,     -1.63936,     90.96740,50.00000,40.00000,2.227439e-10,0.91828,4
300.00699,  86.70000,     -1.63990,     90.70417,50.00000,40.00000,2.221108e-10,0.91835,4
300.00400,  90.10000,     -1.63624,     90.42068,50.00000,40.00000,2.219028e-10,0.91843,4
300.00400,  93.50000,     -1.63797,     90.19125,50.00000,40.00000,2.219868e-10,0.91854,4
300.01401,  96.90000,     -1.63471,     89.97535,50.00000,40.00000,2.220021e-10,0.91866,4
300.00299, 100.30000,     -1.63431,     89.76620,50.00000,40.00000,2.215214e-10,0.91879,4
300.01001, 103.70000,     -1.63683,     89.57058,50.00000,40.00000,2.221641e-10,0.91893,4
300.00800, 107.10000,     -1.63624,     89.42207,50.00000,40.00000,2.216739e-10,0.91908,4
300.02100, 110.50000,     -1.63319,     89.23996,50.00000,40.00000,2.221107e-10,0.91922,4
300.02200, 113.90000,     -1.63280,     89.08250,50.00000,40.00000,2.217827e-10,0.91943,4
300.00800, 117.30000,     -1.63200,     88.89364,50.00000,40.00000,2.212295e-10,0.91931,4
300.00601, 120.70000,     -1.63123,     88.75189,50.00000,40.00000,2.215862e-10,0.91889,4
300.01599, 124.10000,     -1.63106,     88.59443,50.00000,40.00000,2.209739e-10,0.91824,4
300.01901, 127.50000,     -1.63087,     88.44374,50.00000,40.00000,2.221909e-10,0.91735,4
300.00601, 130.90000,     -1.63219,     88.28171,50.00000,40.00000,2.223797e-10,0.91623,4
300.01300, 134.30000,     -1.63067,     88.13340,50.00000,40.00000,2.219639e-10,0.91481,4
300.01801, 137.70000,     -1.63164,     88.00517,50.00000,40.00000,2.219944e-10,0.91315,4
300.01001, 141.10000,     -1.62835,     87.86342,50.00000,40.00000,2.220955e-10,0.91139,4
300.01700, 144.50000,     -1.62798,     87.74652,50.00000,40.00000,2.223110e-10,0.90935,4
300.02301, 147.90000,     -1.62857,     87.58449,50.00000,40.00000,2.221298e-10,0.90715,4
300.03400, 151.30000,     -1.62936,     87.44950,50.00000,40.00000,2.218552e-10,0.90483,4
300.02802, 154.70000,     -1.62761,     87.33479,50.00000,40.00000,2.216950e-10,0.90253,4
300.01300, 158.10000,     -1.62970,     87.17296,50.00000,40.00000,2.221317e-10,0.90004,4
300.01300, 161.50000,     -1.62855,     87.15050,50.00000,40.00000,2.218666e-10,0.89750,4
300.01001, 164.90000,     -1.62681,     86.95249,50.00000,40.00000,2.223949e-10,0.89502,4
300.01501, 168.30000,     -1.62585,     86.80398,50.00000,40.00000,2.214660e-10,0.89238,4
300.02399, 171.70000,     -1.62625,     86.68926,50.00000,40.00000,2.212983e-10,0.88984,4
300.00800, 175.10000,     -1.62468,     86.56123,50.00000,40.00000,2.216739e-10,0.88713,4
300.01099, 178.50000,     -1.62469,     86.44652,50.00000,40.00000,2.219811e-10,0.88439,4
299.99600, 181.90000,     -1.62293,     86.33857,50.00000,40.00000,2.217789e-10,0.88159,4
300.00500, 185.30000,     -1.62140,     86.22147,50.00000,40.00000,2.212276e-10,0.87889,4
300.01901, 188.70000,     -1.62162,     86.14056,50.00000,40.00000,2.217445e-10,0.87599,4
300.02200, 192.10000,     -1.61893,     86.07316,50.00000,40.00000,2.221107e-10,0.87307,4
300.00800, 195.50000,     -1.62179,     85.92465,50.00000,40.00000,2.215919e-10,0.87022,4
300.01300, 198.90000,     -1.61853,     85.76938,50.00000,40.00000,2.212524e-10,0.86719,4
300.01501, 202.30000,     -1.61988,     85.65467,50.00000,40.00000,2.208195e-10,0.86410,4
300.01700, 205.70000,     -1.62027,     85.54453,50.00000,40.00000,2.208882e-10,0.86111,4
300.00900, 209.10000,     -1.62199,     85.44553,50.00000,40.00000,2.213898e-10,0.85793,4
300.01199, 212.50000,     -1.61872,     85.29483,50.00000,40.00000,2.213135e-10,0.85469,4
300.02899, 215.90000,     -1.61933,     85.18688,50.00000,40.00000,2.210217e-10,0.85156,4
300.01801, 219.30000,     -1.62027,     85.05189,50.00000,40.00000,2.222538e-10,0.84823,4
300.01001, 222.70000,     -1.62006,     84.93718,50.00000,40.00000,2.210788e-10,0.84485,4
300.01199, 226.10000,     -1.61949,     84.82247,50.00000,40.00000,2.208022e-10,0.84159,4
300.01501, 229.50000,     -1.61853,     84.68091,50.00000,40.00000,2.212791e-10,0.83811,4
300.01801, 232.90000,     -1.61815,     84.58191,50.00000,40.00000,2.210808e-10,0.83460,4
300.01300, 236.30000,     -1.61968,     84.48748,50.00000,40.00000,2.200298e-10,0.83105,4
300.00601, 239.70000,     -1.62044,     84.34791,50.00000,40.00000,2.211571e-10,0.82763,4
300.01199, 243.10000,     -1.61660,     84.24672,50.00000,40.00000,2.201958e-10,0.82401,4
300.01901, 246.50000,     -1.61565,     84.19960,50.00000,40.00000,2.204742e-10,0.82034,4
300.01401, 249.90000,     -1.61564,     84.06004,50.00000,40.00000,2.208900e-10,0.81664,4
300.01401, 253.30000,     -1.61814,     83.91829,50.00000,40.00000,2.201004e-10,0.81310,4
300.00000, 256.70000,     -1.61696,     83.83519,50.00000,40.00000,2.177964e-10,0.80933,4
300.01401, 260.10000,     -1.61660,     83.73400,50.00000,41.00000,2.173348e-10,0.80555,4
300.01099, 263.50000,     -1.61698,     83.60577,50.00000,41.00000,2.164307e-10,0.80193,4
300.02301, 266.90000,     -1.61604,     83.49781,50.00000,41.00000,2.060795e-10,0.79810,4
300.01700, 270.30000,     -1.61352,     83.37634,50.00000,41.00000,2.056694e-10,0.79444,4
300.02399, 273.70000,     -1.61354,     83.28867,50.00000,41.00000,2.052479e-10,0.79057,4
300.01199, 277.10000,     -1.61660,     83.18072,50.00000,41.00000,2.058086e-10,0.78554,4
300.01099, 280.50000,     -1.61313,     83.09960,50.00000,41.00000,2.053623e-10,0.78428,4
300.01401, 283.90000,     -1.61410,     82.97137,50.00000,41.00000,2.053508e-10,0.78456,4
300.01599, 287.30000,     -1.61372,     82.92425,50.00000,41.00000,2.058411e-10,0.78530,4
300.00299, 290.70000,     -1.61523,     82.78926,50.00000,41.00000,2.062359e-10,0.78591,4
300.00201, 294.10000,     -1.61388,     82.70835,50.00000,41.00000,2.060071e-10,0.78640,4
300.00900, 297.50000,     -1.61274,     82.58012,50.00000,41.00000,2.063504e-10,0.78672,4
300.01199, 300.90000,     -1.61506,     82.47893,50.00000,41.00000,2.058659e-10,0.78690,4
299.99600, 304.30000,     -1.61406,     82.39125,50.00000,41.00000,2.060871e-10,0.78703,4
300.01901, 307.70000,     -1.61334,     82.28330,50.00000,41.00000,2.060432e-10,0.78709,4
300.00800, 311.10000,     -1.61447,     82.19324,50.00000,41.00000,2.071495e-10,0.78714,4
300.01700, 314.50000,     -1.61275,     82.08529,50.00000,41.00000,2.060394e-10,0.78717,4
300.02200, 317.90000,     -1.61430,     81.98847,50.00000,41.00000,2.066136e-10,0.78718,4
300.02200, 321.30000,     -1.61103,     81.89404,50.00000,41.00000,2.057629e-10,0.78718,4
300.01599, 324.70000,     -1.61333,     81.79960,50.00000,41.00000,2.063617e-10,0.78719,4
300.02200, 328.10000,     -1.61334,     81.70517,50.00000,41.00000,2.059765e-10,0.78719,4
300.02600, 331.50000,     -1.61219,     81.62644,50.00000,41.00000,2.058620e-10,0.78720,4
300.02499, 334.90000,     -1.61450,     81.55229,50.00000,41.00000,2.059078e-10,0.78720,4
300.01801, 338.30000,     -1.61102,     81.43082,50.00000,41.00000,2.061882e-10,0.78720,4
300.00900, 341.70000,     -1.61043,     81.36322,50.00000,41.00000,2.065868e-10,0.78720,4
300.01401, 345.10000,     -1.60928,     81.25308,50.00000,41.00000,2.061196e-10,0.78719,4
300.04901, 348.50000,     -1.60954,     81.16302,50.00000,41.00000,2.059270e-10,0.78720,4
300.00299, 351.90000,     -1.61273,     81.04175,50.00000,41.00000,2.056999e-10,0.78720,4
300.01599, 355.30000,     -1.60909,     80.95388,50.00000,41.00000,2.064476e-10,0.78718,4
300.01599, 358.70000,     -1.60851,     80.82565,50.00000,41.00000,2.065163e-10,0.78720,4
300.01700, 362.10000,     -1.60851,     80.73121,50.00000,41.00000,2.058048e-10,0.78719,4
300.02200, 365.50000,     -1.61064,     80.65030,50.00000,41.00000,2.058277e-10,0.78719,4
300.00500, 368.90000,     -1.60888,     80.58052,50.00000,41.00000,2.057667e-10,0.78719,4
300.01901, 372.30000,     -1.60871,     80.43439,50.00000,41.00000,2.057266e-10,0.78720,4
300.02701, 375.70000,     -1.60738,     80.33996,50.00000,41.00000,2.064094e-10,0.78719,4
300.00900, 379.10000,     -1.60850,     80.28588,50.00000,41.00000,2.066536e-10,0.78720,4
300.01999, 382.50000,     -1.60794,     80.14871,50.00000,41.00000,2.069111e-10,0.78720,4
300.01599, 385.90000,     -1.60774,     80.04076,50.00000,41.00000,2.066707e-10,0.78720,4
300.01300, 389.30000,     -1.60523,     79.93956,50.00000,41.00000,2.071610e-10,0.78718,4
300.01300, 392.70000,     -1.60619,     79.86759,50.00000,41.00000,2.069950e-10,0.78720,4
300.00699, 396.10000,     -1.60599,     79.73936,50.00000,41.00000,2.067852e-10,0.78720,4
300.00299, 399.50000,     -1.60579,     79.67197,50.00000,41.00000,2.069187e-10,0.78719,4
300.03000, 402.90000,     -1.60546,     79.52565,50.00000,41.00000,2.063522e-10,0.78720,4
300.01099, 406.30000,     -1.60619,     79.45149,50.00000,41.00000,2.076663e-10,0.78720,4
300.01501, 409.70000,     -1.60697,     79.35706,50.00000,41.00000,2.071038e-10,0.78720,4
300.01501, 413.10000,     -1.60543,     79.24672,50.00000,41.00000,2.073383e-10,0.78719,4
300.01001, 416.50000,     -1.60927,     79.10278,50.00000,41.00000,2.073784e-10,0.78719,4
300.00601, 419.90000,     -1.60714,     79.05567,50.00000,41.00000,2.082272e-10,0.78719,4
300.01501, 423.30000,     -1.60543,     78.92744,50.00000,41.00000,2.073230e-10,0.78719,4
300.00500, 426.70000,     -1.60849,     78.86004,50.00000,41.00000,2.084560e-10,0.78719,4
300.01001, 430.10000,     -1.60523,     78.73181,50.00000,41.00000,2.076034e-10,0.78718,4
300.01599, 433.50000,     -1.60678,     78.65984,50.00000,41.00000,2.079087e-10,0.78718,4
300.00400, 436.90000,     -1.60464,     78.52485,50.00000,41.00000,2.075615e-10,0.78719,4
300.02100, 440.30000,     -1.60563,     78.44394,50.00000,41.00000,2.074643e-10,0.78719,4
300.01901, 443.70000,     -1.60659,     78.41690,50.00000,41.00000,2.072334e-10,0.78719,4
300.01801, 447.10000,     -1.60640,     78.29543,50.00000,41.00000,2.081929e-10,0.78718,4
300.01999, 450.50000,     -1.60736,     78.20775,50.00000,41.00000,2.075977e-10,0.78719,4
300.01700, 453.90000,     -1.60370,     78.11332,50.00000,41.00000,2.069301e-10,0.78719,4
300.03400, 457.30000,     -1.60643,     78.05924,50.00000,41.00000,2.079105e-10,0.78718,4
300.01901, 460.70000,     -1.60698,     77.94235,50.00000,41.00000,2.070389e-10,0.78718,4
300.02200, 464.10000,     -1.60563,     77.84791,50.00000,41.00000,2.069530e-10,0.78718,4
300.01501, 467.50000,     -1.60235,     77.76680,50.00000,41.00000,2.067490e-10,0.78719,4
300.01501, 470.90000,     -1.60254,     77.71054,50.00000,41.00000,2.079067e-10,0.78718,4
300.01901, 474.30000,     -1.60120,     77.59583,50.00000,41.00000,2.009353e-10,0.78721,4
300.03000, 477.70000,     -1.60430,     77.50139,50.00000,41.00000,2.008075e-10,0.78720,4
300.03500, 481.10000,     -1.60103,     77.44513,50.00000,41.00000,1.996784e-10,0.78720,4
300.00500, 484.50000,     -1.60175,     77.35746,50.00000,41.00000,2.002353e-10,0.78720,4
300.01901, 487.90000,     -1.60023,     77.25626,50.00000,41.00000,2.002278e-10,0.78719,4
300.02200, 491.30000,     -1.59985,     77.14831,50.00000,41.00000,2.002735e-10,0.78719,4
300.01199, 494.70000,     -1.59945,     77.04036,50.00000,41.00000,2.003975e-10,0.78718,4
300.01801, 498.10000,     -1.59811,     76.95706,50.00000,41.00000,2.004910e-10,0.78719,4
300.02802, 501.50000,     -1.59832,     76.87614,50.00000,41.00000,2.011490e-10,0.78719,4
300.02399, 504.90000,     -1.59832,     76.72763,50.00000,41.00000,2.008800e-10,0.78718,4
300.01700, 508.30000,     -1.59753,     76.67376,50.00000,40.00000,2.001800e-10,0.78720,4
300.02100, 511.70000,     -1.59523,     76.57256,50.00000,41.00000,2.003650e-10,0.78719,4
300.01401, 515.10000,     -1.59945,     76.45109,50.00000,41.00000,2.009430e-10,0.78719,4
300.00000, 518.50000,     -1.59673,     76.36342,50.00000,41.00000,2.006855e-10,0.78719,4
300.01599, 521.90000,     -1.59676,     76.26899,50.00000,41.00000,2.006302e-10,0.78719,4
300.01801, 525.30000,     -1.59830,     76.16759,50.00000,41.00000,2.018337e-10,0.78720,4
300.00900, 528.70000,     -1.59887,     76.04632,50.00000,41.00000,2.014847e-10,0.78719,4
300.01901, 532.10000,     -1.59908,     75.96521,50.00000,41.00000,2.019558e-10,0.78719,4
300.01501, 535.50000,     -1.59695,     75.87753,50.00000,41.00000,2.014866e-10,0.78719,4
300.01300, 538.90000,     -1.59714,     75.78310,50.00000,41.00000,2.018623e-10,0.78719,4
300.01099, 542.30000,     -1.59733,     75.68191,50.00000,41.00000,2.017365e-10,0.78719,4
300.00201, 545.70000,     -1.59538,     75.60080,50.00000,41.00000,2.022362e-10,0.78719,4
300.00101, 549.10000,     -1.59789,     75.54016,50.00000,41.00000,2.015934e-10,0.78719,4
300.00299, 552.50000,     -1.59712,     75.40517,50.00000,41.00000,2.019387e-10,0.78719,4
300.01801, 555.90000,     -1.60004,     75.33777,50.00000,41.00000,2.020226e-10,0.78719,4
300.01901, 559.30000,     -1.59888,     75.25686,50.00000,41.00000,2.021218e-10,0.78718,4
300.01001, 562.70000,     -1.59713,     75.16223,50.00000,41.00000,2.024441e-10,0.78720,4
300.00800, 566.10000,     -1.59771,     75.08807,50.00000,41.00000,2.022952e-10,0.78718,4
300.01700, 569.50000,     -1.59850,     74.96660,50.00000,41.00000,2.026329e-10,0.78720,4
300.02399, 572.90000,     -1.59909,     74.88569,50.00000,41.00000,2.030449e-10,0.78719,4
300.00699, 576.30000,     -1.59655,     74.79563,50.00000,41.00000,2.021064e-10,0.78719,4
300.02301, 579.70000,     -1.59600,     74.73499,50.00000,41.00000,2.025051e-10,0.78720,4
300.01501, 583.10000,     -1.59907,     74.62704,50.00000,41.00000,2.024498e-10,0.78719,4
300.01300, 586.50000,     -1.59772,     74.53936,50.00000,41.00000,2.025681e-10,0.78720,4
300.01700, 589.90000,     -1.59927,     74.43121,50.00000,41.00000,2.033710e-10,0.78719,4
300.01501, 593.30000,     -1.59695,     74.33678,50.00000,41.00000,2.032356e-10,0.78715,4
300.01501, 596.70000,     -1.59772,     74.25586,50.00000,41.00000,2.029400e-10,0.78719,4
300.01099, 600.10000,     -1.59636,     74.16143,50.00000,41.00000,2.031898e-10,0.78720,4
300.00601, 603.50000,     -1.59539,     74.07376,50.00000,41.00000,2.026005e-10,0.78720,4
300.02600, 606.90000,     -1.59292,     73.99264,50.00000,41.00000,2.023315e-10,0.78720,4
300.01700, 610.30000,     -1.59734,     73.89145,50.00000,41.00000,2.032280e-10,0.78719,4
300.03500, 613.70000,     -1.59294,     73.78350,50.00000,41.00000,2.032337e-10,0.78720,4
300.01700, 617.10000,     -1.59271,     73.67555,50.00000,41.00000,2.031880e-10,0.78720,4
300.01801, 620.50000,     -1.59310,     73.59463,50.00000,41.00000,2.026920e-10,0.78717,4
300.02600, 623.90000,     -1.59196,     73.50696,50.00000,41.00000,2.038117e-10,0.78721,4
300.01001, 627.30000,     -1.59251,     73.41252,50.00000,41.00000,2.034129e-10,0.78719,4
300.01599, 630.70000,     -1.59310,     73.31789,50.00000,41.00000,2.030449e-10,0.78718,4
300.01501, 634.10000,     -1.58847,     73.26402,50.00000,41.00000,2.031899e-10,0.78720,4
300.00601, 637.50000,     -1.59077,     73.16282,50.00000,41.00000,2.035275e-10,0.78719,4
300.00400, 640.90000,     -1.59153,     73.04811,50.00000,41.00000,2.037106e-10,0.78719,4
300.01401, 644.30000,     -1.59194,     72.96044,50.00000,41.00000,2.035656e-10,0.78719,4
300.00699, 647.70000,     -1.59000,     72.85229,50.00000,41.00000,2.051849e-10,0.78719,4
300.01700, 651.10000,     -1.59079,     72.77594,50.00000,41.00000,2.050819e-10,0.78720,4
300.01401, 654.50000,     -1.59155,     72.67475,50.00000,41.00000,2.049808e-10,0.78719,4
300.02802, 657.90000,     -1.59158,     72.56004,50.00000,41.00000,2.055530e-10,0.78718,4
300.01700, 661.30000,     -1.59175,     72.46561,50.00000,41.00000,2.050667e-10,0.78720,4
300.01801, 664.70000,     -1.59291,     72.32386,50.00000,41.00000,2.050628e-10,0.78720,4
300.00699, 668.10000,     -1.59154,     72.26978,50.00000,41.00000,2.043591e-10,0.78719,4
300.01001, 671.50000,     -1.59270,     72.18887,50.00000,41.00000,2.047329e-10,0.78720,4
300.02200, 674.90000,     -1.59330,     72.11471,50.00000,41.00000,2.049980e-10,0.78720,4
300.00800, 678.30000,     -1.59270,     71.97972,50.00000,41.00000,2.055550e-10,0.78719,4
300.00500, 681.70000,     -1.59385,     71.92565,50.00000,41.00000,2.049656e-10,0.78720,4
300.00900, 685.10000,     -1.59366,     71.81093,50.00000,41.00000,2.060127e-10,0.78719,4
299.99701, 688.50000,     -1.59460,     71.74354,50.00000,41.00000,2.053718e-10,0.78719,4
300.05099, 691.90000,     -1.59451,     71.66262,50.00000,41.00000,2.062836e-10,0.78719,4
300.01501, 695.30000,     -1.59502,     71.55467,50.00000,41.00000,2.063599e-10,0.78718,4
300.01599, 698.70000,     -1.59464,     71.48708,50.00000,41.00000,2.066250e-10,0.78718,4
300.01099, 702.10000,     -1.59309,     71.39940,50.00000,41.00000,2.065277e-10,0.78719,4
300.02301, 705.50000,     -1.59407,     71.33201,50.00000,41.00000,2.064667e-10,0.78719,4
300.01599, 708.90000,     -1.59348,     71.23738,50.00000,41.00000,2.065754e-10,0.78719,4
300.00900, 712.30000,     -1.59405,     71.16322,50.00000,41.00000,2.066593e-10,0.78719,4
300.00400, 715.70000,     -1.59346,     71.06879,50.00000,41.00000,2.071838e-10,0.78719,4
300.00900, 719.10000,     -1.59347,     70.98111,50.00000,41.00000,2.069092e-10,0.78719,4
300.02100, 722.50000,     -1.59407,     70.90676,50.00000,41.00000,2.078704e-10,0.78720,4
300.01599, 725.90000,     -1.59425,     70.80557,50.00000,41.00000,2.072373e-10,0.78720,4
300.02399, 729.30000,     -1.59331,     70.73817,50.00000,41.00000,2.074108e-10,0.78718,4
300.02802, 732.70000,     -1.59543,     70.65726,50.00000,41.00000,2.079106e-10,0.78719,4
300.01401, 736.10000,     -1.59290,     70.58290,50.00000,41.00000,2.085036e-10,0.78720,4
300.00299, 739.50000,     -1.59442,     70.47952,50.00000,41.00000,2.086086e-10,0.78719,4
300.01199, 742.90000,     -1.59463,     70.40537,50.00000,41.00000,2.089176e-10,0.78719,4
300.01999, 746.30000,     -1.59542,     70.30398,50.00000,41.00000,2.095814e-10,0.78719,4
300.01999, 749.70000,     -1.59696,     70.24334,50.00000,41.00000,2.091312e-10,0.78719,4
300.01901, 753.10000,     -1.59831,     70.13539,50.00000,41.00000,2.087612e-10,0.78718,4
300.01901, 756.50000,     -1.59484,     70.06123,50.00000,41.00000,2.080040e-10,0.78718,4
300.01999, 759.90000,     -1.59561,     69.95984,50.00000,41.00000,2.086887e-10,0.78718,4
300.01401, 763.30000,     -1.59868,     69.90596,50.00000,41.00000,2.095509e-10,0.78720,4
300.01401, 766.70000,     -1.59618,     69.79125,50.00000,41.00000,2.087536e-10,0.78720,4
300.02499, 770.10000,     -1.59543,     69.72386,50.00000,41.00000,2.090512e-10,0.78718,4
300.02499, 773.50000,     -1.59678,     69.62922,50.00000,41.00000,2.092991e-10,0.78719,4
300.01801, 776.90000,     -1.59580,     69.52127,50.00000,41.00000,2.100297e-10,0.78719,4
300.01501, 780.30000,     -1.59464,     69.45388,50.00000,41.00000,2.091293e-10,0.78719,4
300.01901, 783.70000,     -1.59349,     69.33917,50.00000,41.00000,2.097951e-10,0.78719,4
300.01700, 787.10000,     -1.59406,     69.26501,50.00000,41.00000,2.098866e-10,0.78719,4
300.02802, 790.50000,     -1.59601,     69.19742,50.00000,41.00000,2.094555e-10,0.78719,4
300.01501, 793.90000,     -1.59868,     69.06243,50.00000,41.00000,2.101459e-10,0.78719,4
300.02200, 797.30000,     -1.59754,     68.96799,50.00000,41.00000,2.098027e-10,0.78718,4
300.01801, 800.70000,     -1.59657,     68.91412,50.00000,41.00000,2.104702e-10,0.78719,4
300.01501, 804.10000,     -1.59772,     68.83300,50.00000,41.00000,2.105007e-10,0.78719,4
300.01401, 807.50000,     -1.59753,     68.73181,50.00000,41.00000,2.104550e-10,0.78720,4
300.02600, 810.90000,     -1.59813,     68.65765,50.00000,41.00000,2.116184e-10,0.78719,4
300.00699, 814.30000,     -1.59713,     68.60358,50.00000,41.00000,2.111836e-10,0.78719,4
299.99899, 817.70000,     -1.59846,     68.46879,50.00000,41.00000,2.111549e-10,0.78719,4
300.01300, 821.10000,     -1.59907,     68.40795,50.00000,41.00000,2.115402e-10,0.78719,4
300.00800, 824.50000,     -1.60060,     68.30676,50.00000,41.00000,2.118110e-10,0.78719,4
300.01599, 827.90000,     -1.59965,     68.23936,50.00000,41.00000,2.120571e-10,0.78718,4
300.02499, 831.30000,     -1.60140,     68.15169,50.00000,41.00000,1.975307e-10,0.78719,4
300.01801, 834.70000,     -1.60062,     68.05706,50.00000,42.00000,1.965485e-10,0.78720,4
300.02399, 838.10000,     -1.60140,     68.02783,50.00000,42.00000,1.977501e-10,0.78720,4
300.01801, 841.50000,     -1.60254,     67.95368,50.00000,42.00000,1.974812e-10,0.78719,4
300.04700, 844.90000,     -1.60318,     67.87276,50.00000,42.00000,1.974220e-10,0.78718,4
300.01700, 848.30000,     -1.60447,     67.78489,50.00000,42.00000,1.980457e-10,0.78720,4
300.01001, 851.70000,     -1.60503,     67.69722,50.00000,42.00000,1.981678e-10,0.78719,4
300.02802, 855.10000,     -1.60565,     67.63658,50.00000,42.00000,1.966496e-10,0.78719,4
300.01901, 858.50000,     -1.60486,     67.58250,50.00000,42.00000,1.972409e-10,0.78720,4
300.01099, 861.90000,     -1.60600,     67.47237,50.00000,42.00000,1.972943e-10,0.78719,4
300.00500, 865.30000,     -1.60599,     67.39145,50.00000,42.00000,1.975097e-10,0.78719,4
300.01999, 868.70000,     -1.60409,     67.29682,50.00000,42.00000,1.974068e-10,0.78721,4
300.01700, 872.10000,     -1.60428,     67.24513,50.00000,42.00000,1.979618e-10,0.78719,4
300.02499, 875.50000,     -1.60525,     67.17316,50.00000,42.00000,1.977997e-10,0.78719,4
300.01501, 878.90000,     -1.60254,     67.07197,50.00000,42.00000,1.985321e-10,0.78718,4
300.01599, 882.30000,     -1.60370,     67.00457,50.00000,42.00000,1.989136e-10,0.78719,4
300.02399, 885.70000,     -1.60410,     66.91670,50.00000,42.00000,1.981125e-10,0.78720,4
300.01599, 889.10000,     -1.60485,     66.84254,50.00000,42.00000,1.988354e-10,0.78720,4
300.01099, 892.50000,     -1.60561,     66.75487,50.00000,42.00000,1.994819e-10,0.78720,4
300.01999, 895.90000,     -1.60602,     66.70080,50.00000,42.00000,1.983280e-10,0.78719,4
300.01999, 899.30000,     -1.60602,     66.61312,50.00000,42.00000,1.988315e-10,0.78719,4
300.02200, 902.70000,     -1.60795,     66.55249,50.00000,42.00000,1.990814e-10,0.78720,4
300.03000, 906.10000,     -1.60989,     66.43777,50.00000,42.00000,1.997586e-10,0.78719,4
300.01901, 909.50000,     -1.61064,     66.36581,50.00000,42.00000,1.988715e-10,0.78718,4
300.00900, 912.90000,     -1.60927,     66.27793,50.00000,42.00000,2.001247e-10,0.78719,4
300.00500, 916.30000,     -1.60946,     66.19026,50.00000,42.00000,2.005062e-10,0.78719,4
300.02200, 919.70000,     -1.60814,     66.12962,50.00000,42.00000,1.997833e-10,0.78719,4
300.00900, 923.10000,     -1.61004,     66.06203,50.00000,42.00000,2.008228e-10,0.78719,4
300.00900, 926.50000,     -1.60888,     65.96083,50.00000,42.00000,2.009258e-10,0.78720,4
300.02301, 929.90000,     -1.61238,     65.85964,50.00000,42.00000,2.002372e-10,0.78719,4
300.02100, 933.30000,     -1.61257,     65.78549,50.00000,42.00000,2.015438e-10,0.78718,4
300.01099, 936.70000,     -1.61197,     65.71113,50.00000,42.00000,2.018185e-10,0.78719,4
300.01300, 940.10000,     -1.61198,     65.65050,50.00000,42.00000,2.015553e-10,0.78718,4
300.01901, 943.50000,     -1.61314,     65.53579,50.00000,42.00000,2.011947e-10,0.78719,4
300.01300, 946.90000,     -1.61255,     65.47515,50.00000,42.00000,2.024784e-10,0.78719,4
300.01501, 950.30000,     -1.61333,     65.37376,50.00000,42.00000,2.025776e-10,0.78718,4
300.00900, 953.70000,     -1.61216,     65.32664,50.00000,42.00000,2.026387e-10,0.78720,4
300.02899, 957.10000,     -1.61297,     65.26581,50.00000,42.00000,2.028180e-10,0.78719,4
300.01901, 960.50000,     -1.61430,     65.14891,50.00000,42.00000,2.038555e-10,0.78718,4
300.01999, 963.90000,     -1.61546,     65.08151,50.00000,42.00000,2.031841e-10,0.78718,4
300.01700, 967.30000,     -1.61507,     65.02068,50.00000,42.00000,2.031021e-10,0.78718,4
300.01599, 970.70000,     -1.61622,     64.90596,50.00000,42.00000,2.036628e-10,0.78718,4
300.01099, 974.10000,     -1.61486,     64.84533,50.00000,42.00000,2.032928e-10,0.78718,4
300.00699, 977.50000,     -1.61697,     64.78449,50.00000,42.00000,2.039166e-10,0.78720,4
300.00699, 980.90000,     -1.61601,     64.71034,50.00000,42.00000,2.041549e-10,0.78720,4
300.01700, 984.30000,     -1.61911,     64.62266,50.00000,42.00000,2.042961e-10,0.78720,4
300.01099, 987.70000,     -1.61775,     64.53499,50.00000,42.00000,2.042676e-10,0.78718,4
300.01099, 991.10000,     -1.61756,     64.46740,50.00000,42.00000,2.051868e-10,0.78719,4
300.01901, 994.50000,     -1.61969,     64.37296,50.00000,42.00000,2.045517e-10,0.78720,4
300.01700, 997.90000,     -1.61950,     64.28529,50.00000,42.00000,2.047539e-10,0.78719,4
300.01300,1001.30000,     -1.61988,     64.21769,50.00000,42.00000,2.045765e-10,0.78720,4
300.02600,1004.70000,     -1.62144,     64.13897,50.00000,42.00000,2.050896e-10,0.78719,4
300.01401,1008.10000,     -1.62065,     64.04453,50.00000,42.00000,2.055874e-10,0.78719,4
300.02200,1011.50000,     -1.62278,     63.97038,50.00000,42.00000,2.051086e-10,0.78719,4
300.02802,1014.90000,     -1.61933,     63.87594,50.00000,42.00000,2.062301e-10,0.78718,4
300.01401,1018.30000,     -1.62161,     63.78151,50.00000,42.00000,2.061443e-10,0.78720,4
300.01700,1021.70000,     -1.62123,     63.73419,50.00000,42.00000,2.065200e-10,0.78719,4
300.01401,1025.10000,     -1.62546,     63.65328,50.00000,42.00000,2.062187e-10,0.78718,4
300.01901,1028.50000,     -1.62336,     63.57893,50.00000,42.00000,2.066479e-10,0.78719,4
300.01300,1031.90000,     -1.62411,     63.51829,50.00000,42.00000,2.068653e-10,0.78720,4
300.00699,1035.30000,     -1.62468,     63.41252,50.00000,42.00000,2.065468e-10,0.78719,4
300.01501,1038.70000,     -1.62277,     63.36541,50.00000,42.00000,2.067623e-10,0.78719,4
300.01999,1042.10000,     -1.62259,     63.27078,50.00000,42.00000,2.067242e-10,0.78718,4
300.01999,1045.50000,     -1.62316,     63.20795,50.00000,42.00000,2.072830e-10,0.78719,4
300.01700,1048.90000,     -1.62509,     63.13360,50.00000,42.00000,2.080765e-10,0.78720,4
300.00800,1052.30000,     -1.62661,     63.04135,50.00000,42.00000,2.084217e-10,0.78720,4
300.00900,1055.70000,     -1.62912,     62.95368,50.00000,42.00000,2.083492e-10,0.78719,4
300.02200,1059.10000,     -1.62876,     62.91332,50.00000,42.00000,2.082462e-10,0.78719,4
300.02499,1062.50000,     -1.62722,     62.81869,50.00000,42.00000,2.085018e-10,0.78719,4
300.01599,1065.90000,     -1.62778,     62.76481,50.00000,42.00000,2.089043e-10,0.78720,4
300.01401,1069.30000,     -1.62778,     62.68390,50.00000,42.00000,2.089386e-10,0.78719,4
300.01599,1072.70000,     -1.62605,     62.58926,50.00000,42.00000,2.081242e-10,0.78719,4
300.00201,1076.10000,     -1.62698,     62.54891,50.00000,42.00000,2.095051e-10,0.78719,4
300.01801,1079.50000,     -1.62624,     62.48807,50.00000,42.00000,2.092723e-10,0.78719,4
300.01300,1082.90000,     -1.62739,     62.40040,50.00000,41.00000,2.099781e-10,0.78721,4
300.01901,1086.30000,     -1.62702,     62.33976,50.00000,41.00000,2.096043e-10,0.78720,4
300.01099,1089.70000,     -1.62527,     62.28569,50.00000,41.00000,2.102471e-10,0.78720,4
300.02399,1093.10000,     -1.62876,     62.17773,50.00000,41.00000,2.099476e-10,0.78720,4
300.01300,1096.50000,     -1.62720,     62.10577,50.00000,41.00000,2.095871e-10,0.78719,4
300.00500,1099.90000,     -1.62699,     62.01133,50.00000,41.00000,2.108002e-10,0.78719,4
300.01599,1103.30000,     -1.62662,     61.94394,50.00000,41.00000,2.102699e-10,0.78720,4
300.02301,1106.70000,     -1.62606,     61.86064,50.00000,41.00000,2.111053e-10,0.78720,4
300.01599,1110.10000,     -1.62778,     61.79761,50.00000,41.00000,2.115002e-10,0.78718,4
300.01801,1113.50000,     -1.62798,     61.70994,50.00000,41.00000,2.114868e-10,0.78719,4
300.02100,1116.90000,     -1.62625,     61.60199,50.00000,41.00000,2.114601e-10,0.78719,4
300.01999,1120.30000,     -1.62625,     61.54115,50.00000,41.00000,2.118435e-10,0.78718,4
300.01901,1123.70000,     -1.62836,     61.43996,50.00000,41.00000,2.113132e-10,0.78719,4
300.00500,1127.10000,     -1.62622,     61.34553,50.00000,41.00000,2.114161e-10,0.78719,4
300.01001,1130.50000,     -1.62469,     61.29165,50.00000,41.00000,2.121715e-10,0.78718,4
300.01501,1133.90000,     -1.62566,     61.19046,50.00000,41.00000,2.117767e-10,0.78719,4
300.01099,1137.30000,     -1.62507,     61.11849,50.00000,41.00000,2.115994e-10,0.78720,4
300.00900,1140.70000,     -1.62391,     61.02386,50.00000,41.00000,2.118454e-10,0.78719,4
300.01801,1144.10000,     -1.62470,     60.95865,50.00000,40.00000,2.116986e-10,0.78718,4
300.02499,1147.50000,     -1.62452,     60.85070,50.00000,40.00000,2.120610e-10,0.78720,4
300.01501,1150.90000,     -1.62373,     60.77873,50.00000,40.00000,2.122135e-10,0.78719,4
300.01599,1154.30000,     -1.62585,     60.67078,50.00000,40.00000,2.118417e-10,0.78719,4
300.01001,1157.70000,     -1.62430,     60.58310,50.00000,40.00000,2.121696e-10,0.78720,4
300.01199,1161.10000,     -1.62450,     60.52903,50.00000,40.00000,2.111473e-10,0.78718,4
300.02301,1164.50000,     -1.62510,     60.45487,50.00000,40.00000,2.121639e-10,0.78720,4
300.02600,1167.90000,     -1.62337,     60.36262,50.00000,40.00000,2.124042e-10,0.78719,4
300.01700,1171.30000,     -1.62489,     60.27495,50.00000,40.00000,2.133408e-10,0.78719,4
300.01501,1174.70000,     -1.62527,     60.19404,50.00000,40.00000,2.121563e-10,0.78719,4
300.01300,1178.10000,     -1.62488,     60.11292,50.00000,40.00000,2.125892e-10,0.78719,4
300.01901,1181.50000,     -1.62355,     60.00497,50.00000,40.00000,2.129936e-10,0.78718,4
300.02499,1184.90000,     -1.62645,     59.92406,50.00000,40.00000,2.125760e-10,0.78717,4
300.02701,1188.30000,     -1.62607,     59.85666,50.00000,40.00000,2.120437e-10,0.78719,4
300.01901,1191.70000,     -1.62490,     59.77555,50.00000,40.00000,2.128124e-10,0.78719,4
300.02399,1195.10000,     -1.62703,     59.67435,50.00000,40.00000,2.130413e-10,0.78719,4
300.02600,1198.50000,     -1.62876,     59.60696,50.00000,40.00000,2.125206e-10,0.78719,4
300.00900,1201.90000,     -1.62815,     59.51252,50.00000,40.00000,2.126674e-10,0.78719,4
300.01199,1205.30000,     -1.62585,     59.43817,50.00000,40.00000,2.121086e-10,0.78719,4
300.00900,1208.70000,     -1.62468,     59.35726,50.00000,40.00000,2.129059e-10,0.78719,4
300.02200,1212.10000,     -1.62317,     59.26282,50.00000,40.00000,2.126083e-10,0.78720,4
300.01501,1215.50000,     -1.62527,     59.17515,50.00000,40.00000,2.131366e-10,0.78720,4
300.01700,1218.90000,     -1.62663,     59.09404,50.00000,40.00000,2.134113e-10,0.78720,4
300.02200,1222.30000,     -1.62606,     59.04016,50.00000,40.00000,2.134037e-10,0.78719,4
300.01999,1225.70000,     -1.62605,     58.93221,50.00000,40.00000,2.130642e-10,0.78719,4
300.02899,1229.10000,     -1.62549,     58.86243,50.00000,40.00000,2.139969e-10,0.78720,4
300.01300,1232.50000,     -1.62720,     58.76123,50.00000,40.00000,2.140293e-10,0.78718,4
300.01401,1235.90000,     -1.62604,     58.69602,50.00000,40.00000,2.143021e-10,0.78716,4
300.01001,1239.30000,     -1.62507,     58.60159,50.00000,40.00000,2.150498e-10,0.78720,4
300.00201,1242.70000,     -1.62583,     58.51392,50.00000,40.00000,2.141285e-10,0.78720,4
300.01700,1246.10000,     -1.62374,     58.41928,50.00000,40.00000,2.148742e-10,0.78719,4
300.01801,1249.50000,     -1.62586,     58.35189,50.00000,40.00000,2.154503e-10,0.78720,4
300.01700,1252.90000,     -1.62682,     58.27316,50.00000,40.00000,2.151185e-10,0.78719,4
300.01700,1256.30000,     -1.62682,     58.14950,50.00000,40.00000,2.149792e-10,0.78720,4
300.06799,1257.13500,     -1.60861,     58.06859,50.00000,50.00000,2.155876e-10,0.78720,5
300.43399,1257.30500,     -1.35812,     58.01451,50.00000,50.00000,2.148208e-10,0.78720,5
301.36600,1257.47500,     -0.78663,     57.92684,50.00000,50.00000,2.154350e-10,0.78719,5
302.94699,1257.64500, 5.955320e-02,     57.94930,50.00000,50.00000,2.158603e-10,0.78720,5
305.12299,1257.81500,      1.04373,     58.21471,50.00000,50.00000,2.156963e-10,0.78719,5
307.79099,1257.98500,      2.01423,     58.49125,50.00000,50.00000,2.159824e-10,0.78719,5
310.76099,1258.15500,      2.84103,     58.80179,50.00000,50.00000,2.157517e-10,0.78719,5
313.86700,1258.32500,      3.44677,     59.01769,50.00000,50.00000,2.158356e-10,0.78720,5
316.98300,1258.49500,      3.81747,     59.17734,50.00000,50.00000,2.155361e-10,0.78719,5
320.01999,1258.66500,      3.97448,     59.28310,50.00000,50.00000,2.159729e-10,0.78719,5
322.97601,1258.83500,      3.98923,     59.34374,50.00000,50.00000,2.154655e-10,0.78719,5
325.84201,1259.00500,      3.92294,     59.39781,50.00000,50.00000,2.150689e-10,0.78718,5
328.67801,1259.17500,      3.84587,     59.45169,50.00000,50.00000,2.155609e-10,0.78718,5
331.51501,1259.34500,      3.80071,     59.47873,50.00000,50.00000,2.157688e-10,0.78719,5
334.42200,1259.51500,      3.82712,     59.53280,50.00000,50.00000,2.157154e-10,0.78719,5
337.45300,1259.68500,      3.92839,     59.57992,50.00000,50.00000,2.158585e-10,0.78718,5
340.60599,1259.85500,      4.09367,     59.64294,50.00000,50.00000,2.163563e-10,0.78718,5
343.90302,1260.02500,      4.30440,     59.69682,50.00000,50.00000,2.158261e-10,0.78719,5
347.32199,1260.19500,      4.52887,     59.74414,50.00000,50.00000,2.151451e-10,0.78718,5
350.85300,1260.36500,      4.74348,     59.79145,50.00000,50.00000,2.160968e-10,0.78718,5
354.43900,1260.53500,      4.92536,     59.83419,50.00000,50.00000,2.161446e-10,0.78719,5
358.06500,1260.70500,      5.06319,     59.86103,50.00000,50.00000,2.160416e-10,0.78719,5
361.72101,1260.87500,      5.16192,     59.83419,50.00000,50.00000,2.160530e-10,0.78720,5
365.36801,1261.04500,      5.22219,     59.77336,50.00000,50.00000,2.158222e-10,0.78719,5
369.00699,1261.21500,      5.25709,     59.67217,50.00000,50.00000,2.150688e-10,0.78719,5
372.65399,1261.38500,      5.27799,     59.50119,50.00000,50.00000,2.154617e-10,0.78719,5
376.29300,1261.55500,      5.29431,     59.26740,50.00000,50.00000,2.160396e-10,0.78720,5
379.95300,1261.72500,      5.32986,     58.92087,50.00000,50.00000,2.153492e-10,0.78720,5
383.60300,1261.89500,      5.36862,     58.42604,50.00000,50.00000,2.157821e-10,0.78719,5
387.27399,1262.06500,      5.41409,     57.82565,50.00000,50.00000,2.153663e-10,0.78719,5
390.94901,1262.23500,      5.45779,     57.03380,50.00000,50.00000,2.158432e-10,0.78719,5
394.65601,1262.40500,      5.50773,     56.13638,50.00000,50.00000,2.157707e-10,0.78719,5
398.34100,1262.57500,      5.56905,     54.98708,50.00000,50.00000,2.160396e-10,0.78720,5
402.03799,1262.74500,      5.72452,     53.54533,50.00000,50.00000,2.164478e-10,0.78719,5
405.73401,1262.91500,      5.84104,     51.73698,50.00000,50.00000,2.163925e-10,0.78719,5
409.43100,1263.08500,      6.03025,     49.59364,50.00000,50.00000,2.160149e-10,0.78719,5
413.10901,1263.25500,      6.24424,     46.96421,50.00000,50.00000,2.158623e-10,0.78719,5
416.77200,1263.42500,      6.48181,     43.78390,50.00000,50.00000,2.165375e-10,0.78719,5
420.42999,1263.59500,      6.76363,     39.98966,50.00000,50.00000,2.162361e-10,0.78719,5
424.07199,1263.76500,      7.03322,     35.68469,50.00000,50.00000,2.163944e-10,0.78719,5
427.70700,1263.93500,      7.27293,     30.84672,50.00000,50.00000,2.156162e-10,0.78720,5
431.34201,1264.10500,      7.44948,     25.59026,50.00000,50.00000,2.161732e-10,0.78719,5
434.94699,1264.27500,      7.52213,     20.17197,50.00000,50.00000,2.161102e-10,0.78719,5
438.55301,1264.44500,      7.44467,     14.99225,50.00000,50.00000,2.165337e-10,0.78718,5
442.15201,1264.61500,      7.16686,     10.31153,50.00000,50.00000,2.160129e-10,0.78719,5
445.76501,1264.78500,      6.70579,      6.44533,50.00000,50.00000,2.157307e-10,0.78719,5
449.33801,1264.95500,      6.11007,      3.50338,50.00000,50.00000,2.164230e-10,0.78719,5
452.92999,1265.12500,      5.46297,      1.54652,50.00000,50.00000,2.155285e-10,0.78718,5
456.51001,1265.29500,      4.84295,      0.21948,50.00000,50.00000,2.164956e-10,0.78720,5
460.07101,1265.46500,      4.31143,     -0.62167,50.00000,50.00000,2.161541e-10,0.78720,5
463.66299,1265.63500,      3.88697,     -1.15706,50.00000,50.00000,2.162819e-10,0.78719,5
467.22101,1265.80500,      3.55474,     -1.48767,50.00000,50.00000,2.167034e-10,0.78720,5
470.77802,1265.97500,      3.29075,     -1.67654,50.00000,50.00000,2.166118e-10,0.78720,5
474.34000,1266.14500,      3.07716,     -1.76203,50.00000,50.00000,2.153949e-10,0.78720,5
477.86401,1266.31500,      2.88779,     -1.84751,50.00000,50.00000,2.165546e-10,0.78720,5
481.41199,1266.48500,      2.72106,     -1.87455,50.00000,50.00000,2.164058e-10,0.78720,5
484.92401,1266.65500,      2.57365,     -1.87455,50.00000,50.00000,2.163353e-10,0.78720,5
488.43600,1266.82500,      2.43760,     -1.86779,50.00000,50.00000,2.161751e-10,0.78720,5
491.94000,1266.99500,      2.31232,     -1.82048,50.00000,50.00000,2.164822e-10,0.78720,5
495.45099,1267.16500,      2.20349,     -1.79344,50.00000,50.00000,2.160721e-10,0.78718,5
498.96799,1267.33500,      2.09660,     -1.76660,50.00000,50.00000,2.163391e-10,0.78720,5
502.42001,1267.50500,      1.98372,     -1.70577,50.00000,50.00000,2.166633e-10,0.78719,5
505.89899,1267.67500,      1.87186,     -1.68549,50.00000,50.00000,2.165336e-10,0.78719,5
509.37399,1267.84500,      1.76119,     -1.65845,50.00000,50.00000,2.154045e-10,0.78720,5
512.85699,1268.01500,      1.64771,     -1.60457,50.00000,50.00000,2.159462e-10,0.78720,5
516.30298,1268.18500,      1.53896,     -1.55050,50.00000,50.00000,2.167149e-10,0.78720,5
519.75299,1268.35500,      1.43255,     -1.52366,50.00000,50.00000,2.164669e-10,0.78719,5
523.22400,1268.52500,      1.32467,     -1.46958,50.00000,50.00000,2.166767e-10,0.78719,5
526.66400,1268.69500,      1.21654,     -1.44254,50.00000,50.00000,2.161617e-10,0.78719,5
530.12000,1268.86500,      1.10745,     -1.38867,50.00000,50.00000,2.159386e-10,0.78719,5
533.55402,1269.03500,      1.00310,     -1.36839,50.00000,50.00000,2.165699e-10,0.78720,5
536.99902,1269.20500,      0.89757,     -1.33459,50.00000,50.00000,2.174320e-10,0.78719,5
540.42999,1269.37500,      0.79058,     -1.28072,50.00000,50.00000,2.168656e-10,0.78719,5
543.86401,1269.54500,      0.68186,     -1.22664,50.00000,50.00000,2.171402e-10,0.78719,5
547.30798,1269.71500,      0.57726,     -1.17276,50.00000,50.00000,2.165375e-10,0.78718,5
550.73700,1269.88500,      0.46803,     -1.15249,50.00000,50.00000,2.162646e-10,0.78719,5
554.16199,1270.05500,      0.36028,     -1.11869,50.00000,50.00000,2.171783e-10,0.78719,5
557.59198,1270.22500,      0.25137,     -1.06481,50.00000,50.00000,2.174815e-10,0.78719,5
561.02100,1270.39500,      0.13968,     -1.01074,50.00000,50.00000,2.169114e-10,0.78719,5
564.45599,1270.56500, 1.895184e-02,     -0.98370,50.00000,50.00000,2.164974e-10,0.78719,5
567.88000,1270.73500,-9.323562e-02,     -0.95686,50.00000,50.00000,2.165432e-10,0.78718,5
571.30902,1270.90500,     -0.20250,     -0.92982,50.00000,50.00000,2.170505e-10,0.78718,5
574.72400,1271.07500,     -0.30303,     -0.87575,50.00000,50.00000,2.170257e-10,0.78719,5
578.13898,1271.24500,     -0.41946,     -0.87575,50.00000,50.00000,2.167817e-10,0.78718,5
581.56299,1271.41500,     -0.53210,     -0.82187,50.00000,50.00000,2.169036e-10,0.78719,5
584.98499,1271.58500,     -0.64754,     -0.76779,50.00000,50.00000,2.168503e-10,0.78720,5
588.41199,1271.75500,     -0.75690,     -0.71392,50.00000,50.00000,2.173862e-10,0.78719,5
591.83502,1271.92500,     -0.87377,     -0.68688,50.00000,50.00000,2.170811e-10,0.78719,5
595.25299,1272.09500,     -0.98533,     -0.70716,50.00000,50.00000,2.172794e-10,0.78720,5
598.67401,1272.26500,     -1.09939,     -0.65308,50.00000,50.00000,2.166558e-10,0.78719,5
602.09100,1272.43500,     -1.20946,     -0.59920,50.00000,50.00000,2.167796e-10,0.78719,5
605.50897,1272.60500,     -1.32258,     -0.57217,50.00000,50.00000,2.170849e-10,0.78719,5
608.93402,1272.77500,     -1.43565,     -0.54513,50.00000,50.00000,2.169418e-10,0.78719,5
612.35797,1272.94500,     -1.54921,     -0.50477,50.00000,50.00000,2.179393e-10,0.78719,5
615.78302,1273.11500,     -1.67187,     -0.47097,50.00000,50.00000,2.170848e-10,0.78720,5
619.18903,1273.28500,     -1.79102,     -0.45070,50.00000,50.00000,2.170486e-10,0.78719,5
622.61102,1273.45500,     -1.91157,     -0.38091,50.00000,50.00000,2.172317e-10,0.78719,5
626.01801,1273.62500,     -2.02681,     -0.40119,50.00000,50.00000,2.173176e-10,0.78719,5
629.43201,1273.79500,     -2.14834,     -0.34493,50.00000,50.00000,2.174549e-10,0.78719,5
632.85699,1273.96500,     -2.26514,     -0.34950,50.00000,50.00000,2.169018e-10,0.78719,5
636.26202,1274.13500,     -2.38352,     -0.29563,50.00000,50.00000,2.173824e-10,0.78718,5
639.67499,1274.30500,     -2.49796,     -0.26859,50.00000,50.00000,2.168350e-10,0.78719,5
643.09198,1274.47500,     -2.61903,     -0.24155,50.00000,50.00000,2.170697e-10,0.78719,5
646.51202,1274.64500,     -2.73908,     -0.18767,50.00000,50.00000,2.175046e-10,0.78719,5
649.91998,1274.81500,     -2.85627,     -0.16064,50.00000,50.00000,2.171555e-10,0.78719,5
653.32501,1274.98500,     -2.97923,     -0.10656,50.00000,50.00000,2.176551e-10,0.78719,5
656.74298,1275.15500,     -3.09490,     -0.10656,50.00000,50.00000,2.169762e-10,0.78718,5
660.14801,1275.32500,     -3.21001,-7.733598e-02,50.00000,50.00000,2.174759e-10,0.78720,5
663.56097,1275.49500,     -3.32583,-7.057654e-02,50.00000,50.00000,2.172203e-10,0.78719,5
666.97302,1275.66500,     -3.44262,-4.353877e-02,50.00000,50.00000,2.170982e-10,0.78719,5
670.39801,1275.83500,     -3.55619, 1.033797e-02,50.00000,50.00000,2.175236e-10,0.78719,5
673.80402,1276.00500,     -3.66639, 3.737575e-02,50.00000,50.00000,2.176514e-10,0.78719,5
677.22198,1276.17500,     -3.77756, 6.441352e-02,50.00000,50.00000,2.173843e-10,0.78719,5
680.64001,1276.34500,     -3.91046, 9.125249e-02,50.00000,50.00000,2.180671e-10,0.78719,5
684.05603,1276.51500,     -4.02970,      0.14533,50.00000,50.00000,2.177830e-10,0.78719,5
687.45801,1276.68500,     -4.14492,      0.14533,50.00000,50.00000,2.173329e-10,0.78719,5
690.87598,1276.85500,     -4.26023,      0.17237,50.00000,50.00000,2.173652e-10,0.78719,5
694.30103,1277.02500,     -4.38084,      0.23082,50.00000,50.00000,2.177257e-10,0.78719,5
697.72101,1277.19500,     -4.49433,      0.23082,50.00000,50.00000,2.173672e-10,0.78719,5
701.13898,1277.36500,     -4.61279,      0.25785,50.00000,50.00000,2.164402e-10,0.78719,5
704.55603,1277.53500,     -4.72845,      0.31173,50.00000,50.00000,2.180405e-10,0.78719,5
707.98901,1277.70500,     -4.85580,      0.31173,50.00000,50.00000,2.176113e-10,0.78720,5
711.39600,1277.87500,     -4.96892,      0.33877,50.00000,50.00000,2.178783e-10,0.78720,5
714.81897,1278.04500,     -5.08620,      0.36581,50.00000,50.00000,2.176151e-10,0.78719,5
718.23401,1278.21500,     -5.20724,      0.39264,50.00000,50.00000,2.168598e-10,0.78719,5
721.65900,1278.38500,     -5.33978,      0.43996,50.00000,50.00000,2.171726e-10,0.78719,5
725.07098,1278.55500,     -5.47331,      0.47376,50.00000,50.00000,2.174301e-10,0.78720,5
728.48999,1278.72500,     -5.61879,      0.50060,50.00000,50.00000,2.180958e-10,0.78719,5
731.91803,1278.89500,     -5.75389,      0.55467,50.00000,50.00000,2.173862e-10,0.78719,5
735.32800,1279.06500,     -5.89350,      0.58171,50.00000,50.00000,2.170277e-10,0.78719,5
738.74402,1279.23500,     -6.02455,      0.62883,50.00000,50.00000,2.176456e-10,0.78719,5
742.17700,1279.40500,     -6.16255,      0.66262,50.00000,50.00000,2.183743e-10,0.78719,5
745.58502,1279.57500,     -6.30312,      0.68966,50.00000,50.00000,2.174835e-10,0.78719,5
749.00897,1279.74500,     -6.44879,      0.70994,50.00000,50.00000,2.179794e-10,0.78719,5
752.42798,1279.91500,     -6.59295,      0.74354,50.00000,50.00000,2.174664e-10,0.78720,5
755.83801,1280.08500,     -6.74999,      0.77058,50.00000,50.00000,2.184181e-10,0.78720,5
759.26599,1280.25500,     -6.89553,      0.82445,50.00000,50.00000,2.180137e-10,0.78719,5
762.67401,1280.42500,     -7.04539,      0.85149,50.00000,50.00000,2.185955e-10,0.78719,5
766.08801,1280.59500,     -7.20539,      0.88529,50.00000,50.00000,2.172374e-10,0.78720,5
769.51202,1280.76500,     -7.35807,      0.93479,50.00000,50.00000,2.178879e-10,0.78719,5
772.92297,1280.93500,     -7.51354,      0.96859,50.00000,50.00000,2.183570e-10,0.78719,5
776.33698,1281.10500,     -7.67092,      1.01789,50.00000,50.00000,2.178688e-10,0.78719,5
779.76703,1281.27500,     -7.82329,      1.03817,50.00000,50.00000,2.178784e-10,0.78720,5
783.17700,1281.44500,     -7.97137,      1.07197,50.00000,50.00000,2.175313e-10,0.78720,5
786.59497,1281.61500,     -8.11129,      1.09901,50.00000,50.00000,2.188130e-10,0.78719,5
790.01501,1281.78500,     -8.25981,      1.15288,50.00000,50.00000,            ,0.44889,5
793.43903,1281.95500,     -8.39840,      1.17992,50.00000,50.00000,            ,0.44752,5
794.33899,1282.00000,     -8.43639,      1.17992,50.00000,50.00000,            ,0.44716,5