File: data/TGA/005d-L_M/ExpDat_2025_07_04_SL_PS_Tosoh_F1_isothermal.csv
#EXPORTTYPE:                 ,DATA ALL
#FILE:                       ,2025_07_04_SL_PS_Tosoh_F1_isothermal.ngb-ss5
#FORMAT:                     ,NETZSCH5
#FTYPE:                      ,ASCII
#IDENTITY:                   ,PS-F1
#DECIMAL:                    ,POINT
#SEPARATOR:                  ,COMMA
#MTYPE:                      ,DSC
#INSTRUMENT:                 ,NETZSCH STA 449F5
#PROJECT:                    ,PS
#DATE/TIME:                  ,7/4/2025 6:12:43 PM (UTC-4)
#CORR. FILE:                 ,
#TEMPCAL:                    ,05-05-2025 14:38
#SENSITIVITY:                ,28-06-2023 13:53
#LABORATORY:                 ,Tran/AAG
#OPERATOR:                   ,Stanley
#REMARK:                     ,2025_03_29_SL_005d_M1_isothermal
#SAMPLE:                     ,PS-F1
#SAMPLE MASS /mg:            ,5.00
#MATERIAL:                   ,Polystyrene
#REFERENCE:                  ,
#REFERENCE MASS /mg:         ,0
#TYPE OF CRUCIBLE:           ,Al2O3 85 ‘l, open
#SAMPLE CRUCIBLE MASS /mg:   ,0
#REFERENCE CRUCIBLE MASS /mg:,0
#DSC RANGE /‘V:              ,5000
#TG RANGE /mg:               ,35000
#TAU-R:                      ,---
#CORR. CODE:                 ,000
#EXO:                        ,-1
#RANGE:                      ,30›C....800›C/0.0....20.0K/min
#SEGMENT:                    ,S1-5/5
#SEG. 1:                     ,30›C/10.0(K/min)/100›C
#SEG. 2:                     ,100›C/00:10/100›C
#SEG. 3:                     ,100›C/5.0(K/min)/300›C
#SEG. 4:                     ,300›C/20:00/300›C
#SEG. 5:                     ,300›C/20.0(K/min)/800›C

##Temp./›C,Time/min,DSC/(mW/mg),Mass/%,Gas Flow(purge2)/(ml/min),Gas Flow(protective)/(ml/min),TIC(scan:1)/A,Sensit./(uV/mW),Segment
 33.63000,   0.00000,     -0.13852,   100.00000,50.00000,50.00000,            ,0.92418,1
 35.15600,   1.36000,      0.24000,   101.39600,50.00000,50.00000,2.967284e-09,0.92419,1
 41.03600,   2.72000,      0.90148,   103.67900,50.00000,50.00000,2.943541e-09,0.92421,1
 50.36900,   4.08000,      1.52723,   105.78780,50.00000,50.00000,2.921263e-09,0.92427,1
 63.42000,   5.44000,      2.23955,   107.60020,50.00000,50.00000,2.908138e-09,0.92440,1
 78.98600,   6.80000,      2.87841,   108.85380,50.00000,50.00000,2.910232e-09,0.92456,1
 88.27000,   7.57917,      3.02391,   109.03940,50.00000,50.00000,2.899435e-09,0.92466,2
 94.80300,   8.25917,      2.59499,   108.17960,50.00000,50.00000,2.894959e-09,0.92476,2
 99.48000,   8.93917,      2.03913,   107.19980,50.00000,50.00000,2.886618e-09,0.92485,2
103.02300,   9.61917,      1.57288,   106.50280,50.00000,50.00000,2.883567e-09,0.92495,2
105.96200,  10.29917,      1.26408,   105.95080,50.00000,50.00000,2.876210e-09,0.92505,2
108.19200,  10.97917,      0.96819,   105.37160,50.00000,50.00000,2.868127e-09,0.92515,2
109.66500,  11.65917,      0.65446,   104.69960,50.00000,50.00000,2.864639e-09,0.92525,2
110.46400,  12.33917,      0.36845,   104.10220,50.00000,50.00000,2.858801e-09,0.92535,2
110.79100,  13.01917,      0.14244,   103.58400,50.00000,50.00000,2.855400e-09,0.92545,2
110.72700,  13.69917,-3.689801e-02,   103.12240,50.00000,50.00000,2.852760e-09,0.92555,2
110.37400,  14.37917,     -0.17832,   102.74240,50.00000,50.00000,2.846743e-09,0.92564,2
109.80100,  15.05917,     -0.28346,   102.38020,50.00000,50.00000,2.841528e-09,0.92576,2
109.05900,  15.73917,     -0.36180,   102.07040,50.00000,50.00000,2.833982e-09,0.92584,2
108.22000,  16.41917,     -0.41169,   101.79880,50.00000,50.00000,2.832533e-09,0.92592,2
107.18800,  17.19917,     -0.44028,   101.58160,50.00000,50.00000,2.829913e-09,0.92600,3
107.05200,  18.55917, 6.491002e-02,   102.30780,50.00000,50.00000,2.811968e-09,0.92613,3
109.63600,  19.91917,      0.59946,   103.03880,50.00000,50.00000,2.811265e-09,0.92619,3
114.04300,  21.27917,      1.04797,   103.59760,50.00000,50.00000,2.791702e-09,0.92620,3
120.17400,  22.63917,      1.46414,   104.01620,50.00000,50.00000,2.788452e-09,0.92613,3
127.43400,  23.99917,      1.75523,   104.15200,50.00000,50.00000,2.776200e-09,0.92599,3
135.27600,  25.35917,      1.91110,   103.97540,50.00000,50.00000,2.773857e-09,0.92574,3
143.40199,  26.71917,      2.01599,   103.47320,50.00000,50.00000,2.770781e-09,0.92542,3
151.43500,  28.07917,      2.06854,   102.80560,50.00000,50.00000,2.762379e-09,0.92500,3
159.26601,  29.43917,      2.08220,   101.84860,50.00000,50.00000,2.764559e-09,0.92455,3
166.83200,  30.79917,      2.07712,   100.80100,50.00000,50.00000,2.756606e-09,0.92423,3
174.13800,  32.15917,      2.06979,    99.59260,50.00000,50.00000,2.747844e-09,0.92392,3
181.26401,  33.51917,      2.06971,    98.38900,50.00000,50.00000,2.746148e-09,0.92361,3
188.25400,  34.87917,      2.07821,    97.09700,50.00000,50.00000,2.740909e-09,0.92325,3
195.17101,  36.23917,      2.09985,    95.88420,50.00000,50.00000,2.737961e-09,0.92294,3
202.00301,  37.59917,      2.13006,    94.61940,50.00000,50.00000,2.737238e-09,0.92263,3
208.79100,  38.95917,      2.16975,    93.32740,50.00000,50.00000,2.736949e-09,0.92234,3
215.56300,  40.31917,      2.21060,    92.03080,50.00000,50.00000,2.733162e-09,0.92202,3
222.33000,  41.67917,      2.26176,    90.72980,50.00000,50.00000,2.728020e-09,0.92176,3
229.07800,  43.03917,      2.30633,    89.33140,50.00000,50.00000,2.725157e-09,0.92151,3
235.81700,  44.39917,      2.35523,    88.03940,50.00000,50.00000,2.719817e-09,0.92124,3
242.58400,  45.75917,      2.39733,    86.86740,50.00000,50.00000,2.718326e-09,0.92102,3
249.34000,  47.11917,      2.44598,    85.82420,50.00000,50.00000,2.719498e-09,0.92080,3
256.11899,  48.47917,      2.48810,    84.82200,50.00000,50.00000,2.714843e-09,0.92059,3
262.89999,  49.83917,      2.53428,    83.87620,50.00000,50.00000,2.713902e-09,0.92036,3
269.67700,  51.19917,      2.57446,    82.94380,50.00000,50.00000,2.717710e-09,0.92016,3
276.46301,  52.55917,      2.61741,    82.02520,50.00000,50.00000,2.715434e-09,0.91996,3
283.23199,  53.91917,      2.66024,    81.12240,50.00000,50.00000,2.711396e-09,0.91975,3
289.98700,  55.27917,      2.70544,    80.21520,50.00000,50.00000,2.710839e-09,0.91957,3
296.74200,  56.63917,      2.75020,    79.28520,50.00000,50.00000,2.710274e-09,0.91939,3
303.02301,  59.49917,      0.92675,    77.33020,50.00000,45.00000,2.702097e-09,0.91904,4
302.73599,  62.89917,      0.40838,    75.53580,50.00000,45.00000,2.705250e-09,0.91870,4
301.46701,  66.29917,      0.43514,    74.68060,50.00000,45.00000,2.701146e-09,0.91844,4
300.68201,  69.69917,      0.50069,    74.13520,50.00000,45.00000,2.711837e-09,0.91825,4
300.31100,  73.09917,      0.54119,    73.72120,50.00000,45.00000,2.710649e-09,0.91813,4
300.15100,  76.49917,      0.56746,    73.39540,50.00000,45.00000,2.714616e-09,0.91806,4
300.06500,  79.89917,      0.57787,    73.12380,50.00000,45.00000,2.713199e-09,0.91804,4
300.04401,  83.29917,      0.58405,    72.86600,50.00000,45.00000,2.712014e-09,0.91806,4
300.01801,  86.69917,      0.58094,    72.61920,50.00000,45.00000,2.709853e-09,0.91810,4
300.01700,  90.09917,      0.57900,    72.47680,50.00000,45.00000,2.709490e-09,0.91818,4
300.01901,  93.49917,      0.57551,    72.27760,50.00000,45.00000,2.711624e-09,0.91828,4
300.01501,  96.89917,      0.57609,    72.10800,50.00000,45.00000,2.713215e-09,0.91841,4
300.00800, 100.29917,      0.57337,    71.97900,50.00000,45.00000,2.710541e-09,0.91855,4
300.01099, 103.69917,      0.57376,    71.83420,50.00000,45.00000,2.710283e-09,0.91869,4
300.00800, 107.09917,      0.57337,    71.69160,50.00000,45.00000,2.716664e-09,0.91885,4
300.01599, 110.49917,      0.57609,    71.64400,50.00000,45.00000,2.712082e-09,0.91901,4
300.01801, 113.89917,      0.57318,    71.50840,50.00000,45.00000,2.713826e-09,0.91924,4
300.00601, 117.29917,      0.57666,    71.39980,50.00000,45.00000,2.712342e-09,0.91916,4
300.00699, 120.69917,      0.57453,    71.29120,50.00000,45.00000,2.716460e-09,0.91877,4
300.01099, 124.09917,      0.57783,    71.20960,50.00000,45.00000,2.711907e-09,0.91816,4
300.00101, 127.49917,      0.57588,    71.11460,50.00000,45.00000,2.720489e-09,0.91731,4
300.01099, 130.89917,      0.57977,    71.01280,50.00000,45.00000,2.720242e-09,0.91624,4
300.01001, 134.29917,      0.57899,    70.94720,50.00000,45.00000,2.715697e-09,0.91485,4
300.02802, 137.69917,      0.57959,    70.83640,50.00000,45.00000,2.715398e-09,0.91322,4
300.01099, 141.09917,      0.58016,    70.75040,50.00000,45.00000,2.720858e-09,0.91146,4
300.01700, 144.49917,      0.58171,    70.66880,50.00000,45.00000,2.716232e-09,0.90944,4
300.01801, 147.89917,      0.58113,    70.60100,50.00000,45.00000,2.716714e-09,0.90724,4
300.01501, 151.29917,      0.58307,    70.51040,50.00000,45.00000,2.720311e-09,0.90491,4
300.00500, 154.69917,      0.58480,    70.40420,50.00000,45.00000,2.712848e-09,0.90258,4
300.00299, 158.09917,      0.58403,    70.33400,50.00000,45.00000,2.714569e-09,0.90006,4
300.01801, 161.49917,      0.58617,    70.25940,50.00000,45.00000,2.712905e-09,0.89750,4
300.01401, 164.89917,      0.58636,    70.18920,50.00000,45.00000,2.714342e-09,0.89487,4
300.01999, 168.29917,      0.58888,    70.10780,50.00000,45.00000,2.709771e-09,0.89234,4
300.01401, 171.69917,      0.58810,    70.02400,50.00000,45.00000,2.714672e-09,0.88965,4
300.02701, 175.09917,      0.58986,    69.97420,50.00000,45.00000,2.715490e-09,0.88692,4
300.01700, 178.49917,      0.58772,    69.89960,50.00000,45.00000,2.717424e-09,0.88416,4
300.02301, 181.89917,      0.58830,    69.80460,50.00000,45.00000,2.715763e-09,0.88149,4
300.02301, 185.29917,      0.59257,    69.76380,50.00000,45.00000,2.722488e-09,0.87863,4
300.01300, 188.69917,      0.58849,    69.66880,50.00000,45.00000,2.719374e-09,0.87574,4
300.01999, 192.09917,      0.59470,    69.58740,50.00000,45.00000,2.720447e-09,0.87279,4
300.01099, 195.49917,      0.59275,    69.49460,50.00000,45.00000,2.719170e-09,0.86994,4
300.01401, 198.89917,      0.59392,    69.42440,50.00000,45.00000,2.722893e-09,0.86690,4
300.00400, 202.29917,      0.59527,    69.34980,50.00000,45.00000,2.722971e-09,0.86382,4
300.02600, 205.69917,      0.59432,    69.25460,50.00000,45.00000,2.717640e-09,0.86069,4
300.01501, 209.09917,      0.59896,    69.18680,50.00000,45.00000,2.720531e-09,0.85764,4
300.01700, 212.49917,      0.59625,    69.13260,50.00000,45.00000,2.721771e-09,0.85440,4
300.01801, 215.89917,      0.59974,    69.01720,50.00000,45.00000,2.720333e-09,0.85112,4
300.01999, 219.29917,      0.59974,    68.96280,50.00000,45.00000,2.720306e-09,0.84793,4
300.01901, 222.69917,      0.60187,    68.90400,50.00000,45.00000,2.726152e-09,0.84457,4
300.02301, 226.09917,      0.60187,    68.80220,50.00000,45.00000,2.720463e-09,0.84112,4
299.99799, 229.49917,      0.60282,    68.74560,50.00000,45.00000,2.723194e-09,0.83767,4
300.01700, 232.89917,      0.60361,    68.67780,50.00000,45.00000,2.722818e-09,0.83431,4
300.01700, 236.29917,      0.60575,    68.58720,50.00000,45.00000,2.725974e-09,0.83075,4
300.01300, 239.69917,      0.60225,    68.51940,50.00000,45.00000,2.727423e-09,0.82716,4
300.01401, 243.09917,      0.60497,    68.46500,50.00000,45.00000,2.731793e-09,0.82369,4
300.02200, 246.49917,      0.60924,    68.34740,50.00000,45.00000,2.723510e-09,0.82002,4
300.02200, 249.89917,      0.60536,    68.28620,50.00000,45.00000,2.728376e-09,0.81632,4
300.02200, 253.29917,      0.60943,    68.20260,50.00000,45.00000,2.724977e-09,0.81258,4
300.02301, 256.69917,      0.61001,    68.13240,50.00000,45.00000,2.731225e-09,0.80900,4
300.01199, 260.09917,      0.60904,    68.08040,50.00000,45.00000,2.728350e-09,0.80521,4
299.99301, 263.49917,      0.61135,    67.98540,50.00000,45.00000,2.729199e-09,0.80142,4
299.99899, 266.89917,      0.61368,    67.93100,50.00000,45.00000,2.723964e-09,0.79759,4
300.00101, 270.29917,      0.61698,    67.85640,50.00000,45.00000,2.748584e-09,0.79392,4
300.01001, 273.69917,      0.61446,    67.80200,50.00000,45.00000,2.766867e-09,0.79005,4
299.99799, 277.09917,      0.61252,    67.71380,50.00000,45.00000,2.763709e-09,0.78524,4
299.99600, 280.49917,      0.61562,    67.62780,50.00000,45.00000,2.766178e-09,0.78405,4
300.01401, 283.89917,      0.61640,    67.58700,50.00000,45.00000,2.771556e-09,0.78448,4
300.01099, 287.29917,      0.61543,    67.50120,50.00000,45.00000,2.767681e-09,0.78526,4
300.00299, 290.69917,      0.61795,    67.44460,50.00000,45.00000,2.776557e-09,0.78590,4
300.01801, 294.09917,      0.62145,    67.34960,50.00000,45.00000,2.769277e-09,0.78637,4
300.01901, 297.49917,      0.62048,    67.31100,50.00000,45.00000,2.770109e-09,0.78670,4
299.99701, 300.89917,      0.62066,    67.23640,50.00000,45.00000,2.775633e-09,0.78689,4
300.01901, 304.29917,      0.62261,    67.13460,50.00000,45.00000,2.777315e-09,0.78701,4
300.01901, 307.69917,      0.62106,    67.11420,50.00000,45.00000,2.779794e-09,0.78708,4
300.02200, 311.09917,      0.62068,    67.03280,50.00000,45.00000,2.772907e-09,0.78713,4
300.00299, 314.49917,      0.62124,    66.97160,50.00000,45.00000,2.773118e-09,0.78715,4
300.01999, 317.89917,      0.62048,    66.87660,50.00000,45.00000,2.781067e-09,0.78717,4
300.01801, 321.29917,      0.62222,    66.84940,50.00000,45.00000,2.780068e-09,0.78717,4
300.00601, 324.69917,      0.62280,    66.76580,50.00000,45.00000,2.781194e-09,0.78719,4
300.00201, 328.09917,      0.62337,    66.71820,50.00000,45.00000,2.783162e-09,0.78718,4
300.02100, 331.49917,      0.62397,    66.60740,50.00000,45.00000,2.784224e-09,0.78719,4
300.02100, 334.89917,      0.62242,    66.55300,50.00000,45.00000,2.787566e-09,0.78719,4
300.01501, 338.29917,      0.62319,    66.51920,50.00000,45.00000,2.784532e-09,0.78720,4
300.02499, 341.69917,      0.62359,    66.40380,50.00000,45.00000,2.784736e-09,0.78718,4
300.02301, 345.09917,      0.62397,    66.37660,50.00000,45.00000,2.783281e-09,0.78719,4
300.02802, 348.49917,      0.62727,    66.30180,50.00000,45.00000,2.787995e-09,0.78719,4
300.00900, 351.89917,      0.62377,    66.24080,50.00000,45.00000,2.785787e-09,0.78719,4
300.01801, 355.29917,      0.62494,    66.16620,50.00000,45.00000,2.787465e-09,0.78719,4
300.01599, 358.69917,      0.62687,    66.09140,50.00000,45.00000,2.788946e-09,0.78720,4
300.01801, 362.09917,      0.62571,    66.03720,50.00000,45.00000,2.784135e-09,0.78719,4
300.01501, 365.49917,      0.62513,    65.97600,50.00000,45.00000,2.792848e-09,0.78719,4
300.01901, 368.89917,      0.62668,    65.90600,50.00000,45.00000,2.788340e-09,0.78720,4
300.01401, 372.29917,      0.62532,    65.85160,50.00000,45.00000,2.787568e-09,0.78720,4
300.01401, 375.69917,      0.62629,    65.77240,50.00000,45.00000,2.787836e-09,0.78719,4
300.01901, 379.09917,      0.62785,    65.70000,50.00000,45.00000,2.784756e-09,0.78719,4
300.01801, 382.49917,      0.62629,    65.62540,50.00000,45.00000,2.783759e-09,0.78719,4
300.02301, 385.89917,      0.62610,    65.59820,50.00000,45.00000,2.782375e-09,0.78720,4
300.02499, 389.29917,      0.62688,    65.49640,50.00000,45.00000,2.785834e-09,0.78720,4
299.99500, 392.69917,      0.62860,    65.44880,50.00000,45.00000,2.780925e-09,0.78721,4
300.00699, 396.09917,      0.62900,    65.37200,50.00000,45.00000,2.787895e-09,0.78719,4
300.01401, 399.49917,      0.63017,    65.32220,50.00000,45.00000,2.786412e-09,0.78719,4
300.01801, 402.89917,      0.63095,    65.28140,50.00000,45.00000,2.788973e-09,0.78720,4
300.01501, 406.29917,      0.62978,    65.16600,50.00000,45.00000,2.790864e-09,0.78718,4
300.02200, 409.69917,      0.62727,    65.12760,50.00000,45.00000,2.786072e-09,0.78719,4
300.03799, 413.09917,      0.63096,    65.07320,50.00000,45.00000,2.787606e-09,0.78720,4
300.01401, 416.49917,      0.62939,    65.03260,50.00000,45.00000,2.792070e-09,0.78720,4
300.02899, 419.89917,      0.62979,    64.97140,50.00000,45.00000,2.784006e-09,0.78719,4
300.01999, 423.29917,      0.62901,    64.89000,50.00000,45.00000,2.793884e-09,0.78719,4
300.02100, 426.69917,      0.62688,    64.84240,50.00000,45.00000,2.784786e-09,0.78720,4
300.02802, 430.09917,      0.62960,    64.79500,50.00000,45.00000,2.783652e-09,0.78719,4
300.01099, 433.49917,      0.62958,    64.68860,50.00000,45.00000,2.786100e-09,0.78719,4
300.01599, 436.89917,      0.62959,    64.65460,50.00000,45.00000,2.781998e-09,0.78719,4
300.00400, 440.29917,      0.62861,    64.60040,50.00000,45.00000,2.784617e-09,0.78720,4
300.01599, 443.69917,      0.62901,    64.51900,50.00000,45.00000,2.784762e-09,0.78719,4
300.00699, 447.09917,      0.63036,    64.46460,50.00000,45.00000,2.784426e-09,0.78719,4
300.01700, 450.49917,      0.63017,    64.39000,50.00000,45.00000,2.776516e-09,0.78719,4
300.00800, 453.89917,      0.62919,    64.30620,50.00000,45.00000,2.777338e-09,0.78718,4
300.02399, 457.29917,      0.63153,    64.26780,50.00000,45.00000,2.778735e-09,0.78718,4
300.01401, 460.69917,      0.62939,    64.18620,50.00000,45.00000,2.775005e-09,0.78720,4
300.01999, 464.09917,      0.63056,    64.11160,50.00000,45.00000,2.772610e-09,0.78719,4
300.01901, 467.49917,      0.63172,    64.06420,50.00000,45.00000,2.769954e-09,0.78718,4
300.01801, 470.89917,      0.63095,    63.96900,50.00000,45.00000,2.776220e-09,0.78718,4
300.02200, 474.29917,      0.62920,    63.94200,50.00000,45.00000,2.779766e-09,0.78719,4
300.02600, 477.69917,      0.63192,    63.88080,50.00000,45.00000,2.774689e-09,0.78718,4
300.03101, 481.09917,      0.63212,    63.80620,50.00000,45.00000,2.771623e-09,0.78719,4
300.00299, 484.49917,      0.63229,    63.77220,50.00000,45.00000,2.771541e-09,0.78719,4
300.01199, 487.89917,      0.63114,    63.70440,50.00000,45.00000,2.773402e-09,0.78720,4
300.01801, 491.29917,      0.63095,    63.62960,50.00000,45.00000,2.776839e-09,0.78720,4
300.01401, 494.69917,      0.63191,    63.54820,50.00000,45.00000,2.778252e-09,0.78719,4
300.01001, 498.09917,      0.62958,    63.48720,50.00000,45.00000,2.780225e-09,0.78719,4
300.01599, 501.49917,      0.63153,    63.44420,50.00000,45.00000,2.776819e-09,0.78719,4
300.01501, 504.89917,      0.63366,    63.40340,50.00000,45.00000,2.771300e-09,0.78719,4
300.00201, 508.29917,      0.63229,    63.33560,50.00000,45.00000,2.775906e-09,0.78720,4
300.00800, 511.69917,      0.63501,    63.25400,50.00000,45.00000,2.771996e-09,0.78719,4
300.01801, 515.09917,      0.63347,    63.21560,50.00000,45.00000,2.775203e-09,0.78720,4
300.01300, 518.49917,      0.63249,    63.12740,50.00000,45.00000,2.775083e-09,0.78720,4
300.02200, 521.89917,      0.63347,    63.05940,50.00000,45.00000,2.780639e-09,0.78719,4
300.01199, 525.29917,      0.63559,    63.01420,50.00000,45.00000,2.773780e-09,0.78719,4
300.01901, 528.69917,      0.63133,    62.95320,50.00000,45.00000,2.765905e-09,0.78718,4
300.02802, 532.09917,      0.63289,    62.89880,50.00000,45.00000,2.778271e-09,0.78718,4
300.01801, 535.49917,      0.63114,    62.84460,50.00000,45.00000,2.775388e-09,0.78719,4
300.01599, 538.89917,      0.63230,    62.79020,50.00000,45.00000,2.773374e-09,0.78719,4
300.02802, 542.29917,      0.63231,    62.71560,50.00000,45.00000,2.773847e-09,0.78719,4
300.01300, 545.69917,      0.63191,    62.63400,50.00000,45.00000,2.775123e-09,0.78719,4
300.01199, 549.09917,      0.63424,    62.58660,50.00000,45.00000,2.771588e-09,0.78718,4
300.00101, 552.49917,      0.63326,    62.53900,50.00000,45.00000,2.775337e-09,0.78718,4
300.02100, 555.89917,      0.63366,    62.47120,50.00000,45.00000,2.778107e-09,0.78719,4
300.00800, 559.29917,      0.63055,    62.38980,50.00000,45.00000,2.768922e-09,0.78720,4
300.02802, 562.69917,      0.63192,    62.32860,50.00000,45.00000,2.778377e-09,0.78719,4
300.00900, 566.09917,      0.63385,    62.28120,50.00000,45.00000,2.781916e-09,0.78719,4
300.00800, 569.49917,      0.63171,    62.21780,50.00000,45.00000,2.779136e-09,0.78720,4
300.01001, 572.89917,      0.63443,    62.14980,50.00000,45.00000,2.776364e-09,0.78719,4
300.01401, 576.29917,      0.63521,    62.11600,50.00000,45.00000,2.775551e-09,0.78720,4
300.01401, 579.69917,      0.63443,    62.01420,50.00000,45.00000,2.775996e-09,0.78720,4
300.01599, 583.09917,      0.63501,    61.98020,50.00000,45.00000,2.778505e-09,0.78719,4
300.01401, 586.49917,      0.63249,    61.91900,50.00000,45.00000,2.774743e-09,0.78718,4
300.01199, 589.89917,      0.63404,    61.83760,50.00000,45.00000,2.779514e-09,0.78719,4
300.02200, 593.29917,      0.63424,    61.77420,50.00000,45.00000,2.781891e-09,0.78719,4
300.02399, 596.69917,      0.63192,    61.71540,50.00000,45.00000,2.779683e-09,0.78718,4
300.00299, 600.09917,      0.63093,    61.64540,50.00000,45.00000,2.769305e-09,0.78719,4
300.01599, 603.49917,      0.63211,    61.59780,50.00000,45.00000,2.779284e-09,0.78718,4
300.01300, 606.89917,      0.62959,    61.52320,50.00000,45.00000,2.777376e-09,0.78720,4
300.00201, 610.29917,      0.63229,    61.48700,50.00000,45.00000,2.775019e-09,0.78720,4
300.01501, 613.69917,      0.63172,    61.41220,50.00000,45.00000,2.778430e-09,0.78722,4
300.03201, 617.09917,      0.63231,    61.35800,50.00000,45.00000,2.809136e-09,0.78722,4
300.02701, 620.49917,      0.63153,    61.32400,50.00000,45.00000,2.808516e-09,0.78722,4
300.01999, 623.89917,      0.62998,    61.22220,50.00000,45.00000,2.808444e-09,0.78720,4
300.00900, 627.29917,      0.63016,    61.17460,50.00000,45.00000,2.805769e-09,0.78720,4
300.02600, 630.69917,      0.63405,    61.10680,50.00000,45.00000,2.810588e-09,0.78720,4
300.01801, 634.09917,      0.63327,    61.03900,50.00000,45.00000,2.811949e-09,0.78720,4
300.01401, 637.49917,      0.63288,    60.99140,50.00000,45.00000,2.811999e-09,0.78721,4
300.01199, 640.89917,      0.63249,    60.93700,50.00000,45.00000,2.809557e-09,0.78721,4
300.01901, 644.29917,      0.63482,    60.88280,50.00000,45.00000,2.808628e-09,0.78719,4
300.02301, 647.69917,      0.63502,    60.82840,50.00000,45.00000,2.808721e-09,0.78719,4
300.01300, 651.09917,      0.63501,    60.74700,50.00000,45.00000,2.808179e-09,0.78719,4
300.02701, 654.49917,      0.63754,    60.69960,50.00000,45.00000,2.805273e-09,0.78718,4
299.99899, 657.89917,      0.63190,    60.61800,50.00000,45.00000,2.811699e-09,0.78719,4
300.01700, 661.29917,      0.63153,    60.59760,50.00000,45.00000,2.803812e-09,0.78719,4
300.01199, 664.69917,      0.63036,    60.49580,50.00000,45.00000,2.807014e-09,0.78719,4
300.00601, 668.09917,      0.63268,    60.43480,50.00000,45.00000,2.809216e-09,0.78720,4
300.01300, 671.49917,      0.63579,    60.36680,50.00000,45.00000,2.800512e-09,0.78719,4
300.01199, 674.89917,      0.63501,    60.30580,50.00000,45.00000,2.802204e-09,0.78720,4
300.01901, 678.29917,      0.63230,    60.24480,50.00000,45.00000,2.806997e-09,0.78719,4
300.03500, 681.69917,      0.63309,    60.19040,50.00000,45.00000,2.801503e-09,0.78720,4
300.03101, 685.09917,      0.62999,    60.13620,50.00000,45.00000,2.800537e-09,0.78720,4
300.01901, 688.49917,      0.63327,    60.04780,50.00000,45.00000,2.805536e-09,0.78719,4
300.02100, 691.89917,      0.63037,    59.99360,50.00000,45.00000,2.801780e-09,0.78719,4
300.00900, 695.29917,      0.63520,    59.91880,50.00000,45.00000,2.807538e-09,0.78719,4
300.02200, 698.69917,      0.63366,    59.88500,50.00000,45.00000,2.806511e-09,0.78720,4
300.00500, 702.09917,      0.63055,    59.83060,50.00000,45.00000,2.806763e-09,0.78719,4
300.01801, 705.49917,      0.63230,    59.76960,50.00000,45.00000,2.800152e-09,0.78721,4
300.01199, 708.89917,      0.63230,    59.70840,50.00000,45.00000,2.803004e-09,0.78719,4
300.01599, 712.29917,      0.63443,    59.66780,50.00000,45.00000,2.799617e-09,0.78719,4
300.01300, 715.69917,      0.63366,    59.59980,50.00000,45.00000,2.801018e-09,0.78720,4
300.02200, 719.09917,      0.63308,    59.52300,50.00000,45.00000,2.800234e-09,0.78720,4
300.01599, 722.49917,      0.63172,    59.47080,50.00000,45.00000,2.801343e-09,0.78720,4
300.02301, 725.89917,      0.63328,    59.39620,50.00000,45.00000,2.798555e-09,0.78719,4
300.02600, 729.29917,      0.63270,    59.34860,50.00000,45.00000,2.798983e-09,0.78719,4
300.01001, 732.69917,      0.63133,    59.30800,50.00000,45.00000,2.802516e-09,0.78720,4
300.01901, 736.09917,      0.63637,    59.27400,50.00000,45.00000,2.800211e-09,0.78719,4
300.00500, 739.49917,      0.63171,    59.17680,50.00000,45.00000,2.805525e-09,0.78719,4
300.01001, 742.89917,      0.63249,    59.15640,50.00000,45.00000,2.799637e-09,0.78718,4
300.01099, 746.29917,      0.63462,    59.05900,50.00000,45.00000,2.806250e-09,0.78718,4
300.01801, 749.69917,      0.63443,    59.02520,50.00000,45.00000,2.807826e-09,0.78720,4
300.03799, 753.09917,      0.63329,    58.97080,50.00000,45.00000,2.808241e-09,0.78719,4
300.03299, 756.49917,      0.63173,    58.93680,50.00000,45.00000,2.808376e-09,0.78719,4
300.00400, 759.89917,      0.63346,    58.85540,50.00000,45.00000,2.805226e-09,0.78719,4
300.00699, 763.29917,      0.63520,    58.77400,50.00000,45.00000,2.807959e-09,0.78719,4
300.01401, 766.69917,      0.63463,    58.71960,50.00000,45.00000,2.813304e-09,0.78719,4
300.00400, 770.09917,      0.63384,    58.67900,50.00000,45.00000,2.806095e-09,0.78719,4
300.01901, 773.49917,      0.63269,    58.59520,50.00000,45.00000,2.809368e-09,0.78718,4
300.02100, 776.89917,      0.63134,    58.54780,50.00000,45.00000,2.806856e-09,0.78719,4
300.02499, 780.29917,      0.63347,    58.50700,50.00000,45.00000,2.805647e-09,0.78720,4
300.02301, 783.69917,      0.63366,    58.45720,50.00000,45.00000,2.806980e-09,0.78719,4
300.01099, 787.09917,      0.63385,    58.35760,50.00000,45.00000,2.807368e-09,0.78719,4
300.01999, 790.49917,      0.63405,    58.33500,50.00000,45.00000,2.810187e-09,0.78718,4
300.02701, 793.89917,      0.63212,    58.27400,50.00000,45.00000,2.810240e-09,0.78720,4
300.01001, 797.29917,      0.63249,    58.21960,50.00000,45.00000,2.807153e-09,0.78720,4
300.01001, 800.69917,      0.63268,    58.18120,50.00000,45.00000,2.812888e-09,0.78718,4
300.00299, 804.09917,      0.63307,    58.10200,50.00000,45.00000,2.800725e-09,0.78720,4
300.02200, 807.49917,      0.63153,    58.06340,50.00000,45.00000,2.805504e-09,0.78718,4
300.02100, 810.89917,      0.63405,    57.99560,50.00000,45.00000,2.803534e-09,0.78720,4
300.01199, 814.29917,      0.63036,    57.92780,50.00000,45.00000,2.807718e-09,0.78719,4
300.02399, 817.69917,      0.63231,    57.85980,50.00000,45.00000,2.801745e-09,0.78719,4
300.01099, 821.09917,      0.63365,    57.81240,50.00000,45.00000,2.803360e-09,0.78719,4
300.01001, 824.49917,      0.63346,    57.77840,50.00000,45.00000,2.796643e-09,0.78721,4
300.01700, 827.89917,      0.63327,    57.68560,50.00000,45.00000,2.805006e-09,0.78719,4
300.02499, 831.29917,      0.63386,    57.65160,50.00000,45.00000,2.801976e-09,0.78720,4
299.99701, 834.69917,      0.63616,    57.55660,50.00000,45.00000,2.793499e-09,0.78719,4
300.01700, 838.09917,      0.63269,    57.52500,50.00000,45.00000,2.798189e-09,0.78719,4
300.02301, 841.49917,      0.63153,    57.43900,50.00000,45.00000,2.803250e-09,0.78719,4
300.01501, 844.89917,      0.63249,    57.38460,50.00000,45.00000,2.803277e-09,0.78719,4
300.01401, 848.29917,      0.63056,    57.30320,50.00000,45.00000,2.795960e-09,0.78720,4
300.01300, 851.69917,      0.63249,    57.26240,50.00000,45.00000,2.802531e-09,0.78719,4
300.01700, 855.09917,      0.63172,    57.18780,50.00000,45.00000,2.802818e-09,0.78719,4
300.00900, 858.49917,      0.63230,    57.14720,50.00000,45.00000,2.795231e-09,0.78719,4
300.01501, 861.89917,      0.63153,    57.07920,50.00000,45.00000,2.798919e-09,0.78719,4
300.00299, 865.29917,      0.63132,    57.02940,50.00000,45.00000,2.799079e-09,0.78719,4
300.01999, 868.69917,      0.63211,    56.95480,50.00000,45.00000,2.795632e-09,0.78719,4
300.01599, 872.09917,      0.63172,    56.88240,50.00000,45.00000,2.801239e-09,0.78719,4
300.01501, 875.49917,      0.63327,    56.84160,50.00000,45.00000,2.803922e-09,0.78718,4
300.01099, 878.89917,      0.63055,    56.78060,50.00000,45.00000,2.801783e-09,0.78718,4
300.01300, 882.29917,      0.62959,    56.71940,50.00000,45.00000,2.796147e-09,0.78720,4
300.00400, 885.69917,      0.62919,    56.69460,50.00000,45.00000,2.793436e-09,0.78720,4
300.00699, 889.09917,      0.62919,    56.62660,50.00000,45.00000,2.791677e-09,0.78719,4
300.01401, 892.49917,      0.63269,    56.55200,50.00000,45.00000,2.806696e-09,0.78719,4
300.00699, 895.89917,      0.63016,    56.49780,50.00000,45.00000,2.803771e-09,0.78719,4
300.01001, 899.29917,      0.63288,    56.46380,50.00000,45.00000,2.795036e-09,0.78719,4
300.02301, 902.69917,      0.63580,    56.42080,50.00000,45.00000,2.797760e-09,0.78719,4
300.02200, 906.09917,      0.63231,    56.34620,50.00000,45.00000,2.793671e-09,0.78719,4
300.01901, 909.49917,      0.63308,    56.26920,50.00000,45.00000,2.799884e-09,0.78719,4
300.01599, 912.89917,      0.63230,    56.20140,50.00000,45.00000,2.803974e-09,0.78718,4
300.01599, 916.29917,      0.63211,    56.17420,50.00000,45.00000,2.805798e-09,0.78718,4
300.00601, 919.69917,      0.63191,    56.11540,50.00000,45.00000,2.799908e-09,0.78719,4
300.01001, 923.09917,      0.63210,    56.04740,50.00000,45.00000,2.793382e-09,0.78719,4
300.01599, 926.49917,      0.63114,    55.98640,50.00000,45.00000,2.795925e-09,0.78720,4
300.00900, 929.89917,      0.63094,    55.91840,50.00000,45.00000,2.799560e-09,0.78718,4
300.03500, 933.29917,      0.63232,    55.87100,50.00000,45.00000,2.793525e-09,0.78719,4
300.01001, 936.69917,      0.63365,    55.81660,50.00000,45.00000,2.794288e-09,0.78719,4
300.02200, 940.09917,      0.63192,    55.75560,50.00000,45.00000,2.797144e-09,0.78719,4
300.01501, 943.49917,      0.63075,    55.70120,50.00000,45.00000,2.798157e-09,0.78719,4
300.01700, 946.89917,      0.63114,    55.64020,50.00000,45.00000,2.802547e-09,0.78719,4
300.02301, 950.29917,      0.63037,    55.58580,50.00000,45.00000,2.794597e-09,0.78721,4
300.00699, 953.69917,      0.63365,    55.52480,50.00000,45.00000,2.800488e-09,0.78719,4
300.03000, 957.09917,      0.63386,    55.44340,50.00000,45.00000,2.800574e-09,0.78718,4
300.02200, 960.49917,      0.63405,    55.38900,50.00000,45.00000,2.795454e-09,0.78718,4
300.00900, 963.89917,      0.63152,    55.34140,50.00000,45.00000,2.798443e-09,0.78719,4
300.01599, 967.29917,      0.63172,    55.27360,50.00000,45.00000,2.800609e-09,0.78719,4
300.00601, 970.69917,      0.63132,    55.23960,50.00000,45.00000,2.797601e-09,0.78719,4
300.01801, 974.09917,      0.63327,    55.16500,50.00000,45.00000,2.791908e-09,0.78720,4
300.02200, 977.49917,      0.62901,    55.10840,50.00000,45.00000,2.797964e-09,0.78719,4
300.02200, 980.89917,      0.62940,    55.04060,50.00000,45.00000,2.790901e-09,0.78719,4
300.00500, 984.29917,      0.62977,    54.98400,50.00000,45.00000,2.796779e-09,0.78719,4
300.01999, 987.69917,      0.63192,    54.93420,50.00000,45.00000,2.797317e-09,0.78720,4
300.01700, 991.09917,      0.62939,    54.90020,50.00000,45.00000,2.799008e-09,0.78719,4
300.02100, 994.49917,      0.63134,    54.82560,50.00000,45.00000,2.793284e-09,0.78719,4
300.01999, 997.89917,      0.63153,    54.75780,50.00000,45.00000,2.797298e-09,0.78719,4
300.01599,1001.29917,      0.63346,    54.71020,50.00000,45.00000,2.798618e-09,0.78719,4
300.00699,1004.69917,      0.63229,    54.66260,50.00000,45.00000,2.794015e-09,0.78719,4
300.01999,1008.09917,      0.63308,    54.60840,50.00000,45.00000,2.799506e-09,0.78720,4
300.01501,1011.49917,      0.63133,    54.51780,50.00000,45.00000,2.794636e-09,0.78719,4
300.01999,1014.89917,      0.63133,    54.46140,50.00000,45.00000,2.798989e-09,0.78719,4
300.02200,1018.29917,      0.63153,    54.40700,50.00000,45.00000,2.796928e-09,0.78720,4
300.00900,1021.69917,      0.63094,    54.36620,50.00000,45.00000,2.799419e-09,0.78719,4
300.01099,1025.09917,      0.63055,    54.30520,50.00000,45.00000,2.801053e-09,0.78718,4
300.01099,1028.49917,      0.63191,    54.21700,50.00000,45.00000,2.794241e-09,0.78720,4
300.01599,1031.89917,      0.63153,    54.18760,50.00000,45.00000,2.797964e-09,0.78719,4
300.01300,1035.29917,      0.62939,    54.10380,50.00000,45.00000,2.801348e-09,0.78719,4
300.01700,1038.69917,      0.63269,    54.05620,50.00000,45.00000,2.800143e-09,0.78719,4
300.01501,1042.09917,      0.63114,    54.02920,50.00000,45.00000,2.809810e-09,0.78720,4
300.02701,1045.49917,      0.63115,    53.97480,50.00000,45.00000,2.805214e-09,0.78719,4
300.02399,1048.89917,      0.63114,    53.89340,50.00000,45.00000,2.807534e-09,0.78719,4
300.01099,1052.29917,      0.63172,    53.85260,50.00000,45.00000,2.807845e-09,0.78719,4
300.02399,1055.69917,      0.62998,    53.81200,50.00000,45.00000,2.804704e-09,0.78719,4
300.02200,1059.09917,      0.62979,    53.75760,50.00000,45.00000,2.804278e-09,0.78719,4
300.01001,1062.49917,      0.63133,    53.68300,50.00000,45.00000,2.801970e-09,0.78720,4
300.01300,1065.89917,      0.63230,    53.62860,50.00000,45.00000,2.807111e-09,0.78719,4
299.99500,1069.29917,      0.63073,    53.56760,50.00000,45.00000,2.811260e-09,0.78719,4
300.00101,1072.69917,      0.62996,    53.50640,50.00000,45.00000,2.808564e-09,0.78719,4
300.02301,1076.09917,      0.63172,    53.47940,50.00000,45.00000,2.808989e-09,0.78720,4
300.01901,1079.49917,      0.63056,    53.39780,50.00000,45.00000,2.807394e-09,0.78719,4
300.01300,1082.89917,      0.63036,    53.39100,50.00000,45.00000,2.807396e-09,0.78720,4
300.01801,1086.29917,      0.62920,    53.32320,50.00000,45.00000,2.800099e-09,0.78720,4
300.02200,1089.69917,      0.63037,    53.25080,50.00000,45.00000,2.811402e-09,0.78719,4
300.00800,1093.09917,      0.63191,    53.21000,50.00000,45.00000,2.807545e-09,0.78720,4
300.01001,1096.49917,      0.63210,    53.14900,50.00000,45.00000,2.805441e-09,0.78720,4
299.99899,1099.89917,      0.63190,    53.08780,50.00000,45.00000,2.806350e-09,0.78720,4
300.01099,1103.29917,      0.62978,    53.05160,50.00000,45.00000,2.809059e-09,0.78718,4
300.01501,1106.69917,      0.63249,    52.98380,50.00000,45.00000,2.805365e-09,0.78720,4
300.01099,1110.09917,      0.63152,    52.96340,50.00000,45.00000,2.810710e-09,0.78718,4
300.01599,1113.49917,      0.63385,    52.88880,50.00000,45.00000,2.812217e-09,0.78720,4
300.00900,1116.89917,      0.63385,    52.85480,50.00000,45.00000,2.807726e-09,0.78720,4
300.02399,1120.29917,      0.63405,    52.78700,50.00000,45.00000,2.814731e-09,0.78719,4
300.01199,1123.69917,      0.63307,    52.74620,50.00000,45.00000,2.818226e-09,0.78720,4
300.00500,1127.09917,      0.63384,    52.65800,50.00000,45.00000,2.807939e-09,0.78720,4
299.99899,1130.49917,      0.63365,    52.63080,50.00000,45.00000,2.814378e-09,0.78720,4
300.01300,1133.89917,      0.63191,    52.56980,50.00000,45.00000,2.808997e-09,0.78720,4
300.01300,1137.29917,      0.63075,    52.49500,50.00000,45.00000,2.810041e-09,0.78721,4
300.01099,1140.69917,      0.63017,    52.45440,50.00000,45.00000,2.819999e-09,0.78718,4
300.02600,1144.09917,      0.63173,    52.39320,50.00000,45.00000,2.813014e-09,0.78719,4
300.00800,1147.49917,      0.63133,    52.30500,50.00000,45.00000,2.813186e-09,0.78718,4
300.01599,1150.89917,      0.63114,    52.26420,50.00000,45.00000,2.815577e-09,0.78719,4
300.01001,1154.29917,      0.63113,    52.23480,50.00000,45.00000,2.810742e-09,0.78719,4
300.01700,1157.69917,      0.63075,    52.17380,50.00000,45.00000,2.813850e-09,0.78719,4
300.01999,1161.09917,      0.63114,    52.10360,50.00000,45.00000,2.818133e-09,0.78718,4
300.01700,1164.49917,      0.62901,    52.02220,50.00000,45.00000,2.812992e-09,0.78719,4
300.02499,1167.89917,      0.63095,    51.97240,50.00000,45.00000,2.816004e-09,0.78719,4
300.02100,1171.29917,      0.62979,    51.94520,50.00000,45.00000,2.806749e-09,0.78718,4
300.01599,1174.69917,      0.63114,    51.86140,50.00000,45.00000,2.810534e-09,0.78719,4
300.01700,1178.09917,      0.63075,    51.77320,50.00000,45.00000,2.809326e-09,0.78719,4
300.01999,1181.49917,      0.62920,    51.73260,50.00000,45.00000,2.814111e-09,0.78719,4
300.01599,1184.89917,      0.63094,    51.67140,50.00000,45.00000,2.807245e-09,0.78720,4
300.01501,1188.29917,      0.63249,    51.60800,50.00000,45.00000,2.804059e-09,0.78719,4
300.02399,1191.69917,      0.63056,    51.54020,50.00000,45.00000,2.840938e-09,0.78719,4
300.01401,1195.09917,      0.62978,    51.45880,50.00000,45.00000,2.840013e-09,0.78719,4
300.00699,1198.49917,      0.63055,    51.39080,50.00000,45.00000,2.839803e-09,0.78719,4
300.02701,1201.89917,      0.62785,    51.34340,50.00000,45.00000,2.844218e-09,0.78719,4
300.02600,1205.29917,      0.62824,    51.30480,50.00000,45.00000,2.844269e-09,0.78719,4
300.01599,1208.69917,      0.62901,    51.25060,50.00000,45.00000,2.847737e-09,0.78720,4
300.01801,1212.09917,      0.62998,    51.14200,50.00000,45.00000,2.843998e-09,0.78719,4
300.02399,1215.49917,      0.62882,    51.11940,50.00000,45.00000,2.845421e-09,0.78718,4
300.01501,1218.89917,      0.62823,    51.04460,50.00000,45.00000,2.844908e-09,0.78719,4
300.01599,1222.29917,      0.63017,    50.99040,50.00000,45.00000,2.850368e-09,0.78719,4
300.01801,1225.69917,      0.62881,    50.93840,50.00000,45.00000,2.846134e-09,0.78719,4
300.00299,1229.09917,      0.62706,    50.89080,50.00000,45.00000,2.850724e-09,0.78718,4
300.00699,1232.49917,      0.62725,    50.82980,50.00000,45.00000,2.842274e-09,0.78719,4
300.01901,1235.89917,      0.62998,    50.77540,50.00000,45.00000,2.853805e-09,0.78718,4
300.01999,1239.29917,      0.62998,    50.71200,50.00000,45.00000,2.856127e-09,0.78719,4
300.01001,1242.69917,      0.62842,    50.64420,50.00000,45.00000,2.860481e-09,0.78718,4
300.01599,1246.09917,      0.62881,    50.59660,50.00000,46.00000,2.855740e-09,0.78719,4
300.01099,1249.49917,      0.62900,    50.53560,50.00000,46.00000,2.858224e-09,0.78719,4
300.01599,1252.89917,      0.63133,    50.48120,50.00000,46.00000,2.860352e-09,0.78719,4
300.02600,1256.29917,      0.62785,    50.39980,50.00000,46.00000,2.866727e-09,0.78719,4
300.05399,1257.13417,      0.65327,    50.37260,50.00000,50.00000,2.861423e-09,0.78718,5
300.35599,1257.30417,      0.91218,    50.42700,50.00000,50.00000,2.865573e-09,0.78718,5
301.14301,1257.47417,      1.51746,    50.62840,50.00000,50.00000,2.866615e-09,0.78719,5
302.57199,1257.64417,      2.43443,    50.91560,50.00000,50.00000,2.857049e-09,0.78718,5
304.58801,1257.81417,      3.54146,    51.24600,50.00000,50.00000,2.865175e-09,0.78718,5
307.12000,1257.98417,      4.68392,    51.53340,50.00000,50.00000,2.856907e-09,0.78718,5
310.00000,1258.15417,      5.70853,    51.79140,50.00000,50.00000,2.865644e-09,0.78718,5
313.05801,1258.32417,      6.52207,    52.01540,50.00000,50.00000,2.862013e-09,0.78718,5
316.16299,1258.49417,      7.08602,    52.11040,50.00000,50.00000,2.861090e-09,0.78719,5
319.22601,1258.66417,      7.40635,    52.13760,50.00000,50.00000,2.862691e-09,0.78718,5
322.18600,1258.83417,      7.54657,    52.21900,50.00000,50.00000,2.864941e-09,0.78719,5
325.08200,1259.00417,      7.57594,    52.21900,50.00000,50.00000,2.855107e-09,0.78718,5
327.91000,1259.17417,      7.56681,    52.27320,50.00000,50.00000,2.857291e-09,0.78719,5
330.73901,1259.34417,      7.58282,    52.29360,50.00000,50.00000,2.859391e-09,0.78718,5
333.63599,1259.51417,      7.66648,    52.30040,50.00000,50.00000,2.863894e-09,0.78719,5
336.63599,1259.68417,      7.83450,    52.41360,50.00000,50.00000,2.861720e-09,0.78719,5
339.76901,1259.85417,      8.08132,    52.42040,50.00000,50.00000,2.861984e-09,0.78718,5
343.04599,1260.02417,      8.38379,    52.55620,50.00000,50.00000,2.862465e-09,0.78718,5
346.45599,1260.19417,      8.71965,    52.61720,50.00000,50.00000,2.857046e-09,0.78718,5
349.97601,1260.36417,      9.04945,    52.67160,50.00000,50.00000,2.859898e-09,0.78719,5
353.58099,1260.53417,      9.34846,    52.71900,50.00000,50.00000,2.861769e-09,0.78718,5
357.25000,1260.70417,      9.60151,    52.75300,50.00000,50.00000,2.862331e-09,0.78720,5
360.91699,1260.87417,      9.80023,    52.78020,50.00000,50.00000,2.865757e-09,0.78719,5
364.59900,1261.04417,      9.95076,    52.75300,50.00000,50.00000,2.859717e-09,0.78719,5
368.26700,1261.21417,     10.06681,    52.66920,50.00000,50.00000,2.862611e-09,0.78719,5
371.94199,1261.38417,     10.16277,    52.61500,50.00000,50.00000,2.862953e-09,0.78720,5
375.60001,1261.55417,     10.23546,    52.50180,50.00000,50.00000,2.863637e-09,0.78721,5
379.28299,1261.72417,     10.37617,    52.35020,50.00000,50.00000,2.860898e-09,0.78719,5
382.95099,1261.89417,     10.54679,    52.13300,50.00000,50.00000,2.863179e-09,0.78719,5
386.63000,1262.06417,     10.71326,    51.80940,50.00000,50.00000,2.863721e-09,0.78719,5
390.33499,1262.23417,     10.87355,    51.45880,50.00000,50.00000,2.866759e-09,0.78719,5
394.04401,1262.40417,     10.79074,    50.97460,50.00000,50.00000,2.862926e-09,0.78719,5
397.76501,1262.57417,     11.10974,    50.24600,50.00000,50.00000,2.857349e-09,0.78720,5
401.49600,1262.74417,     11.24733,    49.33400,50.00000,50.00000,2.862009e-09,0.78719,5
405.21701,1262.91417,     11.44538,    48.24340,50.00000,50.00000,2.867210e-09,0.78719,5
408.93701,1263.08417,     11.71274,    46.71620,50.00000,50.00000,2.862915e-09,0.78719,5
412.64200,1263.25417,     11.91775,    44.86760,50.00000,50.00000,2.864687e-09,0.78719,5
416.34500,1263.42417,     12.08397,    42.44880,50.00000,50.00000,2.861416e-09,0.78719,5
420.03299,1263.59417,     12.49372,    39.46660,50.00000,50.00000,2.851728e-09,0.78719,5
423.71301,1263.76417,     12.99126,    35.74000,50.00000,50.00000,2.857678e-09,0.78720,5
427.38300,1263.93417,     13.71017,    31.31420,50.00000,50.00000,2.861213e-09,0.78719,5
431.02802,1264.10417,     14.57432,    26.20040,50.00000,50.00000,2.861786e-09,0.78719,5
434.67599,1264.27417,     14.40006,    20.28800,50.00000,50.00000,2.856085e-09,0.78719,5
438.32599,1264.44417,     15.26245,    13.85980,50.00000,50.00000,2.866274e-09,0.78719,5
441.94601,1264.61417,     15.93993,     7.34780,50.00000,50.00000,2.860270e-09,0.78719,5
445.54001,1264.78417,     16.38126,     0.90600,50.00000,50.00000,2.856407e-09,0.78720,5
449.12601,1264.95417,     16.46681,    -5.15120,50.00000,50.00000,2.866030e-09,0.78719,5
452.72400,1265.12417,     15.91187,   -10.50020,50.00000,50.00000,2.856843e-09,0.78719,5
456.32401,1265.29417,     15.30503,   -14.77660,50.00000,50.00000,2.854831e-09,0.78719,5
459.90100,1265.46417,     14.66250,   -18.12080,50.00000,50.00000,2.853218e-09,0.78719,5
463.50201,1265.63417,     14.08049,   -20.62340,50.00000,50.00000,2.855663e-09,0.78718,5
467.08899,1265.80417,     13.60594,   -22.48100,50.00000,50.00000,2.859392e-09,0.78719,5
470.67999,1265.97417,     13.22382,   -23.74360,50.00000,50.00000,2.860737e-09,0.78719,5
474.25900,1266.14417,     12.92304,   -24.63740,50.00000,50.00000,2.860611e-09,0.78719,5
477.81100,1266.31417,     12.69185,   -25.21220,50.00000,50.00000,2.864714e-09,0.78718,5
481.37100,1266.48417,     12.50803,   -25.60360,50.00000,50.00000,2.860925e-09,0.78718,5
484.90701,1266.65417,     12.35841,   -25.83880,50.00000,50.00000,2.859557e-09,0.78719,5
488.44000,1266.82417,     12.23417,   -26.02220,50.00000,50.00000,2.857095e-09,0.78719,5
491.95901,1266.99417,     12.12605,   -26.05600,50.00000,50.00000,2.857807e-09,0.78719,5
495.46799,1267.16417,     12.03684,   -26.08320,50.00000,50.00000,2.853836e-09,0.78719,5
498.98300,1267.33417,     11.96883,   -26.11040,50.00000,50.00000,2.859154e-09,0.78718,5
502.46799,1267.50417,     11.90786,   -26.11040,50.00000,50.00000,2.854332e-09,0.78719,5
505.97198,1267.67417,     11.85963,   -26.08320,50.00000,50.00000,2.858855e-09,0.78719,5
509.45200,1267.84417,     11.81549,   -26.08100,50.00000,50.00000,2.859353e-09,0.78719,5
512.91901,1268.01417,     11.77594,   -26.05380,50.00000,50.00000,2.862927e-09,0.78721,5
516.39301,1268.18417,     11.74083,   -26.02660,50.00000,50.00000,2.863767e-09,0.78719,5
519.86298,1268.35417,     11.70954,   -26.01320,50.00000,50.00000,2.859070e-09,0.78720,5
523.30298,1268.52417,     11.68330,   -25.98600,50.00000,50.00000,2.861203e-09,0.78719,5
526.78003,1268.69417,     11.65406,   -25.95880,50.00000,50.00000,2.860310e-09,0.78719,5
530.21997,1268.86417,     11.62983,   -25.95880,50.00000,50.00000,2.863145e-09,0.78719,5
533.67102,1269.03417,     11.60642,   -25.90440,50.00000,50.00000,2.862734e-09,0.78719,5
537.10901,1269.20417,     11.58374,   -25.86380,50.00000,50.00000,2.862524e-09,0.78720,5
540.55103,1269.37417,     11.56020,   -25.85020,50.00000,50.00000,2.859065e-09,0.78719,5
544.00598,1269.54417,     11.53964,   -25.79580,50.00000,50.00000,2.862997e-09,0.78719,5
547.42999,1269.71417,     11.52202,   -25.73940,50.00000,50.00000,2.865028e-09,0.78719,5
550.87000,1269.88417,     11.50642,   -25.71220,50.00000,50.00000,2.863232e-09,0.78718,5
554.30499,1270.05417,     11.48587,   -25.71220,50.00000,50.00000,2.865354e-09,0.78719,5
557.73297,1270.22417,     11.46783,   -25.65780,50.00000,50.00000,2.867366e-09,0.78718,5
561.17902,1270.39417,     11.44618,   -25.65780,50.00000,50.00000,2.863269e-09,0.78719,5
564.61603,1270.56417,     11.42758,   -25.62840,50.00000,50.00000,2.867801e-09,0.78718,5
568.03198,1270.73417,     11.40372,   -25.62840,50.00000,50.00000,2.862937e-09,0.78719,5
571.45502,1270.90417,     11.38425,   -25.60120,50.00000,50.00000,2.862355e-09,0.78718,5
574.88501,1271.07417,     11.36344,   -25.57420,50.00000,50.00000,2.866120e-09,0.78718,5
578.32098,1271.24417,     11.34569,   -25.54700,50.00000,50.00000,2.865639e-09,0.78719,5
581.73901,1271.41417,     11.32795,   -25.51980,50.00000,50.00000,2.864748e-09,0.78719,5
585.16400,1271.58417,     11.31168,   -25.49260,50.00000,50.00000,2.859344e-09,0.78719,5
588.59698,1271.75417,     11.29885,   -25.43620,50.00000,50.00000,2.863403e-09,0.78718,5
592.02301,1271.92417,     11.28005,   -25.40900,50.00000,50.00000,2.863223e-09,0.78718,5
595.43701,1272.09417,     11.26250,   -25.35460,50.00000,50.00000,2.864470e-09,0.78718,5
598.86401,1272.26417,     11.24766,   -25.32760,50.00000,50.00000,2.866239e-09,0.78718,5
602.29700,1272.43417,     11.22666,   -25.30040,50.00000,50.00000,2.858958e-09,0.78719,5
605.71600,1272.60417,     11.21175,   -25.30040,50.00000,50.00000,2.864593e-09,0.78720,5
609.13098,1272.77417,     11.19683,   -25.27320,50.00000,50.00000,2.864406e-09,0.78719,5
612.53998,1272.94417,     11.17757,   -25.27320,50.00000,50.00000,2.860785e-09,0.78719,5
615.95300,1273.11417,     11.15550,   -25.24600,50.00000,50.00000,2.861914e-09,0.78719,5
619.37701,1273.28417,     11.13502,   -25.24600,50.00000,50.00000,2.866090e-09,0.78720,5
622.79199,1273.45417,     11.11038,   -25.24600,50.00000,50.00000,2.860744e-09,0.78719,5
626.21301,1273.62417,     11.09516,   -25.24600,50.00000,50.00000,2.862619e-09,0.78719,5
629.62299,1273.79417,     11.08018,   -25.21900,50.00000,50.00000,2.855790e-09,0.78719,5
633.03003,1273.96417,     11.07231,   -25.21900,50.00000,50.00000,2.866128e-09,0.78719,5
636.45001,1274.13417,     11.06239,   -25.19180,50.00000,50.00000,2.861690e-09,0.78719,5
639.85400,1274.30417,     11.05124,   -25.19180,50.00000,50.00000,2.863745e-09,0.78719,5
643.27197,1274.47417,     11.03950,   -25.19180,50.00000,50.00000,2.860715e-09,0.78719,5
646.68597,1274.64417,     11.02399,   -25.16460,50.00000,50.00000,2.859250e-09,0.78720,5
650.09802,1274.81417,     11.00589,   -25.15780,50.00000,50.00000,2.867457e-09,0.78719,5
653.50299,1274.98417,     10.98994,   -25.13740,50.00000,50.00000,2.868269e-09,0.78719,5
656.92297,1275.15417,     10.97520,   -25.11020,50.00000,50.00000,2.868091e-09,0.78720,5
660.33698,1275.32417,     10.96388,   -25.08320,50.00000,50.00000,2.867308e-09,0.78719,5
663.73999,1275.49417,     10.94840,   -25.05600,50.00000,50.00000,2.861333e-09,0.78720,5
667.16199,1275.66417,     10.92994,   -25.04240,50.00000,50.00000,2.862216e-09,0.78719,5
670.57898,1275.83417,     10.91343,   -25.03560,50.00000,50.00000,2.865489e-09,0.78719,5
673.99500,1276.00417,     10.89373,   -24.97460,50.00000,50.00000,2.862737e-09,0.78719,5
677.41498,1276.17417,     10.87302,   -24.97460,50.00000,50.00000,2.859208e-09,0.78719,5
680.82098,1276.34417,     10.85696,   -24.94740,50.00000,50.00000,2.862127e-09,0.78720,5
684.23999,1276.51417,     10.83631,   -24.92020,50.00000,50.00000,2.862451e-09,0.78719,5
687.65100,1276.68417,     10.81981,   -24.92020,50.00000,50.00000,2.857597e-09,0.78720,5
691.07001,1276.85417,     10.80580,   -24.86600,50.00000,50.00000,2.861075e-09,0.78719,5
694.47900,1277.02417,     10.79009,   -24.83880,50.00000,50.00000,2.865167e-09,0.78719,5
697.90198,1277.19417,     10.77008,   -24.81160,50.00000,50.00000,2.865302e-09,0.78720,5
701.31097,1277.36417,     10.74421,   -24.81160,50.00000,50.00000,2.870149e-09,0.78720,5
704.73499,1277.53417,     10.71147,   -24.75740,50.00000,50.00000,2.865108e-09,0.78720,5
708.15399,1277.70417,     10.67507,   -24.73700,50.00000,50.00000,2.863248e-09,0.78720,5
711.56598,1277.87417,     10.63181,   -24.73020,50.00000,50.00000,2.863442e-09,0.78720,5
714.98199,1278.04417,     10.58936,   -24.70300,50.00000,50.00000,2.861328e-09,0.78719,5
718.39203,1278.21417,     10.53777,   -24.67580,50.00000,50.00000,2.863065e-09,0.78719,5
721.81500,1278.38417,     10.48162,   -24.64880,50.00000,50.00000,2.862788e-09,0.78720,5
725.24597,1278.55417,     10.41698,   -24.62160,50.00000,50.00000,2.868498e-09,0.78720,5
728.67200,1278.72417,     10.34269,   -24.59440,50.00000,50.00000,2.864170e-09,0.78719,5
732.08698,1278.89417,     10.26055,   -24.54000,50.00000,50.00000,2.865941e-09,0.78719,5
735.49402,1279.06417,     10.17120,   -24.54000,50.00000,50.00000,2.863875e-09,0.78719,5
738.91901,1279.23417,     10.08033,   -24.51300,50.00000,50.00000,2.868323e-09,0.78720,5
742.33698,1279.40417,      9.98119,   -24.48580,50.00000,50.00000,2.868559e-09,0.78720,5
745.74799,1279.57417,      9.87339,   -24.48580,50.00000,50.00000,2.866855e-09,0.78720,5
749.16998,1279.74417,      9.75638,   -24.43140,50.00000,50.00000,2.862338e-09,0.78720,5
752.58002,1279.91417,      9.63120,   -24.41800,50.00000,50.00000,2.861999e-09,0.78720,5
756.00598,1280.08417,      9.50165,   -24.35900,50.00000,50.00000,2.866186e-09,0.78720,5
759.41901,1280.25417,      9.36811,   -24.34560,50.00000,50.00000,2.860543e-09,0.78720,5
762.82599,1280.42417,      9.22897,   -24.33200,50.00000,50.00000,2.858466e-09,0.78718,5
766.24597,1280.59417,      9.08801,   -24.29800,50.00000,50.00000,2.855527e-09,0.78719,5
769.67297,1280.76417,      8.93948,   -24.27760,50.00000,50.00000,2.865002e-09,0.78720,5
773.08099,1280.93417,      8.78681,   -24.25040,50.00000,50.00000,2.868102e-09,0.78719,5
776.49500,1281.10417,      8.63018,   -24.22340,50.00000,50.00000,2.862300e-09,0.78719,5
779.91101,1281.27417,      8.47423,   -24.19620,50.00000,50.00000,2.866217e-09,0.78720,5
783.33002,1281.44417,      8.31731,   -24.19620,50.00000,50.00000,2.868619e-09,0.78719,5
786.74103,1281.61417,      8.15458,   -24.14180,50.00000,50.00000,2.868028e-09,0.78720,5
790.16803,1281.78417,      7.99943,   -24.11480,50.00000,50.00000,2.867050e-09,0.78720,5
793.57300,1281.95417,      7.84213,   -24.11480,50.00000,50.00000,            ,0.44746,5
794.48199,1281.99917,      7.79768,   -24.11480,50.00000,50.00000,            ,0.44710,5