File: data/TGA/005d-L_M/ExpDat_2025_02_20_PS-A1000-dynamic-1K.csv
#EXPORTTYPE:                 ,DATA ALL
#FILE:                       ,2025_02_20_PS-A1000-dynamic-1K.ngb-ss5
#FORMAT:                     ,NETZSCH5
#FTYPE:                      ,ASCII
#IDENTITY:                   ,PS-A1000
#DECIMAL:                    ,POINT
#SEPARATOR:                  ,COMMA
#MTYPE:                      ,DSC
#INSTRUMENT:                 ,NETZSCH STA 449F5
#PROJECT:                    ,PS
#DATE/TIME:                  ,2/19/2025 6:36:45 PM (UTC-5)
#CORR. FILE:                 ,
#TEMPCAL:                    ,13-11-2024 10:37
#SENSITIVITY:                ,28-06-2023 13:53
#LABORATORY:                 ,Tran/Aspuru
#OPERATOR:                   ,Stanley
#REMARK:                     ,
#SAMPLE:                     ,PS
#SAMPLE MASS /mg:            ,5.12
#MATERIAL:                   ,
#REFERENCE:                  ,
#REFERENCE MASS /mg:         ,0
#TYPE OF CRUCIBLE:           ,Al2O3 85 ‘l, open
#SAMPLE CRUCIBLE MASS /mg:   ,0
#REFERENCE CRUCIBLE MASS /mg:,0
#DSC RANGE /‘V:              ,5000
#TG RANGE /mg:               ,35000
#TAU-R:                      ,---
#CORR. CODE:                 ,000
#EXO:                        ,-1
#RANGE:                      ,20›C....800›C/0.0....20.0K/min
#SEGMENT:                    ,S1-4/4
#SEG. 1:                     ,20›C/5.0(K/min)/100›C
#SEG. 2:                     ,100›C/00:05/100›C
#SEG. 3:                     ,100›C/1.0(K/min)/400›C
#SEG. 4:                     ,400›C/20.0(K/min)/800›C

##Temp./›C,Time/min,DSC/(mW/mg),Mass/%,Gas Flow(purge2)/(ml/min),Gas Flow(protective)/(ml/min),TIC(scan:1)/A,Sensit./(uV/mW),Segment
 28.55100,  0.00000,      0.52389,    100.00000,50.00000,34.00000,            ,0.92328,1
 29.85000,  1.06667,      0.17539,     99.76797,50.00000,33.00000,1.775380e-10,0.92336,1
 31.04700,  2.13333,      0.11953,     93.55449,50.00000,33.00000,1.781693e-10,0.92346,1
 32.33800,  3.20000,      0.15224,     93.55234,50.00000,33.00000,1.777954e-10,0.92356,1
 34.45100,  4.26667,      0.30534,     93.65840,50.00000,33.00000,1.784954e-10,0.92366,1
 37.64800,  5.33333,      0.50902,     93.96328,50.00000,33.00000,1.778450e-10,0.92373,1
 41.82500,  6.40000,      0.71101,     94.39199,50.00000,33.00000,1.779556e-10,0.92382,1
 46.88500,  7.46667,      0.89817,     94.74102,50.00000,33.00000,1.780987e-10,0.92392,1
 52.65700,  8.53333,      1.05779,     94.99961,50.00000,33.00000,1.775951e-10,0.92402,1
 58.90300,  9.60000,      1.18685,     95.19844,50.00000,33.00000,1.784001e-10,0.92417,1
 65.41600, 10.66667,      1.28003,     95.21172,50.00000,33.00000,1.786308e-10,0.92431,1
 72.02600, 11.73333,      1.33999,     95.07910,50.00000,33.00000,1.786671e-10,0.92450,1
 78.58900, 12.80000,      1.37769,     94.92012,50.00000,33.00000,1.786995e-10,0.92468,1
 85.06800, 13.86667,      1.39679,     94.62832,50.00000,33.00000,1.790333e-10,0.92487,1
 91.44500, 14.93333,      1.40014,     94.36094,50.00000,33.00000,1.779690e-10,0.92510,1
 97.55500, 15.98333,      1.39050,     94.06719,50.00000,33.00000,1.786422e-10,0.92529,2
101.58900, 16.78333,      1.20601,     93.54121,50.00000,33.00000,1.792488e-10,0.92544,2
104.20400, 17.58333,      0.81233,     92.68398,50.00000,33.00000,1.794586e-10,0.92559,2
105.90400, 18.38333,      0.53302,     92.12480,50.00000,33.00000,1.789303e-10,0.92573,2
107.07600, 19.18333,      0.35294,     91.66309,50.00000,33.00000,1.794452e-10,0.92585,2
107.73100, 19.98333,      0.17821,     91.16582,50.00000,33.00000,1.788978e-10,0.92596,2
107.87400, 20.78333, 1.572964e-02,     90.70410,50.00000,33.00000,1.790599e-10,0.92605,2
107.63700, 21.80000,     -0.10540,     90.23789,50.00000,33.00000,1.796894e-10,0.92613,3
107.39200, 22.86667,     -0.11187,     89.97266,50.00000,33.00000,1.793633e-10,0.92618,3
107.15200, 23.93333,     -0.11008,     89.68105,50.00000,33.00000,1.791782e-10,0.92620,3
106.98100, 25.00000,-8.575927e-02,     89.52187,50.00000,33.00000,1.796551e-10,0.92617,3
107.00300, 26.06667,-3.955653e-02,     89.38262,50.00000,33.00000,1.795940e-10,0.92610,3
107.22300, 27.13333, 8.754915e-03,     89.28320,50.00000,33.00000,1.796913e-10,0.92599,3
107.64100, 28.20000, 5.723871e-02,     89.17500,50.00000,33.00000,1.793937e-10,0.92581,3
108.21400, 29.26667,      0.10088,     89.09551,50.00000,33.00000,1.797009e-10,0.92562,3
108.95800, 30.33333,      0.13967,     89.06230,50.00000,33.00000,1.800765e-10,0.92535,3
109.81300, 31.40000,      0.17119,     89.00918,50.00000,33.00000,1.798763e-10,0.92508,3
110.76800, 32.46667,      0.19786,     88.92969,50.00000,33.00000,1.797237e-10,0.92473,3
111.79200, 33.53333,      0.21774,     88.88340,50.00000,33.00000,1.804028e-10,0.92438,3
112.88100, 34.60000,      0.23049,     88.83477,50.00000,33.00000,1.803475e-10,0.92394,3
113.97600, 35.66667,      0.23886,     88.77500,50.00000,33.00000,1.797543e-10,0.92352,3
115.08400, 36.73333,      0.24481,     88.74180,50.00000,33.00000,1.803627e-10,0.92301,3
116.22100, 37.80000,      0.24947,     88.68223,50.00000,33.00000,1.796035e-10,0.92253,3
117.33700, 38.86667,      0.25071,     88.60938,50.00000,33.00000,1.800098e-10,0.92194,3
118.45700, 39.93333,      0.24951,     88.55625,50.00000,33.00000,1.803360e-10,0.92141,3
119.58400, 41.00000,      0.24962,     88.52969,50.00000,33.00000,1.801701e-10,0.92103,3
120.69800, 42.06667,      0.24843,     88.50332,50.00000,32.00000,1.802712e-10,0.92063,3
121.78600, 43.13333,      0.24886,     88.47676,50.00000,33.00000,1.799108e-10,0.92034,3
122.88500, 44.20000,      0.24718,     88.45020,50.00000,33.00000,1.801891e-10,0.92005,3
123.96200, 45.26667,      0.24647,     88.43691,50.00000,33.00000,1.804352e-10,0.91984,3
125.05000, 46.33333,      0.24462,     88.41035,50.00000,33.00000,1.805859e-10,0.91963,3
126.11300, 47.40000,      0.24490,     88.36406,50.00000,33.00000,1.808910e-10,0.91947,3
127.19800, 48.46667,      0.24599,     88.36406,50.00000,33.00000,1.806221e-10,0.91931,3
128.26601, 49.53333,      0.24480,     88.35078,50.00000,33.00000,1.805324e-10,0.91919,3
129.34599, 50.60000,      0.24459,     88.35078,50.00000,32.00000,1.803760e-10,0.91908,3
130.40601, 51.66667,      0.24421,     88.33086,50.00000,33.00000,1.804505e-10,0.91900,3
131.47501, 52.73333,      0.24253,     88.33750,50.00000,33.00000,1.804867e-10,0.91894,3
132.54401, 53.80000,      0.24232,     88.33750,50.00000,32.00000,1.806927e-10,0.91892,3
133.60500, 54.86667,      0.24359,     88.34414,50.00000,33.00000,1.806106e-10,0.91890,3
134.67999, 55.93333,      0.24404,     88.33086,50.00000,33.00000,1.811275e-10,0.91892,3
135.75500, 57.00000,      0.24416,     88.33750,50.00000,32.00000,1.811714e-10,0.91895,3
136.80901, 58.06667,      0.24396,     88.36406,50.00000,33.00000,1.809616e-10,0.91898,3
137.87199, 59.13333,      0.24458,     88.36406,50.00000,33.00000,1.812859e-10,0.91901,3
138.94200, 60.20000,      0.24471,     88.37734,50.00000,32.00000,1.805076e-10,0.91904,3
140.01300, 61.26667,      0.24484,     88.35078,50.00000,32.00000,1.812058e-10,0.91907,3
141.07300, 62.33333,      0.24497,     88.38398,50.00000,32.00000,1.809387e-10,0.91910,3
142.14200, 63.40000,      0.24379,     88.38398,50.00000,32.00000,1.814461e-10,0.91913,3
143.20100, 64.46667,      0.24508,     88.38613,50.00000,32.00000,1.812363e-10,0.91915,3
144.27699, 65.53333,      0.24654,     88.40605,50.00000,32.00000,1.810894e-10,0.91917,3
145.34599, 66.60000,      0.24519,     88.41270,50.00000,32.00000,1.808262e-10,0.91917,3
146.40900, 67.66667,      0.24682,     88.42598,50.00000,32.00000,1.814345e-10,0.91917,3
147.49100, 68.73333,      0.24746,     88.44570,50.00000,32.00000,1.812744e-10,0.91915,3
148.54601, 69.80000,      0.24446,     88.44570,50.00000,33.00000,1.810837e-10,0.91914,3
149.61301, 70.86667,      0.24643,     88.45234,50.00000,33.00000,1.810761e-10,0.91910,3
150.69000, 71.93333,      0.24492,     88.47227,50.00000,33.00000,1.812954e-10,0.91906,3
151.75700, 73.00000,      0.24606,     88.45898,50.00000,32.00000,1.811181e-10,0.91901,3
152.82500, 74.06667,      0.24572,     88.48555,50.00000,33.00000,1.817837e-10,0.91895,3
153.89000, 75.13333,      0.24686,     88.48555,50.00000,33.00000,1.813640e-10,0.91889,3
154.96500, 76.20000,      0.24851,     88.47891,50.00000,33.00000,1.813736e-10,0.91881,3
156.03000, 77.26667,      0.24684,     88.51875,50.00000,33.00000,1.807785e-10,0.91872,3
157.10500, 78.33333,      0.24700,     88.51875,50.00000,33.00000,1.810970e-10,0.91864,3
158.17101, 79.40000,      0.24600,     88.51211,50.00000,33.00000,1.814918e-10,0.91853,3
159.25999, 80.46667,      0.24566,     88.52539,50.00000,33.00000,1.811256e-10,0.91843,3
160.32401, 81.53333,      0.24615,     88.54531,50.00000,33.00000,1.814156e-10,0.91832,3
161.38499, 82.60000,      0.24598,     88.53867,50.00000,33.00000,1.822948e-10,0.91821,3
162.43700, 83.66667,      0.24465,     88.55195,50.00000,33.00000,1.822434e-10,0.91809,3
163.50400, 84.73333,      0.24365,     88.55195,50.00000,33.00000,1.810341e-10,0.91796,3
164.57100, 85.80000,      0.24448,     88.55195,50.00000,33.00000,1.821861e-10,0.91783,3
165.63800, 86.86667,      0.24448,     88.57168,50.00000,33.00000,1.821498e-10,0.91771,3
166.69099, 87.93333,      0.24515,     88.55195,50.00000,33.00000,1.821460e-10,0.91756,3
167.77200, 89.00000,      0.24582,     88.55195,50.00000,33.00000,1.822834e-10,0.91743,3
168.84300, 90.06667,      0.24583,     88.57832,50.00000,33.00000,1.818656e-10,0.91728,3
169.91000, 91.13333,      0.24466,     88.55195,50.00000,33.00000,1.820316e-10,0.91715,3
170.97400, 92.20000,      0.24350,     88.57832,50.00000,33.00000,1.813583e-10,0.91699,3
172.05299, 93.26667,      0.24351,     88.57832,50.00000,33.00000,1.820240e-10,0.91685,3
173.11200, 94.33333,      0.24201,     88.57832,50.00000,33.00000,1.818466e-10,0.91669,3
174.17400, 95.40000,      0.24336,     88.55195,50.00000,33.00000,1.819515e-10,0.91655,3
175.25200, 96.46667,      0.24287,     88.57832,50.00000,33.00000,1.822968e-10,0.91639,3
176.31700, 97.53333,      0.24355,     88.55195,50.00000,33.00000,1.822014e-10,0.91624,3
177.36400, 98.60000,      0.24171,     88.55195,50.00000,33.00000,1.823978e-10,0.91608,3
178.44099, 99.66667,      0.24207,     88.54531,50.00000,33.00000,1.822281e-10,0.91595,3
179.50600,100.73333,      0.24124,     88.53203,50.00000,33.00000,1.827488e-10,0.91577,3
180.57300,101.80000,      0.24193,     88.54531,50.00000,33.00000,1.828785e-10,0.91562,3
181.64400,102.86667,      0.24043,     88.55195,50.00000,33.00000,1.824760e-10,0.91545,3
182.71700,103.93333,      0.24045,     88.53867,50.00000,33.00000,1.826782e-10,0.91531,3
183.76900,105.00000,      0.24114,     88.54531,50.00000,33.00000,1.827354e-10,0.91513,3
184.83701,106.06667,      0.24015,     88.53867,50.00000,33.00000,1.822910e-10,0.91499,3
185.90500,107.13333,      0.23713,     88.53867,50.00000,33.00000,1.823863e-10,0.91481,3
186.96400,108.20000,      0.23749,     88.51875,50.00000,33.00000,1.826706e-10,0.91466,3
188.04900,109.26667,      0.23988,     88.51875,50.00000,33.00000,1.825428e-10,0.91449,3
189.10800,110.33333,      0.23940,     88.51211,50.00000,33.00000,1.831397e-10,0.91431,3
190.16000,111.40000,      0.23857,     88.52539,50.00000,33.00000,1.826820e-10,0.91416,3
191.24899,112.46667,      0.23979,     88.49219,50.00000,33.00000,1.831246e-10,0.91399,3
192.30600,113.53333,      0.23710,     88.49883,50.00000,33.00000,1.824742e-10,0.91383,3
193.36900,114.60000,      0.23832,     88.47891,50.00000,33.00000,1.825638e-10,0.91366,3
194.43900,115.66667,      0.23971,     88.48555,50.00000,33.00000,1.834621e-10,0.91350,3
195.50400,116.73333,      0.23872,     88.49219,50.00000,33.00000,1.835632e-10,0.91332,3
196.57401,117.80000,      0.24029,     88.47891,50.00000,33.00000,1.829662e-10,0.91317,3
197.62500,118.86667,      0.23878,     88.47227,50.00000,33.00000,1.831951e-10,0.91299,3
198.70100,119.93333,      0.23831,     88.46563,50.00000,33.00000,1.832829e-10,0.91284,3
199.76601,121.00000,      0.23954,     88.46133,50.00000,33.00000,1.833553e-10,0.91264,3
200.83600,122.06667,      0.23769,     88.45469,50.00000,33.00000,1.832237e-10,0.91249,3
201.90800,123.13333,      0.23962,     88.43477,50.00000,33.00000,1.834470e-10,0.91231,3
202.96600,124.20000,      0.23862,     88.42812,50.00000,33.00000,1.831265e-10,0.91215,3
204.04100,125.26667,      0.23901,     88.40156,50.00000,33.00000,1.830120e-10,0.91196,3
205.11099,126.33333,      0.23596,     88.40156,50.00000,33.00000,1.832866e-10,0.91180,3
206.16499,127.40000,      0.23840,     88.42148,50.00000,33.00000,1.833038e-10,0.91162,3
207.24899,128.46667,      0.23725,     88.36836,50.00000,33.00000,1.833496e-10,0.91145,3
208.31400,129.53333,      0.23746,     88.38164,50.00000,33.00000,1.839237e-10,0.91126,3
209.37000,130.60000,      0.23595,     88.36191,50.00000,33.00000,1.833801e-10,0.91110,3
210.44299,131.66667,      0.23617,     88.35527,50.00000,33.00000,1.839103e-10,0.91090,3
211.50500,132.73333,      0.23794,     88.32207,50.00000,33.00000,1.832677e-10,0.91074,3
212.57600,133.80000,      0.23903,     88.30879,50.00000,33.00000,1.836739e-10,0.91055,3
213.64200,134.86667,      0.23717,     88.30215,50.00000,33.00000,1.839733e-10,0.91038,3
214.72000,135.93333,      0.23671,     88.26895,50.00000,33.00000,1.835632e-10,0.91019,3
215.76199,137.00000,      0.23606,     88.26895,50.00000,33.00000,1.831703e-10,0.91002,3
216.83099,138.06667,      0.23888,     88.22930,50.00000,33.00000,1.840191e-10,0.90982,3
217.89301,139.13333,      0.23963,     88.21602,50.00000,33.00000,1.833897e-10,0.90965,3
218.96800,140.20000,      0.24108,     88.17617,50.00000,33.00000,1.834278e-10,0.90945,3
220.03900,141.26667,      0.24166,     88.16289,50.00000,33.00000,1.838379e-10,0.90928,3
221.10500,142.33333,      0.24398,     88.15625,50.00000,33.00000,1.843586e-10,0.90908,3
222.17000,143.40000,      0.24300,     88.13652,50.00000,33.00000,1.844635e-10,0.90890,3
223.24100,144.46667,      0.24306,     88.08340,50.00000,33.00000,1.844597e-10,0.90870,3
224.30299,145.53333,      0.23789,     88.04355,50.00000,33.00000,1.841240e-10,0.90852,3
225.36600,146.60000,      0.23340,     88.01055,50.00000,33.00000,1.837158e-10,0.90832,3
226.44600,147.66667,      0.23048,     87.98398,50.00000,33.00000,1.845379e-10,0.90815,3
227.50400,148.73333,      0.23176,     87.93086,50.00000,33.00000,1.841850e-10,0.90794,3
228.56100,149.80000,      0.22936,     87.90449,50.00000,33.00000,1.848202e-10,0.90775,3
229.63100,150.86667,      0.22661,     87.87129,50.00000,33.00000,1.842327e-10,0.90755,3
230.69200,151.93333,      0.22578,     87.81816,50.00000,33.00000,1.845264e-10,0.90737,3
231.76601,153.00000,      0.22461,     87.78516,50.00000,33.00000,1.837635e-10,0.90716,3
232.82100,154.06667,      0.22254,     87.73203,50.00000,33.00000,1.845951e-10,0.90698,3
233.89600,155.13333,      0.22172,     87.69238,50.00000,33.00000,1.842518e-10,0.90675,3
234.96500,156.20000,      0.22142,     87.66582,50.00000,33.00000,1.844883e-10,0.90657,3
236.06200,157.26667,      0.21935,     87.63262,50.00000,33.00000,1.845017e-10,0.90636,3
237.10001,158.33333,      0.21887,     87.55977,50.00000,33.00000,1.842747e-10,0.90617,3
238.16600,159.40000,      0.21715,     87.53320,50.00000,33.00000,1.849117e-10,0.90595,3
239.23900,160.46667,      0.21419,     87.48027,50.00000,33.00000,1.840915e-10,0.90574,3
240.28700,161.53333,      0.21299,     87.45371,50.00000,33.00000,1.845303e-10,0.90555,3
241.35100,162.60000,      0.21126,     87.40723,50.00000,33.00000,1.844731e-10,0.90533,3
242.42200,163.66667,      0.20953,     87.35430,50.00000,33.00000,1.852513e-10,0.90514,3
243.49500,164.73333,      0.20958,     87.30117,50.00000,33.00000,1.847363e-10,0.90492,3
244.55400,165.80000,      0.20553,     87.24824,50.00000,33.00000,1.849480e-10,0.90473,3
245.61200,166.86667,      0.20432,     87.19512,50.00000,33.00000,1.839942e-10,0.90453,3
246.67400,167.93333,      0.20168,     87.14219,50.00000,33.00000,1.846523e-10,0.90431,3
247.75800,169.00000,      0.20101,     87.11563,50.00000,33.00000,1.852875e-10,0.90411,3
248.81300,170.06667,      0.19855,     87.06250,50.00000,33.00000,1.849079e-10,0.90389,3
249.89200,171.13333,      0.19948,     87.00957,50.00000,33.00000,1.849651e-10,0.90368,3
250.95700,172.20000,      0.19468,     86.92988,50.00000,33.00000,1.843929e-10,0.90346,3
252.02100,173.26667,      0.19130,     86.89902,50.00000,33.00000,1.846333e-10,0.90323,3
253.07899,174.33333,      0.19169,     86.81953,50.00000,33.00000,1.850643e-10,0.90303,3
254.16499,175.40000,      0.18669,     86.77969,50.00000,33.00000,1.849041e-10,0.90282,3
255.23100,176.46667,      0.18528,     86.72676,50.00000,33.00000,1.851082e-10,0.90259,3
256.29099,177.53333,      0.18116,     86.68027,50.00000,33.00000,1.850681e-10,0.90236,3
257.35599,178.60000,      0.18118,     86.60078,50.00000,33.00000,1.845722e-10,0.90216,3
258.42401,179.66667,      0.17777,     86.54766,50.00000,33.00000,1.853294e-10,0.90192,3
259.48499,180.73333,      0.17453,     86.49473,50.00000,33.00000,1.852493e-10,0.90172,3
260.54599,181.80000,      0.17473,     86.41504,50.00000,33.00000,1.847668e-10,0.90148,3
261.62100,182.86667,      0.16985,     86.36211,50.00000,33.00000,1.845036e-10,0.90128,3
262.68301,183.93333,      0.16950,     86.28926,50.00000,33.00000,1.844292e-10,0.90103,3
263.75601,185.00000,      0.16661,     86.19629,50.00000,33.00000,1.850738e-10,0.90083,3
264.81699,186.06667,      0.16134,     86.14336,50.00000,33.00000,1.847687e-10,0.90059,3
265.89099,187.13333,      0.16208,     86.06387,50.00000,33.00000,1.844863e-10,0.90038,3
266.95001,188.20000,      0.15770,     85.98418,50.00000,33.00000,1.842690e-10,0.90014,3
268.00500,189.26667,      0.15259,     85.93125,50.00000,33.00000,1.838875e-10,0.89993,3
269.07700,190.33333,      0.15350,     85.82520,50.00000,33.00000,1.844673e-10,0.89968,3
270.14801,191.40000,      0.14837,     85.74570,50.00000,33.00000,1.838818e-10,0.89947,3
271.21399,192.46667,      0.14672,     85.64609,50.00000,33.00000,1.845569e-10,0.89922,3
272.28601,193.53333,      0.14175,     85.55996,50.00000,33.00000,1.847496e-10,0.89901,3
273.34201,194.60000,      0.13880,     85.48711,50.00000,33.00000,1.841144e-10,0.89876,3
274.40399,195.66667,      0.13970,     85.37441,50.00000,33.00000,1.841907e-10,0.89851,3
275.47299,196.73333,      0.13305,     85.26836,50.00000,33.00000,1.843662e-10,0.89829,3
276.53500,197.80000,      0.12971,     85.18887,50.00000,33.00000,1.838684e-10,0.89804,3
277.61499,198.86667,      0.12636,     85.08926,50.00000,33.00000,1.848984e-10,0.89782,3
278.67499,199.93333,      0.12319,     85.00312,50.00000,33.00000,1.849194e-10,0.89758,3
279.74500,201.00000,      0.12241,     84.87051,50.00000,33.00000,1.841335e-10,0.89735,3
280.80899,202.06667,      0.11626,     84.73145,50.00000,33.00000,1.849422e-10,0.89710,3
281.88101,203.13333,      0.11363,     84.63203,50.00000,33.00000,1.848926e-10,0.89687,3
282.93500,204.20000,      0.11023,     84.51934,50.00000,33.00000,1.853218e-10,0.89661,3
284.00800,205.26667,      0.10591,     84.41328,50.00000,33.00000,1.841125e-10,0.89640,3
285.06500,206.33333, 9.952674e-02,     84.28066,50.00000,33.00000,1.842671e-10,0.89613,3
286.16901,207.40000, 9.778979e-02,     84.14805,50.00000,33.00000,1.837521e-10,0.89591,3
287.18701,208.46667, 9.678510e-02,     84.00215,50.00000,33.00000,1.846123e-10,0.89566,3
288.26599,209.53333, 9.130378e-02,     83.88281,50.00000,33.00000,1.845168e-10,0.89543,3
289.33301,210.60000, 8.506003e-02,     83.75039,50.00000,33.00000,1.842671e-10,0.89516,3
290.39801,211.66667, 8.310587e-02,     83.59121,50.00000,33.00000,1.844655e-10,0.89494,3
291.46301,212.73333, 7.871076e-02,     83.48516,50.00000,33.00000,1.843738e-10,0.89467,3
292.53799,213.80000, 7.355521e-02,     83.34590,50.00000,33.00000,1.850109e-10,0.89446,3
293.60199,214.86667, 6.744662e-02,     83.19121,50.00000,33.00000,1.850071e-10,0.89419,3
294.66000,215.93333, 6.696571e-02,     83.06523,50.00000,33.00000,1.848774e-10,0.89396,3
295.72900,217.00000, 6.252940e-02,     82.87969,50.00000,33.00000,1.850204e-10,0.89369,3
296.80301,218.06667, 5.732807e-02,     82.72051,50.00000,33.00000,1.850548e-10,0.89346,3
297.87000,219.13333, 5.135799e-02,     82.58359,50.00000,33.00000,1.850109e-10,0.89320,3
298.93600,220.20000, 4.801966e-02,     82.41797,50.00000,33.00000,1.854668e-10,0.89296,3
300.00800,221.26667, 4.240177e-02,     82.23887,50.00000,33.00000,1.861591e-10,0.89269,3
301.06299,222.33333, 3.733751e-02,     82.07988,50.00000,33.00000,1.858139e-10,0.89242,3
302.12601,223.40000, 3.302000e-02,     81.89414,50.00000,33.00000,1.861954e-10,0.89219,3
303.18301,224.46667, 2.869139e-02,     81.73066,50.00000,33.00000,1.863860e-10,0.89191,3
304.26099,225.53333, 2.663555e-02,     81.54277,50.00000,33.00000,1.862107e-10,0.89167,3
305.33099,226.60000, 2.000226e-02,     81.33066,50.00000,33.00000,1.862602e-10,0.89140,3
306.39301,227.66667, 1.392406e-02,     81.18496,50.00000,33.00000,1.858558e-10,0.89117,3
307.44400,228.73333, 8.785156e-03,     80.97285,50.00000,33.00000,1.859779e-10,0.89088,3
308.52499,229.80000, 6.310608e-03,     80.78711,50.00000,33.00000,1.878796e-10,0.89064,3
309.58701,230.86667,-1.148856e-03,     80.57285,50.00000,33.00000,1.878738e-10,0.89036,3
310.64099,231.93333,-7.285372e-03,     80.40039,50.00000,33.00000,1.876755e-10,0.89012,3
311.71899,233.00000,-8.830671e-03,     80.16191,50.00000,33.00000,1.872310e-10,0.88984,3
312.78101,234.06667,-1.210980e-02,     79.94961,50.00000,33.00000,1.882000e-10,0.88960,3
313.85599,235.13333,-1.886214e-02,     79.73320,50.00000,33.00000,1.878070e-10,0.88932,3
314.91800,236.20000,-2.235557e-02,     79.52109,50.00000,32.00000,1.878871e-10,0.88908,3
316.00299,237.26667,-2.798157e-02,     79.28242,50.00000,32.00000,1.875344e-10,0.88879,3
317.05600,238.33333,-3.767897e-02,     79.04375,50.00000,32.00000,1.867981e-10,0.88855,3
318.12799,239.40000,-4.372648e-02,     78.83164,50.00000,32.00000,1.861458e-10,0.88827,3
319.19699,240.46667,-4.785245e-02,     78.56641,50.00000,32.00000,1.857376e-10,0.88802,3
320.25900,241.53333,-5.761456e-02,     78.32773,50.00000,32.00000,1.857433e-10,0.88773,3
321.32800,242.60000,-5.963312e-02,     78.04277,50.00000,32.00000,1.846733e-10,0.88748,3
322.40799,243.66667,-6.671503e-02,     77.81738,50.00000,32.00000,1.852722e-10,0.88724,3
323.47198,244.73333,-7.108784e-02,     77.54121,50.00000,32.00000,1.852302e-10,0.88695,3
324.53799,245.80000,-7.995789e-02,     77.26270,50.00000,32.00000,1.849327e-10,0.88665,3
325.59299,246.86667,-8.689756e-02,     76.99102,50.00000,32.00000,1.857682e-10,0.88641,3
326.66000,247.93333,-8.896858e-02,     76.67949,50.00000,32.00000,1.852645e-10,0.88612,3
327.70801,249.00000,-9.926624e-02,     76.39004,50.00000,32.00000,1.854477e-10,0.88587,3
328.79599,250.06667,     -0.10038,     76.11152,50.00000,32.00000,1.853065e-10,0.88557,3
329.86499,251.13333,     -0.10955,     75.79785,50.00000,32.00000,1.851120e-10,0.88532,3
330.92899,252.20000,     -0.11618,     75.47949,50.00000,32.00000,1.854668e-10,0.88503,3
331.99799,253.26667,     -0.11771,     75.13047,50.00000,32.00000,1.854820e-10,0.88477,3
333.05301,254.33333,     -0.12576,     74.80781,50.00000,32.00000,1.851921e-10,0.88447,3
334.12701,255.40000,     -0.13205,     74.46309,50.00000,32.00000,1.853141e-10,0.88422,3
335.19199,256.46667,     -0.13954,     74.11621,50.00000,32.00000,1.853657e-10,0.88392,3
336.25900,257.53333,     -0.14665,     73.74277,50.00000,32.00000,1.852588e-10,0.88366,3
337.32300,258.60000,     -0.15279,     73.36504,50.00000,32.00000,1.849556e-10,0.88336,3
338.38901,259.66667,     -0.16213,     72.98926,50.00000,32.00000,1.850948e-10,0.88309,3
339.44601,260.73333,     -0.16732,     72.56504,50.00000,32.00000,1.853371e-10,0.88280,3
340.51700,261.80000,     -0.17292,     72.15410,50.00000,32.00000,1.849975e-10,0.88254,3
341.57599,262.86667,     -0.17992,     71.72754,50.00000,32.00000,1.854343e-10,0.88224,3
342.65302,263.93333,     -0.18317,     71.29453,50.00000,32.00000,1.856232e-10,0.88195,3
343.71201,265.00000,     -0.19360,     70.83047,50.00000,32.00000,1.847343e-10,0.88167,3
344.78601,266.06667,     -0.19567,     70.35977,50.00000,32.00000,1.856040e-10,0.88140,3
345.84100,267.13333,     -0.20275,     69.87813,50.00000,32.00000,1.851788e-10,0.88111,3
346.92200,268.20000,     -0.20624,     69.36543,50.00000,32.00000,1.857757e-10,0.88084,3
347.99100,269.26667,     -0.21717,     68.87051,50.00000,32.00000,1.854477e-10,0.88054,3
349.04999,270.33333,     -0.22229,     68.34902,50.00000,32.00000,1.851158e-10,0.88027,3
350.10999,271.40000,     -0.23166,     67.77676,50.00000,32.00000,1.856612e-10,0.87996,3
351.18100,272.46667,     -0.23582,     67.16699,50.00000,32.00000,1.854343e-10,0.87969,3
352.25201,273.53333,     -0.24079,     66.57031,50.00000,32.00000,1.859989e-10,0.87938,3
353.31400,274.60000,     -0.25467,     65.93164,50.00000,32.00000,1.856708e-10,0.87912,3
354.37000,275.66667,     -0.25117,     65.26445,50.00000,32.00000,1.849537e-10,0.87880,3
355.46100,276.73333,     -0.25396,     64.59043,50.00000,32.00000,1.855755e-10,0.87852,3
356.52499,277.80000,     -0.26346,     63.85469,50.00000,32.00000,1.860580e-10,0.87822,3
357.59299,278.86667,     -0.26870,     63.06133,50.00000,32.00000,1.857681e-10,0.87795,3
358.65100,279.93333,     -0.27804,     62.25039,50.00000,32.00000,1.858749e-10,0.87763,3
359.72000,281.00000,     -0.28638,     61.42852,50.00000,32.00000,1.863423e-10,0.87736,3
360.78900,282.06667,     -0.28780,     60.50254,50.00000,32.00000,1.858367e-10,0.87705,3
361.85599,283.13333,     -0.28800,     59.55918,50.00000,32.00000,1.853790e-10,0.87677,3
362.91000,284.20000,     -0.29270,     58.57578,50.00000,32.00000,1.857738e-10,0.87646,3
363.97900,285.26667,     -0.31259,     57.56387,50.00000,32.00000,1.856536e-10,0.87617,3
365.03201,286.33333,     -0.30851,     56.50762,50.00000,32.00000,1.858062e-10,0.87585,3
366.10699,287.40000,     -0.31182,     55.41816,50.00000,32.00000,1.859208e-10,0.87559,3
367.17300,288.46667,     -0.31576,     54.30234,50.00000,32.00000,1.861362e-10,0.87526,3
368.24799,289.53333,     -0.32054,     53.14004,50.00000,32.00000,1.856194e-10,0.87499,3
369.31299,290.60000,     -0.33152,     51.95781,50.00000,32.00000,1.861496e-10,0.87465,3
370.37299,291.66667,     -0.33529,     50.74473,50.00000,32.00000,1.856555e-10,0.87434,3
371.43600,292.73333,     -0.34612,     49.44336,50.00000,32.00000,1.861343e-10,0.87406,3
372.50101,293.80000,     -0.35407,     48.17949,50.00000,32.00000,1.859665e-10,0.87378,3
373.57199,294.86667,     -0.36683,     46.84922,50.00000,32.00000,1.861839e-10,0.87346,3
374.64700,295.93333,     -0.38025,     45.54766,50.00000,32.00000,1.861915e-10,0.87318,3
375.71701,297.00000,     -0.38474,     44.19551,50.00000,32.00000,1.854934e-10,0.87286,3
376.78101,298.06667,     -0.41178,     42.83418,50.00000,33.00000,1.858596e-10,0.87256,3
377.84399,299.13333,     -0.41988,     41.44668,50.00000,33.00000,1.860752e-10,0.87225,3
378.91501,300.20000,     -0.42675,     40.03906,50.00000,33.00000,1.856232e-10,0.87196,3
379.96799,301.26667,     -0.43761,     38.58516,50.00000,33.00000,1.854343e-10,0.87162,3
381.05200,302.33333,     -0.45587,     37.12891,50.00000,33.00000,1.855106e-10,0.87134,3
382.12601,303.40000,     -0.48614,     35.63516,50.00000,33.00000,1.852951e-10,0.87101,3
383.18500,304.46667,     -0.50597,     34.12832,50.00000,33.00000,1.854076e-10,0.87068,3
384.25601,305.53333,     -0.53007,     32.63457,50.00000,33.00000,1.856708e-10,0.87040,3
385.31900,306.60000,     -0.56543,     31.05898,50.00000,33.00000,1.858692e-10,0.87011,3
386.38699,307.66667,     -0.59813,     29.46152,50.00000,33.00000,1.858692e-10,0.86977,3
387.45599,308.73333,     -0.62670,     27.86387,50.00000,33.00000,1.860733e-10,0.86949,3
388.52899,309.80000,     -0.66659,     26.29941,50.00000,33.00000,1.855164e-10,0.86915,3
389.59698,310.86667,     -0.70425,     24.74395,50.00000,33.00000,1.856556e-10,0.86881,3
390.65100,311.93333,     -0.75262,     23.12207,50.00000,33.00000,1.858234e-10,0.86852,3
391.71899,313.00000,     -0.80264,     21.55098,50.00000,33.00000,1.857147e-10,0.86818,3
392.78400,314.06667,     -0.85322,     19.96445,50.00000,33.00000,1.855659e-10,0.86790,3
393.86301,315.13333,     -0.90694,     18.43320,50.00000,33.00000,1.856823e-10,0.86756,3
394.92999,316.20000,     -0.97406,     16.91289,50.00000,33.00000,1.852551e-10,0.86726,3
396.00201,317.26667,     -1.04865,     15.38379,50.00000,33.00000,1.854648e-10,0.86693,3
397.06699,318.33333,     -1.13094,     13.94102,50.00000,33.00000,1.854401e-10,0.86663,3
398.12399,319.40000,     -1.23256,     12.54668,50.00000,33.00000,1.855774e-10,0.86629,3
399.19101,320.46667,     -1.31664,     11.16348,50.00000,33.00000,1.861210e-10,0.86599,3
399.70599,320.97833,     -1.35174,     10.52480,50.00000,33.00000,1.860885e-10,0.86579,4
399.84100,321.05833,     -1.33026,     10.43652,50.00000,33.00000,1.860885e-10,0.86579,4
400.10699,321.13833,     -1.16977,     10.36797,50.00000,33.00000,1.856670e-10,0.86575,4
400.54001,321.21833,     -0.84554,     10.32813,50.00000,33.00000,1.856670e-10,0.86575,4
401.14200,321.29833,     -0.38249,     10.28613,50.00000,33.00000,1.857681e-10,0.86570,4
401.93399,321.37833,      0.21183,     10.28613,50.00000,33.00000,1.857681e-10,0.86570,4
402.91599,321.45833,      0.88647,     10.25957,50.00000,33.00000,1.859951e-10,0.86566,4
404.06500,321.53833,      1.63030,     10.25957,50.00000,33.00000,1.859951e-10,0.86566,4
405.36099,321.61833,      2.40052,     10.28613,50.00000,33.00000,1.859951e-10,0.86566,4
406.77200,321.69833,      3.15501,     10.25957,50.00000,33.00000,1.858158e-10,0.86561,4
408.28699,321.77833,      3.86395,     10.23320,50.00000,33.00000,1.858158e-10,0.86561,4
409.84399,321.85833,      4.50299,     10.20664,50.00000,33.00000,1.858997e-10,0.86555,4
411.47800,321.93833,      5.05651,     10.15352,50.00000,33.00000,1.858997e-10,0.86555,4
413.10901,322.01833,      5.51279,     10.09609,50.00000,33.00000,1.855373e-10,0.86550,4
414.71701,322.09833,      5.87277,     10.00117,50.00000,33.00000,1.855373e-10,0.86550,4
416.33499,322.17833,      6.11913,      9.89727,50.00000,33.00000,1.855068e-10,0.86543,4
417.90302,322.25833,      6.27067,      9.74707,50.00000,33.00000,1.855068e-10,0.86543,4
419.43600,322.33833,      6.34147,      9.60117,50.00000,33.00000,1.852550e-10,0.86541,4
420.93399,322.41833,      6.34518,      9.40020,50.00000,33.00000,1.852550e-10,0.86541,4
422.38000,322.49833,      6.28702,      9.24980,50.00000,33.00000,1.857910e-10,0.86535,4
423.79999,322.57833,      6.18907,      9.05977,50.00000,33.00000,1.857910e-10,0.86535,4
425.17001,322.65833,      6.07407,      8.83008,50.00000,33.00000,1.856403e-10,0.86530,4
426.51700,322.73833,      5.94015,      8.60684,50.00000,33.00000,1.856403e-10,0.86530,4
427.86200,322.81833,      5.80169,      8.39023,50.00000,33.00000,1.859130e-10,0.86525,4
429.17401,322.89833,      5.67723,      8.15605,50.00000,33.00000,1.859130e-10,0.86525,4
430.50299,322.97833,      5.57843,      7.88867,50.00000,33.00000,1.856766e-10,0.86521,4
431.84201,323.05833,      5.49573,      7.65000,50.00000,33.00000,1.856766e-10,0.86521,4
433.17700,323.13833,      5.44935,      7.38496,50.00000,33.00000,1.856594e-10,0.86516,4
434.54700,323.21833,      5.42941,      7.12422,50.00000,33.00000,1.856594e-10,0.86516,4
435.93600,323.29833,      5.43570,      6.82148,50.00000,33.00000,1.854915e-10,0.86511,4
437.35400,323.37833,      5.47298,      6.57617,50.00000,33.00000,1.854915e-10,0.86511,4
438.80200,323.45833,      5.54210,      6.28887,50.00000,33.00000,1.854019e-10,0.86506,4
440.28799,323.53833,      5.61856,      6.01055,50.00000,33.00000,1.854019e-10,0.86506,4
441.78699,323.61833,      5.71042,      5.70996,50.00000,33.00000,1.850261e-10,0.86501,4
443.32599,323.69833,      5.80750,      5.40957,50.00000,33.00000,1.850261e-10,0.86501,4
444.88901,323.77833,      5.90010,      5.07813,50.00000,33.00000,1.855640e-10,0.86496,4
446.46399,323.85833,      6.00301,      4.77969,50.00000,33.00000,1.855640e-10,0.86496,4
448.06201,323.93833,      6.10122,      4.45938,50.00000,33.00000,1.859646e-10,0.86491,4
449.67001,324.01833,      6.17736,      4.10137,50.00000,33.00000,1.859646e-10,0.86491,4
451.29001,324.09833,      6.24790,      3.76992,50.00000,33.00000,1.856346e-10,0.86487,4
452.92700,324.17833,      6.30360,      3.43184,50.00000,33.00000,1.856346e-10,0.86487,4
454.56299,324.25833,      6.34098,      3.10918,50.00000,33.00000,1.856155e-10,0.86481,4
456.20901,324.33833,      6.36673,      2.78008,50.00000,33.00000,1.856155e-10,0.86481,4
457.84399,324.41833,      6.38060,      2.45293,50.00000,33.00000,1.860409e-10,0.86475,4
459.48999,324.49833,      6.37687,      2.10156,50.00000,33.00000,1.860409e-10,0.86475,4
461.13300,324.57833,      6.35484,      1.81875,50.00000,33.00000,1.855793e-10,0.86471,4
462.76501,324.65833,      6.33141,      1.52051,50.00000,33.00000,1.855793e-10,0.86471,4
464.40799,324.73833,      6.30300,      1.20898,50.00000,33.00000,1.852895e-10,0.86466,4
466.04401,324.81833,      6.27365,      0.92168,50.00000,33.00000,1.852895e-10,0.86466,4
467.68500,324.89833,      6.24394,      0.66758,50.00000,33.00000,1.856956e-10,0.86462,4
469.31900,324.97833,      6.21069,      0.41133,50.00000,33.00000,1.856956e-10,0.86462,4
470.95901,325.05833,      6.18204,      0.18809,50.00000,33.00000,1.856956e-10,0.86462,4
472.60699,325.13833,      6.15517,-2.617187e-02,50.00000,33.00000,1.855640e-10,0.86457,4
474.23801,325.21833,      6.13562,     -0.22285,50.00000,33.00000,1.855640e-10,0.86457,4
475.89600,325.29833,      6.12281,     -0.37969,50.00000,33.00000,1.859932e-10,0.86453,4
477.53101,325.37833,      6.11998,     -0.53008,50.00000,33.00000,1.859932e-10,0.86453,4
479.17700,325.45833,      6.11431,     -0.66699,50.00000,33.00000,1.855755e-10,0.86447,4
480.83200,325.53833,      6.10912,     -0.77305,50.00000,33.00000,1.855755e-10,0.86447,4
482.47800,325.61833,      6.10139,     -0.86816,50.00000,33.00000,1.857719e-10,0.86442,4
484.14499,325.69833,      6.08844,     -0.90566,50.00000,33.00000,1.857719e-10,0.86442,4
485.81500,325.77833,      6.07711,     -0.99414,50.00000,33.00000,1.855678e-10,0.86437,4
487.47000,325.85833,      6.06096,     -1.02051,50.00000,33.00000,1.855678e-10,0.86437,4
489.13901,325.93833,      6.04553,     -1.07578,50.00000,33.00000,1.851063e-10,0.86432,4
490.81201,326.01833,      6.02783,     -1.10234,50.00000,33.00000,1.851063e-10,0.86432,4
492.48099,326.09833,      6.00705,     -1.10234,50.00000,33.00000,1.857700e-10,0.86427,4
494.16101,326.17833,      5.98280,     -1.15527,50.00000,33.00000,1.857700e-10,0.86427,4
495.83401,326.25833,      5.95297,     -1.15527,50.00000,33.00000,1.857891e-10,0.86423,4
497.49899,326.33833,      5.91971,     -1.18184,50.00000,33.00000,1.857891e-10,0.86423,4
499.16901,326.41833,      5.87918,     -1.20840,50.00000,33.00000,1.853237e-10,0.86417,4
500.84201,326.49833,      5.84066,     -1.20840,50.00000,33.00000,1.853237e-10,0.86417,4
502.51700,326.57833,      5.79429,     -1.23496,50.00000,33.00000,1.850433e-10,0.86412,4
504.19901,326.65833,      5.75465,     -1.23496,50.00000,33.00000,1.850433e-10,0.86412,4
505.86301,326.73833,      5.70821,     -1.23496,50.00000,33.00000,1.853790e-10,0.86408,4
507.53601,326.81833,      5.65961,     -1.20840,50.00000,33.00000,1.853790e-10,0.86408,4
509.20401,326.89833,      5.61295,     -1.23496,50.00000,33.00000,1.859264e-10,0.86401,4
510.87100,326.97833,      5.56779,     -1.26152,50.00000,33.00000,1.859264e-10,0.86401,4
512.53699,327.05833,      5.52287,     -1.23496,50.00000,33.00000,1.854209e-10,0.86397,4
514.20801,327.13833,      5.47325,     -1.26152,50.00000,33.00000,1.854209e-10,0.86397,4
515.86700,327.21833,      5.42679,     -1.28789,50.00000,33.00000,1.850128e-10,0.86392,4
517.53497,327.29833,      5.38066,     -1.31445,50.00000,33.00000,1.850128e-10,0.86392,4
519.20502,327.37833,      5.33203,     -1.31445,50.00000,33.00000,1.848469e-10,0.86387,4
520.87097,327.45833,      5.27984,     -1.31445,50.00000,33.00000,1.848469e-10,0.86387,4
522.53101,327.53833,      5.23165,     -1.31445,50.00000,33.00000,1.855354e-10,0.86383,4
524.18903,327.61833,      5.18218,     -1.36758,50.00000,33.00000,1.855354e-10,0.86383,4
525.85699,327.69833,      5.13151,     -1.36758,50.00000,33.00000,1.855870e-10,0.86377,4
527.51398,327.77833,      5.08051,     -1.39395,50.00000,33.00000,1.855870e-10,0.86377,4
529.17499,327.85833,      5.03209,     -1.39395,50.00000,33.00000,1.857757e-10,0.86372,4
530.83899,327.93833,      4.98370,     -1.39395,50.00000,33.00000,1.857757e-10,0.86372,4
532.49500,328.01833,      4.93449,     -1.40723,50.00000,33.00000,1.854229e-10,0.86368,4
534.15302,328.09833,      4.87685,     -1.42051,50.00000,33.00000,1.854229e-10,0.86368,4
535.81299,328.17833,      4.82177,     -1.44707,50.00000,33.00000,1.852665e-10,0.86362,4
537.47198,328.25833,      4.76435,     -1.44707,50.00000,33.00000,1.852665e-10,0.86362,4
539.12903,328.33833,      4.70587,     -1.47363,50.00000,33.00000,1.860980e-10,0.86358,4
540.78198,328.41833,      4.64657,     -1.47363,50.00000,33.00000,1.860980e-10,0.86358,4
542.43799,328.49833,      4.58363,     -1.50000,50.00000,33.00000,1.860980e-10,0.86358,4
544.08698,328.57833,      4.52426,     -1.50000,50.00000,33.00000,1.855240e-10,0.86353,4
545.74402,328.65833,      4.45893,     -1.50000,50.00000,33.00000,1.855240e-10,0.86353,4
547.38599,328.73833,      4.39869,     -1.50000,50.00000,33.00000,1.852188e-10,0.86348,4
549.02802,328.81833,      4.33347,     -1.52656,50.00000,33.00000,1.852188e-10,0.86348,4
550.68500,328.89833,      4.26698,     -1.52656,50.00000,33.00000,1.853294e-10,0.86344,4
552.31897,328.97833,      4.20374,     -1.55312,50.00000,33.00000,1.853294e-10,0.86344,4
553.97400,329.05833,      4.13717,     -1.56641,50.00000,33.00000,1.857567e-10,0.86337,4
555.61102,329.13833,      4.06837,     -1.57969,50.00000,33.00000,1.857567e-10,0.86337,4
557.25897,329.21833,      3.99958,     -1.57969,50.00000,33.00000,1.853275e-10,0.86333,4
558.90198,329.29833,      3.93020,     -1.57969,50.00000,33.00000,1.853275e-10,0.86333,4
560.55200,329.37833,      3.86187,     -1.59297,50.00000,33.00000,1.855698e-10,0.86328,4
562.19202,329.45833,      3.79531,     -1.60605,50.00000,33.00000,1.855698e-10,0.86328,4
563.84100,329.53833,      3.73276,     -1.61270,50.00000,33.00000,1.858577e-10,0.86323,4
565.47198,329.61833,      3.66319,     -1.63262,50.00000,33.00000,1.858577e-10,0.86323,4
567.10303,329.69833,      3.58852,     -1.63262,50.00000,33.00000,1.858006e-10,0.86318,4
568.74902,329.77833,      3.52081,     -1.63262,50.00000,33.00000,1.858006e-10,0.86318,4
570.38599,329.85833,      3.44528,     -1.63262,50.00000,33.00000,1.854953e-10,0.86313,4
572.02002,329.93833,      3.36996,     -1.63262,50.00000,33.00000,1.854953e-10,0.86313,4
573.65802,330.01833,      3.30132,     -1.63262,50.00000,33.00000,1.860332e-10,0.86309,4
575.28699,330.09833,      3.22347,     -1.63262,50.00000,33.00000,1.860332e-10,0.86309,4
576.93597,330.17833,      3.14969,     -1.60605,50.00000,33.00000,1.854554e-10,0.86303,4
578.56000,330.25833,      3.07363,     -1.62598,50.00000,33.00000,1.854554e-10,0.86303,4
580.20099,330.33833,      2.99840,     -1.63262,50.00000,33.00000,1.853828e-10,0.86298,4
581.83099,330.41833,      2.92472,     -1.60605,50.00000,33.00000,1.853828e-10,0.86298,4
583.46600,330.49833,      2.84613,     -1.57969,50.00000,33.00000,1.860523e-10,0.86293,4
585.09802,330.57833,      2.76831,     -1.57969,50.00000,33.00000,1.860523e-10,0.86293,4
586.73499,330.65833,      2.68965,     -1.60605,50.00000,33.00000,1.854305e-10,0.86289,4
588.36401,330.73833,      2.61502,     -1.57305,50.00000,33.00000,1.854305e-10,0.86289,4
589.98901,330.81833,      2.53489,     -1.55312,50.00000,33.00000,1.851730e-10,0.86283,4
591.62598,330.89833,      2.45227,     -1.55312,50.00000,33.00000,1.851730e-10,0.86283,4
593.25897,330.97833,      2.37400,     -1.54648,50.00000,33.00000,1.854305e-10,0.86279,4
594.89099,331.05833,      2.29652,     -1.50000,50.00000,33.00000,1.854305e-10,0.86279,4
596.52100,331.13833,      2.21983,     -1.50000,50.00000,33.00000,1.852169e-10,0.86273,4
598.14899,331.21833,      2.13622,     -1.50000,50.00000,33.00000,1.852169e-10,0.86273,4
599.78302,331.29833,      2.05396,     -1.47363,50.00000,33.00000,1.852169e-10,0.86273,4
601.41101,331.37833,      1.96971,     -1.47363,50.00000,33.00000,1.849441e-10,0.86268,4
603.03802,331.45833,      1.88875,     -1.44707,50.00000,33.00000,1.849441e-10,0.86268,4
604.66498,331.53833,      1.80414,     -1.42051,50.00000,33.00000,1.859074e-10,0.86263,4
606.29401,331.61833,      1.71449,     -1.42051,50.00000,33.00000,1.859074e-10,0.86263,4
607.91498,331.69833,      1.62756,     -1.39395,50.00000,33.00000,1.856346e-10,0.86258,4
609.53601,331.77833,      1.53976,     -1.37422,50.00000,33.00000,1.856346e-10,0.86258,4
611.16199,331.85833,      1.45108,     -1.37422,50.00000,33.00000,1.856365e-10,0.86252,4
612.77301,331.93833,      1.36065,     -1.35430,50.00000,33.00000,1.856365e-10,0.86252,4
614.41199,332.01833,      1.26994,     -1.31445,50.00000,33.00000,1.856155e-10,0.86248,4
616.02600,332.09833,      1.18450,     -1.31445,50.00000,33.00000,1.856155e-10,0.86248,4
617.64899,332.17833,      1.09651,     -1.30117,50.00000,33.00000,1.863003e-10,0.86243,4
619.27301,332.25833,      1.00736,     -1.29453,50.00000,33.00000,1.863003e-10,0.86243,4
620.89697,332.33833,      0.91761,     -1.26152,50.00000,33.00000,1.856555e-10,0.86239,4
622.50403,332.41833,      0.82952,     -1.26152,50.00000,33.00000,1.856555e-10,0.86239,4
624.13098,332.49833,      0.73233,     -1.26152,50.00000,33.00000,1.865291e-10,0.86233,4
625.74799,332.57833,      0.64248,     -1.23496,50.00000,33.00000,1.865291e-10,0.86233,4
627.37799,332.65833,      0.54719,     -1.20840,50.00000,33.00000,1.854306e-10,0.86229,4
628.99701,332.73833,      0.45157,     -1.20840,50.00000,33.00000,1.854306e-10,0.86229,4
630.60699,332.81833,      0.36106,     -1.18184,50.00000,33.00000,1.858234e-10,0.86223,4
632.23798,332.89833,      0.26538,     -1.15527,50.00000,33.00000,1.858234e-10,0.86223,4
633.85400,332.97833,      0.17109,     -1.15527,50.00000,33.00000,1.857376e-10,0.86218,4
635.48297,333.05833, 7.792451e-02,     -1.15527,50.00000,33.00000,1.857376e-10,0.86218,4
637.09802,333.13833,-1.296093e-02,     -1.12891,50.00000,33.00000,1.853600e-10,0.86213,4
638.72400,333.21833,     -0.10963,     -1.10234,50.00000,33.00000,1.853600e-10,0.86213,4
640.33899,333.29833,     -0.20806,     -1.10234,50.00000,33.00000,1.854991e-10,0.86209,4
641.95502,333.37833,     -0.30682,     -1.10234,50.00000,33.00000,1.854991e-10,0.86209,4
643.57501,333.45833,     -0.40184,     -1.07578,50.00000,33.00000,1.853447e-10,0.86204,4
645.18402,333.53833,     -0.50181,     -1.07578,50.00000,33.00000,1.853447e-10,0.86204,4
646.80902,333.61833,     -0.60152,     -1.04922,50.00000,33.00000,1.858540e-10,0.86198,4
648.41901,333.69833,     -0.70330,     -1.02285,50.00000,33.00000,1.858540e-10,0.86198,4
650.03900,333.77833,     -0.80366,     -1.02285,50.00000,33.00000,1.859951e-10,0.86193,4
651.65698,333.85833,     -0.90083,     -0.99629,50.00000,33.00000,1.859951e-10,0.86193,4
653.27802,333.93833,     -1.00007,     -0.99629,50.00000,33.00000,1.858787e-10,0.86189,4
654.88898,334.01833,     -1.10049,     -0.96973,50.00000,33.00000,1.858787e-10,0.86189,4
656.50201,334.09833,     -1.19741,     -0.96973,50.00000,33.00000,1.855068e-10,0.86184,4
658.12701,334.17833,     -1.29611,     -0.94316,50.00000,33.00000,1.855068e-10,0.86184,4
659.74701,334.25833,     -1.39305,     -0.91680,50.00000,33.00000,1.856727e-10,0.86178,4
661.35303,334.33833,     -1.49618,     -0.91016,50.00000,33.00000,1.856727e-10,0.86178,4
662.97198,334.41833,     -1.59609,     -0.89023,50.00000,33.00000,1.860428e-10,0.86173,4
664.57898,334.49833,     -1.69836,     -0.89687,50.00000,33.00000,1.860428e-10,0.86173,4
666.20099,334.57833,     -1.79623,     -0.87031,50.00000,33.00000,1.855221e-10,0.86168,4
667.84802,334.65833,     -1.89800,     -0.87031,50.00000,33.00000,1.855221e-10,0.86168,4
669.42200,334.73833,     -1.99756,     -0.85703,50.00000,33.00000,1.854763e-10,0.86163,4
671.02600,334.81833,     -2.09658,     -0.81738,50.00000,33.00000,1.854763e-10,0.86163,4
672.65601,334.89833,     -2.19476,     -0.81738,50.00000,33.00000,1.856461e-10,0.86159,4
674.25299,334.97833,     -2.29555,     -0.80410,50.00000,33.00000,1.856461e-10,0.86159,4
675.86499,335.05833,     -2.39338,     -0.76426,50.00000,33.00000,1.853390e-10,0.86153,4
677.48798,335.13833,     -2.48732,     -0.76426,50.00000,33.00000,1.853390e-10,0.86153,4
679.09802,335.21833,     -2.58631,     -0.76426,50.00000,33.00000,1.853390e-10,0.86153,4
680.70697,335.29833,     -2.68770,     -0.73770,50.00000,33.00000,1.849536e-10,0.86147,4
682.32599,335.37833,     -2.78639,     -0.73105,50.00000,33.00000,1.849536e-10,0.86147,4
683.93799,335.45833,     -2.88173,     -0.71133,50.00000,33.00000,1.857338e-10,0.86143,4
685.55603,335.53833,     -2.97918,     -0.69141,50.00000,33.00000,1.857338e-10,0.86143,4
687.15900,335.61833,     -3.07595,     -0.69141,50.00000,33.00000,1.861877e-10,0.86138,4
688.77698,335.69833,     -3.17001,     -0.68477,50.00000,33.00000,1.861877e-10,0.86138,4
690.39502,335.77833,     -3.26404,     -0.65820,50.00000,33.00000,1.854992e-10,0.86133,4
692.00403,335.85833,     -3.35953,     -0.63164,50.00000,33.00000,1.854992e-10,0.86133,4
693.61401,335.93833,     -3.45437,     -0.63164,50.00000,33.00000,1.863671e-10,0.86127,4
695.23999,336.01833,     -3.54923,     -0.60293,50.00000,33.00000,1.863671e-10,0.86127,4
696.84497,336.09833,     -3.64002,     -0.60293,50.00000,33.00000,1.848545e-10,0.86122,4
698.46301,336.17833,     -3.73262,     -0.58301,50.00000,33.00000,1.848545e-10,0.86122,4
700.08099,336.25833,     -3.82519,     -0.57637,50.00000,33.00000,1.850643e-10,0.86115,4
701.69000,336.33833,     -3.91368,     -0.55000,50.00000,33.00000,1.850643e-10,0.86115,4
703.29199,336.41833,     -4.00577,     -0.53008,50.00000,33.00000,1.853809e-10,0.86112,4
704.90900,336.49833,     -4.09202,     -0.52344,50.00000,33.00000,1.853809e-10,0.86112,4
706.53400,336.57833,     -4.18007,     -0.52344,50.00000,33.00000,1.856460e-10,0.86107,4
708.13300,336.65833,     -4.26333,     -0.49687,50.00000,33.00000,1.856460e-10,0.86107,4
709.75000,336.73833,     -4.35276,     -0.49687,50.00000,33.00000,1.853637e-10,0.86103,4
711.36700,336.81833,     -4.43872,     -0.47031,50.00000,33.00000,1.853637e-10,0.86103,4
712.97803,336.89833,     -4.51931,     -0.44395,50.00000,33.00000,1.853028e-10,0.86097,4
714.59198,336.97833,     -4.60727,     -0.44395,50.00000,33.00000,1.853028e-10,0.86097,4
716.20398,337.05833,     -4.69297,     -0.44395,50.00000,33.00000,1.858883e-10,0.86093,4
717.81500,337.13833,     -4.77641,     -0.41738,50.00000,33.00000,1.858883e-10,0.86093,4
719.43500,337.21833,     -4.86073,     -0.41738,50.00000,33.00000,1.853733e-10,0.86087,4
721.04901,337.29833,     -4.94401,     -0.39082,50.00000,33.00000,1.853733e-10,0.86087,4
722.65302,337.37833,     -5.02340,     -0.39082,50.00000,33.00000,1.855049e-10,0.86082,4
724.26001,337.45833,     -5.10489,     -0.39082,50.00000,33.00000,1.855049e-10,0.86082,4
725.88000,337.53833,     -5.18761,     -0.33789,50.00000,33.00000,1.857567e-10,0.86077,4
727.48102,337.61833,     -5.26856,     -0.33789,50.00000,33.00000,1.857567e-10,0.86077,4
729.09601,337.69833,     -5.34289,     -0.31133,50.00000,33.00000,1.850872e-10,0.86071,4
730.70697,337.77833,     -5.42054,     -0.28477,50.00000,33.00000,1.850872e-10,0.86071,4
732.32703,337.85833,     -5.49497,     -0.28477,50.00000,33.00000,1.848431e-10,0.86066,4
733.94098,337.93833,     -5.56767,     -0.28477,50.00000,33.00000,1.848431e-10,0.86066,4
735.54999,338.01833,     -5.64464,     -0.25820,50.00000,33.00000,1.850204e-10,0.86061,4
737.15802,338.09833,     -5.73924,     -0.23184,50.00000,33.00000,1.850204e-10,0.86061,4
738.77399,338.17833,     -5.81383,     -0.23184,50.00000,33.00000,1.858693e-10,0.86056,4
740.38501,338.25833,     -5.89304,     -0.21191,50.00000,33.00000,1.858693e-10,0.86056,4
741.99298,338.33833,     -5.96799,     -0.20527,50.00000,33.00000,1.852856e-10,0.86051,4
743.59998,338.41833,     -6.04058,     -0.17871,50.00000,33.00000,1.852856e-10,0.86051,4
745.21802,338.49833,     -6.11406,     -0.15215,50.00000,33.00000,1.859283e-10,0.86047,4
746.82599,338.57833,     -6.18640,     -0.15215,50.00000,33.00000,1.859283e-10,0.86047,4
748.43799,338.65833,     -6.26215,     -0.13223,50.00000,33.00000,1.859283e-10,0.86047,4
750.04797,338.73833,     -6.33425,-9.921875e-02,50.00000,33.00000,1.858596e-10,0.86042,4
751.65900,338.81833,     -6.40462,-9.921875e-02,50.00000,33.00000,1.854648e-10,0.86037,4
753.27197,338.89833,     -6.47840,-7.265625e-02,50.00000,33.00000,1.854648e-10,0.86037,4
754.88300,338.97833,     -6.55461,-7.265625e-02,50.00000,33.00000,1.854648e-10,0.86037,4
756.49500,339.05833,     -6.62297,-7.265625e-02,50.00000,33.00000,1.847382e-10,0.86032,4
758.11499,339.13833,     -6.68802,-4.609375e-02,50.00000,33.00000,1.847382e-10,0.86032,4
759.72302,339.21833,     -6.77352,-3.281250e-02,50.00000,33.00000,1.853104e-10,0.86026,4
761.33002,339.29833,     -6.83530,-1.953125e-02,50.00000,33.00000,1.853104e-10,0.86026,4
762.94299,339.37833,     -6.89727,-6.445312e-03,50.00000,33.00000,1.849250e-10,0.86021,4
764.55499,339.45833,     -6.95616, 6.835938e-03,50.00000,33.00000,1.849250e-10,0.86021,4
766.16498,339.53833,     -7.01942, 3.339844e-02,50.00000,33.00000,1.853695e-10,0.86017,4
767.77399,339.61833,     -7.08577, 3.339844e-02,50.00000,33.00000,1.853695e-10,0.86017,4
769.38397,339.69833,     -7.15849, 3.339844e-02,50.00000,33.00000,1.851978e-10,0.86011,4
770.98798,339.77833,     -7.22060, 5.996094e-02,50.00000,33.00000,1.851978e-10,0.86011,4
772.60303,339.85833,     -7.28458, 8.652344e-02,50.00000,33.00000,1.848545e-10,0.86006,4
774.21399,339.93833,     -7.34838,      0.11289,50.00000,33.00000,1.848545e-10,0.86006,4
775.81897,340.01833,     -7.41427,      0.11289,50.00000,33.00000,1.851310e-10,0.86002,4
777.43201,340.09833,     -7.47745,      0.13945,50.00000,33.00000,1.851310e-10,0.86002,4
779.03699,340.17833,     -7.53482,      0.13945,50.00000,33.00000,1.851540e-10,0.85996,4
780.64600,340.25833,     -7.59403,      0.17266,50.00000,33.00000,1.851540e-10,0.85996,4
782.25598,340.33833,     -7.65142,      0.19258,50.00000,33.00000,1.851482e-10,0.85991,4
783.85498,340.41833,     -7.70625,      0.19258,50.00000,33.00000,1.851482e-10,0.85991,4
785.47498,340.49833,     -7.76105,      0.21895,50.00000,33.00000,1.850643e-10,0.85986,4
787.07397,340.57833,     -7.81816,      0.23887,50.00000,33.00000,1.850643e-10,0.85986,4
788.68903,340.65833,     -7.87356,      0.24551,50.00000,33.00000,1.849174e-10,0.85981,4
790.28802,340.73833,     -7.92701,      0.27207,50.00000,33.00000,            ,0.44878,4
791.89899,340.81833,     -7.98035,      0.29863,50.00000,33.00000,            ,0.44814,4
793.51801,340.89833,     -8.03524,      0.31855,50.00000,33.00000,            ,0.44749,4
794.19897,340.93333,     -8.06014,      0.31855,50.00000,33.00000,            ,0.44721,4