File: data/TGA/005d-L_M/ExpDat_2025_02_22_005d-L2-dynamic-1K.csv
#EXPORTTYPE:                 ,DATA ALL
#FILE:                       ,2025_02_22_005d-L2-dynamic-1K.ngb-ss5
#FORMAT:                     ,NETZSCH5
#FTYPE:                      ,ASCII
#IDENTITY:                   ,005d-L2
#DECIMAL:                    ,POINT
#SEPARATOR:                  ,COMMA
#MTYPE:                      ,DSC
#INSTRUMENT:                 ,NETZSCH STA 449F5
#PROJECT:                    ,PS
#DATE/TIME:                  ,2/22/2025 6:43:46 PM (UTC-5)
#CORR. FILE:                 ,
#TEMPCAL:                    ,13-11-2024 10:37
#SENSITIVITY:                ,28-06-2023 13:53
#LABORATORY:                 ,Tran/Aspuru
#OPERATOR:                   ,Stanley
#REMARK:                     ,
#SAMPLE:                     ,005d-L2
#SAMPLE MASS /mg:            ,5.19
#MATERIAL:                   ,
#REFERENCE:                  ,
#REFERENCE MASS /mg:         ,0
#TYPE OF CRUCIBLE:           ,Al2O3 85 ‘l, open
#SAMPLE CRUCIBLE MASS /mg:   ,0
#REFERENCE CRUCIBLE MASS /mg:,0
#DSC RANGE /‘V:              ,5000
#TG RANGE /mg:               ,35000
#TAU-R:                      ,---
#CORR. CODE:                 ,000
#EXO:                        ,-1
#RANGE:                      ,20›C....800›C/0.0....20.0K/min
#SEGMENT:                    ,S1-4/4
#SEG. 1:                     ,20›C/5.0(K/min)/100›C
#SEG. 2:                     ,100›C/00:05/100›C
#SEG. 3:                     ,100›C/1.0(K/min)/400›C
#SEG. 4:                     ,400›C/20.0(K/min)/800›C

##Temp./›C,Time/min,DSC/(mW/mg),Mass/%,Gas Flow(purge2)/(ml/min),Gas Flow(protective)/(ml/min),TIC(scan:1)/A,Sensit./(uV/mW),Segment
 42.28000,  0.00000,      1.50634,   100.00000,50.00000,37.00000,            ,0.92534,1
 44.06000,  1.06667,      0.28590,    99.12582,50.00000,37.00000,1.892280e-10,0.92542,1
 44.69400,  2.13333, 2.906456e-02,    92.42717,50.00000,37.00000,1.901416e-10,0.92548,1
 44.72800,  3.20000,-6.654651e-02,    91.60096,50.00000,37.00000,1.899910e-10,0.92553,1
 44.40600,  4.26667,     -0.11388,    90.99287,50.00000,37.00000,1.892796e-10,0.92556,1
 44.02300,  5.33333,     -0.11118,    90.67669,50.00000,37.00000,1.900005e-10,0.92557,1
 44.54600,  6.40000, 4.177098e-02,    91.01676,50.00000,37.00000,1.905976e-10,0.92558,1
 46.59000,  7.46667,      0.27551,    91.67726,50.00000,37.00000,1.899242e-10,0.92558,1
 50.05900,  8.53333,      0.50564,    92.41195,50.00000,37.00000,1.899147e-10,0.92557,1
 54.80200,  9.60000,      0.71854,    93.05491,50.00000,37.00000,1.913776e-10,0.92556,1
 60.58400, 10.66667,      0.90278,    93.68497,50.00000,37.00000,1.912880e-10,0.92555,1
 67.03600, 11.73333,      1.04601,    94.13834,50.00000,37.00000,1.910477e-10,0.92553,1
 73.87000, 12.80000,      1.14934,    94.45222,50.00000,37.00000,1.913242e-10,0.92551,1
 80.88300, 13.86667,      1.22108,    94.63545,50.00000,37.00000,1.907101e-10,0.92551,1
 87.89900, 14.93333,      1.26343,    94.71387,50.00000,37.00000,1.907902e-10,0.92552,1
 94.70600, 15.98417,      1.28790,    94.71387,50.00000,37.00000,1.914615e-10,0.92556,2
 99.26800, 16.78417,      1.12979,    94.33680,50.00000,37.00000,1.907768e-10,0.92560,2
102.33500, 17.58417,      0.78832,    93.67842,50.00000,37.00000,1.920738e-10,0.92565,2
104.46400, 18.38417,      0.54526,    93.23160,50.00000,37.00000,1.909294e-10,0.92572,2
106.04600, 19.18417,      0.38196,    92.88709,50.00000,37.00000,1.919651e-10,0.92579,2
107.00300, 19.98417,      0.21783,    92.51002,50.00000,37.00000,1.918468e-10,0.92586,2
107.41700, 20.78417, 6.813916e-02,    92.16127,50.00000,37.00000,1.923619e-10,0.92593,2
107.43700, 21.80083,-4.414677e-02,    91.78844,50.00000,37.00000,1.921691e-10,0.92602,3
107.37200, 22.86750,-6.158030e-02,    91.63160,50.00000,37.00000,1.916141e-10,0.92609,3
107.27100, 23.93417,-7.181475e-02,    91.47457,50.00000,37.00000,1.914291e-10,0.92616,3
107.18000, 25.00083,-5.997721e-02,    91.37649,50.00000,37.00000,1.917610e-10,0.92619,3
107.24500, 26.06750,-2.830982e-02,    91.34374,50.00000,37.00000,1.920586e-10,0.92620,3
107.45400, 27.13417, 7.997647e-03,    91.35029,50.00000,37.00000,1.920547e-10,0.92617,3
107.86600, 28.20083, 4.303293e-02,    91.31773,50.00000,37.00000,1.928425e-10,0.92608,3
108.43100, 29.26750, 7.744120e-02,    91.33064,50.00000,37.00000,1.917343e-10,0.92597,3
109.13500, 30.33417,      0.10787,    91.33719,50.00000,37.00000,1.923123e-10,0.92578,3
109.94500, 31.40083,      0.13383,    91.33064,50.00000,37.00000,1.927013e-10,0.92557,3
110.86800, 32.46750,      0.15581,    91.36339,50.00000,37.00000,1.925487e-10,0.92528,3
111.88000, 33.53417,      0.17236,    91.34374,50.00000,37.00000,1.931972e-10,0.92498,3
112.92900, 34.60083,      0.18396,    91.35029,50.00000,37.00000,1.927013e-10,0.92457,3
114.01600, 35.66750,      0.19317,    91.36339,50.00000,37.00000,1.924877e-10,0.92418,3
115.11900, 36.73417,      0.19869,    91.38304,50.00000,37.00000,1.934376e-10,0.92367,3
116.22200, 37.80083,      0.20118,    91.35684,50.00000,37.00000,1.927261e-10,0.92319,3
117.35900, 38.86750,      0.20383,    91.36994,50.00000,37.00000,1.931762e-10,0.92259,3
118.46600, 39.93417,      0.20392,    91.34374,50.00000,37.00000,1.931782e-10,0.92211,3
119.58400, 41.00083,      0.20401,    91.35029,50.00000,37.00000,1.933307e-10,0.92164,3
120.68800, 42.06750,      0.20313,    91.32428,50.00000,37.00000,1.926193e-10,0.92126,3
121.78400, 43.13417,      0.20370,    91.33719,50.00000,37.00000,1.935024e-10,0.92088,3
122.87400, 44.20083,      0.20395,    91.31773,50.00000,37.00000,1.927319e-10,0.92056,3
123.97200, 45.26750,      0.20227,    91.36339,50.00000,37.00000,1.927585e-10,0.92032,3
125.04300, 46.33417,      0.20220,    91.36339,50.00000,37.00000,1.927891e-10,0.92007,3
126.13100, 47.40083,      0.20213,    91.36339,50.00000,37.00000,1.930447e-10,0.91987,3
127.19600, 48.46750,      0.20190,    91.38960,50.00000,37.00000,1.928177e-10,0.91966,3
128.27100, 49.53417,      0.20151,    91.36339,50.00000,37.00000,1.934128e-10,0.91950,3
129.33200, 50.60083,      0.20225,    91.40925,50.00000,37.00000,1.932107e-10,0.91935,3
130.39101, 51.66750,      0.20235,    91.41580,50.00000,37.00000,1.935101e-10,0.91924,3
131.48000, 52.73417,      0.20455,    91.42890,50.00000,37.00000,1.934890e-10,0.91915,3
132.53999, 53.80083,      0.20271,    91.45491,50.00000,37.00000,1.939774e-10,0.91909,3
133.61099, 54.86750,      0.20443,    91.47457,50.00000,37.00000,1.945438e-10,0.91905,3
134.66499, 55.93417,      0.20275,    91.50077,50.00000,37.00000,1.932354e-10,0.91903,3
135.72900, 57.00083,      0.20350,    91.52697,50.00000,37.00000,1.935578e-10,0.91903,3
136.78999, 58.06750,      0.20344,    91.55299,50.00000,37.00000,1.937675e-10,0.91904,3
137.86400, 59.13417,      0.20517,    91.58574,50.00000,37.00000,1.936245e-10,0.91905,3
138.92300, 60.20083,      0.20495,    91.58574,50.00000,37.00000,1.934986e-10,0.91905,3
139.99899, 61.26750,      0.20571,    91.63815,50.00000,37.00000,1.934986e-10,0.91906,3
141.07600, 62.33417,      0.20388,    91.65125,50.00000,37.00000,1.940212e-10,0.91908,3
142.13699, 63.40083,      0.20496,    91.65761,50.00000,37.00000,1.938038e-10,0.91909,3
143.20799, 64.46750,      0.20378,    91.69037,50.00000,37.00000,1.942406e-10,0.91911,3
144.27800, 65.53417,      0.20259,    91.70347,50.00000,37.00000,1.935940e-10,0.91911,3
145.36000, 66.60083,      0.20304,    91.71657,50.00000,37.00000,1.939773e-10,0.91911,3
146.42101, 67.66750,      0.20136,    91.76243,50.00000,37.00000,1.941128e-10,0.91911,3
147.48700, 68.73417,      0.20408,    91.80809,50.00000,37.00000,1.941872e-10,0.91909,3
148.55099, 69.80083,      0.20355,    91.82119,50.00000,37.00000,1.934338e-10,0.91907,3
149.62399, 70.86750,      0.20139,    91.86050,50.00000,36.00000,1.934356e-10,0.91904,3
150.71800, 71.93417,      0.20168,    91.88651,50.00000,36.00000,1.939468e-10,0.91900,3
151.75500, 73.00083,      0.19984,    91.91272,50.00000,36.00000,1.935825e-10,0.91895,3
152.82401, 74.06750,      0.20094,    91.93892,50.00000,36.00000,1.942233e-10,0.91890,3
153.89000, 75.13417,      0.19992,    91.96513,50.00000,36.00000,1.943340e-10,0.91883,3
154.94701, 76.20083,      0.20103,    92.01734,50.00000,36.00000,1.940995e-10,0.91875,3
156.02400, 77.26750,      0.19985,    92.06975,50.00000,36.00000,1.941642e-10,0.91867,3
157.10001, 78.33417,      0.19883,    92.08285,50.00000,36.00000,1.938457e-10,0.91858,3
158.15900, 79.40083,      0.19748,    92.09576,50.00000,36.00000,1.943416e-10,0.91850,3
159.23199, 80.46750,      0.19532,    92.12197,50.00000,36.00000,1.939316e-10,0.91839,3
160.29800, 81.53417,      0.19594,    92.14817,50.00000,36.00000,1.938800e-10,0.91830,3
161.37000, 82.60083,      0.19295,    92.17437,50.00000,36.00000,1.940937e-10,0.91817,3
162.43401, 83.66750,      0.19045,    92.20058,50.00000,36.00000,1.942711e-10,0.91807,3
163.49600, 84.73417,      0.18992,    92.25279,50.00000,36.00000,1.940937e-10,0.91793,3
164.56700, 85.80083,      0.18742,    92.27900,50.00000,36.00000,1.946163e-10,0.91782,3
165.62399, 86.86750,      0.18607,    92.29865,50.00000,36.00000,1.947098e-10,0.91770,3
166.69701, 87.93417,      0.18274,    92.28555,50.00000,36.00000,1.942939e-10,0.91756,3
167.76601, 89.00083,      0.17842,    92.33121,50.00000,36.00000,1.951675e-10,0.91744,3
168.83800, 90.06750,      0.17459,    92.35742,50.00000,36.00000,1.943760e-10,0.91728,3
169.89301, 91.13417,      0.17224,    92.38362,50.00000,36.00000,1.944943e-10,0.91716,3
170.97200, 92.20083,      0.16724,    92.40983,50.00000,36.00000,1.947880e-10,0.91700,3
172.03000, 93.26750,      0.16538,    92.43584,50.00000,36.00000,1.940689e-10,0.91684,3
173.09900, 94.33417,      0.16004,    92.45549,50.00000,36.00000,1.949215e-10,0.91671,3
174.16701, 95.40083,      0.15735,    92.49480,50.00000,36.00000,1.944236e-10,0.91655,3
175.23399, 96.46750,      0.15415,    92.49480,50.00000,36.00000,1.944961e-10,0.91640,3
176.29800, 97.53417,      0.14963,    92.49480,50.00000,36.00000,1.947593e-10,0.91625,3
177.37100, 98.60083,      0.14675,    92.54701,50.00000,36.00000,1.947174e-10,0.91610,3
178.43900, 99.66750,      0.14421,    92.57322,50.00000,36.00000,1.949195e-10,0.91593,3
179.50400,100.73417,      0.13934,    92.59942,50.00000,36.00000,1.951447e-10,0.91579,3
180.56700,101.80083,      0.13695,    92.62563,50.00000,36.00000,1.950608e-10,0.91562,3
181.63100,102.86750,      0.13207,    92.63218,50.00000,36.00000,1.950608e-10,0.91547,3
182.69800,103.93417,      0.13050,    92.67784,50.00000,36.00000,1.944828e-10,0.91530,3
183.76500,105.00083,      0.12628,    92.69750,50.00000,36.00000,1.952076e-10,0.91516,3
184.83099,106.06750,      0.12204,    92.72370,50.00000,36.00000,1.952343e-10,0.91498,3
185.90100,107.13417,      0.11930,    92.73025,50.00000,36.00000,1.952210e-10,0.91484,3
186.96300,108.20083,      0.11622,    92.73025,50.00000,36.00000,1.954747e-10,0.91469,3
188.02800,109.26750,      0.11097,    92.76936,50.00000,36.00000,1.952534e-10,0.91451,3
189.10100,110.33417,      0.10738,    92.82177,50.00000,36.00000,1.948242e-10,0.91436,3
190.16499,111.40083,      0.10311,    92.83487,50.00000,36.00000,1.954308e-10,0.91418,3
191.22701,112.46750,      0.10169,    92.86089,50.00000,36.00000,1.957607e-10,0.91404,3
192.31000,113.53417, 9.624378e-02,    92.86089,50.00000,36.00000,1.946163e-10,0.91386,3
193.36800,114.60083, 9.229585e-02,    92.88709,50.00000,36.00000,1.955680e-10,0.91371,3
194.42400,115.66750, 8.951731e-02,    92.91329,50.00000,36.00000,1.954746e-10,0.91353,3
195.50800,116.73417, 8.471936e-02,    92.93950,50.00000,36.00000,1.953278e-10,0.91337,3
196.56100,117.80083, 8.125745e-02,    92.95260,50.00000,36.00000,1.951275e-10,0.91319,3
197.63000,118.86750, 7.610730e-02,    92.95915,50.00000,36.00000,1.953278e-10,0.91304,3
198.69600,119.93417, 7.280223e-02,    92.98516,50.00000,36.00000,1.954842e-10,0.91286,3
199.76100,121.00083, 6.864839e-02,    92.99827,50.00000,36.00000,1.957932e-10,0.91270,3
200.83099,122.06750, 6.533201e-02,    93.03757,50.00000,36.00000,1.959800e-10,0.91252,3
201.89301,123.13417, 6.302349e-02,    93.06378,50.00000,36.00000,1.955548e-10,0.91236,3
202.96700,124.20083, 5.699131e-02,    93.08979,50.00000,36.00000,1.954403e-10,0.91218,3
204.03000,125.26750, 5.331786e-02,    93.10289,50.00000,36.00000,1.957111e-10,0.91202,3
205.09599,126.33417, 4.980768e-02,    93.12909,50.00000,36.00000,1.958217e-10,0.91183,3
206.16400,127.40083, 4.544368e-02,    93.14875,50.00000,36.00000,1.960677e-10,0.91164,3
207.23000,128.46750, 4.022336e-02,    93.13565,50.00000,36.00000,1.959629e-10,0.91149,3
208.30099,129.53417, 3.567341e-02,    93.18786,50.00000,36.00000,1.958904e-10,0.91129,3
209.36501,130.60083, 3.128514e-02,    93.18786,50.00000,36.00000,1.957646e-10,0.91113,3
210.43800,131.66750, 2.603828e-02,    93.18150,50.00000,36.00000,1.963253e-10,0.91094,3
211.50301,132.73417, 2.146304e-02,    93.22717,50.00000,36.00000,1.967869e-10,0.91077,3
212.56000,133.80083, 1.704981e-02,    93.25337,50.00000,36.00000,1.958179e-10,0.91060,3
213.63300,134.86750, 1.348199e-02,    93.25337,50.00000,36.00000,1.973076e-10,0.91041,3
214.70399,135.93417, 7.686842e-03,    93.27958,50.00000,36.00000,1.961346e-10,0.91025,3
215.74800,137.00083, 1.709763e-03,    93.31869,50.00000,36.00000,1.963730e-10,0.91005,3
216.82700,138.06750,-3.251663e-03,    93.32524,50.00000,36.00000,1.960906e-10,0.90988,3
217.88200,139.13417,-6.852054e-03,    93.35145,50.00000,36.00000,1.960144e-10,0.90968,3
218.96300,140.20083,-1.080246e-02,    93.37765,50.00000,36.00000,1.966610e-10,0.90951,3
220.03600,141.26750,-1.887969e-02,    93.40366,50.00000,36.00000,1.962528e-10,0.90931,3
221.08000,142.33417,-2.456683e-02,    93.42987,50.00000,36.00000,1.966896e-10,0.90915,3
222.13400,143.40083,-2.734180e-02,    93.44297,50.00000,36.00000,1.969986e-10,0.90894,3
223.21800,144.46750,-3.270502e-02,    93.46917,50.00000,36.00000,1.964855e-10,0.90877,3
224.28700,145.53417,-3.842312e-02,    93.46262,50.00000,36.00000,1.968441e-10,0.90855,3
225.34399,146.60083,-4.328982e-02,    93.50848,50.00000,36.00000,1.961555e-10,0.90838,3
226.41600,147.66750,-4.903010e-02,    93.50193,50.00000,36.00000,1.972141e-10,0.90821,3
227.47600,148.73417,-5.374456e-02,    93.51484,50.00000,36.00000,1.974526e-10,0.90800,3
228.55200,149.80083,-6.071827e-02,    93.53449,50.00000,36.00000,1.966457e-10,0.90782,3
229.61301,150.86750,-6.649325e-02,    93.56069,50.00000,36.00000,1.965199e-10,0.90762,3
230.68500,151.93417,-7.332082e-02,    93.61310,50.00000,36.00000,1.967907e-10,0.90743,3
231.75301,153.00083,-7.825363e-02,    93.59345,50.00000,36.00000,1.962071e-10,0.90722,3
232.81700,154.06750,-8.528071e-02,    93.60655,50.00000,36.00000,1.969109e-10,0.90703,3
233.87801,155.13417,-9.023577e-02,    93.62601,50.00000,36.00000,1.965694e-10,0.90683,3
234.96201,156.20083,-9.537744e-02,    93.65222,50.00000,36.00000,1.969014e-10,0.90664,3
236.03000,157.26750,     -0.10192,    93.67187,50.00000,36.00000,1.971073e-10,0.90642,3
237.08600,158.33417,     -0.10970,    93.67187,50.00000,36.00000,1.971455e-10,0.90624,3
238.14000,159.40083,     -0.11540,    93.67187,50.00000,36.00000,1.968040e-10,0.90602,3
239.20500,160.46750,     -0.12234,    93.71118,50.00000,36.00000,1.971111e-10,0.90583,3
240.27299,161.53417,     -0.12701,    93.76339,50.00000,36.00000,1.969872e-10,0.90561,3
241.33299,162.60083,     -0.13363,    93.75684,50.00000,36.00000,1.971359e-10,0.90542,3
242.40900,163.66750,     -0.14201,    93.76339,50.00000,36.00000,1.971321e-10,0.90520,3
243.48500,164.73417,     -0.14620,    93.78960,50.00000,36.00000,1.971245e-10,0.90501,3
244.54800,165.80083,     -0.15303,    93.81580,50.00000,36.00000,1.966629e-10,0.90479,3
245.61900,166.86750,     -0.15988,    93.82890,50.00000,36.00000,1.977558e-10,0.90460,3
246.67799,167.93417,     -0.16709,    93.84836,50.00000,36.00000,1.976395e-10,0.90437,3
247.74600,169.00083,     -0.17627,    93.86146,50.00000,36.00000,1.977729e-10,0.90417,3
248.81599,170.06750,     -0.18105,    93.88112,50.00000,36.00000,1.973247e-10,0.90395,3
249.87000,171.13417,     -0.18760,    93.90732,50.00000,36.00000,1.973762e-10,0.90376,3
250.94501,172.20083,     -0.19576,    93.92697,50.00000,36.00000,1.973210e-10,0.90352,3
252.00900,173.26750,     -0.20253,    93.92042,50.00000,36.00000,1.973591e-10,0.90332,3
253.08900,174.33417,     -0.21020,    93.93353,50.00000,36.00000,1.974983e-10,0.90309,3
254.14700,175.40083,     -0.21753,    93.96609,50.00000,36.00000,1.981888e-10,0.90289,3
255.21500,176.46750,     -0.22345,    93.94008,50.00000,36.00000,1.975059e-10,0.90266,3
256.28699,177.53417,     -0.23277,    93.96609,50.00000,36.00000,1.979160e-10,0.90246,3
257.34799,178.60083,     -0.24015,    93.97919,50.00000,36.00000,1.978626e-10,0.90223,3
258.41599,179.66750,     -0.24791,    93.99884,50.00000,36.00000,1.984386e-10,0.90203,3
259.47198,180.73417,     -0.25604,    94.02505,50.00000,36.00000,1.981030e-10,0.90177,3
260.54501,181.80083,     -0.26222,    93.99884,50.00000,36.00000,1.984406e-10,0.90158,3
261.60999,182.86750,     -0.27075,    94.01195,50.00000,36.00000,1.988334e-10,0.90135,3
262.67200,183.93417,     -0.27589,    94.02505,50.00000,36.00000,1.984024e-10,0.90114,3
263.72501,185.00083,     -0.28552,    94.03160,50.00000,36.00000,1.989517e-10,0.90091,3
264.79901,186.06750,     -0.29374,    94.03160,50.00000,36.00000,1.984654e-10,0.90069,3
265.87000,187.13417,     -0.30163,    94.05780,50.00000,36.00000,1.977673e-10,0.90045,3
266.94601,188.20083,     -0.30845,    94.01195,50.00000,36.00000,1.975574e-10,0.90025,3
267.99899,189.26750,     -0.31925,    94.03815,50.00000,36.00000,1.981640e-10,0.90004,3
269.07401,190.33417,     -0.32575,    94.05125,50.00000,36.00000,1.987324e-10,0.89979,3
270.14899,191.40083,     -0.33173,    94.05337,50.00000,36.00000,1.983681e-10,0.89959,3
271.20901,192.46750,     -0.34169,    94.06647,50.00000,36.00000,1.983852e-10,0.89934,3
272.28201,193.53417,     -0.34807,    94.04682,50.00000,36.00000,1.987457e-10,0.89910,3
273.35800,194.60083,     -0.35663,    94.05337,50.00000,36.00000,1.988392e-10,0.89887,3
274.42099,195.66750,     -0.36612,    94.05337,50.00000,36.00000,1.992073e-10,0.89866,3
275.47400,196.73417,     -0.37308,    94.05337,50.00000,36.00000,1.986027e-10,0.89839,3
276.56201,197.80083,     -0.38408,    94.04027,50.00000,36.00000,1.989651e-10,0.89819,3
277.62201,198.86750,     -0.39127,    94.03372,50.00000,36.00000,1.993561e-10,0.89793,3
278.68399,199.93417,     -0.40011,    94.02717,50.00000,36.00000,1.990814e-10,0.89772,3
279.74799,201.00083,     -0.41281,    93.99441,50.00000,36.00000,1.992016e-10,0.89747,3
280.81201,202.06750,     -0.42062,    93.97495,50.00000,37.00000,2.000046e-10,0.89725,3
281.87500,203.13417,     -0.42825,    94.00096,50.00000,37.00000,2.003632e-10,0.89699,3
282.95200,204.20083,     -0.43720,    93.98150,50.00000,37.00000,1.998311e-10,0.89677,3
284.00699,205.26750,     -0.44927,    93.95530,50.00000,37.00000,2.009087e-10,0.89651,3
285.07401,206.33417,     -0.45771,    93.93565,50.00000,37.00000,2.001743e-10,0.89629,3
286.13101,207.40083,     -0.46727,    93.93565,50.00000,37.00000,1.998749e-10,0.89604,3
287.19400,208.46750,     -0.47446,    93.90289,50.00000,37.00000,2.004814e-10,0.89581,3
288.26401,209.53417,     -0.48241,    93.87688,50.00000,37.00000,2.003097e-10,0.89555,3
289.32901,210.60083,     -0.49425,    93.87688,50.00000,37.00000,2.010422e-10,0.89533,3
290.39301,211.66750,     -0.50188,    93.85723,50.00000,37.00000,2.001629e-10,0.89506,3
291.45401,212.73417,     -0.51100,    93.84412,50.00000,37.00000,2.005348e-10,0.89483,3
292.52600,213.80083,     -0.51941,    93.82447,50.00000,37.00000,2.002583e-10,0.89457,3
293.59500,214.86750,     -0.52896,    93.79827,50.00000,37.00000,2.002067e-10,0.89434,3
294.64801,215.93417,     -0.53926,    93.77861,50.00000,37.00000,2.002239e-10,0.89409,3
295.71399,217.00083,     -0.54903,    93.75260,50.00000,37.00000,1.995850e-10,0.89386,3
296.78201,218.06750,     -0.55735,    93.75915,50.00000,37.00000,1.999607e-10,0.89358,3
297.84000,219.13417,     -0.56754,    93.70019,50.00000,37.00000,1.994839e-10,0.89335,3
298.92300,220.20083,     -0.57405,    93.66744,50.00000,37.00000,1.998653e-10,0.89312,3
299.97299,221.26750,     -0.58485,    93.64798,50.00000,37.00000,1.999969e-10,0.89285,3
301.04999,222.33417,     -0.59476,    93.60212,50.00000,37.00000,1.994304e-10,0.89261,3
302.10599,223.40083,     -0.60243,    93.55626,50.00000,37.00000,1.997718e-10,0.89235,3
303.18500,224.46750,     -0.61033,    93.51715,50.00000,37.00000,1.998635e-10,0.89211,3
304.25601,225.53417,     -0.62087,    93.46474,50.00000,37.00000,1.992721e-10,0.89183,3
305.32199,226.60083,     -0.62955,    93.40597,50.00000,37.00000,1.992435e-10,0.89160,3
306.38699,227.66750,     -0.64033,    93.35356,50.00000,37.00000,1.993217e-10,0.89133,3
307.44199,228.73417,     -0.64906,    93.28613,50.00000,37.00000,1.997738e-10,0.89105,3
308.52499,229.80083,     -0.65575,    93.23160,50.00000,37.00000,1.995067e-10,0.89081,3
309.58701,230.86750,     -0.66887,    93.15299,50.00000,37.00000,1.994838e-10,0.89057,3
310.66699,231.93417,     -0.67788,    93.04836,50.00000,37.00000,1.994611e-10,0.89029,3
311.72299,233.00083,     -0.68594,    92.98960,50.00000,37.00000,2.000160e-10,0.89005,3
312.78500,234.06750,     -0.69461,    92.88940,50.00000,37.00000,1.997032e-10,0.88977,3
313.86099,235.13417,     -0.70425,    92.78459,50.00000,37.00000,1.997890e-10,0.88952,3
314.91599,236.20083,     -0.71580,    92.65395,50.00000,37.00000,1.998386e-10,0.88924,3
316.00000,237.26750,     -0.72570,    92.54933,50.00000,37.00000,1.998195e-10,0.88900,3
317.06100,238.33417,     -0.73389,    92.46416,50.00000,37.00000,2.000504e-10,0.88872,3
318.11600,239.40083,     -0.74591,    92.33353,50.00000,37.00000,1.996861e-10,0.88847,3
319.19000,240.46750,     -0.75454,    92.17649,50.00000,37.00000,1.994705e-10,0.88819,3
320.25299,241.53417,     -0.76567,    92.01946,50.00000,37.00000,2.004490e-10,0.88794,3
321.31601,242.60083,     -0.77607,    91.86262,50.00000,37.00000,1.995907e-10,0.88763,3
322.37701,243.66750,     -0.78265,    91.70559,50.00000,37.00000,1.997661e-10,0.88742,3
323.46500,244.73417,     -0.79351,    91.52254,50.00000,37.00000,1.997166e-10,0.88712,3
324.51300,245.80083,     -0.80320,    91.33950,50.00000,36.00000,2.002373e-10,0.88687,3
325.59100,246.86750,     -0.81256,    91.14335,50.00000,36.00000,2.000808e-10,0.88658,3
326.66599,247.93417,     -0.82542,    90.93391,50.00000,36.00000,1.998596e-10,0.88633,3
327.73001,249.00083,     -0.83733,    90.69634,50.00000,36.00000,2.002373e-10,0.88604,3
328.78601,250.06750,     -0.84714,    90.46089,50.00000,36.00000,2.001572e-10,0.88578,3
329.85300,251.13417,     -0.85641,    90.19942,50.00000,36.00000,1.996345e-10,0.88549,3
330.92200,252.20083,     -0.86803,    89.91156,50.00000,36.00000,2.009029e-10,0.88524,3
331.97699,253.26750,     -0.87540,    89.62389,50.00000,36.00000,2.003956e-10,0.88495,3
333.05600,254.33417,     -0.88534,    89.31002,50.00000,36.00000,2.004336e-10,0.88469,3
334.13000,255.40083,     -0.89627,    88.97861,50.00000,36.00000,2.007159e-10,0.88444,3
335.19199,256.46750,     -0.90684,    88.61021,50.00000,36.00000,2.005005e-10,0.88413,3
336.26501,257.53417,     -0.91178,    88.24412,50.00000,36.00000,2.006798e-10,0.88388,3
337.32101,258.60083,     -0.92454,    87.84952,50.00000,36.00000,2.010460e-10,0.88358,3
338.37201,259.66750,     -0.93008,    87.42659,50.00000,36.00000,2.004299e-10,0.88332,3
339.45499,260.73417,     -0.93920,    86.97322,50.00000,36.00000,2.009944e-10,0.88301,3
340.51901,261.80083,     -0.94970,    86.48921,50.00000,36.00000,2.007866e-10,0.88276,3
341.56601,262.86750,     -0.95647,    85.97052,50.00000,36.00000,2.011222e-10,0.88245,3
342.64499,263.93417,     -0.96625,    85.40809,50.00000,36.00000,2.007638e-10,0.88220,3
343.71500,265.00083,     -0.97310,    84.83911,50.00000,36.00000,2.013989e-10,0.88190,3
344.77899,266.06750,     -0.98410,    84.19383,50.00000,36.00000,2.008991e-10,0.88163,3
345.83899,267.13417,     -0.98939,    83.55742,50.00000,36.00000,2.011852e-10,0.88133,3
346.90601,268.20083,     -0.99728,    82.84451,50.00000,36.00000,2.019424e-10,0.88106,3
347.97198,269.26750,     -1.01073,    82.05992,50.00000,36.00000,2.007447e-10,0.88075,3
349.04800,270.33417,     -1.01650,    81.24682,50.00000,36.00000,2.017402e-10,0.88048,3
350.12000,271.40083,     -1.02307,    80.41618,50.00000,36.00000,2.014770e-10,0.88018,3
351.18100,272.46750,     -1.03443,    79.51599,50.00000,36.00000,2.013816e-10,0.87991,3
352.24600,273.53417,     -1.04163,    78.51098,50.00000,36.00000,2.018337e-10,0.87961,3
353.30099,274.60083,     -1.05164,    77.46686,50.00000,36.00000,2.007561e-10,0.87934,3
354.39099,275.66750,     -1.05652,    76.36609,50.00000,36.00000,2.021904e-10,0.87903,3
355.44101,276.73417,     -1.06316,    75.25222,50.00000,36.00000,2.011776e-10,0.87875,3
356.51300,277.80083,     -1.07506,    73.95511,50.00000,36.00000,2.012997e-10,0.87845,3
357.57401,278.86750,     -1.08397,    72.65819,50.00000,36.00000,2.023926e-10,0.87818,3
358.63599,279.93417,     -1.08869,    71.27611,50.00000,36.00000,2.020034e-10,0.87787,3
359.70801,281.00083,     -1.10168,    69.77649,50.00000,36.00000,2.018452e-10,0.87759,3
360.77802,282.06750,     -1.10604,    68.19383,50.00000,36.00000,2.019329e-10,0.87727,3
361.85001,283.13417,     -1.11829,    66.53931,50.00000,36.00000,2.019939e-10,0.87700,3
362.90302,284.20083,     -1.12589,    64.75183,50.00000,36.00000,2.021732e-10,0.87668,3
363.95999,285.26750,     -1.13453,    62.94489,50.00000,36.00000,2.020760e-10,0.87641,3
365.03400,286.33417,     -1.14342,    60.98073,50.00000,36.00000,2.021789e-10,0.87609,3
366.09500,287.40083,     -1.15577,    58.94913,50.00000,36.00000,2.016697e-10,0.87581,3
367.17200,288.46750,     -1.16614,    56.80636,50.00000,36.00000,2.022666e-10,0.87555,3
368.24500,289.53417,     -1.17756,    54.57861,50.00000,36.00000,2.024192e-10,0.87522,3
369.30301,290.60083,     -1.19468,    52.24836,50.00000,36.00000,2.025109e-10,0.87494,3
370.37100,291.66750,     -1.20106,    49.87669,50.00000,36.00000,2.023544e-10,0.87462,3
371.43399,292.73417,     -1.22113,    47.41118,50.00000,36.00000,2.027149e-10,0.87434,3
372.50601,293.80083,     -1.23800,    44.90000,50.00000,36.00000,2.027150e-10,0.87401,3
373.57501,294.86750,     -1.26414,    42.33430,50.00000,36.00000,2.022782e-10,0.87374,3
374.62601,295.93417,     -1.28395,    39.75568,50.00000,36.00000,2.026233e-10,0.87341,3
375.69000,297.00083,     -1.31042,    37.10058,50.00000,36.00000,2.028446e-10,0.87313,3
376.76599,298.06750,     -1.34274,    34.49788,50.00000,36.00000,2.023220e-10,0.87281,3
377.81699,299.13417,     -1.37758,    31.87553,50.00000,36.00000,2.020149e-10,0.87253,3
378.89600,300.20083,     -1.40803,    29.29672,50.00000,36.00000,2.021446e-10,0.87220,3
379.95999,301.26750,     -1.44722,    26.74200,50.00000,36.00000,2.031270e-10,0.87191,3
381.03400,302.33417,     -1.48529,    24.30482,50.00000,36.00000,2.023506e-10,0.87159,3
382.10199,303.40083,     -1.52761,    21.86994,50.00000,36.00000,2.034359e-10,0.87130,3
383.17200,304.46750,     -1.57253,    19.60944,50.00000,36.00000,2.029113e-10,0.87098,3
384.23499,305.53417,     -1.61570,    17.44933,50.00000,36.00000,2.028694e-10,0.87070,3
385.31400,306.60083,     -1.66506,    15.40462,50.00000,36.00000,2.028809e-10,0.87035,3
386.37701,307.66750,     -1.71473,    13.47765,50.00000,36.00000,2.036934e-10,0.87006,3
387.44601,308.73417,     -1.75934,    11.69884,50.00000,36.00000,2.038289e-10,0.86974,3
388.51501,309.80083,     -1.80533,    10.11850,50.00000,36.00000,2.028580e-10,0.86945,3
389.57401,310.86750,     -1.85414,     8.64489,50.00000,36.00000,2.036591e-10,0.86911,3
390.64001,311.93417,     -1.89954,     7.31522,50.00000,36.00000,2.032146e-10,0.86881,3
391.70801,313.00083,     -1.94402,     6.06609,50.00000,36.00000,2.032089e-10,0.86848,3
392.79001,314.06750,     -1.99035,     4.97842,50.00000,36.00000,2.037774e-10,0.86819,3
393.83099,315.13417,     -2.03186,     4.01927,50.00000,36.00000,2.036514e-10,0.86785,3
394.91000,316.20083,     -2.07105,     3.13430,50.00000,36.00000,2.035465e-10,0.86757,3
395.97198,317.26750,     -2.11960,     2.36917,50.00000,36.00000,2.035598e-10,0.86727,3
397.03400,318.33417,     -2.16172,     1.69114,50.00000,36.00000,2.041855e-10,0.86693,3
398.08401,319.40083,     -2.20711,     1.10694,50.00000,36.00000,2.035694e-10,0.86663,3
399.14999,320.46750,     -2.26305,     0.58593,50.00000,36.00000,2.033615e-10,0.86629,3
399.67401,320.97917,     -2.29286,     0.37245,50.00000,36.00000,2.028046e-10,0.86615,4
399.80200,321.05917,     -2.27416,     0.32659,50.00000,36.00000,2.034873e-10,0.86610,4
400.06299,321.13917,     -2.13697,     0.32004,50.00000,36.00000,2.034873e-10,0.86610,4
400.47501,321.21917,     -1.86480,     0.32004,50.00000,36.00000,2.036228e-10,0.86605,4
401.07501,321.29917,     -1.46286,     0.36590,50.00000,36.00000,2.036228e-10,0.86605,4
401.85901,321.37917,     -0.94371,     0.38555,50.00000,36.00000,2.036228e-10,0.86605,4
402.81201,321.45917,     -0.34004,     0.47264,50.00000,36.00000,2.031898e-10,0.86600,4
403.95499,321.53917,      0.31666,     0.52717,50.00000,36.00000,2.031898e-10,0.86600,4
405.22000,321.61917,      0.99350,     0.63391,50.00000,36.00000,2.031936e-10,0.86596,4
406.62299,321.69917,      1.65839,     0.68844,50.00000,36.00000,2.031936e-10,0.86596,4
408.11899,321.77917,      2.28852,     0.74740,50.00000,36.00000,2.037524e-10,0.86591,4
409.70801,321.85917,      2.85531,     0.80405,50.00000,36.00000,2.037524e-10,0.86591,4
411.28699,321.93917,      3.34128,     0.83006,50.00000,36.00000,2.039852e-10,0.86585,4
412.91501,322.01917,      3.74188,     0.85626,50.00000,36.00000,2.039852e-10,0.86585,4
414.52701,322.09917,      4.04392,     0.87592,50.00000,36.00000,2.036915e-10,0.86581,4
416.12900,322.17917,      4.25978,     0.88247,50.00000,36.00000,2.036915e-10,0.86581,4
417.70801,322.25917,      4.38904,     0.86281,50.00000,36.00000,2.038040e-10,0.86576,4
419.23001,322.33917,      4.43832,     0.85626,50.00000,36.00000,2.038040e-10,0.86576,4
420.72000,322.41917,      4.43107,     0.81060,50.00000,36.00000,2.041606e-10,0.86570,4
422.16199,322.49917,      4.36511,     0.77784,50.00000,36.00000,2.041606e-10,0.86570,4
423.57300,322.57917,      4.27218,     0.75164,50.00000,36.00000,2.035808e-10,0.86566,4
424.94699,322.65917,      4.15475,     0.69711,50.00000,36.00000,2.035808e-10,0.86566,4
426.29901,322.73917,      4.03235,     0.63622,50.00000,36.00000,2.032814e-10,0.86561,4
427.62201,322.81917,      3.90626,     0.58382,50.00000,36.00000,2.032814e-10,0.86561,4
428.94400,322.89917,      3.79713,     0.55761,50.00000,36.00000,2.035637e-10,0.86556,4
430.27600,322.97917,      3.70533,     0.51195,50.00000,36.00000,2.035637e-10,0.86556,4
431.60001,323.05917,      3.63707,     0.46397,50.00000,36.00000,2.032985e-10,0.86551,4
432.94000,323.13917,      3.59903,     0.38979,50.00000,36.00000,2.032985e-10,0.86551,4
434.29599,323.21917,      3.59070,     0.36358,50.00000,36.00000,2.033176e-10,0.86546,4
435.68399,323.29917,      3.60875,     0.33102,50.00000,36.00000,2.033176e-10,0.86546,4
437.09698,323.37917,      3.65174,     0.28304,50.00000,36.00000,2.037945e-10,0.86541,4
438.54199,323.45917,      3.71762,     0.25684,50.00000,36.00000,2.037945e-10,0.86541,4
440.03799,323.53917,      3.78713,     0.23064,50.00000,36.00000,2.035427e-10,0.86536,4
441.53601,323.61917,      3.89035,     0.20462,50.00000,36.00000,2.035427e-10,0.86536,4
443.06799,323.69917,      3.99482,     0.17842,50.00000,36.00000,2.031440e-10,0.86531,4
444.63000,323.77917,      4.10257,     0.15222,50.00000,36.00000,2.031440e-10,0.86531,4
446.21201,323.85917,      4.20883,     0.12601,50.00000,36.00000,2.038956e-10,0.86527,4
447.81201,323.93917,      4.30905,9.980732e-02,50.00000,36.00000,2.038956e-10,0.86527,4
449.42801,324.01917,      4.39821,7.379576e-02,50.00000,36.00000,2.037983e-10,0.86522,4
451.06500,324.09917,      4.48035,7.379576e-02,50.00000,36.00000,2.037983e-10,0.86522,4
452.70001,324.17917,      4.54503,4.759152e-02,50.00000,36.00000,2.037811e-10,0.86517,4
454.34100,324.25917,      4.59426,4.759152e-02,50.00000,36.00000,2.037811e-10,0.86517,4
455.98801,324.33917,      4.63432,2.138728e-02,50.00000,36.00000,2.041550e-10,0.86512,4
457.63400,324.41917,      4.65504,2.138728e-02,50.00000,36.00000,2.041550e-10,0.86512,4
459.27301,324.49917,      4.66818,2.138728e-02,50.00000,36.00000,2.037238e-10,0.86506,4
460.91000,324.57917,      4.67005,2.138728e-02,50.00000,36.00000,2.037238e-10,0.86506,4
462.54599,324.65917,      4.66405,2.138728e-02,50.00000,36.00000,2.035923e-10,0.86501,4
464.19400,324.73917,      4.65135,2.138728e-02,50.00000,36.00000,2.035923e-10,0.86501,4
465.82401,324.81917,      4.63080,2.138728e-02,50.00000,36.00000,2.037582e-10,0.86497,4
467.46100,324.89917,      4.60971,2.138728e-02,50.00000,36.00000,2.037582e-10,0.86497,4
469.10400,324.97917,      4.58365,4.759152e-02,50.00000,36.00000,2.038917e-10,0.86492,4
470.73599,325.05917,      4.56180,7.379576e-02,50.00000,36.00000,2.038917e-10,0.86492,4
472.38501,325.13917,      4.53829,7.379576e-02,50.00000,36.00000,2.038765e-10,0.86486,4
474.02100,325.21917,      4.51433,7.379576e-02,50.00000,36.00000,2.038765e-10,0.86486,4
475.66101,325.29917,      4.49637,9.980732e-02,50.00000,36.00000,2.034607e-10,0.86482,4
477.30301,325.37917,      4.47689,     0.12601,50.00000,36.00000,2.034607e-10,0.86482,4
478.95001,325.45917,      4.46039,     0.15222,50.00000,36.00000,2.034034e-10,0.86477,4
480.60400,325.53917,      4.44595,     0.17842,50.00000,36.00000,2.034034e-10,0.86477,4
482.25601,325.61917,      4.43093,     0.20462,50.00000,36.00000,2.034034e-10,0.86477,4
483.91501,325.69917,      4.41751,     0.22408,50.00000,36.00000,2.036629e-10,0.86472,4
485.58301,325.77917,      4.40287,     0.22408,50.00000,36.00000,2.036629e-10,0.86472,4
487.25601,325.85917,      4.38934,     0.25684,50.00000,36.00000,2.039623e-10,0.86467,4
488.91000,325.93917,      4.37847,     0.28960,50.00000,36.00000,2.039623e-10,0.86467,4
490.59799,326.01917,      4.36485,     0.30925,50.00000,36.00000,2.038918e-10,0.86463,4
492.26300,326.09917,      4.34571,     0.32216,50.00000,36.00000,2.038918e-10,0.86463,4
493.93500,326.17917,      4.32602,     0.36146,50.00000,36.00000,2.031803e-10,0.86457,4
495.61099,326.25917,      4.30792,     0.36146,50.00000,36.00000,2.031803e-10,0.86457,4
497.29001,326.33917,      4.28198,     0.38767,50.00000,36.00000,2.040444e-10,0.86452,4
498.94800,326.41917,      4.25506,     0.38767,50.00000,36.00000,2.040444e-10,0.86452,4
500.62799,326.49917,      4.22495,     0.41387,50.00000,36.00000,2.037468e-10,0.86447,4
502.29401,326.57917,      4.19411,     0.41387,50.00000,36.00000,2.037468e-10,0.86447,4
503.97699,326.65917,      4.16027,     0.43988,50.00000,36.00000,2.036285e-10,0.86442,4
505.63000,326.73917,      4.12829,     0.46609,50.00000,36.00000,2.036285e-10,0.86442,4
507.30801,326.81917,      4.09480,     0.49229,50.00000,36.00000,2.037277e-10,0.86437,4
508.96500,326.89917,      4.05955,     0.51850,50.00000,36.00000,2.037277e-10,0.86437,4
510.63199,326.97917,      4.02392,     0.51850,50.00000,36.00000,2.037601e-10,0.86433,4
512.30298,327.05917,      3.98468,     0.54451,50.00000,36.00000,2.037601e-10,0.86433,4
513.96301,327.13917,      3.94641,     0.57071,50.00000,36.00000,2.040596e-10,0.86428,4
515.63397,327.21917,      3.90751,     0.59692,50.00000,36.00000,2.040596e-10,0.86428,4
517.27698,327.29917,      3.87051,     0.59692,50.00000,36.00000,2.040768e-10,0.86423,4
518.95001,327.37917,      3.83023,     0.62312,50.00000,36.00000,2.040768e-10,0.86423,4
520.60199,327.45917,      3.79015,     0.62967,50.00000,36.00000,2.039719e-10,0.86418,4
522.25702,327.53917,      3.75063,     0.64913,50.00000,36.00000,2.039719e-10,0.86418,4
523.92700,327.61917,      3.71422,     0.67534,50.00000,36.00000,2.040252e-10,0.86413,4
525.58002,327.69917,      3.67506,     0.67534,50.00000,36.00000,2.040252e-10,0.86413,4
527.23999,327.77917,      3.63598,     0.70154,50.00000,36.00000,2.037392e-10,0.86408,4
528.90399,327.85917,      3.59697,     0.70154,50.00000,36.00000,2.037392e-10,0.86408,4
530.56201,327.93917,      3.55674,     0.75376,50.00000,36.00000,2.036686e-10,0.86403,4
532.20801,328.01917,      3.51575,     0.75376,50.00000,36.00000,2.036686e-10,0.86403,4
533.87500,328.09917,      3.47390,     0.75376,50.00000,36.00000,2.040100e-10,0.86398,4
535.52698,328.17917,      3.43634,     0.77996,50.00000,36.00000,2.040100e-10,0.86398,4
537.19202,328.25917,      3.39256,     0.80617,50.00000,36.00000,2.039548e-10,0.86394,4
538.84399,328.33917,      3.34927,     0.83237,50.00000,36.00000,2.039548e-10,0.86394,4
540.49701,328.41917,      3.30911,     0.84547,50.00000,36.00000,2.038078e-10,0.86388,4
542.15601,328.49917,      3.26468,     0.85857,50.00000,36.00000,2.038078e-10,0.86388,4
543.80200,328.57917,      3.22255,     0.88459,50.00000,36.00000,2.040920e-10,0.86383,4
545.44702,328.65917,      3.18176,     0.88459,50.00000,36.00000,2.040920e-10,0.86383,4
547.09601,328.73917,      3.13849,     0.91079,50.00000,36.00000,2.040920e-10,0.86383,4
548.73798,328.81917,      3.09601,     0.91079,50.00000,36.00000,2.041569e-10,0.86378,4
550.39600,328.89917,      3.04927,     0.96320,50.00000,36.00000,2.041569e-10,0.86378,4
552.05298,328.97917,      3.00671,     0.96320,50.00000,36.00000,2.030831e-10,0.86373,4
553.69897,329.05917,      2.96132,     0.98921,50.00000,36.00000,2.030831e-10,0.86373,4
555.34698,329.13917,      2.91469,     0.98921,50.00000,36.00000,2.039337e-10,0.86368,4
556.99402,329.21917,      2.86863,     0.98921,50.00000,36.00000,2.039337e-10,0.86368,4
558.64301,329.29917,      2.82837,     1.01541,50.00000,36.00000,2.034245e-10,0.86363,4
560.29401,329.37917,      2.78897,     1.01541,50.00000,36.00000,2.034245e-10,0.86363,4
561.93402,329.45917,      2.74805,     1.04162,50.00000,36.00000,2.036285e-10,0.86359,4
563.58002,329.53917,      2.69989,     1.08073,50.00000,36.00000,2.036285e-10,0.86359,4
565.21802,329.61917,      2.65359,     1.09383,50.00000,36.00000,2.035065e-10,0.86353,4
566.87000,329.69917,      2.60898,     1.09383,50.00000,36.00000,2.035065e-10,0.86353,4
568.50500,329.77917,      2.56359,     1.12004,50.00000,36.00000,2.034473e-10,0.86348,4
570.15302,329.85917,      2.51937,     1.14624,50.00000,36.00000,2.034473e-10,0.86348,4
571.79102,329.93917,      2.46804,     1.15934,50.00000,36.00000,2.040290e-10,0.86343,4
573.43298,330.01917,      2.42473,     1.15934,50.00000,36.00000,2.040290e-10,0.86343,4
575.06299,330.09917,      2.37854,     1.15934,50.00000,36.00000,2.035351e-10,0.86339,4
576.71198,330.17917,      2.32981,     1.20077,50.00000,36.00000,2.035351e-10,0.86339,4
578.35199,330.25917,      2.28112,     1.22678,50.00000,36.00000,2.039508e-10,0.86333,4
579.97400,330.33917,      2.22951,     1.22678,50.00000,36.00000,2.039508e-10,0.86333,4
581.60797,330.41917,      2.17612,     1.22678,50.00000,36.00000,2.032948e-10,0.86329,4
583.25702,330.49917,      2.12629,     1.25299,50.00000,36.00000,2.032948e-10,0.86329,4
584.88397,330.57917,      2.07594,     1.24644,50.00000,36.00000,2.036285e-10,0.86324,4
586.52197,330.65917,      2.02703,     1.29229,50.00000,36.00000,2.036285e-10,0.86324,4
588.15302,330.73917,      1.97736,     1.29229,50.00000,36.00000,2.042427e-10,0.86318,4
589.79102,330.81917,      1.93048,     1.29229,50.00000,36.00000,2.042427e-10,0.86318,4
591.41199,330.89917,      1.88175,     1.31850,50.00000,36.00000,2.031956e-10,0.86313,4
593.06097,330.97917,      1.83695,     1.34451,50.00000,36.00000,2.031956e-10,0.86313,4
594.67999,331.05917,      1.78730,     1.34451,50.00000,36.00000,2.033119e-10,0.86309,4
596.31897,331.13917,      1.73966,     1.37071,50.00000,36.00000,2.033119e-10,0.86309,4
597.95099,331.21917,      1.69019,     1.37071,50.00000,36.00000,2.037468e-10,0.86304,4
599.58002,331.29917,      1.64243,     1.39692,50.00000,36.00000,2.037468e-10,0.86304,4
601.21600,331.37917,      1.59122,     1.39692,50.00000,36.00000,2.041855e-10,0.86298,4
602.84802,331.45917,      1.54199,     1.44913,50.00000,36.00000,2.041855e-10,0.86298,4
604.47998,331.53917,      1.49230,     1.44913,50.00000,36.00000,2.039585e-10,0.86294,4
606.09802,331.61917,      1.44405,     1.44913,50.00000,36.00000,2.039585e-10,0.86294,4
607.72601,331.69917,      1.39315,     1.44913,50.00000,36.00000,2.033501e-10,0.86289,4
609.36700,331.77917,      1.34264,     1.49499,50.00000,36.00000,2.033501e-10,0.86289,4
610.99799,331.85917,      1.28804,     1.50154,50.00000,36.00000,2.037315e-10,0.86284,4
612.61298,331.93917,      1.23351,     1.50809,50.00000,36.00000,2.037315e-10,0.86284,4
614.27100,332.01917,      1.18132,     1.52775,50.00000,36.00000,2.035694e-10,0.86279,4
615.86798,332.09917,      1.12831,     1.52775,50.00000,36.00000,2.035694e-10,0.86279,4
617.49500,332.17917,      1.07486,     1.55376,50.00000,36.00000,2.036323e-10,0.86274,4
619.11902,332.25917,      1.01787,     1.57996,50.00000,36.00000,2.036323e-10,0.86274,4
620.73297,332.33917,      0.96095,     1.57996,50.00000,36.00000,2.030144e-10,0.86269,4
622.36603,332.41917,      0.90412,     1.60829,50.00000,36.00000,2.030144e-10,0.86269,4
623.98102,332.49917,      0.84623,     1.63449,50.00000,36.00000,2.042903e-10,0.86264,4
625.61298,332.57917,      0.79236,     1.63449,50.00000,36.00000,2.042903e-10,0.86264,4
627.22601,332.65917,      0.73942,     1.63449,50.00000,36.00000,2.037182e-10,0.86257,4
628.84497,332.73917,      0.68516,     1.63449,50.00000,36.00000,2.037182e-10,0.86257,4
630.46802,332.81917,      0.63242,     1.66281,50.00000,36.00000,2.036190e-10,0.86254,4
632.09698,332.89917,      0.57271,     1.68902,50.00000,36.00000,2.036190e-10,0.86254,4
633.71899,332.97917,      0.52440,     1.71522,50.00000,36.00000,2.038116e-10,0.86249,4
635.34399,333.05917,      0.47195,     1.74123,50.00000,36.00000,2.038116e-10,0.86249,4
636.96899,333.13917,      0.41762,     1.74123,50.00000,36.00000,2.038783e-10,0.86244,4
638.59198,333.21917,      0.35998,     1.74123,50.00000,36.00000,2.038783e-10,0.86244,4
640.21301,333.29917,      0.30328,     1.76744,50.00000,36.00000,2.038783e-10,0.86244,4
641.84900,333.37917,      0.24469,     1.79364,50.00000,36.00000,2.040824e-10,0.86239,4
643.46301,333.45917,      0.18446,     1.79364,50.00000,36.00000,2.040824e-10,0.86239,4
645.08600,333.53917,      0.11315,     1.81985,50.00000,36.00000,2.042332e-10,0.86234,4
646.71301,333.61917, 5.566283e-02,     1.84586,50.00000,36.00000,2.042332e-10,0.86234,4
648.32898,333.69917,-8.621639e-03,     1.87206,50.00000,36.00000,2.040024e-10,0.86229,4
649.94800,333.77917,-6.534295e-02,     1.87206,50.00000,36.00000,2.040024e-10,0.86229,4
651.56702,333.85917,     -0.13176,     1.87206,50.00000,36.00000,2.040119e-10,0.86224,4
653.17200,333.93917,     -0.19839,     1.87206,50.00000,36.00000,2.040119e-10,0.86224,4
654.79602,334.01917,     -0.25830,     1.89827,50.00000,36.00000,2.040557e-10,0.86219,4
656.40302,334.09917,     -0.32274,     1.92447,50.00000,36.00000,2.040557e-10,0.86219,4
658.05298,334.17917,     -0.38826,     1.92447,50.00000,36.00000,2.036133e-10,0.86213,4
659.63501,334.25917,     -0.45397,     1.92447,50.00000,36.00000,2.036133e-10,0.86213,4
661.24597,334.33917,     -0.51989,     1.97900,50.00000,36.00000,2.043400e-10,0.86208,4
662.85602,334.41917,     -0.58427,     1.97900,50.00000,36.00000,2.043400e-10,0.86208,4
664.47699,334.49917,     -0.65441,     1.97900,50.00000,36.00000,2.039261e-10,0.86204,4
666.09100,334.57917,     -0.71920,     2.00501,50.00000,36.00000,2.039261e-10,0.86204,4
667.70502,334.65917,     -0.78213,     2.01811,50.00000,36.00000,2.039127e-10,0.86199,4
669.31897,334.73917,     -0.84702,     2.01811,50.00000,36.00000,2.039127e-10,0.86199,4
670.94000,334.81917,     -0.90918,     2.01811,50.00000,36.00000,2.031574e-10,0.86194,4
672.54901,334.89917,     -0.97328,     2.05742,50.00000,36.00000,2.031574e-10,0.86194,4
674.16400,334.97917,     -1.03758,     2.08362,50.00000,36.00000,2.042236e-10,0.86188,4
675.78802,335.05917,     -1.10355,     2.08362,50.00000,36.00000,2.042236e-10,0.86188,4
677.39899,335.13917,     -1.17208,     2.08362,50.00000,36.00000,2.037850e-10,0.86183,4
679.01703,335.21917,     -1.23934,     2.10963,50.00000,36.00000,2.037850e-10,0.86183,4
680.63898,335.29917,     -1.30324,     2.11618,50.00000,36.00000,2.032833e-10,0.86179,4
682.25098,335.37917,     -1.37416,     2.13584,50.00000,36.00000,2.032833e-10,0.86179,4
683.86603,335.45917,     -1.44796,     2.16204,50.00000,36.00000,2.042599e-10,0.86173,4
685.48602,335.53917,     -1.52437,     2.16204,50.00000,36.00000,2.042599e-10,0.86173,4
687.09399,335.61917,     -1.59920,     2.18825,50.00000,36.00000,2.041798e-10,0.86168,4
688.71301,335.69917,     -1.67068,     2.18825,50.00000,36.00000,2.041798e-10,0.86168,4
690.32800,335.77917,     -1.73937,     2.18825,50.00000,36.00000,2.041740e-10,0.86163,4
691.94299,335.85917,     -1.80675,     2.21426,50.00000,36.00000,2.041740e-10,0.86163,4
693.55499,335.93917,     -1.87913,     2.23391,50.00000,36.00000,2.041740e-10,0.86163,4
695.16998,336.01917,     -1.94751,     2.24046,50.00000,36.00000,2.040634e-10,0.86158,4
696.79102,336.09917,     -2.01550,     2.26012,50.00000,36.00000,2.040634e-10,0.86158,4
698.40100,336.17917,     -2.08396,     2.26012,50.00000,36.00000,2.047538e-10,0.86153,4
700.01703,336.25917,     -2.15021,     2.26667,50.00000,36.00000,2.047538e-10,0.86153,4
701.63898,336.33917,     -2.21818,     2.29287,50.00000,36.00000,2.040043e-10,0.86148,4
703.25201,336.41917,     -2.29389,     2.31888,50.00000,36.00000,2.040043e-10,0.86148,4
704.85999,336.49917,     -2.36677,     2.31888,50.00000,36.00000,2.034073e-10,0.86144,4
706.47803,336.57917,     -2.43410,     2.34509,50.00000,36.00000,2.034073e-10,0.86144,4
708.09100,336.65917,     -2.49918,     2.34509,50.00000,36.00000,2.038612e-10,0.86138,4
709.70203,336.73917,     -2.56718,     2.34509,50.00000,36.00000,2.038612e-10,0.86138,4
711.32001,336.81917,     -2.63263,     2.37129,50.00000,36.00000,2.040825e-10,0.86134,4
712.92902,336.89917,     -2.70130,     2.39750,50.00000,36.00000,2.040825e-10,0.86134,4
714.55603,336.97917,     -2.76715,     2.39750,50.00000,36.00000,2.035427e-10,0.86127,4
716.16498,337.05917,     -2.83037,     2.39750,50.00000,36.00000,2.035427e-10,0.86127,4
717.78497,337.13917,     -2.89779,     2.43006,50.00000,36.00000,2.044105e-10,0.86123,4
719.39001,337.21917,     -2.96258,     2.44971,50.00000,36.00000,2.044105e-10,0.86123,4
721.00201,337.29917,     -3.03280,     2.44316,50.00000,36.00000,2.039700e-10,0.86118,4
722.61102,337.37917,     -3.10599,     2.44316,50.00000,36.00000,2.039700e-10,0.86118,4
724.22400,337.45917,     -3.17537,     2.46936,50.00000,36.00000,2.039414e-10,0.86113,4
725.83502,337.53917,     -3.24648,     2.46936,50.00000,36.00000,2.039414e-10,0.86113,4
727.45300,337.61917,     -3.31378,     2.48902,50.00000,36.00000,2.037697e-10,0.86108,4
729.06403,337.69917,     -3.38931,     2.52177,50.00000,36.00000,2.037697e-10,0.86108,4
730.67401,337.77917,     -3.45075,     2.54778,50.00000,36.00000,2.036972e-10,0.86103,4
732.29303,337.85917,     -3.52079,     2.57399,50.00000,36.00000,2.036972e-10,0.86103,4
733.89899,337.93917,     -3.57913,     2.57399,50.00000,36.00000,2.038327e-10,0.86098,4
735.51703,338.01917,     -3.64610,     2.57399,50.00000,36.00000,2.038327e-10,0.86098,4
737.14099,338.09917,     -3.70514,     2.57399,50.00000,36.00000,2.042294e-10,0.86092,4
738.75897,338.17917,     -3.77215,     2.60019,50.00000,36.00000,2.042294e-10,0.86092,4
740.37201,338.25917,     -3.84370,     2.60019,50.00000,36.00000,2.029953e-10,0.86088,4
741.96997,338.33917,     -3.89657,     2.62640,50.00000,36.00000,2.029953e-10,0.86088,4
743.60101,338.41917,     -3.96541,     2.65241,50.00000,36.00000,2.041435e-10,0.86083,4
745.21002,338.49917,     -4.02680,     2.67861,50.00000,36.00000,2.041435e-10,0.86083,4
746.82501,338.57917,     -4.09154,     2.67861,50.00000,36.00000,2.035046e-10,0.86078,4
748.44299,338.65917,     -4.15141,     2.67861,50.00000,36.00000,2.035046e-10,0.86078,4
750.05200,338.73917,     -4.21361,     2.70482,50.00000,36.00000,2.040367e-10,0.86073,4
751.65900,338.81917,     -4.27218,     2.70482,50.00000,36.00000,2.040367e-10,0.86073,4
753.28101,338.89917,     -4.33952,     2.71792,50.00000,36.00000,2.043667e-10,0.86068,4
754.89502,338.97917,     -4.40067,     2.73102,50.00000,36.00000,2.043667e-10,0.86068,4
756.49799,339.05917,     -4.46607,     2.75703,50.00000,36.00000,2.045670e-10,0.86063,4
758.11603,339.13917,     -4.52852,     2.75703,50.00000,36.00000,2.045670e-10,0.86063,4
759.72900,339.21917,     -4.59335,     2.78324,50.00000,36.00000,2.030544e-10,0.86057,4
761.33197,339.29917,     -4.66151,     2.78324,50.00000,36.00000,2.030544e-10,0.86057,4
762.95001,339.37917,     -4.72768,     2.80944,50.00000,36.00000,2.030544e-10,0.86057,4
764.55701,339.45917,     -4.78470,     2.83565,50.00000,36.00000,2.035180e-10,0.86052,4
766.16199,339.53917,     -4.84955,     2.83565,50.00000,36.00000,2.035180e-10,0.86052,4
767.77301,339.61917,     -4.90241,     2.83565,50.00000,36.00000,2.036343e-10,0.86047,4
769.38300,339.69917,     -4.96184,     2.86185,50.00000,36.00000,2.036343e-10,0.86047,4
771.00201,339.77917,     -5.01632,     2.86185,50.00000,36.00000,2.034073e-10,0.86043,4
772.61200,339.85917,     -5.08767,     2.88786,50.00000,36.00000,2.034073e-10,0.86043,4
774.21899,339.93917,     -5.14274,     2.88786,50.00000,36.00000,2.043323e-10,0.86037,4
775.83099,340.01917,     -5.19636,     2.91407,50.00000,36.00000,2.043323e-10,0.86037,4
777.44299,340.09917,     -5.25920,     2.91407,50.00000,36.00000,2.041855e-10,0.86032,4
779.05603,340.17917,     -5.31346,     2.91407,50.00000,36.00000,2.041855e-10,0.86032,4
780.66803,340.25917,     -5.36851,     2.92062,50.00000,36.00000,2.041816e-10,0.86027,4
782.27502,340.33917,     -5.42304,     2.94027,50.00000,36.00000,2.041816e-10,0.86027,4
783.89099,340.41917,     -5.47776,     2.96647,50.00000,36.00000,2.035962e-10,0.86022,4
785.49500,340.49917,     -5.53747,     2.98593,50.00000,36.00000,2.035962e-10,0.86022,4
787.09998,340.57917,     -5.59213,     2.99249,50.00000,36.00000,2.040139e-10,0.86017,4
788.71100,340.65917,     -5.64337,     2.99249,50.00000,36.00000,            ,0.44942,4
790.31500,340.73917,     -5.70159,     3.01869,50.00000,36.00000,            ,0.44877,4
791.92102,340.81917,     -5.75343,     3.04489,50.00000,36.00000,            ,0.44813,4
793.54102,340.89917,     -5.80779,     3.05800,50.00000,36.00000,            ,0.44748,4
794.23798,340.93417,     -5.82851,     3.07110,50.00000,36.00000,            ,0.44720,4