File: data/TGA/005d-L_M/ExpDat_2025_02_22_PS-F4-dynamic-1K.csv
#EXPORTTYPE:                 ,DATA ALL
#FILE:                       ,2025_02_22_PS-F4-dynamic-1K.ngb-ss5
#FORMAT:                     ,NETZSCH5
#FTYPE:                      ,ASCII
#IDENTITY:                   ,PS-F4
#DECIMAL:                    ,POINT
#SEPARATOR:                  ,COMMA
#MTYPE:                      ,DSC
#INSTRUMENT:                 ,NETZSCH STA 449F5
#PROJECT:                    ,PS
#DATE/TIME:                  ,2/22/2025 12:04:15 PM (UTC-5)
#CORR. FILE:                 ,
#TEMPCAL:                    ,13-11-2024 10:37
#SENSITIVITY:                ,28-06-2023 13:53
#LABORATORY:                 ,Tran/Aspuru
#OPERATOR:                   ,Stanley
#REMARK:                     ,
#SAMPLE:                     ,PS-F4
#SAMPLE MASS /mg:            ,5.35
#MATERIAL:                   ,
#REFERENCE:                  ,
#REFERENCE MASS /mg:         ,0
#TYPE OF CRUCIBLE:           ,Al2O3 85 ‘l, open
#SAMPLE CRUCIBLE MASS /mg:   ,0
#REFERENCE CRUCIBLE MASS /mg:,0
#DSC RANGE /‘V:              ,5000
#TG RANGE /mg:               ,35000
#TAU-R:                      ,---
#CORR. CODE:                 ,000
#EXO:                        ,-1
#RANGE:                      ,20›C....800›C/0.0....20.0K/min
#SEGMENT:                    ,S1-4/4
#SEG. 1:                     ,20›C/5.0(K/min)/100›C
#SEG. 2:                     ,100›C/00:05/100›C
#SEG. 3:                     ,100›C/1.0(K/min)/400›C
#SEG. 4:                     ,400›C/20.0(K/min)/800›C

##Temp./›C,Time/min,DSC/(mW/mg),Mass/%,Gas Flow(purge2)/(ml/min),Gas Flow(protective)/(ml/min),TIC(scan:1)/A,Sensit./(uV/mW),Segment
 37.03700,  0.00000,      0.97914,    100.00000,50.00000,35.00000,            ,0.92470,1
 38.52000,  1.06667,      0.30190,     99.58972,50.00000,34.00000,1.900997e-10,0.92478,1
 39.38000,  2.13333,      0.10622,     93.62841,50.00000,34.00000,1.905155e-10,0.92486,1
 39.78700,  3.20000, 9.712026e-03,     92.66000,50.00000,34.00000,1.906700e-10,0.92492,1
 39.96800,  4.26667,-3.298927e-02,     92.13346,50.00000,34.00000,1.913987e-10,0.92497,1
 40.70300,  5.33333, 9.233050e-02,     92.26037,50.00000,34.00000,1.910419e-10,0.92501,1
 42.71200,  6.40000,      0.35983,     92.72766,50.00000,34.00000,1.909675e-10,0.92503,1
 46.09300,  7.46667,      0.64194,     93.25850,50.00000,34.00000,1.908741e-10,0.92506,1
 50.66100,  8.53333,      0.90631,     93.87794,50.00000,34.00000,1.913719e-10,0.92506,1
 56.19800,  9.60000,      1.14463,     94.40243,50.00000,35.00000,1.913185e-10,0.92507,1
 62.46500, 10.66667,      1.33235,     94.78729,50.00000,35.00000,1.911831e-10,0.92508,1
 69.15400, 11.73333,      1.46569,     95.06636,50.00000,35.00000,1.913719e-10,0.92510,1
 75.99500, 12.80000,      1.55924,     95.26953,50.00000,35.00000,1.905250e-10,0.92514,1
 82.85600, 13.86667,      1.61841,     95.38991,50.00000,35.00000,1.906566e-10,0.92522,1
 89.66200, 14.93333,      1.64913,     95.47888,50.00000,35.00000,1.911335e-10,0.92530,1
 96.20300, 15.98417,      1.65124,     95.52318,50.00000,35.00000,1.918926e-10,0.92542,2
100.55900, 16.78417,      1.45023,     95.19121,50.00000,35.00000,1.912613e-10,0.92549,2
103.41500, 17.58417,      1.02070,     94.56112,50.00000,35.00000,1.910152e-10,0.92559,2
105.36000, 18.38417,      0.70727,     94.13813,50.00000,35.00000,1.911087e-10,0.92569,2
106.75900, 19.18417,      0.48418,     93.80617,50.00000,35.00000,1.912594e-10,0.92579,2
107.56900, 19.98417,      0.26892,     93.39383,50.00000,35.00000,1.912270e-10,0.92589,2
107.85500, 20.78417, 7.355954e-02,     93.00262,50.00000,35.00000,1.913281e-10,0.92598,2
107.71400, 21.80083,-7.821173e-02,     92.64729,50.00000,35.00000,1.908093e-10,0.92607,3
107.54600, 22.86750,-9.977674e-02,     92.49290,50.00000,35.00000,1.913395e-10,0.92614,3
107.33500, 23.93417,     -0.10861,     92.28991,50.00000,35.00000,1.917419e-10,0.92619,3
107.20000, 25.00083,-9.061166e-02,     92.18636,50.00000,35.00000,1.918907e-10,0.92620,3
107.20300, 26.06750,-4.577135e-02,     92.11009,50.00000,35.00000,1.912785e-10,0.92617,3
107.41600, 27.13417, 6.361866e-03,     92.05944,50.00000,35.00000,1.917572e-10,0.92610,3
107.79900, 28.20083, 5.881555e-02,     92.02131,50.00000,35.00000,1.917457e-10,0.92597,3
108.36200, 29.26750,      0.10787,     92.02131,50.00000,35.00000,1.918869e-10,0.92578,3
109.07200, 30.33417,      0.15075,     92.02131,50.00000,35.00000,1.918449e-10,0.92558,3
109.91400, 31.40083,      0.18775,     92.00019,50.00000,35.00000,1.927624e-10,0.92528,3
110.85200, 32.46750,      0.21406,     91.98748,50.00000,35.00000,1.915836e-10,0.92499,3
111.85900, 33.53417,      0.23604,     91.96206,50.00000,35.00000,1.917515e-10,0.92460,3
112.91400, 34.60083,      0.25292,     91.97477,50.00000,35.00000,1.916657e-10,0.92422,3
113.99000, 35.66750,      0.26328,     91.93682,50.00000,35.00000,1.918335e-10,0.92373,3
115.11400, 36.73417,      0.27116,     91.93682,50.00000,35.00000,1.919709e-10,0.92327,3
116.24300, 37.80083,      0.27734,     91.91140,50.00000,35.00000,1.913643e-10,0.92270,3
117.36300, 38.86750,      0.27714,     91.91140,50.00000,35.00000,1.918907e-10,0.92218,3
118.48700, 39.93417,      0.27788,     91.88598,50.00000,35.00000,1.914405e-10,0.92165,3
119.58500, 41.00083,      0.27816,     91.91140,50.00000,35.00000,1.923371e-10,0.92125,3
120.69200, 42.06750,      0.27610,     91.88598,50.00000,35.00000,1.917915e-10,0.92084,3
121.80400, 43.13417,      0.27544,     91.87327,50.00000,35.00000,1.923732e-10,0.92053,3
122.89300, 44.20083,      0.27478,     91.88598,50.00000,35.00000,1.920605e-10,0.92023,3
123.98200, 45.26750,      0.27350,     91.88598,50.00000,35.00000,1.920452e-10,0.92000,3
125.04400, 46.33417,      0.27533,     91.86692,50.00000,35.00000,1.925412e-10,0.91977,3
126.12700, 47.40083,      0.27390,     91.91776,50.00000,35.00000,1.921139e-10,0.91960,3
127.21000, 48.46750,      0.27324,     91.91140,50.00000,35.00000,1.920585e-10,0.91941,3
128.27200, 49.53417,      0.27415,     91.91140,50.00000,35.00000,1.925335e-10,0.91927,3
129.33400, 50.60083,      0.27444,     91.91776,50.00000,35.00000,1.917590e-10,0.91914,3
130.39900, 51.66750,      0.27504,     91.91570,50.00000,35.00000,1.920604e-10,0.91906,3
131.47301, 52.73417,      0.27627,     91.94093,50.00000,35.00000,1.923199e-10,0.91898,3
132.53700, 53.80083,      0.27625,     91.96000,50.00000,35.00000,1.925488e-10,0.91894,3
133.59500, 54.86750,      0.27732,     92.00449,50.00000,35.00000,1.927052e-10,0.91892,3
134.68800, 55.93417,      0.27919,     92.01084,50.00000,35.00000,1.921329e-10,0.91892,3
135.73599, 57.00083,      0.28043,     92.01720,50.00000,35.00000,1.921787e-10,0.91894,3
136.80800, 58.06750,      0.27901,     92.04243,50.00000,35.00000,1.921292e-10,0.91897,3
137.86900, 59.13417,      0.27931,     92.04879,50.00000,36.00000,1.929817e-10,0.91898,3
138.94701, 60.20083,      0.27977,     92.08056,50.00000,36.00000,1.929665e-10,0.91900,3
140.02100, 61.26750,      0.27914,     92.10598,50.00000,36.00000,1.918335e-10,0.91903,3
141.07300, 62.33417,      0.28007,     92.11234,50.00000,36.00000,1.921253e-10,0.91905,3
142.14101, 63.40083,      0.27944,     92.13757,50.00000,36.00000,1.923390e-10,0.91907,3
143.20100, 64.46750,      0.27896,     92.16935,50.00000,36.00000,1.920986e-10,0.91909,3
144.27400, 65.53417,      0.27959,     92.19477,50.00000,36.00000,1.923847e-10,0.91911,3
145.35001, 66.60083,      0.27928,     92.20748,50.00000,36.00000,1.920509e-10,0.91911,3
146.41200, 67.66750,      0.27912,     92.25178,50.00000,36.00000,1.924705e-10,0.91911,3
147.47800, 68.73417,      0.27660,     92.30897,50.00000,36.00000,1.916943e-10,0.91909,3
148.55200, 69.80083,      0.27677,     92.30897,50.00000,36.00000,1.924553e-10,0.91907,3
149.62500, 70.86750,      0.27551,     92.33439,50.00000,36.00000,1.924725e-10,0.91904,3
150.69000, 71.93417,      0.27504,     92.34692,50.00000,36.00000,1.924610e-10,0.91900,3
151.74800, 73.00083,      0.27552,     92.36598,50.00000,36.00000,1.923981e-10,0.91895,3
152.83200, 74.06750,      0.27506,     92.42318,50.00000,36.00000,1.931477e-10,0.91890,3
153.89700, 75.13417,      0.27523,     92.45477,50.00000,36.00000,1.924362e-10,0.91884,3
154.95200, 76.20083,      0.27381,     92.45477,50.00000,36.00000,1.918430e-10,0.91875,3
156.02901, 77.26750,      0.27431,     92.49925,50.00000,36.00000,1.926556e-10,0.91868,3
157.08501, 78.33417,      0.27289,     92.52467,50.00000,36.00000,1.927090e-10,0.91859,3
158.15601, 79.40083,      0.27180,     92.54785,50.00000,36.00000,1.927795e-10,0.91850,3
159.24500, 80.46750,      0.27023,     92.56056,50.00000,36.00000,1.922073e-10,0.91839,3
160.29900, 81.53417,      0.27072,     92.58598,50.00000,36.00000,1.927814e-10,0.91829,3
161.36501, 82.60083,      0.26819,     92.63664,50.00000,36.00000,1.926994e-10,0.91817,3
162.42300, 83.66750,      0.26773,     92.66206,50.00000,36.00000,1.923084e-10,0.91806,3
163.49500, 84.73417,      0.26791,     92.66206,50.00000,36.00000,1.923847e-10,0.91793,3
164.55800, 85.80083,      0.26682,     92.67477,50.00000,36.00000,1.924858e-10,0.91781,3
165.63200, 86.86750,      0.26365,     92.72561,50.00000,36.00000,1.931247e-10,0.91767,3
166.68600, 87.93417,      0.26383,     92.78262,50.00000,36.00000,1.928711e-10,0.91755,3
167.76700, 89.00083,      0.26194,     92.80804,50.00000,36.00000,1.928692e-10,0.91742,3
168.81599, 90.06750,      0.26036,     92.83346,50.00000,36.00000,1.925906e-10,0.91727,3
169.90300, 91.13417,      0.25879,     92.85869,50.00000,36.00000,1.926441e-10,0.91714,3
170.96600, 92.20083,      0.25737,     92.88411,50.00000,36.00000,1.923352e-10,0.91698,3
172.02299, 93.26750,      0.25692,     92.91589,50.00000,36.00000,1.932278e-10,0.91685,3
173.10800, 94.33417,      0.25582,     92.92860,50.00000,36.00000,1.928634e-10,0.91668,3
174.16400, 95.40083,      0.25151,     92.96019,50.00000,36.00000,1.927013e-10,0.91655,3
175.23500, 96.46750,      0.25138,     92.99832,50.00000,36.00000,1.934929e-10,0.91638,3
176.29100, 97.53417,      0.24883,     93.02374,50.00000,36.00000,1.933537e-10,0.91622,3
177.36600, 98.60083,      0.24757,     93.00467,50.00000,36.00000,1.927738e-10,0.91607,3
178.42599, 99.66750,      0.24502,     93.08505,50.00000,36.00000,1.932831e-10,0.91590,3
179.49400,100.73417,      0.24440,     93.08505,50.00000,36.00000,1.925869e-10,0.91577,3
180.55400,101.80083,      0.24217,     93.12299,50.00000,36.00000,1.933365e-10,0.91559,3
181.63300,102.86750,      0.23929,     93.14430,50.00000,36.00000,1.928501e-10,0.91545,3
182.69800,103.93417,      0.23560,     93.16953,50.00000,36.00000,1.938687e-10,0.91527,3
183.77299,105.00083,      0.23385,     93.19495,50.00000,36.00000,1.932525e-10,0.91513,3
184.82899,106.06750,      0.23225,     93.22673,50.00000,36.00000,1.929073e-10,0.91498,3
185.90401,107.13417,      0.22758,     93.23308,50.00000,36.00000,1.934243e-10,0.91481,3
186.96100,108.20083,      0.22225,     93.26467,50.00000,36.00000,1.932907e-10,0.91466,3
188.02000,109.26750,      0.21692,     93.30280,50.00000,36.00000,1.935844e-10,0.91449,3
189.10400,110.33417,      0.21272,     93.31551,50.00000,36.00000,1.928310e-10,0.91433,3
190.16200,111.40083,      0.20639,     93.34093,50.00000,36.00000,1.935901e-10,0.91416,3
191.23100,112.46750,      0.19990,     93.36636,50.00000,36.00000,1.932354e-10,0.91401,3
192.29900,113.53417,      0.19405,     93.36636,50.00000,36.00000,1.930752e-10,0.91383,3
193.37100,114.60083,      0.18721,     93.40430,50.00000,36.00000,1.937561e-10,0.91366,3
194.43500,115.66750,      0.18199,     93.43607,50.00000,36.00000,1.938056e-10,0.91350,3
195.49899,116.73417,      0.17530,     93.44879,50.00000,36.00000,1.938686e-10,0.91333,3
196.56700,117.80083,      0.17169,     93.49944,50.00000,36.00000,1.936512e-10,0.91317,3
197.63600,118.86750,      0.16726,     93.49944,50.00000,36.00000,1.938724e-10,0.91298,3
198.70700,119.93417,      0.16234,     93.51215,50.00000,36.00000,1.940594e-10,0.91283,3
199.76601,121.00083,      0.15774,     93.55664,50.00000,36.00000,1.941890e-10,0.91265,3
200.84399,122.06750,      0.15280,     93.57570,50.00000,37.00000,1.940822e-10,0.91249,3
201.88901,123.13417,      0.14932,     93.58822,50.00000,37.00000,1.945515e-10,0.91231,3
202.96700,124.20083,      0.14421,     93.62000,50.00000,37.00000,1.942081e-10,0.91215,3
204.02699,125.26750,      0.13859,     93.66449,50.00000,37.00000,1.943035e-10,0.91197,3
205.10001,126.33417,      0.13460,     93.65178,50.00000,37.00000,1.944847e-10,0.91181,3
206.16600,127.40083,      0.13012,     93.67084,50.00000,37.00000,1.947345e-10,0.91162,3
207.24300,128.46750,      0.12661,     93.71514,50.00000,37.00000,1.944161e-10,0.91146,3
208.29500,129.53417,      0.12046,     93.74056,50.00000,37.00000,1.949119e-10,0.91126,3
209.36600,130.60083,      0.11661,     93.76598,50.00000,37.00000,1.950435e-10,0.91110,3
210.44501,131.66750,      0.11243,     93.79757,50.00000,37.00000,1.947060e-10,0.91091,3
211.50500,132.73417,      0.10873,     93.82299,50.00000,37.00000,1.947727e-10,0.91075,3
212.56599,133.80083,      0.10172,     93.84841,50.00000,37.00000,1.948414e-10,0.91055,3
213.61501,134.86750, 9.800659e-02,     93.87383,50.00000,37.00000,1.955586e-10,0.91038,3
214.69800,135.93417, 9.594565e-02,     93.87383,50.00000,37.00000,1.950798e-10,0.91019,3
215.76199,137.00083, 8.824020e-02,     93.88654,50.00000,37.00000,1.963883e-10,0.91003,3
216.83400,138.06750, 8.284546e-02,     93.91178,50.00000,37.00000,1.956292e-10,0.90983,3
217.89900,139.13417, 7.827118e-02,     93.93720,50.00000,37.00000,1.957416e-10,0.90966,3
218.96400,140.20083, 7.368848e-02,     93.96897,50.00000,37.00000,1.959858e-10,0.90945,3
220.01601,141.26750, 6.859699e-02,     93.98804,50.00000,37.00000,1.962928e-10,0.90928,3
221.09000,142.33417, 6.566391e-02,     93.99439,50.00000,37.00000,1.954327e-10,0.90908,3
222.15300,143.40083, 5.888785e-02,     94.04505,50.00000,37.00000,1.959972e-10,0.90891,3
223.22000,144.46750, 5.560571e-02,     94.04505,50.00000,37.00000,1.959458e-10,0.90871,3
224.28799,145.53417, 5.014447e-02,     94.04505,50.00000,37.00000,1.968327e-10,0.90850,3
225.36700,146.60083, 4.299996e-02,     94.09589,50.00000,37.00000,1.965046e-10,0.90832,3
226.39900,147.66750, 4.639070e-02,     94.09589,50.00000,37.00000,1.962605e-10,0.90814,3
227.48801,148.73417, 3.822323e-02,     94.12112,50.00000,37.00000,1.968708e-10,0.90794,3
228.56799,149.80083, 3.222060e-02,     94.11907,50.00000,37.00000,1.958942e-10,0.90776,3
229.61900,150.86750, 2.838893e-02,     94.14449,50.00000,37.00000,1.975098e-10,0.90755,3
230.69000,151.93417, 2.068272e-02,     94.19514,50.00000,37.00000,1.966896e-10,0.90737,3
231.75999,153.00083, 1.733731e-02,     94.20150,50.00000,37.00000,1.967106e-10,0.90715,3
232.81700,154.06750, 1.078358e-02,     94.22692,50.00000,37.00000,1.968269e-10,0.90697,3
233.86900,155.13417, 4.891243e-03,     94.22692,50.00000,37.00000,1.966114e-10,0.90676,3
234.94099,156.20083, 1.181865e-03,     94.22692,50.00000,37.00000,1.968822e-10,0.90658,3
236.01801,157.26750,-4.732392e-03,     94.26505,50.00000,37.00000,1.971321e-10,0.90636,3
237.07600,158.33417,-1.015128e-02,     94.30523,50.00000,37.00000,1.977291e-10,0.90617,3
238.15300,159.40083,-1.575103e-02,     94.33047,50.00000,37.00000,1.967583e-10,0.90595,3
239.22200,160.46750,-2.271884e-02,     94.33682,50.00000,37.00000,1.974906e-10,0.90577,3
240.29700,161.53417,-2.902267e-02,     94.36860,50.00000,37.00000,1.978531e-10,0.90555,3
241.34300,162.60083,-3.618846e-02,     94.41944,50.00000,37.00000,1.984100e-10,0.90536,3
242.40800,163.66750,-4.217952e-02,     94.42579,50.00000,37.00000,1.975136e-10,0.90514,3
243.49800,164.73417,-4.665225e-02,     94.45103,50.00000,37.00000,1.977215e-10,0.90495,3
244.54100,165.80083,-5.624574e-02,     94.44467,50.00000,37.00000,1.981754e-10,0.90475,3
245.60600,166.86750,-6.278972e-02,     94.45103,50.00000,37.00000,1.979141e-10,0.90453,3
246.66901,167.93417,-6.866459e-02,     94.49551,50.00000,37.00000,1.984977e-10,0.90430,3
247.72900,169.00083,-7.369713e-02,     94.52093,50.00000,37.00000,1.981297e-10,0.90411,3
248.79201,170.06750,-7.993923e-02,     94.52093,50.00000,37.00000,1.985016e-10,0.90388,3
249.88000,171.13417,-8.602595e-02,     94.52093,50.00000,37.00000,1.985130e-10,0.90369,3
250.94000,172.20083,-9.246697e-02,     94.54617,50.00000,37.00000,1.983776e-10,0.90346,3
251.98900,173.26750,-9.823424e-02,     94.55888,50.00000,37.00000,1.986618e-10,0.90326,3
253.06700,174.33417,     -0.10711,     94.57794,50.00000,37.00000,1.984615e-10,0.90306,3
254.12801,175.40083,     -0.11360,     94.60972,50.00000,37.00000,1.985207e-10,0.90283,3
255.21400,176.46750,     -0.11993,     94.59701,50.00000,37.00000,1.991940e-10,0.90263,3
256.26001,177.53417,     -0.12610,     94.64131,50.00000,37.00000,1.985550e-10,0.90239,3
257.33099,178.60083,     -0.13315,     94.66037,50.00000,37.00000,1.988182e-10,0.90219,3
258.41400,179.66750,     -0.13780,     94.69215,50.00000,37.00000,1.992149e-10,0.90196,3
259.47900,180.73417,     -0.14799,     94.69850,50.00000,37.00000,1.989708e-10,0.90176,3
260.53799,181.80083,     -0.15491,     94.71121,50.00000,37.00000,1.993541e-10,0.90152,3
261.62399,182.86750,     -0.16325,     94.73664,50.00000,37.00000,1.994190e-10,0.90131,3
262.68201,183.93417,     -0.17333,     94.76187,50.00000,37.00000,1.996345e-10,0.90106,3
263.72501,185.00083,     -0.18100,     94.73664,50.00000,37.00000,1.998062e-10,0.90087,3
264.80499,186.06750,     -0.18365,     94.74299,50.00000,37.00000,1.999302e-10,0.90062,3
265.87000,187.13417,     -0.19101,     94.78093,50.00000,37.00000,1.994209e-10,0.90043,3
266.93500,188.20083,     -0.20239,     94.78729,50.00000,37.00000,2.000217e-10,0.90018,3
268.01001,189.26750,     -0.20822,     94.79364,50.00000,37.00000,1.997223e-10,0.89997,3
269.06400,190.33417,     -0.21720,     94.81907,50.00000,37.00000,1.998539e-10,0.89973,3
270.13199,191.40083,     -0.22673,     94.84449,50.00000,37.00000,2.000046e-10,0.89951,3
271.19901,192.46750,     -0.23278,     94.84449,50.00000,37.00000,1.996593e-10,0.89927,3
272.26300,193.53417,     -0.23990,     94.86972,50.00000,37.00000,2.004815e-10,0.89905,3
273.33301,194.60083,     -0.25055,     94.87607,50.00000,37.00000,1.998080e-10,0.89880,3
274.41501,195.66750,     -0.25648,     94.90150,50.00000,37.00000,2.003193e-10,0.89859,3
275.46500,196.73417,     -0.26629,     94.91421,50.00000,37.00000,1.997394e-10,0.89834,3
276.53400,197.80083,     -0.27578,     94.93327,50.00000,37.00000,2.000389e-10,0.89812,3
277.59799,198.86750,     -0.28317,     94.93963,50.00000,37.00000,2.003136e-10,0.89787,3
278.66000,199.93417,     -0.29234,     94.93327,50.00000,37.00000,1.997280e-10,0.89765,3
279.73300,201.00083,     -0.29959,     94.94598,50.00000,37.00000,1.997490e-10,0.89739,3
280.79199,202.06750,     -0.30598,     94.96486,50.00000,37.00000,2.001496e-10,0.89718,3
281.86099,203.13417,     -0.31646,     95.01570,50.00000,37.00000,1.994095e-10,0.89692,3
282.93399,204.20083,     -0.32270,     94.99664,50.00000,37.00000,1.993942e-10,0.89670,3
283.99899,205.26750,     -0.33430,     95.00935,50.00000,37.00000,1.993599e-10,0.89644,3
285.06500,206.33417,     -0.34147,     95.00935,50.00000,37.00000,2.000256e-10,0.89622,3
286.12900,207.40083,     -0.35169,     94.98393,50.00000,37.00000,1.987762e-10,0.89596,3
287.18701,208.46750,     -0.35943,     95.03477,50.00000,37.00000,1.859912e-10,0.89574,3
288.26501,209.53417,     -0.36631,     95.03477,50.00000,37.00000,1.864147e-10,0.89552,3
289.32700,210.60083,     -0.37570,     95.02841,50.00000,37.00000,1.857929e-10,0.89526,3
290.39600,211.66750,     -0.38853,     95.04112,50.00000,37.00000,1.858635e-10,0.89503,3
291.44501,212.73417,     -0.39725,     95.04112,50.00000,37.00000,1.854267e-10,0.89476,3
292.52701,213.80083,     -0.40404,     95.06019,50.00000,37.00000,1.855755e-10,0.89449,3
293.58899,214.86750,     -0.41586,     95.06019,50.00000,37.00000,1.853599e-10,0.89426,3
294.65302,215.93417,     -0.42358,     95.05383,50.00000,37.00000,1.860256e-10,0.89400,3
295.72900,217.00083,     -0.43223,     95.07907,50.00000,37.00000,1.860332e-10,0.89377,3
296.78900,218.06750,     -0.44468,     95.06636,50.00000,37.00000,1.857052e-10,0.89350,3
297.85400,219.13417,     -0.45210,     95.07271,50.00000,37.00000,1.853580e-10,0.89328,3
298.92499,220.20083,     -0.46027,     95.07907,50.00000,37.00000,1.851787e-10,0.89300,3
299.99100,221.26750,     -0.47118,     95.06636,50.00000,37.00000,1.853790e-10,0.89277,3
301.05200,222.33417,     -0.48102,     95.06636,50.00000,37.00000,1.847038e-10,0.89250,3
302.12601,223.40083,     -0.48999,     95.06019,50.00000,37.00000,1.858806e-10,0.89227,3
303.17599,224.46750,     -0.49933,     95.06019,50.00000,37.00000,1.859379e-10,0.89199,3
304.25900,225.53417,     -0.50890,     95.02841,50.00000,37.00000,1.852665e-10,0.89176,3
305.32800,226.60083,     -0.51921,     95.05383,50.00000,37.00000,1.858654e-10,0.89148,3
306.38199,227.66750,     -0.53155,     95.05383,50.00000,37.00000,1.864929e-10,0.89124,3
307.44000,228.73417,     -0.54319,     95.05383,50.00000,37.00000,1.857166e-10,0.89097,3
308.50900,229.80083,     -0.55121,     95.04748,50.00000,37.00000,1.860161e-10,0.89072,3
309.59000,230.86750,     -0.55981,     95.02206,50.00000,37.00000,1.860885e-10,0.89045,3
310.64499,231.93417,     -0.57282,     95.00935,50.00000,37.00000,1.857605e-10,0.89022,3
311.71201,233.00083,     -0.57981,     94.98393,50.00000,37.00000,1.859913e-10,0.88993,3
312.77701,234.06750,     -0.58865,     94.95850,50.00000,37.00000,1.853523e-10,0.88968,3
313.84399,235.13417,     -0.59955,     94.96486,50.00000,37.00000,1.858959e-10,0.88941,3
314.91699,236.20083,     -0.61269,     94.92056,50.00000,37.00000,1.862526e-10,0.88916,3
315.99301,237.26750,     -0.62292,     94.90785,50.00000,37.00000,1.861058e-10,0.88892,3
317.05099,238.33417,     -0.63038,     94.86336,50.00000,37.00000,1.857662e-10,0.88864,3
318.11301,239.40083,     -0.64046,     94.81271,50.00000,37.00000,1.855583e-10,0.88835,3
319.20300,240.46750,     -0.65208,     94.81271,50.00000,37.00000,1.862926e-10,0.88811,3
320.25699,241.53417,     -0.66239,     94.77458,50.00000,37.00000,1.861725e-10,0.88782,3
321.32700,242.60083,     -0.67182,     94.70486,50.00000,37.00000,1.864872e-10,0.88758,3
322.40100,243.66750,     -0.68407,     94.67944,50.00000,37.00000,1.857700e-10,0.88729,3
323.45700,244.73417,     -0.69410,     94.62879,50.00000,37.00000,1.862412e-10,0.88704,3
324.52701,245.80083,     -0.70958,     94.57159,50.00000,37.00000,1.867715e-10,0.88675,3
325.59399,246.86750,     -0.72117,     94.50822,50.00000,37.00000,1.860104e-10,0.88649,3
326.65900,247.93417,     -0.73448,     94.43196,50.00000,37.00000,1.862831e-10,0.88620,3
327.71600,249.00083,     -0.74594,     94.34953,50.00000,37.00000,1.864739e-10,0.88595,3
328.79099,250.06750,     -0.75389,     94.26710,50.00000,37.00000,1.865520e-10,0.88565,3
329.85800,251.13417,     -0.76354,     94.18467,50.00000,37.00000,1.863098e-10,0.88541,3
330.93399,252.20083,     -0.77586,     94.05776,50.00000,37.00000,1.869239e-10,0.88511,3
331.98901,253.26750,     -0.78593,     93.98168,50.00000,37.00000,1.868668e-10,0.88486,3
333.06201,254.33417,     -0.80246,     93.85271,50.00000,37.00000,1.865387e-10,0.88457,3
334.12000,255.40083,     -0.81260,     93.70037,50.00000,37.00000,1.861668e-10,0.88431,3
335.18900,256.46750,     -0.82505,     93.52280,50.00000,37.00000,1.867848e-10,0.88401,3
336.25101,257.53417,     -0.83487,     93.39589,50.00000,37.00000,1.868077e-10,0.88376,3
337.32700,258.60083,     -0.84132,     93.19290,50.00000,37.00000,1.860122e-10,0.88345,3
338.38599,259.66750,     -0.84834,     92.98355,50.00000,37.00000,1.867618e-10,0.88319,3
339.45200,260.73417,     -0.86357,     92.74243,50.00000,37.00000,1.859169e-10,0.88289,3
340.52100,261.80083,     -0.87045,     92.48449,50.00000,37.00000,1.857242e-10,0.88263,3
341.58401,262.86750,     -0.88117,     92.23065,50.00000,37.00000,1.862182e-10,0.88237,3
342.65500,263.93417,     -0.89001,     91.92411,50.00000,37.00000,1.869163e-10,0.88207,3
343.71301,265.00083,     -0.89581,     91.56879,50.00000,37.00000,1.861400e-10,0.88181,3
344.78101,266.06750,     -0.90699,     91.18598,50.00000,37.00000,1.859322e-10,0.88150,3
345.85699,267.13417,     -0.91610,     90.80542,50.00000,37.00000,1.871090e-10,0.88120,3
346.91699,268.20083,     -0.92580,     90.34860,50.00000,37.00000,1.866378e-10,0.88093,3
347.97800,269.26750,     -0.93591,     89.84953,50.00000,37.00000,1.870555e-10,0.88063,3
349.03500,270.33417,     -0.94392,     89.28505,50.00000,37.00000,1.863346e-10,0.88036,3
350.11499,271.40083,     -0.95025,     88.66748,50.00000,37.00000,1.858712e-10,0.88005,3
351.16599,272.46750,     -0.95946,     88.01196,50.00000,37.00000,1.864052e-10,0.87979,3
352.24100,273.53417,     -0.96910,     87.27178,50.00000,37.00000,1.864700e-10,0.87948,3
353.30200,274.60083,     -0.97411,     86.44916,50.00000,37.00000,1.861820e-10,0.87921,3
354.37399,275.66750,     -0.98206,     85.55888,50.00000,37.00000,1.873055e-10,0.87889,3
355.43399,276.73417,     -0.99117,     84.62636,50.00000,37.00000,1.868973e-10,0.87863,3
356.50900,277.80083,     -0.99548,     83.52897,50.00000,37.00000,1.872711e-10,0.87832,3
357.57401,278.86750,     -1.00270,     82.33421,50.00000,37.00000,1.871242e-10,0.87804,3
358.65302,279.93417,     -1.00547,     81.06112,50.00000,37.00000,1.872634e-10,0.87773,3
359.70599,281.00083,     -1.01115,     79.67383,50.00000,37.00000,1.871452e-10,0.87746,3
360.78000,282.06750,     -1.01491,     78.10486,50.00000,37.00000,1.871623e-10,0.87713,3
361.83200,283.13417,     -1.02022,     76.43850,50.00000,37.00000,1.872635e-10,0.87686,3
362.89899,284.20083,     -1.01969,     74.66000,50.00000,37.00000,1.872902e-10,0.87654,3
363.97400,285.26750,     -1.02465,     72.68916,50.00000,37.00000,1.875363e-10,0.87628,3
365.02701,286.33417,     -1.02843,     70.54916,50.00000,37.00000,1.870975e-10,0.87595,3
366.10400,287.40083,     -1.03146,     68.26542,50.00000,37.00000,1.870423e-10,0.87567,3
367.16599,288.46750,     -1.03861,     65.81664,50.00000,37.00000,1.876698e-10,0.87535,3
368.23300,289.53417,     -1.04145,     63.22187,50.00000,37.00000,1.873093e-10,0.87508,3
369.29501,290.60083,     -1.04923,     60.40935,50.00000,37.00000,1.873398e-10,0.87475,3
370.37201,291.66750,     -1.05686,     57.45944,50.00000,37.00000,1.881828e-10,0.87447,3
371.43600,292.73417,     -1.06687,     54.35084,50.00000,37.00000,1.879997e-10,0.87416,3
372.49899,293.80083,     -1.07531,     51.05421,50.00000,37.00000,1.877594e-10,0.87388,3
373.58099,294.86750,     -1.08997,     47.63907,50.00000,37.00000,1.880303e-10,0.87355,3
374.63199,295.93417,     -1.10980,     44.11813,50.00000,37.00000,1.878681e-10,0.87327,3
375.67999,297.00083,     -1.12768,     40.49776,50.00000,37.00000,1.876793e-10,0.87295,3
376.76999,298.06750,     -1.15207,     36.81421,50.00000,37.00000,1.872998e-10,0.87267,3
377.82101,299.13417,     -1.17886,     33.07327,50.00000,37.00000,1.882610e-10,0.87233,3
378.89700,300.20083,     -1.21177,     29.37271,50.00000,37.00000,1.878662e-10,0.87205,3
379.97900,301.26750,     -1.25602,     25.72280,50.00000,37.00000,1.878356e-10,0.87172,3
381.03500,302.33417,     -1.30114,     22.14692,50.00000,37.00000,1.876202e-10,0.87144,3
382.11200,303.40083,     -1.35307,     18.77196,50.00000,37.00000,1.873531e-10,0.87110,3
383.17200,304.46750,     -1.41034,     15.60206,50.00000,37.00000,1.871853e-10,0.87082,3
384.24799,305.53417,     -1.47003,     12.69234,50.00000,37.00000,1.875019e-10,0.87048,3
385.30099,306.60083,     -1.53589,     10.06374,50.00000,37.00000,1.882076e-10,0.87020,3
386.38400,307.66750,     -1.60220,      7.74187,50.00000,37.00000,1.881218e-10,0.86987,3
387.44699,308.73417,     -1.67312,      5.77533,50.00000,37.00000,1.884212e-10,0.86959,3
388.51599,309.80083,     -1.74059,      4.10467,50.00000,37.00000,1.884041e-10,0.86925,3
389.58099,310.86750,     -1.80723,      2.76617,50.00000,37.00000,1.886902e-10,0.86896,3
390.63699,311.93417,     -1.86448,      1.71084,50.00000,37.00000,1.881637e-10,0.86863,3
391.72601,313.00083,     -1.91750,      0.89047,50.00000,37.00000,1.882419e-10,0.86834,3
392.77899,314.06750,     -1.96751,      0.24336,50.00000,37.00000,1.885509e-10,0.86799,3
393.84399,315.13417,     -2.01442,     -0.25570,50.00000,37.00000,1.889362e-10,0.86771,3
394.92401,316.20083,     -2.04985,     -0.66168,50.00000,37.00000,1.884079e-10,0.86737,3
395.99100,317.26750,     -2.09865,     -0.94093,50.00000,37.00000,1.887645e-10,0.86708,3
397.04199,318.33417,     -2.13607,     -1.18822,50.00000,37.00000,1.889572e-10,0.86674,3
398.10101,319.40083,     -2.17278,     -1.39757,50.00000,37.00000,1.889209e-10,0.86644,3
399.16199,320.46750,     -2.20775,     -1.52449,50.00000,37.00000,1.890202e-10,0.86610,3
399.68201,320.97917,     -2.22864,     -1.60075,50.00000,37.00000,1.883945e-10,0.86595,4
399.82300,321.05917,     -2.20456,     -1.61327,50.00000,37.00000,1.895332e-10,0.86591,4
400.07700,321.13917,     -2.05478,     -1.61963,50.00000,37.00000,1.895332e-10,0.86591,4
400.50201,321.21917,     -1.75017,     -1.56467,50.00000,37.00000,1.895332e-10,0.86591,4
401.10300,321.29917,     -1.29667,     -1.52673,50.00000,37.00000,1.893921e-10,0.86585,4
401.87601,321.37917,     -0.71321,     -1.45682,50.00000,37.00000,1.893921e-10,0.86585,4
402.83899,321.45917,-2.397657e-02,     -1.37234,50.00000,37.00000,1.894722e-10,0.86581,4
403.98199,321.53917,      0.73406,     -1.26654,50.00000,37.00000,1.894722e-10,0.86581,4
405.26901,321.61917,      1.52417,     -1.17570,50.00000,37.00000,1.888294e-10,0.86576,4
406.67801,321.69917,      2.31364,     -1.07626,50.00000,37.00000,1.888294e-10,0.86576,4
408.17899,321.77917,      3.06505,     -1.00224,50.00000,37.00000,1.883678e-10,0.86570,4
409.75601,321.85917,      3.75125,     -0.92822,50.00000,37.00000,1.883678e-10,0.86570,4
411.38101,321.93917,      4.35804,     -0.86692,50.00000,37.00000,1.890239e-10,0.86566,4
413.00000,322.01917,      4.86161,     -0.83308,50.00000,37.00000,1.890239e-10,0.86566,4
414.62500,322.09917,      5.25905,     -0.78860,50.00000,37.00000,1.892910e-10,0.86562,4
416.22400,322.17917,      5.55110,     -0.76318,50.00000,37.00000,1.892910e-10,0.86562,4
417.79700,322.25917,      5.74084,     -0.72523,50.00000,37.00000,1.886597e-10,0.86555,4
419.32800,322.33917,      5.84544,     -0.71252,50.00000,37.00000,1.886597e-10,0.86555,4
420.80399,322.41917,      5.86997,     -0.71252,50.00000,37.00000,1.889343e-10,0.86551,4
422.24799,322.49917,      5.83003,     -0.71252,50.00000,37.00000,1.889343e-10,0.86551,4
423.65399,322.57917,      5.74478,     -0.71252,50.00000,37.00000,1.890583e-10,0.86547,4
425.02100,322.65917,      5.63013,     -0.71252,50.00000,37.00000,1.890583e-10,0.86547,4
426.36899,322.73917,      5.50146,     -0.74430,50.00000,37.00000,1.890583e-10,0.86541,4
427.68600,322.81917,      5.37315,     -0.76318,50.00000,37.00000,1.890583e-10,0.86541,4
429.01099,322.89917,      5.25384,     -0.78224,50.00000,37.00000,1.887569e-10,0.86537,4
430.32901,322.97917,      5.15142,     -0.78224,50.00000,37.00000,1.887569e-10,0.86537,4
431.64499,323.05917,      5.07803,     -0.75682,50.00000,37.00000,1.892052e-10,0.86531,4
432.99399,323.13917,      5.03214,     -0.77589,50.00000,37.00000,1.892052e-10,0.86531,4
434.35199,323.21917,      5.01782,     -0.78224,50.00000,37.00000,1.895599e-10,0.86526,4
435.73401,323.29917,      5.03642,     -0.80766,50.00000,37.00000,1.895599e-10,0.86526,4
437.15201,323.37917,      5.08194,     -0.80766,50.00000,37.00000,1.888485e-10,0.86522,4
438.60599,323.45917,      5.15367,     -0.78224,50.00000,37.00000,1.888485e-10,0.86522,4
440.08499,323.53917,      5.24322,     -0.78224,50.00000,37.00000,1.887874e-10,0.86517,4
441.57700,323.61917,      5.34821,     -0.78224,50.00000,37.00000,1.887874e-10,0.86517,4
443.11600,323.69917,      5.46550,     -0.78224,50.00000,37.00000,1.886272e-10,0.86511,4
444.67300,323.77917,      5.58841,     -0.78224,50.00000,37.00000,1.886272e-10,0.86511,4
446.24899,323.85917,      5.71020,     -0.75682,50.00000,37.00000,1.887131e-10,0.86507,4
447.85599,323.93917,      5.82480,     -0.73159,50.00000,37.00000,1.887131e-10,0.86507,4
449.46899,324.01917,      5.93419,     -0.73159,50.00000,37.00000,1.887187e-10,0.86503,4
451.08801,324.09917,      6.03017,     -0.73159,50.00000,37.00000,1.887187e-10,0.86503,4
452.72198,324.17917,      6.11317,     -0.73159,50.00000,37.00000,1.889229e-10,0.86496,4
454.35901,324.25917,      6.18035,     -0.73159,50.00000,37.00000,1.889229e-10,0.86496,4
455.99899,324.33917,      6.23294,     -0.73159,50.00000,37.00000,1.889324e-10,0.86492,4
457.64001,324.41917,      6.26948,     -0.73159,50.00000,37.00000,1.889324e-10,0.86492,4
459.27499,324.49917,      6.29583,     -0.71252,50.00000,37.00000,1.889324e-10,0.86492,4
460.91400,324.57917,      6.30978,     -0.71252,50.00000,37.00000,1.891632e-10,0.86487,4
462.55801,324.65917,      6.31685,     -0.71252,50.00000,37.00000,1.891632e-10,0.86487,4
464.19299,324.73917,      6.31305,     -0.71252,50.00000,37.00000,1.887207e-10,0.86482,4
465.84100,324.81917,      6.30526,     -0.70617,50.00000,37.00000,1.887207e-10,0.86482,4
467.47000,324.89917,      6.29137,     -0.70617,50.00000,37.00000,1.892166e-10,0.86477,4
469.10199,324.97917,      6.27378,     -0.68075,50.00000,37.00000,1.892166e-10,0.86477,4
470.74100,325.05917,      6.25613,     -0.65533,50.00000,37.00000,1.888066e-10,0.86473,4
472.37701,325.13917,      6.23947,     -0.65533,50.00000,37.00000,1.888066e-10,0.86473,4
474.02301,325.21917,      6.22209,     -0.65533,50.00000,37.00000,1.897488e-10,0.86468,4
475.67200,325.29917,      6.20689,     -0.65533,50.00000,37.00000,1.897488e-10,0.86468,4
477.31500,325.37917,      6.19176,     -0.63009,50.00000,37.00000,1.887093e-10,0.86462,4
478.96500,325.45917,      6.17703,     -0.63009,50.00000,37.00000,1.887093e-10,0.86462,4
480.62100,325.53917,      6.16453,     -0.60467,50.00000,37.00000,1.889286e-10,0.86457,4
482.28000,325.61917,      6.15126,     -0.60467,50.00000,37.00000,1.889286e-10,0.86457,4
483.92899,325.69917,      6.13643,     -0.57925,50.00000,37.00000,1.890831e-10,0.86452,4
485.59900,325.77917,      6.12234,     -0.57290,50.00000,37.00000,1.890831e-10,0.86452,4
487.26300,325.85917,      6.11156,     -0.55383,50.00000,37.00000,1.890507e-10,0.86448,4
488.93799,325.93917,      6.09567,     -0.52860,50.00000,37.00000,1.890507e-10,0.86448,4
490.60901,326.01917,      6.07777,     -0.50318,50.00000,37.00000,1.891421e-10,0.86443,4
492.26700,326.09917,      6.05755,     -0.47776,50.00000,37.00000,1.891421e-10,0.86443,4
493.93500,326.17917,      6.03610,     -0.47776,50.00000,37.00000,1.889190e-10,0.86438,4
495.62201,326.25917,      6.01022,     -0.42710,50.00000,37.00000,1.889190e-10,0.86438,4
497.28500,326.33917,      5.98492,     -0.42710,50.00000,37.00000,1.901932e-10,0.86433,4
498.96100,326.41917,      5.95157,     -0.40168,50.00000,37.00000,1.901932e-10,0.86433,4
500.63000,326.49917,      5.92363,     -0.40168,50.00000,37.00000,1.889324e-10,0.86428,4
502.30099,326.57917,      5.88798,     -0.37626,50.00000,37.00000,1.889324e-10,0.86428,4
503.97400,326.65917,      5.85995,     -0.35084,50.00000,37.00000,1.884441e-10,0.86423,4
505.64801,326.73917,      5.82417,     -0.33178,50.00000,37.00000,1.884441e-10,0.86423,4
507.30200,326.81917,      5.78590,     -0.32561,50.00000,37.00000,1.890068e-10,0.86418,4
508.97501,326.89917,      5.74899,     -0.30019,50.00000,37.00000,1.890068e-10,0.86418,4
510.63800,326.97917,      5.70989,     -0.27477,50.00000,37.00000,1.890812e-10,0.86413,4
512.29797,327.05917,      5.66984,     -0.24935,50.00000,37.00000,1.890812e-10,0.86413,4
513.96399,327.13917,      5.63009,     -0.24935,50.00000,37.00000,1.889572e-10,0.86408,4
515.62799,327.21917,      5.58939,     -0.24935,50.00000,37.00000,1.889572e-10,0.86408,4
517.29199,327.29917,      5.54822,     -0.22411,50.00000,37.00000,1.889572e-10,0.86408,4
518.95300,327.37917,      5.50272,     -0.19869,50.00000,37.00000,1.893635e-10,0.86403,4
520.61200,327.45917,      5.45890,     -0.17963,50.00000,37.00000,1.893635e-10,0.86403,4
522.28802,327.53917,      5.41787,     -0.14785,50.00000,37.00000,1.891174e-10,0.86399,4
523.93701,327.61917,      5.37279,     -0.14785,50.00000,37.00000,1.891174e-10,0.86399,4
525.60400,327.69917,      5.33027,     -0.12243,50.00000,37.00000,1.896133e-10,0.86393,4
527.26202,327.77917,      5.28528,     -0.12243,50.00000,37.00000,1.896133e-10,0.86393,4
528.92603,327.85917,      5.24375,-9.719626e-02,50.00000,37.00000,1.897106e-10,0.86388,4
530.57703,327.93917,      5.20046,-7.177570e-02,50.00000,37.00000,1.897106e-10,0.86388,4
532.22601,328.01917,      5.15619,-7.177570e-02,50.00000,37.00000,1.893348e-10,0.86383,4
533.88202,328.09917,      5.11198,-4.635514e-02,50.00000,37.00000,1.893348e-10,0.86383,4
535.54700,328.17917,      5.06638,-2.093458e-02,50.00000,37.00000,1.887989e-10,0.86377,4
537.21100,328.25917,      5.01955,-2.093458e-02,50.00000,37.00000,1.887989e-10,0.86377,4
538.87097,328.33917,      4.97369, 4.299065e-03,50.00000,37.00000,1.898479e-10,0.86373,4
540.53003,328.41917,      4.92487,-1.457944e-02,50.00000,37.00000,1.898479e-10,0.86373,4
542.17700,328.49917,      4.87376, 1.065421e-02,50.00000,37.00000,1.886329e-10,0.86369,4
543.82703,328.57917,      4.82490, 3.607477e-02,50.00000,37.00000,1.886329e-10,0.86369,4
545.48102,328.65917,      4.77358, 6.149533e-02,50.00000,37.00000,1.884326e-10,0.86364,4
547.13599,328.73917,      4.72127, 8.691589e-02,50.00000,37.00000,1.884326e-10,0.86364,4
548.77100,328.81917,      4.66934,      0.10579,50.00000,37.00000,1.886883e-10,0.86359,4
550.43201,328.89917,      4.61331,      0.11215,50.00000,37.00000,1.886883e-10,0.86359,4
552.08502,328.97917,      4.55998,      0.13757,50.00000,37.00000,1.892605e-10,0.86354,4
553.72400,329.05917,      4.50430,      0.16299,50.00000,37.00000,1.892605e-10,0.86354,4
555.37903,329.13917,      4.45123,      0.16299,50.00000,37.00000,1.888465e-10,0.86348,4
557.03497,329.21917,      4.40346,      0.18841,50.00000,37.00000,1.888465e-10,0.86348,4
558.67798,329.29917,      4.35893,      0.21364,50.00000,37.00000,1.888351e-10,0.86343,4
560.33600,329.37917,      4.31199,      0.21364,50.00000,37.00000,1.888351e-10,0.86343,4
561.98102,329.45917,      4.26095,      0.22000,50.00000,37.00000,1.888351e-10,0.86343,4
563.63501,329.53917,      4.21124,      0.23907,50.00000,37.00000,1.891479e-10,0.86339,4
565.27100,329.61917,      4.15842,      0.23907,50.00000,37.00000,1.891479e-10,0.86339,4
566.91998,329.69917,      4.09928,      0.26449,50.00000,37.00000,1.893215e-10,0.86333,4
568.55603,329.77917,      4.04111,      0.27720,50.00000,37.00000,1.893215e-10,0.86333,4
570.20203,329.85917,      3.98092,      0.29196,50.00000,37.00000,1.895085e-10,0.86329,4
571.84198,329.93917,      3.92198,      0.33645,50.00000,37.00000,1.895085e-10,0.86329,4
573.47302,330.01917,      3.86300,      0.34262,50.00000,37.00000,1.893100e-10,0.86324,4
575.10797,330.09917,      3.79914,      0.34262,50.00000,37.00000,1.893100e-10,0.86324,4
576.75598,330.17917,      3.73920,      0.36168,50.00000,37.00000,1.892090e-10,0.86318,4
578.39398,330.25917,      3.67688,      0.36168,50.00000,37.00000,1.892090e-10,0.86318,4
580.02197,330.33917,      3.61192,      0.38710,50.00000,37.00000,1.892891e-10,0.86313,4
581.66803,330.41917,      3.55170,      0.42093,50.00000,37.00000,1.892891e-10,0.86313,4
583.29199,330.49917,      3.49086,      0.44636,50.00000,37.00000,1.886921e-10,0.86310,4
584.91803,330.57917,      3.42927,      0.44636,50.00000,37.00000,1.886921e-10,0.86310,4
586.55798,330.65917,      3.36720,      0.44636,50.00000,37.00000,1.891403e-10,0.86303,4
588.19397,330.73917,      3.30356,      0.44636,50.00000,37.00000,1.891403e-10,0.86303,4
589.82202,330.81917,      3.24145,      0.47178,50.00000,37.00000,1.892490e-10,0.86298,4
591.45099,330.89917,      3.17752,      0.47178,50.00000,37.00000,1.892490e-10,0.86298,4
593.09198,330.97917,      3.11548,      0.49701,50.00000,37.00000,1.895370e-10,0.86293,4
594.71198,331.05917,      3.05311,      0.52243,50.00000,37.00000,1.895370e-10,0.86293,4
596.35602,331.13917,      2.99532,      0.54150,50.00000,37.00000,1.885967e-10,0.86288,4
597.99103,331.21917,      2.92959,      0.57327,50.00000,37.00000,1.885967e-10,0.86288,4
599.61902,331.29917,      2.86199,      0.57327,50.00000,37.00000,1.885510e-10,0.86284,4
601.24799,331.37917,      2.79705,      0.57327,50.00000,37.00000,1.885510e-10,0.86284,4
602.86902,331.45917,      2.72491,      0.59850,50.00000,37.00000,1.891899e-10,0.86278,4
604.50403,331.53917,      2.65573,      0.60486,50.00000,37.00000,1.891899e-10,0.86278,4
606.13599,331.61917,      2.59028,      0.62393,50.00000,37.00000,1.894722e-10,0.86273,4
607.75299,331.69917,      2.52052,      0.63664,50.00000,37.00000,1.894722e-10,0.86273,4
609.39099,331.77917,      2.45189,      0.64935,50.00000,37.00000,1.891499e-10,0.86269,4
611.00897,331.85917,      2.37705,      0.67477,50.00000,37.00000,1.891499e-10,0.86269,4
612.64899,331.93917,      2.29983,      0.70000,50.00000,37.00000,1.891441e-10,0.86264,4
614.27301,332.01917,      2.22766,      0.70000,50.00000,37.00000,1.891441e-10,0.86264,4
615.88702,332.09917,      2.15223,      0.72542,50.00000,37.00000,1.891384e-10,0.86258,4
617.51898,332.17917,      2.07576,      0.72542,50.00000,37.00000,1.891384e-10,0.86258,4
619.14697,332.25917,      2.00062,      0.75084,50.00000,37.00000,1.887417e-10,0.86254,4
620.77197,332.33917,      1.92032,      0.75084,50.00000,37.00000,1.887417e-10,0.86254,4
622.39099,332.41917,      1.84406,      0.76991,50.00000,37.00000,1.887417e-10,0.86254,4
624.02002,332.49917,      1.76563,      0.80150,50.00000,37.00000,1.889591e-10,0.86248,4
625.64099,332.57917,      1.68937,      0.80150,50.00000,37.00000,1.889591e-10,0.86248,4
627.26599,332.65917,      1.60711,      0.82692,50.00000,37.00000,1.889133e-10,0.86243,4
628.89801,332.73917,      1.52484,      0.82692,50.00000,37.00000,1.889133e-10,0.86243,4
630.50500,332.81917,      1.44333,      0.85234,50.00000,37.00000,1.888561e-10,0.86238,4
632.14301,332.89917,      1.35994,      0.87776,50.00000,37.00000,1.888561e-10,0.86238,4
633.75500,332.97917,      1.27815,      0.87776,50.00000,37.00000,1.894074e-10,0.86233,4
635.38898,333.05917,      1.19583,      0.90318,50.00000,37.00000,1.894074e-10,0.86233,4
637.00500,333.13917,      1.11154,      0.90318,50.00000,37.00000,1.891193e-10,0.86228,4
638.62799,333.21917,      1.02588,      0.91570,50.00000,37.00000,1.891193e-10,0.86228,4
640.24701,333.29917,      0.93825,      0.91570,50.00000,37.00000,1.891746e-10,0.86224,4
641.86298,333.37917,      0.85282,      0.93477,50.00000,37.00000,1.891746e-10,0.86224,4
643.48401,333.45917,      0.76545,      0.95383,50.00000,37.00000,1.893654e-10,0.86219,4
645.11102,333.53917,      0.67917,      0.97925,50.00000,37.00000,1.893654e-10,0.86219,4
646.72998,333.61917,      0.59176,      0.97925,50.00000,37.00000,1.891403e-10,0.86214,4
648.34698,333.69917,      0.50602,      1.00467,50.00000,37.00000,1.891403e-10,0.86214,4
649.95801,333.77917,      0.41748,      1.01720,50.00000,37.00000,1.893101e-10,0.86209,4
651.57501,333.85917,      0.33172,      1.02991,50.00000,37.00000,1.893101e-10,0.86209,4
653.19800,333.93917,      0.24793,      1.05533,50.00000,37.00000,1.891232e-10,0.86203,4
654.81500,334.01917,      0.16527,      1.02991,50.00000,37.00000,1.891232e-10,0.86203,4
656.42798,334.09917, 8.066167e-02,      1.08486,50.00000,37.00000,1.893978e-10,0.86198,4
658.04602,334.17917,-6.193013e-03,      1.08486,50.00000,37.00000,1.893978e-10,0.86198,4
659.65698,334.25917,-9.135102e-02,      1.08486,50.00000,37.00000,1.892910e-10,0.86195,4
661.26898,334.33917,     -0.17508,      1.11028,50.00000,37.00000,1.892910e-10,0.86195,4
662.89301,334.41917,     -0.26389,      1.11028,50.00000,37.00000,1.893711e-10,0.86189,4
664.50403,334.49917,     -0.34788,      1.11028,50.00000,37.00000,1.893711e-10,0.86189,4
666.11902,334.57917,     -0.43355,      1.14206,50.00000,37.00000,1.888847e-10,0.86184,4
667.73199,334.65917,     -0.52033,      1.16112,50.00000,37.00000,1.888847e-10,0.86184,4
669.34302,334.73917,     -0.59970,      1.18654,50.00000,37.00000,1.890564e-10,0.86179,4
670.96301,334.81917,     -0.68417,      1.18654,50.00000,37.00000,1.890564e-10,0.86179,4
672.58698,334.89917,     -0.76547,      1.21178,50.00000,37.00000,1.890449e-10,0.86174,4
674.19397,334.97917,     -0.85216,      1.23720,50.00000,37.00000,1.890449e-10,0.86174,4
675.80902,335.05917,     -0.93367,      1.26262,50.00000,37.00000,1.889000e-10,0.86169,4
677.43103,335.13917,     -1.02405,      1.26262,50.00000,37.00000,1.889000e-10,0.86169,4
679.04700,335.21917,     -1.11124,      1.26262,50.00000,37.00000,1.889839e-10,0.86164,4
680.66400,335.29917,     -1.19754,      1.28804,50.00000,37.00000,1.889839e-10,0.86164,4
682.28003,335.37917,     -1.28468,      1.28804,50.00000,37.00000,1.891556e-10,0.86160,4
683.89301,335.45917,     -1.37064,      1.31327,50.00000,37.00000,1.891556e-10,0.86160,4
685.50702,335.53917,     -1.45280,      1.33869,50.00000,37.00000,1.887531e-10,0.86154,4
687.11700,335.61917,     -1.53780,      1.33869,50.00000,37.00000,1.887531e-10,0.86154,4
688.73999,335.69917,     -1.62163,      1.36411,50.00000,37.00000,1.891766e-10,0.86149,4
690.35400,335.77917,     -1.70394,      1.35140,50.00000,37.00000,1.891766e-10,0.86149,4
691.96100,335.85917,     -1.78910,      1.35140,50.00000,37.00000,1.886673e-10,0.86144,4
693.57300,335.93917,     -1.87597,      1.37682,50.00000,37.00000,1.886673e-10,0.86144,4
695.19000,336.01917,     -1.95523,      1.40206,50.00000,37.00000,1.891365e-10,0.86140,4
696.79401,336.09917,     -2.03936,      1.41477,50.00000,37.00000,1.891365e-10,0.86140,4
698.41998,336.17917,     -2.12027,      1.42748,50.00000,37.00000,1.887970e-10,0.86134,4
700.02899,336.25917,     -2.19845,      1.44654,50.00000,37.00000,1.887970e-10,0.86134,4
701.63702,336.33917,     -2.27596,      1.45290,50.00000,37.00000,1.887970e-10,0.86134,4
703.25403,336.41917,     -2.35460,      1.45290,50.00000,37.00000,1.893501e-10,0.86129,4
704.87299,336.49917,     -2.43229,      1.45290,50.00000,37.00000,1.893501e-10,0.86129,4
706.48297,336.57917,     -2.51312,      1.47832,50.00000,37.00000,1.893158e-10,0.86124,4
708.10400,336.65917,     -2.59155,      1.47832,50.00000,37.00000,1.893158e-10,0.86124,4
709.71600,336.73917,     -2.67195,      1.50374,50.00000,37.00000,1.893711e-10,0.86118,4
711.32397,336.81917,     -2.74991,      1.52897,50.00000,37.00000,1.893711e-10,0.86118,4
712.94299,336.89917,     -2.82781,      1.52897,50.00000,37.00000,1.890507e-10,0.86113,4
714.55402,336.97917,     -2.90650,      1.52897,50.00000,37.00000,1.890507e-10,0.86113,4
716.16602,337.05917,     -2.98036,      1.55439,50.00000,37.00000,1.891498e-10,0.86109,4
717.79102,337.13917,     -3.05774,      1.55439,50.00000,37.00000,1.891498e-10,0.86109,4
719.38898,337.21917,     -3.12928,      1.57981,50.00000,37.00000,1.889820e-10,0.86104,4
721.00500,337.29917,     -3.20406,      1.60523,50.00000,37.00000,1.889820e-10,0.86104,4
722.61902,337.37917,     -3.28054,      1.63047,50.00000,37.00000,1.891441e-10,0.86098,4
724.23798,337.45917,     -3.35665,      1.63047,50.00000,37.00000,1.891441e-10,0.86098,4
725.85400,337.53917,     -3.43085,      1.63047,50.00000,37.00000,1.900081e-10,0.86093,4
727.46198,337.61917,     -3.50763,      1.65589,50.00000,37.00000,1.900081e-10,0.86093,4
729.09302,337.69917,     -3.58199,      1.65589,50.00000,37.00000,1.896934e-10,0.86088,4
730.70099,337.77917,     -3.66643,      1.66860,50.00000,37.00000,1.896934e-10,0.86088,4
732.30701,337.85917,     -3.74143,      1.70037,50.00000,37.00000,1.893902e-10,0.86083,4
733.92902,337.93917,     -3.82364,      1.70673,50.00000,37.00000,1.893902e-10,0.86083,4
735.53802,338.01917,     -3.90603,      1.70673,50.00000,37.00000,1.890297e-10,0.86078,4
737.14301,338.09917,     -3.98984,      1.70673,50.00000,37.00000,1.890297e-10,0.86078,4
738.77197,338.17917,     -4.06881,      1.72561,50.00000,37.00000,1.893349e-10,0.86073,4
740.37000,338.25917,     -4.14940,      1.73196,50.00000,37.00000,1.893349e-10,0.86073,4
741.99200,338.33917,     -4.22877,      1.73196,50.00000,37.00000,1.895294e-10,0.86067,4
743.59998,338.41917,     -4.30587,      1.75738,50.00000,37.00000,1.895294e-10,0.86067,4
745.20599,338.49917,     -4.37676,      1.78280,50.00000,37.00000,1.894512e-10,0.86063,4
746.83600,338.57917,     -4.44977,      1.78280,50.00000,37.00000,1.894512e-10,0.86063,4
748.45001,338.65917,     -4.52169,      1.81028,50.00000,37.00000,1.886940e-10,0.86058,4
750.05798,338.73917,     -4.59838,      1.83570,50.00000,37.00000,1.886940e-10,0.86058,4
751.66199,338.81917,     -4.67403,      1.83570,50.00000,37.00000,1.893787e-10,0.86052,4
753.27899,338.89917,     -4.75210,      1.85477,50.00000,37.00000,1.893787e-10,0.86052,4
754.89899,338.97917,     -4.82423,      1.85477,50.00000,37.00000,1.897164e-10,0.86048,4
756.50098,339.05917,     -4.90387,      1.86093,50.00000,37.00000,1.897164e-10,0.86048,4
758.11603,339.13917,     -4.98410,      1.88636,50.00000,37.00000,1.890469e-10,0.86041,4
759.72699,339.21917,     -5.06422,      1.88636,50.00000,37.00000,1.890469e-10,0.86041,4
761.33698,339.29917,     -5.14518,      1.91178,50.00000,37.00000,1.888008e-10,0.86037,4
762.95502,339.37917,     -5.22329,      1.91178,50.00000,37.00000,1.888008e-10,0.86037,4
764.56299,339.45917,     -5.29784,      1.91178,50.00000,37.00000,1.891937e-10,0.86032,4
766.17798,339.53917,     -5.37916,      1.96673,50.00000,37.00000,1.891937e-10,0.86032,4
767.79199,339.61917,     -5.45011,      1.96673,50.00000,37.00000,1.891937e-10,0.86032,4
769.40601,339.69917,     -5.52749,      1.99215,50.00000,37.00000,1.891899e-10,0.86026,4
771.01703,339.77917,     -5.60131,      1.99215,50.00000,37.00000,1.891899e-10,0.86026,4
772.63098,339.85917,     -5.68412,      2.01757,50.00000,37.00000,1.891689e-10,0.86022,4
774.24597,339.93917,     -5.76246,      2.01757,50.00000,37.00000,1.891689e-10,0.86022,4
775.84698,340.01917,     -5.83592,      2.04280,50.00000,37.00000,1.892223e-10,0.86017,4
777.46002,340.09917,     -5.91091,      2.06822,50.00000,37.00000,1.892223e-10,0.86017,4
779.07599,340.17917,     -5.99052,      2.06822,50.00000,37.00000,1.888065e-10,0.86012,4
780.67999,340.25917,     -6.06115,      2.09364,50.00000,37.00000,1.888065e-10,0.86012,4
782.27899,340.33917,     -6.13952,      2.09364,50.00000,37.00000,1.889782e-10,0.86007,4
783.89697,340.41917,     -6.21538,      2.09364,50.00000,37.00000,1.889782e-10,0.86007,4
785.51001,340.49917,     -6.28983,      2.11907,50.00000,37.00000,1.893940e-10,0.86002,4
787.12097,340.57917,     -6.36195,      2.11907,50.00000,37.00000,1.893940e-10,0.86002,4
788.71503,340.65917,     -6.43449,      2.11907,50.00000,37.00000,1.896209e-10,0.85997,4
790.33197,340.73917,     -6.50514,      2.14430,50.00000,37.00000,            ,0.44877,4
791.93597,340.81917,     -6.57527,      2.16972,50.00000,37.00000,            ,0.44812,4
793.54401,340.89917,     -6.64499,      2.16972,50.00000,37.00000,            ,0.44747,4
794.24597,340.93417,     -6.68011,      2.16972,50.00000,37.00000,            ,0.44719,4